{"schema_version":"1.3.0","event_id":"26966e9b-c1ff-45dd-a256-40b22cea11a5","event_type":"raw.depth_update","source":"binance_market_data_recorder","venue":"binance_usdm","market_type":"perpetual_futures","symbol":"BTCUSDT","event_time_ms":1783517064762,"received_time_ms":1783517064855,"trace_id":"53c202f8-fae2-4e90-954d-01cfdb46e839","first_update_id":10999770331228,"final_update_id":10999770341720,"previous_final_update_id":10999770330898,"bids":[{"price":"11452.20","quantity":"0.192"},{"price":"11552.20","quantity":"2.720"},{"price":"11652.20","quantity":"1.036"},{"price":"11752.20","quantity":"0.952"},{"price":"55666.90","quantity":"0.003"},{"price":"58759.50","quantity":"0.000"},{"price":"59378.10","quantity":"0.003"},{"price":"60788.30","quantity":"1.306"},{"price":"60831.60","quantity":"1.166"},{"price":"60844.70","quantity":"4.436"},{"price":"60862.60","quantity":"3.446"},{"price":"60893.50","quantity":"3.449"},{"price":"60937.40","quantity":"13.601"},{"price":"60996.20","quantity":"0.001"},{"price":"61092.00","quantity":"9.171"},{"price":"61233.70","quantity":"0.000"},{"price":"61266.60","quantity":"2.383"},{"price":"61286.90","quantity":"0.014"},{"price":"61294.30","quantity":"1.191"},{"price":"61542.90","quantity":"0.011"},{"price":"61811.60","quantity":"0.069"},{"price":"61815.40","quantity":"0.105"},{"price":"61815.50","quantity":"0.104"},{"price":"61820.50","quantity":"0.656"},{"price":"61821.00","quantity":"0.793"},{"price":"61823.50","quantity":"0.092"},{"price":"61823.80","quantity":"0.203"},{"price":"61823.90","quantity":"0.105"},{"price":"61824.10","quantity":"0.110"},{"price":"61825.10","quantity":"0.263"},{"price":"61830.40","quantity":"0.050"},{"price":"61833.90","quantity":"0.001"},{"price":"61836.50","quantity":"0.087"},{"price":"61837.90","quantity":"0.325"},{"price":"61838.00","quantity":"0.000"},{"price":"61841.80","quantity":"0.085"},{"price":"61842.00","quantity":"0.572"},{"price":"61844.20","quantity":"1.202"},{"price":"61845.00","quantity":"0.348"},{"price":"61845.10","quantity":"0.003"}],"asks":[{"price":"61853.60","quantity":"0.001"},{"price":"61868.80","quantity":"0.040"},{"price":"61872.50","quantity":"0.080"},{"price":"61896.50","quantity":"0.016"},{"price":"61925.80","quantity":"0.275"},{"price":"62172.80","quantity":"0.161"},{"price":"62470.80","quantity":"0.018"},{"price":"62576.10","quantity":"4.277"},{"price":"63089.30","quantity":"0.135"},{"price":"68037.50","quantity":"0.000"}],"raw":{"e":"depthUpdate","E":1783517064762,"T":1783517064761,"s":"BTCUSDT","ps":"BTCUSDT","U":10999770331228,"u":10999770341720,"pu":10999770330898,"b":[["11452.20","0.192"],["11552.20","2.720"],["11652.20","1.036"],["11752.20","0.952"],["55666.90","0.003"],["58759.50","0.000"],["59378.10","0.003"],["60788.30","1.306"],["60831.60","1.166"],["60844.70","4.436"],["60862.60","3.446"],["60893.50","3.449"],["60937.40","13.601"],["60996.20","0.001"],["61092.00","9.171"],["61233.70","0.000"],["61266.60","2.383"],["61286.90","0.014"],["61294.30","1.191"],["61542.90","0.011"],["61811.60","0.069"],["61815.40","0.105"],["61815.50","0.104"],["61820.50","0.656"],["61821.00","0.793"],["61823.50","0.092"],["61823.80","0.203"],["61823.90","0.105"],["61824.10","0.110"],["61825.10","0.263"],["61830.40","0.050"],["61833.90","0.001"],["61836.50","0.087"],["61837.90","0.325"],["61838.00","0.000"],["61841.80","0.085"],["61842.00","0.572"],["61844.20","1.202"],["61845.00","0.348"],["61845.10","0.003"]],"a":[["61853.60","0.001"],["61868.80","0.040"],["61872.50","0.080"],["61896.50","0.016"],["61925.80","0.275"],["62172.80","0.161"],["62470.80","0.018"],["62576.10","4.277"],["63089.30","0.135"],["68037.50","0.000"]],"st":1}}
{"schema_version":"1.3.0","event_id":"83e1b8ec-3091-4839-89f7-bb92803436ee","event_type":"raw.depth_update","source":"binance_market_data_recorder","venue":"binance_usdm","market_type":"perpetual_futures","symbol":"BTCUSDT","event_time_ms":1783517064864,"received_time_ms":1783517064866,"trace_id":"002415dd-e138-428d-b59f-ea581923a6a0","first_update_id":10999770341905,"final_update_id":10999770349305,"previous_final_update_id":10999770341720,"bids":[{"price":"1000.00","quantity":"207.692"},{"price":"11452.20","quantity":"0.320"},{"price":"11552.20","quantity":"2.736"},{"price":"11652.20","quantity":"1.028"},{"price":"11752.20","quantity":"0.816"},{"price":"55666.90","quantity":"0.003"},{"price":"56500.00","quantity":"24.888"},{"price":"58759.50","quantity":"0.000"},{"price":"59378.10","quantity":"0.000"},{"price":"60806.90","quantity":"0.586"},{"price":"60813.70","quantity":"3.037"},{"price":"60862.60","quantity":"4.595"},{"price":"60937.40","quantity":"12.454"},{"price":"60955.30","quantity":"6.882"},{"price":"61122.90","quantity":"1.964"},{"price":"61233.70","quantity":"0.000"},{"price":"61270.30","quantity":"0.031"},{"price":"61295.50","quantity":"1.638"},{"price":"61542.90","quantity":"0.011"},{"price":"61700.30","quantity":"0.528"},{"price":"61721.80","quantity":"0.272"},{"price":"61747.80","quantity":"0.000"},{"price":"61747.90","quantity":"0.017"},{"price":"61763.70","quantity":"0.008"},{"price":"61808.30","quantity":"1.119"},{"price":"61814.50","quantity":"0.003"},{"price":"61815.40","quantity":"0.004"},{"price":"61815.50","quantity":"0.003"},{"price":"61826.10","quantity":"0.003"},{"price":"61827.10","quantity":"0.583"},{"price":"61827.90","quantity":"0.004"},{"price":"61828.10","quantity":"0.001"},{"price":"61830.40","quantity":"0.050"},{"price":"61836.50","quantity":"0.007"},{"price":"61841.80","quantity":"0.085"},{"price":"61842.20","quantity":"0.141"},{"price":"61848.10","quantity":"0.080"}],"asks":[{"price":"61852.30","quantity":"2.290"},{"price":"61853.30","quantity":"0.007"},{"price":"61925.80","quantity":"0.275"},{"price":"61986.80","quantity":"0.707"},{"price":"61987.10","quantity":"0.000"},{"price":"62008.30","quantity":"1.289"},{"price":"62009.50","quantity":"0.000"},{"price":"62026.00","quantity":"0.000"},{"price":"62026.20","quantity":"0.003"},{"price":"62147.50","quantity":"0.018"},{"price":"62170.90","quantity":"0.052"},{"price":"62470.80","quantity":"0.018"},{"price":"62588.30","quantity":"0.958"},{"price":"62594.50","quantity":"5.181"},{"price":"62792.00","quantity":"0.000"},{"price":"89523.20","quantity":"0.666"}],"raw":{"e":"depthUpdate","E":1783517064864,"T":1783517064863,"s":"BTCUSDT","ps":"BTCUSDT","U":10999770341905,"u":10999770349305,"pu":10999770341720,"b":[["1000.00","207.692"],["11452.20","0.320"],["11552.20","2.736"],["11652.20","1.028"],["11752.20","0.816"],["55666.90","0.003"],["56500.00","24.888"],["58759.50","0.000"],["59378.10","0.000"],["60806.90","0.586"],["60813.70","3.037"],["60862.60","4.595"],["60937.40","12.454"],["60955.30","6.882"],["61122.90","1.964"],["61233.70","0.000"],["61270.30","0.031"],["61295.50","1.638"],["61542.90","0.011"],["61700.30","0.528"],["61721.80","0.272"],["61747.80","0.000"],["61747.90","0.017"],["61763.70","0.008"],["61808.30","1.119"],["61814.50","0.003"],["61815.40","0.004"],["61815.50","0.003"],["61826.10","0.003"],["61827.10","0.583"],["61827.90","0.004"],["61828.10","0.001"],["61830.40","0.050"],["61836.50","0.007"],["61841.80","0.085"],["61842.20","0.141"],["61848.10","0.080"]],"a":[["61852.30","2.290"],["61853.30","0.007"],["61925.80","0.275"],["61986.80","0.707"],["61987.10","0.000"],["62008.30","1.289"],["62009.50","0.000"],["62026.00","0.000"],["62026.20","0.003"],["62147.50","0.018"],["62170.90","0.052"],["62470.80","0.018"],["62588.30","0.958"],["62594.50","5.181"],["62792.00","0.000"],["89523.20","0.666"]],"st":1}}
{"schema_version":"1.3.0","event_id":"7643747b-c13c-463c-bb87-6a5e39d61832","event_type":"raw.depth_update","source":"binance_market_data_recorder","venue":"binance_usdm","market_type":"perpetual_futures","symbol":"BTCUSDT","event_time_ms":1783517064966,"received_time_ms":1783517065045,"trace_id":"59f8b9a9-96d1-4315-be15-34cac6bc4202","first_update_id":10999770349344,"final_update_id":10999770358284,"previous_final_update_id":10999770349305,"bids":[{"price":"1000.00","quantity":"207.692"},{"price":"11452.20","quantity":"0.464"},{"price":"11552.20","quantity":"2.720"},{"price":"11652.20","quantity":"1.053"},{"price":"11752.20","quantity":"0.663"},{"price":"55666.90","quantity":"0.003"},{"price":"60992.50","quantity":"0.982"},{"price":"61150.80","quantity":"0.245"},{"price":"61163.20","quantity":"0.245"},{"price":"61233.70","quantity":"0.002"},{"price":"61274.50","quantity":"0.245"},{"price":"61295.50","quantity":"1.882"},{"price":"61759.40","quantity":"0.000"},{"price":"61760.30","quantity":"0.214"},{"price":"61762.90","quantity":"1.941"},{"price":"61767.50","quantity":"0.281"},{"price":"61821.70","quantity":"1.088"},{"price":"61822.50","quantity":"0.761"},{"price":"61823.50","quantity":"0.092"},{"price":"61828.10","quantity":"0.081"},{"price":"61842.00","quantity":"0.006"},{"price":"61842.20","quantity":"0.061"},{"price":"61845.10","quantity":"0.569"},{"price":"61852.20","quantity":"16.123"}],"asks":[{"price":"61852.30","quantity":"1.000"},{"price":"61852.40","quantity":"0.002"},{"price":"61854.90","quantity":"0.148"},{"price":"61856.30","quantity":"0.032"},{"price":"61856.40","quantity":"0.791"},{"price":"61856.90","quantity":"1.617"},{"price":"61857.40","quantity":"1.274"},{"price":"61858.30","quantity":"0.383"},{"price":"61861.00","quantity":"0.047"},{"price":"61865.20","quantity":"0.015"},{"price":"61868.90","quantity":"0.112"},{"price":"61869.10","quantity":"0.004"},{"price":"61871.30","quantity":"0.151"},{"price":"61872.80","quantity":"0.000"},{"price":"61873.60","quantity":"0.035"},{"price":"61878.10","quantity":"0.000"},{"price":"61878.30","quantity":"0.040"},{"price":"61880.70","quantity":"0.236"},{"price":"61887.90","quantity":"0.484"},{"price":"61888.00","quantity":"0.599"},{"price":"61888.80","quantity":"0.057"},{"price":"61925.80","quantity":"0.275"},{"price":"61984.80","quantity":"0.000"},{"price":"62022.50","quantity":"0.162"},{"price":"62056.10","quantity":"0.002"},{"price":"62417.50","quantity":"3.182"},{"price":"62470.80","quantity":"0.000"},{"price":"62594.50","quantity":"5.452"}],"raw":{"e":"depthUpdate","E":1783517064966,"T":1783517064965,"s":"BTCUSDT","ps":"BTCUSDT","U":10999770349344,"u":10999770358284,"pu":10999770349305,"b":[["1000.00","207.692"],["11452.20","0.464"],["11552.20","2.720"],["11652.20","1.053"],["11752.20","0.663"],["55666.90","0.003"],["60992.50","0.982"],["61150.80","0.245"],["61163.20","0.245"],["61233.70","0.002"],["61274.50","0.245"],["61295.50","1.882"],["61759.40","0.000"],["61760.30","0.214"],["61762.90","1.941"],["61767.50","0.281"],["61821.70","1.088"],["61822.50","0.761"],["61823.50","0.092"],["61828.10","0.081"],["61842.00","0.006"],["61842.20","0.061"],["61845.10","0.569"],["61852.20","16.123"]],"a":[["61852.30","1.000"],["61852.40","0.002"],["61854.90","0.148"],["61856.30","0.032"],["61856.40","0.791"],["61856.90","1.617"],["61857.40","1.274"],["61858.30","0.383"],["61861.00","0.047"],["61865.20","0.015"],["61868.90","0.112"],["61869.10","0.004"],["61871.30","0.151"],["61872.80","0.000"],["61873.60","0.035"],["61878.10","0.000"],["61878.30","0.040"],["61880.70","0.236"],["61887.90","0.484"],["61888.00","0.599"],["61888.80","0.057"],["61925.80","0.275"],["61984.80","0.000"],["62022.50","0.162"],["62056.10","0.002"],["62417.50","3.182"],["62470.80","0.000"],["62594.50","5.452"]],"st":1}}
{"schema_version":"1.3.0","event_id":"4ea2e64e-2bd0-47fe-91e3-83bf91395017","event_type":"raw.depth_update","source":"binance_market_data_recorder","venue":"binance_usdm","market_type":"perpetual_futures","symbol":"BTCUSDT","event_time_ms":1783517065068,"received_time_ms":1783517065062,"trace_id":"68f15238-759a-404a-87f9-06d7d94ac8b4","first_update_id":10999770358435,"final_update_id":10999770367988,"previous_final_update_id":10999770358284,"bids":[{"price":"11452.20","quantity":"0.720"},{"price":"11552.20","quantity":"2.480"},{"price":"11652.20","quantity":"1.173"},{"price":"11752.20","quantity":"0.527"},{"price":"55666.90","quantity":"0.003"},{"price":"58759.50","quantity":"0.020"},{"price":"59378.10","quantity":"0.003"},{"price":"60615.20","quantity":"0.057"},{"price":"60875.60","quantity":"5.333"},{"price":"60937.40","quantity":"11.307"},{"price":"61079.00","quantity":"0.974"},{"price":"61122.90","quantity":"0.984"},{"price":"61140.90","quantity":"3.920"},{"price":"61163.20","quantity":"0.000"},{"price":"61233.70","quantity":"0.000"},{"price":"61315.50","quantity":"0.018"},{"price":"61745.70","quantity":"5.883"},{"price":"61746.10","quantity":"0.007"},{"price":"61748.60","quantity":"0.927"},{"price":"61787.20","quantity":"0.051"},{"price":"61787.50","quantity":"0.030"},{"price":"61808.30","quantity":"1.115"},{"price":"61814.50","quantity":"0.007"},{"price":"61828.10","quantity":"0.001"},{"price":"61830.40","quantity":"0.050"},{"price":"61833.10","quantity":"0.407"},{"price":"61835.70","quantity":"0.569"},{"price":"61836.70","quantity":"0.006"},{"price":"61837.60","quantity":"1.240"},{"price":"61841.10","quantity":"0.405"},{"price":"61841.80","quantity":"0.990"},{"price":"61842.20","quantity":"0.141"},{"price":"61845.00","quantity":"0.009"},{"price":"61845.10","quantity":"0.003"},{"price":"61848.10","quantity":"0.000"},{"price":"61850.80","quantity":"0.000"},{"price":"61852.20","quantity":"16.124"}],"asks":[{"price":"61852.30","quantity":"2.293"},{"price":"61852.40","quantity":"0.003"},{"price":"61853.20","quantity":"0.002"},{"price":"61854.90","quantity":"0.022"},{"price":"61856.30","quantity":"1.648"},{"price":"61856.40","quantity":"1.791"},{"price":"61856.90","quantity":"0.001"},{"price":"61857.40","quantity":"0.274"},{"price":"61857.60","quantity":"0.633"},{"price":"61858.50","quantity":"0.540"},{"price":"61859.60","quantity":"0.453"},{"price":"61859.70","quantity":"2.138"},{"price":"61860.40","quantity":"1.785"},{"price":"61862.50","quantity":"0.001"},{"price":"61863.20","quantity":"1.423"},{"price":"61863.40","quantity":"0.033"},{"price":"61864.20","quantity":"0.011"},{"price":"61864.70","quantity":"3.064"},{"price":"61864.90","quantity":"0.054"},{"price":"61866.80","quantity":"3.442"},{"price":"61870.90","quantity":"0.149"},{"price":"61878.10","quantity":"0.002"},{"price":"61887.20","quantity":"0.107"},{"price":"61887.70","quantity":"0.050"},{"price":"61887.80","quantity":"0.286"},{"price":"61887.90","quantity":"0.379"},{"price":"61888.00","quantity":"0.494"},{"price":"61888.80","quantity":"0.055"},{"price":"61893.40","quantity":"0.243"},{"price":"61909.30","quantity":"0.131"},{"price":"61909.50","quantity":"2.715"},{"price":"61909.80","quantity":"0.000"},{"price":"61909.90","quantity":"0.113"},{"price":"61923.30","quantity":"0.096"},{"price":"61923.70","quantity":"0.000"},{"price":"61994.00","quantity":"4.043"},{"price":"61994.80","quantity":"0.831"},{"price":"62470.80","quantity":"0.000"},{"price":"89523.20","quantity":"0.672"}],"raw":{"e":"depthUpdate","E":1783517065068,"T":1783517065066,"s":"BTCUSDT","ps":"BTCUSDT","U":10999770358435,"u":10999770367988,"pu":10999770358284,"b":[["11452.20","0.720"],["11552.20","2.480"],["11652.20","1.173"],["11752.20","0.527"],["55666.90","0.003"],["58759.50","0.020"],["59378.10","0.003"],["60615.20","0.057"],["60875.60","5.333"],["60937.40","11.307"],["61079.00","0.974"],["61122.90","0.984"],["61140.90","3.920"],["61163.20","0.000"],["61233.70","0.000"],["61315.50","0.018"],["61745.70","5.883"],["61746.10","0.007"],["61748.60","0.927"],["61787.20","0.051"],["61787.50","0.030"],["61808.30","1.115"],["61814.50","0.007"],["61828.10","0.001"],["61830.40","0.050"],["61833.10","0.407"],["61835.70","0.569"],["61836.70","0.006"],["61837.60","1.240"],["61841.10","0.405"],["61841.80","0.990"],["61842.20","0.141"],["61845.00","0.009"],["61845.10","0.003"],["61848.10","0.000"],["61850.80","0.000"],["61852.20","16.124"]],"a":[["61852.30","2.293"],["61852.40","0.003"],["61853.20","0.002"],["61854.90","0.022"],["61856.30","1.648"],["61856.40","1.791"],["61856.90","0.001"],["61857.40","0.274"],["61857.60","0.633"],["61858.50","0.540"],["61859.60","0.453"],["61859.70","2.138"],["61860.40","1.785"],["61862.50","0.001"],["61863.20","1.423"],["61863.40","0.033"],["61864.20","0.011"],["61864.70","3.064"],["61864.90","0.054"],["61866.80","3.442"],["61870.90","0.149"],["61878.10","0.002"],["61887.20","0.107"],["61887.70","0.050"],["61887.80","0.286"],["61887.90","0.379"],["61888.00","0.494"],["61888.80","0.055"],["61893.40","0.243"],["61909.30","0.131"],["61909.50","2.715"],["61909.80","0.000"],["61909.90","0.113"],["61923.30","0.096"],["61923.70","0.000"],["61994.00","4.043"],["61994.80","0.831"],["62470.80","0.000"],["89523.20","0.672"]],"st":1}}
{"schema_version":"1.3.0","event_id":"03741e8d-5618-4f5d-80c8-d578adc27652","event_type":"raw.depth_update","source":"binance_market_data_recorder","venue":"binance_usdm","market_type":"perpetual_futures","symbol":"BTCUSDT","event_time_ms":1783517065170,"received_time_ms":1783517065167,"trace_id":"6213d4d4-b047-48a6-9589-310c36c594e2","first_update_id":10999770368096,"final_update_id":10999770379048,"previous_final_update_id":10999770367988,"bids":[{"price":"1000.00","quantity":"207.692"},{"price":"11452.20","quantity":"0.992"},{"price":"11552.20","quantity":"2.208"},{"price":"11652.20","quantity":"1.326"},{"price":"11752.20","quantity":"0.374"},{"price":"55666.90","quantity":"0.003"},{"price":"59378.10","quantity":"0.000"},{"price":"60831.60","quantity":"2.315"},{"price":"60955.30","quantity":"8.029"},{"price":"61233.70","quantity":"0.000"},{"price":"61292.00","quantity":"1.165"},{"price":"61320.00","quantity":"2.053"},{"price":"61542.90","quantity":"0.011"},{"price":"61783.30","quantity":"0.002"},{"price":"61805.00","quantity":"2.114"},{"price":"61807.10","quantity":"0.122"},{"price":"61811.80","quantity":"0.929"},{"price":"61815.40","quantity":"0.105"},{"price":"61815.70","quantity":"0.002"},{"price":"61820.40","quantity":"0.631"},{"price":"61823.40","quantity":"0.181"},{"price":"61823.50","quantity":"0.197"},{"price":"61826.10","quantity":"0.585"},{"price":"61827.10","quantity":"0.001"},{"price":"61827.60","quantity":"0.062"},{"price":"61828.10","quantity":"0.081"},{"price":"61831.60","quantity":"0.968"},{"price":"61832.30","quantity":"0.002"},{"price":"61833.10","quantity":"0.327"},{"price":"61842.20","quantity":"0.061"}],"asks":[{"price":"61853.00","quantity":"0.045"},{"price":"61853.70","quantity":"0.026"},{"price":"61854.10","quantity":"0.126"},{"price":"61856.20","quantity":"0.066"},{"price":"61857.50","quantity":"0.324"},{"price":"61857.80","quantity":"1.156"},{"price":"61859.20","quantity":"0.010"},{"price":"61859.60","quantity":"0.130"},{"price":"61859.80","quantity":"1.210"},{"price":"61860.50","quantity":"0.972"},{"price":"61860.60","quantity":"0.002"},{"price":"61863.00","quantity":"0.053"},{"price":"61863.20","quantity":"0.455"},{"price":"61863.90","quantity":"0.309"},{"price":"61864.10","quantity":"2.329"},{"price":"61864.60","quantity":"0.567"},{"price":"61865.60","quantity":"0.005"},{"price":"61866.80","quantity":"3.427"},{"price":"61883.30","quantity":"0.000"},{"price":"61886.70","quantity":"0.105"},{"price":"61887.20","quantity":"0.107"},{"price":"61898.70","quantity":"0.256"},{"price":"61900.00","quantity":"1.358"},{"price":"61909.40","quantity":"0.371"},{"price":"61909.90","quantity":"0.214"},{"price":"61919.60","quantity":"1.648"},{"price":"61919.70","quantity":"0.000"},{"price":"61925.80","quantity":"0.372"},{"price":"62062.00","quantity":"3.033"},{"price":"62168.00","quantity":"0.004"},{"price":"62470.80","quantity":"0.000"},{"price":"62699.70","quantity":"0.560"},{"price":"62738.60","quantity":"0.000"},{"price":"62801.70","quantity":"0.278"}],"raw":{"e":"depthUpdate","E":1783517065170,"T":1783517065169,"s":"BTCUSDT","ps":"BTCUSDT","U":10999770368096,"u":10999770379048,"pu":10999770367988,"b":[["1000.00","207.692"],["11452.20","0.992"],["11552.20","2.208"],["11652.20","1.326"],["11752.20","0.374"],["55666.90","0.003"],["59378.10","0.000"],["60831.60","2.315"],["60955.30","8.029"],["61233.70","0.000"],["61292.00","1.165"],["61320.00","2.053"],["61542.90","0.011"],["61783.30","0.002"],["61805.00","2.114"],["61807.10","0.122"],["61811.80","0.929"],["61815.40","0.105"],["61815.70","0.002"],["61820.40","0.631"],["61823.40","0.181"],["61823.50","0.197"],["61826.10","0.585"],["61827.10","0.001"],["61827.60","0.062"],["61828.10","0.081"],["61831.60","0.968"],["61832.30","0.002"],["61833.10","0.327"],["61842.20","0.061"]],"a":[["61853.00","0.045"],["61853.70","0.026"],["61854.10","0.126"],["61856.20","0.066"],["61857.50","0.324"],["61857.80","1.156"],["61859.20","0.010"],["61859.60","0.130"],["61859.80","1.210"],["61860.50","0.972"],["61860.60","0.002"],["61863.00","0.053"],["61863.20","0.455"],["61863.90","0.309"],["61864.10","2.329"],["61864.60","0.567"],["61865.60","0.005"],["61866.80","3.427"],["61883.30","0.000"],["61886.70","0.105"],["61887.20","0.107"],["61898.70","0.256"],["61900.00","1.358"],["61909.40","0.371"],["61909.90","0.214"],["61919.60","1.648"],["61919.70","0.000"],["61925.80","0.372"],["62062.00","3.033"],["62168.00","0.004"],["62470.80","0.000"],["62699.70","0.560"],["62738.60","0.000"],["62801.70","0.278"]],"st":1}}
{"schema_version":"1.3.0","event_id":"7cc88822-e775-40eb-ab5d-f2fe96b05229","event_type":"raw.depth_update","source":"binance_market_data_recorder","venue":"binance_usdm","market_type":"perpetual_futures","symbol":"BTCUSDT","event_time_ms":1783517065272,"received_time_ms":1783517065267,"trace_id":"2c2946af-afba-4c0f-9d43-89cd59fb2ce4","first_update_id":10999770379429,"final_update_id":10999770393602,"previous_final_update_id":10999770379048,"bids":[{"price":"1000.00","quantity":"207.692"},{"price":"11452.20","quantity":"1.264"},{"price":"11552.20","quantity":"1.936"},{"price":"11652.20","quantity":"1.462"},{"price":"11752.20","quantity":"0.238"},{"price":"55666.90","quantity":"0.003"},{"price":"58745.80","quantity":"0.033"},{"price":"59378.10","quantity":"0.003"},{"price":"60615.20","quantity":"0.054"},{"price":"61171.80","quantity":"0.737"},{"price":"61233.70","quantity":"0.000"},{"price":"61440.00","quantity":"0.318"},{"price":"61520.00","quantity":"2.901"},{"price":"61600.00","quantity":"56.779"},{"price":"61680.00","quantity":"0.693"},{"price":"61752.40","quantity":"0.012"},{"price":"61754.80","quantity":"1.367"},{"price":"61760.00","quantity":"0.902"},{"price":"61763.70","quantity":"0.000"},{"price":"61828.10","quantity":"0.001"},{"price":"61830.20","quantity":"1.377"},{"price":"61830.40","quantity":"0.130"},{"price":"61831.60","quantity":"0.000"},{"price":"61832.30","quantity":"0.970"},{"price":"61833.80","quantity":"0.000"},{"price":"61839.80","quantity":"0.944"},{"price":"61841.80","quantity":"0.005"},{"price":"61842.00","quantity":"0.911"},{"price":"61842.30","quantity":"0.140"},{"price":"61844.20","quantity":"0.000"},{"price":"61845.00","quantity":"0.009"},{"price":"61845.10","quantity":"0.003"},{"price":"61845.20","quantity":"0.000"},{"price":"61852.20","quantity":"15.999"}],"asks":[{"price":"61852.30","quantity":"2.341"},{"price":"61852.40","quantity":"0.003"},{"price":"61853.40","quantity":"0.006"},{"price":"61854.10","quantity":"0.000"},{"price":"61854.90","quantity":"0.017"},{"price":"61856.20","quantity":"0.171"},{"price":"61857.00","quantity":"0.841"},{"price":"61860.50","quantity":"1.094"},{"price":"61864.10","quantity":"1.361"},{"price":"61864.60","quantity":"0.001"},{"price":"61864.80","quantity":"1.311"},{"price":"61865.60","quantity":"0.571"},{"price":"61909.50","quantity":"2.614"},{"price":"61920.00","quantity":"1.154"},{"price":"61925.80","quantity":"0.275"},{"price":"61950.60","quantity":"1.628"},{"price":"61950.70","quantity":"0.001"},{"price":"62000.00","quantity":"13.005"},{"price":"62080.00","quantity":"0.271"},{"price":"62147.50","quantity":"0.000"},{"price":"62160.00","quantity":"0.266"},{"price":"62240.00","quantity":"0.261"},{"price":"62470.80","quantity":"0.000"},{"price":"62627.50","quantity":"0.335"},{"price":"89523.20","quantity":"0.678"}],"raw":{"e":"depthUpdate","E":1783517065272,"T":1783517065269,"s":"BTCUSDT","ps":"BTCUSDT","U":10999770379429,"u":10999770393602,"pu":10999770379048,"b":[["1000.00","207.692"],["11452.20","1.264"],["11552.20","1.936"],["11652.20","1.462"],["11752.20","0.238"],["55666.90","0.003"],["58745.80","0.033"],["59378.10","0.003"],["60615.20","0.054"],["61171.80","0.737"],["61233.70","0.000"],["61440.00","0.318"],["61520.00","2.901"],["61600.00","56.779"],["61680.00","0.693"],["61752.40","0.012"],["61754.80","1.367"],["61760.00","0.902"],["61763.70","0.000"],["61828.10","0.001"],["61830.20","1.377"],["61830.40","0.130"],["61831.60","0.000"],["61832.30","0.970"],["61833.80","0.000"],["61839.80","0.944"],["61841.80","0.005"],["61842.00","0.911"],["61842.30","0.140"],["61844.20","0.000"],["61845.00","0.009"],["61845.10","0.003"],["61845.20","0.000"],["61852.20","15.999"]],"a":[["61852.30","2.341"],["61852.40","0.003"],["61853.40","0.006"],["61854.10","0.000"],["61854.90","0.017"],["61856.20","0.171"],["61857.00","0.841"],["61860.50","1.094"],["61864.10","1.361"],["61864.60","0.001"],["61864.80","1.311"],["61865.60","0.571"],["61909.50","2.614"],["61920.00","1.154"],["61925.80","0.275"],["61950.60","1.628"],["61950.70","0.001"],["62000.00","13.005"],["62080.00","0.271"],["62147.50","0.000"],["62160.00","0.266"],["62240.00","0.261"],["62470.80","0.000"],["62627.50","0.335"],["89523.20","0.678"]],"st":1}}
{"schema_version":"1.3.0","event_id":"98782152-b43c-4c4c-9bb1-0437309c4066","event_type":"raw.depth_update","source":"binance_market_data_recorder","venue":"binance_usdm","market_type":"perpetual_futures","symbol":"BTCUSDT","event_time_ms":1783517065374,"received_time_ms":1783517065368,"trace_id":"4834e274-3b6f-432c-a579-c739b8207351","first_update_id":10999770393939,"final_update_id":10999770404109,"previous_final_update_id":10999770393602,"bids":[{"price":"11452.20","quantity":"1.536"},{"price":"11552.20","quantity":"1.664"},{"price":"11652.20","quantity":"1.615"},{"price":"11752.20","quantity":"0.085"},{"price":"55666.90","quantity":"0.003"},{"price":"60893.50","quantity":"4.597"},{"price":"60955.30","quantity":"9.176"},{"price":"61042.50","quantity":"1.475"},{"price":"61140.90","quantity":"4.900"},{"price":"61171.80","quantity":"0.982"},{"price":"61233.70","quantity":"0.000"},{"price":"61271.40","quantity":"0.407"},{"price":"61520.00","quantity":"2.919"},{"price":"61600.00","quantity":"56.797"},{"price":"61680.00","quantity":"0.711"},{"price":"61721.80","quantity":"0.273"},{"price":"61760.00","quantity":"0.920"},{"price":"61783.30","quantity":"8.002"},{"price":"61792.90","quantity":"0.017"},{"price":"61805.00","quantity":"6.614"},{"price":"61815.10","quantity":"0.004"},{"price":"61820.40","quantity":"1.425"},{"price":"61823.40","quantity":"0.286"},{"price":"61823.80","quantity":"0.211"},{"price":"61823.90","quantity":"0.000"},{"price":"61824.10","quantity":"0.005"},{"price":"61828.10","quantity":"0.081"},{"price":"61829.60","quantity":"0.039"},{"price":"61830.20","quantity":"1.297"},{"price":"61830.40","quantity":"0.050"},{"price":"61840.00","quantity":"0.076"},{"price":"61841.80","quantity":"0.085"},{"price":"61842.30","quantity":"0.060"},{"price":"61849.80","quantity":"0.002"},{"price":"61852.20","quantity":"15.998"}],"asks":[{"price":"61852.30","quantity":"2.342"},{"price":"61856.20","quantity":"0.172"},{"price":"61862.90","quantity":"0.969"},{"price":"61863.90","quantity":"0.875"},{"price":"61864.80","quantity":"0.343"},{"price":"61865.60","quantity":"0.005"},{"price":"61882.10","quantity":"0.008"},{"price":"61882.90","quantity":"0.826"},{"price":"61898.40","quantity":"5.704"},{"price":"61909.90","quantity":"0.113"},{"price":"61920.00","quantity":"1.172"},{"price":"61920.10","quantity":"8.000"},{"price":"61925.80","quantity":"0.372"},{"price":"61986.60","quantity":"0.735"},{"price":"61986.80","quantity":"0.001"},{"price":"62000.00","quantity":"13.023"},{"price":"62080.00","quantity":"0.289"},{"price":"62160.00","quantity":"0.284"},{"price":"62239.10","quantity":"0.073"},{"price":"62240.00","quantity":"0.279"},{"price":"62470.80","quantity":"0.000"},{"price":"62625.50","quantity":"0.398"},{"price":"62687.30","quantity":"0.477"},{"price":"62911.80","quantity":"0.000"},{"price":"62974.80","quantity":"0.000"}],"raw":{"e":"depthUpdate","E":1783517065374,"T":1783517065373,"s":"BTCUSDT","ps":"BTCUSDT","U":10999770393939,"u":10999770404109,"pu":10999770393602,"b":[["11452.20","1.536"],["11552.20","1.664"],["11652.20","1.615"],["11752.20","0.085"],["55666.90","0.003"],["60893.50","4.597"],["60955.30","9.176"],["61042.50","1.475"],["61140.90","4.900"],["61171.80","0.982"],["61233.70","0.000"],["61271.40","0.407"],["61520.00","2.919"],["61600.00","56.797"],["61680.00","0.711"],["61721.80","0.273"],["61760.00","0.920"],["61783.30","8.002"],["61792.90","0.017"],["61805.00","6.614"],["61815.10","0.004"],["61820.40","1.425"],["61823.40","0.286"],["61823.80","0.211"],["61823.90","0.000"],["61824.10","0.005"],["61828.10","0.081"],["61829.60","0.039"],["61830.20","1.297"],["61830.40","0.050"],["61840.00","0.076"],["61841.80","0.085"],["61842.30","0.060"],["61849.80","0.002"],["61852.20","15.998"]],"a":[["61852.30","2.342"],["61856.20","0.172"],["61862.90","0.969"],["61863.90","0.875"],["61864.80","0.343"],["61865.60","0.005"],["61882.10","0.008"],["61882.90","0.826"],["61898.40","5.704"],["61909.90","0.113"],["61920.00","1.172"],["61920.10","8.000"],["61925.80","0.372"],["61986.60","0.735"],["61986.80","0.001"],["62000.00","13.023"],["62080.00","0.289"],["62160.00","0.284"],["62239.10","0.073"],["62240.00","0.279"],["62470.80","0.000"],["62625.50","0.398"],["62687.30","0.477"],["62911.80","0.000"],["62974.80","0.000"]],"st":1}}
{"schema_version":"1.3.0","event_id":"f723ab1e-2d59-41e0-ac79-de1b1417b5e4","event_type":"raw.depth_update","source":"binance_market_data_recorder","venue":"binance_usdm","market_type":"perpetual_futures","symbol":"BTCUSDT","event_time_ms":1783517065476,"received_time_ms":1783517065471,"trace_id":"0181a97b-e504-46b3-a994-02733b6f64d7","first_update_id":10999770404391,"final_update_id":10999770413869,"previous_final_update_id":10999770404109,"bids":[{"price":"1000.00","quantity":"207.692"},{"price":"11452.20","quantity":"1.808"},{"price":"11552.20","quantity":"1.443"},{"price":"11652.20","quantity":"1.649"},{"price":"11752.20","quantity":"0.000"},{"price":"49482.00","quantity":"0.000"},{"price":"55666.90","quantity":"0.003"},{"price":"58759.70","quantity":"0.000"},{"price":"59378.10","quantity":"0.000"},{"price":"60875.60","quantity":"4.185"},{"price":"60893.50","quantity":"5.745"},{"price":"60937.40","quantity":"10.160"},{"price":"60955.30","quantity":"10.323"},{"price":"61233.70","quantity":"0.000"},{"price":"61260.00","quantity":"0.488"},{"price":"61520.00","quantity":"3.097"},{"price":"61542.90","quantity":"0.011"},{"price":"61600.00","quantity":"56.975"},{"price":"61680.00","quantity":"0.889"},{"price":"61752.40","quantity":"11.012"},{"price":"61754.80","quantity":"2.749"},{"price":"61760.00","quantity":"1.098"},{"price":"61815.30","quantity":"1.274"},{"price":"61823.30","quantity":"2.230"},{"price":"61823.80","quantity":"0.166"},{"price":"61832.00","quantity":"0.429"},{"price":"61834.00","quantity":"4.610"},{"price":"61834.10","quantity":"2.900"},{"price":"61834.20","quantity":"0.163"},{"price":"61840.00","quantity":"0.254"},{"price":"61844.00","quantity":"0.000"},{"price":"61844.90","quantity":"0.163"},{"price":"61849.30","quantity":"0.000"},{"price":"61850.30","quantity":"0.004"},{"price":"61852.20","quantity":"15.998"}],"asks":[{"price":"61852.30","quantity":"2.341"},{"price":"61854.90","quantity":"1.219"},{"price":"61856.20","quantity":"1.374"},{"price":"61857.20","quantity":"0.324"},{"price":"61857.50","quantity":"0.890"},{"price":"61857.60","quantity":"0.067"},{"price":"61858.90","quantity":"0.051"},{"price":"61859.60","quantity":"0.130"},{"price":"61862.90","quantity":"0.001"},{"price":"61863.80","quantity":"0.969"},{"price":"61863.90","quantity":"0.309"},{"price":"61864.60","quantity":"0.001"},{"price":"61865.60","quantity":"0.571"},{"price":"61881.90","quantity":"0.533"},{"price":"61883.40","quantity":"0.395"},{"price":"61891.90","quantity":"0.028"},{"price":"61893.50","quantity":"0.373"},{"price":"61895.60","quantity":"0.408"},{"price":"61908.00","quantity":"0.003"},{"price":"61920.00","quantity":"1.350"},{"price":"61925.80","quantity":"0.372"},{"price":"61951.00","quantity":"11.000"},{"price":"62000.00","quantity":"13.201"},{"price":"62080.00","quantity":"0.467"},{"price":"62160.00","quantity":"0.462"},{"price":"62186.30","quantity":"0.161"},{"price":"62240.00","quantity":"0.457"},{"price":"62470.80","quantity":"0.000"},{"price":"62885.30","quantity":"2.460"},{"price":"63398.60","quantity":"0.079"},{"price":"89523.20","quantity":"0.684"}],"raw":{"e":"depthUpdate","E":1783517065476,"T":1783517065474,"s":"BTCUSDT","ps":"BTCUSDT","U":10999770404391,"u":10999770413869,"pu":10999770404109,"b":[["1000.00","207.692"],["11452.20","1.808"],["11552.20","1.443"],["11652.20","1.649"],["11752.20","0.000"],["49482.00","0.000"],["55666.90","0.003"],["58759.70","0.000"],["59378.10","0.000"],["60875.60","4.185"],["60893.50","5.745"],["60937.40","10.160"],["60955.30","10.323"],["61233.70","0.000"],["61260.00","0.488"],["61520.00","3.097"],["61542.90","0.011"],["61600.00","56.975"],["61680.00","0.889"],["61752.40","11.012"],["61754.80","2.749"],["61760.00","1.098"],["61815.30","1.274"],["61823.30","2.230"],["61823.80","0.166"],["61832.00","0.429"],["61834.00","4.610"],["61834.10","2.900"],["61834.20","0.163"],["61840.00","0.254"],["61844.00","0.000"],["61844.90","0.163"],["61849.30","0.000"],["61850.30","0.004"],["61852.20","15.998"]],"a":[["61852.30","2.341"],["61854.90","1.219"],["61856.20","1.374"],["61857.20","0.324"],["61857.50","0.890"],["61857.60","0.067"],["61858.90","0.051"],["61859.60","0.130"],["61862.90","0.001"],["61863.80","0.969"],["61863.90","0.309"],["61864.60","0.001"],["61865.60","0.571"],["61881.90","0.533"],["61883.40","0.395"],["61891.90","0.028"],["61893.50","0.373"],["61895.60","0.408"],["61908.00","0.003"],["61920.00","1.350"],["61925.80","0.372"],["61951.00","11.000"],["62000.00","13.201"],["62080.00","0.467"],["62160.00","0.462"],["62186.30","0.161"],["62240.00","0.457"],["62470.80","0.000"],["62885.30","2.460"],["63398.60","0.079"],["89523.20","0.684"]],"st":1}}
{"schema_version":"1.3.0","event_id":"4723fe33-968d-4890-89ff-6984ff2cf305","event_type":"raw.depth_update","source":"binance_market_data_recorder","venue":"binance_usdm","market_type":"perpetual_futures","symbol":"BTCUSDT","event_time_ms":1783517065578,"received_time_ms":1783517065575,"trace_id":"cb5b8c8e-9968-4452-bf1c-879f35a32705","first_update_id":10999770414027,"final_update_id":10999770423251,"previous_final_update_id":10999770413869,"bids":[{"price":"1000.00","quantity":"207.692"},{"price":"11452.20","quantity":"2.080"},{"price":"11552.20","quantity":"1.324"},{"price":"11652.20","quantity":"1.496"},{"price":"55666.90","quantity":"0.003"},{"price":"58759.60","quantity":"0.006"},{"price":"58759.70","quantity":"0.003"},{"price":"59378.10","quantity":"0.003"},{"price":"60937.40","quantity":"9.013"},{"price":"61122.90","quantity":"0.003"},{"price":"61233.70","quantity":"0.000"},{"price":"61288.70","quantity":"1.145"},{"price":"61289.90","quantity":"1.796"},{"price":"61762.90","quantity":"1.877"},{"price":"61813.40","quantity":"0.101"},{"price":"61822.00","quantity":"0.001"},{"price":"61822.30","quantity":"0.013"},{"price":"61828.10","quantity":"0.001"},{"price":"61830.40","quantity":"0.130"},{"price":"61832.00","quantity":"0.349"},{"price":"61841.20","quantity":"0.569"},{"price":"61841.80","quantity":"0.005"},{"price":"61841.90","quantity":"0.506"},{"price":"61842.00","quantity":"0.345"},{"price":"61843.70","quantity":"0.326"},{"price":"61844.40","quantity":"0.000"}],"asks":[{"price":"61854.70","quantity":"0.001"},{"price":"61854.80","quantity":"0.000"},{"price":"61856.20","quantity":"1.269"},{"price":"61856.40","quantity":"2.033"},{"price":"61856.80","quantity":"0.001"},{"price":"61858.00","quantity":"0.765"},{"price":"61858.10","quantity":"0.008"},{"price":"61859.80","quantity":"1.208"},{"price":"61862.90","quantity":"0.000"},{"price":"61879.30","quantity":"1.589"},{"price":"61886.50","quantity":"0.027"},{"price":"61886.70","quantity":"0.000"},{"price":"61887.20","quantity":"0.002"},{"price":"61893.40","quantity":"0.036"},{"price":"61893.50","quantity":"0.207"},{"price":"61895.90","quantity":"0.015"},{"price":"61898.20","quantity":"0.265"},{"price":"61908.70","quantity":"0.117"},{"price":"61909.00","quantity":"0.133"},{"price":"61909.20","quantity":"0.176"},{"price":"61909.40","quantity":"0.006"},{"price":"61911.00","quantity":"0.000"},{"price":"61925.80","quantity":"0.275"},{"price":"62161.60","quantity":"0.001"},{"price":"62470.80","quantity":"0.000"},{"price":"62660.00","quantity":"0.811"},{"price":"62903.80","quantity":"3.492"},{"price":"62978.00","quantity":"0.707"}],"raw":{"e":"depthUpdate","E":1783517065578,"T":1783517065577,"s":"BTCUSDT","ps":"BTCUSDT","U":10999770414027,"u":10999770423251,"pu":10999770413869,"b":[["1000.00","207.692"],["11452.20","2.080"],["11552.20","1.324"],["11652.20","1.496"],["55666.90","0.003"],["58759.60","0.006"],["58759.70","0.003"],["59378.10","0.003"],["60937.40","9.013"],["61122.90","0.003"],["61233.70","0.000"],["61288.70","1.145"],["61289.90","1.796"],["61762.90","1.877"],["61813.40","0.101"],["61822.00","0.001"],["61822.30","0.013"],["61828.10","0.001"],["61830.40","0.130"],["61832.00","0.349"],["61841.20","0.569"],["61841.80","0.005"],["61841.90","0.506"],["61842.00","0.345"],["61843.70","0.326"],["61844.40","0.000"]],"a":[["61854.70","0.001"],["61854.80","0.000"],["61856.20","1.269"],["61856.40","2.033"],["61856.80","0.001"],["61858.00","0.765"],["61858.10","0.008"],["61859.80","1.208"],["61862.90","0.000"],["61879.30","1.589"],["61886.50","0.027"],["61886.70","0.000"],["61887.20","0.002"],["61893.40","0.036"],["61893.50","0.207"],["61895.90","0.015"],["61898.20","0.265"],["61908.70","0.117"],["61909.00","0.133"],["61909.20","0.176"],["61909.40","0.006"],["61911.00","0.000"],["61925.80","0.275"],["62161.60","0.001"],["62470.80","0.000"],["62660.00","0.811"],["62903.80","3.492"],["62978.00","0.707"]],"st":1}}
{"schema_version":"1.3.0","event_id":"cced8c27-e2d0-4fc5-a77d-a31c22aa668b","event_type":"raw.depth_update","source":"binance_market_data_recorder","venue":"binance_usdm","market_type":"perpetual_futures","symbol":"BTCUSDT","event_time_ms":1783517065680,"received_time_ms":1783517065674,"trace_id":"f6736f92-00a3-4c9b-8d0a-69b7893d4421","first_update_id":10999770423365,"final_update_id":10999770430032,"previous_final_update_id":10999770423251,"bids":[{"price":"11452.20","quantity":"2.352"},{"price":"11552.20","quantity":"1.188"},{"price":"11652.20","quantity":"1.360"},{"price":"49481.80","quantity":"0.000"},{"price":"55666.90","quantity":"0.003"},{"price":"59378.10","quantity":"0.000"},{"price":"61048.10","quantity":"1.473"},{"price":"61079.00","quantity":"1.097"},{"price":"61233.70","quantity":"0.000"},{"price":"61295.50","quantity":"2.126"},{"price":"61542.90","quantity":"0.012"},{"price":"61721.80","quantity":"0.000"},{"price":"61759.10","quantity":"0.000"},{"price":"61785.90","quantity":"2.043"},{"price":"61812.20","quantity":"1.251"},{"price":"61826.10","quantity":"0.003"},{"price":"61828.10","quantity":"0.583"},{"price":"61835.70","quantity":"0.003"},{"price":"61837.40","quantity":"1.377"},{"price":"61838.60","quantity":"0.387"},{"price":"61841.50","quantity":"0.302"},{"price":"61849.40","quantity":"0.001"}],"asks":[{"price":"61852.30","quantity":"2.342"},{"price":"61853.10","quantity":"0.001"},{"price":"61863.80","quantity":"0.001"},{"price":"61864.60","quantity":"0.969"},{"price":"61869.70","quantity":"0.005"},{"price":"61893.50","quantity":"0.580"},{"price":"61908.00","quantity":"0.158"},{"price":"61909.40","quantity":"0.107"},{"price":"61919.90","quantity":"3.755"},{"price":"61925.80","quantity":"0.275"},{"price":"61986.60","quantity":"0.000"},{"price":"62470.80","quantity":"0.000"},{"price":"62676.70","quantity":"0.401"},{"price":"62999.10","quantity":"0.793"},{"price":"63089.30","quantity":"0.138"},{"price":"89523.20","quantity":"0.690"}],"raw":{"e":"depthUpdate","E":1783517065680,"T":1783517065677,"s":"BTCUSDT","ps":"BTCUSDT","U":10999770423365,"u":10999770430032,"pu":10999770423251,"b":[["11452.20","2.352"],["11552.20","1.188"],["11652.20","1.360"],["49481.80","0.000"],["55666.90","0.003"],["59378.10","0.000"],["61048.10","1.473"],["61079.00","1.097"],["61233.70","0.000"],["61295.50","2.126"],["61542.90","0.012"],["61721.80","0.000"],["61759.10","0.000"],["61785.90","2.043"],["61812.20","1.251"],["61826.10","0.003"],["61828.10","0.583"],["61835.70","0.003"],["61837.40","1.377"],["61838.60","0.387"],["61841.50","0.302"],["61849.40","0.001"]],"a":[["61852.30","2.342"],["61853.10","0.001"],["61863.80","0.001"],["61864.60","0.969"],["61869.70","0.005"],["61893.50","0.580"],["61908.00","0.158"],["61909.40","0.107"],["61919.90","3.755"],["61925.80","0.275"],["61986.60","0.000"],["62470.80","0.000"],["62676.70","0.401"],["62999.10","0.793"],["63089.30","0.138"],["89523.20","0.690"]],"st":1}}
{"schema_version":"1.3.0","event_id":"7e49a288-f20e-4636-9472-bde1775fe340","event_type":"raw.depth_update","source":"binance_market_data_recorder","venue":"binance_usdm","market_type":"perpetual_futures","symbol":"BTCUSDT","event_time_ms":1783517065782,"received_time_ms":1783517065776,"trace_id":"3d7a844a-1752-47c0-ba98-7845d8cf3d83","first_update_id":10999770430314,"final_update_id":10999770437447,"previous_final_update_id":10999770430032,"bids":[{"price":"1000.00","quantity":"207.692"},{"price":"11452.20","quantity":"2.624"},{"price":"11552.20","quantity":"1.069"},{"price":"11652.20","quantity":"1.207"},{"price":"55666.90","quantity":"0.003"},{"price":"59378.10","quantity":"0.003"},{"price":"60893.50","quantity":"6.893"},{"price":"60955.30","quantity":"11.470"},{"price":"61140.90","quantity":"5.880"},{"price":"61233.70","quantity":"0.000"},{"price":"61542.90","quantity":"0.011"},{"price":"61721.80","quantity":"0.278"},{"price":"61813.40","quantity":"0.000"},{"price":"61813.70","quantity":"1.482"},{"price":"61813.80","quantity":"0.115"},{"price":"61815.40","quantity":"0.004"},{"price":"61820.50","quantity":"0.220"},{"price":"61821.00","quantity":"0.357"},{"price":"61827.10","quantity":"0.583"},{"price":"61828.10","quantity":"0.001"},{"price":"61832.50","quantity":"0.084"},{"price":"61835.70","quantity":"0.569"},{"price":"61837.40","quantity":"0.811"},{"price":"61837.90","quantity":"0.761"},{"price":"61843.80","quantity":"0.032"},{"price":"61849.10","quantity":"0.003"}],"asks":[{"price":"61852.30","quantity":"1.370"},{"price":"61852.40","quantity":"0.002"},{"price":"61854.10","quantity":"0.000"},{"price":"61857.20","quantity":"0.000"},{"price":"61857.70","quantity":"0.572"},{"price":"61858.10","quantity":"0.007"},{"price":"61859.80","quantity":"0.007"},{"price":"61909.40","quantity":"0.107"},{"price":"61925.80","quantity":"0.372"},{"price":"61986.50","quantity":"0.736"},{"price":"62161.60","quantity":"0.002"},{"price":"62470.80","quantity":"0.000"},{"price":"62654.50","quantity":"1.276"}],"raw":{"e":"depthUpdate","E":1783517065782,"T":1783517065781,"s":"BTCUSDT","ps":"BTCUSDT","U":10999770430314,"u":10999770437447,"pu":10999770430032,"b":[["1000.00","207.692"],["11452.20","2.624"],["11552.20","1.069"],["11652.20","1.207"],["55666.90","0.003"],["59378.10","0.003"],["60893.50","6.893"],["60955.30","11.470"],["61140.90","5.880"],["61233.70","0.000"],["61542.90","0.011"],["61721.80","0.278"],["61813.40","0.000"],["61813.70","1.482"],["61813.80","0.115"],["61815.40","0.004"],["61820.50","0.220"],["61821.00","0.357"],["61827.10","0.583"],["61828.10","0.001"],["61832.50","0.084"],["61835.70","0.569"],["61837.40","0.811"],["61837.90","0.761"],["61843.80","0.032"],["61849.10","0.003"]],"a":[["61852.30","1.370"],["61852.40","0.002"],["61854.10","0.000"],["61857.20","0.000"],["61857.70","0.572"],["61858.10","0.007"],["61859.80","0.007"],["61909.40","0.107"],["61925.80","0.372"],["61986.50","0.736"],["62161.60","0.002"],["62470.80","0.000"],["62654.50","1.276"]],"st":1}}
{"schema_version":"1.3.0","event_id":"7d41a002-e45d-4dab-835a-cf215beb9ff1","event_type":"raw.depth_update","source":"binance_market_data_recorder","venue":"binance_usdm","market_type":"perpetual_futures","symbol":"BTCUSDT","event_time_ms":1783517065884,"received_time_ms":1783517065878,"trace_id":"f8bcc467-7f3d-4bb9-b056-9645171dded5","first_update_id":10999770437656,"final_update_id":10999770446885,"previous_final_update_id":10999770437447,"bids":[{"price":"1000.00","quantity":"207.692"},{"price":"11352.20","quantity":"0.080"},{"price":"11452.20","quantity":"2.736"},{"price":"11552.20","quantity":"1.013"},{"price":"11652.20","quantity":"1.071"},{"price":"55666.90","quantity":"0.003"},{"price":"60615.20","quantity":"0.045"},{"price":"60955.30","quantity":"12.617"},{"price":"61039.60","quantity":"0.000"},{"price":"61233.70","quantity":"0.000"},{"price":"61300.00","quantity":"78.955"},{"price":"61747.90","quantity":"0.014"},{"price":"61748.00","quantity":"0.157"},{"price":"61765.40","quantity":"0.028"},{"price":"61768.50","quantity":"0.008"},{"price":"61808.30","quantity":"1.119"},{"price":"61813.40","quantity":"0.000"},{"price":"61813.70","quantity":"1.381"},{"price":"61813.80","quantity":"0.014"},{"price":"61813.90","quantity":"0.104"},{"price":"61814.20","quantity":"0.277"},{"price":"61814.50","quantity":"0.003"},{"price":"61815.10","quantity":"0.105"},{"price":"61821.00","quantity":"0.793"},{"price":"61822.30","quantity":"0.007"},{"price":"61823.10","quantity":"0.006"},{"price":"61823.50","quantity":"0.092"},{"price":"61828.40","quantity":"0.016"},{"price":"61832.50","quantity":"0.004"},{"price":"61834.00","quantity":"3.610"},{"price":"61839.80","quantity":"1.048"},{"price":"61841.20","quantity":"0.003"},{"price":"61841.50","quantity":"0.221"},{"price":"61841.70","quantity":"0.021"},{"price":"61842.00","quantity":"0.022"},{"price":"61843.80","quantity":"1.234"},{"price":"61843.90","quantity":"0.889"},{"price":"61846.40","quantity":"0.121"},{"price":"61849.10","quantity":"2.138"},{"price":"61850.30","quantity":"0.053"},{"price":"61851.00","quantity":"0.001"},{"price":"61852.20","quantity":"15.997"}],"asks":[{"price":"61852.30","quantity":"2.037"},{"price":"61852.40","quantity":"0.003"},{"price":"61852.90","quantity":"0.001"},{"price":"61853.30","quantity":"0.507"},{"price":"61853.40","quantity":"0.001"},{"price":"61854.10","quantity":"0.000"},{"price":"61855.00","quantity":"1.956"},{"price":"61855.90","quantity":"0.242"},{"price":"61856.40","quantity":"1.791"},{"price":"61857.10","quantity":"0.002"},{"price":"61857.20","quantity":"0.000"},{"price":"61857.50","quantity":"0.001"},{"price":"61857.60","quantity":"0.051"},{"price":"61858.00","quantity":"0.763"},{"price":"61858.80","quantity":"0.002"},{"price":"61860.40","quantity":"0.496"},{"price":"61860.50","quantity":"0.972"},{"price":"61862.20","quantity":"1.032"},{"price":"61893.40","quantity":"0.243"},{"price":"61925.80","quantity":"0.275"},{"price":"62026.20","quantity":"0.000"},{"price":"62026.30","quantity":"0.003"},{"price":"62142.70","quantity":"0.018"},{"price":"62354.60","quantity":"0.002"},{"price":"62470.80","quantity":"0.002"},{"price":"62569.90","quantity":"3.832"},{"price":"62673.90","quantity":"0.000"},{"price":"62678.10","quantity":"0.279"},{"price":"63089.30","quantity":"0.138"},{"price":"89523.20","quantity":"0.696"}],"raw":{"e":"depthUpdate","E":1783517065884,"T":1783517065883,"s":"BTCUSDT","ps":"BTCUSDT","U":10999770437656,"u":10999770446885,"pu":10999770437447,"b":[["1000.00","207.692"],["11352.20","0.080"],["11452.20","2.736"],["11552.20","1.013"],["11652.20","1.071"],["55666.90","0.003"],["60615.20","0.045"],["60955.30","12.617"],["61039.60","0.000"],["61233.70","0.000"],["61300.00","78.955"],["61747.90","0.014"],["61748.00","0.157"],["61765.40","0.028"],["61768.50","0.008"],["61808.30","1.119"],["61813.40","0.000"],["61813.70","1.381"],["61813.80","0.014"],["61813.90","0.104"],["61814.20","0.277"],["61814.50","0.003"],["61815.10","0.105"],["61821.00","0.793"],["61822.30","0.007"],["61823.10","0.006"],["61823.50","0.092"],["61828.40","0.016"],["61832.50","0.004"],["61834.00","3.610"],["61839.80","1.048"],["61841.20","0.003"],["61841.50","0.221"],["61841.70","0.021"],["61842.00","0.022"],["61843.80","1.234"],["61843.90","0.889"],["61846.40","0.121"],["61849.10","2.138"],["61850.30","0.053"],["61851.00","0.001"],["61852.20","15.997"]],"a":[["61852.30","2.037"],["61852.40","0.003"],["61852.90","0.001"],["61853.30","0.507"],["61853.40","0.001"],["61854.10","0.000"],["61855.00","1.956"],["61855.90","0.242"],["61856.40","1.791"],["61857.10","0.002"],["61857.20","0.000"],["61857.50","0.001"],["61857.60","0.051"],["61858.00","0.763"],["61858.80","0.002"],["61860.40","0.496"],["61860.50","0.972"],["61862.20","1.032"],["61893.40","0.243"],["61925.80","0.275"],["62026.20","0.000"],["62026.30","0.003"],["62142.70","0.018"],["62354.60","0.002"],["62470.80","0.002"],["62569.90","3.832"],["62673.90","0.000"],["62678.10","0.279"],["63089.30","0.138"],["89523.20","0.696"]],"st":1}}
{"schema_version":"1.3.0","event_id":"5bfca7a1-d615-4fbb-951f-980cd7c7e85e","event_type":"raw.depth_update","source":"binance_market_data_recorder","venue":"binance_usdm","market_type":"perpetual_futures","symbol":"BTCUSDT","event_time_ms":1783517065986,"received_time_ms":1783517065980,"trace_id":"33362c70-c4d0-4f9b-8584-027f5124e689","first_update_id":10999770446900,"final_update_id":10999770455075,"previous_final_update_id":10999770446885,"bids":[{"price":"11352.20","quantity":"0.224"},{"price":"11452.20","quantity":"2.720"},{"price":"11552.20","quantity":"1.038"},{"price":"11652.20","quantity":"0.918"},{"price":"49482.00","quantity":"0.000"},{"price":"55666.90","quantity":"0.001"},{"price":"59378.10","quantity":"0.000"},{"price":"61159.80","quantity":"0.000"},{"price":"61233.60","quantity":"6.986"},{"price":"61233.70","quantity":"0.000"},{"price":"61808.30","quantity":"1.115"},{"price":"61813.90","quantity":"0.003"},{"price":"61814.30","quantity":"0.331"},{"price":"61814.50","quantity":"0.007"},{"price":"61823.40","quantity":"0.181"},{"price":"61828.40","quantity":"0.000"},{"price":"61836.00","quantity":"0.144"},{"price":"61841.70","quantity":"0.910"},{"price":"61843.90","quantity":"0.000"},{"price":"61846.40","quantity":"0.041"},{"price":"61852.20","quantity":"15.998"}],"asks":[{"price":"61863.90","quantity":"0.309"},{"price":"61864.60","quantity":"1.535"},{"price":"61865.60","quantity":"0.005"},{"price":"61875.10","quantity":"2.120"},{"price":"61877.00","quantity":"0.166"},{"price":"61925.80","quantity":"0.372"},{"price":"62470.80","quantity":"0.000"},{"price":"62569.90","quantity":"2.874"},{"price":"62656.40","quantity":"2.711"}],"raw":{"e":"depthUpdate","E":1783517065986,"T":1783517065985,"s":"BTCUSDT","ps":"BTCUSDT","U":10999770446900,"u":10999770455075,"pu":10999770446885,"b":[["11352.20","0.224"],["11452.20","2.720"],["11552.20","1.038"],["11652.20","0.918"],["49482.00","0.000"],["55666.90","0.001"],["59378.10","0.000"],["61159.80","0.000"],["61233.60","6.986"],["61233.70","0.000"],["61808.30","1.115"],["61813.90","0.003"],["61814.30","0.331"],["61814.50","0.007"],["61823.40","0.181"],["61828.40","0.000"],["61836.00","0.144"],["61841.70","0.910"],["61843.90","0.000"],["61846.40","0.041"],["61852.20","15.998"]],"a":[["61863.90","0.309"],["61864.60","1.535"],["61865.60","0.005"],["61875.10","2.120"],["61877.00","0.166"],["61925.80","0.372"],["62470.80","0.000"],["62569.90","2.874"],["62656.40","2.711"]],"st":1}}
{"schema_version":"1.3.0","event_id":"99228e02-7db5-4ab0-90b1-5967839185e6","event_type":"raw.depth_update","source":"binance_market_data_recorder","venue":"binance_usdm","market_type":"perpetual_futures","symbol":"BTCUSDT","event_time_ms":1783517066088,"received_time_ms":1783517066084,"trace_id":"dd6c446e-f444-4800-a30c-da1e13703a7f","first_update_id":10999770455079,"final_update_id":10999770464378,"previous_final_update_id":10999770455075,"bids":[{"price":"1000.00","quantity":"207.692"},{"price":"11352.20","quantity":"0.352"},{"price":"11452.20","quantity":"2.736"},{"price":"11552.20","quantity":"1.030"},{"price":"11652.20","quantity":"0.782"},{"price":"55666.90","quantity":"0.003"},{"price":"58759.60","quantity":"0.009"},{"price":"59378.10","quantity":"0.003"},{"price":"61048.10","quantity":"2.618"},{"price":"61079.00","quantity":"1.341"},{"price":"61092.00","quantity":"7.209"},{"price":"61169.90","quantity":"0.736"},{"price":"61233.70","quantity":"0.000"},{"price":"61542.90","quantity":"0.001"},{"price":"61815.30","quantity":"1.173"},{"price":"61831.20","quantity":"0.081"},{"price":"61834.00","quantity":"3.414"},{"price":"61836.00","quantity":"0.064"},{"price":"61841.10","quantity":"0.405"},{"price":"61841.70","quantity":"0.344"},{"price":"61843.90","quantity":"0.566"}],"asks":[{"price":"61852.30","quantity":"2.038"},{"price":"61852.70","quantity":"0.007"},{"price":"61855.50","quantity":"0.245"},{"price":"61855.90","quantity":"0.000"},{"price":"61856.30","quantity":"0.032"},{"price":"61856.40","quantity":"1.069"},{"price":"61858.50","quantity":"0.540"},{"price":"61859.50","quantity":"0.005"},{"price":"61862.10","quantity":"1.617"},{"price":"61863.40","quantity":"0.033"},{"price":"61864.70","quantity":"3.064"},{"price":"61866.80","quantity":"3.443"},{"price":"61870.10","quantity":"0.361"},{"price":"61870.90","quantity":"0.149"},{"price":"61875.10","quantity":"2.118"},{"price":"61876.30","quantity":"0.401"},{"price":"61880.20","quantity":"0.170"},{"price":"61883.20","quantity":"0.005"},{"price":"61925.80","quantity":"0.275"},{"price":"62353.60","quantity":"0.320"},{"price":"62402.80","quantity":"2.719"},{"price":"62452.30","quantity":"1.020"},{"price":"62470.80","quantity":"0.049"},{"price":"62588.30","quantity":"1.916"},{"price":"89523.20","quantity":"0.702"}],"raw":{"e":"depthUpdate","E":1783517066088,"T":1783517066087,"s":"BTCUSDT","ps":"BTCUSDT","U":10999770455079,"u":10999770464378,"pu":10999770455075,"b":[["1000.00","207.692"],["11352.20","0.352"],["11452.20","2.736"],["11552.20","1.030"],["11652.20","0.782"],["55666.90","0.003"],["58759.60","0.009"],["59378.10","0.003"],["61048.10","2.618"],["61079.00","1.341"],["61092.00","7.209"],["61169.90","0.736"],["61233.70","0.000"],["61542.90","0.001"],["61815.30","1.173"],["61831.20","0.081"],["61834.00","3.414"],["61836.00","0.064"],["61841.10","0.405"],["61841.70","0.344"],["61843.90","0.566"]],"a":[["61852.30","2.038"],["61852.70","0.007"],["61855.50","0.245"],["61855.90","0.000"],["61856.30","0.032"],["61856.40","1.069"],["61858.50","0.540"],["61859.50","0.005"],["61862.10","1.617"],["61863.40","0.033"],["61864.70","3.064"],["61866.80","3.443"],["61870.10","0.361"],["61870.90","0.149"],["61875.10","2.118"],["61876.30","0.401"],["61880.20","0.170"],["61883.20","0.005"],["61925.80","0.275"],["62353.60","0.320"],["62402.80","2.719"],["62452.30","1.020"],["62470.80","0.049"],["62588.30","1.916"],["89523.20","0.702"]],"st":1}}
{"schema_version":"1.3.0","event_id":"471c31e6-5b22-4b72-9b89-b765fadb485f","event_type":"raw.depth_update","source":"binance_market_data_recorder","venue":"binance_usdm","market_type":"perpetual_futures","symbol":"BTCUSDT","event_time_ms":1783517066190,"received_time_ms":1783517066664,"trace_id":"a90fead4-9d8f-4c2b-af70-f1a139fcab05","first_update_id":10999770464446,"final_update_id":10999770489945,"previous_final_update_id":10999770464378,"bids":[{"price":"1000.00","quantity":"207.692"},{"price":"11352.20","quantity":"0.464"},{"price":"11353.20","quantity":"0.032"},{"price":"11353.70","quantity":"0.016"},{"price":"11452.20","quantity":"2.688"},{"price":"11552.20","quantity":"1.054"},{"price":"11553.70","quantity":"0.017"},{"price":"11652.20","quantity":"0.629"},{"price":"49482.00","quantity":"0.000"},{"price":"55666.90","quantity":"0.001"},{"price":"55668.30","quantity":"0.002"},{"price":"59378.10","quantity":"0.000"},{"price":"60615.20","quantity":"0.036"},{"price":"60616.70","quantity":"0.005"},{"price":"60845.70","quantity":"0.703"},{"price":"60846.40","quantity":"0.003"},{"price":"60848.70","quantity":"0.012"},{"price":"60853.20","quantity":"0.019"},{"price":"60853.70","quantity":"0.716"},{"price":"61233.70","quantity":"0.000"},{"price":"61234.70","quantity":"2.283"},{"price":"61235.20","quantity":"0.029"},{"price":"61604.80","quantity":"0.041"},{"price":"61607.30","quantity":"0.280"},{"price":"61673.70","quantity":"4.069"},{"price":"61674.20","quantity":"2.184"},{"price":"61704.50","quantity":"8.110"},{"price":"61705.10","quantity":"1.887"},{"price":"61732.00","quantity":"0.148"},{"price":"61735.40","quantity":"8.106"},{"price":"61735.80","quantity":"2.767"},{"price":"61741.50","quantity":"0.408"},{"price":"61744.30","quantity":"0.048"},{"price":"61744.90","quantity":"0.022"},{"price":"61746.90","quantity":"1.975"},{"price":"61748.00","quantity":"0.154"},{"price":"61748.10","quantity":"0.009"},{"price":"61750.80","quantity":"4.082"},{"price":"61751.00","quantity":"0.204"},{"price":"61757.20","quantity":"0.000"},{"price":"61757.30","quantity":"0.792"},{"price":"61763.20","quantity":"34.234"},{"price":"61763.60","quantity":"0.153"},{"price":"61764.00","quantity":"6.492"},{"price":"61765.30","quantity":"0.072"},{"price":"61766.30","quantity":"2.028"},{"price":"61768.10","quantity":"0.004"},{"price":"61768.50","quantity":"0.000"},{"price":"61770.10","quantity":"0.010"},{"price":"61771.20","quantity":"0.093"},{"price":"61771.70","quantity":"0.570"},{"price":"61774.50","quantity":"0.011"},{"price":"61786.30","quantity":"0.000"},{"price":"61786.50","quantity":"0.022"},{"price":"61789.00","quantity":"1.482"},{"price":"61790.40","quantity":"0.016"},{"price":"61791.20","quantity":"0.002"},{"price":"61793.20","quantity":"0.001"},{"price":"61795.80","quantity":"0.001"},{"price":"61797.80","quantity":"0.008"},{"price":"61799.70","quantity":"0.002"},{"price":"61800.60","quantity":"0.238"},{"price":"61800.70","quantity":"0.004"},{"price":"61802.60","quantity":"0.681"},{"price":"61802.90","quantity":"0.864"},{"price":"61803.00","quantity":"0.034"},{"price":"61803.90","quantity":"0.408"},{"price":"61804.50","quantity":"0.119"},{"price":"61804.60","quantity":"0.000"},{"price":"61805.00","quantity":"6.614"},{"price":"61805.20","quantity":"0.018"},{"price":"61806.00","quantity":"0.046"},{"price":"61808.00","quantity":"0.031"},{"price":"61808.60","quantity":"0.018"},{"price":"61809.20","quantity":"0.001"},{"price":"61810.00","quantity":"1.785"},{"price":"61810.20","quantity":"0.080"},{"price":"61810.80","quantity":"0.007"},{"price":"61812.70","quantity":"0.110"},{"price":"61813.00","quantity":"0.001"},{"price":"61813.60","quantity":"0.105"},{"price":"61814.00","quantity":"0.008"},{"price":"61814.10","quantity":"0.569"},{"price":"61814.20","quantity":"0.176"},{"price":"61814.30","quantity":"0.230"},{"price":"61814.50","quantity":"0.032"},{"price":"61814.90","quantity":"0.005"},{"price":"61815.00","quantity":"1.415"},{"price":"61815.10","quantity":"0.004"},{"price":"61815.40","quantity":"0.004"},{"price":"61815.50","quantity":"0.003"},{"price":"61815.70","quantity":"0.002"},{"price":"61817.80","quantity":"0.000"},{"price":"61818.10","quantity":"0.152"},{"price":"61818.30","quantity":"0.003"},{"price":"61819.10","quantity":"0.190"},{"price":"61819.90","quantity":"0.001"},{"price":"61820.10","quantity":"10.764"},{"price":"61820.40","quantity":"1.415"},{"price":"61820.50","quantity":"0.220"},{"price":"61820.70","quantity":"0.667"},{"price":"61820.80","quantity":"0.050"},{"price":"61821.00","quantity":"0.818"},{"price":"61821.20","quantity":"0.005"},{"price":"61821.40","quantity":"0.004"},{"price":"61821.60","quantity":"0.007"},{"price":"61821.80","quantity":"0.657"},{"price":"61822.00","quantity":"0.001"},{"price":"61822.20","quantity":"1.013"},{"price":"61822.30","quantity":"0.158"},{"price":"61822.70","quantity":"0.026"},{"price":"61822.90","quantity":"0.003"},{"price":"61823.10","quantity":"0.000"},{"price":"61823.30","quantity":"2.141"},{"price":"61823.40","quantity":"0.092"},{"price":"61823.50","quantity":"0.003"},{"price":"61823.80","quantity":"0.069"},{"price":"61823.90","quantity":"0.000"},{"price":"61824.20","quantity":"0.010"},{"price":"61824.30","quantity":"0.003"},{"price":"61825.10","quantity":"0.166"},{"price":"61825.40","quantity":"0.874"},{"price":"61825.70","quantity":"0.012"},{"price":"61825.90","quantity":"1.313"},{"price":"61826.00","quantity":"2.142"},{"price":"61826.50","quantity":"0.869"},{"price":"61826.70","quantity":"0.631"},{"price":"61826.90","quantity":"0.052"},{"price":"61827.10","quantity":"0.588"},{"price":"61827.60","quantity":"0.062"},{"price":"61827.90","quantity":"0.002"},{"price":"61828.20","quantity":"0.017"},{"price":"61828.30","quantity":"0.001"},{"price":"61828.50","quantity":"0.508"},{"price":"61828.70","quantity":"0.132"},{"price":"61828.90","quantity":"1.100"},{"price":"61829.00","quantity":"0.294"},{"price":"61829.30","quantity":"0.048"},{"price":"61829.40","quantity":"1.821"},{"price":"61829.70","quantity":"0.003"},{"price":"61830.00","quantity":"0.006"},{"price":"61830.40","quantity":"0.251"},{"price":"61830.50","quantity":"0.001"},{"price":"61830.60","quantity":"0.001"},{"price":"61830.70","quantity":"0.002"},{"price":"61830.90","quantity":"0.000"},{"price":"61831.20","quantity":"0.036"},{"price":"61831.40","quantity":"0.331"},{"price":"61831.60","quantity":"0.002"},{"price":"61831.80","quantity":"0.002"},{"price":"61832.40","quantity":"0.007"},{"price":"61832.50","quantity":"0.012"},{"price":"61832.60","quantity":"0.005"},{"price":"61833.70","quantity":"0.003"},{"price":"61834.20","quantity":"0.252"},{"price":"61834.30","quantity":"0.669"},{"price":"61834.50","quantity":"0.285"},{"price":"61834.60","quantity":"0.138"},{"price":"61834.90","quantity":"0.013"},{"price":"61835.20","quantity":"0.002"},{"price":"61835.40","quantity":"0.090"},{"price":"61835.60","quantity":"0.188"},{"price":"61835.70","quantity":"0.003"},{"price":"61835.80","quantity":"0.003"},{"price":"61836.20","quantity":"0.022"},{"price":"61836.50","quantity":"0.023"},{"price":"61836.60","quantity":"1.227"},{"price":"61837.40","quantity":"1.377"},{"price":"61837.50","quantity":"0.908"},{"price":"61837.60","quantity":"2.329"},{"price":"61837.70","quantity":"0.422"},{"price":"61838.20","quantity":"0.002"},{"price":"61838.50","quantity":"0.015"},{"price":"61838.70","quantity":"1.977"},{"price":"61839.00","quantity":"0.004"},{"price":"61839.10","quantity":"0.000"},{"price":"61839.70","quantity":"0.082"},{"price":"61839.80","quantity":"0.394"},{"price":"61840.20","quantity":"0.001"},{"price":"61840.50","quantity":"2.136"},{"price":"61840.70","quantity":"0.001"},{"price":"61840.80","quantity":"0.011"},{"price":"61841.50","quantity":"0.003"},{"price":"61841.70","quantity":"0.021"},{"price":"61842.00","quantity":"0.006"},{"price":"61843.20","quantity":"0.004"},{"price":"61843.30","quantity":"0.165"},{"price":"61843.40","quantity":"0.006"},{"price":"61843.50","quantity":"0.034"},{"price":"61843.70","quantity":"0.003"},{"price":"61843.80","quantity":"0.032"},{"price":"61843.90","quantity":"0.000"},{"price":"61844.00","quantity":"1.289"},{"price":"61844.10","quantity":"0.016"},{"price":"61844.20","quantity":"0.001"},{"price":"61844.40","quantity":"0.323"},{"price":"61844.90","quantity":"0.163"},{"price":"61845.00","quantity":"0.009"},{"price":"61845.70","quantity":"0.000"},{"price":"61845.80","quantity":"0.004"},{"price":"61846.40","quantity":"0.121"},{"price":"61846.60","quantity":"0.001"},{"price":"61846.80","quantity":"0.564"},{"price":"61846.90","quantity":"0.469"},{"price":"61847.00","quantity":"0.180"},{"price":"61847.40","quantity":"0.002"},{"price":"61847.50","quantity":"0.001"},{"price":"61847.60","quantity":"0.004"},{"price":"61847.90","quantity":"0.000"},{"price":"61848.00","quantity":"0.006"},{"price":"61848.40","quantity":"0.250"},{"price":"61848.90","quantity":"0.003"},{"price":"61849.10","quantity":"2.140"},{"price":"61849.20","quantity":"0.523"},{"price":"61849.60","quantity":"0.072"},{"price":"61849.70","quantity":"0.002"},{"price":"61849.80","quantity":"0.001"},{"price":"61850.70","quantity":"0.448"},{"price":"61851.30","quantity":"0.002"},{"price":"61851.50","quantity":"0.000"},{"price":"61851.60","quantity":"0.069"},{"price":"61851.90","quantity":"0.001"},{"price":"61852.00","quantity":"1.001"},{"price":"61852.10","quantity":"0.007"},{"price":"61852.20","quantity":"0.951"},{"price":"61852.30","quantity":"2.368"},{"price":"61852.40","quantity":"0.000"},{"price":"61852.50","quantity":"0.001"},{"price":"61852.60","quantity":"0.000"},{"price":"61852.70","quantity":"0.000"},{"price":"61852.80","quantity":"0.293"},{"price":"61852.90","quantity":"0.002"},{"price":"61853.00","quantity":"0.000"},{"price":"61853.10","quantity":"0.000"},{"price":"61853.20","quantity":"2.223"},{"price":"61853.30","quantity":"1.802"},{"price":"61853.40","quantity":"2.540"},{"price":"61853.50","quantity":"0.000"},{"price":"61853.60","quantity":"0.002"},{"price":"61853.70","quantity":"17.829"}],"asks":[{"price":"61852.30","quantity":"0.000"},{"price":"61852.40","quantity":"0.000"},{"price":"61852.50","quantity":"0.000"},{"price":"61852.70","quantity":"0.000"},{"price":"61852.80","quantity":"0.000"},{"price":"61852.90","quantity":"0.000"},{"price":"61853.00","quantity":"0.000"},{"price":"61853.10","quantity":"0.000"},{"price":"61853.20","quantity":"0.000"},{"price":"61853.30","quantity":"0.000"},{"price":"61853.40","quantity":"0.000"},{"price":"61853.60","quantity":"0.000"},{"price":"61853.70","quantity":"0.000"},{"price":"61853.80","quantity":"1.598"},{"price":"61853.90","quantity":"0.007"},{"price":"61854.00","quantity":"0.024"},{"price":"61854.20","quantity":"0.013"},{"price":"61854.60","quantity":"0.004"},{"price":"61854.90","quantity":"0.016"},{"price":"61855.40","quantity":"0.001"},{"price":"61855.50","quantity":"0.003"},{"price":"61855.70","quantity":"0.000"},{"price":"61855.80","quantity":"0.007"},{"price":"61856.00","quantity":"0.003"},{"price":"61856.10","quantity":"0.001"},{"price":"61856.20","quantity":"0.002"},{"price":"61856.30","quantity":"0.030"},{"price":"61856.40","quantity":"0.069"},{"price":"61856.50","quantity":"0.000"},{"price":"61856.60","quantity":"0.163"},{"price":"61856.70","quantity":"0.014"},{"price":"61857.10","quantity":"0.001"},{"price":"61857.40","quantity":"1.274"},{"price":"61857.60","quantity":"0.269"},{"price":"61857.70","quantity":"0.178"},{"price":"61857.80","quantity":"0.390"},{"price":"61858.10","quantity":"0.088"},{"price":"61858.20","quantity":"0.128"},{"price":"61858.50","quantity":"0.538"},{"price":"61858.80","quantity":"0.000"},{"price":"61859.00","quantity":"0.104"},{"price":"61859.40","quantity":"0.002"},{"price":"61859.70","quantity":"0.003"},{"price":"61859.80","quantity":"0.002"},{"price":"61859.90","quantity":"0.002"},{"price":"61860.00","quantity":"0.048"},{"price":"61860.40","quantity":"0.016"},{"price":"61860.50","quantity":"0.971"},{"price":"61860.60","quantity":"0.002"},{"price":"61860.70","quantity":"0.127"},{"price":"61861.20","quantity":"0.008"},{"price":"61861.30","quantity":"0.045"},{"price":"61861.90","quantity":"0.004"},{"price":"61862.00","quantity":"0.439"},{"price":"61862.10","quantity":"0.001"},{"price":"61862.20","quantity":"1.024"},{"price":"61862.30","quantity":"0.004"},{"price":"61862.40","quantity":"0.377"},{"price":"61862.60","quantity":"1.623"},{"price":"61862.80","quantity":"0.345"},{"price":"61863.30","quantity":"0.199"},{"price":"61863.60","quantity":"1.029"},{"price":"61864.00","quantity":"2.153"},{"price":"61864.20","quantity":"0.009"},{"price":"61864.60","quantity":"0.969"},{"price":"61865.60","quantity":"0.570"},{"price":"61865.80","quantity":"0.002"},{"price":"61866.10","quantity":"0.000"},{"price":"61866.20","quantity":"0.564"},{"price":"61866.80","quantity":"3.427"},{"price":"61867.10","quantity":"0.582"},{"price":"61867.20","quantity":"0.377"},{"price":"61867.40","quantity":"0.067"},{"price":"61868.30","quantity":"0.009"},{"price":"61868.50","quantity":"0.753"},{"price":"61868.60","quantity":"0.002"},{"price":"61869.90","quantity":"1.831"},{"price":"61870.10","quantity":"0.315"},{"price":"61870.20","quantity":"0.012"},{"price":"61870.60","quantity":"0.033"},{"price":"61871.20","quantity":"0.025"},{"price":"61871.30","quantity":"0.159"},{"price":"61871.90","quantity":"0.366"},{"price":"61872.10","quantity":"0.132"},{"price":"61872.20","quantity":"0.132"},{"price":"61872.30","quantity":"0.025"},{"price":"61873.00","quantity":"2.056"},{"price":"61873.70","quantity":"0.005"},{"price":"61873.80","quantity":"1.292"},{"price":"61873.90","quantity":"2.355"},{"price":"61874.90","quantity":"0.157"},{"price":"61875.00","quantity":"0.150"},{"price":"61875.10","quantity":"2.228"},{"price":"61875.70","quantity":"3.678"},{"price":"61876.30","quantity":"0.399"},{"price":"61877.00","quantity":"0.156"},{"price":"61877.40","quantity":"0.269"},{"price":"61877.60","quantity":"0.001"},{"price":"61877.70","quantity":"0.006"},{"price":"61878.10","quantity":"0.014"},{"price":"61878.50","quantity":"0.004"},{"price":"61878.60","quantity":"0.317"},{"price":"61878.70","quantity":"0.071"},{"price":"61878.80","quantity":"0.001"},{"price":"61879.60","quantity":"0.049"},{"price":"61880.00","quantity":"0.013"},{"price":"61880.30","quantity":"0.887"},{"price":"61880.50","quantity":"0.135"},{"price":"61880.60","quantity":"0.408"},{"price":"61881.10","quantity":"0.002"},{"price":"61881.40","quantity":"0.251"},{"price":"61881.70","quantity":"0.008"},{"price":"61882.30","quantity":"0.000"},{"price":"61882.60","quantity":"0.024"},{"price":"61883.40","quantity":"0.325"},{"price":"61883.90","quantity":"0.020"},{"price":"61885.00","quantity":"0.058"},{"price":"61885.10","quantity":"0.121"},{"price":"61885.60","quantity":"2.010"},{"price":"61886.40","quantity":"0.006"},{"price":"61886.90","quantity":"0.050"},{"price":"61887.10","quantity":"0.080"},{"price":"61888.10","quantity":"0.099"},{"price":"61888.70","quantity":"0.002"},{"price":"61889.30","quantity":"0.000"},{"price":"61889.40","quantity":"0.018"},{"price":"61889.70","quantity":"0.052"},{"price":"61889.80","quantity":"0.191"},{"price":"61889.90","quantity":"0.013"},{"price":"61890.40","quantity":"1.366"},{"price":"61890.60","quantity":"0.031"},{"price":"61892.10","quantity":"0.016"},{"price":"61892.30","quantity":"1.258"},{"price":"61892.40","quantity":"0.000"},{"price":"61892.50","quantity":"0.020"},{"price":"61892.90","quantity":"0.012"},{"price":"61893.50","quantity":"0.595"},{"price":"61894.30","quantity":"0.001"},{"price":"61895.60","quantity":"0.408"},{"price":"61895.80","quantity":"0.157"},{"price":"61896.30","quantity":"0.123"},{"price":"61896.40","quantity":"1.172"},{"price":"61896.50","quantity":"0.002"},{"price":"61896.60","quantity":"0.156"},{"price":"61896.70","quantity":"2.162"},{"price":"61897.20","quantity":"0.013"},{"price":"61897.30","quantity":"0.004"},{"price":"61897.60","quantity":"0.004"},{"price":"61897.70","quantity":"0.015"},{"price":"61897.90","quantity":"0.131"},{"price":"61898.00","quantity":"0.003"},{"price":"61898.10","quantity":"0.002"},{"price":"61898.20","quantity":"0.374"},{"price":"61898.30","quantity":"3.290"},{"price":"61898.40","quantity":"5.706"},{"price":"61898.70","quantity":"0.098"},{"price":"61898.90","quantity":"0.008"},{"price":"61900.70","quantity":"0.000"},{"price":"61901.10","quantity":"0.038"},{"price":"61901.20","quantity":"0.000"},{"price":"61901.60","quantity":"0.033"},{"price":"61903.00","quantity":"0.002"},{"price":"61903.40","quantity":"0.016"},{"price":"61903.90","quantity":"3.653"},{"price":"61904.00","quantity":"0.003"},{"price":"61904.30","quantity":"0.016"},{"price":"61904.80","quantity":"0.388"},{"price":"61906.20","quantity":"0.003"},{"price":"61906.70","quantity":"0.010"},{"price":"61908.70","quantity":"0.016"},{"price":"61909.90","quantity":"0.217"},{"price":"61910.10","quantity":"0.012"},{"price":"61910.50","quantity":"0.023"},{"price":"61910.60","quantity":"0.022"},{"price":"61910.70","quantity":"0.018"},{"price":"61920.80","quantity":"0.324"},{"price":"61950.60","quantity":"3.063"},{"price":"61953.70","quantity":"0.264"},{"price":"61964.60","quantity":"0.027"},{"price":"62026.30","quantity":"0.000"},{"price":"62026.40","quantity":"0.794"},{"price":"62137.80","quantity":"0.246"},{"price":"62138.30","quantity":"0.262"},{"price":"62142.70","quantity":"0.000"},{"price":"62212.70","quantity":"0.006"},{"price":"62470.80","quantity":"0.000"},{"price":"62471.80","quantity":"0.686"},{"price":"62472.30","quantity":"0.002"},{"price":"62677.30","quantity":"0.279"},{"price":"63089.30","quantity":"0.138"}],"raw":{"e":"depthUpdate","E":1783517066190,"T":1783517066189,"s":"BTCUSDT","ps":"BTCUSDT","U":10999770464446,"u":10999770489945,"pu":10999770464378,"b":[["1000.00","207.692"],["11352.20","0.464"],["11353.20","0.032"],["11353.70","0.016"],["11452.20","2.688"],["11552.20","1.054"],["11553.70","0.017"],["11652.20","0.629"],["49482.00","0.000"],["55666.90","0.001"],["55668.30","0.002"],["59378.10","0.000"],["60615.20","0.036"],["60616.70","0.005"],["60845.70","0.703"],["60846.40","0.003"],["60848.70","0.012"],["60853.20","0.019"],["60853.70","0.716"],["61233.70","0.000"],["61234.70","2.283"],["61235.20","0.029"],["61604.80","0.041"],["61607.30","0.280"],["61673.70","4.069"],["61674.20","2.184"],["61704.50","8.110"],["61705.10","1.887"],["61732.00","0.148"],["61735.40","8.106"],["61735.80","2.767"],["61741.50","0.408"],["61744.30","0.048"],["61744.90","0.022"],["61746.90","1.975"],["61748.00","0.154"],["61748.10","0.009"],["61750.80","4.082"],["61751.00","0.204"],["61757.20","0.000"],["61757.30","0.792"],["61763.20","34.234"],["61763.60","0.153"],["61764.00","6.492"],["61765.30","0.072"],["61766.30","2.028"],["61768.10","0.004"],["61768.50","0.000"],["61770.10","0.010"],["61771.20","0.093"],["61771.70","0.570"],["61774.50","0.011"],["61786.30","0.000"],["61786.50","0.022"],["61789.00","1.482"],["61790.40","0.016"],["61791.20","0.002"],["61793.20","0.001"],["61795.80","0.001"],["61797.80","0.008"],["61799.70","0.002"],["61800.60","0.238"],["61800.70","0.004"],["61802.60","0.681"],["61802.90","0.864"],["61803.00","0.034"],["61803.90","0.408"],["61804.50","0.119"],["61804.60","0.000"],["61805.00","6.614"],["61805.20","0.018"],["61806.00","0.046"],["61808.00","0.031"],["61808.60","0.018"],["61809.20","0.001"],["61810.00","1.785"],["61810.20","0.080"],["61810.80","0.007"],["61812.70","0.110"],["61813.00","0.001"],["61813.60","0.105"],["61814.00","0.008"],["61814.10","0.569"],["61814.20","0.176"],["61814.30","0.230"],["61814.50","0.032"],["61814.90","0.005"],["61815.00","1.415"],["61815.10","0.004"],["61815.40","0.004"],["61815.50","0.003"],["61815.70","0.002"],["61817.80","0.000"],["61818.10","0.152"],["61818.30","0.003"],["61819.10","0.190"],["61819.90","0.001"],["61820.10","10.764"],["61820.40","1.415"],["61820.50","0.220"],["61820.70","0.667"],["61820.80","0.050"],["61821.00","0.818"],["61821.20","0.005"],["61821.40","0.004"],["61821.60","0.007"],["61821.80","0.657"],["61822.00","0.001"],["61822.20","1.013"],["61822.30","0.158"],["61822.70","0.026"],["61822.90","0.003"],["61823.10","0.000"],["61823.30","2.141"],["61823.40","0.092"],["61823.50","0.003"],["61823.80","0.069"],["61823.90","0.000"],["61824.20","0.010"],["61824.30","0.003"],["61825.10","0.166"],["61825.40","0.874"],["61825.70","0.012"],["61825.90","1.313"],["61826.00","2.142"],["61826.50","0.869"],["61826.70","0.631"],["61826.90","0.052"],["61827.10","0.588"],["61827.60","0.062"],["61827.90","0.002"],["61828.20","0.017"],["61828.30","0.001"],["61828.50","0.508"],["61828.70","0.132"],["61828.90","1.100"],["61829.00","0.294"],["61829.30","0.048"],["61829.40","1.821"],["61829.70","0.003"],["61830.00","0.006"],["61830.40","0.251"],["61830.50","0.001"],["61830.60","0.001"],["61830.70","0.002"],["61830.90","0.000"],["61831.20","0.036"],["61831.40","0.331"],["61831.60","0.002"],["61831.80","0.002"],["61832.40","0.007"],["61832.50","0.012"],["61832.60","0.005"],["61833.70","0.003"],["61834.20","0.252"],["61834.30","0.669"],["61834.50","0.285"],["61834.60","0.138"],["61834.90","0.013"],["61835.20","0.002"],["61835.40","0.090"],["61835.60","0.188"],["61835.70","0.003"],["61835.80","0.003"],["61836.20","0.022"],["61836.50","0.023"],["61836.60","1.227"],["61837.40","1.377"],["61837.50","0.908"],["61837.60","2.329"],["61837.70","0.422"],["61838.20","0.002"],["61838.50","0.015"],["61838.70","1.977"],["61839.00","0.004"],["61839.10","0.000"],["61839.70","0.082"],["61839.80","0.394"],["61840.20","0.001"],["61840.50","2.136"],["61840.70","0.001"],["61840.80","0.011"],["61841.50","0.003"],["61841.70","0.021"],["61842.00","0.006"],["61843.20","0.004"],["61843.30","0.165"],["61843.40","0.006"],["61843.50","0.034"],["61843.70","0.003"],["61843.80","0.032"],["61843.90","0.000"],["61844.00","1.289"],["61844.10","0.016"],["61844.20","0.001"],["61844.40","0.323"],["61844.90","0.163"],["61845.00","0.009"],["61845.70","0.000"],["61845.80","0.004"],["61846.40","0.121"],["61846.60","0.001"],["61846.80","0.564"],["61846.90","0.469"],["61847.00","0.180"],["61847.40","0.002"],["61847.50","0.001"],["61847.60","0.004"],["61847.90","0.000"],["61848.00","0.006"],["61848.40","0.250"],["61848.90","0.003"],["61849.10","2.140"],["61849.20","0.523"],["61849.60","0.072"],["61849.70","0.002"],["61849.80","0.001"],["61850.70","0.448"],["61851.30","0.002"],["61851.50","0.000"],["61851.60","0.069"],["61851.90","0.001"],["61852.00","1.001"],["61852.10","0.007"],["61852.20","0.951"],["61852.30","2.368"],["61852.40","0.000"],["61852.50","0.001"],["61852.60","0.000"],["61852.70","0.000"],["61852.80","0.293"],["61852.90","0.002"],["61853.00","0.000"],["61853.10","0.000"],["61853.20","2.223"],["61853.30","1.802"],["61853.40","2.540"],["61853.50","0.000"],["61853.60","0.002"],["61853.70","17.829"]],"a":[["61852.30","0.000"],["61852.40","0.000"],["61852.50","0.000"],["61852.70","0.000"],["61852.80","0.000"],["61852.90","0.000"],["61853.00","0.000"],["61853.10","0.000"],["61853.20","0.000"],["61853.30","0.000"],["61853.40","0.000"],["61853.60","0.000"],["61853.70","0.000"],["61853.80","1.598"],["61853.90","0.007"],["61854.00","0.024"],["61854.20","0.013"],["61854.60","0.004"],["61854.90","0.016"],["61855.40","0.001"],["61855.50","0.003"],["61855.70","0.000"],["61855.80","0.007"],["61856.00","0.003"],["61856.10","0.001"],["61856.20","0.002"],["61856.30","0.030"],["61856.40","0.069"],["61856.50","0.000"],["61856.60","0.163"],["61856.70","0.014"],["61857.10","0.001"],["61857.40","1.274"],["61857.60","0.269"],["61857.70","0.178"],["61857.80","0.390"],["61858.10","0.088"],["61858.20","0.128"],["61858.50","0.538"],["61858.80","0.000"],["61859.00","0.104"],["61859.40","0.002"],["61859.70","0.003"],["61859.80","0.002"],["61859.90","0.002"],["61860.00","0.048"],["61860.40","0.016"],["61860.50","0.971"],["61860.60","0.002"],["61860.70","0.127"],["61861.20","0.008"],["61861.30","0.045"],["61861.90","0.004"],["61862.00","0.439"],["61862.10","0.001"],["61862.20","1.024"],["61862.30","0.004"],["61862.40","0.377"],["61862.60","1.623"],["61862.80","0.345"],["61863.30","0.199"],["61863.60","1.029"],["61864.00","2.153"],["61864.20","0.009"],["61864.60","0.969"],["61865.60","0.570"],["61865.80","0.002"],["61866.10","0.000"],["61866.20","0.564"],["61866.80","3.427"],["61867.10","0.582"],["61867.20","0.377"],["61867.40","0.067"],["61868.30","0.009"],["61868.50","0.753"],["61868.60","0.002"],["61869.90","1.831"],["61870.10","0.315"],["61870.20","0.012"],["61870.60","0.033"],["61871.20","0.025"],["61871.30","0.159"],["61871.90","0.366"],["61872.10","0.132"],["61872.20","0.132"],["61872.30","0.025"],["61873.00","2.056"],["61873.70","0.005"],["61873.80","1.292"],["61873.90","2.355"],["61874.90","0.157"],["61875.00","0.150"],["61875.10","2.228"],["61875.70","3.678"],["61876.30","0.399"],["61877.00","0.156"],["61877.40","0.269"],["61877.60","0.001"],["61877.70","0.006"],["61878.10","0.014"],["61878.50","0.004"],["61878.60","0.317"],["61878.70","0.071"],["61878.80","0.001"],["61879.60","0.049"],["61880.00","0.013"],["61880.30","0.887"],["61880.50","0.135"],["61880.60","0.408"],["61881.10","0.002"],["61881.40","0.251"],["61881.70","0.008"],["61882.30","0.000"],["61882.60","0.024"],["61883.40","0.325"],["61883.90","0.020"],["61885.00","0.058"],["61885.10","0.121"],["61885.60","2.010"],["61886.40","0.006"],["61886.90","0.050"],["61887.10","0.080"],["61888.10","0.099"],["61888.70","0.002"],["61889.30","0.000"],["61889.40","0.018"],["61889.70","0.052"],["61889.80","0.191"],["61889.90","0.013"],["61890.40","1.366"],["61890.60","0.031"],["61892.10","0.016"],["61892.30","1.258"],["61892.40","0.000"],["61892.50","0.020"],["61892.90","0.012"],["61893.50","0.595"],["61894.30","0.001"],["61895.60","0.408"],["61895.80","0.157"],["61896.30","0.123"],["61896.40","1.172"],["61896.50","0.002"],["61896.60","0.156"],["61896.70","2.162"],["61897.20","0.013"],["61897.30","0.004"],["61897.60","0.004"],["61897.70","0.015"],["61897.90","0.131"],["61898.00","0.003"],["61898.10","0.002"],["61898.20","0.374"],["61898.30","3.290"],["61898.40","5.706"],["61898.70","0.098"],["61898.90","0.008"],["61900.70","0.000"],["61901.10","0.038"],["61901.20","0.000"],["61901.60","0.033"],["61903.00","0.002"],["61903.40","0.016"],["61903.90","3.653"],["61904.00","0.003"],["61904.30","0.016"],["61904.80","0.388"],["61906.20","0.003"],["61906.70","0.010"],["61908.70","0.016"],["61909.90","0.217"],["61910.10","0.012"],["61910.50","0.023"],["61910.60","0.022"],["61910.70","0.018"],["61920.80","0.324"],["61950.60","3.063"],["61953.70","0.264"],["61964.60","0.027"],["62026.30","0.000"],["62026.40","0.794"],["62137.80","0.246"],["62138.30","0.262"],["62142.70","0.000"],["62212.70","0.006"],["62470.80","0.000"],["62471.80","0.686"],["62472.30","0.002"],["62677.30","0.279"],["63089.30","0.138"]],"st":1}}
{"schema_version":"1.3.0","event_id":"bbd1e055-c77f-4a42-a055-67fbf5ef9d0f","event_type":"raw.depth_update","source":"binance_market_data_recorder","venue":"binance_usdm","market_type":"perpetual_futures","symbol":"BTCUSDT","event_time_ms":1783517066292,"received_time_ms":1783517066984,"trace_id":"d7da7eb6-0726-4f3c-8afd-5077be362e40","first_update_id":10999770489995,"final_update_id":10999770524747,"previous_final_update_id":10999770489945,"bids":[{"price":"11353.70","quantity":"0.288"},{"price":"11452.20","quantity":"2.416"},{"price":"11553.70","quantity":"0.153"},{"price":"11652.20","quantity":"0.493"},{"price":"49483.00","quantity":"0.000"},{"price":"55668.30","quantity":"0.002"},{"price":"58745.80","quantity":"0.031"},{"price":"59379.50","quantity":"0.004"},{"price":"60616.70","quantity":"0.011"},{"price":"60781.60","quantity":"0.822"},{"price":"60948.40","quantity":"3.580"},{"price":"61076.90","quantity":"3.774"},{"price":"61171.80","quantity":"1.227"},{"price":"61177.70","quantity":"0.001"},{"price":"61235.20","quantity":"0.025"},{"price":"61397.00","quantity":"0.052"},{"price":"61440.00","quantity":"0.140"},{"price":"61520.00","quantity":"2.919"},{"price":"61593.90","quantity":"0.276"},{"price":"61600.00","quantity":"56.797"},{"price":"61677.90","quantity":"0.005"},{"price":"61679.40","quantity":"0.588"},{"price":"61680.00","quantity":"0.711"},{"price":"61750.50","quantity":"0.047"},{"price":"61758.90","quantity":"0.019"},{"price":"61759.80","quantity":"0.000"},{"price":"61760.00","quantity":"0.920"},{"price":"61760.50","quantity":"0.009"},{"price":"61763.20","quantity":"0.019"},{"price":"61764.00","quantity":"1.363"},{"price":"61770.00","quantity":"1.664"},{"price":"61773.80","quantity":"0.033"},{"price":"61777.30","quantity":"0.000"},{"price":"61785.80","quantity":"0.000"},{"price":"61786.00","quantity":"0.212"},{"price":"61786.30","quantity":"0.002"},{"price":"61786.40","quantity":"2.413"},{"price":"61786.50","quantity":"0.022"},{"price":"61788.40","quantity":"34.215"},{"price":"61789.00","quantity":"6.412"},{"price":"61790.00","quantity":"0.203"},{"price":"61790.50","quantity":"1.114"},{"price":"61792.40","quantity":"0.162"},{"price":"61792.70","quantity":"0.070"},{"price":"61794.30","quantity":"0.028"},{"price":"61796.30","quantity":"0.001"},{"price":"61796.60","quantity":"0.801"},{"price":"61797.40","quantity":"0.163"},{"price":"61797.50","quantity":"0.003"},{"price":"61797.70","quantity":"0.843"},{"price":"61797.90","quantity":"1.431"},{"price":"61798.00","quantity":"0.015"},{"price":"61798.60","quantity":"0.026"},{"price":"61800.90","quantity":"0.025"},{"price":"61803.90","quantity":"0.198"},{"price":"61804.60","quantity":"0.049"},{"price":"61806.00","quantity":"0.043"},{"price":"61806.30","quantity":"0.021"},{"price":"61807.60","quantity":"1.444"},{"price":"61808.00","quantity":"0.056"},{"price":"61808.10","quantity":"0.000"},{"price":"61808.50","quantity":"0.000"},{"price":"61808.80","quantity":"0.351"},{"price":"61808.90","quantity":"0.111"},{"price":"61809.30","quantity":"0.182"},{"price":"61810.30","quantity":"1.007"},{"price":"61812.50","quantity":"0.933"},{"price":"61813.60","quantity":"0.103"},{"price":"61814.20","quantity":"0.296"},{"price":"61814.30","quantity":"0.232"},{"price":"61814.40","quantity":"0.110"},{"price":"61814.50","quantity":"0.007"},{"price":"61815.70","quantity":"0.002"},{"price":"61815.90","quantity":"0.002"},{"price":"61816.30","quantity":"0.390"},{"price":"61816.40","quantity":"0.868"},{"price":"61816.50","quantity":"0.081"},{"price":"61817.00","quantity":"0.018"},{"price":"61817.30","quantity":"1.771"},{"price":"61818.20","quantity":"0.000"},{"price":"61818.40","quantity":"0.004"},{"price":"61819.10","quantity":"0.120"},{"price":"61819.40","quantity":"0.100"},{"price":"61820.00","quantity":"50.542"},{"price":"61820.10","quantity":"10.663"},{"price":"61820.30","quantity":"0.556"},{"price":"61820.40","quantity":"1.415"},{"price":"61820.50","quantity":"0.309"},{"price":"61820.90","quantity":"1.779"},{"price":"61821.00","quantity":"0.737"},{"price":"61821.20","quantity":"0.065"},{"price":"61821.30","quantity":"0.096"},{"price":"61821.50","quantity":"0.324"},{"price":"61822.10","quantity":"0.001"},{"price":"61822.30","quantity":"0.002"},{"price":"61822.70","quantity":"0.016"},{"price":"61823.20","quantity":"0.355"},{"price":"61823.40","quantity":"0.002"},{"price":"61823.80","quantity":"0.017"},{"price":"61824.20","quantity":"0.002"},{"price":"61824.30","quantity":"0.092"},{"price":"61824.70","quantity":"0.001"},{"price":"61824.80","quantity":"0.009"},{"price":"61825.00","quantity":"3.092"},{"price":"61825.10","quantity":"0.255"},{"price":"61825.30","quantity":"0.017"},{"price":"61825.50","quantity":"0.008"},{"price":"61825.70","quantity":"0.004"},{"price":"61825.90","quantity":"1.319"},{"price":"61826.40","quantity":"0.881"},{"price":"61826.70","quantity":"0.011"},{"price":"61826.90","quantity":"0.003"},{"price":"61827.10","quantity":"0.006"},{"price":"61827.50","quantity":"2.686"},{"price":"61827.60","quantity":"0.002"},{"price":"61828.10","quantity":"0.081"},{"price":"61828.30","quantity":"0.001"},{"price":"61828.50","quantity":"0.016"},{"price":"61828.70","quantity":"0.129"},{"price":"61828.90","quantity":"1.011"},{"price":"61829.00","quantity":"0.098"},{"price":"61829.50","quantity":"0.879"},{"price":"61829.90","quantity":"0.005"},{"price":"61830.00","quantity":"0.004"},{"price":"61830.30","quantity":"0.007"},{"price":"61830.40","quantity":"0.419"},{"price":"61830.50","quantity":"0.001"},{"price":"61831.20","quantity":"0.001"},{"price":"61831.70","quantity":"0.247"},{"price":"61831.90","quantity":"0.001"},{"price":"61832.30","quantity":"0.002"},{"price":"61832.50","quantity":"0.004"},{"price":"61832.90","quantity":"0.021"},{"price":"61833.10","quantity":"0.325"},{"price":"61833.30","quantity":"0.000"},{"price":"61833.70","quantity":"0.001"},{"price":"61834.00","quantity":"2.414"},{"price":"61834.20","quantity":"0.163"},{"price":"61834.60","quantity":"0.049"},{"price":"61834.90","quantity":"0.001"},{"price":"61835.00","quantity":"2.035"},{"price":"61835.20","quantity":"1.640"},{"price":"61835.40","quantity":"0.001"},{"price":"61835.50","quantity":"0.014"},{"price":"61835.60","quantity":"0.129"},{"price":"61835.70","quantity":"1.070"},{"price":"61836.20","quantity":"0.012"},{"price":"61836.50","quantity":"0.023"},{"price":"61836.60","quantity":"2.227"},{"price":"61836.70","quantity":"0.006"},{"price":"61836.90","quantity":"0.001"},{"price":"61837.40","quantity":"0.811"},{"price":"61837.50","quantity":"2.197"},{"price":"61837.60","quantity":"1.240"},{"price":"61837.80","quantity":"2.139"},{"price":"61837.90","quantity":"1.483"},{"price":"61838.00","quantity":"1.202"},{"price":"61838.10","quantity":"0.483"},{"price":"61838.60","quantity":"0.018"},{"price":"61838.70","quantity":"1.329"},{"price":"61839.10","quantity":"0.080"},{"price":"61839.20","quantity":"0.003"},{"price":"61839.30","quantity":"0.001"},{"price":"61840.00","quantity":"0.500"},{"price":"61840.60","quantity":"0.564"},{"price":"61840.70","quantity":"1.393"},{"price":"61840.80","quantity":"0.241"},{"price":"61840.90","quantity":"0.284"},{"price":"61841.00","quantity":"0.190"},{"price":"61841.20","quantity":"0.152"},{"price":"61841.30","quantity":"0.703"},{"price":"61841.40","quantity":"0.027"},{"price":"61841.60","quantity":"0.053"},{"price":"61841.70","quantity":"1.223"},{"price":"61841.90","quantity":"0.402"},{"price":"61842.00","quantity":"0.046"},{"price":"61842.40","quantity":"0.413"},{"price":"61842.60","quantity":"0.081"},{"price":"61842.80","quantity":"0.180"},{"price":"61842.90","quantity":"0.000"},{"price":"61843.00","quantity":"0.033"},{"price":"61843.10","quantity":"0.052"},{"price":"61843.20","quantity":"0.008"},{"price":"61843.60","quantity":"0.002"},{"price":"61843.70","quantity":"0.003"},{"price":"61843.90","quantity":"0.000"},{"price":"61844.00","quantity":"0.000"},{"price":"61844.10","quantity":"1.202"},{"price":"61844.20","quantity":"0.131"},{"price":"61844.30","quantity":"0.002"},{"price":"61844.40","quantity":"0.020"},{"price":"61844.70","quantity":"1.202"},{"price":"61844.80","quantity":"0.139"},{"price":"61844.90","quantity":"0.001"},{"price":"61845.00","quantity":"0.007"},{"price":"61845.10","quantity":"0.001"},{"price":"61845.30","quantity":"0.005"},{"price":"61845.60","quantity":"0.002"},{"price":"61846.20","quantity":"1.253"},{"price":"61846.40","quantity":"0.001"},{"price":"61846.50","quantity":"0.006"},{"price":"61846.80","quantity":"0.000"},{"price":"61846.90","quantity":"0.146"},{"price":"61847.00","quantity":"0.002"},{"price":"61847.40","quantity":"0.002"},{"price":"61847.80","quantity":"0.002"},{"price":"61848.20","quantity":"0.000"},{"price":"61848.40","quantity":"0.008"},{"price":"61848.70","quantity":"0.064"},{"price":"61849.10","quantity":"0.003"},{"price":"61849.20","quantity":"0.000"},{"price":"61850.00","quantity":"0.032"},{"price":"61850.10","quantity":"0.049"},{"price":"61850.20","quantity":"0.002"},{"price":"61850.30","quantity":"0.004"},{"price":"61850.50","quantity":"0.000"},{"price":"61850.60","quantity":"0.043"},{"price":"61850.70","quantity":"0.002"},{"price":"61851.30","quantity":"0.001"},{"price":"61851.50","quantity":"0.004"},{"price":"61851.60","quantity":"0.070"},{"price":"61852.00","quantity":"1.000"},{"price":"61852.10","quantity":"0.000"},{"price":"61852.20","quantity":"0.871"},{"price":"61852.30","quantity":"0.000"},{"price":"61852.80","quantity":"0.000"},{"price":"61853.20","quantity":"0.000"},{"price":"61853.30","quantity":"0.000"},{"price":"61853.40","quantity":"0.002"},{"price":"61853.50","quantity":"0.000"},{"price":"61853.60","quantity":"0.002"},{"price":"61853.70","quantity":"2.240"}],"asks":[{"price":"61853.80","quantity":"8.406"},{"price":"61853.90","quantity":"0.008"},{"price":"61854.00","quantity":"0.266"},{"price":"61854.40","quantity":"0.001"},{"price":"61854.50","quantity":"0.060"},{"price":"61854.60","quantity":"0.053"},{"price":"61854.80","quantity":"1.881"},{"price":"61854.90","quantity":"2.366"},{"price":"61855.00","quantity":"1.951"},{"price":"61855.50","quantity":"0.003"},{"price":"61855.80","quantity":"0.005"},{"price":"61856.50","quantity":"0.049"},{"price":"61856.70","quantity":"0.915"},{"price":"61856.80","quantity":"1.070"},{"price":"61856.90","quantity":"0.006"},{"price":"61857.00","quantity":"0.841"},{"price":"61857.10","quantity":"0.325"},{"price":"61857.20","quantity":"2.135"},{"price":"61857.30","quantity":"1.402"},{"price":"61857.40","quantity":"1.273"},{"price":"61857.70","quantity":"0.113"},{"price":"61857.80","quantity":"1.022"},{"price":"61857.90","quantity":"0.498"},{"price":"61858.20","quantity":"0.558"},{"price":"61858.40","quantity":"0.002"},{"price":"61858.70","quantity":"0.157"},{"price":"61858.90","quantity":"0.101"},{"price":"61859.20","quantity":"0.069"},{"price":"61859.40","quantity":"0.182"},{"price":"61859.50","quantity":"0.017"},{"price":"61859.60","quantity":"0.133"},{"price":"61859.70","quantity":"0.567"},{"price":"61859.80","quantity":"1.042"},{"price":"61859.90","quantity":"0.199"},{"price":"61860.00","quantity":"0.335"},{"price":"61860.20","quantity":"1.293"},{"price":"61860.30","quantity":"0.018"},{"price":"61860.40","quantity":"0.016"},{"price":"61860.50","quantity":"2.086"},{"price":"61860.60","quantity":"0.124"},{"price":"61860.70","quantity":"0.126"},{"price":"61860.80","quantity":"0.023"},{"price":"61861.00","quantity":"0.047"},{"price":"61861.10","quantity":"0.047"},{"price":"61861.20","quantity":"0.328"},{"price":"61861.30","quantity":"1.247"},{"price":"61861.70","quantity":"0.163"},{"price":"61861.80","quantity":"0.968"},{"price":"61862.00","quantity":"0.163"},{"price":"61862.10","quantity":"0.265"},{"price":"61862.20","quantity":"0.127"},{"price":"61862.30","quantity":"0.002"},{"price":"61862.40","quantity":"0.373"},{"price":"61862.50","quantity":"0.001"},{"price":"61862.60","quantity":"0.007"},{"price":"61862.80","quantity":"0.343"},{"price":"61863.30","quantity":"0.003"},{"price":"61863.40","quantity":"0.596"},{"price":"61863.50","quantity":"0.082"},{"price":"61863.60","quantity":"0.170"},{"price":"61863.80","quantity":"0.003"},{"price":"61863.90","quantity":"0.471"},{"price":"61864.10","quantity":"1.763"},{"price":"61864.50","quantity":"0.000"},{"price":"61864.60","quantity":"0.066"},{"price":"61864.70","quantity":"3.063"},{"price":"61865.00","quantity":"0.003"},{"price":"61865.20","quantity":"0.027"},{"price":"61865.40","quantity":"0.000"},{"price":"61865.60","quantity":"0.004"},{"price":"61866.00","quantity":"0.014"},{"price":"61866.20","quantity":"0.566"},{"price":"61866.40","quantity":"0.122"},{"price":"61866.60","quantity":"0.203"},{"price":"61867.10","quantity":"0.000"},{"price":"61868.40","quantity":"0.025"},{"price":"61868.90","quantity":"0.122"},{"price":"61869.10","quantity":"0.004"},{"price":"61869.40","quantity":"0.007"},{"price":"61870.00","quantity":"0.412"},{"price":"61870.10","quantity":"0.235"},{"price":"61871.30","quantity":"0.111"},{"price":"61871.60","quantity":"0.003"},{"price":"61872.10","quantity":"0.011"},{"price":"61872.90","quantity":"0.394"},{"price":"61873.20","quantity":"0.016"},{"price":"61873.30","quantity":"0.011"},{"price":"61873.60","quantity":"0.033"},{"price":"61873.70","quantity":"0.007"},{"price":"61873.80","quantity":"1.290"},{"price":"61874.70","quantity":"0.011"},{"price":"61874.90","quantity":"0.159"},{"price":"61875.10","quantity":"2.218"},{"price":"61875.20","quantity":"0.283"},{"price":"61875.70","quantity":"3.718"},{"price":"61877.80","quantity":"0.016"},{"price":"61878.10","quantity":"0.002"},{"price":"61878.60","quantity":"1.024"},{"price":"61878.90","quantity":"0.002"},{"price":"61879.20","quantity":"0.055"},{"price":"61879.60","quantity":"0.000"},{"price":"61879.70","quantity":"0.105"},{"price":"61880.20","quantity":"0.121"},{"price":"61880.80","quantity":"0.008"},{"price":"61881.00","quantity":"0.572"},{"price":"61881.10","quantity":"0.002"},{"price":"61881.30","quantity":"0.975"},{"price":"61881.40","quantity":"0.249"},{"price":"61881.50","quantity":"0.014"},{"price":"61881.70","quantity":"0.000"},{"price":"61882.20","quantity":"0.799"},{"price":"61882.30","quantity":"0.008"},{"price":"61882.40","quantity":"0.000"},{"price":"61882.60","quantity":"0.016"},{"price":"61885.90","quantity":"0.013"},{"price":"61886.30","quantity":"0.002"},{"price":"61886.70","quantity":"0.010"},{"price":"61886.80","quantity":"0.735"},{"price":"61886.90","quantity":"0.000"},{"price":"61887.40","quantity":"0.013"},{"price":"61888.20","quantity":"0.123"},{"price":"61888.30","quantity":"0.078"},{"price":"61888.90","quantity":"0.952"},{"price":"61889.00","quantity":"0.002"},{"price":"61889.40","quantity":"0.018"},{"price":"61889.80","quantity":"0.121"},{"price":"61889.90","quantity":"0.003"},{"price":"61891.50","quantity":"0.004"},{"price":"61892.90","quantity":"0.009"},{"price":"61894.10","quantity":"0.020"},{"price":"61895.20","quantity":"0.015"},{"price":"61895.30","quantity":"0.002"},{"price":"61895.70","quantity":"0.090"},{"price":"61895.80","quantity":"0.158"},{"price":"61895.90","quantity":"0.000"},{"price":"61896.40","quantity":"1.052"},{"price":"61896.50","quantity":"0.002"},{"price":"61897.30","quantity":"0.001"},{"price":"61897.50","quantity":"0.012"},{"price":"61897.60","quantity":"0.007"},{"price":"61902.80","quantity":"0.097"},{"price":"61903.30","quantity":"0.469"},{"price":"61904.80","quantity":"0.386"},{"price":"61905.60","quantity":"0.004"},{"price":"61907.70","quantity":"0.513"},{"price":"61909.00","quantity":"0.032"},{"price":"61909.40","quantity":"0.006"},{"price":"61909.50","quantity":"2.640"},{"price":"61909.90","quantity":"0.116"},{"price":"61910.10","quantity":"0.036"},{"price":"61910.40","quantity":"1.157"},{"price":"61910.60","quantity":"0.019"},{"price":"61911.70","quantity":"0.004"},{"price":"61913.50","quantity":"2.244"},{"price":"61914.40","quantity":"0.363"},{"price":"61915.10","quantity":"0.121"},{"price":"61916.00","quantity":"0.003"},{"price":"61916.30","quantity":"0.149"},{"price":"61916.40","quantity":"6.531"},{"price":"61918.30","quantity":"0.000"},{"price":"61918.40","quantity":"25.201"},{"price":"61920.00","quantity":"1.172"},{"price":"61920.30","quantity":"0.000"},{"price":"61921.50","quantity":"0.000"},{"price":"61921.80","quantity":"0.029"},{"price":"61922.30","quantity":"0.218"},{"price":"61926.60","quantity":"0.001"},{"price":"61928.70","quantity":"0.026"},{"price":"61946.30","quantity":"2.154"},{"price":"61950.90","quantity":"0.833"},{"price":"61953.70","quantity":"0.000"},{"price":"62000.00","quantity":"13.023"},{"price":"62080.00","quantity":"0.289"},{"price":"62136.50","quantity":"0.149"},{"price":"62138.30","quantity":"0.017"},{"price":"62160.00","quantity":"0.284"},{"price":"62240.00","quantity":"0.279"},{"price":"62470.80","quantity":"0.022"},{"price":"62472.30","quantity":"0.002"},{"price":"62564.00","quantity":"0.002"},{"price":"62564.20","quantity":"0.000"},{"price":"62565.10","quantity":"2.374"},{"price":"62565.30","quantity":"13.286"},{"price":"62589.30","quantity":"0.958"},{"price":"62625.90","quantity":"4.426"},{"price":"62626.10","quantity":"0.000"},{"price":"62627.00","quantity":"3.160"},{"price":"62627.20","quantity":"6.168"},{"price":"63090.80","quantity":"0.003"},{"price":"89523.20","quantity":"0.708"}],"raw":{"e":"depthUpdate","E":1783517066292,"T":1783517066291,"s":"BTCUSDT","ps":"BTCUSDT","U":10999770489995,"u":10999770524747,"pu":10999770489945,"b":[["11353.70","0.288"],["11452.20","2.416"],["11553.70","0.153"],["11652.20","0.493"],["49483.00","0.000"],["55668.30","0.002"],["58745.80","0.031"],["59379.50","0.004"],["60616.70","0.011"],["60781.60","0.822"],["60948.40","3.580"],["61076.90","3.774"],["61171.80","1.227"],["61177.70","0.001"],["61235.20","0.025"],["61397.00","0.052"],["61440.00","0.140"],["61520.00","2.919"],["61593.90","0.276"],["61600.00","56.797"],["61677.90","0.005"],["61679.40","0.588"],["61680.00","0.711"],["61750.50","0.047"],["61758.90","0.019"],["61759.80","0.000"],["61760.00","0.920"],["61760.50","0.009"],["61763.20","0.019"],["61764.00","1.363"],["61770.00","1.664"],["61773.80","0.033"],["61777.30","0.000"],["61785.80","0.000"],["61786.00","0.212"],["61786.30","0.002"],["61786.40","2.413"],["61786.50","0.022"],["61788.40","34.215"],["61789.00","6.412"],["61790.00","0.203"],["61790.50","1.114"],["61792.40","0.162"],["61792.70","0.070"],["61794.30","0.028"],["61796.30","0.001"],["61796.60","0.801"],["61797.40","0.163"],["61797.50","0.003"],["61797.70","0.843"],["61797.90","1.431"],["61798.00","0.015"],["61798.60","0.026"],["61800.90","0.025"],["61803.90","0.198"],["61804.60","0.049"],["61806.00","0.043"],["61806.30","0.021"],["61807.60","1.444"],["61808.00","0.056"],["61808.10","0.000"],["61808.50","0.000"],["61808.80","0.351"],["61808.90","0.111"],["61809.30","0.182"],["61810.30","1.007"],["61812.50","0.933"],["61813.60","0.103"],["61814.20","0.296"],["61814.30","0.232"],["61814.40","0.110"],["61814.50","0.007"],["61815.70","0.002"],["61815.90","0.002"],["61816.30","0.390"],["61816.40","0.868"],["61816.50","0.081"],["61817.00","0.018"],["61817.30","1.771"],["61818.20","0.000"],["61818.40","0.004"],["61819.10","0.120"],["61819.40","0.100"],["61820.00","50.542"],["61820.10","10.663"],["61820.30","0.556"],["61820.40","1.415"],["61820.50","0.309"],["61820.90","1.779"],["61821.00","0.737"],["61821.20","0.065"],["61821.30","0.096"],["61821.50","0.324"],["61822.10","0.001"],["61822.30","0.002"],["61822.70","0.016"],["61823.20","0.355"],["61823.40","0.002"],["61823.80","0.017"],["61824.20","0.002"],["61824.30","0.092"],["61824.70","0.001"],["61824.80","0.009"],["61825.00","3.092"],["61825.10","0.255"],["61825.30","0.017"],["61825.50","0.008"],["61825.70","0.004"],["61825.90","1.319"],["61826.40","0.881"],["61826.70","0.011"],["61826.90","0.003"],["61827.10","0.006"],["61827.50","2.686"],["61827.60","0.002"],["61828.10","0.081"],["61828.30","0.001"],["61828.50","0.016"],["61828.70","0.129"],["61828.90","1.011"],["61829.00","0.098"],["61829.50","0.879"],["61829.90","0.005"],["61830.00","0.004"],["61830.30","0.007"],["61830.40","0.419"],["61830.50","0.001"],["61831.20","0.001"],["61831.70","0.247"],["61831.90","0.001"],["61832.30","0.002"],["61832.50","0.004"],["61832.90","0.021"],["61833.10","0.325"],["61833.30","0.000"],["61833.70","0.001"],["61834.00","2.414"],["61834.20","0.163"],["61834.60","0.049"],["61834.90","0.001"],["61835.00","2.035"],["61835.20","1.640"],["61835.40","0.001"],["61835.50","0.014"],["61835.60","0.129"],["61835.70","1.070"],["61836.20","0.012"],["61836.50","0.023"],["61836.60","2.227"],["61836.70","0.006"],["61836.90","0.001"],["61837.40","0.811"],["61837.50","2.197"],["61837.60","1.240"],["61837.80","2.139"],["61837.90","1.483"],["61838.00","1.202"],["61838.10","0.483"],["61838.60","0.018"],["61838.70","1.329"],["61839.10","0.080"],["61839.20","0.003"],["61839.30","0.001"],["61840.00","0.500"],["61840.60","0.564"],["61840.70","1.393"],["61840.80","0.241"],["61840.90","0.284"],["61841.00","0.190"],["61841.20","0.152"],["61841.30","0.703"],["61841.40","0.027"],["61841.60","0.053"],["61841.70","1.223"],["61841.90","0.402"],["61842.00","0.046"],["61842.40","0.413"],["61842.60","0.081"],["61842.80","0.180"],["61842.90","0.000"],["61843.00","0.033"],["61843.10","0.052"],["61843.20","0.008"],["61843.60","0.002"],["61843.70","0.003"],["61843.90","0.000"],["61844.00","0.000"],["61844.10","1.202"],["61844.20","0.131"],["61844.30","0.002"],["61844.40","0.020"],["61844.70","1.202"],["61844.80","0.139"],["61844.90","0.001"],["61845.00","0.007"],["61845.10","0.001"],["61845.30","0.005"],["61845.60","0.002"],["61846.20","1.253"],["61846.40","0.001"],["61846.50","0.006"],["61846.80","0.000"],["61846.90","0.146"],["61847.00","0.002"],["61847.40","0.002"],["61847.80","0.002"],["61848.20","0.000"],["61848.40","0.008"],["61848.70","0.064"],["61849.10","0.003"],["61849.20","0.000"],["61850.00","0.032"],["61850.10","0.049"],["61850.20","0.002"],["61850.30","0.004"],["61850.50","0.000"],["61850.60","0.043"],["61850.70","0.002"],["61851.30","0.001"],["61851.50","0.004"],["61851.60","0.070"],["61852.00","1.000"],["61852.10","0.000"],["61852.20","0.871"],["61852.30","0.000"],["61852.80","0.000"],["61853.20","0.000"],["61853.30","0.000"],["61853.40","0.002"],["61853.50","0.000"],["61853.60","0.002"],["61853.70","2.240"]],"a":[["61853.80","8.406"],["61853.90","0.008"],["61854.00","0.266"],["61854.40","0.001"],["61854.50","0.060"],["61854.60","0.053"],["61854.80","1.881"],["61854.90","2.366"],["61855.00","1.951"],["61855.50","0.003"],["61855.80","0.005"],["61856.50","0.049"],["61856.70","0.915"],["61856.80","1.070"],["61856.90","0.006"],["61857.00","0.841"],["61857.10","0.325"],["61857.20","2.135"],["61857.30","1.402"],["61857.40","1.273"],["61857.70","0.113"],["61857.80","1.022"],["61857.90","0.498"],["61858.20","0.558"],["61858.40","0.002"],["61858.70","0.157"],["61858.90","0.101"],["61859.20","0.069"],["61859.40","0.182"],["61859.50","0.017"],["61859.60","0.133"],["61859.70","0.567"],["61859.80","1.042"],["61859.90","0.199"],["61860.00","0.335"],["61860.20","1.293"],["61860.30","0.018"],["61860.40","0.016"],["61860.50","2.086"],["61860.60","0.124"],["61860.70","0.126"],["61860.80","0.023"],["61861.00","0.047"],["61861.10","0.047"],["61861.20","0.328"],["61861.30","1.247"],["61861.70","0.163"],["61861.80","0.968"],["61862.00","0.163"],["61862.10","0.265"],["61862.20","0.127"],["61862.30","0.002"],["61862.40","0.373"],["61862.50","0.001"],["61862.60","0.007"],["61862.80","0.343"],["61863.30","0.003"],["61863.40","0.596"],["61863.50","0.082"],["61863.60","0.170"],["61863.80","0.003"],["61863.90","0.471"],["61864.10","1.763"],["61864.50","0.000"],["61864.60","0.066"],["61864.70","3.063"],["61865.00","0.003"],["61865.20","0.027"],["61865.40","0.000"],["61865.60","0.004"],["61866.00","0.014"],["61866.20","0.566"],["61866.40","0.122"],["61866.60","0.203"],["61867.10","0.000"],["61868.40","0.025"],["61868.90","0.122"],["61869.10","0.004"],["61869.40","0.007"],["61870.00","0.412"],["61870.10","0.235"],["61871.30","0.111"],["61871.60","0.003"],["61872.10","0.011"],["61872.90","0.394"],["61873.20","0.016"],["61873.30","0.011"],["61873.60","0.033"],["61873.70","0.007"],["61873.80","1.290"],["61874.70","0.011"],["61874.90","0.159"],["61875.10","2.218"],["61875.20","0.283"],["61875.70","3.718"],["61877.80","0.016"],["61878.10","0.002"],["61878.60","1.024"],["61878.90","0.002"],["61879.20","0.055"],["61879.60","0.000"],["61879.70","0.105"],["61880.20","0.121"],["61880.80","0.008"],["61881.00","0.572"],["61881.10","0.002"],["61881.30","0.975"],["61881.40","0.249"],["61881.50","0.014"],["61881.70","0.000"],["61882.20","0.799"],["61882.30","0.008"],["61882.40","0.000"],["61882.60","0.016"],["61885.90","0.013"],["61886.30","0.002"],["61886.70","0.010"],["61886.80","0.735"],["61886.90","0.000"],["61887.40","0.013"],["61888.20","0.123"],["61888.30","0.078"],["61888.90","0.952"],["61889.00","0.002"],["61889.40","0.018"],["61889.80","0.121"],["61889.90","0.003"],["61891.50","0.004"],["61892.90","0.009"],["61894.10","0.020"],["61895.20","0.015"],["61895.30","0.002"],["61895.70","0.090"],["61895.80","0.158"],["61895.90","0.000"],["61896.40","1.052"],["61896.50","0.002"],["61897.30","0.001"],["61897.50","0.012"],["61897.60","0.007"],["61902.80","0.097"],["61903.30","0.469"],["61904.80","0.386"],["61905.60","0.004"],["61907.70","0.513"],["61909.00","0.032"],["61909.40","0.006"],["61909.50","2.640"],["61909.90","0.116"],["61910.10","0.036"],["61910.40","1.157"],["61910.60","0.019"],["61911.70","0.004"],["61913.50","2.244"],["61914.40","0.363"],["61915.10","0.121"],["61916.00","0.003"],["61916.30","0.149"],["61916.40","6.531"],["61918.30","0.000"],["61918.40","25.201"],["61920.00","1.172"],["61920.30","0.000"],["61921.50","0.000"],["61921.80","0.029"],["61922.30","0.218"],["61926.60","0.001"],["61928.70","0.026"],["61946.30","2.154"],["61950.90","0.833"],["61953.70","0.000"],["62000.00","13.023"],["62080.00","0.289"],["62136.50","0.149"],["62138.30","0.017"],["62160.00","0.284"],["62240.00","0.279"],["62470.80","0.022"],["62472.30","0.002"],["62564.00","0.002"],["62564.20","0.000"],["62565.10","2.374"],["62565.30","13.286"],["62589.30","0.958"],["62625.90","4.426"],["62626.10","0.000"],["62627.00","3.160"],["62627.20","6.168"],["63090.80","0.003"],["89523.20","0.708"]],"st":1}}
{"schema_version":"1.3.0","event_id":"13e7dcc0-e11e-4bae-b79b-3143ebe37819","event_type":"raw.depth_update","source":"binance_market_data_recorder","venue":"binance_usdm","market_type":"perpetual_futures","symbol":"BTCUSDT","event_time_ms":1783517066394,"received_time_ms":1783517067156,"trace_id":"d616c977-5bd4-4929-9493-ed4cd6c9d1f8","first_update_id":10999770524885,"final_update_id":10999770545000,"previous_final_update_id":10999770524747,"bids":[{"price":"1000.00","quantity":"207.692"},{"price":"11353.70","quantity":"0.560"},{"price":"11452.20","quantity":"2.144"},{"price":"11553.70","quantity":"0.306"},{"price":"11652.20","quantity":"0.340"},{"price":"49482.00","quantity":"0.000"},{"price":"55668.30","quantity":"0.002"},{"price":"58759.50","quantity":"0.000"},{"price":"58761.00","quantity":"0.000"},{"price":"60931.00","quantity":"4.693"},{"price":"60955.30","quantity":"13.764"},{"price":"61110.00","quantity":"4.977"},{"price":"61171.80","quantity":"1.472"},{"price":"61235.20","quantity":"0.025"},{"price":"61293.60","quantity":"1.776"},{"price":"61537.60","quantity":"0.348"},{"price":"61542.90","quantity":"0.011"},{"price":"61584.10","quantity":"0.000"},{"price":"61584.20","quantity":"0.084"},{"price":"61598.60","quantity":"0.873"},{"price":"61606.30","quantity":"0.621"},{"price":"61769.50","quantity":"34.249"},{"price":"61770.00","quantity":"6.631"},{"price":"61771.60","quantity":"0.001"},{"price":"61788.10","quantity":"0.809"},{"price":"61788.40","quantity":"0.002"},{"price":"61789.00","quantity":"1.484"},{"price":"61792.70","quantity":"0.000"},{"price":"61799.60","quantity":"0.000"},{"price":"61804.60","quantity":"0.000"},{"price":"61807.60","quantity":"1.442"},{"price":"61807.90","quantity":"0.070"},{"price":"61808.00","quantity":"4.445"},{"price":"61808.90","quantity":"0.110"},{"price":"61809.50","quantity":"0.061"},{"price":"61810.30","quantity":"1.591"},{"price":"61813.30","quantity":"2.195"},{"price":"61817.30","quantity":"1.861"},{"price":"61817.40","quantity":"0.014"},{"price":"61820.00","quantity":"50.544"},{"price":"61820.90","quantity":"1.744"},{"price":"61821.20","quantity":"0.064"},{"price":"61821.30","quantity":"0.060"},{"price":"61823.20","quantity":"0.357"},{"price":"61823.40","quantity":"0.009"},{"price":"61823.50","quantity":"0.124"},{"price":"61823.80","quantity":"0.599"},{"price":"61825.00","quantity":"3.094"},{"price":"61825.90","quantity":"0.009"},{"price":"61826.10","quantity":"1.417"},{"price":"61826.20","quantity":"0.161"},{"price":"61827.50","quantity":"2.168"},{"price":"61827.80","quantity":"0.321"},{"price":"61828.10","quantity":"0.001"},{"price":"61828.40","quantity":"0.000"},{"price":"61829.30","quantity":"0.048"},{"price":"61829.40","quantity":"1.829"},{"price":"61829.80","quantity":"0.016"},{"price":"61830.00","quantity":"0.006"},{"price":"61830.30","quantity":"0.162"},{"price":"61830.40","quantity":"0.499"},{"price":"61830.50","quantity":"0.989"},{"price":"61831.00","quantity":"0.010"},{"price":"61831.60","quantity":"0.002"},{"price":"61832.90","quantity":"0.001"},{"price":"61833.00","quantity":"1.034"},{"price":"61833.30","quantity":"0.566"},{"price":"61833.60","quantity":"0.056"},{"price":"61833.70","quantity":"2.548"},{"price":"61834.20","quantity":"0.001"},{"price":"61834.80","quantity":"0.019"},{"price":"61835.00","quantity":"2.037"},{"price":"61835.20","quantity":"0.438"},{"price":"61835.40","quantity":"0.003"},{"price":"61835.50","quantity":"0.014"},{"price":"61835.60","quantity":"0.131"},{"price":"61835.70","quantity":"0.003"},{"price":"61836.50","quantity":"1.023"},{"price":"61836.60","quantity":"1.227"},{"price":"61836.80","quantity":"0.001"},{"price":"61837.80","quantity":"2.219"},{"price":"61837.90","quantity":"1.645"},{"price":"61838.10","quantity":"0.403"},{"price":"61838.20","quantity":"0.325"},{"price":"61838.30","quantity":"0.003"},{"price":"61838.80","quantity":"0.009"},{"price":"61839.10","quantity":"0.000"},{"price":"61839.50","quantity":"0.126"},{"price":"61840.00","quantity":"0.502"},{"price":"61840.30","quantity":"0.446"},{"price":"61840.60","quantity":"0.564"},{"price":"61841.00","quantity":"0.191"},{"price":"61841.30","quantity":"0.819"},{"price":"61841.40","quantity":"1.281"},{"price":"61841.50","quantity":"0.221"},{"price":"61841.80","quantity":"0.106"},{"price":"61841.90","quantity":"0.403"},{"price":"61842.00","quantity":"0.470"},{"price":"61842.10","quantity":"0.243"},{"price":"61842.40","quantity":"0.736"},{"price":"61842.70","quantity":"0.213"},{"price":"61842.80","quantity":"0.281"},{"price":"61842.90","quantity":"0.037"},{"price":"61843.80","quantity":"0.234"},{"price":"61844.20","quantity":"0.001"},{"price":"61844.40","quantity":"0.176"},{"price":"61844.50","quantity":"0.784"},{"price":"61844.70","quantity":"1.204"},{"price":"61844.80","quantity":"0.599"},{"price":"61845.00","quantity":"0.009"},{"price":"61845.10","quantity":"0.123"},{"price":"61846.20","quantity":"1.255"},{"price":"61846.30","quantity":"0.131"},{"price":"61847.50","quantity":"0.002"},{"price":"61847.70","quantity":"1.203"},{"price":"61847.80","quantity":"0.491"},{"price":"61848.70","quantity":"0.000"},{"price":"61848.80","quantity":"0.289"},{"price":"61849.10","quantity":"0.197"},{"price":"61849.60","quantity":"0.076"},{"price":"61850.00","quantity":"0.034"},{"price":"61850.10","quantity":"0.049"},{"price":"61850.20","quantity":"0.002"},{"price":"61851.20","quantity":"0.001"},{"price":"61851.50","quantity":"0.000"},{"price":"61852.20","quantity":"0.867"},{"price":"61853.50","quantity":"0.002"},{"price":"61853.60","quantity":"0.002"},{"price":"61853.70","quantity":"2.876"}],"asks":[{"price":"61853.80","quantity":"7.969"},{"price":"61854.30","quantity":"0.027"},{"price":"61854.60","quantity":"0.004"},{"price":"61854.70","quantity":"0.001"},{"price":"61854.80","quantity":"1.617"},{"price":"61856.70","quantity":"0.917"},{"price":"61857.30","quantity":"0.200"},{"price":"61857.80","quantity":"1.023"},{"price":"61859.50","quantity":"0.017"},{"price":"61859.80","quantity":"0.002"},{"price":"61860.30","quantity":"0.018"},{"price":"61860.50","quantity":"0.971"},{"price":"61861.00","quantity":"0.047"},{"price":"61861.30","quantity":"0.045"},{"price":"61861.60","quantity":"0.001"},{"price":"61861.70","quantity":"0.162"},{"price":"61861.80","quantity":"0.968"},{"price":"61862.10","quantity":"0.001"},{"price":"61862.50","quantity":"0.002"},{"price":"61862.60","quantity":"0.573"},{"price":"61862.70","quantity":"3.327"},{"price":"61863.00","quantity":"0.133"},{"price":"61863.40","quantity":"0.030"},{"price":"61863.90","quantity":"0.470"},{"price":"61864.10","quantity":"1.181"},{"price":"61866.90","quantity":"0.022"},{"price":"61872.80","quantity":"0.000"},{"price":"61872.90","quantity":"0.394"},{"price":"61873.40","quantity":"2.986"},{"price":"61873.80","quantity":"1.292"},{"price":"61874.20","quantity":"0.000"},{"price":"61874.90","quantity":"0.157"},{"price":"61875.10","quantity":"2.267"},{"price":"61876.90","quantity":"0.661"},{"price":"61879.70","quantity":"0.048"},{"price":"61881.10","quantity":"0.122"},{"price":"61881.40","quantity":"0.249"},{"price":"61882.20","quantity":"0.750"},{"price":"61883.90","quantity":"0.950"},{"price":"61888.20","quantity":"0.073"},{"price":"61888.30","quantity":"0.008"},{"price":"61892.50","quantity":"0.116"},{"price":"61893.40","quantity":"0.570"},{"price":"61894.00","quantity":"0.016"},{"price":"61895.00","quantity":"2.587"},{"price":"61895.20","quantity":"0.013"},{"price":"61895.30","quantity":"0.000"},{"price":"61897.40","quantity":"0.000"},{"price":"61897.80","quantity":"0.011"},{"price":"61899.10","quantity":"5.031"},{"price":"61902.60","quantity":"0.001"},{"price":"61902.80","quantity":"0.082"},{"price":"61905.00","quantity":"0.000"},{"price":"61907.60","quantity":"0.101"},{"price":"61907.90","quantity":"0.317"},{"price":"61908.70","quantity":"0.016"},{"price":"61909.00","quantity":"0.032"},{"price":"61914.40","quantity":"0.153"},{"price":"61920.80","quantity":"4.703"},{"price":"61926.40","quantity":"12.130"},{"price":"62137.80","quantity":"0.001"},{"price":"62211.60","quantity":"0.000"},{"price":"62213.10","quantity":"0.008"},{"price":"62471.30","quantity":"0.000"},{"price":"62472.30","quantity":"0.000"},{"price":"62472.90","quantity":"0.008"},{"price":"62662.70","quantity":"0.809"},{"price":"63000.00","quantity":"46.663"},{"price":"63090.80","quantity":"0.006"}],"raw":{"e":"depthUpdate","E":1783517066394,"T":1783517066393,"s":"BTCUSDT","ps":"BTCUSDT","U":10999770524885,"u":10999770545000,"pu":10999770524747,"b":[["1000.00","207.692"],["11353.70","0.560"],["11452.20","2.144"],["11553.70","0.306"],["11652.20","0.340"],["49482.00","0.000"],["55668.30","0.002"],["58759.50","0.000"],["58761.00","0.000"],["60931.00","4.693"],["60955.30","13.764"],["61110.00","4.977"],["61171.80","1.472"],["61235.20","0.025"],["61293.60","1.776"],["61537.60","0.348"],["61542.90","0.011"],["61584.10","0.000"],["61584.20","0.084"],["61598.60","0.873"],["61606.30","0.621"],["61769.50","34.249"],["61770.00","6.631"],["61771.60","0.001"],["61788.10","0.809"],["61788.40","0.002"],["61789.00","1.484"],["61792.70","0.000"],["61799.60","0.000"],["61804.60","0.000"],["61807.60","1.442"],["61807.90","0.070"],["61808.00","4.445"],["61808.90","0.110"],["61809.50","0.061"],["61810.30","1.591"],["61813.30","2.195"],["61817.30","1.861"],["61817.40","0.014"],["61820.00","50.544"],["61820.90","1.744"],["61821.20","0.064"],["61821.30","0.060"],["61823.20","0.357"],["61823.40","0.009"],["61823.50","0.124"],["61823.80","0.599"],["61825.00","3.094"],["61825.90","0.009"],["61826.10","1.417"],["61826.20","0.161"],["61827.50","2.168"],["61827.80","0.321"],["61828.10","0.001"],["61828.40","0.000"],["61829.30","0.048"],["61829.40","1.829"],["61829.80","0.016"],["61830.00","0.006"],["61830.30","0.162"],["61830.40","0.499"],["61830.50","0.989"],["61831.00","0.010"],["61831.60","0.002"],["61832.90","0.001"],["61833.00","1.034"],["61833.30","0.566"],["61833.60","0.056"],["61833.70","2.548"],["61834.20","0.001"],["61834.80","0.019"],["61835.00","2.037"],["61835.20","0.438"],["61835.40","0.003"],["61835.50","0.014"],["61835.60","0.131"],["61835.70","0.003"],["61836.50","1.023"],["61836.60","1.227"],["61836.80","0.001"],["61837.80","2.219"],["61837.90","1.645"],["61838.10","0.403"],["61838.20","0.325"],["61838.30","0.003"],["61838.80","0.009"],["61839.10","0.000"],["61839.50","0.126"],["61840.00","0.502"],["61840.30","0.446"],["61840.60","0.564"],["61841.00","0.191"],["61841.30","0.819"],["61841.40","1.281"],["61841.50","0.221"],["61841.80","0.106"],["61841.90","0.403"],["61842.00","0.470"],["61842.10","0.243"],["61842.40","0.736"],["61842.70","0.213"],["61842.80","0.281"],["61842.90","0.037"],["61843.80","0.234"],["61844.20","0.001"],["61844.40","0.176"],["61844.50","0.784"],["61844.70","1.204"],["61844.80","0.599"],["61845.00","0.009"],["61845.10","0.123"],["61846.20","1.255"],["61846.30","0.131"],["61847.50","0.002"],["61847.70","1.203"],["61847.80","0.491"],["61848.70","0.000"],["61848.80","0.289"],["61849.10","0.197"],["61849.60","0.076"],["61850.00","0.034"],["61850.10","0.049"],["61850.20","0.002"],["61851.20","0.001"],["61851.50","0.000"],["61852.20","0.867"],["61853.50","0.002"],["61853.60","0.002"],["61853.70","2.876"]],"a":[["61853.80","7.969"],["61854.30","0.027"],["61854.60","0.004"],["61854.70","0.001"],["61854.80","1.617"],["61856.70","0.917"],["61857.30","0.200"],["61857.80","1.023"],["61859.50","0.017"],["61859.80","0.002"],["61860.30","0.018"],["61860.50","0.971"],["61861.00","0.047"],["61861.30","0.045"],["61861.60","0.001"],["61861.70","0.162"],["61861.80","0.968"],["61862.10","0.001"],["61862.50","0.002"],["61862.60","0.573"],["61862.70","3.327"],["61863.00","0.133"],["61863.40","0.030"],["61863.90","0.470"],["61864.10","1.181"],["61866.90","0.022"],["61872.80","0.000"],["61872.90","0.394"],["61873.40","2.986"],["61873.80","1.292"],["61874.20","0.000"],["61874.90","0.157"],["61875.10","2.267"],["61876.90","0.661"],["61879.70","0.048"],["61881.10","0.122"],["61881.40","0.249"],["61882.20","0.750"],["61883.90","0.950"],["61888.20","0.073"],["61888.30","0.008"],["61892.50","0.116"],["61893.40","0.570"],["61894.00","0.016"],["61895.00","2.587"],["61895.20","0.013"],["61895.30","0.000"],["61897.40","0.000"],["61897.80","0.011"],["61899.10","5.031"],["61902.60","0.001"],["61902.80","0.082"],["61905.00","0.000"],["61907.60","0.101"],["61907.90","0.317"],["61908.70","0.016"],["61909.00","0.032"],["61914.40","0.153"],["61920.80","4.703"],["61926.40","12.130"],["62137.80","0.001"],["62211.60","0.000"],["62213.10","0.008"],["62471.30","0.000"],["62472.30","0.000"],["62472.90","0.008"],["62662.70","0.809"],["63000.00","46.663"],["63090.80","0.006"]],"st":1}}
{"schema_version":"1.3.0","event_id":"d15df2f4-52c6-463e-9ab6-cfab71b5d915","event_type":"raw.depth_update","source":"binance_market_data_recorder","venue":"binance_usdm","market_type":"perpetual_futures","symbol":"BTCUSDT","event_time_ms":1783517066496,"received_time_ms":1783517067176,"trace_id":"d383be5c-6422-4e79-8131-e1953c9bc88d","first_update_id":10999770545134,"final_update_id":10999770557223,"previous_final_update_id":10999770545000,"bids":[{"price":"1000.00","quantity":"207.692"},{"price":"11353.70","quantity":"0.832"},{"price":"11452.20","quantity":"1.872"},{"price":"11553.70","quantity":"0.442"},{"price":"11652.20","quantity":"0.204"},{"price":"55668.30","quantity":"0.002"},{"price":"58761.00","quantity":"0.000"},{"price":"59379.50","quantity":"0.001"},{"price":"60765.50","quantity":"0.822"},{"price":"61107.80","quantity":"5.918"},{"price":"61235.20","quantity":"0.025"},{"price":"61397.70","quantity":"0.264"},{"price":"61520.00","quantity":"3.097"},{"price":"61600.00","quantity":"56.975"},{"price":"61680.00","quantity":"0.889"},{"price":"61740.90","quantity":"0.747"},{"price":"61760.00","quantity":"1.098"},{"price":"61762.10","quantity":"1.547"},{"price":"61762.30","quantity":"0.023"},{"price":"61769.50","quantity":"0.092"},{"price":"61770.00","quantity":"1.664"},{"price":"61782.40","quantity":"1.567"},{"price":"61782.60","quantity":"0.003"},{"price":"61784.20","quantity":"34.159"},{"price":"61785.90","quantity":"7.014"},{"price":"61786.00","quantity":"0.002"},{"price":"61792.90","quantity":"0.227"},{"price":"61796.10","quantity":"0.661"},{"price":"61802.70","quantity":"9.395"},{"price":"61802.90","quantity":"0.856"},{"price":"61807.90","quantity":"0.000"},{"price":"61810.10","quantity":"0.003"},{"price":"61813.30","quantity":"2.146"},{"price":"61814.80","quantity":"0.074"},{"price":"61820.20","quantity":"0.183"},{"price":"61822.50","quantity":"0.061"},{"price":"61831.60","quantity":"0.042"},{"price":"61833.50","quantity":"0.000"},{"price":"61833.60","quantity":"0.055"},{"price":"61834.00","quantity":"1.414"},{"price":"61837.40","quantity":"0.812"},{"price":"61837.60","quantity":"1.244"},{"price":"61837.90","quantity":"1.483"},{"price":"61838.30","quantity":"0.003"},{"price":"61838.80","quantity":"0.171"},{"price":"61840.00","quantity":"0.680"},{"price":"61841.30","quantity":"0.975"},{"price":"61842.50","quantity":"0.588"},{"price":"61844.80","quantity":"0.017"},{"price":"61844.90","quantity":"0.001"},{"price":"61846.30","quantity":"0.333"},{"price":"61847.70","quantity":"1.205"},{"price":"61849.10","quantity":"0.003"},{"price":"61849.20","quantity":"1.204"},{"price":"61849.30","quantity":"0.374"},{"price":"61850.10","quantity":"0.000"},{"price":"61850.20","quantity":"0.051"},{"price":"61852.20","quantity":"0.846"},{"price":"61853.60","quantity":"0.001"},{"price":"61853.70","quantity":"1.607"}],"asks":[{"price":"61853.80","quantity":"7.965"},{"price":"61854.40","quantity":"0.002"},{"price":"61854.50","quantity":"0.001"},{"price":"61855.10","quantity":"0.061"},{"price":"61856.10","quantity":"0.000"},{"price":"61856.60","quantity":"0.164"},{"price":"61862.50","quantity":"0.001"},{"price":"61862.60","quantity":"0.007"},{"price":"61863.90","quantity":"1.036"},{"price":"61865.70","quantity":"0.474"},{"price":"61872.00","quantity":"0.340"},{"price":"61879.20","quantity":"0.005"},{"price":"61882.20","quantity":"0.751"},{"price":"61890.90","quantity":"0.246"},{"price":"61898.20","quantity":"0.638"},{"price":"61920.00","quantity":"1.350"},{"price":"61924.50","quantity":"1.529"},{"price":"61924.70","quantity":"0.000"},{"price":"61926.30","quantity":"0.722"},{"price":"61926.40","quantity":"12.227"},{"price":"61944.90","quantity":"1.538"},{"price":"61945.00","quantity":"0.003"},{"price":"61965.20","quantity":"2.360"},{"price":"61965.40","quantity":"0.000"},{"price":"62000.00","quantity":"13.201"},{"price":"62080.00","quantity":"0.467"},{"price":"62136.50","quantity":"0.108"},{"price":"62160.00","quantity":"0.462"},{"price":"62240.00","quantity":"0.457"},{"price":"62450.00","quantity":"3.927"},{"price":"62472.30","quantity":"0.000"},{"price":"62530.80","quantity":"0.720"},{"price":"62565.10","quantity":"0.476"},{"price":"62565.70","quantity":"1.898"},{"price":"63090.80","quantity":"0.009"},{"price":"89523.20","quantity":"0.714"}],"raw":{"e":"depthUpdate","E":1783517066496,"T":1783517066494,"s":"BTCUSDT","ps":"BTCUSDT","U":10999770545134,"u":10999770557223,"pu":10999770545000,"b":[["1000.00","207.692"],["11353.70","0.832"],["11452.20","1.872"],["11553.70","0.442"],["11652.20","0.204"],["55668.30","0.002"],["58761.00","0.000"],["59379.50","0.001"],["60765.50","0.822"],["61107.80","5.918"],["61235.20","0.025"],["61397.70","0.264"],["61520.00","3.097"],["61600.00","56.975"],["61680.00","0.889"],["61740.90","0.747"],["61760.00","1.098"],["61762.10","1.547"],["61762.30","0.023"],["61769.50","0.092"],["61770.00","1.664"],["61782.40","1.567"],["61782.60","0.003"],["61784.20","34.159"],["61785.90","7.014"],["61786.00","0.002"],["61792.90","0.227"],["61796.10","0.661"],["61802.70","9.395"],["61802.90","0.856"],["61807.90","0.000"],["61810.10","0.003"],["61813.30","2.146"],["61814.80","0.074"],["61820.20","0.183"],["61822.50","0.061"],["61831.60","0.042"],["61833.50","0.000"],["61833.60","0.055"],["61834.00","1.414"],["61837.40","0.812"],["61837.60","1.244"],["61837.90","1.483"],["61838.30","0.003"],["61838.80","0.171"],["61840.00","0.680"],["61841.30","0.975"],["61842.50","0.588"],["61844.80","0.017"],["61844.90","0.001"],["61846.30","0.333"],["61847.70","1.205"],["61849.10","0.003"],["61849.20","1.204"],["61849.30","0.374"],["61850.10","0.000"],["61850.20","0.051"],["61852.20","0.846"],["61853.60","0.001"],["61853.70","1.607"]],"a":[["61853.80","7.965"],["61854.40","0.002"],["61854.50","0.001"],["61855.10","0.061"],["61856.10","0.000"],["61856.60","0.164"],["61862.50","0.001"],["61862.60","0.007"],["61863.90","1.036"],["61865.70","0.474"],["61872.00","0.340"],["61879.20","0.005"],["61882.20","0.751"],["61890.90","0.246"],["61898.20","0.638"],["61920.00","1.350"],["61924.50","1.529"],["61924.70","0.000"],["61926.30","0.722"],["61926.40","12.227"],["61944.90","1.538"],["61945.00","0.003"],["61965.20","2.360"],["61965.40","0.000"],["62000.00","13.201"],["62080.00","0.467"],["62136.50","0.108"],["62160.00","0.462"],["62240.00","0.457"],["62450.00","3.927"],["62472.30","0.000"],["62530.80","0.720"],["62565.10","0.476"],["62565.70","1.898"],["63090.80","0.009"],["89523.20","0.714"]],"st":1}}
{"schema_version":"1.3.0","event_id":"ca0ab5ee-8524-4e92-a993-b8d7f0221bec","event_type":"raw.depth_update","source":"binance_market_data_recorder","venue":"binance_usdm","market_type":"perpetual_futures","symbol":"BTCUSDT","event_time_ms":1783517066598,"received_time_ms":1783517067206,"trace_id":"ea907a22-c7fa-4d9e-ad16-e0c053fed3a8","first_update_id":10999770557565,"final_update_id":10999770567076,"previous_final_update_id":10999770557223,"bids":[{"price":"11353.70","quantity":"1.104"},{"price":"11452.20","quantity":"1.600"},{"price":"11553.70","quantity":"0.595"},{"price":"11652.20","quantity":"0.051"},{"price":"55668.30","quantity":"0.002"},{"price":"58623.90","quantity":"0.002"},{"price":"58761.00","quantity":"0.000"},{"price":"59379.50","quantity":"0.004"},{"price":"61110.00","quantity":"5.794"},{"price":"61222.70","quantity":"0.000"},{"price":"61235.20","quantity":"0.025"},{"price":"61283.40","quantity":"0.000"},{"price":"61360.00","quantity":"2.308"},{"price":"61671.50","quantity":"0.002"},{"price":"61775.80","quantity":"36.292"},{"price":"61776.80","quantity":"7.528"},{"price":"61784.00","quantity":"1.582"},{"price":"61784.20","quantity":"0.002"},{"price":"61784.60","quantity":"0.002"},{"price":"61784.80","quantity":"0.000"},{"price":"61785.10","quantity":"0.001"},{"price":"61785.40","quantity":"0.000"},{"price":"61785.60","quantity":"0.009"},{"price":"61785.90","quantity":"0.223"},{"price":"61786.30","quantity":"0.002"},{"price":"61789.00","quantity":"1.484"},{"price":"61791.80","quantity":"0.045"},{"price":"61803.90","quantity":"0.166"},{"price":"61804.20","quantity":"2.864"},{"price":"61804.50","quantity":"0.087"},{"price":"61804.80","quantity":"0.003"},{"price":"61805.00","quantity":"6.582"},{"price":"61805.30","quantity":"1.345"},{"price":"61814.20","quantity":"0.176"},{"price":"61818.80","quantity":"0.276"},{"price":"61818.90","quantity":"0.000"},{"price":"61819.00","quantity":"0.974"},{"price":"61819.10","quantity":"0.000"},{"price":"61819.40","quantity":"0.040"},{"price":"61819.50","quantity":"0.002"},{"price":"61820.00","quantity":"50.424"},{"price":"61821.10","quantity":"0.247"},{"price":"61821.50","quantity":"0.274"},{"price":"61821.70","quantity":"1.208"},{"price":"61823.30","quantity":"2.021"},{"price":"61825.00","quantity":"3.174"},{"price":"61826.60","quantity":"0.113"},{"price":"61828.90","quantity":"1.061"},{"price":"61830.40","quantity":"0.419"},{"price":"61832.70","quantity":"0.009"},{"price":"61833.30","quantity":"0.000"},{"price":"61835.20","quantity":"1.004"},{"price":"61840.60","quantity":"0.566"},{"price":"61840.80","quantity":"0.160"},{"price":"61842.10","quantity":"0.003"},{"price":"61842.20","quantity":"0.001"},{"price":"61842.30","quantity":"0.000"},{"price":"61842.40","quantity":"0.616"},{"price":"61842.70","quantity":"0.001"},{"price":"61842.80","quantity":"0.101"},{"price":"61843.00","quantity":"0.001"},{"price":"61843.30","quantity":"0.013"},{"price":"61843.50","quantity":"0.002"},{"price":"61843.80","quantity":"0.262"},{"price":"61844.00","quantity":"0.032"},{"price":"61844.40","quantity":"0.236"},{"price":"61847.20","quantity":"0.007"},{"price":"61847.80","quantity":"0.491"},{"price":"61847.90","quantity":"0.004"},{"price":"61850.00","quantity":"0.358"},{"price":"61850.60","quantity":"0.000"},{"price":"61851.80","quantity":"0.049"},{"price":"61852.20","quantity":"0.823"},{"price":"61853.20","quantity":"0.003"},{"price":"61853.40","quantity":"0.004"},{"price":"61853.60","quantity":"0.002"},{"price":"61853.70","quantity":"1.627"}],"asks":[{"price":"61853.90","quantity":"0.006"},{"price":"61856.60","quantity":"0.001"},{"price":"61856.70","quantity":"0.012"},{"price":"61857.00","quantity":"0.713"},{"price":"61857.30","quantity":"0.002"},{"price":"61857.40","quantity":"1.005"},{"price":"61857.70","quantity":"0.007"},{"price":"61857.80","quantity":"0.578"},{"price":"61857.90","quantity":"0.162"},{"price":"61858.00","quantity":"0.011"},{"price":"61858.20","quantity":"0.128"},{"price":"61858.30","quantity":"0.011"},{"price":"61858.50","quantity":"0.004"},{"price":"61858.60","quantity":"0.001"},{"price":"61858.70","quantity":"0.001"},{"price":"61859.60","quantity":"0.563"},{"price":"61860.30","quantity":"0.216"},{"price":"61860.60","quantity":"0.230"},{"price":"61861.00","quantity":"0.185"},{"price":"61861.80","quantity":"0.000"},{"price":"61862.30","quantity":"0.907"},{"price":"61862.50","quantity":"0.969"},{"price":"61862.70","quantity":"2.745"},{"price":"61864.00","quantity":"2.735"},{"price":"61865.80","quantity":"0.000"},{"price":"61876.00","quantity":"0.125"},{"price":"61876.40","quantity":"0.944"},{"price":"61876.70","quantity":"0.048"},{"price":"61877.00","quantity":"0.050"},{"price":"61877.30","quantity":"0.229"},{"price":"61877.40","quantity":"0.003"},{"price":"61878.50","quantity":"0.624"},{"price":"61880.00","quantity":"0.119"},{"price":"61880.60","quantity":"0.210"},{"price":"61880.70","quantity":"0.074"},{"price":"61881.20","quantity":"0.122"},{"price":"61881.30","quantity":"0.681"},{"price":"61881.60","quantity":"0.003"},{"price":"61881.80","quantity":"0.027"},{"price":"61881.90","quantity":"0.035"},{"price":"61883.20","quantity":"0.007"},{"price":"61883.30","quantity":"0.002"},{"price":"61883.60","quantity":"0.308"},{"price":"61883.70","quantity":"0.004"},{"price":"61884.30","quantity":"0.139"},{"price":"61884.40","quantity":"0.005"},{"price":"61888.80","quantity":"0.115"},{"price":"61893.30","quantity":"0.307"},{"price":"61893.50","quantity":"0.388"},{"price":"61895.40","quantity":"0.096"},{"price":"61895.70","quantity":"0.030"},{"price":"61895.80","quantity":"0.030"},{"price":"61896.10","quantity":"0.001"},{"price":"61896.40","quantity":"0.946"},{"price":"61896.80","quantity":"0.449"},{"price":"61908.30","quantity":"0.127"},{"price":"61909.00","quantity":"0.133"},{"price":"61913.50","quantity":"5.754"},{"price":"61915.70","quantity":"0.294"},{"price":"61916.30","quantity":"25.272"},{"price":"61916.40","quantity":"3.237"},{"price":"61918.40","quantity":"0.000"},{"price":"62061.80","quantity":"0.824"},{"price":"62086.80","quantity":"0.359"},{"price":"62086.90","quantity":"1.121"},{"price":"62087.50","quantity":"0.000"},{"price":"62472.30","quantity":"0.000"},{"price":"62569.90","quantity":"1.916"},{"price":"62596.00","quantity":"0.971"},{"price":"62657.90","quantity":"0.319"},{"price":"62732.60","quantity":"0.005"}],"raw":{"e":"depthUpdate","E":1783517066598,"T":1783517066597,"s":"BTCUSDT","ps":"BTCUSDT","U":10999770557565,"u":10999770567076,"pu":10999770557223,"b":[["11353.70","1.104"],["11452.20","1.600"],["11553.70","0.595"],["11652.20","0.051"],["55668.30","0.002"],["58623.90","0.002"],["58761.00","0.000"],["59379.50","0.004"],["61110.00","5.794"],["61222.70","0.000"],["61235.20","0.025"],["61283.40","0.000"],["61360.00","2.308"],["61671.50","0.002"],["61775.80","36.292"],["61776.80","7.528"],["61784.00","1.582"],["61784.20","0.002"],["61784.60","0.002"],["61784.80","0.000"],["61785.10","0.001"],["61785.40","0.000"],["61785.60","0.009"],["61785.90","0.223"],["61786.30","0.002"],["61789.00","1.484"],["61791.80","0.045"],["61803.90","0.166"],["61804.20","2.864"],["61804.50","0.087"],["61804.80","0.003"],["61805.00","6.582"],["61805.30","1.345"],["61814.20","0.176"],["61818.80","0.276"],["61818.90","0.000"],["61819.00","0.974"],["61819.10","0.000"],["61819.40","0.040"],["61819.50","0.002"],["61820.00","50.424"],["61821.10","0.247"],["61821.50","0.274"],["61821.70","1.208"],["61823.30","2.021"],["61825.00","3.174"],["61826.60","0.113"],["61828.90","1.061"],["61830.40","0.419"],["61832.70","0.009"],["61833.30","0.000"],["61835.20","1.004"],["61840.60","0.566"],["61840.80","0.160"],["61842.10","0.003"],["61842.20","0.001"],["61842.30","0.000"],["61842.40","0.616"],["61842.70","0.001"],["61842.80","0.101"],["61843.00","0.001"],["61843.30","0.013"],["61843.50","0.002"],["61843.80","0.262"],["61844.00","0.032"],["61844.40","0.236"],["61847.20","0.007"],["61847.80","0.491"],["61847.90","0.004"],["61850.00","0.358"],["61850.60","0.000"],["61851.80","0.049"],["61852.20","0.823"],["61853.20","0.003"],["61853.40","0.004"],["61853.60","0.002"],["61853.70","1.627"]],"a":[["61853.90","0.006"],["61856.60","0.001"],["61856.70","0.012"],["61857.00","0.713"],["61857.30","0.002"],["61857.40","1.005"],["61857.70","0.007"],["61857.80","0.578"],["61857.90","0.162"],["61858.00","0.011"],["61858.20","0.128"],["61858.30","0.011"],["61858.50","0.004"],["61858.60","0.001"],["61858.70","0.001"],["61859.60","0.563"],["61860.30","0.216"],["61860.60","0.230"],["61861.00","0.185"],["61861.80","0.000"],["61862.30","0.907"],["61862.50","0.969"],["61862.70","2.745"],["61864.00","2.735"],["61865.80","0.000"],["61876.00","0.125"],["61876.40","0.944"],["61876.70","0.048"],["61877.00","0.050"],["61877.30","0.229"],["61877.40","0.003"],["61878.50","0.624"],["61880.00","0.119"],["61880.60","0.210"],["61880.70","0.074"],["61881.20","0.122"],["61881.30","0.681"],["61881.60","0.003"],["61881.80","0.027"],["61881.90","0.035"],["61883.20","0.007"],["61883.30","0.002"],["61883.60","0.308"],["61883.70","0.004"],["61884.30","0.139"],["61884.40","0.005"],["61888.80","0.115"],["61893.30","0.307"],["61893.50","0.388"],["61895.40","0.096"],["61895.70","0.030"],["61895.80","0.030"],["61896.10","0.001"],["61896.40","0.946"],["61896.80","0.449"],["61908.30","0.127"],["61909.00","0.133"],["61913.50","5.754"],["61915.70","0.294"],["61916.30","25.272"],["61916.40","3.237"],["61918.40","0.000"],["62061.80","0.824"],["62086.80","0.359"],["62086.90","1.121"],["62087.50","0.000"],["62472.30","0.000"],["62569.90","1.916"],["62596.00","0.971"],["62657.90","0.319"],["62732.60","0.005"]],"st":1}}
{"schema_version":"1.3.0","event_id":"512e7d22-b365-459a-931c-76075612b869","event_type":"raw.depth_update","source":"binance_market_data_recorder","venue":"binance_usdm","market_type":"perpetual_futures","symbol":"BTCUSDT","event_time_ms":1783517066700,"received_time_ms":1783517067232,"trace_id":"fef374cd-f235-49eb-a508-e692726b4925","first_update_id":10999770567250,"final_update_id":10999770574901,"previous_final_update_id":10999770567076,"bids":[{"price":"1000.00","quantity":"207.692"},{"price":"11353.70","quantity":"1.376"},{"price":"11452.20","quantity":"1.328"},{"price":"11453.70","quantity":"0.085"},{"price":"11553.70","quantity":"0.561"},{"price":"11652.20","quantity":"0.000"},{"price":"49483.00","quantity":"0.000"},{"price":"55668.30","quantity":"0.002"},{"price":"59379.50","quantity":"0.001"},{"price":"60615.20","quantity":"0.033"},{"price":"60955.30","quantity":"14.911"},{"price":"61024.10","quantity":"0.821"},{"price":"61235.20","quantity":"0.025"},{"price":"61295.50","quantity":"2.370"},{"price":"61542.90","quantity":"0.000"},{"price":"61543.90","quantity":"0.011"},{"price":"61775.80","quantity":"2.135"},{"price":"61776.80","quantity":"2.746"},{"price":"61786.30","quantity":"34.159"},{"price":"61789.00","quantity":"6.403"},{"price":"61805.60","quantity":"0.331"},{"price":"61809.30","quantity":"0.053"},{"price":"61820.20","quantity":"0.134"},{"price":"61821.00","quantity":"0.735"},{"price":"61823.20","quantity":"0.359"},{"price":"61823.50","quantity":"0.003"},{"price":"61823.80","quantity":"0.017"},{"price":"61826.60","quantity":"0.695"},{"price":"61826.90","quantity":"0.124"},{"price":"61827.40","quantity":"0.613"},{"price":"61828.90","quantity":"1.384"},{"price":"61830.50","quantity":"0.021"},{"price":"61831.30","quantity":"3.103"},{"price":"61832.10","quantity":"0.067"},{"price":"61832.80","quantity":"0.343"},{"price":"61835.10","quantity":"1.874"},{"price":"61837.30","quantity":"0.805"},{"price":"61838.60","quantity":"0.016"},{"price":"61840.70","quantity":"1.292"},{"price":"61840.90","quantity":"0.286"},{"price":"61841.30","quantity":"1.056"},{"price":"61841.60","quantity":"0.055"},{"price":"61842.50","quantity":"0.689"},{"price":"61843.90","quantity":"0.120"},{"price":"61844.40","quantity":"0.328"},{"price":"61846.30","quantity":"0.203"},{"price":"61847.50","quantity":"0.131"},{"price":"61847.60","quantity":"0.006"},{"price":"61847.90","quantity":"0.134"},{"price":"61852.20","quantity":"0.636"},{"price":"61853.60","quantity":"0.003"},{"price":"61853.70","quantity":"2.135"}],"asks":[{"price":"61853.80","quantity":"7.964"},{"price":"61854.40","quantity":"0.003"},{"price":"61856.90","quantity":"0.002"},{"price":"61857.30","quantity":"0.003"},{"price":"61858.40","quantity":"0.001"},{"price":"61860.30","quantity":"0.322"},{"price":"61860.40","quantity":"0.178"},{"price":"61860.90","quantity":"0.312"},{"price":"61862.40","quantity":"0.374"},{"price":"61862.50","quantity":"0.001"},{"price":"61863.30","quantity":"0.002"},{"price":"61863.60","quantity":"0.493"},{"price":"61863.80","quantity":"0.971"},{"price":"61863.90","quantity":"0.470"},{"price":"61864.00","quantity":"2.719"},{"price":"61864.60","quantity":"0.066"},{"price":"61865.60","quantity":"0.586"},{"price":"61865.70","quantity":"0.472"},{"price":"61866.40","quantity":"0.001"},{"price":"61866.60","quantity":"0.203"},{"price":"61866.90","quantity":"0.103"},{"price":"61867.20","quantity":"0.054"},{"price":"61867.80","quantity":"0.205"},{"price":"61868.40","quantity":"0.017"},{"price":"61869.70","quantity":"0.011"},{"price":"61873.10","quantity":"0.165"},{"price":"61876.90","quantity":"0.602"},{"price":"61879.00","quantity":"0.069"},{"price":"61879.30","quantity":"1.912"},{"price":"61879.70","quantity":"0.154"},{"price":"61881.10","quantity":"0.002"},{"price":"61883.70","quantity":"0.166"},{"price":"61884.20","quantity":"0.315"},{"price":"61887.90","quantity":"0.499"},{"price":"61897.10","quantity":"0.306"},{"price":"61907.90","quantity":"0.107"},{"price":"61908.00","quantity":"0.003"},{"price":"61908.20","quantity":"0.665"},{"price":"61908.70","quantity":"0.016"},{"price":"61909.00","quantity":"0.032"},{"price":"61913.50","quantity":"2.244"},{"price":"61914.10","quantity":"0.261"},{"price":"61916.30","quantity":"25.272"},{"price":"61916.40","quantity":"6.520"},{"price":"61918.40","quantity":"0.000"},{"price":"62472.30","quantity":"0.000"},{"price":"89523.20","quantity":"0.720"}],"raw":{"e":"depthUpdate","E":1783517066700,"T":1783517066697,"s":"BTCUSDT","ps":"BTCUSDT","U":10999770567250,"u":10999770574901,"pu":10999770567076,"b":[["1000.00","207.692"],["11353.70","1.376"],["11452.20","1.328"],["11453.70","0.085"],["11553.70","0.561"],["11652.20","0.000"],["49483.00","0.000"],["55668.30","0.002"],["59379.50","0.001"],["60615.20","0.033"],["60955.30","14.911"],["61024.10","0.821"],["61235.20","0.025"],["61295.50","2.370"],["61542.90","0.000"],["61543.90","0.011"],["61775.80","2.135"],["61776.80","2.746"],["61786.30","34.159"],["61789.00","6.403"],["61805.60","0.331"],["61809.30","0.053"],["61820.20","0.134"],["61821.00","0.735"],["61823.20","0.359"],["61823.50","0.003"],["61823.80","0.017"],["61826.60","0.695"],["61826.90","0.124"],["61827.40","0.613"],["61828.90","1.384"],["61830.50","0.021"],["61831.30","3.103"],["61832.10","0.067"],["61832.80","0.343"],["61835.10","1.874"],["61837.30","0.805"],["61838.60","0.016"],["61840.70","1.292"],["61840.90","0.286"],["61841.30","1.056"],["61841.60","0.055"],["61842.50","0.689"],["61843.90","0.120"],["61844.40","0.328"],["61846.30","0.203"],["61847.50","0.131"],["61847.60","0.006"],["61847.90","0.134"],["61852.20","0.636"],["61853.60","0.003"],["61853.70","2.135"]],"a":[["61853.80","7.964"],["61854.40","0.003"],["61856.90","0.002"],["61857.30","0.003"],["61858.40","0.001"],["61860.30","0.322"],["61860.40","0.178"],["61860.90","0.312"],["61862.40","0.374"],["61862.50","0.001"],["61863.30","0.002"],["61863.60","0.493"],["61863.80","0.971"],["61863.90","0.470"],["61864.00","2.719"],["61864.60","0.066"],["61865.60","0.586"],["61865.70","0.472"],["61866.40","0.001"],["61866.60","0.203"],["61866.90","0.103"],["61867.20","0.054"],["61867.80","0.205"],["61868.40","0.017"],["61869.70","0.011"],["61873.10","0.165"],["61876.90","0.602"],["61879.00","0.069"],["61879.30","1.912"],["61879.70","0.154"],["61881.10","0.002"],["61883.70","0.166"],["61884.20","0.315"],["61887.90","0.499"],["61897.10","0.306"],["61907.90","0.107"],["61908.00","0.003"],["61908.20","0.665"],["61908.70","0.016"],["61909.00","0.032"],["61913.50","2.244"],["61914.10","0.261"],["61916.30","25.272"],["61916.40","6.520"],["61918.40","0.000"],["62472.30","0.000"],["89523.20","0.720"]],"st":1}}
{"schema_version":"1.3.0","event_id":"6594df29-0dd8-4fb1-b920-f76e40f41f28","event_type":"raw.depth_update","source":"binance_market_data_recorder","venue":"binance_usdm","market_type":"perpetual_futures","symbol":"BTCUSDT","event_time_ms":1783517066802,"received_time_ms":1783517067242,"trace_id":"ca46a3cd-9fff-4a9f-8bc5-1a7ec3936fb9","first_update_id":10999770575010,"final_update_id":10999770581814,"previous_final_update_id":10999770574901,"bids":[{"price":"1000.00","quantity":"207.692"},{"price":"11353.70","quantity":"1.648"},{"price":"11452.20","quantity":"1.056"},{"price":"11453.70","quantity":"0.238"},{"price":"11553.70","quantity":"0.408"},{"price":"55668.30","quantity":"0.002"},{"price":"58760.50","quantity":"0.003"},{"price":"59379.50","quantity":"0.004"},{"price":"60781.60","quantity":"0.000"},{"price":"61235.20","quantity":"0.025"},{"price":"61301.70","quantity":"2.794"},{"price":"61399.90","quantity":"2.071"},{"price":"61544.40","quantity":"0.003"},{"price":"61593.50","quantity":"0.001"},{"price":"61593.90","quantity":"0.144"},{"price":"61756.70","quantity":"0.000"},{"price":"61762.80","quantity":"2.425"},{"price":"61770.10","quantity":"0.002"},{"price":"61775.80","quantity":"2.135"},{"price":"61776.80","quantity":"2.746"},{"price":"61786.30","quantity":"34.159"},{"price":"61789.00","quantity":"6.403"},{"price":"61805.00","quantity":"6.614"},{"price":"61806.10","quantity":"0.039"},{"price":"61818.00","quantity":"3.658"},{"price":"61825.50","quantity":"0.590"},{"price":"61826.60","quantity":"0.113"},{"price":"61833.00","quantity":"0.034"},{"price":"61834.40","quantity":"0.688"},{"price":"61835.20","quantity":"0.438"},{"price":"61840.10","quantity":"0.002"},{"price":"61841.00","quantity":"0.899"},{"price":"61841.30","quantity":"0.975"},{"price":"61843.20","quantity":"0.188"},{"price":"61843.50","quantity":"0.062"},{"price":"61843.80","quantity":"0.414"},{"price":"61844.90","quantity":"0.033"},{"price":"61850.30","quantity":"0.002"},{"price":"61852.20","quantity":"0.638"},{"price":"61853.70","quantity":"1.816"}],"asks":[{"price":"61853.80","quantity":"7.969"},{"price":"61856.70","quantity":"0.917"},{"price":"61857.80","quantity":"1.058"},{"price":"61859.60","quantity":"0.726"},{"price":"61860.10","quantity":"2.140"},{"price":"61860.40","quantity":"0.987"},{"price":"61860.90","quantity":"0.684"},{"price":"61861.00","quantity":"0.271"},{"price":"61861.30","quantity":"0.225"},{"price":"61861.50","quantity":"0.206"},{"price":"61861.60","quantity":"0.319"},{"price":"61862.00","quantity":"1.131"},{"price":"61862.30","quantity":"0.002"},{"price":"61862.40","quantity":"0.373"},{"price":"61863.80","quantity":"0.003"},{"price":"61871.20","quantity":"0.027"},{"price":"61879.00","quantity":"0.232"},{"price":"61880.30","quantity":"1.079"},{"price":"61880.40","quantity":"0.371"},{"price":"61882.20","quantity":"1.076"},{"price":"61884.20","quantity":"0.495"},{"price":"61884.60","quantity":"0.183"},{"price":"61884.80","quantity":"0.254"},{"price":"61884.90","quantity":"0.332"},{"price":"61904.80","quantity":"0.487"},{"price":"61905.20","quantity":"0.121"},{"price":"61907.60","quantity":"0.000"},{"price":"61907.70","quantity":"0.412"},{"price":"61908.20","quantity":"0.564"},{"price":"61913.50","quantity":"2.244"},{"price":"61916.30","quantity":"0.149"},{"price":"61916.40","quantity":"6.520"},{"price":"61918.40","quantity":"25.123"},{"price":"61971.50","quantity":"0.860"},{"price":"61976.20","quantity":"2.427"},{"price":"62161.60","quantity":"0.001"},{"price":"62163.10","quantity":"0.002"},{"price":"62472.30","quantity":"0.000"},{"price":"62532.70","quantity":"4.299"},{"price":"62623.20","quantity":"2.662"},{"price":"62693.80","quantity":"0.000"},{"price":"63089.30","quantity":"0.135"}],"raw":{"e":"depthUpdate","E":1783517066802,"T":1783517066801,"s":"BTCUSDT","ps":"BTCUSDT","U":10999770575010,"u":10999770581814,"pu":10999770574901,"b":[["1000.00","207.692"],["11353.70","1.648"],["11452.20","1.056"],["11453.70","0.238"],["11553.70","0.408"],["55668.30","0.002"],["58760.50","0.003"],["59379.50","0.004"],["60781.60","0.000"],["61235.20","0.025"],["61301.70","2.794"],["61399.90","2.071"],["61544.40","0.003"],["61593.50","0.001"],["61593.90","0.144"],["61756.70","0.000"],["61762.80","2.425"],["61770.10","0.002"],["61775.80","2.135"],["61776.80","2.746"],["61786.30","34.159"],["61789.00","6.403"],["61805.00","6.614"],["61806.10","0.039"],["61818.00","3.658"],["61825.50","0.590"],["61826.60","0.113"],["61833.00","0.034"],["61834.40","0.688"],["61835.20","0.438"],["61840.10","0.002"],["61841.00","0.899"],["61841.30","0.975"],["61843.20","0.188"],["61843.50","0.062"],["61843.80","0.414"],["61844.90","0.033"],["61850.30","0.002"],["61852.20","0.638"],["61853.70","1.816"]],"a":[["61853.80","7.969"],["61856.70","0.917"],["61857.80","1.058"],["61859.60","0.726"],["61860.10","2.140"],["61860.40","0.987"],["61860.90","0.684"],["61861.00","0.271"],["61861.30","0.225"],["61861.50","0.206"],["61861.60","0.319"],["61862.00","1.131"],["61862.30","0.002"],["61862.40","0.373"],["61863.80","0.003"],["61871.20","0.027"],["61879.00","0.232"],["61880.30","1.079"],["61880.40","0.371"],["61882.20","1.076"],["61884.20","0.495"],["61884.60","0.183"],["61884.80","0.254"],["61884.90","0.332"],["61904.80","0.487"],["61905.20","0.121"],["61907.60","0.000"],["61907.70","0.412"],["61908.20","0.564"],["61913.50","2.244"],["61916.30","0.149"],["61916.40","6.520"],["61918.40","25.123"],["61971.50","0.860"],["61976.20","2.427"],["62161.60","0.001"],["62163.10","0.002"],["62472.30","0.000"],["62532.70","4.299"],["62623.20","2.662"],["62693.80","0.000"],["63089.30","0.135"]],"st":1}}
{"schema_version":"1.3.0","event_id":"de0fd7b7-d771-4479-b348-8c8a4c2bb65e","event_type":"raw.depth_update","source":"binance_market_data_recorder","venue":"binance_usdm","market_type":"perpetual_futures","symbol":"BTCUSDT","event_time_ms":1783517066904,"received_time_ms":1783517067255,"trace_id":"4dc35c5b-7907-4e99-914b-b4217c8cb22f","first_update_id":10999770581980,"final_update_id":10999770588150,"previous_final_update_id":10999770581814,"bids":[{"price":"11353.70","quantity":"1.920"},{"price":"11452.20","quantity":"0.784"},{"price":"11453.70","quantity":"0.374"},{"price":"11553.70","quantity":"0.272"},{"price":"55668.30","quantity":"0.002"},{"price":"60886.60","quantity":"0.001"},{"price":"61041.90","quantity":"1.145"},{"price":"61235.20","quantity":"0.025"},{"price":"61295.50","quantity":"2.614"},{"price":"61320.00","quantity":"2.068"},{"price":"61537.60","quantity":"0.348"},{"price":"61611.00","quantity":"1.986"},{"price":"61771.60","quantity":"34.158"},{"price":"61773.60","quantity":"8.059"},{"price":"61785.90","quantity":"0.255"},{"price":"61786.30","quantity":"0.002"},{"price":"61789.00","quantity":"1.484"},{"price":"61795.30","quantity":"4.734"},{"price":"61795.40","quantity":"0.003"},{"price":"61805.90","quantity":"0.034"},{"price":"61825.00","quantity":"1.748"},{"price":"61825.80","quantity":"0.121"},{"price":"61826.90","quantity":"0.003"},{"price":"61831.30","quantity":"3.105"},{"price":"61832.50","quantity":"0.002"},{"price":"61841.90","quantity":"0.503"},{"price":"61842.00","quantity":"0.377"},{"price":"61842.10","quantity":"0.001"},{"price":"61842.50","quantity":"0.681"},{"price":"61842.60","quantity":"0.081"},{"price":"61842.80","quantity":"0.000"},{"price":"61842.90","quantity":"0.036"},{"price":"61843.20","quantity":"0.248"},{"price":"61843.50","quantity":"0.122"},{"price":"61843.70","quantity":"0.004"},{"price":"61843.80","quantity":"0.474"},{"price":"61844.60","quantity":"0.033"},{"price":"61844.80","quantity":"0.017"},{"price":"61844.90","quantity":"0.033"},{"price":"61849.40","quantity":"0.001"},{"price":"61853.70","quantity":"2.485"}],"asks":[{"price":"61853.80","quantity":"7.968"},{"price":"61854.70","quantity":"0.163"},{"price":"61857.90","quantity":"0.000"},{"price":"61860.00","quantity":"0.463"},{"price":"61860.50","quantity":"1.317"},{"price":"61861.00","quantity":"0.451"},{"price":"61861.30","quantity":"0.417"},{"price":"61861.50","quantity":"0.386"},{"price":"61862.00","quantity":"0.163"},{"price":"61862.50","quantity":"0.002"},{"price":"61862.60","quantity":"0.007"},{"price":"61862.90","quantity":"0.968"},{"price":"61866.60","quantity":"0.203"},{"price":"61866.90","quantity":"0.022"},{"price":"61872.90","quantity":"0.394"},{"price":"61873.10","quantity":"0.003"},{"price":"61879.30","quantity":"1.589"},{"price":"61879.40","quantity":"0.469"},{"price":"61880.30","quantity":"1.196"},{"price":"61884.60","quantity":"0.375"},{"price":"61884.80","quantity":"0.434"},{"price":"61893.20","quantity":"0.207"},{"price":"61893.30","quantity":"0.680"},{"price":"61893.40","quantity":"0.363"},{"price":"61893.50","quantity":"0.015"},{"price":"61897.10","quantity":"0.307"},{"price":"61899.40","quantity":"2.403"},{"price":"61970.20","quantity":"0.635"},{"price":"62472.30","quantity":"0.000"},{"price":"62589.90","quantity":"0.961"},{"price":"62725.90","quantity":"0.637"},{"price":"89523.20","quantity":"0.726"}],"raw":{"e":"depthUpdate","E":1783517066904,"T":1783517066901,"s":"BTCUSDT","ps":"BTCUSDT","U":10999770581980,"u":10999770588150,"pu":10999770581814,"b":[["11353.70","1.920"],["11452.20","0.784"],["11453.70","0.374"],["11553.70","0.272"],["55668.30","0.002"],["60886.60","0.001"],["61041.90","1.145"],["61235.20","0.025"],["61295.50","2.614"],["61320.00","2.068"],["61537.60","0.348"],["61611.00","1.986"],["61771.60","34.158"],["61773.60","8.059"],["61785.90","0.255"],["61786.30","0.002"],["61789.00","1.484"],["61795.30","4.734"],["61795.40","0.003"],["61805.90","0.034"],["61825.00","1.748"],["61825.80","0.121"],["61826.90","0.003"],["61831.30","3.105"],["61832.50","0.002"],["61841.90","0.503"],["61842.00","0.377"],["61842.10","0.001"],["61842.50","0.681"],["61842.60","0.081"],["61842.80","0.000"],["61842.90","0.036"],["61843.20","0.248"],["61843.50","0.122"],["61843.70","0.004"],["61843.80","0.474"],["61844.60","0.033"],["61844.80","0.017"],["61844.90","0.033"],["61849.40","0.001"],["61853.70","2.485"]],"a":[["61853.80","7.968"],["61854.70","0.163"],["61857.90","0.000"],["61860.00","0.463"],["61860.50","1.317"],["61861.00","0.451"],["61861.30","0.417"],["61861.50","0.386"],["61862.00","0.163"],["61862.50","0.002"],["61862.60","0.007"],["61862.90","0.968"],["61866.60","0.203"],["61866.90","0.022"],["61872.90","0.394"],["61873.10","0.003"],["61879.30","1.589"],["61879.40","0.469"],["61880.30","1.196"],["61884.60","0.375"],["61884.80","0.434"],["61893.20","0.207"],["61893.30","0.680"],["61893.40","0.363"],["61893.50","0.015"],["61897.10","0.307"],["61899.40","2.403"],["61970.20","0.635"],["62472.30","0.000"],["62589.90","0.961"],["62725.90","0.637"],["89523.20","0.726"]],"st":1}}
{"schema_version":"1.3.0","event_id":"ea79dac1-d700-4bfe-bb31-02cbbc2aebdb","event_type":"raw.depth_update","source":"binance_market_data_recorder","venue":"binance_usdm","market_type":"perpetual_futures","symbol":"BTCUSDT","event_time_ms":1783517067006,"received_time_ms":1783517067270,"trace_id":"4cc170a4-c1e3-4fda-908b-a6a876298b8e","first_update_id":10999770588364,"final_update_id":10999770597811,"previous_final_update_id":10999770588150,"bids":[{"price":"1000.00","quantity":"207.692"},{"price":"11353.70","quantity":"2.192"},{"price":"11452.20","quantity":"0.512"},{"price":"11453.70","quantity":"0.527"},{"price":"11553.70","quantity":"0.119"},{"price":"55668.30","quantity":"0.002"},{"price":"59379.50","quantity":"0.001"},{"price":"60763.30","quantity":"0.822"},{"price":"61233.60","quantity":"6.985"},{"price":"61235.20","quantity":"0.025"},{"price":"61543.90","quantity":"0.001"},{"price":"61544.40","quantity":"0.013"},{"price":"61721.80","quantity":"0.000"},{"price":"61722.50","quantity":"2.363"},{"price":"61771.60","quantity":"0.001"},{"price":"61773.60","quantity":"3.357"},{"price":"61786.20","quantity":"0.032"},{"price":"61786.30","quantity":"34.159"},{"price":"61786.70","quantity":"0.089"},{"price":"61789.00","quantity":"6.403"},{"price":"61820.50","quantity":"0.369"},{"price":"61821.10","quantity":"0.307"},{"price":"61821.20","quantity":"0.101"},{"price":"61830.40","quantity":"0.050"},{"price":"61831.70","quantity":"0.227"},{"price":"61841.70","quantity":"1.592"},{"price":"61841.80","quantity":"0.005"},{"price":"61841.90","quantity":"0.484"},{"price":"61842.00","quantity":"0.369"},{"price":"61842.90","quantity":"0.000"},{"price":"61843.10","quantity":"0.053"},{"price":"61843.20","quantity":"0.308"},{"price":"61843.40","quantity":"0.066"},{"price":"61843.70","quantity":"0.003"},{"price":"61844.80","quantity":"0.025"},{"price":"61852.20","quantity":"0.630"},{"price":"61853.70","quantity":"2.486"}],"asks":[{"price":"61853.80","quantity":"8.050"},{"price":"61854.70","quantity":"0.532"},{"price":"61856.40","quantity":"0.029"},{"price":"61860.00","quantity":"0.467"},{"price":"61861.00","quantity":"0.408"},{"price":"61861.40","quantity":"0.165"},{"price":"61861.50","quantity":"0.554"},{"price":"61861.80","quantity":"0.095"},{"price":"61862.40","quantity":"0.004"},{"price":"61866.20","quantity":"0.570"},{"price":"61868.30","quantity":"0.024"},{"price":"61870.10","quantity":"0.140"},{"price":"61870.60","quantity":"0.103"},{"price":"61872.40","quantity":"0.007"},{"price":"61878.70","quantity":"0.093"},{"price":"61880.20","quantity":"0.051"},{"price":"61883.00","quantity":"0.141"},{"price":"61884.70","quantity":"0.440"},{"price":"61884.80","quantity":"0.602"},{"price":"61888.10","quantity":"0.050"},{"price":"61898.40","quantity":"5.869"},{"price":"61899.10","quantity":"5.137"},{"price":"61904.70","quantity":"0.104"},{"price":"61910.00","quantity":"23.581"},{"price":"61985.90","quantity":"0.695"},{"price":"61986.50","quantity":"0.001"},{"price":"62470.80","quantity":"0.000"},{"price":"62472.30","quantity":"0.000"},{"price":"62627.00","quantity":"3.558"},{"price":"62694.70","quantity":"0.796"}],"raw":{"e":"depthUpdate","E":1783517067006,"T":1783517067005,"s":"BTCUSDT","ps":"BTCUSDT","U":10999770588364,"u":10999770597811,"pu":10999770588150,"b":[["1000.00","207.692"],["11353.70","2.192"],["11452.20","0.512"],["11453.70","0.527"],["11553.70","0.119"],["55668.30","0.002"],["59379.50","0.001"],["60763.30","0.822"],["61233.60","6.985"],["61235.20","0.025"],["61543.90","0.001"],["61544.40","0.013"],["61721.80","0.000"],["61722.50","2.363"],["61771.60","0.001"],["61773.60","3.357"],["61786.20","0.032"],["61786.30","34.159"],["61786.70","0.089"],["61789.00","6.403"],["61820.50","0.369"],["61821.10","0.307"],["61821.20","0.101"],["61830.40","0.050"],["61831.70","0.227"],["61841.70","1.592"],["61841.80","0.005"],["61841.90","0.484"],["61842.00","0.369"],["61842.90","0.000"],["61843.10","0.053"],["61843.20","0.308"],["61843.40","0.066"],["61843.70","0.003"],["61844.80","0.025"],["61852.20","0.630"],["61853.70","2.486"]],"a":[["61853.80","8.050"],["61854.70","0.532"],["61856.40","0.029"],["61860.00","0.467"],["61861.00","0.408"],["61861.40","0.165"],["61861.50","0.554"],["61861.80","0.095"],["61862.40","0.004"],["61866.20","0.570"],["61868.30","0.024"],["61870.10","0.140"],["61870.60","0.103"],["61872.40","0.007"],["61878.70","0.093"],["61880.20","0.051"],["61883.00","0.141"],["61884.70","0.440"],["61884.80","0.602"],["61888.10","0.050"],["61898.40","5.869"],["61899.10","5.137"],["61904.70","0.104"],["61910.00","23.581"],["61985.90","0.695"],["61986.50","0.001"],["62470.80","0.000"],["62472.30","0.000"],["62627.00","3.558"],["62694.70","0.796"]],"st":1}}
{"schema_version":"1.3.0","event_id":"733c7fa3-7c0a-4ca7-87d5-f307d325b76b","event_type":"raw.depth_update","source":"binance_market_data_recorder","venue":"binance_usdm","market_type":"perpetual_futures","symbol":"BTCUSDT","event_time_ms":1783517067108,"received_time_ms":1783517067273,"trace_id":"0718a334-2307-44fb-be24-46358db2d5c4","first_update_id":10999770597875,"final_update_id":10999770608672,"previous_final_update_id":10999770597811,"bids":[{"price":"1000.00","quantity":"207.692"},{"price":"11353.70","quantity":"2.240"},{"price":"11452.20","quantity":"0.352"},{"price":"11453.70","quantity":"0.663"},{"price":"11552.20","quantity":"1.037"},{"price":"11553.70","quantity":"0.000"},{"price":"11753.70","quantity":"0.112"},{"price":"55668.30","quantity":"0.002"},{"price":"58468.40","quantity":"0.002"},{"price":"59379.50","quantity":"0.004"},{"price":"60895.00","quantity":"1.312"},{"price":"61022.20","quantity":"0.501"},{"price":"61134.30","quantity":"0.000"},{"price":"61235.20","quantity":"0.025"},{"price":"61287.00","quantity":"0.000"},{"price":"61750.50","quantity":"0.000"},{"price":"61785.60","quantity":"0.041"},{"price":"61809.00","quantity":"0.164"},{"price":"61816.10","quantity":"0.047"},{"price":"61819.50","quantity":"0.702"},{"price":"61820.60","quantity":"0.140"},{"price":"61821.10","quantity":"0.367"},{"price":"61824.40","quantity":"0.061"},{"price":"61832.10","quantity":"0.065"},{"price":"61837.00","quantity":"1.002"},{"price":"61840.80","quantity":"0.100"},{"price":"61841.20","quantity":"0.092"},{"price":"61841.80","quantity":"0.065"},{"price":"61842.60","quantity":"0.081"},{"price":"61852.30","quantity":"0.002"},{"price":"61852.80","quantity":"0.002"}],"asks":[{"price":"61853.80","quantity":"8.059"},{"price":"61854.50","quantity":"0.028"},{"price":"61858.20","quantity":"0.130"},{"price":"61860.00","quantity":"0.463"},{"price":"61864.90","quantity":"0.054"},{"price":"61866.20","quantity":"0.566"},{"price":"61868.30","quantity":"0.009"},{"price":"61872.40","quantity":"0.003"},{"price":"61899.70","quantity":"0.089"},{"price":"61904.50","quantity":"0.282"},{"price":"61904.60","quantity":"4.290"},{"price":"61904.70","quantity":"0.003"},{"price":"61904.80","quantity":"0.386"},{"price":"62472.30","quantity":"0.002"},{"price":"62899.10","quantity":"0.480"},{"price":"89523.20","quantity":"0.732"}],"raw":{"e":"depthUpdate","E":1783517067108,"T":1783517067107,"s":"BTCUSDT","ps":"BTCUSDT","U":10999770597875,"u":10999770608672,"pu":10999770597811,"b":[["1000.00","207.692"],["11353.70","2.240"],["11452.20","0.352"],["11453.70","0.663"],["11552.20","1.037"],["11553.70","0.000"],["11753.70","0.112"],["55668.30","0.002"],["58468.40","0.002"],["59379.50","0.004"],["60895.00","1.312"],["61022.20","0.501"],["61134.30","0.000"],["61235.20","0.025"],["61287.00","0.000"],["61750.50","0.000"],["61785.60","0.041"],["61809.00","0.164"],["61816.10","0.047"],["61819.50","0.702"],["61820.60","0.140"],["61821.10","0.367"],["61824.40","0.061"],["61832.10","0.065"],["61837.00","1.002"],["61840.80","0.100"],["61841.20","0.092"],["61841.80","0.065"],["61842.60","0.081"],["61852.30","0.002"],["61852.80","0.002"]],"a":[["61853.80","8.059"],["61854.50","0.028"],["61858.20","0.130"],["61860.00","0.463"],["61864.90","0.054"],["61866.20","0.566"],["61868.30","0.009"],["61872.40","0.003"],["61899.70","0.089"],["61904.50","0.282"],["61904.60","4.290"],["61904.70","0.003"],["61904.80","0.386"],["62472.30","0.002"],["62899.10","0.480"],["89523.20","0.732"]],"st":1}}
{"schema_version":"1.3.0","event_id":"95bfc403-d073-42cd-8c92-b2bd77f9429a","event_type":"raw.depth_update","source":"binance_market_data_recorder","venue":"binance_usdm","market_type":"perpetual_futures","symbol":"BTCUSDT","event_time_ms":1783517067210,"received_time_ms":1783517067280,"trace_id":"966b9629-d3c7-4571-a487-2cda91d399c8","first_update_id":10999770608744,"final_update_id":10999770615846,"previous_final_update_id":10999770608672,"bids":[{"price":"11353.70","quantity":"2.224"},{"price":"11452.20","quantity":"0.224"},{"price":"11453.70","quantity":"0.816"},{"price":"11552.20","quantity":"0.884"},{"price":"11753.70","quantity":"0.256"},{"price":"55668.30","quantity":"0.002"},{"price":"58761.00","quantity":"0.003"},{"price":"59379.50","quantity":"0.001"},{"price":"61235.20","quantity":"0.025"},{"price":"61295.50","quantity":"3.755"},{"price":"61544.40","quantity":"0.003"},{"price":"61757.60","quantity":"0.049"},{"price":"61786.50","quantity":"0.054"},{"price":"61799.90","quantity":"0.018"},{"price":"61816.10","quantity":"0.000"},{"price":"61819.90","quantity":"0.181"},{"price":"61820.20","quantity":"0.194"},{"price":"61820.50","quantity":"0.429"},{"price":"61821.10","quantity":"0.427"},{"price":"61835.10","quantity":"1.712"},{"price":"61835.20","quantity":"0.002"},{"price":"61844.40","quantity":"0.172"},{"price":"61853.40","quantity":"0.006"},{"price":"61853.70","quantity":"2.486"}],"asks":[{"price":"61853.80","quantity":"8.450"},{"price":"61870.60","quantity":"0.100"},{"price":"61871.90","quantity":"0.364"},{"price":"61893.50","quantity":"0.388"},{"price":"61897.10","quantity":"0.309"},{"price":"61898.20","quantity":"0.265"},{"price":"61898.70","quantity":"0.226"},{"price":"62472.30","quantity":"0.000"},{"price":"62675.30","quantity":"0.000"},{"price":"62722.30","quantity":"0.000"},{"price":"63823.00","quantity":"0.600"}],"raw":{"e":"depthUpdate","E":1783517067210,"T":1783517067209,"s":"BTCUSDT","ps":"BTCUSDT","U":10999770608744,"u":10999770615846,"pu":10999770608672,"b":[["11353.70","2.224"],["11452.20","0.224"],["11453.70","0.816"],["11552.20","0.884"],["11753.70","0.256"],["55668.30","0.002"],["58761.00","0.003"],["59379.50","0.001"],["61235.20","0.025"],["61295.50","3.755"],["61544.40","0.003"],["61757.60","0.049"],["61786.50","0.054"],["61799.90","0.018"],["61816.10","0.000"],["61819.90","0.181"],["61820.20","0.194"],["61820.50","0.429"],["61821.10","0.427"],["61835.10","1.712"],["61835.20","0.002"],["61844.40","0.172"],["61853.40","0.006"],["61853.70","2.486"]],"a":[["61853.80","8.450"],["61870.60","0.100"],["61871.90","0.364"],["61893.50","0.388"],["61897.10","0.309"],["61898.20","0.265"],["61898.70","0.226"],["62472.30","0.000"],["62675.30","0.000"],["62722.30","0.000"],["63823.00","0.600"]],"st":1}}
{"schema_version":"1.3.0","event_id":"6f9e981f-5f0f-488b-bd8d-bd05fbbe09d3","event_type":"raw.depth_update","source":"binance_market_data_recorder","venue":"binance_usdm","market_type":"perpetual_futures","symbol":"BTCUSDT","event_time_ms":1783517067312,"received_time_ms":1783517067309,"trace_id":"fdaa6e7e-6e34-41d8-9530-d286e5f8dd2f","first_update_id":10999770615874,"final_update_id":10999770625502,"previous_final_update_id":10999770615846,"bids":[{"price":"1000.00","quantity":"207.692"},{"price":"11353.70","quantity":"2.240"},{"price":"11452.20","quantity":"0.080"},{"price":"11453.70","quantity":"0.952"},{"price":"11552.20","quantity":"0.748"},{"price":"11753.70","quantity":"0.384"},{"price":"55668.30","quantity":"0.002"},{"price":"58759.60","quantity":"0.011"},{"price":"58761.00","quantity":"0.006"},{"price":"60616.70","quantity":"0.014"},{"price":"61013.90","quantity":"0.825"},{"price":"61055.20","quantity":"0.002"},{"price":"61235.20","quantity":"0.025"},{"price":"61544.40","quantity":"0.013"},{"price":"61584.20","quantity":"0.076"},{"price":"61585.40","quantity":"0.008"},{"price":"61722.50","quantity":"2.143"},{"price":"61722.70","quantity":"0.830"},{"price":"61748.10","quantity":"0.006"},{"price":"61748.90","quantity":"0.284"},{"price":"61775.20","quantity":"0.055"},{"price":"61819.90","quantity":"0.241"},{"price":"61820.10","quantity":"10.723"},{"price":"61820.20","quantity":"0.254"},{"price":"61822.80","quantity":"0.400"},{"price":"61823.80","quantity":"0.009"},{"price":"61824.40","quantity":"0.121"},{"price":"61828.50","quantity":"0.003"},{"price":"61833.40","quantity":"0.008"},{"price":"61834.00","quantity":"1.402"},{"price":"61838.00","quantity":"0.000"},{"price":"61838.70","quantity":"0.127"},{"price":"61842.00","quantity":"0.470"},{"price":"61842.10","quantity":"0.102"},{"price":"61842.50","quantity":"0.682"},{"price":"61842.60","quantity":"0.089"},{"price":"61843.10","quantity":"0.052"},{"price":"61844.80","quantity":"0.017"},{"price":"61848.80","quantity":"0.002"},{"price":"61850.20","quantity":"0.002"},{"price":"61853.70","quantity":"2.473"}],"asks":[{"price":"61853.80","quantity":"8.448"},{"price":"61856.20","quantity":"0.001"},{"price":"61856.90","quantity":"0.289"},{"price":"61985.80","quantity":"0.744"},{"price":"61985.90","quantity":"0.000"},{"price":"62026.40","quantity":"0.791"},{"price":"62027.20","quantity":"0.003"},{"price":"62136.00","quantity":"0.034"},{"price":"62451.50","quantity":"0.000"},{"price":"62472.30","quantity":"0.000"},{"price":"89523.20","quantity":"0.738"}],"raw":{"e":"depthUpdate","E":1783517067312,"T":1783517067310,"s":"BTCUSDT","ps":"BTCUSDT","U":10999770615874,"u":10999770625502,"pu":10999770615846,"b":[["1000.00","207.692"],["11353.70","2.240"],["11452.20","0.080"],["11453.70","0.952"],["11552.20","0.748"],["11753.70","0.384"],["55668.30","0.002"],["58759.60","0.011"],["58761.00","0.006"],["60616.70","0.014"],["61013.90","0.825"],["61055.20","0.002"],["61235.20","0.025"],["61544.40","0.013"],["61584.20","0.076"],["61585.40","0.008"],["61722.50","2.143"],["61722.70","0.830"],["61748.10","0.006"],["61748.90","0.284"],["61775.20","0.055"],["61819.90","0.241"],["61820.10","10.723"],["61820.20","0.254"],["61822.80","0.400"],["61823.80","0.009"],["61824.40","0.121"],["61828.50","0.003"],["61833.40","0.008"],["61834.00","1.402"],["61838.00","0.000"],["61838.70","0.127"],["61842.00","0.470"],["61842.10","0.102"],["61842.50","0.682"],["61842.60","0.089"],["61843.10","0.052"],["61844.80","0.017"],["61848.80","0.002"],["61850.20","0.002"],["61853.70","2.473"]],"a":[["61853.80","8.448"],["61856.20","0.001"],["61856.90","0.289"],["61985.80","0.744"],["61985.90","0.000"],["62026.40","0.791"],["62027.20","0.003"],["62136.00","0.034"],["62451.50","0.000"],["62472.30","0.000"],["89523.20","0.738"]],"st":1}}
{"schema_version":"1.3.0","event_id":"aefe8995-8dc5-44d4-8acd-abbea451b1a3","event_type":"raw.depth_update","source":"binance_market_data_recorder","venue":"binance_usdm","market_type":"perpetual_futures","symbol":"BTCUSDT","event_time_ms":1783517067414,"received_time_ms":1783517067408,"trace_id":"e26f3eeb-4252-4e5f-9595-33c96c8c9c23","first_update_id":10999770625642,"final_update_id":10999770634790,"previous_final_update_id":10999770625502,"bids":[{"price":"1000.00","quantity":"207.692"},{"price":"11353.70","quantity":"2.128"},{"price":"11452.20","quantity":"0.000"},{"price":"11453.70","quantity":"1.105"},{"price":"11552.20","quantity":"0.595"},{"price":"11753.70","quantity":"0.576"},{"price":"55668.30","quantity":"0.002"},{"price":"59379.50","quantity":"0.004"},{"price":"61130.00","quantity":"1.987"},{"price":"61235.20","quantity":"0.025"},{"price":"61537.60","quantity":"0.348"},{"price":"61814.80","quantity":"0.004"},{"price":"61818.00","quantity":"2.958"},{"price":"61819.90","quantity":"0.301"},{"price":"61822.20","quantity":"1.083"},{"price":"61825.70","quantity":"0.012"},{"price":"61830.00","quantity":"0.974"},{"price":"61831.30","quantity":"2.137"},{"price":"61835.00","quantity":"1.037"},{"price":"61841.80","quantity":"0.166"},{"price":"61841.90","quantity":"0.383"},{"price":"61848.90","quantity":"0.002"},{"price":"61850.20","quantity":"0.051"},{"price":"61850.40","quantity":"0.000"},{"price":"61851.70","quantity":"0.001"},{"price":"61852.30","quantity":"0.002"},{"price":"61853.70","quantity":"2.600"}],"asks":[{"price":"61858.10","quantity":"0.089"},{"price":"61858.30","quantity":"0.013"},{"price":"61861.00","quantity":"0.408"},{"price":"61861.70","quantity":"0.440"},{"price":"61862.00","quantity":"1.131"},{"price":"61862.90","quantity":"0.000"},{"price":"61863.10","quantity":"0.582"},{"price":"61865.60","quantity":"0.004"},{"price":"61880.50","quantity":"0.198"},{"price":"62472.30","quantity":"0.000"},{"price":"62678.00","quantity":"1.910"},{"price":"62691.10","quantity":"0.796"},{"price":"62754.30","quantity":"0.796"}],"raw":{"e":"depthUpdate","E":1783517067414,"T":1783517067413,"s":"BTCUSDT","ps":"BTCUSDT","U":10999770625642,"u":10999770634790,"pu":10999770625502,"b":[["1000.00","207.692"],["11353.70","2.128"],["11452.20","0.000"],["11453.70","1.105"],["11552.20","0.595"],["11753.70","0.576"],["55668.30","0.002"],["59379.50","0.004"],["61130.00","1.987"],["61235.20","0.025"],["61537.60","0.348"],["61814.80","0.004"],["61818.00","2.958"],["61819.90","0.301"],["61822.20","1.083"],["61825.70","0.012"],["61830.00","0.974"],["61831.30","2.137"],["61835.00","1.037"],["61841.80","0.166"],["61841.90","0.383"],["61848.90","0.002"],["61850.20","0.051"],["61850.40","0.000"],["61851.70","0.001"],["61852.30","0.002"],["61853.70","2.600"]],"a":[["61858.10","0.089"],["61858.30","0.013"],["61861.00","0.408"],["61861.70","0.440"],["61862.00","1.131"],["61862.90","0.000"],["61863.10","0.582"],["61865.60","0.004"],["61880.50","0.198"],["62472.30","0.000"],["62678.00","1.910"],["62691.10","0.796"],["62754.30","0.796"]],"st":1}}
{"schema_version":"1.3.0","event_id":"80d228b0-3d88-4ac7-bda5-57d88bd77eab","event_type":"raw.depth_update","source":"binance_market_data_recorder","venue":"binance_usdm","market_type":"perpetual_futures","symbol":"BTCUSDT","event_time_ms":1783517067516,"received_time_ms":1783517067510,"trace_id":"d6d9890a-7740-4968-9a70-106743a6960c","first_update_id":10999770634812,"final_update_id":10999770642587,"previous_final_update_id":10999770634790,"bids":[{"price":"11353.70","quantity":"1.856"},{"price":"11453.70","quantity":"1.241"},{"price":"11552.20","quantity":"0.459"},{"price":"11753.70","quantity":"0.848"},{"price":"55668.30","quantity":"0.002"},{"price":"59379.50","quantity":"0.001"},{"price":"60275.60","quantity":"0.000"},{"price":"61034.70","quantity":"0.010"},{"price":"61235.20","quantity":"0.025"},{"price":"61544.40","quantity":"0.013"},{"price":"61673.70","quantity":"0.012"},{"price":"61674.20","quantity":"1.644"},{"price":"61704.50","quantity":"0.000"},{"price":"61705.10","quantity":"0.739"},{"price":"61735.40","quantity":"0.000"},{"price":"61735.80","quantity":"1.411"},{"price":"61750.80","quantity":"0.030"},{"price":"61766.30","quantity":"0.003"},{"price":"61775.80","quantity":"36.037"},{"price":"61776.80","quantity":"7.491"},{"price":"61786.30","quantity":"0.002"},{"price":"61788.40","quantity":"0.002"},{"price":"61789.00","quantity":"1.484"},{"price":"61821.90","quantity":"0.291"},{"price":"61828.90","quantity":"1.061"},{"price":"61837.80","quantity":"2.139"},{"price":"61838.00","quantity":"0.162"},{"price":"61838.80","quantity":"0.009"},{"price":"61839.00","quantity":"0.084"},{"price":"61841.90","quantity":"0.385"},{"price":"61842.00","quantity":"0.147"},{"price":"61844.80","quantity":"0.441"},{"price":"61850.10","quantity":"0.001"},{"price":"61853.70","quantity":"1.918"}],"asks":[{"price":"61853.80","quantity":"8.441"},{"price":"61854.50","quantity":"0.528"},{"price":"61863.10","quantity":"0.000"},{"price":"61864.50","quantity":"0.582"},{"price":"61883.90","quantity":"0.020"},{"price":"61884.00","quantity":"0.002"},{"price":"61890.20","quantity":"0.012"},{"price":"61896.40","quantity":"0.017"},{"price":"61904.80","quantity":"0.487"},{"price":"62136.50","quantity":"0.072"},{"price":"62136.70","quantity":"0.000"},{"price":"62152.10","quantity":"0.214"},{"price":"62472.30","quantity":"0.000"},{"price":"62838.80","quantity":"0.087"},{"price":"89523.20","quantity":"0.744"}],"raw":{"e":"depthUpdate","E":1783517067516,"T":1783517067513,"s":"BTCUSDT","ps":"BTCUSDT","U":10999770634812,"u":10999770642587,"pu":10999770634790,"b":[["11353.70","1.856"],["11453.70","1.241"],["11552.20","0.459"],["11753.70","0.848"],["55668.30","0.002"],["59379.50","0.001"],["60275.60","0.000"],["61034.70","0.010"],["61235.20","0.025"],["61544.40","0.013"],["61673.70","0.012"],["61674.20","1.644"],["61704.50","0.000"],["61705.10","0.739"],["61735.40","0.000"],["61735.80","1.411"],["61750.80","0.030"],["61766.30","0.003"],["61775.80","36.037"],["61776.80","7.491"],["61786.30","0.002"],["61788.40","0.002"],["61789.00","1.484"],["61821.90","0.291"],["61828.90","1.061"],["61837.80","2.139"],["61838.00","0.162"],["61838.80","0.009"],["61839.00","0.084"],["61841.90","0.385"],["61842.00","0.147"],["61844.80","0.441"],["61850.10","0.001"],["61853.70","1.918"]],"a":[["61853.80","8.441"],["61854.50","0.528"],["61863.10","0.000"],["61864.50","0.582"],["61883.90","0.020"],["61884.00","0.002"],["61890.20","0.012"],["61896.40","0.017"],["61904.80","0.487"],["62136.50","0.072"],["62136.70","0.000"],["62152.10","0.214"],["62472.30","0.000"],["62838.80","0.087"],["89523.20","0.744"]],"st":1}}
{"schema_version":"1.3.0","event_id":"f0554dfb-70b9-4440-b1af-e115eb312c65","event_type":"raw.depth_update","source":"binance_market_data_recorder","venue":"binance_usdm","market_type":"perpetual_futures","symbol":"BTCUSDT","event_time_ms":1783517067618,"received_time_ms":1783517067612,"trace_id":"78be09f5-49e8-498e-88a3-e864ca133689","first_update_id":10999770643081,"final_update_id":10999770654358,"previous_final_update_id":10999770642587,"bids":[{"price":"1000.00","quantity":"207.692"},{"price":"11353.70","quantity":"1.584"},{"price":"11453.70","quantity":"1.394"},{"price":"11552.20","quantity":"0.306"},{"price":"11753.70","quantity":"1.120"},{"price":"49483.00","quantity":"0.000"},{"price":"55668.30","quantity":"0.002"},{"price":"59379.50","quantity":"0.004"},{"price":"60280.60","quantity":"2.403"},{"price":"61235.20","quantity":"0.025"},{"price":"61380.40","quantity":"0.005"},{"price":"61841.30","quantity":"0.819"},{"price":"61842.50","quantity":"0.674"},{"price":"61842.60","quantity":"0.420"},{"price":"61844.80","quantity":"0.118"},{"price":"61844.90","quantity":"0.033"},{"price":"61845.00","quantity":"0.009"},{"price":"61852.30","quantity":"0.264"},{"price":"61853.70","quantity":"2.218"}],"asks":[{"price":"61860.20","quantity":"1.295"},{"price":"61893.30","quantity":"0.473"},{"price":"61899.20","quantity":"0.000"},{"price":"62472.30","quantity":"0.002"},{"price":"63090.80","quantity":"0.012"}],"raw":{"e":"depthUpdate","E":1783517067618,"T":1783517067617,"s":"BTCUSDT","ps":"BTCUSDT","U":10999770643081,"u":10999770654358,"pu":10999770642587,"b":[["1000.00","207.692"],["11353.70","1.584"],["11453.70","1.394"],["11552.20","0.306"],["11753.70","1.120"],["49483.00","0.000"],["55668.30","0.002"],["59379.50","0.004"],["60280.60","2.403"],["61235.20","0.025"],["61380.40","0.005"],["61841.30","0.819"],["61842.50","0.674"],["61842.60","0.420"],["61844.80","0.118"],["61844.90","0.033"],["61845.00","0.009"],["61852.30","0.264"],["61853.70","2.218"]],"a":[["61860.20","1.295"],["61893.30","0.473"],["61899.20","0.000"],["62472.30","0.002"],["63090.80","0.012"]],"st":1}}
{"schema_version":"1.3.0","event_id":"f824cbb9-8978-483a-9487-66421205b44c","event_type":"raw.depth_update","source":"binance_market_data_recorder","venue":"binance_usdm","market_type":"perpetual_futures","symbol":"BTCUSDT","event_time_ms":1783517067720,"received_time_ms":1783517067715,"trace_id":"3eee21d6-94d7-4cd5-9630-1726050a229a","first_update_id":10999770654454,"final_update_id":10999770663056,"previous_final_update_id":10999770654358,"bids":[{"price":"11353.70","quantity":"1.312"},{"price":"11453.70","quantity":"1.530"},{"price":"11552.20","quantity":"0.170"},{"price":"11753.70","quantity":"1.392"},{"price":"49483.00","quantity":"0.000"},{"price":"55668.30","quantity":"0.002"},{"price":"59379.50","quantity":"0.001"},{"price":"61235.20","quantity":"0.025"},{"price":"61289.60","quantity":"0.004"},{"price":"61830.00","quantity":"0.006"},{"price":"61831.30","quantity":"3.105"},{"price":"61832.20","quantity":"0.002"},{"price":"61835.00","quantity":"0.037"},{"price":"61838.20","quantity":"0.481"},{"price":"61839.20","quantity":"0.001"},{"price":"61839.80","quantity":"0.360"},{"price":"61840.10","quantity":"0.000"},{"price":"61842.50","quantity":"0.673"},{"price":"61843.70","quantity":"0.004"},{"price":"61847.50","quantity":"0.418"},{"price":"61850.00","quantity":"0.858"},{"price":"61852.30","quantity":"0.002"},{"price":"61853.70","quantity":"2.218"}],"asks":[{"price":"61853.80","quantity":"8.069"},{"price":"61854.70","quantity":"0.370"},{"price":"61856.60","quantity":"0.163"},{"price":"61862.00","quantity":"0.163"},{"price":"61863.20","quantity":"1.423"},{"price":"61871.20","quantity":"0.025"},{"price":"61904.50","quantity":"0.181"},{"price":"61904.60","quantity":"4.189"},{"price":"62163.10","quantity":"0.001"},{"price":"62472.30","quantity":"0.000"},{"price":"62565.30","quantity":"12.337"},{"price":"62756.90","quantity":"0.397"},{"price":"62771.90","quantity":"0.000"},{"price":"62775.60","quantity":"0.578"},{"price":"89523.20","quantity":"0.750"}],"raw":{"e":"depthUpdate","E":1783517067720,"T":1783517067718,"s":"BTCUSDT","ps":"BTCUSDT","U":10999770654454,"u":10999770663056,"pu":10999770654358,"b":[["11353.70","1.312"],["11453.70","1.530"],["11552.20","0.170"],["11753.70","1.392"],["49483.00","0.000"],["55668.30","0.002"],["59379.50","0.001"],["61235.20","0.025"],["61289.60","0.004"],["61830.00","0.006"],["61831.30","3.105"],["61832.20","0.002"],["61835.00","0.037"],["61838.20","0.481"],["61839.20","0.001"],["61839.80","0.360"],["61840.10","0.000"],["61842.50","0.673"],["61843.70","0.004"],["61847.50","0.418"],["61850.00","0.858"],["61852.30","0.002"],["61853.70","2.218"]],"a":[["61853.80","8.069"],["61854.70","0.370"],["61856.60","0.163"],["61862.00","0.163"],["61863.20","1.423"],["61871.20","0.025"],["61904.50","0.181"],["61904.60","4.189"],["62163.10","0.001"],["62472.30","0.000"],["62565.30","12.337"],["62756.90","0.397"],["62771.90","0.000"],["62775.60","0.578"],["89523.20","0.750"]],"st":1}}
{"schema_version":"1.3.0","event_id":"7b06ef10-d335-4ffa-98e0-86b45ebb36a1","event_type":"raw.depth_update","source":"binance_market_data_recorder","venue":"binance_usdm","market_type":"perpetual_futures","symbol":"BTCUSDT","event_time_ms":1783517067822,"received_time_ms":1783517067817,"trace_id":"ce3d2aec-2885-4793-b764-228ad3df3a59","first_update_id":10999770663190,"final_update_id":10999770672081,"previous_final_update_id":10999770663056,"bids":[{"price":"11353.70","quantity":"1.040"},{"price":"11453.70","quantity":"1.683"},{"price":"11552.20","quantity":"0.017"},{"price":"11753.70","quantity":"1.664"},{"price":"49483.00","quantity":"0.000"},{"price":"55668.30","quantity":"0.002"},{"price":"60615.20","quantity":"0.027"},{"price":"61235.20","quantity":"0.025"},{"price":"61358.90","quantity":"1.217"},{"price":"61399.60","quantity":"0.207"},{"price":"61544.40","quantity":"0.013"},{"price":"61606.30","quantity":"0.823"},{"price":"61722.70","quantity":"0.551"},{"price":"61722.90","quantity":"0.387"},{"price":"61748.90","quantity":"0.281"},{"price":"61749.00","quantity":"0.029"},{"price":"61757.60","quantity":"0.002"},{"price":"61775.20","quantity":"0.047"},{"price":"61777.90","quantity":"0.154"},{"price":"61816.10","quantity":"0.047"},{"price":"61823.60","quantity":"0.323"},{"price":"61825.10","quantity":"0.837"},{"price":"61825.50","quantity":"0.008"},{"price":"61829.40","quantity":"1.821"},{"price":"61829.80","quantity":"0.178"},{"price":"61830.50","quantity":"0.989"},{"price":"61830.60","quantity":"0.009"},{"price":"61831.30","quantity":"2.137"},{"price":"61836.00","quantity":"0.145"},{"price":"61840.10","quantity":"0.002"},{"price":"61842.50","quantity":"0.572"},{"price":"61843.10","quantity":"0.053"},{"price":"61843.70","quantity":"0.003"},{"price":"61846.30","quantity":"0.001"},{"price":"61851.60","quantity":"0.072"},{"price":"61853.70","quantity":"1.886"}],"asks":[{"price":"61853.80","quantity":"8.038"},{"price":"61854.40","quantity":"1.619"},{"price":"61854.80","quantity":"0.001"},{"price":"61861.40","quantity":"0.165"},{"price":"61863.50","quantity":"0.082"},{"price":"61864.40","quantity":"0.582"},{"price":"61864.50","quantity":"0.000"},{"price":"61866.50","quantity":"0.125"},{"price":"61867.60","quantity":"0.507"},{"price":"61867.80","quantity":"0.084"},{"price":"61871.20","quantity":"0.027"},{"price":"61873.80","quantity":"1.615"},{"price":"61880.50","quantity":"0.067"},{"price":"61881.80","quantity":"0.029"},{"price":"61899.30","quantity":"0.485"},{"price":"61899.40","quantity":"2.534"},{"price":"61985.80","quantity":"0.744"},{"price":"62027.20","quantity":"0.000"},{"price":"62027.30","quantity":"0.003"},{"price":"62133.20","quantity":"0.018"},{"price":"62136.00","quantity":"0.016"},{"price":"62163.10","quantity":"0.002"},{"price":"62472.30","quantity":"0.000"},{"price":"62565.70","quantity":"2.856"},{"price":"62781.70","quantity":"0.375"},{"price":"62805.50","quantity":"0.000"},{"price":"62819.10","quantity":"0.810"},{"price":"62922.30","quantity":"0.000"}],"raw":{"e":"depthUpdate","E":1783517067822,"T":1783517067821,"s":"BTCUSDT","ps":"BTCUSDT","U":10999770663190,"u":10999770672081,"pu":10999770663056,"b":[["11353.70","1.040"],["11453.70","1.683"],["11552.20","0.017"],["11753.70","1.664"],["49483.00","0.000"],["55668.30","0.002"],["60615.20","0.027"],["61235.20","0.025"],["61358.90","1.217"],["61399.60","0.207"],["61544.40","0.013"],["61606.30","0.823"],["61722.70","0.551"],["61722.90","0.387"],["61748.90","0.281"],["61749.00","0.029"],["61757.60","0.002"],["61775.20","0.047"],["61777.90","0.154"],["61816.10","0.047"],["61823.60","0.323"],["61825.10","0.837"],["61825.50","0.008"],["61829.40","1.821"],["61829.80","0.178"],["61830.50","0.989"],["61830.60","0.009"],["61831.30","2.137"],["61836.00","0.145"],["61840.10","0.002"],["61842.50","0.572"],["61843.10","0.053"],["61843.70","0.003"],["61846.30","0.001"],["61851.60","0.072"],["61853.70","1.886"]],"a":[["61853.80","8.038"],["61854.40","1.619"],["61854.80","0.001"],["61861.40","0.165"],["61863.50","0.082"],["61864.40","0.582"],["61864.50","0.000"],["61866.50","0.125"],["61867.60","0.507"],["61867.80","0.084"],["61871.20","0.027"],["61873.80","1.615"],["61880.50","0.067"],["61881.80","0.029"],["61899.30","0.485"],["61899.40","2.534"],["61985.80","0.744"],["62027.20","0.000"],["62027.30","0.003"],["62133.20","0.018"],["62136.00","0.016"],["62163.10","0.002"],["62472.30","0.000"],["62565.70","2.856"],["62781.70","0.375"],["62805.50","0.000"],["62819.10","0.810"],["62922.30","0.000"]],"st":1}}
{"schema_version":"1.3.0","event_id":"bc9bd7a5-5524-4c93-ae17-86c2b918ace7","event_type":"raw.depth_update","source":"binance_market_data_recorder","venue":"binance_usdm","market_type":"perpetual_futures","symbol":"BTCUSDT","event_time_ms":1783517067924,"received_time_ms":1783517067918,"trace_id":"9193e4d0-18d4-4a2a-8498-e71bb5ac7d00","first_update_id":10999770672253,"final_update_id":10999770680289,"previous_final_update_id":10999770672081,"bids":[{"price":"1000.00","quantity":"207.692"},{"price":"11352.20","quantity":"0.400"},{"price":"11353.20","quantity":"0.016"},{"price":"11353.70","quantity":"0.967"},{"price":"11453.70","quantity":"1.581"},{"price":"11552.20","quantity":"0.000"},{"price":"11753.70","quantity":"1.936"},{"price":"55668.30","quantity":"0.002"},{"price":"59379.50","quantity":"0.004"},{"price":"61171.80","quantity":"4.737"},{"price":"61235.20","quantity":"0.025"},{"price":"61537.60","quantity":"0.348"},{"price":"61722.90","quantity":"0.108"},{"price":"61723.00","quantity":"0.983"},{"price":"61759.10","quantity":"0.047"},{"price":"61775.80","quantity":"2.135"},{"price":"61776.80","quantity":"2.746"},{"price":"61786.30","quantity":"0.002"},{"price":"61788.40","quantity":"33.904"},{"price":"61789.00","quantity":"6.379"},{"price":"61816.10","quantity":"0.000"},{"price":"61825.00","quantity":"1.415"},{"price":"61825.40","quantity":"0.995"},{"price":"61825.80","quantity":"0.000"},{"price":"61835.40","quantity":"0.001"},{"price":"61835.50","quantity":"0.012"},{"price":"61841.90","quantity":"0.484"},{"price":"61842.00","quantity":"0.369"},{"price":"61842.10","quantity":"0.001"},{"price":"61842.50","quantity":"0.673"},{"price":"61842.60","quantity":"0.097"},{"price":"61843.10","quantity":"0.154"},{"price":"61844.80","quantity":"0.017"}],"asks":[{"price":"61853.80","quantity":"8.384"},{"price":"61856.60","quantity":"0.001"},{"price":"61858.90","quantity":"0.103"},{"price":"61873.70","quantity":"0.007"},{"price":"61878.10","quantity":"0.005"},{"price":"61893.20","quantity":"0.373"},{"price":"61893.30","quantity":"0.307"},{"price":"61893.40","quantity":"1.280"},{"price":"61985.80","quantity":"0.744"},{"price":"62407.10","quantity":"0.720"},{"price":"62472.30","quantity":"0.000"},{"price":"62526.90","quantity":"0.240"},{"price":"62723.10","quantity":"0.000"},{"price":"62747.90","quantity":"0.795"},{"price":"89523.20","quantity":"0.756"}],"raw":{"e":"depthUpdate","E":1783517067924,"T":1783517067923,"s":"BTCUSDT","ps":"BTCUSDT","U":10999770672253,"u":10999770680289,"pu":10999770672081,"b":[["1000.00","207.692"],["11352.20","0.400"],["11353.20","0.016"],["11353.70","0.967"],["11453.70","1.581"],["11552.20","0.000"],["11753.70","1.936"],["55668.30","0.002"],["59379.50","0.004"],["61171.80","4.737"],["61235.20","0.025"],["61537.60","0.348"],["61722.90","0.108"],["61723.00","0.983"],["61759.10","0.047"],["61775.80","2.135"],["61776.80","2.746"],["61786.30","0.002"],["61788.40","33.904"],["61789.00","6.379"],["61816.10","0.000"],["61825.00","1.415"],["61825.40","0.995"],["61825.80","0.000"],["61835.40","0.001"],["61835.50","0.012"],["61841.90","0.484"],["61842.00","0.369"],["61842.10","0.001"],["61842.50","0.673"],["61842.60","0.097"],["61843.10","0.154"],["61844.80","0.017"]],"a":[["61853.80","8.384"],["61856.60","0.001"],["61858.90","0.103"],["61873.70","0.007"],["61878.10","0.005"],["61893.20","0.373"],["61893.30","0.307"],["61893.40","1.280"],["61985.80","0.744"],["62407.10","0.720"],["62472.30","0.000"],["62526.90","0.240"],["62723.10","0.000"],["62747.90","0.795"],["89523.20","0.756"]],"st":1}}
{"schema_version":"1.3.0","event_id":"74e0fb88-9718-42ec-ac18-3c4c28acc14e","event_type":"raw.depth_update","source":"binance_market_data_recorder","venue":"binance_usdm","market_type":"perpetual_futures","symbol":"BTCUSDT","event_time_ms":1783517068026,"received_time_ms":1783517068040,"trace_id":"40a05289-3a69-41aa-b209-59073a86b298","first_update_id":10999770680381,"final_update_id":10999770688919,"previous_final_update_id":10999770680289,"bids":[{"price":"11352.20","quantity":"0.256"},{"price":"11353.70","quantity":"0.992"},{"price":"11453.70","quantity":"1.428"},{"price":"11753.70","quantity":"2.208"},{"price":"55668.30","quantity":"0.002"},{"price":"58761.00","quantity":"0.006"},{"price":"59379.50","quantity":"0.001"},{"price":"61080.50","quantity":"0.246"},{"price":"61180.00","quantity":"1.630"},{"price":"61235.20","quantity":"0.025"},{"price":"61295.00","quantity":"1.173"},{"price":"61608.80","quantity":"0.202"},{"price":"61723.00","quantity":"0.709"},{"price":"61821.00","quantity":"0.999"},{"price":"61821.10","quantity":"0.863"},{"price":"61821.20","quantity":"0.597"},{"price":"61835.40","quantity":"0.003"},{"price":"61835.50","quantity":"1.014"},{"price":"61835.60","quantity":"0.131"},{"price":"61836.00","quantity":"0.064"},{"price":"61836.50","quantity":"0.023"},{"price":"61836.70","quantity":"0.003"},{"price":"61837.10","quantity":"0.002"},{"price":"61838.40","quantity":"0.014"},{"price":"61838.80","quantity":"0.012"},{"price":"61841.80","quantity":"0.106"},{"price":"61842.00","quantity":"0.371"},{"price":"61842.50","quantity":"0.674"},{"price":"61843.10","quantity":"0.153"},{"price":"61843.80","quantity":"0.272"},{"price":"61844.80","quantity":"0.118"},{"price":"61844.90","quantity":"0.033"},{"price":"61850.10","quantity":"0.050"},{"price":"61850.20","quantity":"0.002"},{"price":"61853.60","quantity":"0.002"},{"price":"61853.70","quantity":"2.513"}],"asks":[{"price":"61853.80","quantity":"8.383"},{"price":"61860.00","quantity":"0.467"},{"price":"61866.20","quantity":"0.570"},{"price":"61867.60","quantity":"0.345"},{"price":"61868.20","quantity":"0.065"},{"price":"61872.40","quantity":"0.007"},{"price":"61873.80","quantity":"1.292"},{"price":"61949.40","quantity":"0.021"},{"price":"61985.80","quantity":"0.008"},{"price":"61986.30","quantity":"0.345"},{"price":"62472.30","quantity":"0.000"},{"price":"62700.60","quantity":"0.796"},{"price":"62812.50","quantity":"1.127"},{"price":"62844.20","quantity":"0.682"}],"raw":{"e":"depthUpdate","E":1783517068026,"T":1783517068025,"s":"BTCUSDT","ps":"BTCUSDT","U":10999770680381,"u":10999770688919,"pu":10999770680289,"b":[["11352.20","0.256"],["11353.70","0.992"],["11453.70","1.428"],["11753.70","2.208"],["55668.30","0.002"],["58761.00","0.006"],["59379.50","0.001"],["61080.50","0.246"],["61180.00","1.630"],["61235.20","0.025"],["61295.00","1.173"],["61608.80","0.202"],["61723.00","0.709"],["61821.00","0.999"],["61821.10","0.863"],["61821.20","0.597"],["61835.40","0.003"],["61835.50","1.014"],["61835.60","0.131"],["61836.00","0.064"],["61836.50","0.023"],["61836.70","0.003"],["61837.10","0.002"],["61838.40","0.014"],["61838.80","0.012"],["61841.80","0.106"],["61842.00","0.371"],["61842.50","0.674"],["61843.10","0.153"],["61843.80","0.272"],["61844.80","0.118"],["61844.90","0.033"],["61850.10","0.050"],["61850.20","0.002"],["61853.60","0.002"],["61853.70","2.513"]],"a":[["61853.80","8.383"],["61860.00","0.467"],["61866.20","0.570"],["61867.60","0.345"],["61868.20","0.065"],["61872.40","0.007"],["61873.80","1.292"],["61949.40","0.021"],["61985.80","0.008"],["61986.30","0.345"],["62472.30","0.000"],["62700.60","0.796"],["62812.50","1.127"],["62844.20","0.682"]],"st":1}}
{"schema_version":"1.3.0","event_id":"dbc00230-79d9-42a1-9471-c60ab40beb39","event_type":"raw.depth_update","source":"binance_market_data_recorder","venue":"binance_usdm","market_type":"perpetual_futures","symbol":"BTCUSDT","event_time_ms":1783517068128,"received_time_ms":1783517068256,"trace_id":"458ed856-95b2-4216-aeee-437730754566","first_update_id":10999770688984,"final_update_id":10999770701625,"previous_final_update_id":10999770688919,"bids":[{"price":"11352.20","quantity":"0.128"},{"price":"11353.70","quantity":"0.984"},{"price":"11453.70","quantity":"1.292"},{"price":"11753.70","quantity":"2.480"},{"price":"55668.30","quantity":"0.002"},{"price":"58761.00","quantity":"0.006"},{"price":"59379.50","quantity":"0.004"},{"price":"60615.20","quantity":"0.021"},{"price":"60616.70","quantity":"0.020"},{"price":"61235.20","quantity":"0.025"},{"price":"61544.40","quantity":"0.013"},{"price":"61723.00","quantity":"0.983"},{"price":"61749.00","quantity":"0.026"},{"price":"61749.10","quantity":"0.006"},{"price":"61771.60","quantity":"0.001"},{"price":"61773.60","quantity":"7.988"},{"price":"61777.90","quantity":"0.146"},{"price":"61779.20","quantity":"2.213"},{"price":"61784.20","quantity":"33.904"},{"price":"61788.40","quantity":"0.002"},{"price":"61789.00","quantity":"1.484"},{"price":"61795.30","quantity":"4.695"},{"price":"61796.40","quantity":"0.046"},{"price":"61819.50","quantity":"0.002"},{"price":"61824.70","quantity":"0.122"},{"price":"61825.40","quantity":"0.874"},{"price":"61829.00","quantity":"0.118"},{"price":"61830.50","quantity":"0.969"},{"price":"61842.60","quantity":"0.097"},{"price":"61850.00","quantity":"0.907"},{"price":"61850.10","quantity":"0.001"},{"price":"61853.50","quantity":"0.001"},{"price":"61853.60","quantity":"0.005"},{"price":"61853.70","quantity":"2.501"}],"asks":[{"price":"61853.80","quantity":"8.347"},{"price":"61856.60","quantity":"0.163"},{"price":"61860.00","quantity":"0.463"},{"price":"61861.40","quantity":"1.133"},{"price":"61862.50","quantity":"0.001"},{"price":"61863.00","quantity":"0.283"},{"price":"61863.20","quantity":"0.455"},{"price":"61864.90","quantity":"0.054"},{"price":"61866.20","quantity":"0.566"},{"price":"61868.20","quantity":"0.048"},{"price":"61872.40","quantity":"0.003"},{"price":"61875.10","quantity":"2.218"},{"price":"61880.90","quantity":"0.169"},{"price":"61881.60","quantity":"0.052"},{"price":"61887.90","quantity":"0.379"},{"price":"61904.40","quantity":"0.237"},{"price":"61914.10","quantity":"0.051"},{"price":"61985.80","quantity":"0.744"},{"price":"62027.30","quantity":"0.000"},{"price":"62027.40","quantity":"0.003"},{"price":"62410.50","quantity":"0.240"},{"price":"62472.30","quantity":"0.000"},{"price":"62534.20","quantity":"0.240"},{"price":"62760.70","quantity":"0.000"},{"price":"89523.20","quantity":"0.762"}],"raw":{"e":"depthUpdate","E":1783517068128,"T":1783517068127,"s":"BTCUSDT","ps":"BTCUSDT","U":10999770688984,"u":10999770701625,"pu":10999770688919,"b":[["11352.20","0.128"],["11353.70","0.984"],["11453.70","1.292"],["11753.70","2.480"],["55668.30","0.002"],["58761.00","0.006"],["59379.50","0.004"],["60615.20","0.021"],["60616.70","0.020"],["61235.20","0.025"],["61544.40","0.013"],["61723.00","0.983"],["61749.00","0.026"],["61749.10","0.006"],["61771.60","0.001"],["61773.60","7.988"],["61777.90","0.146"],["61779.20","2.213"],["61784.20","33.904"],["61788.40","0.002"],["61789.00","1.484"],["61795.30","4.695"],["61796.40","0.046"],["61819.50","0.002"],["61824.70","0.122"],["61825.40","0.874"],["61829.00","0.118"],["61830.50","0.969"],["61842.60","0.097"],["61850.00","0.907"],["61850.10","0.001"],["61853.50","0.001"],["61853.60","0.005"],["61853.70","2.501"]],"a":[["61853.80","8.347"],["61856.60","0.163"],["61860.00","0.463"],["61861.40","1.133"],["61862.50","0.001"],["61863.00","0.283"],["61863.20","0.455"],["61864.90","0.054"],["61866.20","0.566"],["61868.20","0.048"],["61872.40","0.003"],["61875.10","2.218"],["61880.90","0.169"],["61881.60","0.052"],["61887.90","0.379"],["61904.40","0.237"],["61914.10","0.051"],["61985.80","0.744"],["62027.30","0.000"],["62027.40","0.003"],["62410.50","0.240"],["62472.30","0.000"],["62534.20","0.240"],["62760.70","0.000"],["89523.20","0.762"]],"st":1}}
