{"schema_version":"1.3.0","event_id":"4ed39e2a-b58e-44b6-991d-2e56ec974fac","event_type":"raw.depth_update","source":"binance_market_data_recorder","venue":"binance_usdm","market_type":"perpetual_futures","symbol":"BTCUSDT","event_time_ms":1783517068230,"received_time_ms":1783517068267,"trace_id":"c957cf7e-57e6-439a-9099-8bbcfa7e531b","first_update_id":10999770701799,"final_update_id":10999770711116,"previous_final_update_id":10999770701625,"bids":[{"price":"1000.00","quantity":"207.692"},{"price":"11352.20","quantity":"0.000"},{"price":"11353.70","quantity":"1.009"},{"price":"11453.70","quantity":"1.139"},{"price":"11653.70","quantity":"0.016"},{"price":"11753.70","quantity":"2.720"},{"price":"55668.30","quantity":"0.002"},{"price":"58761.00","quantity":"0.006"},{"price":"59379.50","quantity":"0.001"},{"price":"61111.50","quantity":"11.685"},{"price":"61235.20","quantity":"0.025"},{"price":"61293.60","quantity":"1.532"},{"price":"61771.60","quantity":"33.903"},{"price":"61773.60","quantity":"7.988"},{"price":"61784.00","quantity":"1.582"},{"price":"61784.20","quantity":"0.002"},{"price":"61784.30","quantity":"0.078"},{"price":"61786.30","quantity":"0.002"},{"price":"61789.00","quantity":"1.484"},{"price":"61821.10","quantity":"0.803"},{"price":"61821.30","quantity":"0.120"},{"price":"61841.90","quantity":"0.482"},{"price":"61853.40","quantity":"0.007"},{"price":"61853.50","quantity":"0.002"},{"price":"61853.60","quantity":"0.003"},{"price":"61853.70","quantity":"2.501"}],"asks":[{"price":"61853.80","quantity":"8.291"},{"price":"61860.80","quantity":"0.025"},{"price":"61861.90","quantity":"0.002"},{"price":"61862.40","quantity":"0.005"},{"price":"61871.70","quantity":"0.002"},{"price":"61872.70","quantity":"0.012"},{"price":"61893.10","quantity":"0.208"},{"price":"61893.30","quantity":"0.680"},{"price":"61893.50","quantity":"0.015"},{"price":"61904.80","quantity":"0.487"},{"price":"62328.80","quantity":"0.002"},{"price":"62472.30","quantity":"0.000"},{"price":"62544.40","quantity":"0.000"}],"raw":{"e":"depthUpdate","E":1783517068230,"T":1783517068229,"s":"BTCUSDT","ps":"BTCUSDT","U":10999770701799,"u":10999770711116,"pu":10999770701625,"b":[["1000.00","207.692"],["11352.20","0.000"],["11353.70","1.009"],["11453.70","1.139"],["11653.70","0.016"],["11753.70","2.720"],["55668.30","0.002"],["58761.00","0.006"],["59379.50","0.001"],["61111.50","11.685"],["61235.20","0.025"],["61293.60","1.532"],["61771.60","33.903"],["61773.60","7.988"],["61784.00","1.582"],["61784.20","0.002"],["61784.30","0.078"],["61786.30","0.002"],["61789.00","1.484"],["61821.10","0.803"],["61821.30","0.120"],["61841.90","0.482"],["61853.40","0.007"],["61853.50","0.002"],["61853.60","0.003"],["61853.70","2.501"]],"a":[["61853.80","8.291"],["61860.80","0.025"],["61861.90","0.002"],["61862.40","0.005"],["61871.70","0.002"],["61872.70","0.012"],["61893.10","0.208"],["61893.30","0.680"],["61893.50","0.015"],["61904.80","0.487"],["62328.80","0.002"],["62472.30","0.000"],["62544.40","0.000"]],"st":1}}
{"schema_version":"1.3.0","event_id":"4c8880eb-63c0-4995-a285-7b8159628fb6","event_type":"raw.depth_update","source":"binance_market_data_recorder","venue":"binance_usdm","market_type":"perpetual_futures","symbol":"BTCUSDT","event_time_ms":1783517068332,"received_time_ms":1783517068326,"trace_id":"3c4f60be-f5d8-4461-9e16-c96d9f3bd780","first_update_id":10999770711335,"final_update_id":10999770719502,"previous_final_update_id":10999770711116,"bids":[{"price":"11353.70","quantity":"1.001"},{"price":"11453.70","quantity":"1.003"},{"price":"11653.70","quantity":"0.144"},{"price":"11753.70","quantity":"2.736"},{"price":"34000.00","quantity":"13.622"},{"price":"55668.30","quantity":"0.002"},{"price":"58759.60","quantity":"0.009"},{"price":"58761.00","quantity":"0.006"},{"price":"59525.10","quantity":"0.002"},{"price":"61235.20","quantity":"0.025"},{"price":"61297.00","quantity":"2.276"},{"price":"61735.90","quantity":"0.100"},{"price":"61771.60","quantity":"0.001"},{"price":"61773.60","quantity":"3.357"},{"price":"61784.00","quantity":"0.000"},{"price":"61784.20","quantity":"33.904"},{"price":"61784.30","quantity":"6.747"},{"price":"61786.30","quantity":"0.002"},{"price":"61789.00","quantity":"1.484"},{"price":"61828.10","quantity":"0.041"},{"price":"61828.60","quantity":"0.411"},{"price":"61831.60","quantity":"0.002"},{"price":"61833.00","quantity":"0.014"},{"price":"61843.10","quantity":"0.052"},{"price":"61853.40","quantity":"0.006"},{"price":"61853.50","quantity":"0.001"},{"price":"61853.60","quantity":"0.005"},{"price":"61853.70","quantity":"2.469"}],"asks":[{"price":"61853.80","quantity":"8.207"},{"price":"61861.40","quantity":"0.165"},{"price":"61862.20","quantity":"0.127"},{"price":"61862.90","quantity":"0.001"},{"price":"61863.20","quantity":"1.423"},{"price":"61866.50","quantity":"0.004"},{"price":"61867.30","quantity":"0.123"},{"price":"61870.00","quantity":"0.411"},{"price":"62472.30","quantity":"0.002"},{"price":"62732.10","quantity":"0.314"},{"price":"63089.30","quantity":"0.132"},{"price":"89523.20","quantity":"0.768"}],"raw":{"e":"depthUpdate","E":1783517068332,"T":1783517068330,"s":"BTCUSDT","ps":"BTCUSDT","U":10999770711335,"u":10999770719502,"pu":10999770711116,"b":[["11353.70","1.001"],["11453.70","1.003"],["11653.70","0.144"],["11753.70","2.736"],["34000.00","13.622"],["55668.30","0.002"],["58759.60","0.009"],["58761.00","0.006"],["59525.10","0.002"],["61235.20","0.025"],["61297.00","2.276"],["61735.90","0.100"],["61771.60","0.001"],["61773.60","3.357"],["61784.00","0.000"],["61784.20","33.904"],["61784.30","6.747"],["61786.30","0.002"],["61789.00","1.484"],["61828.10","0.041"],["61828.60","0.411"],["61831.60","0.002"],["61833.00","0.014"],["61843.10","0.052"],["61853.40","0.006"],["61853.50","0.001"],["61853.60","0.005"],["61853.70","2.469"]],"a":[["61853.80","8.207"],["61861.40","0.165"],["61862.20","0.127"],["61862.90","0.001"],["61863.20","1.423"],["61866.50","0.004"],["61867.30","0.123"],["61870.00","0.411"],["62472.30","0.002"],["62732.10","0.314"],["63089.30","0.132"],["89523.20","0.768"]],"st":1}}
{"schema_version":"1.3.0","event_id":"cc4e8450-f9d0-45d5-b3a5-ebcfd8659f40","event_type":"raw.depth_update","source":"binance_market_data_recorder","venue":"binance_usdm","market_type":"perpetual_futures","symbol":"BTCUSDT","event_time_ms":1783517068434,"received_time_ms":1783517068429,"trace_id":"d13e8a50-e914-4012-ae50-f2f1fe73468c","first_update_id":10999770719588,"final_update_id":10999770728171,"previous_final_update_id":10999770719502,"bids":[{"price":"11353.70","quantity":"1.026"},{"price":"11453.70","quantity":"0.850"},{"price":"11653.70","quantity":"0.288"},{"price":"11753.70","quantity":"2.720"},{"price":"55668.30","quantity":"0.002"},{"price":"58761.00","quantity":"0.006"},{"price":"59379.50","quantity":"0.004"},{"price":"61235.20","quantity":"0.025"},{"price":"61298.60","quantity":"0.449"},{"price":"61300.10","quantity":"0.016"},{"price":"61451.90","quantity":"0.000"},{"price":"61453.30","quantity":"0.021"},{"price":"61537.60","quantity":"0.348"},{"price":"61544.40","quantity":"0.013"},{"price":"61605.50","quantity":"0.000"},{"price":"61607.00","quantity":"0.075"},{"price":"61759.50","quantity":"0.029"},{"price":"61761.00","quantity":"0.035"},{"price":"61821.90","quantity":"0.291"},{"price":"61826.10","quantity":"1.457"},{"price":"61828.10","quantity":"0.001"},{"price":"61830.50","quantity":"0.001"},{"price":"61831.40","quantity":"1.299"},{"price":"61832.30","quantity":"0.002"},{"price":"61839.00","quantity":"0.004"},{"price":"61839.10","quantity":"0.080"},{"price":"61848.40","quantity":"0.002"},{"price":"61849.70","quantity":"0.008"},{"price":"61853.40","quantity":"0.007"},{"price":"61853.50","quantity":"0.002"},{"price":"61853.60","quantity":"0.003"},{"price":"61853.70","quantity":"2.471"}],"asks":[{"price":"61859.50","quantity":"0.019"},{"price":"61864.40","quantity":"0.000"},{"price":"61865.60","quantity":"0.586"},{"price":"61883.10","quantity":"0.002"},{"price":"61945.00","quantity":"0.001"},{"price":"61946.50","quantity":"0.005"},{"price":"62099.90","quantity":"0.598"},{"price":"62101.40","quantity":"0.006"},{"price":"62255.10","quantity":"0.000"},{"price":"62256.60","quantity":"0.008"},{"price":"62410.70","quantity":"0.037"},{"price":"62412.30","quantity":"0.016"},{"price":"62472.30","quantity":"0.000"},{"price":"62598.00","quantity":"0.025"},{"price":"62627.00","quantity":"3.828"},{"price":"62750.70","quantity":"0.960"},{"price":"62776.20","quantity":"0.000"},{"price":"63089.30","quantity":"0.129"}],"raw":{"e":"depthUpdate","E":1783517068434,"T":1783517068433,"s":"BTCUSDT","ps":"BTCUSDT","U":10999770719588,"u":10999770728171,"pu":10999770719502,"b":[["11353.70","1.026"],["11453.70","0.850"],["11653.70","0.288"],["11753.70","2.720"],["55668.30","0.002"],["58761.00","0.006"],["59379.50","0.004"],["61235.20","0.025"],["61298.60","0.449"],["61300.10","0.016"],["61451.90","0.000"],["61453.30","0.021"],["61537.60","0.348"],["61544.40","0.013"],["61605.50","0.000"],["61607.00","0.075"],["61759.50","0.029"],["61761.00","0.035"],["61821.90","0.291"],["61826.10","1.457"],["61828.10","0.001"],["61830.50","0.001"],["61831.40","1.299"],["61832.30","0.002"],["61839.00","0.004"],["61839.10","0.080"],["61848.40","0.002"],["61849.70","0.008"],["61853.40","0.007"],["61853.50","0.002"],["61853.60","0.003"],["61853.70","2.471"]],"a":[["61859.50","0.019"],["61864.40","0.000"],["61865.60","0.586"],["61883.10","0.002"],["61945.00","0.001"],["61946.50","0.005"],["62099.90","0.598"],["62101.40","0.006"],["62255.10","0.000"],["62256.60","0.008"],["62410.70","0.037"],["62412.30","0.016"],["62472.30","0.000"],["62598.00","0.025"],["62627.00","3.828"],["62750.70","0.960"],["62776.20","0.000"],["63089.30","0.129"]],"st":1}}
{"schema_version":"1.3.0","event_id":"42ccffc7-499f-4b78-87a7-ce18f98d10f0","event_type":"raw.depth_update","source":"binance_market_data_recorder","venue":"binance_usdm","market_type":"perpetual_futures","symbol":"BTCUSDT","event_time_ms":1783517068536,"received_time_ms":1783517068530,"trace_id":"2ae9a667-40d0-4466-8869-f095270eb0c9","first_update_id":10999770728257,"final_update_id":10999770734850,"previous_final_update_id":10999770728171,"bids":[{"price":"1000.00","quantity":"207.692"},{"price":"11353.70","quantity":"1.018"},{"price":"11453.70","quantity":"0.714"},{"price":"11653.70","quantity":"0.416"},{"price":"11753.70","quantity":"2.736"},{"price":"49482.00","quantity":"0.000"},{"price":"55668.30","quantity":"0.002"},{"price":"58761.00","quantity":"0.009"},{"price":"59379.50","quantity":"0.001"},{"price":"60615.20","quantity":"0.015"},{"price":"60616.70","quantity":"0.023"},{"price":"60924.50","quantity":"0.003"},{"price":"61235.20","quantity":"0.025"},{"price":"61396.50","quantity":"0.000"},{"price":"61779.20","quantity":"2.205"},{"price":"61829.00","quantity":"0.364"},{"price":"61829.80","quantity":"0.016"},{"price":"61835.50","quantity":"0.014"},{"price":"61836.50","quantity":"1.023"},{"price":"61841.90","quantity":"0.484"},{"price":"61842.00","quantity":"0.470"},{"price":"61842.10","quantity":"0.102"},{"price":"61842.50","quantity":"0.572"},{"price":"61844.00","quantity":"0.033"},{"price":"61844.80","quantity":"0.017"},{"price":"61849.30","quantity":"0.000"},{"price":"61851.00","quantity":"1.001"},{"price":"61851.10","quantity":"0.631"},{"price":"61853.40","quantity":"0.006"},{"price":"61853.50","quantity":"0.001"},{"price":"61853.60","quantity":"0.005"},{"price":"61853.70","quantity":"2.622"}],"asks":[{"price":"61853.80","quantity":"8.854"},{"price":"61856.60","quantity":"0.398"},{"price":"61861.70","quantity":"0.278"},{"price":"61862.00","quantity":"0.001"},{"price":"61863.90","quantity":"0.308"},{"price":"61872.90","quantity":"0.070"},{"price":"61904.70","quantity":"0.104"},{"price":"62133.20","quantity":"0.000"},{"price":"62348.60","quantity":"4.003"},{"price":"62472.30","quantity":"0.000"},{"price":"62555.30","quantity":"0.240"},{"price":"62637.20","quantity":"0.008"},{"price":"62946.40","quantity":"3.873"},{"price":"63089.30","quantity":"0.117"},{"price":"89523.20","quantity":"0.774"}],"raw":{"e":"depthUpdate","E":1783517068536,"T":1783517068533,"s":"BTCUSDT","ps":"BTCUSDT","U":10999770728257,"u":10999770734850,"pu":10999770728171,"b":[["1000.00","207.692"],["11353.70","1.018"],["11453.70","0.714"],["11653.70","0.416"],["11753.70","2.736"],["49482.00","0.000"],["55668.30","0.002"],["58761.00","0.009"],["59379.50","0.001"],["60615.20","0.015"],["60616.70","0.023"],["60924.50","0.003"],["61235.20","0.025"],["61396.50","0.000"],["61779.20","2.205"],["61829.00","0.364"],["61829.80","0.016"],["61835.50","0.014"],["61836.50","1.023"],["61841.90","0.484"],["61842.00","0.470"],["61842.10","0.102"],["61842.50","0.572"],["61844.00","0.033"],["61844.80","0.017"],["61849.30","0.000"],["61851.00","1.001"],["61851.10","0.631"],["61853.40","0.006"],["61853.50","0.001"],["61853.60","0.005"],["61853.70","2.622"]],"a":[["61853.80","8.854"],["61856.60","0.398"],["61861.70","0.278"],["61862.00","0.001"],["61863.90","0.308"],["61872.90","0.070"],["61904.70","0.104"],["62133.20","0.000"],["62348.60","4.003"],["62472.30","0.000"],["62555.30","0.240"],["62637.20","0.008"],["62946.40","3.873"],["63089.30","0.117"],["89523.20","0.774"]],"st":1}}
{"schema_version":"1.3.0","event_id":"4a57e5e9-fc15-4e86-b35f-cf57eb779982","event_type":"raw.depth_update","source":"binance_market_data_recorder","venue":"binance_usdm","market_type":"perpetual_futures","symbol":"BTCUSDT","event_time_ms":1783517068638,"received_time_ms":1783517068632,"trace_id":"e5d68c67-d928-4234-8fee-41671764e9a0","first_update_id":10999770735067,"final_update_id":10999770745594,"previous_final_update_id":10999770734850,"bids":[{"price":"11353.20","quantity":"0.000"},{"price":"11353.70","quantity":"1.139"},{"price":"11453.70","quantity":"0.561"},{"price":"11653.70","quantity":"0.640"},{"price":"11753.70","quantity":"2.560"},{"price":"55668.30","quantity":"0.002"},{"price":"58759.60","quantity":"0.006"},{"price":"58759.70","quantity":"0.006"},{"price":"58761.00","quantity":"0.009"},{"price":"59379.50","quantity":"0.004"},{"price":"61235.20","quantity":"0.025"},{"price":"61319.70","quantity":"0.000"},{"price":"61321.10","quantity":"0.011"},{"price":"61548.50","quantity":"0.001"},{"price":"61550.00","quantity":"9.669"},{"price":"61730.40","quantity":"0.019"},{"price":"61778.10","quantity":"0.008"},{"price":"61784.20","quantity":"0.002"},{"price":"61784.30","quantity":"0.078"},{"price":"61786.30","quantity":"33.857"},{"price":"61789.00","quantity":"6.372"},{"price":"61808.60","quantity":"0.065"},{"price":"61841.80","quantity":"0.005"},{"price":"61850.00","quantity":"0.907"},{"price":"61853.20","quantity":"0.000"},{"price":"61853.50","quantity":"0.002"},{"price":"61853.60","quantity":"0.003"},{"price":"61853.70","quantity":"2.650"}],"asks":[{"price":"61853.80","quantity":"8.857"},{"price":"61888.20","quantity":"0.071"},{"price":"62472.30","quantity":"0.000"},{"price":"62815.00","quantity":"0.874"},{"price":"62936.20","quantity":"0.733"}],"raw":{"e":"depthUpdate","E":1783517068638,"T":1783517068637,"s":"BTCUSDT","ps":"BTCUSDT","U":10999770735067,"u":10999770745594,"pu":10999770734850,"b":[["11353.20","0.000"],["11353.70","1.139"],["11453.70","0.561"],["11653.70","0.640"],["11753.70","2.560"],["55668.30","0.002"],["58759.60","0.006"],["58759.70","0.006"],["58761.00","0.009"],["59379.50","0.004"],["61235.20","0.025"],["61319.70","0.000"],["61321.10","0.011"],["61548.50","0.001"],["61550.00","9.669"],["61730.40","0.019"],["61778.10","0.008"],["61784.20","0.002"],["61784.30","0.078"],["61786.30","33.857"],["61789.00","6.372"],["61808.60","0.065"],["61841.80","0.005"],["61850.00","0.907"],["61853.20","0.000"],["61853.50","0.002"],["61853.60","0.003"],["61853.70","2.650"]],"a":[["61853.80","8.857"],["61888.20","0.071"],["62472.30","0.000"],["62815.00","0.874"],["62936.20","0.733"]],"st":1}}
{"schema_version":"1.3.0","event_id":"04026bcc-64fc-41e2-aef9-4360571b3c1f","event_type":"raw.depth_update","source":"binance_market_data_recorder","venue":"binance_usdm","market_type":"perpetual_futures","symbol":"BTCUSDT","event_time_ms":1783517068740,"received_time_ms":1783517068735,"trace_id":"f6d49980-7cdd-4ea6-9278-15a87e592541","first_update_id":10999770745812,"final_update_id":10999770753660,"previous_final_update_id":10999770745594,"bids":[{"price":"1000.00","quantity":"207.842"},{"price":"11353.70","quantity":"1.275"},{"price":"11453.70","quantity":"0.425"},{"price":"11653.70","quantity":"0.912"},{"price":"11753.70","quantity":"2.288"},{"price":"49483.00","quantity":"0.000"},{"price":"55668.30","quantity":"0.002"},{"price":"58759.70","quantity":"0.003"},{"price":"61235.20","quantity":"0.025"},{"price":"61388.40","quantity":"0.007"},{"price":"61399.20","quantity":"0.123"},{"price":"61544.40","quantity":"0.013"},{"price":"61759.10","quantity":"0.000"},{"price":"61767.30","quantity":"0.001"},{"price":"61767.40","quantity":"0.000"},{"price":"61767.50","quantity":"2.323"},{"price":"61784.00","quantity":"0.000"},{"price":"61784.20","quantity":"33.857"},{"price":"61784.30","quantity":"6.740"},{"price":"61786.30","quantity":"0.002"},{"price":"61789.00","quantity":"1.484"},{"price":"61816.10","quantity":"0.047"},{"price":"61824.70","quantity":"0.001"},{"price":"61825.70","quantity":"0.133"},{"price":"61830.30","quantity":"1.130"},{"price":"61831.40","quantity":"0.331"},{"price":"61837.60","quantity":"1.229"},{"price":"61842.00","quantity":"0.468"},{"price":"61853.70","quantity":"2.652"}],"asks":[{"price":"61853.80","quantity":"8.063"},{"price":"61861.30","quantity":"1.385"},{"price":"61863.20","quantity":"0.455"},{"price":"61864.00","quantity":"3.301"},{"price":"61865.60","quantity":"0.004"},{"price":"61866.40","quantity":"0.122"},{"price":"61867.30","quantity":"0.002"},{"price":"62472.30","quantity":"0.000"},{"price":"62599.40","quantity":"0.798"},{"price":"62618.00","quantity":"1.321"},{"price":"62744.40","quantity":"0.005"},{"price":"89523.20","quantity":"0.780"}],"raw":{"e":"depthUpdate","E":1783517068740,"T":1783517068739,"s":"BTCUSDT","ps":"BTCUSDT","U":10999770745812,"u":10999770753660,"pu":10999770745594,"b":[["1000.00","207.842"],["11353.70","1.275"],["11453.70","0.425"],["11653.70","0.912"],["11753.70","2.288"],["49483.00","0.000"],["55668.30","0.002"],["58759.70","0.003"],["61235.20","0.025"],["61388.40","0.007"],["61399.20","0.123"],["61544.40","0.013"],["61759.10","0.000"],["61767.30","0.001"],["61767.40","0.000"],["61767.50","2.323"],["61784.00","0.000"],["61784.20","33.857"],["61784.30","6.740"],["61786.30","0.002"],["61789.00","1.484"],["61816.10","0.047"],["61824.70","0.001"],["61825.70","0.133"],["61830.30","1.130"],["61831.40","0.331"],["61837.60","1.229"],["61842.00","0.468"],["61853.70","2.652"]],"a":[["61853.80","8.063"],["61861.30","1.385"],["61863.20","0.455"],["61864.00","3.301"],["61865.60","0.004"],["61866.40","0.122"],["61867.30","0.002"],["62472.30","0.000"],["62599.40","0.798"],["62618.00","1.321"],["62744.40","0.005"],["89523.20","0.780"]],"st":1}}
{"schema_version":"1.3.0","event_id":"274ace75-bb63-4fd4-9b32-ab8de3060978","event_type":"raw.depth_update","source":"binance_market_data_recorder","venue":"binance_usdm","market_type":"perpetual_futures","symbol":"BTCUSDT","event_time_ms":1783517068842,"received_time_ms":1783517068836,"trace_id":"b3cfb27a-6d6f-47b2-a89f-8caf9caf31fe","first_update_id":10999770753707,"final_update_id":10999770764209,"previous_final_update_id":10999770753660,"bids":[{"price":"1000.00","quantity":"207.692"},{"price":"11353.70","quantity":"1.428"},{"price":"11453.70","quantity":"0.272"},{"price":"11653.70","quantity":"1.184"},{"price":"11753.70","quantity":"2.016"},{"price":"55668.30","quantity":"0.002"},{"price":"58761.00","quantity":"0.009"},{"price":"59379.50","quantity":"0.001"},{"price":"60615.20","quantity":"0.003"},{"price":"61235.20","quantity":"0.025"},{"price":"61544.40","quantity":"0.012"},{"price":"61784.00","quantity":"1.582"},{"price":"61784.20","quantity":"0.002"},{"price":"61784.30","quantity":"0.078"},{"price":"61786.30","quantity":"33.857"},{"price":"61789.00","quantity":"6.372"},{"price":"61808.10","quantity":"0.101"},{"price":"61822.00","quantity":"0.081"},{"price":"61822.80","quantity":"0.400"},{"price":"61823.60","quantity":"0.000"},{"price":"61824.50","quantity":"0.445"},{"price":"61825.00","quantity":"1.335"},{"price":"61825.10","quantity":"0.255"},{"price":"61825.20","quantity":"0.001"},{"price":"61825.60","quantity":"0.601"},{"price":"61825.70","quantity":"0.012"},{"price":"61826.40","quantity":"0.881"},{"price":"61829.00","quantity":"0.364"},{"price":"61835.20","quantity":"0.002"},{"price":"61838.00","quantity":"0.000"},{"price":"61838.20","quantity":"0.325"},{"price":"61839.00","quantity":"0.004"},{"price":"61839.10","quantity":"0.080"},{"price":"61839.20","quantity":"0.001"},{"price":"61840.10","quantity":"0.002"},{"price":"61840.70","quantity":"0.090"},{"price":"61841.40","quantity":"1.281"},{"price":"61842.20","quantity":"0.001"},{"price":"61843.10","quantity":"0.053"},{"price":"61844.00","quantity":"0.032"},{"price":"61846.90","quantity":"0.082"},{"price":"61850.00","quantity":"0.534"},{"price":"61851.10","quantity":"0.000"},{"price":"61852.30","quantity":"0.007"},{"price":"61853.40","quantity":"0.004"},{"price":"61853.60","quantity":"0.002"},{"price":"61853.70","quantity":"1.020"}],"asks":[{"price":"61853.80","quantity":"9.171"},{"price":"61854.00","quantity":"0.024"},{"price":"61854.80","quantity":"0.906"},{"price":"61854.90","quantity":"2.366"},{"price":"61855.10","quantity":"0.061"},{"price":"61856.40","quantity":"0.031"},{"price":"61856.60","quantity":"0.398"},{"price":"61856.70","quantity":"0.012"},{"price":"61857.30","quantity":"0.001"},{"price":"61860.40","quantity":"0.178"},{"price":"61861.30","quantity":"0.417"},{"price":"61862.20","quantity":"0.693"},{"price":"61862.30","quantity":"0.970"},{"price":"61862.40","quantity":"0.004"},{"price":"61864.00","quantity":"2.153"},{"price":"61864.50","quantity":"0.582"},{"price":"61866.80","quantity":"3.427"},{"price":"61871.20","quantity":"0.027"},{"price":"61872.90","quantity":"0.334"},{"price":"61873.00","quantity":"2.056"},{"price":"61879.20","quantity":"0.005"},{"price":"61893.10","quantity":"0.472"},{"price":"61893.40","quantity":"1.016"},{"price":"61898.20","quantity":"0.001"},{"price":"61904.50","quantity":"0.282"},{"price":"61904.60","quantity":"4.290"},{"price":"61904.70","quantity":"0.003"},{"price":"61904.80","quantity":"0.487"},{"price":"62163.10","quantity":"0.001"},{"price":"62353.50","quantity":"0.008"},{"price":"62472.30","quantity":"0.000"},{"price":"63089.30","quantity":"0.099"},{"price":"63979.20","quantity":"0.000"}],"raw":{"e":"depthUpdate","E":1783517068842,"T":1783517068841,"s":"BTCUSDT","ps":"BTCUSDT","U":10999770753707,"u":10999770764209,"pu":10999770753660,"b":[["1000.00","207.692"],["11353.70","1.428"],["11453.70","0.272"],["11653.70","1.184"],["11753.70","2.016"],["55668.30","0.002"],["58761.00","0.009"],["59379.50","0.001"],["60615.20","0.003"],["61235.20","0.025"],["61544.40","0.012"],["61784.00","1.582"],["61784.20","0.002"],["61784.30","0.078"],["61786.30","33.857"],["61789.00","6.372"],["61808.10","0.101"],["61822.00","0.081"],["61822.80","0.400"],["61823.60","0.000"],["61824.50","0.445"],["61825.00","1.335"],["61825.10","0.255"],["61825.20","0.001"],["61825.60","0.601"],["61825.70","0.012"],["61826.40","0.881"],["61829.00","0.364"],["61835.20","0.002"],["61838.00","0.000"],["61838.20","0.325"],["61839.00","0.004"],["61839.10","0.080"],["61839.20","0.001"],["61840.10","0.002"],["61840.70","0.090"],["61841.40","1.281"],["61842.20","0.001"],["61843.10","0.053"],["61844.00","0.032"],["61846.90","0.082"],["61850.00","0.534"],["61851.10","0.000"],["61852.30","0.007"],["61853.40","0.004"],["61853.60","0.002"],["61853.70","1.020"]],"a":[["61853.80","9.171"],["61854.00","0.024"],["61854.80","0.906"],["61854.90","2.366"],["61855.10","0.061"],["61856.40","0.031"],["61856.60","0.398"],["61856.70","0.012"],["61857.30","0.001"],["61860.40","0.178"],["61861.30","0.417"],["61862.20","0.693"],["61862.30","0.970"],["61862.40","0.004"],["61864.00","2.153"],["61864.50","0.582"],["61866.80","3.427"],["61871.20","0.027"],["61872.90","0.334"],["61873.00","2.056"],["61879.20","0.005"],["61893.10","0.472"],["61893.40","1.016"],["61898.20","0.001"],["61904.50","0.282"],["61904.60","4.290"],["61904.70","0.003"],["61904.80","0.487"],["62163.10","0.001"],["62353.50","0.008"],["62472.30","0.000"],["63089.30","0.099"],["63979.20","0.000"]],"st":1}}
{"schema_version":"1.3.0","event_id":"1ccad710-e31b-4502-85f8-ef1859547f35","event_type":"raw.depth_update","source":"binance_market_data_recorder","venue":"binance_usdm","market_type":"perpetual_futures","symbol":"BTCUSDT","event_time_ms":1783517068944,"received_time_ms":1783517068940,"trace_id":"439451ec-6699-46f2-a8ab-0ef99ba7350c","first_update_id":10999770764375,"final_update_id":10999770780155,"previous_final_update_id":10999770764209,"bids":[{"price":"11353.70","quantity":"1.564"},{"price":"11453.70","quantity":"0.136"},{"price":"11653.70","quantity":"1.456"},{"price":"11753.70","quantity":"1.744"},{"price":"55668.30","quantity":"0.002"},{"price":"58761.00","quantity":"0.009"},{"price":"59379.50","quantity":"0.004"},{"price":"60616.70","quantity":"0.026"},{"price":"60984.10","quantity":"9.904"},{"price":"61045.00","quantity":"0.380"},{"price":"61235.20","quantity":"0.025"},{"price":"61537.60","quantity":"0.348"},{"price":"61544.40","quantity":"0.013"},{"price":"61730.00","quantity":"0.457"},{"price":"61748.20","quantity":"0.016"},{"price":"61749.10","quantity":"0.003"},{"price":"61749.20","quantity":"0.005"},{"price":"61768.20","quantity":"0.066"},{"price":"61798.00","quantity":"0.062"},{"price":"61808.60","quantity":"0.018"},{"price":"61810.20","quantity":"0.080"},{"price":"61816.10","quantity":"0.000"},{"price":"61820.20","quantity":"0.343"},{"price":"61822.00","quantity":"0.001"},{"price":"61822.80","quantity":"0.400"},{"price":"61824.60","quantity":"0.587"},{"price":"61825.00","quantity":"1.415"},{"price":"61825.60","quantity":"0.019"},{"price":"61829.90","quantity":"0.013"},{"price":"61830.60","quantity":"0.001"},{"price":"61835.40","quantity":"1.003"},{"price":"61836.50","quantity":"0.023"},{"price":"61837.90","quantity":"1.645"},{"price":"61838.50","quantity":"0.095"},{"price":"61839.10","quantity":"0.000"},{"price":"61841.20","quantity":"0.003"},{"price":"61841.80","quantity":"0.106"},{"price":"61842.30","quantity":"0.001"},{"price":"61843.10","quantity":"0.052"},{"price":"61848.40","quantity":"0.008"},{"price":"61849.70","quantity":"0.002"},{"price":"61850.60","quantity":"0.000"},{"price":"61852.20","quantity":"0.630"},{"price":"61853.60","quantity":"0.002"},{"price":"61853.70","quantity":"0.981"}],"asks":[{"price":"61853.80","quantity":"10.124"},{"price":"61854.00","quantity":"0.266"},{"price":"61854.80","quantity":"0.905"},{"price":"61854.90","quantity":"2.366"},{"price":"61855.00","quantity":"1.953"},{"price":"61855.10","quantity":"0.063"},{"price":"61856.40","quantity":"0.029"},{"price":"61856.50","quantity":"0.050"},{"price":"61856.60","quantity":"0.397"},{"price":"61856.70","quantity":"0.010"},{"price":"61859.50","quantity":"0.019"},{"price":"61860.20","quantity":"1.297"},{"price":"61868.60","quantity":"0.002"},{"price":"61869.70","quantity":"0.011"},{"price":"61872.90","quantity":"0.070"},{"price":"61884.30","quantity":"0.141"},{"price":"61893.00","quantity":"0.580"},{"price":"61893.10","quantity":"0.208"},{"price":"61893.20","quantity":"0.000"},{"price":"61893.30","quantity":"0.473"},{"price":"61895.90","quantity":"0.051"},{"price":"61897.20","quantity":"0.001"},{"price":"62027.40","quantity":"0.000"},{"price":"62027.50","quantity":"0.003"},{"price":"62163.10","quantity":"0.002"},{"price":"62316.20","quantity":"0.007"},{"price":"62472.30","quantity":"0.000"},{"price":"62534.00","quantity":"0.023"},{"price":"62623.20","quantity":"2.392"},{"price":"89523.20","quantity":"0.786"}],"raw":{"e":"depthUpdate","E":1783517068944,"T":1783517068943,"s":"BTCUSDT","ps":"BTCUSDT","U":10999770764375,"u":10999770780155,"pu":10999770764209,"b":[["11353.70","1.564"],["11453.70","0.136"],["11653.70","1.456"],["11753.70","1.744"],["55668.30","0.002"],["58761.00","0.009"],["59379.50","0.004"],["60616.70","0.026"],["60984.10","9.904"],["61045.00","0.380"],["61235.20","0.025"],["61537.60","0.348"],["61544.40","0.013"],["61730.00","0.457"],["61748.20","0.016"],["61749.10","0.003"],["61749.20","0.005"],["61768.20","0.066"],["61798.00","0.062"],["61808.60","0.018"],["61810.20","0.080"],["61816.10","0.000"],["61820.20","0.343"],["61822.00","0.001"],["61822.80","0.400"],["61824.60","0.587"],["61825.00","1.415"],["61825.60","0.019"],["61829.90","0.013"],["61830.60","0.001"],["61835.40","1.003"],["61836.50","0.023"],["61837.90","1.645"],["61838.50","0.095"],["61839.10","0.000"],["61841.20","0.003"],["61841.80","0.106"],["61842.30","0.001"],["61843.10","0.052"],["61848.40","0.008"],["61849.70","0.002"],["61850.60","0.000"],["61852.20","0.630"],["61853.60","0.002"],["61853.70","0.981"]],"a":[["61853.80","10.124"],["61854.00","0.266"],["61854.80","0.905"],["61854.90","2.366"],["61855.00","1.953"],["61855.10","0.063"],["61856.40","0.029"],["61856.50","0.050"],["61856.60","0.397"],["61856.70","0.010"],["61859.50","0.019"],["61860.20","1.297"],["61868.60","0.002"],["61869.70","0.011"],["61872.90","0.070"],["61884.30","0.141"],["61893.00","0.580"],["61893.10","0.208"],["61893.20","0.000"],["61893.30","0.473"],["61895.90","0.051"],["61897.20","0.001"],["62027.40","0.000"],["62027.50","0.003"],["62163.10","0.002"],["62316.20","0.007"],["62472.30","0.000"],["62534.00","0.023"],["62623.20","2.392"],["89523.20","0.786"]],"st":1}}
{"schema_version":"1.3.0","event_id":"c9ab21fa-514d-4aa6-8253-44d2106cd9b8","event_type":"raw.depth_update","source":"binance_market_data_recorder","venue":"binance_usdm","market_type":"perpetual_futures","symbol":"BTCUSDT","event_time_ms":1783517069046,"received_time_ms":1783517069045,"trace_id":"6ad056ad-b16c-493c-8557-5633cf00a612","first_update_id":10999770780449,"final_update_id":10999770794616,"previous_final_update_id":10999770780155,"bids":[{"price":"1000.00","quantity":"207.692"},{"price":"11353.70","quantity":"1.683"},{"price":"11453.70","quantity":"0.000"},{"price":"11653.70","quantity":"1.728"},{"price":"11753.70","quantity":"1.489"},{"price":"55668.30","quantity":"0.002"},{"price":"58761.00","quantity":"0.009"},{"price":"59379.50","quantity":"0.001"},{"price":"60616.70","quantity":"0.029"},{"price":"60703.90","quantity":"0.000"},{"price":"60704.30","quantity":"0.823"},{"price":"61048.20","quantity":"3.408"},{"price":"61235.20","quantity":"0.025"},{"price":"61280.50","quantity":"3.713"},{"price":"61431.00","quantity":"0.010"},{"price":"61544.40","quantity":"0.013"},{"price":"61771.60","quantity":"0.001"},{"price":"61773.60","quantity":"3.357"},{"price":"61784.00","quantity":"0.000"},{"price":"61784.20","quantity":"0.002"},{"price":"61784.30","quantity":"6.740"},{"price":"61786.30","quantity":"33.857"},{"price":"61789.00","quantity":"1.484"},{"price":"61810.20","quantity":"0.080"},{"price":"61821.20","quantity":"0.161"},{"price":"61828.60","quantity":"0.391"},{"price":"61834.80","quantity":"0.039"},{"price":"61842.60","quantity":"0.102"},{"price":"61848.80","quantity":"0.001"},{"price":"61852.20","quantity":"0.630"},{"price":"61853.60","quantity":"0.002"},{"price":"61853.70","quantity":"0.998"}],"asks":[{"price":"61853.80","quantity":"10.058"},{"price":"61854.70","quantity":"0.370"},{"price":"61854.80","quantity":"0.000"},{"price":"61856.70","quantity":"0.915"},{"price":"61858.20","quantity":"0.131"},{"price":"61859.50","quantity":"0.019"},{"price":"61860.00","quantity":"0.467"},{"price":"61862.20","quantity":"0.127"},{"price":"61863.90","quantity":"0.874"},{"price":"61864.90","quantity":"0.059"},{"price":"61866.20","quantity":"0.570"},{"price":"61868.20","quantity":"0.065"},{"price":"61872.40","quantity":"0.007"},{"price":"61872.90","quantity":"0.070"},{"price":"61892.20","quantity":"0.268"},{"price":"61893.20","quantity":"0.264"},{"price":"62361.00","quantity":"0.320"},{"price":"62472.30","quantity":"0.000"},{"price":"62725.90","quantity":"1.432"},{"price":"63089.30","quantity":"0.096"}],"raw":{"e":"depthUpdate","E":1783517069046,"T":1783517069045,"s":"BTCUSDT","ps":"BTCUSDT","U":10999770780449,"u":10999770794616,"pu":10999770780155,"b":[["1000.00","207.692"],["11353.70","1.683"],["11453.70","0.000"],["11653.70","1.728"],["11753.70","1.489"],["55668.30","0.002"],["58761.00","0.009"],["59379.50","0.001"],["60616.70","0.029"],["60703.90","0.000"],["60704.30","0.823"],["61048.20","3.408"],["61235.20","0.025"],["61280.50","3.713"],["61431.00","0.010"],["61544.40","0.013"],["61771.60","0.001"],["61773.60","3.357"],["61784.00","0.000"],["61784.20","0.002"],["61784.30","6.740"],["61786.30","33.857"],["61789.00","1.484"],["61810.20","0.080"],["61821.20","0.161"],["61828.60","0.391"],["61834.80","0.039"],["61842.60","0.102"],["61848.80","0.001"],["61852.20","0.630"],["61853.60","0.002"],["61853.70","0.998"]],"a":[["61853.80","10.058"],["61854.70","0.370"],["61854.80","0.000"],["61856.70","0.915"],["61858.20","0.131"],["61859.50","0.019"],["61860.00","0.467"],["61862.20","0.127"],["61863.90","0.874"],["61864.90","0.059"],["61866.20","0.570"],["61868.20","0.065"],["61872.40","0.007"],["61872.90","0.070"],["61892.20","0.268"],["61893.20","0.264"],["62361.00","0.320"],["62472.30","0.000"],["62725.90","1.432"],["63089.30","0.096"]],"st":1}}
{"schema_version":"1.3.0","event_id":"186ae67b-4620-4824-9207-8143b1a40e90","event_type":"raw.depth_update","source":"binance_market_data_recorder","venue":"binance_usdm","market_type":"perpetual_futures","symbol":"BTCUSDT","event_time_ms":1783517069148,"received_time_ms":1783517069143,"trace_id":"f1ac8330-e96f-4aa0-92a2-5d488193800b","first_update_id":10999770794824,"final_update_id":10999770808923,"previous_final_update_id":10999770794616,"bids":[{"price":"1000.00","quantity":"207.692"},{"price":"11353.70","quantity":"1.547"},{"price":"11653.70","quantity":"2.000"},{"price":"11753.70","quantity":"1.353"},{"price":"55668.30","quantity":"0.002"},{"price":"58761.00","quantity":"0.012"},{"price":"59379.50","quantity":"0.004"},{"price":"60616.70","quantity":"0.032"},{"price":"61235.20","quantity":"0.025"},{"price":"61749.20","quantity":"0.002"},{"price":"61749.30","quantity":"0.003"},{"price":"61771.60","quantity":"0.001"},{"price":"61773.60","quantity":"3.357"},{"price":"61784.00","quantity":"1.582"},{"price":"61784.30","quantity":"0.078"},{"price":"61786.30","quantity":"33.857"},{"price":"61789.00","quantity":"6.372"},{"price":"61810.80","quantity":"0.008"},{"price":"61830.30","quantity":"0.162"},{"price":"61832.40","quantity":"0.975"},{"price":"61841.90","quantity":"0.383"},{"price":"61842.00","quantity":"0.369"},{"price":"61842.10","quantity":"0.001"},{"price":"61842.50","quantity":"0.673"},{"price":"61842.60","quantity":"0.097"},{"price":"61850.10","quantity":"0.050"},{"price":"61851.10","quantity":"0.583"},{"price":"61853.50","quantity":"0.001"},{"price":"61853.60","quantity":"0.005"},{"price":"61853.70","quantity":"1.814"}],"asks":[{"price":"61853.80","quantity":"9.237"},{"price":"61854.80","quantity":"0.000"},{"price":"61856.50","quantity":"0.955"},{"price":"61856.70","quantity":"0.010"},{"price":"61860.00","quantity":"0.463"},{"price":"61862.30","quantity":"0.002"},{"price":"61863.40","quantity":"0.998"},{"price":"61864.50","quantity":"0.000"},{"price":"61864.90","quantity":"0.054"},{"price":"61865.60","quantity":"0.586"},{"price":"61866.20","quantity":"0.566"},{"price":"61868.20","quantity":"0.048"},{"price":"61871.70","quantity":"0.000"},{"price":"61872.40","quantity":"0.003"},{"price":"61872.70","quantity":"0.010"},{"price":"62027.50","quantity":"0.000"},{"price":"62027.60","quantity":"0.011"},{"price":"62441.40","quantity":"3.221"},{"price":"62472.30","quantity":"0.000"},{"price":"62780.10","quantity":"0.361"},{"price":"89523.20","quantity":"0.792"}],"raw":{"e":"depthUpdate","E":1783517069148,"T":1783517069145,"s":"BTCUSDT","ps":"BTCUSDT","U":10999770794824,"u":10999770808923,"pu":10999770794616,"b":[["1000.00","207.692"],["11353.70","1.547"],["11653.70","2.000"],["11753.70","1.353"],["55668.30","0.002"],["58761.00","0.012"],["59379.50","0.004"],["60616.70","0.032"],["61235.20","0.025"],["61749.20","0.002"],["61749.30","0.003"],["61771.60","0.001"],["61773.60","3.357"],["61784.00","1.582"],["61784.30","0.078"],["61786.30","33.857"],["61789.00","6.372"],["61810.80","0.008"],["61830.30","0.162"],["61832.40","0.975"],["61841.90","0.383"],["61842.00","0.369"],["61842.10","0.001"],["61842.50","0.673"],["61842.60","0.097"],["61850.10","0.050"],["61851.10","0.583"],["61853.50","0.001"],["61853.60","0.005"],["61853.70","1.814"]],"a":[["61853.80","9.237"],["61854.80","0.000"],["61856.50","0.955"],["61856.70","0.010"],["61860.00","0.463"],["61862.30","0.002"],["61863.40","0.998"],["61864.50","0.000"],["61864.90","0.054"],["61865.60","0.586"],["61866.20","0.566"],["61868.20","0.048"],["61871.70","0.000"],["61872.40","0.003"],["61872.70","0.010"],["62027.50","0.000"],["62027.60","0.011"],["62441.40","3.221"],["62472.30","0.000"],["62780.10","0.361"],["89523.20","0.792"]],"st":1}}
{"schema_version":"1.3.0","event_id":"7a55ef5f-8c96-4acd-a94b-efe6e53a2de4","event_type":"raw.depth_update","source":"binance_market_data_recorder","venue":"binance_usdm","market_type":"perpetual_futures","symbol":"BTCUSDT","event_time_ms":1783517069250,"received_time_ms":1783517069245,"trace_id":"7f9ae5dd-9ad9-433f-b512-a41bfa3fe2b2","first_update_id":10999770809124,"final_update_id":10999770821184,"previous_final_update_id":10999770808923,"bids":[{"price":"11353.70","quantity":"1.394"},{"price":"11653.70","quantity":"2.272"},{"price":"11753.70","quantity":"1.234"},{"price":"55668.30","quantity":"0.002"},{"price":"58761.00","quantity":"0.012"},{"price":"61149.10","quantity":"0.003"},{"price":"61235.20","quantity":"0.027"},{"price":"61293.60","quantity":"1.288"},{"price":"61297.00","quantity":"2.520"},{"price":"61771.60","quantity":"0.001"},{"price":"61773.60","quantity":"3.357"},{"price":"61786.30","quantity":"33.857"},{"price":"61789.00","quantity":"1.484"},{"price":"61790.30","quantity":"0.001"},{"price":"61808.00","quantity":"4.445"},{"price":"61821.30","quantity":"0.060"},{"price":"61822.00","quantity":"0.001"},{"price":"61838.50","quantity":"0.015"},{"price":"61838.60","quantity":"0.096"},{"price":"61853.40","quantity":"0.005"},{"price":"61853.50","quantity":"0.002"},{"price":"61853.60","quantity":"0.003"},{"price":"61853.70","quantity":"1.813"}],"asks":[{"price":"61863.90","quantity":"0.308"},{"price":"61864.60","quantity":"0.632"},{"price":"61866.40","quantity":"0.001"},{"price":"61867.60","quantity":"0.466"},{"price":"61893.10","quantity":"0.001"},{"price":"61893.20","quantity":"0.471"},{"price":"61914.20","quantity":"0.080"},{"price":"62472.30","quantity":"0.000"},{"price":"62528.00","quantity":"0.655"}],"raw":{"e":"depthUpdate","E":1783517069250,"T":1783517069249,"s":"BTCUSDT","ps":"BTCUSDT","U":10999770809124,"u":10999770821184,"pu":10999770808923,"b":[["11353.70","1.394"],["11653.70","2.272"],["11753.70","1.234"],["55668.30","0.002"],["58761.00","0.012"],["61149.10","0.003"],["61235.20","0.027"],["61293.60","1.288"],["61297.00","2.520"],["61771.60","0.001"],["61773.60","3.357"],["61786.30","33.857"],["61789.00","1.484"],["61790.30","0.001"],["61808.00","4.445"],["61821.30","0.060"],["61822.00","0.001"],["61838.50","0.015"],["61838.60","0.096"],["61853.40","0.005"],["61853.50","0.002"],["61853.60","0.003"],["61853.70","1.813"]],"a":[["61863.90","0.308"],["61864.60","0.632"],["61866.40","0.001"],["61867.60","0.466"],["61893.10","0.001"],["61893.20","0.471"],["61914.20","0.080"],["62472.30","0.000"],["62528.00","0.655"]],"st":1}}
{"schema_version":"1.3.0","event_id":"01173c1d-27dd-4c9c-8bd6-2c537b248736","event_type":"raw.depth_update","source":"binance_market_data_recorder","venue":"binance_usdm","market_type":"perpetual_futures","symbol":"BTCUSDT","event_time_ms":1783517069352,"received_time_ms":1783517069347,"trace_id":"c052d45e-ba6a-4430-b5fa-7bfd99966e30","first_update_id":10999770821275,"final_update_id":10999770834247,"previous_final_update_id":10999770821184,"bids":[{"price":"1000.00","quantity":"207.692"},{"price":"11353.70","quantity":"1.258"},{"price":"11653.70","quantity":"2.544"},{"price":"11753.70","quantity":"1.098"},{"price":"49483.00","quantity":"0.000"},{"price":"55668.30","quantity":"0.002"},{"price":"58759.60","quantity":"0.008"},{"price":"58761.00","quantity":"0.012"},{"price":"59379.50","quantity":"0.001"},{"price":"59806.00","quantity":"0.016"},{"price":"60888.00","quantity":"34.115"},{"price":"61018.70","quantity":"0.490"},{"price":"61235.20","quantity":"0.025"},{"price":"61297.00","quantity":"2.764"},{"price":"61537.60","quantity":"0.348"},{"price":"61544.40","quantity":"0.013"},{"price":"61585.40","quantity":"0.000"},{"price":"61585.50","quantity":"0.008"},{"price":"61723.00","quantity":"0.709"},{"price":"61723.20","quantity":"0.513"},{"price":"61735.90","quantity":"0.000"},{"price":"61794.30","quantity":"0.067"},{"price":"61796.40","quantity":"0.007"},{"price":"61808.10","quantity":"0.000"},{"price":"61808.30","quantity":"1.216"},{"price":"61821.20","quantity":"0.161"},{"price":"61822.00","quantity":"0.001"},{"price":"61835.40","quantity":"0.003"},{"price":"61836.60","quantity":"2.227"},{"price":"61838.20","quantity":"0.481"},{"price":"61838.60","quantity":"0.096"},{"price":"61840.70","quantity":"0.001"},{"price":"61840.80","quantity":"0.011"},{"price":"61841.00","quantity":"0.812"},{"price":"61841.80","quantity":"0.005"},{"price":"61841.90","quantity":"0.484"},{"price":"61842.00","quantity":"0.046"},{"price":"61842.10","quantity":"0.061"},{"price":"61842.30","quantity":"0.000"},{"price":"61842.50","quantity":"0.107"},{"price":"61842.60","quantity":"0.198"},{"price":"61844.00","quantity":"0.033"},{"price":"61844.80","quantity":"2.152"},{"price":"61844.90","quantity":"0.922"},{"price":"61848.40","quantity":"0.002"},{"price":"61850.00","quantity":"1.019"},{"price":"61850.30","quantity":"0.051"},{"price":"61850.50","quantity":"0.006"},{"price":"61852.30","quantity":"0.269"},{"price":"61853.40","quantity":"0.004"},{"price":"61853.50","quantity":"0.001"},{"price":"61853.60","quantity":"0.005"},{"price":"61853.70","quantity":"2.580"}],"asks":[{"price":"61853.80","quantity":"6.908"},{"price":"61854.30","quantity":"2.810"},{"price":"61854.40","quantity":"0.003"},{"price":"61854.90","quantity":"0.016"},{"price":"61855.10","quantity":"0.061"},{"price":"61856.50","quantity":"0.049"},{"price":"61856.60","quantity":"0.235"},{"price":"61856.80","quantity":"0.005"},{"price":"61856.90","quantity":"0.002"},{"price":"61857.20","quantity":"0.000"},{"price":"61857.50","quantity":"0.003"},{"price":"61859.50","quantity":"0.924"},{"price":"61862.90","quantity":"0.002"},{"price":"61883.20","quantity":"0.005"},{"price":"61883.30","quantity":"0.000"},{"price":"61883.70","quantity":"0.164"},{"price":"61893.10","quantity":"0.374"},{"price":"61893.30","quantity":"0.100"},{"price":"61904.40","quantity":"0.027"},{"price":"61910.70","quantity":"0.228"},{"price":"61957.20","quantity":"8.401"},{"price":"61958.10","quantity":"0.000"},{"price":"61985.60","quantity":"0.808"},{"price":"61985.80","quantity":"0.008"},{"price":"62062.00","quantity":"3.032"},{"price":"62472.30","quantity":"0.000"},{"price":"89523.20","quantity":"0.798"}],"raw":{"e":"depthUpdate","E":1783517069352,"T":1783517069350,"s":"BTCUSDT","ps":"BTCUSDT","U":10999770821275,"u":10999770834247,"pu":10999770821184,"b":[["1000.00","207.692"],["11353.70","1.258"],["11653.70","2.544"],["11753.70","1.098"],["49483.00","0.000"],["55668.30","0.002"],["58759.60","0.008"],["58761.00","0.012"],["59379.50","0.001"],["59806.00","0.016"],["60888.00","34.115"],["61018.70","0.490"],["61235.20","0.025"],["61297.00","2.764"],["61537.60","0.348"],["61544.40","0.013"],["61585.40","0.000"],["61585.50","0.008"],["61723.00","0.709"],["61723.20","0.513"],["61735.90","0.000"],["61794.30","0.067"],["61796.40","0.007"],["61808.10","0.000"],["61808.30","1.216"],["61821.20","0.161"],["61822.00","0.001"],["61835.40","0.003"],["61836.60","2.227"],["61838.20","0.481"],["61838.60","0.096"],["61840.70","0.001"],["61840.80","0.011"],["61841.00","0.812"],["61841.80","0.005"],["61841.90","0.484"],["61842.00","0.046"],["61842.10","0.061"],["61842.30","0.000"],["61842.50","0.107"],["61842.60","0.198"],["61844.00","0.033"],["61844.80","2.152"],["61844.90","0.922"],["61848.40","0.002"],["61850.00","1.019"],["61850.30","0.051"],["61850.50","0.006"],["61852.30","0.269"],["61853.40","0.004"],["61853.50","0.001"],["61853.60","0.005"],["61853.70","2.580"]],"a":[["61853.80","6.908"],["61854.30","2.810"],["61854.40","0.003"],["61854.90","0.016"],["61855.10","0.061"],["61856.50","0.049"],["61856.60","0.235"],["61856.80","0.005"],["61856.90","0.002"],["61857.20","0.000"],["61857.50","0.003"],["61859.50","0.924"],["61862.90","0.002"],["61883.20","0.005"],["61883.30","0.000"],["61883.70","0.164"],["61893.10","0.374"],["61893.30","0.100"],["61904.40","0.027"],["61910.70","0.228"],["61957.20","8.401"],["61958.10","0.000"],["61985.60","0.808"],["61985.80","0.008"],["62062.00","3.032"],["62472.30","0.000"],["89523.20","0.798"]],"st":1}}
{"schema_version":"1.3.0","event_id":"e8f40197-19f4-401b-8d19-91e4121744ed","event_type":"raw.depth_update","source":"binance_market_data_recorder","venue":"binance_usdm","market_type":"perpetual_futures","symbol":"BTCUSDT","event_time_ms":1783517069454,"received_time_ms":1783517069453,"trace_id":"f4d81f55-4406-4dc8-b3f8-b087f93f53a5","first_update_id":10999770834593,"final_update_id":10999770850269,"previous_final_update_id":10999770834247,"bids":[{"price":"1000.00","quantity":"207.692"},{"price":"11353.70","quantity":"1.105"},{"price":"11553.70","quantity":"0.048"},{"price":"11653.70","quantity":"2.720"},{"price":"11753.70","quantity":"1.027"},{"price":"55668.30","quantity":"0.002"},{"price":"58761.00","quantity":"0.012"},{"price":"59379.50","quantity":"0.004"},{"price":"60616.70","quantity":"0.035"},{"price":"60896.30","quantity":"0.483"},{"price":"60962.70","quantity":"0.000"},{"price":"61235.20","quantity":"0.025"},{"price":"61259.40","quantity":"0.011"},{"price":"61342.70","quantity":"0.000"},{"price":"61358.90","quantity":"1.225"},{"price":"61541.30","quantity":"0.000"},{"price":"61606.30","quantity":"0.499"},{"price":"61607.30","quantity":"0.158"},{"price":"61608.80","quantity":"0.000"},{"price":"61624.90","quantity":"0.165"},{"price":"61771.60","quantity":"33.563"},{"price":"61786.30","quantity":"0.002"},{"price":"61798.00","quantity":"0.015"},{"price":"61800.20","quantity":"0.331"},{"price":"61806.00","quantity":"0.046"},{"price":"61806.20","quantity":"0.179"},{"price":"61806.30","quantity":"0.018"},{"price":"61808.10","quantity":"0.000"},{"price":"61808.30","quantity":"1.115"},{"price":"61810.30","quantity":"1.606"},{"price":"61811.10","quantity":"0.016"},{"price":"61811.50","quantity":"0.115"},{"price":"61812.60","quantity":"0.000"},{"price":"61814.10","quantity":"0.571"},{"price":"61814.30","quantity":"0.230"},{"price":"61817.40","quantity":"0.004"},{"price":"61820.20","quantity":"0.254"},{"price":"61820.30","quantity":"0.467"},{"price":"61820.50","quantity":"0.340"},{"price":"61821.00","quantity":"1.009"},{"price":"61821.10","quantity":"0.367"},{"price":"61821.20","quantity":"0.101"},{"price":"61822.30","quantity":"0.091"},{"price":"61822.70","quantity":"0.105"},{"price":"61822.90","quantity":"0.092"},{"price":"61823.80","quantity":"0.001"},{"price":"61824.50","quantity":"0.332"},{"price":"61824.60","quantity":"0.005"},{"price":"61824.80","quantity":"0.001"},{"price":"61825.30","quantity":"0.017"},{"price":"61825.80","quantity":"0.008"},{"price":"61826.10","quantity":"1.091"},{"price":"61826.60","quantity":"0.695"},{"price":"61827.40","quantity":"0.564"},{"price":"61827.80","quantity":"0.286"},{"price":"61828.10","quantity":"0.001"},{"price":"61829.00","quantity":"0.610"},{"price":"61829.10","quantity":"0.339"},{"price":"61829.70","quantity":"0.006"},{"price":"61829.80","quantity":"0.004"},{"price":"61829.90","quantity":"0.002"},{"price":"61831.00","quantity":"0.000"},{"price":"61832.10","quantity":"1.033"},{"price":"61832.40","quantity":"0.007"},{"price":"61833.20","quantity":"0.885"},{"price":"61834.40","quantity":"0.179"},{"price":"61835.10","quantity":"1.714"},{"price":"61835.20","quantity":"0.568"},{"price":"61835.30","quantity":"0.355"},{"price":"61835.70","quantity":"0.013"},{"price":"61835.90","quantity":"1.054"},{"price":"61836.00","quantity":"0.064"},{"price":"61836.60","quantity":"1.227"},{"price":"61836.70","quantity":"0.003"},{"price":"61837.10","quantity":"0.002"},{"price":"61837.30","quantity":"0.885"},{"price":"61837.50","quantity":"3.197"},{"price":"61838.00","quantity":"0.566"},{"price":"61838.30","quantity":"0.062"},{"price":"61838.80","quantity":"0.010"},{"price":"61839.50","quantity":"0.124"},{"price":"61840.00","quantity":"0.432"},{"price":"61841.00","quantity":"0.003"},{"price":"61841.30","quantity":"0.573"},{"price":"61841.50","quantity":"0.221"},{"price":"61841.80","quantity":"0.441"},{"price":"61841.90","quantity":"0.383"},{"price":"61842.10","quantity":"0.001"},{"price":"61842.30","quantity":"0.002"},{"price":"61842.40","quantity":"0.293"},{"price":"61842.50","quantity":"0.006"},{"price":"61842.60","quantity":"0.081"},{"price":"61843.10","quantity":"0.002"},{"price":"61843.30","quantity":"0.015"},{"price":"61844.00","quantity":"0.032"},{"price":"61844.10","quantity":"0.000"},{"price":"61844.20","quantity":"1.290"},{"price":"61844.50","quantity":"0.003"},{"price":"61844.90","quantity":"1.119"},{"price":"61845.00","quantity":"0.009"},{"price":"61845.10","quantity":"0.284"},{"price":"61846.20","quantity":"1.305"},{"price":"61846.30","quantity":"0.324"},{"price":"61847.20","quantity":"0.000"},{"price":"61847.60","quantity":"0.006"},{"price":"61847.80","quantity":"0.002"},{"price":"61847.90","quantity":"2.139"},{"price":"61848.00","quantity":"1.138"},{"price":"61848.20","quantity":"0.001"},{"price":"61848.90","quantity":"0.003"},{"price":"61849.30","quantity":"0.248"},{"price":"61849.60","quantity":"0.072"},{"price":"61850.00","quantity":"1.018"},{"price":"61850.20","quantity":"0.124"},{"price":"61850.50","quantity":"0.000"},{"price":"61850.60","quantity":"0.287"},{"price":"61851.20","quantity":"1.527"},{"price":"61851.50","quantity":"0.000"},{"price":"61852.10","quantity":"0.004"},{"price":"61852.30","quantity":"1.209"},{"price":"61852.40","quantity":"1.575"},{"price":"61852.70","quantity":"0.000"},{"price":"61853.40","quantity":"0.004"},{"price":"61853.50","quantity":"0.006"},{"price":"61853.60","quantity":"0.002"},{"price":"61853.70","quantity":"6.391"}],"asks":[{"price":"61853.80","quantity":"2.272"},{"price":"61853.90","quantity":"0.005"},{"price":"61854.00","quantity":"0.001"},{"price":"61854.20","quantity":"0.022"},{"price":"61854.30","quantity":"0.023"},{"price":"61854.40","quantity":"0.127"},{"price":"61855.00","quantity":"1.951"},{"price":"61855.10","quantity":"0.002"},{"price":"61855.30","quantity":"0.002"},{"price":"61855.80","quantity":"0.005"},{"price":"61856.00","quantity":"0.026"},{"price":"61856.10","quantity":"0.005"},{"price":"61856.30","quantity":"0.079"},{"price":"61856.40","quantity":"0.271"},{"price":"61856.50","quantity":"0.000"},{"price":"61856.60","quantity":"0.235"},{"price":"61856.80","quantity":"0.001"},{"price":"61857.00","quantity":"0.714"},{"price":"61857.10","quantity":"0.002"},{"price":"61857.30","quantity":"0.000"},{"price":"61857.40","quantity":"1.005"},{"price":"61857.50","quantity":"0.001"},{"price":"61857.80","quantity":"0.001"},{"price":"61858.90","quantity":"0.053"},{"price":"61859.00","quantity":"0.104"},{"price":"61859.10","quantity":"0.000"},{"price":"61859.20","quantity":"0.501"},{"price":"61859.30","quantity":"0.367"},{"price":"61859.40","quantity":"1.618"},{"price":"61859.50","quantity":"0.019"},{"price":"61859.60","quantity":"0.166"},{"price":"61859.70","quantity":"0.001"},{"price":"61859.80","quantity":"0.187"},{"price":"61859.90","quantity":"0.568"},{"price":"61860.10","quantity":"0.005"},{"price":"61860.20","quantity":"0.347"},{"price":"61860.60","quantity":"0.108"},{"price":"61860.80","quantity":"0.027"},{"price":"61861.00","quantity":"0.408"},{"price":"61861.10","quantity":"0.372"},{"price":"61861.20","quantity":"0.004"},{"price":"61861.40","quantity":"0.165"},{"price":"61862.10","quantity":"0.003"},{"price":"61862.30","quantity":"0.052"},{"price":"61862.40","quantity":"0.038"},{"price":"61862.60","quantity":"0.437"},{"price":"61862.70","quantity":"2.747"},{"price":"61862.90","quantity":"0.001"},{"price":"61863.00","quantity":"0.053"},{"price":"61863.10","quantity":"0.968"},{"price":"61863.40","quantity":"0.030"},{"price":"61863.50","quantity":"0.002"},{"price":"61863.60","quantity":"0.170"},{"price":"61863.80","quantity":"0.280"},{"price":"61864.10","quantity":"0.797"},{"price":"61864.60","quantity":"0.001"},{"price":"61864.70","quantity":"0.003"},{"price":"61865.50","quantity":"0.611"},{"price":"61865.60","quantity":"0.766"},{"price":"61867.60","quantity":"0.345"},{"price":"61868.00","quantity":"0.334"},{"price":"61868.70","quantity":"0.101"},{"price":"61869.50","quantity":"0.083"},{"price":"61869.70","quantity":"0.003"},{"price":"61869.90","quantity":"1.832"},{"price":"61870.00","quantity":"0.532"},{"price":"61871.10","quantity":"0.011"},{"price":"61872.00","quantity":"0.290"},{"price":"61872.80","quantity":"0.008"},{"price":"61873.20","quantity":"0.002"},{"price":"61873.70","quantity":"0.005"},{"price":"61873.80","quantity":"1.292"},{"price":"61874.70","quantity":"0.001"},{"price":"61876.10","quantity":"0.162"},{"price":"61877.30","quantity":"0.229"},{"price":"61877.80","quantity":"0.000"},{"price":"61878.00","quantity":"2.202"},{"price":"61878.20","quantity":"0.062"},{"price":"61878.50","quantity":"0.014"},{"price":"61878.80","quantity":"0.051"},{"price":"61879.70","quantity":"0.152"},{"price":"61880.80","quantity":"0.000"},{"price":"61880.90","quantity":"0.049"},{"price":"61881.30","quantity":"0.681"},{"price":"61881.80","quantity":"0.037"},{"price":"61882.30","quantity":"0.000"},{"price":"61883.00","quantity":"0.149"},{"price":"61883.50","quantity":"0.951"},{"price":"61886.70","quantity":"0.000"},{"price":"61886.80","quantity":"4.243"},{"price":"61887.70","quantity":"0.170"},{"price":"61888.50","quantity":"0.082"},{"price":"61889.20","quantity":"0.023"},{"price":"61890.20","quantity":"0.022"},{"price":"61892.20","quantity":"0.004"},{"price":"61892.50","quantity":"0.080"},{"price":"61893.20","quantity":"0.207"},{"price":"61893.80","quantity":"2.462"},{"price":"61894.00","quantity":"0.001"},{"price":"61894.10","quantity":"0.017"},{"price":"61895.60","quantity":"0.097"},{"price":"61896.60","quantity":"0.000"},{"price":"61897.10","quantity":"0.310"},{"price":"61897.20","quantity":"0.004"},{"price":"61897.40","quantity":"0.000"},{"price":"61897.60","quantity":"0.004"},{"price":"61898.50","quantity":"0.083"},{"price":"61899.10","quantity":"0.137"},{"price":"61904.50","quantity":"0.181"},{"price":"61904.60","quantity":"4.189"},{"price":"61904.80","quantity":"0.386"},{"price":"61905.40","quantity":"0.015"},{"price":"61905.60","quantity":"0.002"},{"price":"61906.10","quantity":"0.084"},{"price":"61906.30","quantity":"0.122"},{"price":"61909.00","quantity":"0.133"},{"price":"61909.20","quantity":"0.277"},{"price":"61909.40","quantity":"0.006"},{"price":"61909.50","quantity":"2.795"},{"price":"61909.90","quantity":"0.217"},{"price":"61910.70","quantity":"0.018"},{"price":"61911.50","quantity":"0.005"},{"price":"61911.70","quantity":"0.001"},{"price":"61913.50","quantity":"5.790"},{"price":"61916.30","quantity":"25.516"},{"price":"61916.40","quantity":"3.235"},{"price":"61917.00","quantity":"0.229"},{"price":"61918.40","quantity":"0.000"},{"price":"61950.50","quantity":"0.264"},{"price":"61952.80","quantity":"0.000"},{"price":"61953.70","quantity":"0.264"},{"price":"62472.30","quantity":"0.000"},{"price":"63089.30","quantity":"0.093"},{"price":"63090.80","quantity":"0.015"}],"raw":{"e":"depthUpdate","E":1783517069454,"T":1783517069453,"s":"BTCUSDT","ps":"BTCUSDT","U":10999770834593,"u":10999770850269,"pu":10999770834247,"b":[["1000.00","207.692"],["11353.70","1.105"],["11553.70","0.048"],["11653.70","2.720"],["11753.70","1.027"],["55668.30","0.002"],["58761.00","0.012"],["59379.50","0.004"],["60616.70","0.035"],["60896.30","0.483"],["60962.70","0.000"],["61235.20","0.025"],["61259.40","0.011"],["61342.70","0.000"],["61358.90","1.225"],["61541.30","0.000"],["61606.30","0.499"],["61607.30","0.158"],["61608.80","0.000"],["61624.90","0.165"],["61771.60","33.563"],["61786.30","0.002"],["61798.00","0.015"],["61800.20","0.331"],["61806.00","0.046"],["61806.20","0.179"],["61806.30","0.018"],["61808.10","0.000"],["61808.30","1.115"],["61810.30","1.606"],["61811.10","0.016"],["61811.50","0.115"],["61812.60","0.000"],["61814.10","0.571"],["61814.30","0.230"],["61817.40","0.004"],["61820.20","0.254"],["61820.30","0.467"],["61820.50","0.340"],["61821.00","1.009"],["61821.10","0.367"],["61821.20","0.101"],["61822.30","0.091"],["61822.70","0.105"],["61822.90","0.092"],["61823.80","0.001"],["61824.50","0.332"],["61824.60","0.005"],["61824.80","0.001"],["61825.30","0.017"],["61825.80","0.008"],["61826.10","1.091"],["61826.60","0.695"],["61827.40","0.564"],["61827.80","0.286"],["61828.10","0.001"],["61829.00","0.610"],["61829.10","0.339"],["61829.70","0.006"],["61829.80","0.004"],["61829.90","0.002"],["61831.00","0.000"],["61832.10","1.033"],["61832.40","0.007"],["61833.20","0.885"],["61834.40","0.179"],["61835.10","1.714"],["61835.20","0.568"],["61835.30","0.355"],["61835.70","0.013"],["61835.90","1.054"],["61836.00","0.064"],["61836.60","1.227"],["61836.70","0.003"],["61837.10","0.002"],["61837.30","0.885"],["61837.50","3.197"],["61838.00","0.566"],["61838.30","0.062"],["61838.80","0.010"],["61839.50","0.124"],["61840.00","0.432"],["61841.00","0.003"],["61841.30","0.573"],["61841.50","0.221"],["61841.80","0.441"],["61841.90","0.383"],["61842.10","0.001"],["61842.30","0.002"],["61842.40","0.293"],["61842.50","0.006"],["61842.60","0.081"],["61843.10","0.002"],["61843.30","0.015"],["61844.00","0.032"],["61844.10","0.000"],["61844.20","1.290"],["61844.50","0.003"],["61844.90","1.119"],["61845.00","0.009"],["61845.10","0.284"],["61846.20","1.305"],["61846.30","0.324"],["61847.20","0.000"],["61847.60","0.006"],["61847.80","0.002"],["61847.90","2.139"],["61848.00","1.138"],["61848.20","0.001"],["61848.90","0.003"],["61849.30","0.248"],["61849.60","0.072"],["61850.00","1.018"],["61850.20","0.124"],["61850.50","0.000"],["61850.60","0.287"],["61851.20","1.527"],["61851.50","0.000"],["61852.10","0.004"],["61852.30","1.209"],["61852.40","1.575"],["61852.70","0.000"],["61853.40","0.004"],["61853.50","0.006"],["61853.60","0.002"],["61853.70","6.391"]],"a":[["61853.80","2.272"],["61853.90","0.005"],["61854.00","0.001"],["61854.20","0.022"],["61854.30","0.023"],["61854.40","0.127"],["61855.00","1.951"],["61855.10","0.002"],["61855.30","0.002"],["61855.80","0.005"],["61856.00","0.026"],["61856.10","0.005"],["61856.30","0.079"],["61856.40","0.271"],["61856.50","0.000"],["61856.60","0.235"],["61856.80","0.001"],["61857.00","0.714"],["61857.10","0.002"],["61857.30","0.000"],["61857.40","1.005"],["61857.50","0.001"],["61857.80","0.001"],["61858.90","0.053"],["61859.00","0.104"],["61859.10","0.000"],["61859.20","0.501"],["61859.30","0.367"],["61859.40","1.618"],["61859.50","0.019"],["61859.60","0.166"],["61859.70","0.001"],["61859.80","0.187"],["61859.90","0.568"],["61860.10","0.005"],["61860.20","0.347"],["61860.60","0.108"],["61860.80","0.027"],["61861.00","0.408"],["61861.10","0.372"],["61861.20","0.004"],["61861.40","0.165"],["61862.10","0.003"],["61862.30","0.052"],["61862.40","0.038"],["61862.60","0.437"],["61862.70","2.747"],["61862.90","0.001"],["61863.00","0.053"],["61863.10","0.968"],["61863.40","0.030"],["61863.50","0.002"],["61863.60","0.170"],["61863.80","0.280"],["61864.10","0.797"],["61864.60","0.001"],["61864.70","0.003"],["61865.50","0.611"],["61865.60","0.766"],["61867.60","0.345"],["61868.00","0.334"],["61868.70","0.101"],["61869.50","0.083"],["61869.70","0.003"],["61869.90","1.832"],["61870.00","0.532"],["61871.10","0.011"],["61872.00","0.290"],["61872.80","0.008"],["61873.20","0.002"],["61873.70","0.005"],["61873.80","1.292"],["61874.70","0.001"],["61876.10","0.162"],["61877.30","0.229"],["61877.80","0.000"],["61878.00","2.202"],["61878.20","0.062"],["61878.50","0.014"],["61878.80","0.051"],["61879.70","0.152"],["61880.80","0.000"],["61880.90","0.049"],["61881.30","0.681"],["61881.80","0.037"],["61882.30","0.000"],["61883.00","0.149"],["61883.50","0.951"],["61886.70","0.000"],["61886.80","4.243"],["61887.70","0.170"],["61888.50","0.082"],["61889.20","0.023"],["61890.20","0.022"],["61892.20","0.004"],["61892.50","0.080"],["61893.20","0.207"],["61893.80","2.462"],["61894.00","0.001"],["61894.10","0.017"],["61895.60","0.097"],["61896.60","0.000"],["61897.10","0.310"],["61897.20","0.004"],["61897.40","0.000"],["61897.60","0.004"],["61898.50","0.083"],["61899.10","0.137"],["61904.50","0.181"],["61904.60","4.189"],["61904.80","0.386"],["61905.40","0.015"],["61905.60","0.002"],["61906.10","0.084"],["61906.30","0.122"],["61909.00","0.133"],["61909.20","0.277"],["61909.40","0.006"],["61909.50","2.795"],["61909.90","0.217"],["61910.70","0.018"],["61911.50","0.005"],["61911.70","0.001"],["61913.50","5.790"],["61916.30","25.516"],["61916.40","3.235"],["61917.00","0.229"],["61918.40","0.000"],["61950.50","0.264"],["61952.80","0.000"],["61953.70","0.264"],["62472.30","0.000"],["63089.30","0.093"],["63090.80","0.015"]],"st":1}}
{"schema_version":"1.3.0","event_id":"055c302c-1ebc-4aec-bbd6-985c434e7576","event_type":"raw.depth_update","source":"binance_market_data_recorder","venue":"binance_usdm","market_type":"perpetual_futures","symbol":"BTCUSDT","event_time_ms":1783517069558,"received_time_ms":1783517069553,"trace_id":"0c0fe0e2-91a7-4852-9a41-07c7c4cad682","first_update_id":10999770850644,"final_update_id":10999770859633,"previous_final_update_id":10999770850269,"bids":[{"price":"11353.70","quantity":"0.952"},{"price":"11553.70","quantity":"0.176"},{"price":"11653.70","quantity":"2.736"},{"price":"11753.70","quantity":"1.036"},{"price":"55668.30","quantity":"0.002"},{"price":"58761.00","quantity":"0.012"},{"price":"59379.50","quantity":"0.001"},{"price":"61043.60","quantity":"0.000"},{"price":"61151.70","quantity":"0.245"},{"price":"61235.20","quantity":"0.027"},{"price":"61275.90","quantity":"0.245"},{"price":"61313.50","quantity":"0.008"},{"price":"61543.40","quantity":"1.429"},{"price":"61771.60","quantity":"0.001"},{"price":"61784.20","quantity":"0.002"},{"price":"61786.30","quantity":"33.564"},{"price":"61792.90","quantity":"0.017"},{"price":"61799.80","quantity":"1.266"},{"price":"61821.00","quantity":"1.098"},{"price":"61821.10","quantity":"0.456"},{"price":"61823.40","quantity":"0.069"},{"price":"61824.10","quantity":"0.002"},{"price":"61834.00","quantity":"1.382"},{"price":"61834.10","quantity":"2.902"},{"price":"61835.10","quantity":"1.712"},{"price":"61835.40","quantity":"0.001"},{"price":"61835.50","quantity":"0.012"},{"price":"61835.60","quantity":"0.129"},{"price":"61836.90","quantity":"0.081"},{"price":"61837.30","quantity":"0.805"},{"price":"61838.60","quantity":"0.016"},{"price":"61844.70","quantity":"0.002"},{"price":"61844.90","quantity":"1.003"},{"price":"61845.00","quantity":"0.017"},{"price":"61845.10","quantity":"0.123"},{"price":"61846.30","quantity":"0.526"},{"price":"61847.70","quantity":"0.003"},{"price":"61848.00","quantity":"0.726"},{"price":"61850.60","quantity":"0.289"},{"price":"61850.70","quantity":"0.006"},{"price":"61852.10","quantity":"0.000"},{"price":"61852.40","quantity":"1.567"},{"price":"61853.50","quantity":"0.004"},{"price":"61853.60","quantity":"0.004"},{"price":"61853.70","quantity":"6.445"}],"asks":[{"price":"61853.80","quantity":"2.421"},{"price":"61853.90","quantity":"0.006"},{"price":"61854.40","quantity":"0.001"},{"price":"61855.50","quantity":"0.245"},{"price":"61856.00","quantity":"0.026"},{"price":"61856.40","quantity":"0.029"},{"price":"61858.70","quantity":"0.066"},{"price":"61858.90","quantity":"0.623"},{"price":"61859.00","quantity":"0.104"},{"price":"61859.10","quantity":"0.722"},{"price":"61859.20","quantity":"0.069"},{"price":"61859.30","quantity":"0.000"},{"price":"61859.80","quantity":"0.003"},{"price":"61859.90","quantity":"0.002"},{"price":"61860.80","quantity":"0.029"},{"price":"61861.50","quantity":"2.689"},{"price":"61863.80","quantity":"0.200"},{"price":"61868.70","quantity":"0.081"},{"price":"61869.70","quantity":"0.083"},{"price":"61871.00","quantity":"0.020"},{"price":"61913.50","quantity":"2.244"},{"price":"61916.30","quantity":"0.149"},{"price":"61916.40","quantity":"3.237"},{"price":"61918.20","quantity":"0.023"},{"price":"61918.40","quantity":"25.284"},{"price":"61926.40","quantity":"12.227"},{"price":"62472.30","quantity":"0.000"},{"price":"62768.60","quantity":"0.000"},{"price":"89523.20","quantity":"0.804"}],"raw":{"e":"depthUpdate","E":1783517069558,"T":1783517069557,"s":"BTCUSDT","ps":"BTCUSDT","U":10999770850644,"u":10999770859633,"pu":10999770850269,"b":[["11353.70","0.952"],["11553.70","0.176"],["11653.70","2.736"],["11753.70","1.036"],["55668.30","0.002"],["58761.00","0.012"],["59379.50","0.001"],["61043.60","0.000"],["61151.70","0.245"],["61235.20","0.027"],["61275.90","0.245"],["61313.50","0.008"],["61543.40","1.429"],["61771.60","0.001"],["61784.20","0.002"],["61786.30","33.564"],["61792.90","0.017"],["61799.80","1.266"],["61821.00","1.098"],["61821.10","0.456"],["61823.40","0.069"],["61824.10","0.002"],["61834.00","1.382"],["61834.10","2.902"],["61835.10","1.712"],["61835.40","0.001"],["61835.50","0.012"],["61835.60","0.129"],["61836.90","0.081"],["61837.30","0.805"],["61838.60","0.016"],["61844.70","0.002"],["61844.90","1.003"],["61845.00","0.017"],["61845.10","0.123"],["61846.30","0.526"],["61847.70","0.003"],["61848.00","0.726"],["61850.60","0.289"],["61850.70","0.006"],["61852.10","0.000"],["61852.40","1.567"],["61853.50","0.004"],["61853.60","0.004"],["61853.70","6.445"]],"a":[["61853.80","2.421"],["61853.90","0.006"],["61854.40","0.001"],["61855.50","0.245"],["61856.00","0.026"],["61856.40","0.029"],["61858.70","0.066"],["61858.90","0.623"],["61859.00","0.104"],["61859.10","0.722"],["61859.20","0.069"],["61859.30","0.000"],["61859.80","0.003"],["61859.90","0.002"],["61860.80","0.029"],["61861.50","2.689"],["61863.80","0.200"],["61868.70","0.081"],["61869.70","0.083"],["61871.00","0.020"],["61913.50","2.244"],["61916.30","0.149"],["61916.40","3.237"],["61918.20","0.023"],["61918.40","25.284"],["61926.40","12.227"],["62472.30","0.000"],["62768.60","0.000"],["89523.20","0.804"]],"st":1}}
{"schema_version":"1.3.0","event_id":"786256f8-e98b-4235-9073-15577eba4dd4","event_type":"raw.depth_update","source":"binance_market_data_recorder","venue":"binance_usdm","market_type":"perpetual_futures","symbol":"BTCUSDT","event_time_ms":1783517069660,"received_time_ms":1783517069654,"trace_id":"fa1abb1f-27f6-4bee-8052-15917b29719f","first_update_id":10999770859706,"final_update_id":10999770867877,"previous_final_update_id":10999770859633,"bids":[{"price":"1000.00","quantity":"207.692"},{"price":"11353.70","quantity":"0.816"},{"price":"11553.70","quantity":"0.320"},{"price":"11653.70","quantity":"2.720"},{"price":"11753.70","quantity":"1.044"},{"price":"55668.30","quantity":"0.002"},{"price":"58761.00","quantity":"0.012"},{"price":"59379.50","quantity":"0.004"},{"price":"60794.40","quantity":"0.000"},{"price":"60895.00","quantity":"2.460"},{"price":"60987.70","quantity":"7.651"},{"price":"61076.90","quantity":"3.497"},{"price":"61235.20","quantity":"0.025"},{"price":"61544.40","quantity":"0.013"},{"price":"61747.90","quantity":"0.000"},{"price":"61749.30","quantity":"0.000"},{"price":"61749.40","quantity":"0.014"},{"price":"61749.60","quantity":"0.024"},{"price":"61783.60","quantity":"0.057"},{"price":"61785.10","quantity":"0.015"},{"price":"61789.00","quantity":"6.328"},{"price":"61801.70","quantity":"0.070"},{"price":"61810.30","quantity":"1.591"},{"price":"61814.60","quantity":"0.005"},{"price":"61816.10","quantity":"0.014"},{"price":"61822.50","quantity":"0.761"},{"price":"61823.80","quantity":"0.081"},{"price":"61833.90","quantity":"0.081"},{"price":"61836.90","quantity":"0.001"},{"price":"61843.10","quantity":"0.907"},{"price":"61844.20","quantity":"1.291"},{"price":"61845.00","quantity":"0.009"},{"price":"61845.10","quantity":"0.123"},{"price":"61846.30","quantity":"0.648"},{"price":"61852.40","quantity":"0.670"},{"price":"61853.60","quantity":"0.005"}],"asks":[{"price":"61853.80","quantity":"2.540"},{"price":"61854.80","quantity":"0.001"},{"price":"61854.90","quantity":"0.258"},{"price":"61855.50","quantity":"0.003"},{"price":"61857.00","quantity":"0.713"},{"price":"61858.80","quantity":"0.000"},{"price":"61859.10","quantity":"0.491"},{"price":"61863.10","quantity":"0.000"},{"price":"61863.90","quantity":"1.276"},{"price":"61869.00","quantity":"0.147"},{"price":"61870.50","quantity":"0.178"},{"price":"61892.50","quantity":"0.116"},{"price":"61899.00","quantity":"0.017"},{"price":"61900.50","quantity":"0.030"},{"price":"61926.40","quantity":"12.130"},{"price":"61933.50","quantity":"0.001"},{"price":"61935.00","quantity":"0.014"},{"price":"62027.60","quantity":"0.008"},{"price":"62027.80","quantity":"0.003"},{"price":"62472.30","quantity":"0.000"},{"price":"62778.20","quantity":"0.716"}],"raw":{"e":"depthUpdate","E":1783517069660,"T":1783517069658,"s":"BTCUSDT","ps":"BTCUSDT","U":10999770859706,"u":10999770867877,"pu":10999770859633,"b":[["1000.00","207.692"],["11353.70","0.816"],["11553.70","0.320"],["11653.70","2.720"],["11753.70","1.044"],["55668.30","0.002"],["58761.00","0.012"],["59379.50","0.004"],["60794.40","0.000"],["60895.00","2.460"],["60987.70","7.651"],["61076.90","3.497"],["61235.20","0.025"],["61544.40","0.013"],["61747.90","0.000"],["61749.30","0.000"],["61749.40","0.014"],["61749.60","0.024"],["61783.60","0.057"],["61785.10","0.015"],["61789.00","6.328"],["61801.70","0.070"],["61810.30","1.591"],["61814.60","0.005"],["61816.10","0.014"],["61822.50","0.761"],["61823.80","0.081"],["61833.90","0.081"],["61836.90","0.001"],["61843.10","0.907"],["61844.20","1.291"],["61845.00","0.009"],["61845.10","0.123"],["61846.30","0.648"],["61852.40","0.670"],["61853.60","0.005"]],"a":[["61853.80","2.540"],["61854.80","0.001"],["61854.90","0.258"],["61855.50","0.003"],["61857.00","0.713"],["61858.80","0.000"],["61859.10","0.491"],["61863.10","0.000"],["61863.90","1.276"],["61869.00","0.147"],["61870.50","0.178"],["61892.50","0.116"],["61899.00","0.017"],["61900.50","0.030"],["61926.40","12.130"],["61933.50","0.001"],["61935.00","0.014"],["62027.60","0.008"],["62027.80","0.003"],["62472.30","0.000"],["62778.20","0.716"]],"st":1}}
{"schema_version":"1.3.0","event_id":"4543e6e1-831e-480c-906c-fe345d17457f","event_type":"raw.depth_update","source":"binance_market_data_recorder","venue":"binance_usdm","market_type":"perpetual_futures","symbol":"BTCUSDT","event_time_ms":1783517069762,"received_time_ms":1783517069759,"trace_id":"2420b4a3-6d6f-4503-a6df-c97a6854dea7","first_update_id":10999770868001,"final_update_id":10999770875462,"previous_final_update_id":10999770867877,"bids":[{"price":"1000.00","quantity":"207.692"},{"price":"11353.70","quantity":"0.663"},{"price":"11553.70","quantity":"0.448"},{"price":"11653.70","quantity":"2.736"},{"price":"11753.70","quantity":"1.053"},{"price":"49483.00","quantity":"0.008"},{"price":"55668.30","quantity":"0.002"},{"price":"58761.00","quantity":"0.012"},{"price":"60717.80","quantity":"0.000"},{"price":"61049.10","quantity":"1.144"},{"price":"61169.90","quantity":"0.491"},{"price":"61235.20","quantity":"0.025"},{"price":"61335.70","quantity":"0.039"},{"price":"61763.50","quantity":"0.001"},{"price":"61823.80","quantity":"0.001"},{"price":"61826.60","quantity":"0.113"},{"price":"61827.50","quantity":"2.750"},{"price":"61827.90","quantity":"0.622"},{"price":"61828.10","quantity":"0.122"},{"price":"61829.10","quantity":"0.218"},{"price":"61832.20","quantity":"0.010"},{"price":"61833.90","quantity":"0.001"},{"price":"61834.40","quantity":"0.171"},{"price":"61838.10","quantity":"0.483"},{"price":"61840.00","quantity":"0.512"},{"price":"61840.30","quantity":"0.123"},{"price":"61840.40","quantity":"0.004"},{"price":"61840.50","quantity":"2.138"},{"price":"61840.60","quantity":"0.566"},{"price":"61840.70","quantity":"0.003"},{"price":"61841.40","quantity":"0.955"},{"price":"61841.60","quantity":"0.053"},{"price":"61843.10","quantity":"0.018"},{"price":"61844.50","quantity":"0.326"},{"price":"61845.00","quantity":"0.332"},{"price":"61845.10","quantity":"0.689"},{"price":"61847.60","quantity":"0.004"},{"price":"61847.80","quantity":"0.004"},{"price":"61852.20","quantity":"0.632"},{"price":"61853.70","quantity":"6.445"}],"asks":[{"price":"61853.80","quantity":"2.429"},{"price":"61857.10","quantity":"0.001"},{"price":"61858.10","quantity":"0.154"},{"price":"61858.30","quantity":"0.014"},{"price":"61858.50","quantity":"0.776"},{"price":"61858.60","quantity":"0.001"},{"price":"61858.70","quantity":"0.001"},{"price":"61858.80","quantity":"0.000"},{"price":"61858.90","quantity":"0.057"},{"price":"61859.10","quantity":"0.000"},{"price":"61859.40","quantity":"0.002"},{"price":"61859.80","quantity":"0.002"},{"price":"61859.90","quantity":"0.002"},{"price":"61860.20","quantity":"2.529"},{"price":"61861.60","quantity":"0.320"},{"price":"61865.60","quantity":"0.184"},{"price":"61866.10","quantity":"0.582"},{"price":"61869.00","quantity":"0.147"},{"price":"61869.40","quantity":"0.128"},{"price":"61870.00","quantity":"0.411"},{"price":"61871.10","quantity":"0.019"},{"price":"61872.80","quantity":"0.000"},{"price":"61926.40","quantity":"12.227"},{"price":"62472.30","quantity":"0.000"},{"price":"63089.30","quantity":"0.090"},{"price":"89523.20","quantity":"0.810"}],"raw":{"e":"depthUpdate","E":1783517069762,"T":1783517069761,"s":"BTCUSDT","ps":"BTCUSDT","U":10999770868001,"u":10999770875462,"pu":10999770867877,"b":[["1000.00","207.692"],["11353.70","0.663"],["11553.70","0.448"],["11653.70","2.736"],["11753.70","1.053"],["49483.00","0.008"],["55668.30","0.002"],["58761.00","0.012"],["60717.80","0.000"],["61049.10","1.144"],["61169.90","0.491"],["61235.20","0.025"],["61335.70","0.039"],["61763.50","0.001"],["61823.80","0.001"],["61826.60","0.113"],["61827.50","2.750"],["61827.90","0.622"],["61828.10","0.122"],["61829.10","0.218"],["61832.20","0.010"],["61833.90","0.001"],["61834.40","0.171"],["61838.10","0.483"],["61840.00","0.512"],["61840.30","0.123"],["61840.40","0.004"],["61840.50","2.138"],["61840.60","0.566"],["61840.70","0.003"],["61841.40","0.955"],["61841.60","0.053"],["61843.10","0.018"],["61844.50","0.326"],["61845.00","0.332"],["61845.10","0.689"],["61847.60","0.004"],["61847.80","0.004"],["61852.20","0.632"],["61853.70","6.445"]],"a":[["61853.80","2.429"],["61857.10","0.001"],["61858.10","0.154"],["61858.30","0.014"],["61858.50","0.776"],["61858.60","0.001"],["61858.70","0.001"],["61858.80","0.000"],["61858.90","0.057"],["61859.10","0.000"],["61859.40","0.002"],["61859.80","0.002"],["61859.90","0.002"],["61860.20","2.529"],["61861.60","0.320"],["61865.60","0.184"],["61866.10","0.582"],["61869.00","0.147"],["61869.40","0.128"],["61870.00","0.411"],["61871.10","0.019"],["61872.80","0.000"],["61926.40","12.227"],["62472.30","0.000"],["63089.30","0.090"],["89523.20","0.810"]],"st":1}}
{"schema_version":"1.3.0","event_id":"c858634f-cd01-4efa-8fce-1630e8bee290","event_type":"raw.depth_update","source":"binance_market_data_recorder","venue":"binance_usdm","market_type":"perpetual_futures","symbol":"BTCUSDT","event_time_ms":1783517069864,"received_time_ms":1783517069858,"trace_id":"f1f09b41-d097-42e8-ae81-052966fe041d","first_update_id":10999770875480,"final_update_id":10999770881747,"previous_final_update_id":10999770875462,"bids":[{"price":"11353.70","quantity":"0.527"},{"price":"11553.70","quantity":"0.704"},{"price":"11653.70","quantity":"2.496"},{"price":"11753.70","quantity":"1.173"},{"price":"49483.00","quantity":"0.000"},{"price":"55668.30","quantity":"0.002"},{"price":"59379.50","quantity":"0.001"},{"price":"60788.60","quantity":"4.452"},{"price":"61235.20","quantity":"0.025"},{"price":"61260.70","quantity":"1.487"},{"price":"61339.30","quantity":"0.034"},{"price":"61352.40","quantity":"0.338"},{"price":"61537.60","quantity":"0.348"},{"price":"61544.40","quantity":"0.012"},{"price":"61826.10","quantity":"1.051"},{"price":"61833.50","quantity":"0.040"},{"price":"61838.10","quantity":"0.403"},{"price":"61840.00","quantity":"0.592"},{"price":"61840.10","quantity":"0.002"}],"asks":[{"price":"61853.90","quantity":"0.009"},{"price":"61854.60","quantity":"0.005"},{"price":"61858.50","quantity":"0.776"},{"price":"61859.60","quantity":"0.163"},{"price":"61859.80","quantity":"0.128"},{"price":"61859.90","quantity":"1.618"},{"price":"61860.20","quantity":"0.913"},{"price":"61861.70","quantity":"0.000"},{"price":"61862.80","quantity":"0.346"},{"price":"61871.20","quantity":"0.027"},{"price":"61893.00","quantity":"0.373"},{"price":"61926.40","quantity":"12.130"},{"price":"62163.10","quantity":"0.001"},{"price":"62472.30","quantity":"0.002"},{"price":"62781.60","quantity":"0.358"},{"price":"63348.50","quantity":"0.000"}],"raw":{"e":"depthUpdate","E":1783517069864,"T":1783517069863,"s":"BTCUSDT","ps":"BTCUSDT","U":10999770875480,"u":10999770881747,"pu":10999770875462,"b":[["11353.70","0.527"],["11553.70","0.704"],["11653.70","2.496"],["11753.70","1.173"],["49483.00","0.000"],["55668.30","0.002"],["59379.50","0.001"],["60788.60","4.452"],["61235.20","0.025"],["61260.70","1.487"],["61339.30","0.034"],["61352.40","0.338"],["61537.60","0.348"],["61544.40","0.012"],["61826.10","1.051"],["61833.50","0.040"],["61838.10","0.403"],["61840.00","0.592"],["61840.10","0.002"]],"a":[["61853.90","0.009"],["61854.60","0.005"],["61858.50","0.776"],["61859.60","0.163"],["61859.80","0.128"],["61859.90","1.618"],["61860.20","0.913"],["61861.70","0.000"],["61862.80","0.346"],["61871.20","0.027"],["61893.00","0.373"],["61926.40","12.130"],["62163.10","0.001"],["62472.30","0.002"],["62781.60","0.358"],["63348.50","0.000"]],"st":1}}
{"schema_version":"1.3.0","event_id":"494f8951-dbf7-4a78-ab6c-54e805e3c1f4","event_type":"raw.depth_update","source":"binance_market_data_recorder","venue":"binance_usdm","market_type":"perpetual_futures","symbol":"BTCUSDT","event_time_ms":1783517069966,"received_time_ms":1783517069963,"trace_id":"137248ca-ba80-4b90-b489-2a99adffe07f","first_update_id":10999770881792,"final_update_id":10999770887268,"previous_final_update_id":10999770881747,"bids":[{"price":"1000.00","quantity":"207.692"},{"price":"11353.70","quantity":"0.374"},{"price":"11553.70","quantity":"0.976"},{"price":"11653.70","quantity":"2.224"},{"price":"11753.70","quantity":"1.326"},{"price":"55668.30","quantity":"0.002"},{"price":"58761.00","quantity":"0.012"},{"price":"59379.50","quantity":"0.004"},{"price":"60616.70","quantity":"0.038"},{"price":"60909.40","quantity":"16.796"},{"price":"61235.20","quantity":"0.025"},{"price":"61266.10","quantity":"1.621"},{"price":"61358.90","quantity":"5.292"},{"price":"61544.40","quantity":"0.013"},{"price":"61812.20","quantity":"1.187"},{"price":"61832.30","quantity":"0.082"},{"price":"61840.00","quantity":"0.512"},{"price":"61845.20","quantity":"0.323"},{"price":"61846.30","quantity":"0.325"}],"asks":[{"price":"61859.80","quantity":"0.325"},{"price":"61860.20","quantity":"0.590"},{"price":"61893.00","quantity":"0.000"},{"price":"61893.30","quantity":"0.680"},{"price":"62163.10","quantity":"0.002"},{"price":"62472.30","quantity":"0.000"},{"price":"62835.20","quantity":"0.000"},{"price":"89523.20","quantity":"0.816"}],"raw":{"e":"depthUpdate","E":1783517069966,"T":1783517069965,"s":"BTCUSDT","ps":"BTCUSDT","U":10999770881792,"u":10999770887268,"pu":10999770881747,"b":[["1000.00","207.692"],["11353.70","0.374"],["11553.70","0.976"],["11653.70","2.224"],["11753.70","1.326"],["55668.30","0.002"],["58761.00","0.012"],["59379.50","0.004"],["60616.70","0.038"],["60909.40","16.796"],["61235.20","0.025"],["61266.10","1.621"],["61358.90","5.292"],["61544.40","0.013"],["61812.20","1.187"],["61832.30","0.082"],["61840.00","0.512"],["61845.20","0.323"],["61846.30","0.325"]],"a":[["61859.80","0.325"],["61860.20","0.590"],["61893.00","0.000"],["61893.30","0.680"],["62163.10","0.002"],["62472.30","0.000"],["62835.20","0.000"],["89523.20","0.816"]],"st":1}}
{"schema_version":"1.3.0","event_id":"7f74313c-a23e-4c28-bcee-d00267ed6f74","event_type":"raw.depth_update","source":"binance_market_data_recorder","venue":"binance_usdm","market_type":"perpetual_futures","symbol":"BTCUSDT","event_time_ms":1783517070068,"received_time_ms":1783517070063,"trace_id":"7dd00f11-dd63-4216-901e-f57021502acf","first_update_id":10999770887370,"final_update_id":10999770894683,"previous_final_update_id":10999770887268,"bids":[{"price":"1000.00","quantity":"207.692"},{"price":"11353.70","quantity":"0.238"},{"price":"11553.70","quantity":"1.248"},{"price":"11653.70","quantity":"1.952"},{"price":"11753.70","quantity":"1.462"},{"price":"55668.30","quantity":"0.002"},{"price":"58761.00","quantity":"0.012"},{"price":"59379.50","quantity":"0.001"},{"price":"60615.20","quantity":"0.000"},{"price":"61173.30","quantity":"0.256"},{"price":"61235.20","quantity":"0.025"},{"price":"61723.20","quantity":"0.513"},{"price":"61811.10","quantity":"0.016"},{"price":"61811.60","quantity":"0.170"},{"price":"61821.10","quantity":"0.561"},{"price":"61832.30","quantity":"0.002"},{"price":"61837.00","quantity":"0.002"},{"price":"61838.20","quantity":"0.609"},{"price":"61842.60","quantity":"0.081"}],"asks":[{"price":"61859.70","quantity":"0.127"},{"price":"61860.00","quantity":"0.595"},{"price":"61861.40","quantity":"0.167"},{"price":"61863.70","quantity":"0.250"},{"price":"61864.90","quantity":"0.054"},{"price":"61866.20","quantity":"0.570"},{"price":"61868.20","quantity":"0.064"},{"price":"61868.60","quantity":"0.004"},{"price":"61872.40","quantity":"0.007"},{"price":"61889.70","quantity":"0.157"},{"price":"61890.20","quantity":"0.022"},{"price":"61909.00","quantity":"0.032"},{"price":"61909.20","quantity":"0.176"},{"price":"61970.90","quantity":"0.007"},{"price":"61985.60","quantity":"0.806"},{"price":"62465.90","quantity":"0.000"},{"price":"62472.30","quantity":"0.000"},{"price":"63036.60","quantity":"0.000"}],"raw":{"e":"depthUpdate","E":1783517070068,"T":1783517070065,"s":"BTCUSDT","ps":"BTCUSDT","U":10999770887370,"u":10999770894683,"pu":10999770887268,"b":[["1000.00","207.692"],["11353.70","0.238"],["11553.70","1.248"],["11653.70","1.952"],["11753.70","1.462"],["55668.30","0.002"],["58761.00","0.012"],["59379.50","0.001"],["60615.20","0.000"],["61173.30","0.256"],["61235.20","0.025"],["61723.20","0.513"],["61811.10","0.016"],["61811.60","0.170"],["61821.10","0.561"],["61832.30","0.002"],["61837.00","0.002"],["61838.20","0.609"],["61842.60","0.081"]],"a":[["61859.70","0.127"],["61860.00","0.595"],["61861.40","0.167"],["61863.70","0.250"],["61864.90","0.054"],["61866.20","0.570"],["61868.20","0.064"],["61868.60","0.004"],["61872.40","0.007"],["61889.70","0.157"],["61890.20","0.022"],["61909.00","0.032"],["61909.20","0.176"],["61970.90","0.007"],["61985.60","0.806"],["62465.90","0.000"],["62472.30","0.000"],["63036.60","0.000"]],"st":1}}
{"schema_version":"1.3.0","event_id":"389adc10-1e6a-4346-96db-a83349e2e25b","event_type":"raw.depth_update","source":"binance_market_data_recorder","venue":"binance_usdm","market_type":"perpetual_futures","symbol":"BTCUSDT","event_time_ms":1783517070170,"received_time_ms":1783517070291,"trace_id":"6b13d940-864b-4963-8426-7d4b9bda234a","first_update_id":10999770894946,"final_update_id":10999770908242,"previous_final_update_id":10999770894683,"bids":[{"price":"11353.70","quantity":"0.085"},{"price":"11553.70","quantity":"1.424"},{"price":"11554.10","quantity":"0.096"},{"price":"11653.70","quantity":"1.680"},{"price":"11753.70","quantity":"1.547"},{"price":"11754.10","quantity":"0.068"},{"price":"55668.30","quantity":"0.000"},{"price":"55668.60","quantity":"0.002"},{"price":"58761.00","quantity":"0.012"},{"price":"60846.40","quantity":"0.001"},{"price":"60848.70","quantity":"0.010"},{"price":"60851.40","quantity":"0.000"},{"price":"60851.60","quantity":"0.020"},{"price":"60854.10","quantity":"0.013"},{"price":"60886.30","quantity":"0.009"},{"price":"60887.90","quantity":"3.457"},{"price":"60925.80","quantity":"0.407"},{"price":"60984.10","quantity":"8.595"},{"price":"61235.20","quantity":"0.025"},{"price":"61235.60","quantity":"0.328"},{"price":"61606.70","quantity":"2.973"},{"price":"61751.00","quantity":"0.201"},{"price":"61763.20","quantity":"33.581"},{"price":"61765.30","quantity":"0.072"},{"price":"61767.50","quantity":"2.323"},{"price":"61770.50","quantity":"0.003"},{"price":"61776.60","quantity":"0.000"},{"price":"61785.00","quantity":"0.001"},{"price":"61786.30","quantity":"0.002"},{"price":"61788.20","quantity":"1.290"},{"price":"61789.00","quantity":"1.492"},{"price":"61789.30","quantity":"0.000"},{"price":"61789.80","quantity":"0.002"},{"price":"61792.60","quantity":"0.000"},{"price":"61794.10","quantity":"0.008"},{"price":"61796.30","quantity":"0.211"},{"price":"61798.90","quantity":"0.000"},{"price":"61799.80","quantity":"1.071"},{"price":"61800.80","quantity":"0.119"},{"price":"61801.70","quantity":"0.000"},{"price":"61802.20","quantity":"0.003"},{"price":"61802.90","quantity":"0.823"},{"price":"61808.90","quantity":"0.108"},{"price":"61809.50","quantity":"0.063"},{"price":"61811.10","quantity":"0.016"},{"price":"61811.50","quantity":"0.115"},{"price":"61811.60","quantity":"0.069"},{"price":"61811.90","quantity":"0.001"},{"price":"61812.60","quantity":"0.033"},{"price":"61813.40","quantity":"0.062"},{"price":"61813.70","quantity":"1.381"},{"price":"61815.00","quantity":"1.415"},{"price":"61815.70","quantity":"0.103"},{"price":"61816.30","quantity":"0.491"},{"price":"61816.70","quantity":"0.055"},{"price":"61816.90","quantity":"0.015"},{"price":"61817.00","quantity":"0.002"},{"price":"61817.30","quantity":"1.771"},{"price":"61817.40","quantity":"0.105"},{"price":"61818.10","quantity":"0.253"},{"price":"61818.30","quantity":"0.000"},{"price":"61818.80","quantity":"0.292"},{"price":"61819.60","quantity":"0.003"},{"price":"61819.70","quantity":"0.000"},{"price":"61821.00","quantity":"1.009"},{"price":"61821.10","quantity":"0.803"},{"price":"61821.60","quantity":"0.004"},{"price":"61821.70","quantity":"1.088"},{"price":"61822.00","quantity":"0.121"},{"price":"61822.30","quantity":"0.002"},{"price":"61822.70","quantity":"0.013"},{"price":"61822.90","quantity":"0.003"},{"price":"61823.00","quantity":"2.166"},{"price":"61823.20","quantity":"0.515"},{"price":"61823.70","quantity":"1.294"},{"price":"61823.80","quantity":"0.150"},{"price":"61824.00","quantity":"0.340"},{"price":"61824.10","quantity":"0.002"},{"price":"61824.30","quantity":"0.197"},{"price":"61824.50","quantity":"0.421"},{"price":"61824.60","quantity":"0.110"},{"price":"61825.00","quantity":"1.335"},{"price":"61825.10","quantity":"0.360"},{"price":"61825.30","quantity":"0.003"},{"price":"61825.90","quantity":"0.093"},{"price":"61826.10","quantity":"1.245"},{"price":"61826.20","quantity":"0.191"},{"price":"61826.50","quantity":"0.958"},{"price":"61827.50","quantity":"2.168"},{"price":"61827.60","quantity":"0.007"},{"price":"61828.10","quantity":"0.008"},{"price":"61828.30","quantity":"0.583"},{"price":"61829.20","quantity":"0.293"},{"price":"61829.40","quantity":"2.288"},{"price":"61830.10","quantity":"0.122"},{"price":"61830.40","quantity":"0.130"},{"price":"61830.50","quantity":"0.000"},{"price":"61830.80","quantity":"0.001"},{"price":"61830.90","quantity":"0.001"},{"price":"61831.20","quantity":"0.060"},{"price":"61831.40","quantity":"0.436"},{"price":"61832.10","quantity":"0.114"},{"price":"61833.40","quantity":"0.007"},{"price":"61833.80","quantity":"0.968"},{"price":"61834.10","quantity":"2.900"},{"price":"61834.30","quantity":"0.704"},{"price":"61834.40","quantity":"0.124"},{"price":"61834.70","quantity":"0.013"},{"price":"61835.20","quantity":"0.002"},{"price":"61835.30","quantity":"0.320"},{"price":"61835.40","quantity":"0.001"},{"price":"61835.60","quantity":"0.139"},{"price":"61835.70","quantity":"0.003"},{"price":"61837.30","quantity":"0.803"},{"price":"61837.40","quantity":"0.811"},{"price":"61837.90","quantity":"1.646"},{"price":"61838.00","quantity":"1.002"},{"price":"61838.20","quantity":"0.325"},{"price":"61838.50","quantity":"0.012"},{"price":"61838.60","quantity":"0.000"},{"price":"61839.50","quantity":"0.128"},{"price":"61840.60","quantity":"0.696"},{"price":"61841.30","quantity":"0.105"},{"price":"61841.40","quantity":"0.951"},{"price":"61841.50","quantity":"0.221"},{"price":"61841.60","quantity":"0.053"},{"price":"61841.70","quantity":"0.518"},{"price":"61841.80","quantity":"0.085"},{"price":"61841.90","quantity":"0.384"},{"price":"61842.00","quantity":"0.069"},{"price":"61842.10","quantity":"0.001"},{"price":"61843.00","quantity":"0.001"},{"price":"61843.10","quantity":"0.010"},{"price":"61843.40","quantity":"0.062"},{"price":"61843.60","quantity":"0.899"},{"price":"61844.60","quantity":"0.037"},{"price":"61845.00","quantity":"0.009"},{"price":"61845.10","quantity":"0.123"},{"price":"61845.20","quantity":"0.323"},{"price":"61845.30","quantity":"0.005"},{"price":"61845.80","quantity":"0.000"},{"price":"61846.20","quantity":"0.101"},{"price":"61846.30","quantity":"0.001"},{"price":"61846.70","quantity":"0.016"},{"price":"61846.80","quantity":"0.564"},{"price":"61847.60","quantity":"0.008"},{"price":"61847.80","quantity":"0.004"},{"price":"61848.80","quantity":"0.002"},{"price":"61848.90","quantity":"0.004"},{"price":"61849.20","quantity":"0.002"},{"price":"61849.90","quantity":"0.004"},{"price":"61850.60","quantity":"0.287"},{"price":"61850.70","quantity":"0.002"},{"price":"61851.20","quantity":"0.001"},{"price":"61851.30","quantity":"0.002"},{"price":"61852.30","quantity":"0.007"},{"price":"61852.40","quantity":"0.000"},{"price":"61852.50","quantity":"0.001"},{"price":"61852.60","quantity":"0.001"},{"price":"61852.90","quantity":"0.006"},{"price":"61853.50","quantity":"0.004"},{"price":"61853.60","quantity":"0.002"},{"price":"61853.70","quantity":"0.418"},{"price":"61853.80","quantity":"1.800"},{"price":"61853.90","quantity":"0.598"},{"price":"61854.00","quantity":"0.005"},{"price":"61854.10","quantity":"23.111"}],"asks":[{"price":"61853.80","quantity":"0.000"},{"price":"61853.90","quantity":"0.000"},{"price":"61854.00","quantity":"0.000"},{"price":"61854.20","quantity":"1.501"},{"price":"61854.30","quantity":"0.025"},{"price":"61854.50","quantity":"0.027"},{"price":"61854.70","quantity":"0.369"},{"price":"61854.90","quantity":"0.016"},{"price":"61855.60","quantity":"0.023"},{"price":"61855.90","quantity":"0.000"},{"price":"61856.10","quantity":"0.000"},{"price":"61856.30","quantity":"0.030"},{"price":"61856.40","quantity":"0.029"},{"price":"61856.50","quantity":"0.000"},{"price":"61856.70","quantity":"0.001"},{"price":"61856.90","quantity":"0.220"},{"price":"61857.30","quantity":"1.001"},{"price":"61857.40","quantity":"0.005"},{"price":"61857.60","quantity":"0.051"},{"price":"61857.70","quantity":"0.249"},{"price":"61857.90","quantity":"0.005"},{"price":"61858.10","quantity":"0.089"},{"price":"61858.40","quantity":"0.001"},{"price":"61858.50","quantity":"0.614"},{"price":"61858.90","quantity":"0.053"},{"price":"61859.20","quantity":"0.010"},{"price":"61859.50","quantity":"0.084"},{"price":"61859.70","quantity":"0.127"},{"price":"61859.90","quantity":"1.616"},{"price":"61860.00","quantity":"0.176"},{"price":"61860.20","quantity":"0.589"},{"price":"61860.30","quantity":"0.306"},{"price":"61860.40","quantity":"0.180"},{"price":"61860.80","quantity":"0.029"},{"price":"61861.00","quantity":"0.412"},{"price":"61861.30","quantity":"0.372"},{"price":"61861.50","quantity":"0.554"},{"price":"61861.80","quantity":"0.161"},{"price":"61862.70","quantity":"2.747"},{"price":"61863.20","quantity":"0.001"},{"price":"61863.90","quantity":"0.308"},{"price":"61864.00","quantity":"2.153"},{"price":"61864.90","quantity":"0.050"},{"price":"61865.20","quantity":"0.016"},{"price":"61865.50","quantity":"0.045"},{"price":"61865.70","quantity":"0.472"},{"price":"61865.80","quantity":"0.968"},{"price":"61866.10","quantity":"0.000"},{"price":"61866.20","quantity":"0.002"},{"price":"61866.50","quantity":"0.570"},{"price":"61866.60","quantity":"3.356"},{"price":"61866.70","quantity":"0.732"},{"price":"61866.80","quantity":"1.292"},{"price":"61866.90","quantity":"0.018"},{"price":"61867.10","quantity":"0.081"},{"price":"61867.40","quantity":"0.061"},{"price":"61867.60","quantity":"0.345"},{"price":"61867.80","quantity":"0.083"},{"price":"61867.90","quantity":"0.584"},{"price":"61868.20","quantity":"0.048"},{"price":"61868.90","quantity":"0.148"},{"price":"61869.40","quantity":"0.007"},{"price":"61870.00","quantity":"0.329"},{"price":"61870.40","quantity":"0.038"},{"price":"61870.60","quantity":"0.242"},{"price":"61870.70","quantity":"2.147"},{"price":"61870.90","quantity":"0.133"},{"price":"61871.00","quantity":"0.020"},{"price":"61871.10","quantity":"0.046"},{"price":"61871.80","quantity":"0.001"},{"price":"61872.10","quantity":"0.019"},{"price":"61872.40","quantity":"0.003"},{"price":"61872.60","quantity":"0.204"},{"price":"61873.20","quantity":"0.004"},{"price":"61873.30","quantity":"0.205"},{"price":"61873.50","quantity":"0.005"},{"price":"61873.60","quantity":"0.043"},{"price":"61873.80","quantity":"1.290"},{"price":"61874.10","quantity":"0.823"},{"price":"61874.90","quantity":"0.122"},{"price":"61875.40","quantity":"0.051"},{"price":"61876.10","quantity":"0.485"},{"price":"61877.40","quantity":"0.063"},{"price":"61877.50","quantity":"0.002"},{"price":"61878.00","quantity":"2.200"},{"price":"61878.20","quantity":"0.046"},{"price":"61878.50","quantity":"0.004"},{"price":"61878.60","quantity":"1.040"},{"price":"61878.70","quantity":"0.032"},{"price":"61878.80","quantity":"0.001"},{"price":"61879.00","quantity":"0.173"},{"price":"61879.50","quantity":"0.412"},{"price":"61879.60","quantity":"0.000"},{"price":"61880.20","quantity":"0.100"},{"price":"61880.50","quantity":"0.004"},{"price":"61881.20","quantity":"0.181"},{"price":"61881.30","quantity":"0.771"},{"price":"61882.50","quantity":"0.000"},{"price":"61882.90","quantity":"1.756"},{"price":"61883.00","quantity":"0.290"},{"price":"61883.50","quantity":"0.937"},{"price":"61885.10","quantity":"0.121"},{"price":"61886.40","quantity":"0.003"},{"price":"61886.60","quantity":"2.136"},{"price":"61887.50","quantity":"0.005"},{"price":"61887.70","quantity":"0.050"},{"price":"61888.10","quantity":"0.170"},{"price":"61888.20","quantity":"0.001"},{"price":"61888.80","quantity":"0.125"},{"price":"61889.10","quantity":"1.024"},{"price":"61889.70","quantity":"0.052"},{"price":"61889.80","quantity":"0.121"},{"price":"61889.90","quantity":"0.000"},{"price":"61890.20","quantity":"0.022"},{"price":"61890.30","quantity":"0.941"},{"price":"61890.40","quantity":"1.471"},{"price":"61891.20","quantity":"0.379"},{"price":"61891.30","quantity":"0.330"},{"price":"61891.90","quantity":"0.042"},{"price":"61893.00","quantity":"0.000"},{"price":"61893.20","quantity":"0.207"},{"price":"61893.40","quantity":"0.099"},{"price":"61893.50","quantity":"0.000"},{"price":"61895.00","quantity":"2.587"},{"price":"61895.30","quantity":"0.929"},{"price":"61895.50","quantity":"0.036"},{"price":"61895.80","quantity":"0.030"},{"price":"61896.10","quantity":"0.061"},{"price":"61897.50","quantity":"0.296"},{"price":"61897.70","quantity":"0.012"},{"price":"61898.30","quantity":"3.274"},{"price":"61900.30","quantity":"0.007"},{"price":"61900.60","quantity":"1.403"},{"price":"61901.50","quantity":"2.205"},{"price":"61902.10","quantity":"0.010"},{"price":"61905.40","quantity":"0.031"},{"price":"61906.10","quantity":"0.069"},{"price":"61907.70","quantity":"0.427"},{"price":"61909.40","quantity":"0.002"},{"price":"61909.90","quantity":"0.376"},{"price":"61915.00","quantity":"2.059"},{"price":"61919.00","quantity":"0.166"},{"price":"61926.40","quantity":"12.130"},{"price":"61930.50","quantity":"2.138"},{"price":"61939.90","quantity":"0.296"},{"price":"62027.80","quantity":"0.000"},{"price":"62027.90","quantity":"0.004"},{"price":"62122.20","quantity":"0.018"},{"price":"62472.30","quantity":"0.338"},{"price":"62472.60","quantity":"0.009"},{"price":"62472.70","quantity":"0.080"},{"price":"62565.30","quantity":"1.898"},{"price":"62565.90","quantity":"10.482"},{"price":"62627.00","quantity":"0.668"},{"price":"62627.80","quantity":"3.160"},{"price":"62818.10","quantity":"0.009"},{"price":"63090.80","quantity":"0.018"},{"price":"63091.20","quantity":"0.008"},{"price":"64947.00","quantity":"0.016"},{"price":"89523.20","quantity":"0.822"}],"raw":{"e":"depthUpdate","E":1783517070170,"T":1783517070169,"s":"BTCUSDT","ps":"BTCUSDT","U":10999770894946,"u":10999770908242,"pu":10999770894683,"b":[["11353.70","0.085"],["11553.70","1.424"],["11554.10","0.096"],["11653.70","1.680"],["11753.70","1.547"],["11754.10","0.068"],["55668.30","0.000"],["55668.60","0.002"],["58761.00","0.012"],["60846.40","0.001"],["60848.70","0.010"],["60851.40","0.000"],["60851.60","0.020"],["60854.10","0.013"],["60886.30","0.009"],["60887.90","3.457"],["60925.80","0.407"],["60984.10","8.595"],["61235.20","0.025"],["61235.60","0.328"],["61606.70","2.973"],["61751.00","0.201"],["61763.20","33.581"],["61765.30","0.072"],["61767.50","2.323"],["61770.50","0.003"],["61776.60","0.000"],["61785.00","0.001"],["61786.30","0.002"],["61788.20","1.290"],["61789.00","1.492"],["61789.30","0.000"],["61789.80","0.002"],["61792.60","0.000"],["61794.10","0.008"],["61796.30","0.211"],["61798.90","0.000"],["61799.80","1.071"],["61800.80","0.119"],["61801.70","0.000"],["61802.20","0.003"],["61802.90","0.823"],["61808.90","0.108"],["61809.50","0.063"],["61811.10","0.016"],["61811.50","0.115"],["61811.60","0.069"],["61811.90","0.001"],["61812.60","0.033"],["61813.40","0.062"],["61813.70","1.381"],["61815.00","1.415"],["61815.70","0.103"],["61816.30","0.491"],["61816.70","0.055"],["61816.90","0.015"],["61817.00","0.002"],["61817.30","1.771"],["61817.40","0.105"],["61818.10","0.253"],["61818.30","0.000"],["61818.80","0.292"],["61819.60","0.003"],["61819.70","0.000"],["61821.00","1.009"],["61821.10","0.803"],["61821.60","0.004"],["61821.70","1.088"],["61822.00","0.121"],["61822.30","0.002"],["61822.70","0.013"],["61822.90","0.003"],["61823.00","2.166"],["61823.20","0.515"],["61823.70","1.294"],["61823.80","0.150"],["61824.00","0.340"],["61824.10","0.002"],["61824.30","0.197"],["61824.50","0.421"],["61824.60","0.110"],["61825.00","1.335"],["61825.10","0.360"],["61825.30","0.003"],["61825.90","0.093"],["61826.10","1.245"],["61826.20","0.191"],["61826.50","0.958"],["61827.50","2.168"],["61827.60","0.007"],["61828.10","0.008"],["61828.30","0.583"],["61829.20","0.293"],["61829.40","2.288"],["61830.10","0.122"],["61830.40","0.130"],["61830.50","0.000"],["61830.80","0.001"],["61830.90","0.001"],["61831.20","0.060"],["61831.40","0.436"],["61832.10","0.114"],["61833.40","0.007"],["61833.80","0.968"],["61834.10","2.900"],["61834.30","0.704"],["61834.40","0.124"],["61834.70","0.013"],["61835.20","0.002"],["61835.30","0.320"],["61835.40","0.001"],["61835.60","0.139"],["61835.70","0.003"],["61837.30","0.803"],["61837.40","0.811"],["61837.90","1.646"],["61838.00","1.002"],["61838.20","0.325"],["61838.50","0.012"],["61838.60","0.000"],["61839.50","0.128"],["61840.60","0.696"],["61841.30","0.105"],["61841.40","0.951"],["61841.50","0.221"],["61841.60","0.053"],["61841.70","0.518"],["61841.80","0.085"],["61841.90","0.384"],["61842.00","0.069"],["61842.10","0.001"],["61843.00","0.001"],["61843.10","0.010"],["61843.40","0.062"],["61843.60","0.899"],["61844.60","0.037"],["61845.00","0.009"],["61845.10","0.123"],["61845.20","0.323"],["61845.30","0.005"],["61845.80","0.000"],["61846.20","0.101"],["61846.30","0.001"],["61846.70","0.016"],["61846.80","0.564"],["61847.60","0.008"],["61847.80","0.004"],["61848.80","0.002"],["61848.90","0.004"],["61849.20","0.002"],["61849.90","0.004"],["61850.60","0.287"],["61850.70","0.002"],["61851.20","0.001"],["61851.30","0.002"],["61852.30","0.007"],["61852.40","0.000"],["61852.50","0.001"],["61852.60","0.001"],["61852.90","0.006"],["61853.50","0.004"],["61853.60","0.002"],["61853.70","0.418"],["61853.80","1.800"],["61853.90","0.598"],["61854.00","0.005"],["61854.10","23.111"]],"a":[["61853.80","0.000"],["61853.90","0.000"],["61854.00","0.000"],["61854.20","1.501"],["61854.30","0.025"],["61854.50","0.027"],["61854.70","0.369"],["61854.90","0.016"],["61855.60","0.023"],["61855.90","0.000"],["61856.10","0.000"],["61856.30","0.030"],["61856.40","0.029"],["61856.50","0.000"],["61856.70","0.001"],["61856.90","0.220"],["61857.30","1.001"],["61857.40","0.005"],["61857.60","0.051"],["61857.70","0.249"],["61857.90","0.005"],["61858.10","0.089"],["61858.40","0.001"],["61858.50","0.614"],["61858.90","0.053"],["61859.20","0.010"],["61859.50","0.084"],["61859.70","0.127"],["61859.90","1.616"],["61860.00","0.176"],["61860.20","0.589"],["61860.30","0.306"],["61860.40","0.180"],["61860.80","0.029"],["61861.00","0.412"],["61861.30","0.372"],["61861.50","0.554"],["61861.80","0.161"],["61862.70","2.747"],["61863.20","0.001"],["61863.90","0.308"],["61864.00","2.153"],["61864.90","0.050"],["61865.20","0.016"],["61865.50","0.045"],["61865.70","0.472"],["61865.80","0.968"],["61866.10","0.000"],["61866.20","0.002"],["61866.50","0.570"],["61866.60","3.356"],["61866.70","0.732"],["61866.80","1.292"],["61866.90","0.018"],["61867.10","0.081"],["61867.40","0.061"],["61867.60","0.345"],["61867.80","0.083"],["61867.90","0.584"],["61868.20","0.048"],["61868.90","0.148"],["61869.40","0.007"],["61870.00","0.329"],["61870.40","0.038"],["61870.60","0.242"],["61870.70","2.147"],["61870.90","0.133"],["61871.00","0.020"],["61871.10","0.046"],["61871.80","0.001"],["61872.10","0.019"],["61872.40","0.003"],["61872.60","0.204"],["61873.20","0.004"],["61873.30","0.205"],["61873.50","0.005"],["61873.60","0.043"],["61873.80","1.290"],["61874.10","0.823"],["61874.90","0.122"],["61875.40","0.051"],["61876.10","0.485"],["61877.40","0.063"],["61877.50","0.002"],["61878.00","2.200"],["61878.20","0.046"],["61878.50","0.004"],["61878.60","1.040"],["61878.70","0.032"],["61878.80","0.001"],["61879.00","0.173"],["61879.50","0.412"],["61879.60","0.000"],["61880.20","0.100"],["61880.50","0.004"],["61881.20","0.181"],["61881.30","0.771"],["61882.50","0.000"],["61882.90","1.756"],["61883.00","0.290"],["61883.50","0.937"],["61885.10","0.121"],["61886.40","0.003"],["61886.60","2.136"],["61887.50","0.005"],["61887.70","0.050"],["61888.10","0.170"],["61888.20","0.001"],["61888.80","0.125"],["61889.10","1.024"],["61889.70","0.052"],["61889.80","0.121"],["61889.90","0.000"],["61890.20","0.022"],["61890.30","0.941"],["61890.40","1.471"],["61891.20","0.379"],["61891.30","0.330"],["61891.90","0.042"],["61893.00","0.000"],["61893.20","0.207"],["61893.40","0.099"],["61893.50","0.000"],["61895.00","2.587"],["61895.30","0.929"],["61895.50","0.036"],["61895.80","0.030"],["61896.10","0.061"],["61897.50","0.296"],["61897.70","0.012"],["61898.30","3.274"],["61900.30","0.007"],["61900.60","1.403"],["61901.50","2.205"],["61902.10","0.010"],["61905.40","0.031"],["61906.10","0.069"],["61907.70","0.427"],["61909.40","0.002"],["61909.90","0.376"],["61915.00","2.059"],["61919.00","0.166"],["61926.40","12.130"],["61930.50","2.138"],["61939.90","0.296"],["62027.80","0.000"],["62027.90","0.004"],["62122.20","0.018"],["62472.30","0.338"],["62472.60","0.009"],["62472.70","0.080"],["62565.30","1.898"],["62565.90","10.482"],["62627.00","0.668"],["62627.80","3.160"],["62818.10","0.009"],["63090.80","0.018"],["63091.20","0.008"],["64947.00","0.016"],["89523.20","0.822"]],"st":1}}
{"schema_version":"1.3.0","event_id":"82d19057-b51d-425f-9ada-33ae6118ac5b","event_type":"raw.depth_update","source":"binance_market_data_recorder","venue":"binance_usdm","market_type":"perpetual_futures","symbol":"BTCUSDT","event_time_ms":1783517070272,"received_time_ms":1783517070315,"trace_id":"b6ff28d1-edfe-4876-aff9-3e6bd86f17cb","first_update_id":10999770908337,"final_update_id":10999770918410,"previous_final_update_id":10999770908242,"bids":[{"price":"1000.00","quantity":"207.692"},{"price":"11353.70","quantity":"0.000"},{"price":"11554.10","quantity":"0.368"},{"price":"11653.70","quantity":"1.408"},{"price":"11654.10","quantity":"0.051"},{"price":"11754.10","quantity":"0.102"},{"price":"55668.60","quantity":"0.002"},{"price":"58759.60","quantity":"0.006"},{"price":"58761.30","quantity":"0.000"},{"price":"59379.90","quantity":"0.003"},{"price":"61235.60","quantity":"0.328"},{"price":"61544.40","quantity":"0.003"},{"price":"61740.90","quantity":"0.847"},{"price":"61763.20","quantity":"0.019"},{"price":"61784.20","quantity":"0.002"},{"price":"61785.20","quantity":"0.018"},{"price":"61786.30","quantity":"33.564"},{"price":"61794.20","quantity":"0.024"},{"price":"61802.00","quantity":"0.014"},{"price":"61810.70","quantity":"0.027"},{"price":"61811.80","quantity":"0.995"},{"price":"61811.90","quantity":"0.030"},{"price":"61815.50","quantity":"0.003"},{"price":"61823.40","quantity":"0.069"},{"price":"61823.50","quantity":"0.003"},{"price":"61823.80","quantity":"0.150"},{"price":"61827.40","quantity":"0.568"},{"price":"61836.70","quantity":"0.569"},{"price":"61838.00","quantity":"0.436"},{"price":"61841.80","quantity":"0.005"},{"price":"61844.40","quantity":"0.174"},{"price":"61847.80","quantity":"0.002"},{"price":"61852.60","quantity":"0.002"},{"price":"61853.70","quantity":"0.407"},{"price":"61854.00","quantity":"0.006"},{"price":"61854.10","quantity":"22.835"}],"asks":[{"price":"61854.20","quantity":"2.622"},{"price":"61854.30","quantity":"0.026"},{"price":"61856.00","quantity":"0.003"},{"price":"61856.50","quantity":"0.000"},{"price":"61856.60","quantity":"0.284"},{"price":"61857.20","quantity":"0.242"},{"price":"61857.70","quantity":"0.007"},{"price":"61859.70","quantity":"0.001"},{"price":"61863.90","quantity":"1.692"},{"price":"61864.10","quantity":"0.000"},{"price":"61867.60","quantity":"0.427"},{"price":"61867.80","quantity":"0.003"},{"price":"61869.70","quantity":"0.003"},{"price":"61872.10","quantity":"0.021"},{"price":"61874.10","quantity":"0.821"},{"price":"61874.20","quantity":"0.082"},{"price":"61875.40","quantity":"0.052"},{"price":"61889.40","quantity":"0.123"},{"price":"61890.30","quantity":"0.836"},{"price":"61890.40","quantity":"1.366"},{"price":"61891.30","quantity":"0.202"},{"price":"61893.20","quantity":"0.000"},{"price":"61893.50","quantity":"0.207"},{"price":"61897.40","quantity":"0.004"},{"price":"61918.40","quantity":"0.000"},{"price":"61918.60","quantity":"0.014"},{"price":"61920.50","quantity":"25.284"},{"price":"61931.00","quantity":"0.044"},{"price":"61960.20","quantity":"0.299"},{"price":"61970.20","quantity":"0.970"},{"price":"61972.00","quantity":"2.760"},{"price":"62460.20","quantity":"0.638"},{"price":"62472.70","quantity":"0.080"},{"price":"62565.30","quantity":"0.000"},{"price":"62565.90","quantity":"12.380"},{"price":"62819.70","quantity":"0.013"},{"price":"63060.00","quantity":"1.666"}],"raw":{"e":"depthUpdate","E":1783517070272,"T":1783517070270,"s":"BTCUSDT","ps":"BTCUSDT","U":10999770908337,"u":10999770918410,"pu":10999770908242,"b":[["1000.00","207.692"],["11353.70","0.000"],["11554.10","0.368"],["11653.70","1.408"],["11654.10","0.051"],["11754.10","0.102"],["55668.60","0.002"],["58759.60","0.006"],["58761.30","0.000"],["59379.90","0.003"],["61235.60","0.328"],["61544.40","0.003"],["61740.90","0.847"],["61763.20","0.019"],["61784.20","0.002"],["61785.20","0.018"],["61786.30","33.564"],["61794.20","0.024"],["61802.00","0.014"],["61810.70","0.027"],["61811.80","0.995"],["61811.90","0.030"],["61815.50","0.003"],["61823.40","0.069"],["61823.50","0.003"],["61823.80","0.150"],["61827.40","0.568"],["61836.70","0.569"],["61838.00","0.436"],["61841.80","0.005"],["61844.40","0.174"],["61847.80","0.002"],["61852.60","0.002"],["61853.70","0.407"],["61854.00","0.006"],["61854.10","22.835"]],"a":[["61854.20","2.622"],["61854.30","0.026"],["61856.00","0.003"],["61856.50","0.000"],["61856.60","0.284"],["61857.20","0.242"],["61857.70","0.007"],["61859.70","0.001"],["61863.90","1.692"],["61864.10","0.000"],["61867.60","0.427"],["61867.80","0.003"],["61869.70","0.003"],["61872.10","0.021"],["61874.10","0.821"],["61874.20","0.082"],["61875.40","0.052"],["61889.40","0.123"],["61890.30","0.836"],["61890.40","1.366"],["61891.30","0.202"],["61893.20","0.000"],["61893.50","0.207"],["61897.40","0.004"],["61918.40","0.000"],["61918.60","0.014"],["61920.50","25.284"],["61931.00","0.044"],["61960.20","0.299"],["61970.20","0.970"],["61972.00","2.760"],["62460.20","0.638"],["62472.70","0.080"],["62565.30","0.000"],["62565.90","12.380"],["62819.70","0.013"],["63060.00","1.666"]],"st":1}}
{"schema_version":"1.3.0","event_id":"d6d8aee5-44c2-43cc-bc30-f7fb22c65567","event_type":"raw.depth_update","source":"binance_market_data_recorder","venue":"binance_usdm","market_type":"perpetual_futures","symbol":"BTCUSDT","event_time_ms":1783517070374,"received_time_ms":1783517070368,"trace_id":"39053ca3-dc1e-40ab-9620-b5805da0de6d","first_update_id":10999770918538,"final_update_id":10999770928413,"previous_final_update_id":10999770918410,"bids":[{"price":"1000.00","quantity":"207.692"},{"price":"11554.10","quantity":"0.640"},{"price":"11653.70","quantity":"1.136"},{"price":"11654.10","quantity":"0.204"},{"price":"11753.70","quantity":"1.496"},{"price":"11754.10","quantity":"0.000"},{"price":"55668.60","quantity":"0.002"},{"price":"58761.00","quantity":"0.009"},{"price":"58761.10","quantity":"0.003"},{"price":"58761.30","quantity":"0.000"},{"price":"59379.90","quantity":"0.000"},{"price":"60987.70","quantity":"8.960"},{"price":"61235.60","quantity":"0.328"},{"price":"61520.00","quantity":"3.061"},{"price":"61537.60","quantity":"0.348"},{"price":"61585.50","quantity":"0.000"},{"price":"61585.60","quantity":"0.023"},{"price":"61600.00","quantity":"56.939"},{"price":"61672.30","quantity":"0.000"},{"price":"61680.00","quantity":"0.853"},{"price":"61691.40","quantity":"0.164"},{"price":"61760.00","quantity":"1.062"},{"price":"61815.40","quantity":"0.004"},{"price":"61815.50","quantity":"0.104"},{"price":"61821.90","quantity":"0.413"},{"price":"61823.40","quantity":"0.075"},{"price":"61823.50","quantity":"0.092"},{"price":"61826.80","quantity":"0.586"},{"price":"61828.10","quantity":"0.008"},{"price":"61828.30","quantity":"0.001"},{"price":"61829.20","quantity":"0.352"},{"price":"61830.40","quantity":"0.130"},{"price":"61831.20","quantity":"0.001"},{"price":"61832.50","quantity":"0.970"},{"price":"61833.80","quantity":"0.000"},{"price":"61839.30","quantity":"0.203"},{"price":"61840.00","quantity":"0.396"},{"price":"61840.60","quantity":"0.696"},{"price":"61841.40","quantity":"0.928"},{"price":"61843.00","quantity":"0.001"},{"price":"61843.60","quantity":"0.899"},{"price":"61854.10","quantity":"21.893"}],"asks":[{"price":"61854.20","quantity":"2.383"},{"price":"61854.30","quantity":"0.025"},{"price":"61855.40","quantity":"0.025"},{"price":"61856.20","quantity":"0.050"},{"price":"61856.30","quantity":"0.272"},{"price":"61856.50","quantity":"0.009"},{"price":"61856.60","quantity":"0.235"},{"price":"61856.70","quantity":"0.001"},{"price":"61857.20","quantity":"0.000"},{"price":"61863.50","quantity":"0.002"},{"price":"61863.70","quantity":"0.132"},{"price":"61864.40","quantity":"0.809"},{"price":"61864.50","quantity":"0.968"},{"price":"61865.80","quantity":"0.000"},{"price":"61869.70","quantity":"0.003"},{"price":"61872.80","quantity":"0.128"},{"price":"61889.00","quantity":"0.107"},{"price":"61889.40","quantity":"0.018"},{"price":"61893.10","quantity":"0.001"},{"price":"61893.50","quantity":"0.580"},{"price":"61918.40","quantity":"25.284"},{"price":"61920.00","quantity":"1.314"},{"price":"61920.50","quantity":"0.000"},{"price":"61926.60","quantity":"0.001"},{"price":"62000.00","quantity":"13.165"},{"price":"62080.00","quantity":"0.431"},{"price":"62160.00","quantity":"0.426"},{"price":"62240.00","quantity":"0.421"},{"price":"62472.70","quantity":"0.082"},{"price":"62627.20","quantity":"0.638"},{"price":"62628.00","quantity":"5.534"},{"price":"62654.30","quantity":"0.000"},{"price":"62838.50","quantity":"0.000"},{"price":"63091.20","quantity":"0.011"},{"price":"63732.20","quantity":"0.000"},{"price":"89523.20","quantity":"0.828"}],"raw":{"e":"depthUpdate","E":1783517070374,"T":1783517070373,"s":"BTCUSDT","ps":"BTCUSDT","U":10999770918538,"u":10999770928413,"pu":10999770918410,"b":[["1000.00","207.692"],["11554.10","0.640"],["11653.70","1.136"],["11654.10","0.204"],["11753.70","1.496"],["11754.10","0.000"],["55668.60","0.002"],["58761.00","0.009"],["58761.10","0.003"],["58761.30","0.000"],["59379.90","0.000"],["60987.70","8.960"],["61235.60","0.328"],["61520.00","3.061"],["61537.60","0.348"],["61585.50","0.000"],["61585.60","0.023"],["61600.00","56.939"],["61672.30","0.000"],["61680.00","0.853"],["61691.40","0.164"],["61760.00","1.062"],["61815.40","0.004"],["61815.50","0.104"],["61821.90","0.413"],["61823.40","0.075"],["61823.50","0.092"],["61826.80","0.586"],["61828.10","0.008"],["61828.30","0.001"],["61829.20","0.352"],["61830.40","0.130"],["61831.20","0.001"],["61832.50","0.970"],["61833.80","0.000"],["61839.30","0.203"],["61840.00","0.396"],["61840.60","0.696"],["61841.40","0.928"],["61843.00","0.001"],["61843.60","0.899"],["61854.10","21.893"]],"a":[["61854.20","2.383"],["61854.30","0.025"],["61855.40","0.025"],["61856.20","0.050"],["61856.30","0.272"],["61856.50","0.009"],["61856.60","0.235"],["61856.70","0.001"],["61857.20","0.000"],["61863.50","0.002"],["61863.70","0.132"],["61864.40","0.809"],["61864.50","0.968"],["61865.80","0.000"],["61869.70","0.003"],["61872.80","0.128"],["61889.00","0.107"],["61889.40","0.018"],["61893.10","0.001"],["61893.50","0.580"],["61918.40","25.284"],["61920.00","1.314"],["61920.50","0.000"],["61926.60","0.001"],["62000.00","13.165"],["62080.00","0.431"],["62160.00","0.426"],["62240.00","0.421"],["62472.70","0.082"],["62627.20","0.638"],["62628.00","5.534"],["62654.30","0.000"],["62838.50","0.000"],["63091.20","0.011"],["63732.20","0.000"],["89523.20","0.828"]],"st":1}}
{"schema_version":"1.3.0","event_id":"09ecbea6-dc50-440f-a6b7-3cbccc4db91d","event_type":"raw.depth_update","source":"binance_market_data_recorder","venue":"binance_usdm","market_type":"perpetual_futures","symbol":"BTCUSDT","event_time_ms":1783517070476,"received_time_ms":1783517070471,"trace_id":"55fd9cf8-533a-41b6-9ab0-e008f073d7bf","first_update_id":10999770928446,"final_update_id":10999770941612,"previous_final_update_id":10999770928413,"bids":[{"price":"11554.10","quantity":"0.912"},{"price":"11653.70","quantity":"0.864"},{"price":"11654.10","quantity":"0.340"},{"price":"11753.70","quantity":"1.360"},{"price":"55668.60","quantity":"0.002"},{"price":"58761.30","quantity":"0.000"},{"price":"59379.90","quantity":"0.003"},{"price":"60617.10","quantity":"0.003"},{"price":"61235.60","quantity":"0.328"},{"price":"61293.60","quantity":"1.044"},{"price":"61598.60","quantity":"0.000"},{"price":"61601.90","quantity":"0.027"},{"price":"61680.30","quantity":"0.065"},{"price":"61762.00","quantity":"1.554"},{"price":"61762.10","quantity":"0.009"},{"price":"61782.30","quantity":"1.539"},{"price":"61782.40","quantity":"0.029"},{"price":"61802.50","quantity":"0.053"},{"price":"61802.70","quantity":"9.387"},{"price":"61815.50","quantity":"0.104"},{"price":"61823.40","quantity":"0.451"},{"price":"61823.50","quantity":"0.092"},{"price":"61823.80","quantity":"0.255"},{"price":"61828.10","quantity":"0.008"},{"price":"61829.60","quantity":"0.099"},{"price":"61830.40","quantity":"0.050"},{"price":"61831.40","quantity":"0.331"},{"price":"61832.50","quantity":"0.002"},{"price":"61832.80","quantity":"1.311"},{"price":"61833.60","quantity":"0.055"},{"price":"61834.60","quantity":"0.049"},{"price":"61836.80","quantity":"0.081"},{"price":"61836.90","quantity":"0.001"},{"price":"61838.00","quantity":"0.000"},{"price":"61838.90","quantity":"0.505"},{"price":"61840.60","quantity":"0.696"},{"price":"61842.00","quantity":"0.046"},{"price":"61842.50","quantity":"0.030"},{"price":"61843.00","quantity":"0.081"},{"price":"61853.90","quantity":"0.552"},{"price":"61854.10","quantity":"20.956"}],"asks":[{"price":"61854.20","quantity":"2.639"},{"price":"61854.30","quantity":"0.025"},{"price":"61856.00","quantity":"0.004"},{"price":"61856.10","quantity":"0.242"},{"price":"61856.20","quantity":"0.002"},{"price":"61856.30","quantity":"0.030"},{"price":"61856.40","quantity":"0.078"},{"price":"61856.70","quantity":"0.001"},{"price":"61857.30","quantity":"1.000"},{"price":"61859.00","quantity":"0.144"},{"price":"61859.80","quantity":"0.487"},{"price":"61860.20","quantity":"0.648"},{"price":"61862.50","quantity":"0.163"},{"price":"61864.50","quantity":"0.000"},{"price":"61865.50","quantity":"0.005"},{"price":"61865.60","quantity":"1.152"},{"price":"61866.40","quantity":"0.163"},{"price":"61869.70","quantity":"0.003"},{"price":"61869.80","quantity":"0.174"},{"price":"61871.60","quantity":"0.004"},{"price":"61872.80","quantity":"0.128"},{"price":"61873.30","quantity":"0.367"},{"price":"61875.40","quantity":"0.051"},{"price":"61884.50","quantity":"0.005"},{"price":"61888.80","quantity":"0.230"},{"price":"61889.00","quantity":"0.002"},{"price":"61889.40","quantity":"0.018"},{"price":"61897.50","quantity":"0.296"},{"price":"61924.40","quantity":"1.529"},{"price":"61924.50","quantity":"0.000"},{"price":"61926.60","quantity":"0.001"},{"price":"61944.70","quantity":"1.539"},{"price":"61944.90","quantity":"0.001"},{"price":"61965.00","quantity":"1.538"},{"price":"61965.20","quantity":"0.824"},{"price":"62407.10","quantity":"0.480"},{"price":"62472.70","quantity":"0.080"},{"price":"62587.40","quantity":"0.001"}],"raw":{"e":"depthUpdate","E":1783517070476,"T":1783517070473,"s":"BTCUSDT","ps":"BTCUSDT","U":10999770928446,"u":10999770941612,"pu":10999770928413,"b":[["11554.10","0.912"],["11653.70","0.864"],["11654.10","0.340"],["11753.70","1.360"],["55668.60","0.002"],["58761.30","0.000"],["59379.90","0.003"],["60617.10","0.003"],["61235.60","0.328"],["61293.60","1.044"],["61598.60","0.000"],["61601.90","0.027"],["61680.30","0.065"],["61762.00","1.554"],["61762.10","0.009"],["61782.30","1.539"],["61782.40","0.029"],["61802.50","0.053"],["61802.70","9.387"],["61815.50","0.104"],["61823.40","0.451"],["61823.50","0.092"],["61823.80","0.255"],["61828.10","0.008"],["61829.60","0.099"],["61830.40","0.050"],["61831.40","0.331"],["61832.50","0.002"],["61832.80","1.311"],["61833.60","0.055"],["61834.60","0.049"],["61836.80","0.081"],["61836.90","0.001"],["61838.00","0.000"],["61838.90","0.505"],["61840.60","0.696"],["61842.00","0.046"],["61842.50","0.030"],["61843.00","0.081"],["61853.90","0.552"],["61854.10","20.956"]],"a":[["61854.20","2.639"],["61854.30","0.025"],["61856.00","0.004"],["61856.10","0.242"],["61856.20","0.002"],["61856.30","0.030"],["61856.40","0.078"],["61856.70","0.001"],["61857.30","1.000"],["61859.00","0.144"],["61859.80","0.487"],["61860.20","0.648"],["61862.50","0.163"],["61864.50","0.000"],["61865.50","0.005"],["61865.60","1.152"],["61866.40","0.163"],["61869.70","0.003"],["61869.80","0.174"],["61871.60","0.004"],["61872.80","0.128"],["61873.30","0.367"],["61875.40","0.051"],["61884.50","0.005"],["61888.80","0.230"],["61889.00","0.002"],["61889.40","0.018"],["61897.50","0.296"],["61924.40","1.529"],["61924.50","0.000"],["61926.60","0.001"],["61944.70","1.539"],["61944.90","0.001"],["61965.00","1.538"],["61965.20","0.824"],["62407.10","0.480"],["62472.70","0.080"],["62587.40","0.001"]],"st":1}}
{"schema_version":"1.3.0","event_id":"ebbbad92-8c8d-422e-bb29-e7bfec4eb521","event_type":"raw.depth_update","source":"binance_market_data_recorder","venue":"binance_usdm","market_type":"perpetual_futures","symbol":"BTCUSDT","event_time_ms":1783517070578,"received_time_ms":1783517070575,"trace_id":"7fc5cc4f-ae7f-41ef-9b9b-4bb44857e2c3","first_update_id":10999770941826,"final_update_id":10999770948900,"previous_final_update_id":10999770941612,"bids":[{"price":"1000.00","quantity":"207.692"},{"price":"11554.10","quantity":"1.184"},{"price":"11653.70","quantity":"0.592"},{"price":"11654.10","quantity":"0.493"},{"price":"11753.70","quantity":"1.207"},{"price":"55668.60","quantity":"0.002"},{"price":"58761.30","quantity":"0.000"},{"price":"59379.90","quantity":"0.000"},{"price":"61235.60","quantity":"0.328"},{"price":"61520.00","quantity":"3.079"},{"price":"61544.40","quantity":"0.013"},{"price":"61600.00","quantity":"56.957"},{"price":"61680.00","quantity":"0.871"},{"price":"61760.00","quantity":"1.080"},{"price":"61789.00","quantity":"1.484"},{"price":"61790.70","quantity":"0.038"},{"price":"61828.10","quantity":"0.088"},{"price":"61828.30","quantity":"0.122"},{"price":"61830.10","quantity":"0.001"},{"price":"61830.40","quantity":"0.130"},{"price":"61834.70","quantity":"0.023"},{"price":"61835.60","quantity":"0.129"},{"price":"61836.00","quantity":"0.630"},{"price":"61836.70","quantity":"0.003"},{"price":"61836.80","quantity":"0.001"},{"price":"61838.90","quantity":"0.425"},{"price":"61840.00","quantity":"0.414"},{"price":"61841.70","quantity":"0.518"},{"price":"61842.50","quantity":"0.006"},{"price":"61842.70","quantity":"0.567"},{"price":"61843.00","quantity":"0.001"},{"price":"61843.60","quantity":"0.333"},{"price":"61852.20","quantity":"0.631"},{"price":"61853.70","quantity":"0.405"},{"price":"61854.10","quantity":"19.892"}],"asks":[{"price":"61854.20","quantity":"2.632"},{"price":"61854.30","quantity":"0.026"},{"price":"61854.60","quantity":"0.003"},{"price":"61855.80","quantity":"0.007"},{"price":"61859.70","quantity":"0.001"},{"price":"61860.80","quantity":"0.029"},{"price":"61861.60","quantity":"0.322"},{"price":"61862.70","quantity":"2.745"},{"price":"61863.20","quantity":"0.001"},{"price":"61864.10","quantity":"0.968"},{"price":"61864.30","quantity":"0.002"},{"price":"61865.60","quantity":"0.184"},{"price":"61866.50","quantity":"0.570"},{"price":"61867.40","quantity":"0.691"},{"price":"61887.20","quantity":"0.107"},{"price":"61887.70","quantity":"0.050"},{"price":"61887.80","quantity":"0.286"},{"price":"61888.00","quantity":"0.599"},{"price":"61888.80","quantity":"0.230"},{"price":"61909.40","quantity":"0.266"},{"price":"61909.50","quantity":"2.896"},{"price":"61909.80","quantity":"0.000"},{"price":"61909.90","quantity":"0.376"},{"price":"61918.30","quantity":"0.264"},{"price":"61920.00","quantity":"1.332"},{"price":"61926.60","quantity":"0.098"},{"price":"61950.50","quantity":"0.000"},{"price":"61953.70","quantity":"0.000"},{"price":"62000.00","quantity":"13.183"},{"price":"62080.00","quantity":"0.449"},{"price":"62160.00","quantity":"0.444"},{"price":"62240.00","quantity":"0.439"},{"price":"62407.10","quantity":"0.240"},{"price":"62472.70","quantity":"0.080"},{"price":"62817.00","quantity":"0.794"},{"price":"63069.80","quantity":"0.005"},{"price":"63091.20","quantity":"0.017"},{"price":"63738.00","quantity":"2.758"},{"price":"89523.20","quantity":"0.834"}],"raw":{"e":"depthUpdate","E":1783517070578,"T":1783517070577,"s":"BTCUSDT","ps":"BTCUSDT","U":10999770941826,"u":10999770948900,"pu":10999770941612,"b":[["1000.00","207.692"],["11554.10","1.184"],["11653.70","0.592"],["11654.10","0.493"],["11753.70","1.207"],["55668.60","0.002"],["58761.30","0.000"],["59379.90","0.000"],["61235.60","0.328"],["61520.00","3.079"],["61544.40","0.013"],["61600.00","56.957"],["61680.00","0.871"],["61760.00","1.080"],["61789.00","1.484"],["61790.70","0.038"],["61828.10","0.088"],["61828.30","0.122"],["61830.10","0.001"],["61830.40","0.130"],["61834.70","0.023"],["61835.60","0.129"],["61836.00","0.630"],["61836.70","0.003"],["61836.80","0.001"],["61838.90","0.425"],["61840.00","0.414"],["61841.70","0.518"],["61842.50","0.006"],["61842.70","0.567"],["61843.00","0.001"],["61843.60","0.333"],["61852.20","0.631"],["61853.70","0.405"],["61854.10","19.892"]],"a":[["61854.20","2.632"],["61854.30","0.026"],["61854.60","0.003"],["61855.80","0.007"],["61859.70","0.001"],["61860.80","0.029"],["61861.60","0.322"],["61862.70","2.745"],["61863.20","0.001"],["61864.10","0.968"],["61864.30","0.002"],["61865.60","0.184"],["61866.50","0.570"],["61867.40","0.691"],["61887.20","0.107"],["61887.70","0.050"],["61887.80","0.286"],["61888.00","0.599"],["61888.80","0.230"],["61909.40","0.266"],["61909.50","2.896"],["61909.80","0.000"],["61909.90","0.376"],["61918.30","0.264"],["61920.00","1.332"],["61926.60","0.098"],["61950.50","0.000"],["61953.70","0.000"],["62000.00","13.183"],["62080.00","0.449"],["62160.00","0.444"],["62240.00","0.439"],["62407.10","0.240"],["62472.70","0.080"],["62817.00","0.794"],["63069.80","0.005"],["63091.20","0.017"],["63738.00","2.758"],["89523.20","0.834"]],"st":1}}
{"schema_version":"1.3.0","event_id":"0da2131a-0704-4e14-bf97-0e2d30d11af7","event_type":"raw.depth_update","source":"binance_market_data_recorder","venue":"binance_usdm","market_type":"perpetual_futures","symbol":"BTCUSDT","event_time_ms":1783517070680,"received_time_ms":1783517070675,"trace_id":"b325f0cf-97a4-41a7-914f-ed50d0e86a81","first_update_id":10999770949153,"final_update_id":10999770956690,"previous_final_update_id":10999770948900,"bids":[{"price":"1000.00","quantity":"207.692"},{"price":"11454.10","quantity":"0.080"},{"price":"11554.10","quantity":"1.296"},{"price":"11653.70","quantity":"0.400"},{"price":"11654.10","quantity":"0.629"},{"price":"11753.70","quantity":"1.071"},{"price":"49483.00","quantity":"0.000"},{"price":"55668.60","quantity":"0.002"},{"price":"58761.30","quantity":"0.000"},{"price":"60617.10","quantity":"0.006"},{"price":"60987.70","quantity":"9.238"},{"price":"61235.60","quantity":"0.328"},{"price":"61520.00","quantity":"3.097"},{"price":"61600.00","quantity":"56.975"},{"price":"61680.00","quantity":"0.889"},{"price":"61749.60","quantity":"0.021"},{"price":"61750.30","quantity":"0.826"},{"price":"61760.00","quantity":"1.098"},{"price":"61789.00","quantity":"6.280"},{"price":"61805.60","quantity":"0.386"},{"price":"61828.10","quantity":"0.008"},{"price":"61835.30","quantity":"0.400"},{"price":"61835.90","quantity":"1.056"},{"price":"61836.00","quantity":"0.632"},{"price":"61836.10","quantity":"0.003"},{"price":"61840.00","quantity":"0.432"},{"price":"61841.70","quantity":"0.598"},{"price":"61853.70","quantity":"0.401"},{"price":"61854.10","quantity":"19.893"}],"asks":[{"price":"61854.20","quantity":"2.616"},{"price":"61854.90","quantity":"0.017"},{"price":"61856.20","quantity":"0.001"},{"price":"61864.00","quantity":"2.153"},{"price":"61866.50","quantity":"0.570"},{"price":"61875.20","quantity":"0.318"},{"price":"61878.90","quantity":"0.056"},{"price":"61880.70","quantity":"0.136"},{"price":"61889.20","quantity":"0.083"},{"price":"61893.70","quantity":"0.882"},{"price":"61896.10","quantity":"0.001"},{"price":"61916.40","quantity":"6.620"},{"price":"61920.00","quantity":"1.350"},{"price":"61926.60","quantity":"0.098"},{"price":"62000.00","quantity":"13.201"},{"price":"62027.90","quantity":"0.001"},{"price":"62028.60","quantity":"0.003"},{"price":"62080.00","quantity":"0.467"},{"price":"62160.00","quantity":"0.462"},{"price":"62240.00","quantity":"0.457"},{"price":"62472.70","quantity":"0.080"},{"price":"62627.40","quantity":"0.270"},{"price":"63966.00","quantity":"1.463"}],"raw":{"e":"depthUpdate","E":1783517070680,"T":1783517070679,"s":"BTCUSDT","ps":"BTCUSDT","U":10999770949153,"u":10999770956690,"pu":10999770948900,"b":[["1000.00","207.692"],["11454.10","0.080"],["11554.10","1.296"],["11653.70","0.400"],["11654.10","0.629"],["11753.70","1.071"],["49483.00","0.000"],["55668.60","0.002"],["58761.30","0.000"],["60617.10","0.006"],["60987.70","9.238"],["61235.60","0.328"],["61520.00","3.097"],["61600.00","56.975"],["61680.00","0.889"],["61749.60","0.021"],["61750.30","0.826"],["61760.00","1.098"],["61789.00","6.280"],["61805.60","0.386"],["61828.10","0.008"],["61835.30","0.400"],["61835.90","1.056"],["61836.00","0.632"],["61836.10","0.003"],["61840.00","0.432"],["61841.70","0.598"],["61853.70","0.401"],["61854.10","19.893"]],"a":[["61854.20","2.616"],["61854.90","0.017"],["61856.20","0.001"],["61864.00","2.153"],["61866.50","0.570"],["61875.20","0.318"],["61878.90","0.056"],["61880.70","0.136"],["61889.20","0.083"],["61893.70","0.882"],["61896.10","0.001"],["61916.40","6.620"],["61920.00","1.350"],["61926.60","0.098"],["62000.00","13.201"],["62027.90","0.001"],["62028.60","0.003"],["62080.00","0.467"],["62160.00","0.462"],["62240.00","0.457"],["62472.70","0.080"],["62627.40","0.270"],["63966.00","1.463"]],"st":1}}
{"schema_version":"1.3.0","event_id":"462f40b3-fa5d-483e-a9c6-5daf10db5ee1","event_type":"raw.depth_update","source":"binance_market_data_recorder","venue":"binance_usdm","market_type":"perpetual_futures","symbol":"BTCUSDT","event_time_ms":1783517070782,"received_time_ms":1783517070776,"trace_id":"a308022c-72f9-44d9-ad7b-3e24ee330173","first_update_id":10999770956897,"final_update_id":10999770963926,"previous_final_update_id":10999770956690,"bids":[{"price":"11454.10","quantity":"0.208"},{"price":"11554.10","quantity":"1.312"},{"price":"11653.70","quantity":"0.256"},{"price":"11654.10","quantity":"0.782"},{"price":"11753.70","quantity":"0.918"},{"price":"49483.00","quantity":"0.000"},{"price":"55668.60","quantity":"0.002"},{"price":"58761.30","quantity":"0.000"},{"price":"59379.90","quantity":"0.003"},{"price":"60291.10","quantity":"5.168"},{"price":"61049.60","quantity":"2.279"},{"price":"61076.90","quantity":"3.089"},{"price":"61235.60","quantity":"0.328"},{"price":"61297.40","quantity":"0.254"},{"price":"61815.10","quantity":"0.105"},{"price":"61816.70","quantity":"0.053"},{"price":"61817.40","quantity":"0.004"},{"price":"61818.10","quantity":"0.152"},{"price":"61823.40","quantity":"0.556"},{"price":"61825.10","quantity":"0.255"},{"price":"61826.10","quantity":"1.140"},{"price":"61826.80","quantity":"0.004"},{"price":"61827.20","quantity":"0.583"},{"price":"61828.20","quantity":"0.017"},{"price":"61828.30","quantity":"0.001"},{"price":"61829.30","quantity":"0.169"},{"price":"61833.20","quantity":"0.887"},{"price":"61834.00","quantity":"1.380"},{"price":"61834.40","quantity":"0.122"},{"price":"61835.30","quantity":"0.320"},{"price":"61837.20","quantity":"0.331"},{"price":"61842.30","quantity":"0.004"},{"price":"61842.40","quantity":"0.616"},{"price":"61843.10","quantity":"0.010"},{"price":"61843.60","quantity":"0.010"},{"price":"61843.80","quantity":"0.595"},{"price":"61844.40","quantity":"0.172"},{"price":"61844.50","quantity":"0.003"},{"price":"61852.20","quantity":"0.629"},{"price":"61854.00","quantity":"0.008"},{"price":"61854.10","quantity":"19.569"}],"asks":[{"price":"61854.20","quantity":"2.562"},{"price":"61854.50","quantity":"0.028"},{"price":"61857.20","quantity":"0.001"},{"price":"61859.00","quantity":"0.148"},{"price":"61859.70","quantity":"0.001"},{"price":"61859.80","quantity":"0.164"},{"price":"61859.90","quantity":"0.000"},{"price":"61860.00","quantity":"0.499"},{"price":"61860.10","quantity":"1.621"},{"price":"61861.00","quantity":"0.408"},{"price":"61863.50","quantity":"0.130"},{"price":"61865.80","quantity":"0.582"},{"price":"61866.30","quantity":"0.323"},{"price":"61866.70","quantity":"0.732"},{"price":"61867.90","quantity":"0.002"},{"price":"61868.00","quantity":"0.011"},{"price":"61869.80","quantity":"0.174"},{"price":"61870.30","quantity":"0.121"},{"price":"61870.60","quantity":"0.250"},{"price":"61871.60","quantity":"0.327"},{"price":"61872.10","quantity":"0.013"},{"price":"61872.60","quantity":"0.083"},{"price":"61872.80","quantity":"0.000"},{"price":"61876.10","quantity":"0.162"},{"price":"61926.60","quantity":"0.098"},{"price":"62393.60","quantity":"5.138"},{"price":"62410.50","quantity":"0.480"},{"price":"62410.90","quantity":"0.240"},{"price":"62472.70","quantity":"0.080"},{"price":"62482.40","quantity":"2.396"},{"price":"62607.70","quantity":"0.506"},{"price":"62668.00","quantity":"11.351"},{"price":"63060.40","quantity":"0.475"},{"price":"63735.00","quantity":"0.002"},{"price":"89523.20","quantity":"0.840"}],"raw":{"e":"depthUpdate","E":1783517070782,"T":1783517070781,"s":"BTCUSDT","ps":"BTCUSDT","U":10999770956897,"u":10999770963926,"pu":10999770956690,"b":[["11454.10","0.208"],["11554.10","1.312"],["11653.70","0.256"],["11654.10","0.782"],["11753.70","0.918"],["49483.00","0.000"],["55668.60","0.002"],["58761.30","0.000"],["59379.90","0.003"],["60291.10","5.168"],["61049.60","2.279"],["61076.90","3.089"],["61235.60","0.328"],["61297.40","0.254"],["61815.10","0.105"],["61816.70","0.053"],["61817.40","0.004"],["61818.10","0.152"],["61823.40","0.556"],["61825.10","0.255"],["61826.10","1.140"],["61826.80","0.004"],["61827.20","0.583"],["61828.20","0.017"],["61828.30","0.001"],["61829.30","0.169"],["61833.20","0.887"],["61834.00","1.380"],["61834.40","0.122"],["61835.30","0.320"],["61837.20","0.331"],["61842.30","0.004"],["61842.40","0.616"],["61843.10","0.010"],["61843.60","0.010"],["61843.80","0.595"],["61844.40","0.172"],["61844.50","0.003"],["61852.20","0.629"],["61854.00","0.008"],["61854.10","19.569"]],"a":[["61854.20","2.562"],["61854.50","0.028"],["61857.20","0.001"],["61859.00","0.148"],["61859.70","0.001"],["61859.80","0.164"],["61859.90","0.000"],["61860.00","0.499"],["61860.10","1.621"],["61861.00","0.408"],["61863.50","0.130"],["61865.80","0.582"],["61866.30","0.323"],["61866.70","0.732"],["61867.90","0.002"],["61868.00","0.011"],["61869.80","0.174"],["61870.30","0.121"],["61870.60","0.250"],["61871.60","0.327"],["61872.10","0.013"],["61872.60","0.083"],["61872.80","0.000"],["61876.10","0.162"],["61926.60","0.098"],["62393.60","5.138"],["62410.50","0.480"],["62410.90","0.240"],["62472.70","0.080"],["62482.40","2.396"],["62607.70","0.506"],["62668.00","11.351"],["63060.40","0.475"],["63735.00","0.002"],["89523.20","0.840"]],"st":1}}
{"schema_version":"1.3.0","event_id":"871a2e20-13ef-4b5d-9874-d7e93e80b411","event_type":"raw.depth_update","source":"binance_market_data_recorder","venue":"binance_usdm","market_type":"perpetual_futures","symbol":"BTCUSDT","event_time_ms":1783517070884,"received_time_ms":1783517070878,"trace_id":"8077c9a0-ef9d-4100-a9d8-85d0e107c474","first_update_id":10999770963979,"final_update_id":10999770971153,"previous_final_update_id":10999770963926,"bids":[{"price":"1000.00","quantity":"207.692"},{"price":"11454.10","quantity":"0.352"},{"price":"11554.10","quantity":"1.296"},{"price":"11653.70","quantity":"0.128"},{"price":"11654.10","quantity":"0.918"},{"price":"11753.70","quantity":"0.782"},{"price":"55668.60","quantity":"0.002"},{"price":"59379.90","quantity":"0.000"},{"price":"61235.60","quantity":"0.328"},{"price":"61368.70","quantity":"0.000"},{"price":"61537.60","quantity":"0.348"},{"price":"61544.40","quantity":"0.003"},{"price":"61544.80","quantity":"0.038"},{"price":"61790.70","quantity":"0.030"},{"price":"61792.10","quantity":"0.130"},{"price":"61815.70","quantity":"0.002"},{"price":"61816.30","quantity":"0.390"},{"price":"61824.30","quantity":"0.092"},{"price":"61824.60","quantity":"0.005"},{"price":"61824.80","quantity":"0.050"},{"price":"61828.10","quantity":"0.008"},{"price":"61828.80","quantity":"2.259"},{"price":"61829.30","quantity":"0.048"},{"price":"61832.10","quantity":"0.065"},{"price":"61837.20","quantity":"0.251"},{"price":"61839.10","quantity":"0.080"},{"price":"61840.10","quantity":"0.000"},{"price":"61840.50","quantity":"2.140"},{"price":"61841.70","quantity":"0.598"},{"price":"61842.10","quantity":"0.001"},{"price":"61850.20","quantity":"0.002"},{"price":"61853.70","quantity":"0.126"},{"price":"61854.10","quantity":"19.693"}],"asks":[{"price":"61854.20","quantity":"3.143"},{"price":"61855.20","quantity":"0.008"},{"price":"61856.10","quantity":"0.000"},{"price":"61857.00","quantity":"1.037"},{"price":"61859.90","quantity":"0.000"},{"price":"61860.40","quantity":"0.308"},{"price":"61861.40","quantity":"2.302"},{"price":"61863.50","quantity":"0.002"},{"price":"61867.10","quantity":"0.000"},{"price":"61871.20","quantity":"0.025"},{"price":"61871.60","quantity":"0.329"},{"price":"61873.30","quantity":"0.205"},{"price":"61879.50","quantity":"0.089"},{"price":"61887.80","quantity":"0.286"},{"price":"61887.90","quantity":"0.379"},{"price":"61888.00","quantity":"0.494"},{"price":"61888.80","quantity":"0.125"},{"price":"61897.50","quantity":"0.168"},{"price":"61909.80","quantity":"0.000"},{"price":"61909.90","quantity":"0.275"},{"price":"61926.60","quantity":"0.001"},{"price":"62472.70","quantity":"0.080"}],"raw":{"e":"depthUpdate","E":1783517070884,"T":1783517070883,"s":"BTCUSDT","ps":"BTCUSDT","U":10999770963979,"u":10999770971153,"pu":10999770963926,"b":[["1000.00","207.692"],["11454.10","0.352"],["11554.10","1.296"],["11653.70","0.128"],["11654.10","0.918"],["11753.70","0.782"],["55668.60","0.002"],["59379.90","0.000"],["61235.60","0.328"],["61368.70","0.000"],["61537.60","0.348"],["61544.40","0.003"],["61544.80","0.038"],["61790.70","0.030"],["61792.10","0.130"],["61815.70","0.002"],["61816.30","0.390"],["61824.30","0.092"],["61824.60","0.005"],["61824.80","0.050"],["61828.10","0.008"],["61828.80","2.259"],["61829.30","0.048"],["61832.10","0.065"],["61837.20","0.251"],["61839.10","0.080"],["61840.10","0.000"],["61840.50","2.140"],["61841.70","0.598"],["61842.10","0.001"],["61850.20","0.002"],["61853.70","0.126"],["61854.10","19.693"]],"a":[["61854.20","3.143"],["61855.20","0.008"],["61856.10","0.000"],["61857.00","1.037"],["61859.90","0.000"],["61860.40","0.308"],["61861.40","2.302"],["61863.50","0.002"],["61867.10","0.000"],["61871.20","0.025"],["61871.60","0.329"],["61873.30","0.205"],["61879.50","0.089"],["61887.80","0.286"],["61887.90","0.379"],["61888.00","0.494"],["61888.80","0.125"],["61897.50","0.168"],["61909.80","0.000"],["61909.90","0.275"],["61926.60","0.001"],["62472.70","0.080"]],"st":1}}
{"schema_version":"1.3.0","event_id":"99dcc8af-f2ff-442e-8416-e7f317414f17","event_type":"raw.depth_update","source":"binance_market_data_recorder","venue":"binance_usdm","market_type":"perpetual_futures","symbol":"BTCUSDT","event_time_ms":1783517070986,"received_time_ms":1783517070980,"trace_id":"c1ede41c-14c3-4365-8a79-98c48a904f8a","first_update_id":10999770971300,"final_update_id":10999770977464,"previous_final_update_id":10999770971153,"bids":[{"price":"1000.00","quantity":"207.692"},{"price":"11454.10","quantity":"0.496"},{"price":"11554.10","quantity":"1.280"},{"price":"11653.70","quantity":"0.000"},{"price":"11654.10","quantity":"1.071"},{"price":"11753.70","quantity":"0.629"},{"price":"55668.60","quantity":"0.002"},{"price":"58761.30","quantity":"0.000"},{"price":"59379.90","quantity":"0.003"},{"price":"60934.90","quantity":"0.001"},{"price":"61088.10","quantity":"21.946"},{"price":"61235.60","quantity":"0.328"},{"price":"61293.60","quantity":"0.800"},{"price":"61544.40","quantity":"0.002"},{"price":"61714.60","quantity":"0.000"},{"price":"61747.70","quantity":"1.611"},{"price":"61777.90","quantity":"0.146"},{"price":"61786.30","quantity":"33.396"},{"price":"61789.00","quantity":"1.484"},{"price":"61813.80","quantity":"0.016"},{"price":"61813.90","quantity":"0.104"},{"price":"61814.10","quantity":"0.672"},{"price":"61814.20","quantity":"0.277"},{"price":"61823.10","quantity":"0.105"},{"price":"61828.30","quantity":"0.122"},{"price":"61828.80","quantity":"2.138"},{"price":"61830.40","quantity":"0.130"},{"price":"61831.60","quantity":"0.010"},{"price":"61832.00","quantity":"1.317"},{"price":"61832.20","quantity":"0.002"},{"price":"61832.80","quantity":"0.343"},{"price":"61835.20","quantity":"0.568"},{"price":"61836.00","quantity":"0.066"},{"price":"61839.10","quantity":"0.000"},{"price":"61841.70","quantity":"0.598"},{"price":"61842.00","quantity":"0.369"},{"price":"61842.10","quantity":"0.009"},{"price":"61842.40","quantity":"0.293"},{"price":"61843.10","quantity":"0.010"},{"price":"61843.60","quantity":"0.002"},{"price":"61844.90","quantity":"0.841"},{"price":"61849.50","quantity":"0.001"},{"price":"61853.70","quantity":"0.090"},{"price":"61853.80","quantity":"0.000"},{"price":"61854.10","quantity":"18.333"}],"asks":[{"price":"61854.20","quantity":"5.817"},{"price":"61859.90","quantity":"0.126"},{"price":"61860.40","quantity":"0.308"},{"price":"61860.60","quantity":"0.230"},{"price":"61861.30","quantity":"0.569"},{"price":"61862.60","quantity":"0.482"},{"price":"61863.80","quantity":"0.569"},{"price":"61864.00","quantity":"2.153"},{"price":"61864.40","quantity":"0.000"},{"price":"61865.70","quantity":"0.472"},{"price":"61866.50","quantity":"0.004"},{"price":"61867.00","quantity":"0.310"},{"price":"61868.90","quantity":"0.103"},{"price":"61871.10","quantity":"0.062"},{"price":"61872.80","quantity":"0.000"},{"price":"61873.20","quantity":"0.104"},{"price":"61873.60","quantity":"0.017"},{"price":"61877.80","quantity":"0.024"},{"price":"61878.70","quantity":"0.016"},{"price":"61880.20","quantity":"0.000"},{"price":"61884.80","quantity":"0.793"},{"price":"61886.70","quantity":"0.105"},{"price":"61887.00","quantity":"0.036"},{"price":"61887.20","quantity":"0.002"},{"price":"61888.40","quantity":"0.128"},{"price":"61893.20","quantity":"0.207"},{"price":"61893.30","quantity":"0.100"},{"price":"61909.40","quantity":"0.367"},{"price":"61921.10","quantity":"2.431"},{"price":"61937.60","quantity":"0.882"},{"price":"62163.10","quantity":"0.001"},{"price":"62410.50","quantity":"0.720"},{"price":"62472.30","quantity":"0.000"},{"price":"62472.70","quantity":"0.080"},{"price":"63089.30","quantity":"0.087"},{"price":"63286.70","quantity":"0.000"},{"price":"89523.20","quantity":"0.846"}],"raw":{"e":"depthUpdate","E":1783517070986,"T":1783517070985,"s":"BTCUSDT","ps":"BTCUSDT","U":10999770971300,"u":10999770977464,"pu":10999770971153,"b":[["1000.00","207.692"],["11454.10","0.496"],["11554.10","1.280"],["11653.70","0.000"],["11654.10","1.071"],["11753.70","0.629"],["55668.60","0.002"],["58761.30","0.000"],["59379.90","0.003"],["60934.90","0.001"],["61088.10","21.946"],["61235.60","0.328"],["61293.60","0.800"],["61544.40","0.002"],["61714.60","0.000"],["61747.70","1.611"],["61777.90","0.146"],["61786.30","33.396"],["61789.00","1.484"],["61813.80","0.016"],["61813.90","0.104"],["61814.10","0.672"],["61814.20","0.277"],["61823.10","0.105"],["61828.30","0.122"],["61828.80","2.138"],["61830.40","0.130"],["61831.60","0.010"],["61832.00","1.317"],["61832.20","0.002"],["61832.80","0.343"],["61835.20","0.568"],["61836.00","0.066"],["61839.10","0.000"],["61841.70","0.598"],["61842.00","0.369"],["61842.10","0.009"],["61842.40","0.293"],["61843.10","0.010"],["61843.60","0.002"],["61844.90","0.841"],["61849.50","0.001"],["61853.70","0.090"],["61853.80","0.000"],["61854.10","18.333"]],"a":[["61854.20","5.817"],["61859.90","0.126"],["61860.40","0.308"],["61860.60","0.230"],["61861.30","0.569"],["61862.60","0.482"],["61863.80","0.569"],["61864.00","2.153"],["61864.40","0.000"],["61865.70","0.472"],["61866.50","0.004"],["61867.00","0.310"],["61868.90","0.103"],["61871.10","0.062"],["61872.80","0.000"],["61873.20","0.104"],["61873.60","0.017"],["61877.80","0.024"],["61878.70","0.016"],["61880.20","0.000"],["61884.80","0.793"],["61886.70","0.105"],["61887.00","0.036"],["61887.20","0.002"],["61888.40","0.128"],["61893.20","0.207"],["61893.30","0.100"],["61909.40","0.367"],["61921.10","2.431"],["61937.60","0.882"],["62163.10","0.001"],["62410.50","0.720"],["62472.30","0.000"],["62472.70","0.080"],["63089.30","0.087"],["63286.70","0.000"],["89523.20","0.846"]],"st":1}}
{"schema_version":"1.3.0","event_id":"872da1a9-127d-4dc2-884c-d606183e7c50","event_type":"raw.depth_update","source":"binance_market_data_recorder","venue":"binance_usdm","market_type":"perpetual_futures","symbol":"BTCUSDT","event_time_ms":1783517071088,"received_time_ms":1783517071083,"trace_id":"3ed32756-adc6-4d87-bc7e-912d64886c14","first_update_id":10999770977633,"final_update_id":10999770985646,"previous_final_update_id":10999770977464,"bids":[{"price":"11454.10","quantity":"0.768"},{"price":"11554.10","quantity":"1.008"},{"price":"11654.10","quantity":"1.207"},{"price":"11753.70","quantity":"0.493"},{"price":"55668.60","quantity":"0.002"},{"price":"58761.30","quantity":"0.000"},{"price":"59379.90","quantity":"0.000"},{"price":"59803.80","quantity":"1.670"},{"price":"60500.00","quantity":"236.674"},{"price":"61092.00","quantity":"6.556"},{"price":"61124.80","quantity":"0.130"},{"price":"61235.60","quantity":"0.328"},{"price":"61300.00","quantity":"78.965"},{"price":"61544.80","quantity":"0.039"},{"price":"61750.30","quantity":"0.823"},{"price":"61750.40","quantity":"0.016"},{"price":"61783.30","quantity":"0.002"},{"price":"61784.00","quantity":"0.000"},{"price":"61805.00","quantity":"2.114"},{"price":"61813.40","quantity":"0.163"},{"price":"61815.50","quantity":"0.003"},{"price":"61820.40","quantity":"0.621"},{"price":"61822.30","quantity":"0.107"},{"price":"61822.60","quantity":"0.106"},{"price":"61822.70","quantity":"0.118"},{"price":"61823.80","quantity":"0.150"},{"price":"61840.30","quantity":"0.203"},{"price":"61841.70","quantity":"0.518"},{"price":"61843.00","quantity":"0.001"},{"price":"61851.00","quantity":"1.005"},{"price":"61852.10","quantity":"0.002"},{"price":"61852.90","quantity":"0.002"},{"price":"61853.60","quantity":"0.000"},{"price":"61853.70","quantity":"0.088"},{"price":"61853.90","quantity":"0.346"},{"price":"61854.10","quantity":"17.723"}],"asks":[{"price":"61854.20","quantity":"5.451"},{"price":"61854.70","quantity":"0.611"},{"price":"61855.10","quantity":"0.002"},{"price":"61856.30","quantity":"0.035"},{"price":"61856.50","quantity":"0.010"},{"price":"61857.90","quantity":"0.000"},{"price":"61858.30","quantity":"0.013"},{"price":"61860.40","quantity":"0.312"},{"price":"61861.40","quantity":"2.304"},{"price":"61863.80","quantity":"0.003"},{"price":"61865.30","quantity":"0.456"},{"price":"61865.70","quantity":"1.038"},{"price":"61866.60","quantity":"3.360"},{"price":"61868.60","quantity":"0.019"},{"price":"61872.80","quantity":"0.004"},{"price":"61882.90","quantity":"0.937"},{"price":"61887.20","quantity":"0.107"},{"price":"61898.40","quantity":"1.369"},{"price":"61909.90","quantity":"0.376"},{"price":"61912.50","quantity":"0.024"},{"price":"61920.10","quantity":"0.000"},{"price":"62028.60","quantity":"0.000"},{"price":"62028.70","quantity":"0.004"},{"price":"62163.50","quantity":"0.001"},{"price":"62472.70","quantity":"0.080"},{"price":"62472.80","quantity":"0.214"},{"price":"62644.60","quantity":"0.796"},{"price":"62658.30","quantity":"0.956"},{"price":"63737.10","quantity":"2.273"}],"raw":{"e":"depthUpdate","E":1783517071088,"T":1783517071087,"s":"BTCUSDT","ps":"BTCUSDT","U":10999770977633,"u":10999770985646,"pu":10999770977464,"b":[["11454.10","0.768"],["11554.10","1.008"],["11654.10","1.207"],["11753.70","0.493"],["55668.60","0.002"],["58761.30","0.000"],["59379.90","0.000"],["59803.80","1.670"],["60500.00","236.674"],["61092.00","6.556"],["61124.80","0.130"],["61235.60","0.328"],["61300.00","78.965"],["61544.80","0.039"],["61750.30","0.823"],["61750.40","0.016"],["61783.30","0.002"],["61784.00","0.000"],["61805.00","2.114"],["61813.40","0.163"],["61815.50","0.003"],["61820.40","0.621"],["61822.30","0.107"],["61822.60","0.106"],["61822.70","0.118"],["61823.80","0.150"],["61840.30","0.203"],["61841.70","0.518"],["61843.00","0.001"],["61851.00","1.005"],["61852.10","0.002"],["61852.90","0.002"],["61853.60","0.000"],["61853.70","0.088"],["61853.90","0.346"],["61854.10","17.723"]],"a":[["61854.20","5.451"],["61854.70","0.611"],["61855.10","0.002"],["61856.30","0.035"],["61856.50","0.010"],["61857.90","0.000"],["61858.30","0.013"],["61860.40","0.312"],["61861.40","2.304"],["61863.80","0.003"],["61865.30","0.456"],["61865.70","1.038"],["61866.60","3.360"],["61868.60","0.019"],["61872.80","0.004"],["61882.90","0.937"],["61887.20","0.107"],["61898.40","1.369"],["61909.90","0.376"],["61912.50","0.024"],["61920.10","0.000"],["62028.60","0.000"],["62028.70","0.004"],["62163.50","0.001"],["62472.70","0.080"],["62472.80","0.214"],["62644.60","0.796"],["62658.30","0.956"],["63737.10","2.273"]],"st":1}}
{"schema_version":"1.3.0","event_id":"9f370476-dae6-46e6-acea-d3504ff9b84d","event_type":"raw.depth_update","source":"binance_market_data_recorder","venue":"binance_usdm","market_type":"perpetual_futures","symbol":"BTCUSDT","event_time_ms":1783517071190,"received_time_ms":1783517071185,"trace_id":"875f2673-f7bd-4e00-a859-c0c5504d9d8c","first_update_id":10999770985797,"final_update_id":10999770991346,"previous_final_update_id":10999770985646,"bids":[{"price":"1000.00","quantity":"207.692"},{"price":"11454.10","quantity":"1.040"},{"price":"11553.70","quantity":"1.328"},{"price":"11554.10","quantity":"0.832"},{"price":"11654.10","quantity":"1.360"},{"price":"11753.70","quantity":"0.340"},{"price":"55668.60","quantity":"0.002"},{"price":"58761.30","quantity":"0.000"},{"price":"61212.00","quantity":"0.438"},{"price":"61235.60","quantity":"0.328"},{"price":"61297.00","quantity":"3.008"},{"price":"61544.80","quantity":"0.039"},{"price":"61723.20","quantity":"0.234"},{"price":"61723.50","quantity":"0.289"},{"price":"61752.40","quantity":"0.012"},{"price":"61754.80","quantity":"1.367"},{"price":"61792.10","quantity":"0.122"},{"price":"61793.40","quantity":"0.033"},{"price":"61822.30","quantity":"0.002"},{"price":"61828.90","quantity":"1.384"},{"price":"61835.10","quantity":"1.874"},{"price":"61841.30","quantity":"0.186"},{"price":"61842.00","quantity":"0.046"},{"price":"61843.10","quantity":"0.333"},{"price":"61853.40","quantity":"0.002"},{"price":"61854.00","quantity":"0.009"}],"asks":[{"price":"61854.20","quantity":"5.300"},{"price":"61857.00","quantity":"0.713"},{"price":"61858.40","quantity":"0.127"},{"price":"61859.70","quantity":"0.001"},{"price":"61859.80","quantity":"0.326"},{"price":"61859.90","quantity":"0.373"},{"price":"61860.40","quantity":"0.308"},{"price":"61862.00","quantity":"0.003"},{"price":"61865.60","quantity":"0.004"},{"price":"61865.90","quantity":"0.586"},{"price":"61866.60","quantity":"3.356"},{"price":"61866.70","quantity":"0.813"},{"price":"61868.60","quantity":"0.004"},{"price":"61872.10","quantity":"0.011"},{"price":"61872.80","quantity":"0.000"},{"price":"61872.90","quantity":"0.232"},{"price":"61879.10","quantity":"0.326"},{"price":"61887.00","quantity":"0.141"},{"price":"61887.20","quantity":"0.002"},{"price":"61926.60","quantity":"0.001"},{"price":"61950.60","quantity":"1.628"},{"price":"61951.00","quantity":"0.000"},{"price":"61985.40","quantity":"1.569"},{"price":"61985.60","quantity":"0.072"},{"price":"62122.20","quantity":"0.000"},{"price":"62472.70","quantity":"0.080"},{"price":"89523.20","quantity":"0.852"}],"raw":{"e":"depthUpdate","E":1783517071190,"T":1783517071189,"s":"BTCUSDT","ps":"BTCUSDT","U":10999770985797,"u":10999770991346,"pu":10999770985646,"b":[["1000.00","207.692"],["11454.10","1.040"],["11553.70","1.328"],["11554.10","0.832"],["11654.10","1.360"],["11753.70","0.340"],["55668.60","0.002"],["58761.30","0.000"],["61212.00","0.438"],["61235.60","0.328"],["61297.00","3.008"],["61544.80","0.039"],["61723.20","0.234"],["61723.50","0.289"],["61752.40","0.012"],["61754.80","1.367"],["61792.10","0.122"],["61793.40","0.033"],["61822.30","0.002"],["61828.90","1.384"],["61835.10","1.874"],["61841.30","0.186"],["61842.00","0.046"],["61843.10","0.333"],["61853.40","0.002"],["61854.00","0.009"]],"a":[["61854.20","5.300"],["61857.00","0.713"],["61858.40","0.127"],["61859.70","0.001"],["61859.80","0.326"],["61859.90","0.373"],["61860.40","0.308"],["61862.00","0.003"],["61865.60","0.004"],["61865.90","0.586"],["61866.60","3.356"],["61866.70","0.813"],["61868.60","0.004"],["61872.10","0.011"],["61872.80","0.000"],["61872.90","0.232"],["61879.10","0.326"],["61887.00","0.141"],["61887.20","0.002"],["61926.60","0.001"],["61950.60","1.628"],["61951.00","0.000"],["61985.40","1.569"],["61985.60","0.072"],["62122.20","0.000"],["62472.70","0.080"],["89523.20","0.852"]],"st":1}}
{"schema_version":"1.3.0","event_id":"98998e3c-fb60-4ca9-be9a-1fc6982936df","event_type":"raw.depth_update","source":"binance_market_data_recorder","venue":"binance_usdm","market_type":"perpetual_futures","symbol":"BTCUSDT","event_time_ms":1783517071292,"received_time_ms":1783517071287,"trace_id":"3fcf0d87-3264-40a7-ba6c-6feb9fc892c3","first_update_id":10999770991356,"final_update_id":10999770996575,"previous_final_update_id":10999770991346,"bids":[{"price":"1000.00","quantity":"207.692"},{"price":"11454.10","quantity":"1.312"},{"price":"11553.70","quantity":"1.184"},{"price":"11554.10","quantity":"0.704"},{"price":"11654.10","quantity":"1.496"},{"price":"11753.70","quantity":"0.204"},{"price":"55668.60","quantity":"0.002"},{"price":"58759.60","quantity":"0.005"},{"price":"58759.70","quantity":"0.006"},{"price":"58761.30","quantity":"0.000"},{"price":"59379.90","quantity":"0.003"},{"price":"60616.70","quantity":"0.032"},{"price":"60636.20","quantity":"0.706"},{"price":"60876.50","quantity":"0.004"},{"price":"60944.50","quantity":"0.581"},{"price":"60959.20","quantity":"0.001"},{"price":"61031.50","quantity":"0.013"},{"price":"61080.50","quantity":"0.523"},{"price":"61235.60","quantity":"0.328"},{"price":"61783.30","quantity":"8.002"},{"price":"61805.00","quantity":"6.614"},{"price":"61813.40","quantity":"0.064"},{"price":"61813.80","quantity":"0.115"},{"price":"61820.40","quantity":"1.429"},{"price":"61822.50","quantity":"0.866"},{"price":"61822.60","quantity":"0.106"},{"price":"61822.70","quantity":"0.013"},{"price":"61823.80","quantity":"0.150"},{"price":"61828.90","quantity":"1.061"},{"price":"61830.50","quantity":"0.008"},{"price":"61831.60","quantity":"0.002"},{"price":"61835.10","quantity":"1.712"},{"price":"61835.20","quantity":"0.002"},{"price":"61837.60","quantity":"1.795"},{"price":"61841.30","quantity":"0.105"},{"price":"61850.30","quantity":"0.173"},{"price":"61854.10","quantity":"17.515"}],"asks":[{"price":"61854.20","quantity":"4.003"},{"price":"61856.80","quantity":"0.001"},{"price":"61858.40","quantity":"0.001"},{"price":"61859.70","quantity":"0.001"},{"price":"61859.80","quantity":"0.002"},{"price":"61859.90","quantity":"0.000"},{"price":"61860.00","quantity":"0.661"},{"price":"61860.60","quantity":"0.108"},{"price":"61861.30","quantity":"0.372"},{"price":"61862.20","quantity":"0.324"},{"price":"61862.50","quantity":"0.001"},{"price":"61863.40","quantity":"0.839"},{"price":"61863.80","quantity":"0.165"},{"price":"61865.00","quantity":"0.007"},{"price":"61865.80","quantity":"0.000"},{"price":"61866.40","quantity":"0.001"},{"price":"61866.50","quantity":"0.166"},{"price":"61866.70","quantity":"1.314"},{"price":"61868.90","quantity":"0.099"},{"price":"61869.80","quantity":"0.174"},{"price":"61872.90","quantity":"0.070"},{"price":"61873.20","quantity":"0.102"},{"price":"61873.30","quantity":"0.205"},{"price":"61879.10","quantity":"0.003"},{"price":"61884.30","quantity":"0.922"},{"price":"61887.00","quantity":"0.036"},{"price":"61887.20","quantity":"0.107"},{"price":"61887.80","quantity":"0.391"},{"price":"61893.40","quantity":"0.306"},{"price":"61893.50","quantity":"0.373"},{"price":"61899.70","quantity":"4.589"},{"price":"61909.50","quantity":"2.896"},{"price":"61909.80","quantity":"0.101"},{"price":"61909.90","quantity":"0.275"},{"price":"61921.40","quantity":"8.016"},{"price":"61950.90","quantity":"0.825"},{"price":"61951.00","quantity":"0.008"},{"price":"62472.70","quantity":"0.080"},{"price":"62658.40","quantity":"1.275"},{"price":"62751.00","quantity":"1.710"},{"price":"63089.30","quantity":"0.084"},{"price":"63090.80","quantity":"0.015"}],"raw":{"e":"depthUpdate","E":1783517071292,"T":1783517071289,"s":"BTCUSDT","ps":"BTCUSDT","U":10999770991356,"u":10999770996575,"pu":10999770991346,"b":[["1000.00","207.692"],["11454.10","1.312"],["11553.70","1.184"],["11554.10","0.704"],["11654.10","1.496"],["11753.70","0.204"],["55668.60","0.002"],["58759.60","0.005"],["58759.70","0.006"],["58761.30","0.000"],["59379.90","0.003"],["60616.70","0.032"],["60636.20","0.706"],["60876.50","0.004"],["60944.50","0.581"],["60959.20","0.001"],["61031.50","0.013"],["61080.50","0.523"],["61235.60","0.328"],["61783.30","8.002"],["61805.00","6.614"],["61813.40","0.064"],["61813.80","0.115"],["61820.40","1.429"],["61822.50","0.866"],["61822.60","0.106"],["61822.70","0.013"],["61823.80","0.150"],["61828.90","1.061"],["61830.50","0.008"],["61831.60","0.002"],["61835.10","1.712"],["61835.20","0.002"],["61837.60","1.795"],["61841.30","0.105"],["61850.30","0.173"],["61854.10","17.515"]],"a":[["61854.20","4.003"],["61856.80","0.001"],["61858.40","0.001"],["61859.70","0.001"],["61859.80","0.002"],["61859.90","0.000"],["61860.00","0.661"],["61860.60","0.108"],["61861.30","0.372"],["61862.20","0.324"],["61862.50","0.001"],["61863.40","0.839"],["61863.80","0.165"],["61865.00","0.007"],["61865.80","0.000"],["61866.40","0.001"],["61866.50","0.166"],["61866.70","1.314"],["61868.90","0.099"],["61869.80","0.174"],["61872.90","0.070"],["61873.20","0.102"],["61873.30","0.205"],["61879.10","0.003"],["61884.30","0.922"],["61887.00","0.036"],["61887.20","0.107"],["61887.80","0.391"],["61893.40","0.306"],["61893.50","0.373"],["61899.70","4.589"],["61909.50","2.896"],["61909.80","0.101"],["61909.90","0.275"],["61921.40","8.016"],["61950.90","0.825"],["61951.00","0.008"],["62472.70","0.080"],["62658.40","1.275"],["62751.00","1.710"],["63089.30","0.084"],["63090.80","0.015"]],"st":1}}
{"schema_version":"1.3.0","event_id":"e502b845-39bc-4c5e-98f7-b0f1746bcfa3","event_type":"raw.depth_update","source":"binance_market_data_recorder","venue":"binance_usdm","market_type":"perpetual_futures","symbol":"BTCUSDT","event_time_ms":1783517071394,"received_time_ms":1783517071391,"trace_id":"a491d0ac-a4c0-44c8-9232-6f2ab56ad91a","first_update_id":10999770996763,"final_update_id":10999771003858,"previous_final_update_id":10999770996575,"bids":[{"price":"11454.10","quantity":"1.584"},{"price":"11553.70","quantity":"1.056"},{"price":"11554.10","quantity":"0.560"},{"price":"11654.10","quantity":"1.649"},{"price":"11753.70","quantity":"0.051"},{"price":"55668.60","quantity":"0.002"},{"price":"58761.30","quantity":"0.000"},{"price":"59379.90","quantity":"0.000"},{"price":"61122.10","quantity":"0.572"},{"price":"61235.60","quantity":"0.328"},{"price":"61537.60","quantity":"0.348"},{"price":"61585.60","quantity":"0.015"},{"price":"61586.00","quantity":"0.060"},{"price":"61609.20","quantity":"0.202"},{"price":"61665.50","quantity":"0.023"},{"price":"61689.10","quantity":"1.020"},{"price":"61752.40","quantity":"11.012"},{"price":"61812.60","quantity":"0.035"},{"price":"61813.40","quantity":"0.163"},{"price":"61815.10","quantity":"0.004"},{"price":"61821.90","quantity":"0.518"},{"price":"61822.30","quantity":"0.107"},{"price":"61823.40","quantity":"0.451"},{"price":"61836.70","quantity":"0.569"},{"price":"61837.60","quantity":"1.229"},{"price":"61838.60","quantity":"0.128"},{"price":"61839.30","quantity":"0.001"},{"price":"61841.70","quantity":"0.390"},{"price":"61841.80","quantity":"0.894"},{"price":"61842.00","quantity":"0.069"},{"price":"61842.40","quantity":"0.293"},{"price":"61842.70","quantity":"0.001"},{"price":"61843.10","quantity":"0.010"},{"price":"61845.90","quantity":"0.247"},{"price":"61849.30","quantity":"0.000"},{"price":"61850.30","quantity":"0.051"},{"price":"61850.90","quantity":"0.005"},{"price":"61851.90","quantity":"0.002"},{"price":"61852.10","quantity":"0.000"},{"price":"61854.00","quantity":"0.008"},{"price":"61854.10","quantity":"14.915"}],"asks":[{"price":"61854.20","quantity":"6.160"},{"price":"61856.10","quantity":"0.324"},{"price":"61858.40","quantity":"1.123"},{"price":"61859.40","quantity":"0.012"},{"price":"61859.70","quantity":"1.290"},{"price":"61859.80","quantity":"1.192"},{"price":"61859.90","quantity":"1.302"},{"price":"61860.10","quantity":"1.631"},{"price":"61860.60","quantity":"0.230"},{"price":"61865.70","quantity":"0.472"},{"price":"61865.90","quantity":"0.406"},{"price":"61866.50","quantity":"0.732"},{"price":"61887.20","quantity":"0.002"},{"price":"61887.80","quantity":"0.286"},{"price":"61893.40","quantity":"0.570"},{"price":"61897.50","quantity":"0.323"},{"price":"61909.30","quantity":"0.232"},{"price":"61909.50","quantity":"2.795"},{"price":"61909.80","quantity":"0.000"},{"price":"61909.90","quantity":"0.120"},{"price":"61918.30","quantity":"0.000"},{"price":"61926.60","quantity":"0.001"},{"price":"61950.60","quantity":"3.064"},{"price":"61952.40","quantity":"11.000"},{"price":"62472.70","quantity":"0.080"},{"price":"62986.00","quantity":"1.572"},{"price":"63090.80","quantity":"0.012"},{"price":"63091.20","quantity":"0.020"},{"price":"89523.20","quantity":"0.858"}],"raw":{"e":"depthUpdate","E":1783517071394,"T":1783517071393,"s":"BTCUSDT","ps":"BTCUSDT","U":10999770996763,"u":10999771003858,"pu":10999770996575,"b":[["11454.10","1.584"],["11553.70","1.056"],["11554.10","0.560"],["11654.10","1.649"],["11753.70","0.051"],["55668.60","0.002"],["58761.30","0.000"],["59379.90","0.000"],["61122.10","0.572"],["61235.60","0.328"],["61537.60","0.348"],["61585.60","0.015"],["61586.00","0.060"],["61609.20","0.202"],["61665.50","0.023"],["61689.10","1.020"],["61752.40","11.012"],["61812.60","0.035"],["61813.40","0.163"],["61815.10","0.004"],["61821.90","0.518"],["61822.30","0.107"],["61823.40","0.451"],["61836.70","0.569"],["61837.60","1.229"],["61838.60","0.128"],["61839.30","0.001"],["61841.70","0.390"],["61841.80","0.894"],["61842.00","0.069"],["61842.40","0.293"],["61842.70","0.001"],["61843.10","0.010"],["61845.90","0.247"],["61849.30","0.000"],["61850.30","0.051"],["61850.90","0.005"],["61851.90","0.002"],["61852.10","0.000"],["61854.00","0.008"],["61854.10","14.915"]],"a":[["61854.20","6.160"],["61856.10","0.324"],["61858.40","1.123"],["61859.40","0.012"],["61859.70","1.290"],["61859.80","1.192"],["61859.90","1.302"],["61860.10","1.631"],["61860.60","0.230"],["61865.70","0.472"],["61865.90","0.406"],["61866.50","0.732"],["61887.20","0.002"],["61887.80","0.286"],["61893.40","0.570"],["61897.50","0.323"],["61909.30","0.232"],["61909.50","2.795"],["61909.80","0.000"],["61909.90","0.120"],["61918.30","0.000"],["61926.60","0.001"],["61950.60","3.064"],["61952.40","11.000"],["62472.70","0.080"],["62986.00","1.572"],["63090.80","0.012"],["63091.20","0.020"],["89523.20","0.858"]],"st":1}}
{"schema_version":"1.3.0","event_id":"4d6d5181-a0c2-4ff7-bc27-aff1fb5aeb30","event_type":"raw.depth_update","source":"binance_market_data_recorder","venue":"binance_usdm","market_type":"perpetual_futures","symbol":"BTCUSDT","event_time_ms":1783517071496,"received_time_ms":1783517071491,"trace_id":"82be612f-8a7e-4eca-ae91-80fef28ab566","first_update_id":10999771003911,"final_update_id":10999771008780,"previous_final_update_id":10999771003858,"bids":[{"price":"1000.00","quantity":"207.692"},{"price":"11454.10","quantity":"1.856"},{"price":"11553.70","quantity":"0.912"},{"price":"11554.10","quantity":"0.517"},{"price":"11654.10","quantity":"1.615"},{"price":"11753.70","quantity":"0.000"},{"price":"49483.00","quantity":"0.002"},{"price":"55668.60","quantity":"0.002"},{"price":"58761.30","quantity":"0.000"},{"price":"59379.90","quantity":"0.003"},{"price":"60993.90","quantity":"1.636"},{"price":"61019.10","quantity":"0.981"},{"price":"61145.10","quantity":"0.817"},{"price":"61235.60","quantity":"0.328"},{"price":"61351.20","quantity":"0.002"},{"price":"61544.80","quantity":"0.029"},{"price":"61754.80","quantity":"2.749"},{"price":"61821.20","quantity":"0.206"},{"price":"61823.10","quantity":"0.000"},{"price":"61823.40","quantity":"0.075"},{"price":"61829.60","quantity":"0.039"},{"price":"61830.40","quantity":"0.130"},{"price":"61843.10","quantity":"0.010"},{"price":"61854.10","quantity":"14.914"}],"asks":[{"price":"61854.20","quantity":"5.885"},{"price":"61856.90","quantity":"0.346"},{"price":"61857.30","quantity":"1.128"},{"price":"61858.20","quantity":"1.484"},{"price":"61858.30","quantity":"2.696"},{"price":"61858.50","quantity":"0.004"},{"price":"61858.60","quantity":"0.003"},{"price":"61859.40","quantity":"0.002"},{"price":"61859.50","quantity":"0.029"},{"price":"61859.60","quantity":"0.163"},{"price":"61860.00","quantity":"0.338"},{"price":"61860.10","quantity":"0.005"},{"price":"61860.20","quantity":"0.066"},{"price":"61860.40","quantity":"0.180"},{"price":"61861.60","quantity":"0.320"},{"price":"61863.40","quantity":"0.030"},{"price":"61865.50","quantity":"0.014"},{"price":"61866.00","quantity":"0.005"},{"price":"61866.70","quantity":"1.346"},{"price":"61867.30","quantity":"0.067"},{"price":"61867.60","quantity":"0.427"},{"price":"61873.30","quantity":"0.173"},{"price":"61886.50","quantity":"0.132"},{"price":"61886.70","quantity":"0.000"},{"price":"61894.40","quantity":"0.699"},{"price":"61907.70","quantity":"0.528"},{"price":"61909.30","quantity":"0.131"},{"price":"61909.40","quantity":"0.266"},{"price":"61926.60","quantity":"0.098"},{"price":"61957.20","quantity":"8.362"},{"price":"61957.90","quantity":"3.137"},{"price":"62472.70","quantity":"0.080"},{"price":"62530.80","quantity":"0.480"}],"raw":{"e":"depthUpdate","E":1783517071496,"T":1783517071494,"s":"BTCUSDT","ps":"BTCUSDT","U":10999771003911,"u":10999771008780,"pu":10999771003858,"b":[["1000.00","207.692"],["11454.10","1.856"],["11553.70","0.912"],["11554.10","0.517"],["11654.10","1.615"],["11753.70","0.000"],["49483.00","0.002"],["55668.60","0.002"],["58761.30","0.000"],["59379.90","0.003"],["60993.90","1.636"],["61019.10","0.981"],["61145.10","0.817"],["61235.60","0.328"],["61351.20","0.002"],["61544.80","0.029"],["61754.80","2.749"],["61821.20","0.206"],["61823.10","0.000"],["61823.40","0.075"],["61829.60","0.039"],["61830.40","0.130"],["61843.10","0.010"],["61854.10","14.914"]],"a":[["61854.20","5.885"],["61856.90","0.346"],["61857.30","1.128"],["61858.20","1.484"],["61858.30","2.696"],["61858.50","0.004"],["61858.60","0.003"],["61859.40","0.002"],["61859.50","0.029"],["61859.60","0.163"],["61860.00","0.338"],["61860.10","0.005"],["61860.20","0.066"],["61860.40","0.180"],["61861.60","0.320"],["61863.40","0.030"],["61865.50","0.014"],["61866.00","0.005"],["61866.70","1.346"],["61867.30","0.067"],["61867.60","0.427"],["61873.30","0.173"],["61886.50","0.132"],["61886.70","0.000"],["61894.40","0.699"],["61907.70","0.528"],["61909.30","0.131"],["61909.40","0.266"],["61926.60","0.098"],["61957.20","8.362"],["61957.90","3.137"],["62472.70","0.080"],["62530.80","0.480"]],"st":1}}
{"schema_version":"1.3.0","event_id":"f3fe8b01-09b8-4fb1-9b78-67d9fa626f02","event_type":"raw.depth_update","source":"binance_market_data_recorder","venue":"binance_usdm","market_type":"perpetual_futures","symbol":"BTCUSDT","event_time_ms":1783517071598,"received_time_ms":1783517071596,"trace_id":"3faa63ca-7505-492f-ba98-49b7b6333e43","first_update_id":10999771008899,"final_update_id":10999771020511,"previous_final_update_id":10999771008780,"bids":[{"price":"1000.00","quantity":"207.692"},{"price":"11454.10","quantity":"2.128"},{"price":"11553.70","quantity":"0.784"},{"price":"11554.10","quantity":"0.526"},{"price":"11654.10","quantity":"1.462"},{"price":"49483.00","quantity":"0.000"},{"price":"55668.60","quantity":"0.002"},{"price":"58759.60","quantity":"0.002"},{"price":"58759.70","quantity":"0.009"},{"price":"58761.30","quantity":"0.000"},{"price":"60617.10","quantity":"0.009"},{"price":"60859.70","quantity":"0.703"},{"price":"61152.50","quantity":"0.245"},{"price":"61152.80","quantity":"0.025"},{"price":"61235.60","quantity":"0.328"},{"price":"61812.30","quantity":"0.017"},{"price":"61812.60","quantity":"0.134"},{"price":"61813.80","quantity":"0.113"},{"price":"61813.90","quantity":"0.003"},{"price":"61814.10","quantity":"0.571"},{"price":"61814.20","quantity":"0.176"},{"price":"61821.10","quantity":"0.367"},{"price":"61821.20","quantity":"0.101"},{"price":"61823.40","quantity":"0.511"},{"price":"61832.00","quantity":"0.349"},{"price":"61834.10","quantity":"3.868"},{"price":"61835.20","quantity":"0.002"},{"price":"61836.70","quantity":"0.003"},{"price":"61837.90","quantity":"2.212"},{"price":"61838.00","quantity":"1.061"},{"price":"61840.70","quantity":"1.125"},{"price":"61841.80","quantity":"0.005"},{"price":"61842.00","quantity":"1.191"},{"price":"61842.90","quantity":"1.089"},{"price":"61845.00","quantity":"2.020"},{"price":"61845.70","quantity":"1.122"},{"price":"61848.10","quantity":"1.117"},{"price":"61850.40","quantity":"0.122"},{"price":"61851.00","quantity":"1.001"},{"price":"61851.90","quantity":"0.001"},{"price":"61852.10","quantity":"0.000"},{"price":"61852.20","quantity":"0.394"},{"price":"61854.00","quantity":"0.333"},{"price":"61854.10","quantity":"16.512"}],"asks":[{"price":"61854.20","quantity":"1.676"},{"price":"61854.70","quantity":"0.369"},{"price":"61855.30","quantity":"0.002"},{"price":"61855.60","quantity":"0.000"},{"price":"61856.10","quantity":"0.000"},{"price":"61856.40","quantity":"0.078"},{"price":"61856.50","quantity":"0.009"},{"price":"61856.80","quantity":"0.001"},{"price":"61856.90","quantity":"0.002"},{"price":"61857.30","quantity":"1.000"},{"price":"61858.10","quantity":"0.089"},{"price":"61858.20","quantity":"1.702"},{"price":"61858.30","quantity":"0.176"},{"price":"61858.40","quantity":"0.001"},{"price":"61858.60","quantity":"0.001"},{"price":"61859.00","quantity":"0.104"},{"price":"61859.50","quantity":"1.635"},{"price":"61859.60","quantity":"0.179"},{"price":"61859.70","quantity":"0.001"},{"price":"61859.80","quantity":"0.002"},{"price":"61859.90","quantity":"0.000"},{"price":"61860.00","quantity":"0.176"},{"price":"61860.20","quantity":"0.955"},{"price":"61860.60","quantity":"0.108"},{"price":"61860.80","quantity":"0.033"},{"price":"61861.50","quantity":"0.556"},{"price":"61861.80","quantity":"0.201"},{"price":"61863.80","quantity":"0.003"},{"price":"61864.10","quantity":"0.000"},{"price":"61865.00","quantity":"0.087"},{"price":"61865.10","quantity":"1.188"},{"price":"61865.90","quantity":"0.586"},{"price":"61866.50","quantity":"0.570"},{"price":"61867.70","quantity":"0.000"},{"price":"61869.80","quantity":"0.012"},{"price":"61872.50","quantity":"0.000"},{"price":"61873.30","quantity":"0.011"},{"price":"61886.70","quantity":"0.105"},{"price":"61889.20","quantity":"0.023"},{"price":"61889.80","quantity":"0.181"},{"price":"61893.40","quantity":"0.306"},{"price":"61898.10","quantity":"0.002"},{"price":"61908.10","quantity":"0.102"},{"price":"61908.60","quantity":"0.102"},{"price":"61926.60","quantity":"0.001"},{"price":"61952.30","quantity":"0.264"},{"price":"62472.70","quantity":"0.080"},{"price":"62906.70","quantity":"0.794"},{"price":"63090.80","quantity":"0.009"},{"price":"63091.20","quantity":"0.023"},{"price":"89523.20","quantity":"0.864"}],"raw":{"e":"depthUpdate","E":1783517071598,"T":1783517071597,"s":"BTCUSDT","ps":"BTCUSDT","U":10999771008899,"u":10999771020511,"pu":10999771008780,"b":[["1000.00","207.692"],["11454.10","2.128"],["11553.70","0.784"],["11554.10","0.526"],["11654.10","1.462"],["49483.00","0.000"],["55668.60","0.002"],["58759.60","0.002"],["58759.70","0.009"],["58761.30","0.000"],["60617.10","0.009"],["60859.70","0.703"],["61152.50","0.245"],["61152.80","0.025"],["61235.60","0.328"],["61812.30","0.017"],["61812.60","0.134"],["61813.80","0.113"],["61813.90","0.003"],["61814.10","0.571"],["61814.20","0.176"],["61821.10","0.367"],["61821.20","0.101"],["61823.40","0.511"],["61832.00","0.349"],["61834.10","3.868"],["61835.20","0.002"],["61836.70","0.003"],["61837.90","2.212"],["61838.00","1.061"],["61840.70","1.125"],["61841.80","0.005"],["61842.00","1.191"],["61842.90","1.089"],["61845.00","2.020"],["61845.70","1.122"],["61848.10","1.117"],["61850.40","0.122"],["61851.00","1.001"],["61851.90","0.001"],["61852.10","0.000"],["61852.20","0.394"],["61854.00","0.333"],["61854.10","16.512"]],"a":[["61854.20","1.676"],["61854.70","0.369"],["61855.30","0.002"],["61855.60","0.000"],["61856.10","0.000"],["61856.40","0.078"],["61856.50","0.009"],["61856.80","0.001"],["61856.90","0.002"],["61857.30","1.000"],["61858.10","0.089"],["61858.20","1.702"],["61858.30","0.176"],["61858.40","0.001"],["61858.60","0.001"],["61859.00","0.104"],["61859.50","1.635"],["61859.60","0.179"],["61859.70","0.001"],["61859.80","0.002"],["61859.90","0.000"],["61860.00","0.176"],["61860.20","0.955"],["61860.60","0.108"],["61860.80","0.033"],["61861.50","0.556"],["61861.80","0.201"],["61863.80","0.003"],["61864.10","0.000"],["61865.00","0.087"],["61865.10","1.188"],["61865.90","0.586"],["61866.50","0.570"],["61867.70","0.000"],["61869.80","0.012"],["61872.50","0.000"],["61873.30","0.011"],["61886.70","0.105"],["61889.20","0.023"],["61889.80","0.181"],["61893.40","0.306"],["61898.10","0.002"],["61908.10","0.102"],["61908.60","0.102"],["61926.60","0.001"],["61952.30","0.264"],["62472.70","0.080"],["62906.70","0.794"],["63090.80","0.009"],["63091.20","0.023"],["89523.20","0.864"]],"st":1}}
{"schema_version":"1.3.0","event_id":"f23e2be4-4a8e-44c0-8822-018f58f6f585","event_type":"raw.depth_update","source":"binance_market_data_recorder","venue":"binance_usdm","market_type":"perpetual_futures","symbol":"BTCUSDT","event_time_ms":1783517071700,"received_time_ms":1783517071699,"trace_id":"6e4a5575-7b34-4045-ae3c-f473f1d96096","first_update_id":10999771020642,"final_update_id":10999771028721,"previous_final_update_id":10999771020511,"bids":[{"price":"11454.10","quantity":"2.400"},{"price":"11553.70","quantity":"0.640"},{"price":"11554.10","quantity":"0.534"},{"price":"11654.10","quantity":"1.326"},{"price":"49483.00","quantity":"0.000"},{"price":"55668.60","quantity":"0.002"},{"price":"55668.70","quantity":"0.007"},{"price":"58761.30","quantity":"0.000"},{"price":"58761.40","quantity":"0.017"},{"price":"59379.90","quantity":"0.000"},{"price":"61235.60","quantity":"0.328"},{"price":"61296.20","quantity":"1.144"},{"price":"61777.90","quantity":"33.540"},{"price":"61786.30","quantity":"0.002"},{"price":"61789.00","quantity":"6.255"},{"price":"61809.50","quantity":"0.061"},{"price":"61810.10","quantity":"0.005"},{"price":"61812.60","quantity":"0.033"},{"price":"61813.40","quantity":"0.062"},{"price":"61813.80","quantity":"0.014"},{"price":"61815.40","quantity":"0.105"},{"price":"61815.70","quantity":"0.103"},{"price":"61821.10","quantity":"0.803"},{"price":"61821.90","quantity":"0.413"},{"price":"61822.30","quantity":"0.002"},{"price":"61822.50","quantity":"0.761"},{"price":"61822.60","quantity":"0.001"},{"price":"61823.40","quantity":"0.616"},{"price":"61823.50","quantity":"0.197"},{"price":"61823.80","quantity":"0.255"},{"price":"61828.10","quantity":"0.008"},{"price":"61830.40","quantity":"0.130"},{"price":"61833.10","quantity":"1.293"},{"price":"61834.10","quantity":"2.900"},{"price":"61836.70","quantity":"0.569"},{"price":"61837.00","quantity":"0.082"},{"price":"61837.70","quantity":"0.454"},{"price":"61837.90","quantity":"1.646"},{"price":"61838.00","quantity":"0.000"},{"price":"61840.30","quantity":"0.123"},{"price":"61840.70","quantity":"0.003"},{"price":"61843.10","quantity":"0.090"},{"price":"61845.10","quantity":"0.285"},{"price":"61848.00","quantity":"1.045"},{"price":"61853.90","quantity":"0.243"}],"asks":[{"price":"61854.20","quantity":"2.857"},{"price":"61854.70","quantity":"0.370"},{"price":"61854.80","quantity":"0.024"},{"price":"61856.40","quantity":"0.029"},{"price":"61856.50","quantity":"0.300"},{"price":"61856.90","quantity":"0.002"},{"price":"61857.20","quantity":"0.001"},{"price":"61857.80","quantity":"0.001"},{"price":"61857.90","quantity":"0.694"},{"price":"61858.00","quantity":"0.011"},{"price":"61858.10","quantity":"0.089"},{"price":"61858.20","quantity":"0.349"},{"price":"61859.50","quantity":"0.084"},{"price":"61860.10","quantity":"1.783"},{"price":"61860.40","quantity":"0.308"},{"price":"61862.60","quantity":"0.484"},{"price":"61863.80","quantity":"0.165"},{"price":"61865.00","quantity":"0.007"},{"price":"61867.30","quantity":"0.002"},{"price":"61869.80","quantity":"0.336"},{"price":"61872.50","quantity":"0.080"},{"price":"61873.30","quantity":"0.173"},{"price":"61887.80","quantity":"0.288"},{"price":"61887.90","quantity":"0.484"},{"price":"61888.80","quantity":"0.125"},{"price":"61889.00","quantity":"0.002"},{"price":"61894.40","quantity":"0.571"},{"price":"61897.50","quantity":"0.451"},{"price":"61926.60","quantity":"0.001"},{"price":"62472.70","quantity":"0.080"},{"price":"62534.20","quantity":"0.480"}],"raw":{"e":"depthUpdate","E":1783517071700,"T":1783517071697,"s":"BTCUSDT","ps":"BTCUSDT","U":10999771020642,"u":10999771028721,"pu":10999771020511,"b":[["11454.10","2.400"],["11553.70","0.640"],["11554.10","0.534"],["11654.10","1.326"],["49483.00","0.000"],["55668.60","0.002"],["55668.70","0.007"],["58761.30","0.000"],["58761.40","0.017"],["59379.90","0.000"],["61235.60","0.328"],["61296.20","1.144"],["61777.90","33.540"],["61786.30","0.002"],["61789.00","6.255"],["61809.50","0.061"],["61810.10","0.005"],["61812.60","0.033"],["61813.40","0.062"],["61813.80","0.014"],["61815.40","0.105"],["61815.70","0.103"],["61821.10","0.803"],["61821.90","0.413"],["61822.30","0.002"],["61822.50","0.761"],["61822.60","0.001"],["61823.40","0.616"],["61823.50","0.197"],["61823.80","0.255"],["61828.10","0.008"],["61830.40","0.130"],["61833.10","1.293"],["61834.10","2.900"],["61836.70","0.569"],["61837.00","0.082"],["61837.70","0.454"],["61837.90","1.646"],["61838.00","0.000"],["61840.30","0.123"],["61840.70","0.003"],["61843.10","0.090"],["61845.10","0.285"],["61848.00","1.045"],["61853.90","0.243"]],"a":[["61854.20","2.857"],["61854.70","0.370"],["61854.80","0.024"],["61856.40","0.029"],["61856.50","0.300"],["61856.90","0.002"],["61857.20","0.001"],["61857.80","0.001"],["61857.90","0.694"],["61858.00","0.011"],["61858.10","0.089"],["61858.20","0.349"],["61859.50","0.084"],["61860.10","1.783"],["61860.40","0.308"],["61862.60","0.484"],["61863.80","0.165"],["61865.00","0.007"],["61867.30","0.002"],["61869.80","0.336"],["61872.50","0.080"],["61873.30","0.173"],["61887.80","0.288"],["61887.90","0.484"],["61888.80","0.125"],["61889.00","0.002"],["61894.40","0.571"],["61897.50","0.451"],["61926.60","0.001"],["62472.70","0.080"],["62534.20","0.480"]],"st":1}}
{"schema_version":"1.3.0","event_id":"fa1e2a43-dd5c-4f7c-a7e4-884153c31286","event_type":"raw.depth_update","source":"binance_market_data_recorder","venue":"binance_usdm","market_type":"perpetual_futures","symbol":"BTCUSDT","event_time_ms":1783517071802,"received_time_ms":1783517071800,"trace_id":"c5340658-4e24-4b22-98db-e9eb4e90311c","first_update_id":10999771029068,"final_update_id":10999771036834,"previous_final_update_id":10999771028721,"bids":[{"price":"1000.00","quantity":"207.692"},{"price":"11454.10","quantity":"2.672"},{"price":"11553.70","quantity":"0.512"},{"price":"11554.10","quantity":"0.543"},{"price":"11654.10","quantity":"1.173"},{"price":"49483.30","quantity":"0.000"},{"price":"55668.60","quantity":"0.002"},{"price":"55668.70","quantity":"0.005"},{"price":"58761.00","quantity":"0.006"},{"price":"58761.10","quantity":"0.006"},{"price":"58761.30","quantity":"0.000"},{"price":"59379.90","quantity":"0.003"},{"price":"61206.50","quantity":"1.386"},{"price":"61235.60","quantity":"0.328"},{"price":"61504.50","quantity":"0.000"},{"price":"61544.80","quantity":"0.029"},{"price":"61684.60","quantity":"0.327"},{"price":"61762.60","quantity":"0.214"},{"price":"61777.90","quantity":"0.146"},{"price":"61786.30","quantity":"33.263"},{"price":"61789.00","quantity":"1.484"},{"price":"61792.20","quantity":"0.326"},{"price":"61815.10","quantity":"0.105"},{"price":"61823.30","quantity":"2.126"},{"price":"61830.50","quantity":"0.000"},{"price":"61830.90","quantity":"0.081"},{"price":"61831.80","quantity":"0.010"},{"price":"61837.00","quantity":"0.002"},{"price":"61838.10","quantity":"0.000"},{"price":"61840.90","quantity":"0.003"},{"price":"61854.10","quantity":"16.512"}],"asks":[{"price":"61855.60","quantity":"0.000"},{"price":"61856.00","quantity":"0.246"},{"price":"61856.50","quantity":"0.058"},{"price":"61860.40","quantity":"0.308"},{"price":"61865.60","quantity":"0.004"},{"price":"61866.20","quantity":"0.584"},{"price":"61866.70","quantity":"0.764"},{"price":"61867.40","quantity":"0.061"},{"price":"61880.30","quantity":"1.191"},{"price":"61897.50","quantity":"0.323"},{"price":"61907.70","quantity":"0.517"},{"price":"61926.60","quantity":"0.098"},{"price":"61976.30","quantity":"0.001"},{"price":"62138.50","quantity":"0.001"},{"price":"62408.40","quantity":"0.875"},{"price":"62472.70","quantity":"0.080"},{"price":"62778.20","quantity":"0.358"},{"price":"89523.20","quantity":"0.870"}],"raw":{"e":"depthUpdate","E":1783517071802,"T":1783517071801,"s":"BTCUSDT","ps":"BTCUSDT","U":10999771029068,"u":10999771036834,"pu":10999771028721,"b":[["1000.00","207.692"],["11454.10","2.672"],["11553.70","0.512"],["11554.10","0.543"],["11654.10","1.173"],["49483.30","0.000"],["55668.60","0.002"],["55668.70","0.005"],["58761.00","0.006"],["58761.10","0.006"],["58761.30","0.000"],["59379.90","0.003"],["61206.50","1.386"],["61235.60","0.328"],["61504.50","0.000"],["61544.80","0.029"],["61684.60","0.327"],["61762.60","0.214"],["61777.90","0.146"],["61786.30","33.263"],["61789.00","1.484"],["61792.20","0.326"],["61815.10","0.105"],["61823.30","2.126"],["61830.50","0.000"],["61830.90","0.081"],["61831.80","0.010"],["61837.00","0.002"],["61838.10","0.000"],["61840.90","0.003"],["61854.10","16.512"]],"a":[["61855.60","0.000"],["61856.00","0.246"],["61856.50","0.058"],["61860.40","0.308"],["61865.60","0.004"],["61866.20","0.584"],["61866.70","0.764"],["61867.40","0.061"],["61880.30","1.191"],["61897.50","0.323"],["61907.70","0.517"],["61926.60","0.098"],["61976.30","0.001"],["62138.50","0.001"],["62408.40","0.875"],["62472.70","0.080"],["62778.20","0.358"],["89523.20","0.870"]],"st":1}}
{"schema_version":"1.3.0","event_id":"534df492-fde0-402e-b659-e3574bf6cafb","event_type":"raw.depth_update","source":"binance_market_data_recorder","venue":"binance_usdm","market_type":"perpetual_futures","symbol":"BTCUSDT","event_time_ms":1783517071904,"received_time_ms":1783517071901,"trace_id":"e15c0a01-825b-4e80-9d28-55674f8cfc49","first_update_id":10999771036997,"final_update_id":10999771042310,"previous_final_update_id":10999771036834,"bids":[{"price":"1000.00","quantity":"207.692"},{"price":"11354.10","quantity":"0.112"},{"price":"11454.10","quantity":"2.720"},{"price":"11553.70","quantity":"0.368"},{"price":"11554.10","quantity":"0.663"},{"price":"11654.10","quantity":"1.037"},{"price":"55668.60","quantity":"0.002"},{"price":"59379.90","quantity":"0.000"},{"price":"61045.80","quantity":"0.001"},{"price":"61134.20","quantity":"0.817"},{"price":"61235.60","quantity":"0.328"},{"price":"61242.20","quantity":"0.028"},{"price":"61723.50","quantity":"0.011"},{"price":"61723.60","quantity":"0.285"},{"price":"61813.80","quantity":"0.115"},{"price":"61823.10","quantity":"0.105"},{"price":"61827.20","quantity":"0.583"},{"price":"61828.10","quantity":"0.008"},{"price":"61828.20","quantity":"0.017"},{"price":"61830.40","quantity":"0.050"},{"price":"61830.90","quantity":"0.001"},{"price":"61832.10","quantity":"1.033"},{"price":"61833.10","quantity":"0.325"},{"price":"61836.50","quantity":"0.103"},{"price":"61838.60","quantity":"0.000"},{"price":"61840.50","quantity":"2.140"},{"price":"61842.00","quantity":"0.069"},{"price":"61842.40","quantity":"0.859"},{"price":"61842.50","quantity":"0.329"},{"price":"61842.90","quantity":"0.000"},{"price":"61843.10","quantity":"0.170"},{"price":"61843.20","quantity":"0.308"},{"price":"61845.00","quantity":"1.131"},{"price":"61845.10","quantity":"0.285"}],"asks":[{"price":"61854.20","quantity":"2.798"},{"price":"61854.40","quantity":"0.002"},{"price":"61855.40","quantity":"0.001"},{"price":"61855.60","quantity":"0.000"},{"price":"61856.00","quantity":"0.004"},{"price":"61859.90","quantity":"0.180"},{"price":"61860.00","quantity":"0.176"},{"price":"61860.40","quantity":"0.308"},{"price":"61863.10","quantity":"0.000"},{"price":"61863.90","quantity":"1.692"},{"price":"61864.10","quantity":"0.968"},{"price":"61865.10","quantity":"0.220"},{"price":"61865.80","quantity":"0.566"},{"price":"61865.90","quantity":"0.406"},{"price":"61866.50","quantity":"0.004"},{"price":"61869.70","quantity":"0.003"},{"price":"61871.60","quantity":"0.329"},{"price":"61893.20","quantity":"0.000"},{"price":"61926.60","quantity":"0.001"},{"price":"61985.30","quantity":"2.859"},{"price":"61985.40","quantity":"0.841"},{"price":"62472.70","quantity":"0.080"}],"raw":{"e":"depthUpdate","E":1783517071904,"T":1783517071903,"s":"BTCUSDT","ps":"BTCUSDT","U":10999771036997,"u":10999771042310,"pu":10999771036834,"b":[["1000.00","207.692"],["11354.10","0.112"],["11454.10","2.720"],["11553.70","0.368"],["11554.10","0.663"],["11654.10","1.037"],["55668.60","0.002"],["59379.90","0.000"],["61045.80","0.001"],["61134.20","0.817"],["61235.60","0.328"],["61242.20","0.028"],["61723.50","0.011"],["61723.60","0.285"],["61813.80","0.115"],["61823.10","0.105"],["61827.20","0.583"],["61828.10","0.008"],["61828.20","0.017"],["61830.40","0.050"],["61830.90","0.001"],["61832.10","1.033"],["61833.10","0.325"],["61836.50","0.103"],["61838.60","0.000"],["61840.50","2.140"],["61842.00","0.069"],["61842.40","0.859"],["61842.50","0.329"],["61842.90","0.000"],["61843.10","0.170"],["61843.20","0.308"],["61845.00","1.131"],["61845.10","0.285"]],"a":[["61854.20","2.798"],["61854.40","0.002"],["61855.40","0.001"],["61855.60","0.000"],["61856.00","0.004"],["61859.90","0.180"],["61860.00","0.176"],["61860.40","0.308"],["61863.10","0.000"],["61863.90","1.692"],["61864.10","0.968"],["61865.10","0.220"],["61865.80","0.566"],["61865.90","0.406"],["61866.50","0.004"],["61869.70","0.003"],["61871.60","0.329"],["61893.20","0.000"],["61926.60","0.001"],["61985.30","2.859"],["61985.40","0.841"],["62472.70","0.080"]],"st":1}}
{"schema_version":"1.3.0","event_id":"2667e53b-005f-4084-9eed-32458640772c","event_type":"raw.depth_update","source":"binance_market_data_recorder","venue":"binance_usdm","market_type":"perpetual_futures","symbol":"BTCUSDT","event_time_ms":1783517072006,"received_time_ms":1783517072001,"trace_id":"45fd96f4-d73c-4bba-913b-ff0ad8c3ee49","first_update_id":10999771042334,"final_update_id":10999771048411,"previous_final_update_id":10999771042310,"bids":[{"price":"11354.10","quantity":"0.240"},{"price":"11454.10","quantity":"2.736"},{"price":"11553.70","quantity":"0.224"},{"price":"11554.10","quantity":"0.816"},{"price":"11654.10","quantity":"0.884"},{"price":"55668.60","quantity":"0.002"},{"price":"58761.30","quantity":"0.000"},{"price":"58761.40","quantity":"0.020"},{"price":"59379.90","quantity":"0.003"},{"price":"61148.90","quantity":"0.008"},{"price":"61169.90","quantity":"0.246"},{"price":"61235.60","quantity":"0.328"},{"price":"61287.20","quantity":"0.004"},{"price":"61359.30","quantity":"0.717"},{"price":"61731.40","quantity":"0.047"},{"price":"61763.60","quantity":"0.200"},{"price":"61813.40","quantity":"0.163"},{"price":"61831.70","quantity":"0.263"},{"price":"61834.20","quantity":"0.081"},{"price":"61835.20","quantity":"0.568"},{"price":"61835.50","quantity":"0.140"},{"price":"61836.50","quantity":"0.023"},{"price":"61836.70","quantity":"0.003"},{"price":"61841.90","quantity":"0.420"},{"price":"61850.40","quantity":"0.000"},{"price":"61851.90","quantity":"0.002"},{"price":"61854.00","quantity":"0.008"},{"price":"61854.10","quantity":"15.192"}],"asks":[{"price":"61854.20","quantity":"4.315"},{"price":"61859.00","quantity":"0.108"},{"price":"61860.40","quantity":"0.312"},{"price":"61860.80","quantity":"0.029"},{"price":"61863.80","quantity":"0.731"},{"price":"61865.80","quantity":"0.000"},{"price":"61866.60","quantity":"3.360"},{"price":"61867.10","quantity":"0.323"},{"price":"61868.00","quantity":"0.091"},{"price":"61868.60","quantity":"0.021"},{"price":"61871.60","quantity":"0.006"},{"price":"61872.80","quantity":"0.004"},{"price":"61874.20","quantity":"0.002"},{"price":"61893.50","quantity":"0.580"},{"price":"61926.60","quantity":"0.001"},{"price":"61952.30","quantity":"0.000"},{"price":"62472.70","quantity":"0.080"},{"price":"62782.10","quantity":"0.572"},{"price":"63091.20","quantity":"0.026"},{"price":"89523.20","quantity":"0.876"}],"raw":{"e":"depthUpdate","E":1783517072006,"T":1783517072005,"s":"BTCUSDT","ps":"BTCUSDT","U":10999771042334,"u":10999771048411,"pu":10999771042310,"b":[["11354.10","0.240"],["11454.10","2.736"],["11553.70","0.224"],["11554.10","0.816"],["11654.10","0.884"],["55668.60","0.002"],["58761.30","0.000"],["58761.40","0.020"],["59379.90","0.003"],["61148.90","0.008"],["61169.90","0.246"],["61235.60","0.328"],["61287.20","0.004"],["61359.30","0.717"],["61731.40","0.047"],["61763.60","0.200"],["61813.40","0.163"],["61831.70","0.263"],["61834.20","0.081"],["61835.20","0.568"],["61835.50","0.140"],["61836.50","0.023"],["61836.70","0.003"],["61841.90","0.420"],["61850.40","0.000"],["61851.90","0.002"],["61854.00","0.008"],["61854.10","15.192"]],"a":[["61854.20","4.315"],["61859.00","0.108"],["61860.40","0.312"],["61860.80","0.029"],["61863.80","0.731"],["61865.80","0.000"],["61866.60","3.360"],["61867.10","0.323"],["61868.00","0.091"],["61868.60","0.021"],["61871.60","0.006"],["61872.80","0.004"],["61874.20","0.002"],["61893.50","0.580"],["61926.60","0.001"],["61952.30","0.000"],["62472.70","0.080"],["62782.10","0.572"],["63091.20","0.026"],["89523.20","0.876"]],"st":1}}
{"schema_version":"1.3.0","event_id":"928fa8e8-fead-4e0b-9a56-3cd52b7ef4bd","event_type":"raw.depth_update","source":"binance_market_data_recorder","venue":"binance_usdm","market_type":"perpetual_futures","symbol":"BTCUSDT","event_time_ms":1783517072108,"received_time_ms":1783517072103,"trace_id":"ee1f0844-e66f-40bb-96b8-7021205a13bb","first_update_id":10999771048527,"final_update_id":10999771054607,"previous_final_update_id":10999771048411,"bids":[{"price":"1000.00","quantity":"207.692"},{"price":"11354.10","quantity":"0.384"},{"price":"11454.10","quantity":"2.720"},{"price":"11553.70","quantity":"0.096"},{"price":"11554.10","quantity":"0.952"},{"price":"11654.10","quantity":"0.748"},{"price":"55668.60","quantity":"0.002"},{"price":"61235.60","quantity":"0.328"},{"price":"61247.50","quantity":"0.653"},{"price":"61544.80","quantity":"0.039"},{"price":"61731.40","quantity":"0.000"},{"price":"61793.40","quantity":"0.025"},{"price":"61794.70","quantity":"0.049"},{"price":"61813.40","quantity":"0.163"},{"price":"61828.10","quantity":"0.088"},{"price":"61830.40","quantity":"0.130"},{"price":"61834.20","quantity":"0.001"},{"price":"61838.40","quantity":"0.011"},{"price":"61838.80","quantity":"0.010"},{"price":"61839.30","quantity":"0.004"},{"price":"61841.60","quantity":"0.255"},{"price":"61843.00","quantity":"0.001"},{"price":"61843.10","quantity":"0.010"},{"price":"61854.10","quantity":"15.192"}],"asks":[{"price":"61854.20","quantity":"4.787"},{"price":"61860.00","quantity":"0.302"},{"price":"61860.40","quantity":"0.308"},{"price":"61863.70","quantity":"1.109"},{"price":"61863.80","quantity":"0.165"},{"price":"61865.30","quantity":"0.456"},{"price":"61866.10","quantity":"0.566"},{"price":"61866.60","quantity":"3.356"},{"price":"61867.40","quantity":"0.691"},{"price":"61868.00","quantity":"0.011"},{"price":"61868.60","quantity":"0.004"},{"price":"61869.20","quantity":"0.124"},{"price":"61869.70","quantity":"0.083"},{"price":"61870.30","quantity":"0.000"},{"price":"61872.80","quantity":"0.000"},{"price":"61881.60","quantity":"0.222"},{"price":"61886.50","quantity":"0.027"},{"price":"61887.20","quantity":"0.107"},{"price":"61887.80","quantity":"0.286"},{"price":"61887.90","quantity":"0.379"},{"price":"61888.80","quantity":"0.125"},{"price":"61898.20","quantity":"0.265"},{"price":"61907.70","quantity":"0.416"},{"price":"61909.50","quantity":"2.896"},{"price":"61909.90","quantity":"0.120"},{"price":"61950.50","quantity":"0.000"},{"price":"61957.70","quantity":"0.039"},{"price":"61957.90","quantity":"3.098"},{"price":"62163.50","quantity":"0.001"},{"price":"62472.70","quantity":"0.080"},{"price":"62472.80","quantity":"0.213"}],"raw":{"e":"depthUpdate","E":1783517072108,"T":1783517072105,"s":"BTCUSDT","ps":"BTCUSDT","U":10999771048527,"u":10999771054607,"pu":10999771048411,"b":[["1000.00","207.692"],["11354.10","0.384"],["11454.10","2.720"],["11553.70","0.096"],["11554.10","0.952"],["11654.10","0.748"],["55668.60","0.002"],["61235.60","0.328"],["61247.50","0.653"],["61544.80","0.039"],["61731.40","0.000"],["61793.40","0.025"],["61794.70","0.049"],["61813.40","0.163"],["61828.10","0.088"],["61830.40","0.130"],["61834.20","0.001"],["61838.40","0.011"],["61838.80","0.010"],["61839.30","0.004"],["61841.60","0.255"],["61843.00","0.001"],["61843.10","0.010"],["61854.10","15.192"]],"a":[["61854.20","4.787"],["61860.00","0.302"],["61860.40","0.308"],["61863.70","1.109"],["61863.80","0.165"],["61865.30","0.456"],["61866.10","0.566"],["61866.60","3.356"],["61867.40","0.691"],["61868.00","0.011"],["61868.60","0.004"],["61869.20","0.124"],["61869.70","0.083"],["61870.30","0.000"],["61872.80","0.000"],["61881.60","0.222"],["61886.50","0.027"],["61887.20","0.107"],["61887.80","0.286"],["61887.90","0.379"],["61888.80","0.125"],["61898.20","0.265"],["61907.70","0.416"],["61909.50","2.896"],["61909.90","0.120"],["61950.50","0.000"],["61957.70","0.039"],["61957.90","3.098"],["62163.50","0.001"],["62472.70","0.080"],["62472.80","0.213"]],"st":1}}
{"schema_version":"1.3.0","event_id":"ebfa4620-6faa-4c0a-84f8-018f628c45ad","event_type":"raw.depth_update","source":"binance_market_data_recorder","venue":"binance_usdm","market_type":"perpetual_futures","symbol":"BTCUSDT","event_time_ms":1783517072210,"received_time_ms":1783517072205,"trace_id":"2a3c0067-9752-4528-a6d8-e50947f98b7e","first_update_id":10999771054832,"final_update_id":10999771064414,"previous_final_update_id":10999771054607,"bids":[{"price":"1000.00","quantity":"207.692"},{"price":"11354.10","quantity":"0.560"},{"price":"11454.10","quantity":"2.640"},{"price":"11553.70","quantity":"0.000"},{"price":"11554.10","quantity":"1.105"},{"price":"11654.10","quantity":"0.595"},{"price":"49483.00","quantity":"0.000"},{"price":"55668.60","quantity":"0.002"},{"price":"59379.90","quantity":"0.000"},{"price":"60616.70","quantity":"0.029"},{"price":"61235.60","quantity":"0.328"},{"price":"61287.50","quantity":"1.147"},{"price":"61813.40","quantity":"0.062"},{"price":"61813.90","quantity":"0.104"},{"price":"61828.10","quantity":"0.008"},{"price":"61828.30","quantity":"0.001"},{"price":"61829.30","quantity":"0.048"},{"price":"61830.00","quantity":"0.127"},{"price":"61835.20","quantity":"0.002"},{"price":"61835.50","quantity":"0.012"},{"price":"61836.70","quantity":"0.569"},{"price":"61837.60","quantity":"1.229"},{"price":"61838.60","quantity":"0.128"},{"price":"61841.40","quantity":"1.008"},{"price":"61841.70","quantity":"0.390"},{"price":"61842.40","quantity":"0.293"},{"price":"61842.50","quantity":"0.006"},{"price":"61845.10","quantity":"1.174"},{"price":"61850.40","quantity":"0.122"},{"price":"61851.90","quantity":"0.001"},{"price":"61853.80","quantity":"0.002"},{"price":"61854.00","quantity":"0.009"},{"price":"61854.10","quantity":"16.836"}],"asks":[{"price":"61854.20","quantity":"2.610"},{"price":"61854.30","quantity":"0.025"},{"price":"61854.70","quantity":"0.369"},{"price":"61854.80","quantity":"0.001"},{"price":"61855.80","quantity":"0.005"},{"price":"61855.90","quantity":"0.000"},{"price":"61856.00","quantity":"0.028"},{"price":"61856.30","quantity":"0.277"},{"price":"61856.40","quantity":"0.078"},{"price":"61856.50","quantity":"0.009"},{"price":"61858.30","quantity":"0.175"},{"price":"61859.00","quantity":"0.104"},{"price":"61859.90","quantity":"0.000"},{"price":"61860.00","quantity":"0.176"},{"price":"61860.10","quantity":"1.621"},{"price":"61860.20","quantity":"0.956"},{"price":"61860.40","quantity":"0.180"},{"price":"61860.70","quantity":"0.130"},{"price":"61861.80","quantity":"0.161"},{"price":"61862.40","quantity":"0.008"},{"price":"61863.30","quantity":"0.004"},{"price":"61863.80","quantity":"0.003"},{"price":"61865.90","quantity":"0.586"},{"price":"61866.80","quantity":"1.362"},{"price":"61867.00","quantity":"0.310"},{"price":"61869.20","quantity":"0.003"},{"price":"61869.80","quantity":"0.012"},{"price":"61869.90","quantity":"1.832"},{"price":"61870.90","quantity":"0.254"},{"price":"61872.50","quantity":"0.082"},{"price":"61872.80","quantity":"0.000"},{"price":"61873.20","quantity":"0.102"},{"price":"61873.30","quantity":"0.011"},{"price":"61873.60","quantity":"0.019"},{"price":"61879.40","quantity":"0.469"},{"price":"61886.70","quantity":"0.000"},{"price":"61887.80","quantity":"0.391"},{"price":"61887.90","quantity":"0.484"},{"price":"61888.60","quantity":"0.012"},{"price":"61888.80","quantity":"0.125"},{"price":"61891.30","quantity":"0.330"},{"price":"61893.40","quantity":"0.679"},{"price":"61893.50","quantity":"0.580"},{"price":"61898.20","quantity":"0.001"},{"price":"61909.90","quantity":"0.120"},{"price":"61926.60","quantity":"0.098"},{"price":"61952.30","quantity":"0.264"},{"price":"62407.10","quantity":"0.000"},{"price":"62472.70","quantity":"0.080"},{"price":"62634.90","quantity":"0.271"},{"price":"63089.30","quantity":"0.078"},{"price":"63091.20","quantity":"0.029"},{"price":"89523.20","quantity":"0.882"}],"raw":{"e":"depthUpdate","E":1783517072210,"T":1783517072209,"s":"BTCUSDT","ps":"BTCUSDT","U":10999771054832,"u":10999771064414,"pu":10999771054607,"b":[["1000.00","207.692"],["11354.10","0.560"],["11454.10","2.640"],["11553.70","0.000"],["11554.10","1.105"],["11654.10","0.595"],["49483.00","0.000"],["55668.60","0.002"],["59379.90","0.000"],["60616.70","0.029"],["61235.60","0.328"],["61287.50","1.147"],["61813.40","0.062"],["61813.90","0.104"],["61828.10","0.008"],["61828.30","0.001"],["61829.30","0.048"],["61830.00","0.127"],["61835.20","0.002"],["61835.50","0.012"],["61836.70","0.569"],["61837.60","1.229"],["61838.60","0.128"],["61841.40","1.008"],["61841.70","0.390"],["61842.40","0.293"],["61842.50","0.006"],["61845.10","1.174"],["61850.40","0.122"],["61851.90","0.001"],["61853.80","0.002"],["61854.00","0.009"],["61854.10","16.836"]],"a":[["61854.20","2.610"],["61854.30","0.025"],["61854.70","0.369"],["61854.80","0.001"],["61855.80","0.005"],["61855.90","0.000"],["61856.00","0.028"],["61856.30","0.277"],["61856.40","0.078"],["61856.50","0.009"],["61858.30","0.175"],["61859.00","0.104"],["61859.90","0.000"],["61860.00","0.176"],["61860.10","1.621"],["61860.20","0.956"],["61860.40","0.180"],["61860.70","0.130"],["61861.80","0.161"],["61862.40","0.008"],["61863.30","0.004"],["61863.80","0.003"],["61865.90","0.586"],["61866.80","1.362"],["61867.00","0.310"],["61869.20","0.003"],["61869.80","0.012"],["61869.90","1.832"],["61870.90","0.254"],["61872.50","0.082"],["61872.80","0.000"],["61873.20","0.102"],["61873.30","0.011"],["61873.60","0.019"],["61879.40","0.469"],["61886.70","0.000"],["61887.80","0.391"],["61887.90","0.484"],["61888.60","0.012"],["61888.80","0.125"],["61891.30","0.330"],["61893.40","0.679"],["61893.50","0.580"],["61898.20","0.001"],["61909.90","0.120"],["61926.60","0.098"],["61952.30","0.264"],["62407.10","0.000"],["62472.70","0.080"],["62634.90","0.271"],["63089.30","0.078"],["63091.20","0.029"],["89523.20","0.882"]],"st":1}}
