{"schema_version":"1.3.0","event_id":"d5238802-51e9-4cdb-b12e-c34a6aa8574e","event_type":"raw.depth_update","source":"binance_market_data_recorder","venue":"binance_usdm","market_type":"perpetual_futures","symbol":"BTCUSDT","event_time_ms":1783517077412,"received_time_ms":1783517077407,"trace_id":"558a1377-0ffb-475b-a166-4687335b01cb","first_update_id":10999771563628,"final_update_id":10999771574018,"previous_final_update_id":10999771563613,"bids":[{"price":"11454.10","quantity":"1.632"},{"price":"11554.10","quantity":"1.568"},{"price":"11654.10","quantity":"1.666"},{"price":"11754.10","quantity":"0.034"},{"price":"49483.00","quantity":"0.000"},{"price":"55668.60","quantity":"0.002"},{"price":"60889.00","quantity":"0.123"},{"price":"61019.10","quantity":"2.370"},{"price":"61111.90","quantity":"10.736"},{"price":"61235.60","quantity":"0.328"},{"price":"61297.40","quantity":"0.498"},{"price":"61537.60","quantity":"0.348"},{"price":"61544.80","quantity":"0.038"},{"price":"61601.80","quantity":"0.881"},{"price":"61812.60","quantity":"0.033"},{"price":"61823.30","quantity":"2.029"},{"price":"61829.20","quantity":"0.470"},{"price":"61838.60","quantity":"0.128"},{"price":"61842.00","quantity":"0.473"},{"price":"61852.60","quantity":"0.002"},{"price":"61853.90","quantity":"0.291"}],"asks":[{"price":"61854.20","quantity":"5.354"},{"price":"61856.90","quantity":"0.128"},{"price":"61859.50","quantity":"0.019"},{"price":"61859.60","quantity":"1.818"},{"price":"61863.80","quantity":"0.567"},{"price":"61866.50","quantity":"0.004"},{"price":"61872.80","quantity":"0.000"},{"price":"61909.40","quantity":"0.367"},{"price":"61920.50","quantity":"0.000"},{"price":"61926.80","quantity":"26.123"},{"price":"61926.90","quantity":"0.021"},{"price":"62087.90","quantity":"0.018"},{"price":"62163.50","quantity":"2.409"},{"price":"62472.70","quantity":"1.678"},{"price":"63091.20","quantity":"0.080"}],"raw":{"e":"depthUpdate","E":1783517077412,"T":1783517077409,"s":"BTCUSDT","ps":"BTCUSDT","U":10999771563628,"u":10999771574018,"pu":10999771563613,"b":[["11454.10","1.632"],["11554.10","1.568"],["11654.10","1.666"],["11754.10","0.034"],["49483.00","0.000"],["55668.60","0.002"],["60889.00","0.123"],["61019.10","2.370"],["61111.90","10.736"],["61235.60","0.328"],["61297.40","0.498"],["61537.60","0.348"],["61544.80","0.038"],["61601.80","0.881"],["61812.60","0.033"],["61823.30","2.029"],["61829.20","0.470"],["61838.60","0.128"],["61842.00","0.473"],["61852.60","0.002"],["61853.90","0.291"]],"a":[["61854.20","5.354"],["61856.90","0.128"],["61859.50","0.019"],["61859.60","1.818"],["61863.80","0.567"],["61866.50","0.004"],["61872.80","0.000"],["61909.40","0.367"],["61920.50","0.000"],["61926.80","26.123"],["61926.90","0.021"],["62087.90","0.018"],["62163.50","2.409"],["62472.70","1.678"],["63091.20","0.080"]],"st":1}}
{"schema_version":"1.3.0","event_id":"4b23a956-4ca3-4875-a9b9-9821185634c5","event_type":"raw.depth_update","source":"binance_market_data_recorder","venue":"binance_usdm","market_type":"perpetual_futures","symbol":"BTCUSDT","event_time_ms":1783517077514,"received_time_ms":1783517077509,"trace_id":"c52147de-3c46-4394-af56-697b3c05007e","first_update_id":10999771574450,"final_update_id":10999771583041,"previous_final_update_id":10999771574018,"bids":[{"price":"1000.00","quantity":"207.692"},{"price":"11454.10","quantity":"1.904"},{"price":"11554.10","quantity":"1.415"},{"price":"11654.10","quantity":"1.581"},{"price":"11754.10","quantity":"0.000"},{"price":"55668.60","quantity":"0.002"},{"price":"58761.00","quantity":"0.000"},{"price":"58761.10","quantity":"0.006"},{"price":"59379.90","quantity":"0.003"},{"price":"61050.00","quantity":"5.427"},{"price":"61059.50","quantity":"9.651"},{"price":"61082.60","quantity":"0.941"},{"price":"61235.60","quantity":"0.328"},{"price":"61400.40","quantity":"0.122"},{"price":"61544.80","quantity":"0.039"},{"price":"61825.00","quantity":"1.287"},{"price":"61835.60","quantity":"0.000"},{"price":"61838.80","quantity":"0.007"},{"price":"61838.90","quantity":"0.428"},{"price":"61842.00","quantity":"0.392"}],"asks":[{"price":"61854.20","quantity":"5.329"},{"price":"61856.90","quantity":"0.002"},{"price":"61859.50","quantity":"0.145"},{"price":"61859.60","quantity":"1.632"},{"price":"61860.40","quantity":"0.596"},{"price":"61860.50","quantity":"1.479"},{"price":"61863.80","quantity":"0.567"},{"price":"61866.50","quantity":"0.004"},{"price":"61872.80","quantity":"0.128"},{"price":"61897.50","quantity":"0.451"},{"price":"61924.70","quantity":"25.042"},{"price":"61926.80","quantity":"0.891"},{"price":"62472.70","quantity":"1.678"},{"price":"62534.60","quantity":"0.720"},{"price":"63427.20","quantity":"2.283"}],"raw":{"e":"depthUpdate","E":1783517077514,"T":1783517077513,"s":"BTCUSDT","ps":"BTCUSDT","U":10999771574450,"u":10999771583041,"pu":10999771574018,"b":[["1000.00","207.692"],["11454.10","1.904"],["11554.10","1.415"],["11654.10","1.581"],["11754.10","0.000"],["55668.60","0.002"],["58761.00","0.000"],["58761.10","0.006"],["59379.90","0.003"],["61050.00","5.427"],["61059.50","9.651"],["61082.60","0.941"],["61235.60","0.328"],["61400.40","0.122"],["61544.80","0.039"],["61825.00","1.287"],["61835.60","0.000"],["61838.80","0.007"],["61838.90","0.428"],["61842.00","0.392"]],"a":[["61854.20","5.329"],["61856.90","0.002"],["61859.50","0.145"],["61859.60","1.632"],["61860.40","0.596"],["61860.50","1.479"],["61863.80","0.567"],["61866.50","0.004"],["61872.80","0.128"],["61897.50","0.451"],["61924.70","25.042"],["61926.80","0.891"],["62472.70","1.678"],["62534.60","0.720"],["63427.20","2.283"]],"st":1}}
{"schema_version":"1.3.0","event_id":"e2f567b2-72d3-4369-813e-37e9a0d76e68","event_type":"raw.depth_update","source":"binance_market_data_recorder","venue":"binance_usdm","market_type":"perpetual_futures","symbol":"BTCUSDT","event_time_ms":1783517077616,"received_time_ms":1783517077611,"trace_id":"e5bda0e2-ee70-42cd-91f2-f33d12fadb20","first_update_id":10999771583103,"final_update_id":10999771591574,"previous_final_update_id":10999771583041,"bids":[{"price":"1000.00","quantity":"207.692"},{"price":"11454.10","quantity":"2.176"},{"price":"11554.10","quantity":"1.279"},{"price":"11654.10","quantity":"1.445"},{"price":"55668.60","quantity":"0.002"},{"price":"59379.90","quantity":"0.000"},{"price":"60617.10","quantity":"0.033"},{"price":"60891.70","quantity":"0.820"},{"price":"61235.60","quantity":"0.328"},{"price":"61812.30","quantity":"0.017"},{"price":"61812.50","quantity":"0.933"},{"price":"61813.40","quantity":"0.163"},{"price":"61817.40","quantity":"0.004"},{"price":"61823.40","quantity":"0.069"},{"price":"61826.30","quantity":"0.063"},{"price":"61827.70","quantity":"0.634"},{"price":"61829.60","quantity":"0.099"},{"price":"61838.00","quantity":"1.118"},{"price":"61850.10","quantity":"0.172"},{"price":"61853.80","quantity":"0.002"},{"price":"61854.00","quantity":"0.009"},{"price":"61854.10","quantity":"17.491"}],"asks":[{"price":"61854.20","quantity":"4.255"},{"price":"61866.70","quantity":"0.764"},{"price":"61873.10","quantity":"0.003"},{"price":"61878.90","quantity":"0.056"},{"price":"61879.30","quantity":"1.589"},{"price":"61882.00","quantity":"3.718"},{"price":"61893.40","quantity":"0.036"},{"price":"61897.50","quantity":"0.451"},{"price":"61920.50","quantity":"25.042"},{"price":"61924.70","quantity":"0.000"},{"price":"61926.90","quantity":"0.118"},{"price":"62472.70","quantity":"1.678"},{"price":"62962.50","quantity":"0.000"},{"price":"65000.00","quantity":"144.417"},{"price":"89523.20","quantity":"1.038"}],"raw":{"e":"depthUpdate","E":1783517077616,"T":1783517077613,"s":"BTCUSDT","ps":"BTCUSDT","U":10999771583103,"u":10999771591574,"pu":10999771583041,"b":[["1000.00","207.692"],["11454.10","2.176"],["11554.10","1.279"],["11654.10","1.445"],["55668.60","0.002"],["59379.90","0.000"],["60617.10","0.033"],["60891.70","0.820"],["61235.60","0.328"],["61812.30","0.017"],["61812.50","0.933"],["61813.40","0.163"],["61817.40","0.004"],["61823.40","0.069"],["61826.30","0.063"],["61827.70","0.634"],["61829.60","0.099"],["61838.00","1.118"],["61850.10","0.172"],["61853.80","0.002"],["61854.00","0.009"],["61854.10","17.491"]],"a":[["61854.20","4.255"],["61866.70","0.764"],["61873.10","0.003"],["61878.90","0.056"],["61879.30","1.589"],["61882.00","3.718"],["61893.40","0.036"],["61897.50","0.451"],["61920.50","25.042"],["61924.70","0.000"],["61926.90","0.118"],["62472.70","1.678"],["62962.50","0.000"],["65000.00","144.417"],["89523.20","1.038"]],"st":1}}
{"schema_version":"1.3.0","event_id":"764f4148-3077-48ad-bbc6-5ab007501d92","event_type":"raw.depth_update","source":"binance_market_data_recorder","venue":"binance_usdm","market_type":"perpetual_futures","symbol":"BTCUSDT","event_time_ms":1783517077718,"received_time_ms":1783517077717,"trace_id":"4f223b26-503b-4f5e-85b1-a07183911683","first_update_id":10999771591796,"final_update_id":10999771597428,"previous_final_update_id":10999771591574,"bids":[{"price":"11454.10","quantity":"2.448"},{"price":"11554.10","quantity":"1.160"},{"price":"11654.10","quantity":"1.292"},{"price":"55668.60","quantity":"0.002"},{"price":"59379.90","quantity":"0.003"},{"price":"61015.90","quantity":"0.817"},{"price":"61031.00","quantity":"0.003"},{"price":"61050.00","quantity":"5.672"},{"price":"61235.60","quantity":"0.328"},{"price":"61583.10","quantity":"10.354"},{"price":"61723.70","quantity":"0.000"},{"price":"61744.50","quantity":"4.042"},{"price":"61745.70","quantity":"1.841"},{"price":"61754.80","quantity":"2.642"},{"price":"61786.30","quantity":"0.051"},{"price":"61787.20","quantity":"0.002"},{"price":"61789.00","quantity":"6.173"},{"price":"61805.00","quantity":"2.080"},{"price":"61806.10","quantity":"4.541"},{"price":"61821.00","quantity":"0.284"},{"price":"61821.90","quantity":"0.438"},{"price":"61829.50","quantity":"1.282"},{"price":"61854.10","quantity":"17.493"}],"asks":[{"price":"61854.20","quantity":"3.104"},{"price":"61858.00","quantity":"0.076"},{"price":"61859.50","quantity":"0.019"},{"price":"61870.20","quantity":"0.012"},{"price":"61872.80","quantity":"0.000"},{"price":"61893.40","quantity":"0.243"},{"price":"61897.80","quantity":"4.513"},{"price":"61898.40","quantity":"1.367"},{"price":"61909.50","quantity":"2.896"},{"price":"61919.90","quantity":"6.684"},{"price":"61922.40","quantity":"0.256"},{"price":"61923.30","quantity":"0.047"},{"price":"61926.90","quantity":"0.021"},{"price":"61985.10","quantity":"0.000"},{"price":"61993.90","quantity":"6.014"},{"price":"61994.00","quantity":"0.001"},{"price":"62127.10","quantity":"10.804"},{"price":"62127.70","quantity":"0.002"},{"price":"62472.70","quantity":"1.678"},{"price":"62619.70","quantity":"4.295"},{"price":"62720.20","quantity":"2.668"},{"price":"62780.10","quantity":"0.003"},{"price":"63091.20","quantity":"0.080"},{"price":"65848.10","quantity":"0.004"}],"raw":{"e":"depthUpdate","E":1783517077718,"T":1783517077717,"s":"BTCUSDT","ps":"BTCUSDT","U":10999771591796,"u":10999771597428,"pu":10999771591574,"b":[["11454.10","2.448"],["11554.10","1.160"],["11654.10","1.292"],["55668.60","0.002"],["59379.90","0.003"],["61015.90","0.817"],["61031.00","0.003"],["61050.00","5.672"],["61235.60","0.328"],["61583.10","10.354"],["61723.70","0.000"],["61744.50","4.042"],["61745.70","1.841"],["61754.80","2.642"],["61786.30","0.051"],["61787.20","0.002"],["61789.00","6.173"],["61805.00","2.080"],["61806.10","4.541"],["61821.00","0.284"],["61821.90","0.438"],["61829.50","1.282"],["61854.10","17.493"]],"a":[["61854.20","3.104"],["61858.00","0.076"],["61859.50","0.019"],["61870.20","0.012"],["61872.80","0.000"],["61893.40","0.243"],["61897.80","4.513"],["61898.40","1.367"],["61909.50","2.896"],["61919.90","6.684"],["61922.40","0.256"],["61923.30","0.047"],["61926.90","0.021"],["61985.10","0.000"],["61993.90","6.014"],["61994.00","0.001"],["62127.10","10.804"],["62127.70","0.002"],["62472.70","1.678"],["62619.70","4.295"],["62720.20","2.668"],["62780.10","0.003"],["63091.20","0.080"],["65848.10","0.004"]],"st":1}}
{"schema_version":"1.3.0","event_id":"563823cd-d263-4aef-9b5a-60092d472b23","event_type":"raw.depth_update","source":"binance_market_data_recorder","venue":"binance_usdm","market_type":"perpetual_futures","symbol":"BTCUSDT","event_time_ms":1783517077820,"received_time_ms":1783517077817,"trace_id":"12ff5fa4-23b0-4a1c-b9d5-3992b7c779e0","first_update_id":10999771597766,"final_update_id":10999771606958,"previous_final_update_id":10999771597428,"bids":[{"price":"1000.00","quantity":"207.692"},{"price":"11454.10","quantity":"2.720"},{"price":"11554.10","quantity":"1.024"},{"price":"11654.10","quantity":"1.156"},{"price":"49483.30","quantity":"0.000"},{"price":"55668.60","quantity":"0.002"},{"price":"59379.90","quantity":"0.000"},{"price":"60842.90","quantity":"0.197"},{"price":"60921.30","quantity":"0.068"},{"price":"61235.60","quantity":"0.328"},{"price":"61359.30","quantity":"1.372"},{"price":"61527.70","quantity":"0.003"},{"price":"61544.80","quantity":"0.039"},{"price":"61702.20","quantity":"0.580"},{"price":"61723.70","quantity":"0.226"},{"price":"61795.50","quantity":"0.001"},{"price":"61795.70","quantity":"0.073"},{"price":"61850.00","quantity":"1.956"},{"price":"61854.10","quantity":"17.493"}],"asks":[{"price":"61854.20","quantity":"2.863"},{"price":"61854.90","quantity":"0.287"},{"price":"61857.10","quantity":"0.001"},{"price":"61859.90","quantity":"0.000"},{"price":"61860.30","quantity":"0.002"},{"price":"61863.80","quantity":"0.001"},{"price":"61865.90","quantity":"0.586"},{"price":"61866.50","quantity":"0.570"},{"price":"61878.90","quantity":"0.184"},{"price":"61897.50","quantity":"0.451"},{"price":"61909.80","quantity":"0.101"},{"price":"61919.90","quantity":"3.755"},{"price":"61920.50","quantity":"0.000"},{"price":"61926.80","quantity":"25.933"},{"price":"61926.90","quantity":"0.021"},{"price":"61985.10","quantity":"0.642"},{"price":"61993.80","quantity":"1.852"},{"price":"61993.90","quantity":"4.329"},{"price":"62006.60","quantity":"1.040"},{"price":"62006.80","quantity":"0.010"},{"price":"62472.70","quantity":"1.678"},{"price":"62943.20","quantity":"0.800"},{"price":"89523.20","quantity":"1.044"}],"raw":{"e":"depthUpdate","E":1783517077820,"T":1783517077818,"s":"BTCUSDT","ps":"BTCUSDT","U":10999771597766,"u":10999771606958,"pu":10999771597428,"b":[["1000.00","207.692"],["11454.10","2.720"],["11554.10","1.024"],["11654.10","1.156"],["49483.30","0.000"],["55668.60","0.002"],["59379.90","0.000"],["60842.90","0.197"],["60921.30","0.068"],["61235.60","0.328"],["61359.30","1.372"],["61527.70","0.003"],["61544.80","0.039"],["61702.20","0.580"],["61723.70","0.226"],["61795.50","0.001"],["61795.70","0.073"],["61850.00","1.956"],["61854.10","17.493"]],"a":[["61854.20","2.863"],["61854.90","0.287"],["61857.10","0.001"],["61859.90","0.000"],["61860.30","0.002"],["61863.80","0.001"],["61865.90","0.586"],["61866.50","0.570"],["61878.90","0.184"],["61897.50","0.451"],["61909.80","0.101"],["61919.90","3.755"],["61920.50","0.000"],["61926.80","25.933"],["61926.90","0.021"],["61985.10","0.642"],["61993.80","1.852"],["61993.90","4.329"],["62006.60","1.040"],["62006.80","0.010"],["62472.70","1.678"],["62943.20","0.800"],["89523.20","1.044"]],"st":1}}
{"schema_version":"1.3.0","event_id":"c0d748b5-6ec0-4ee5-9ae8-6584fb15d981","event_type":"raw.depth_update","source":"binance_market_data_recorder","venue":"binance_usdm","market_type":"perpetual_futures","symbol":"BTCUSDT","event_time_ms":1783517077922,"received_time_ms":1783517077917,"trace_id":"f10f6261-027e-4440-ad2a-6d6f885948b6","first_update_id":10999771607095,"final_update_id":10999771614337,"previous_final_update_id":10999771606958,"bids":[{"price":"1000.00","quantity":"207.692"},{"price":"11354.10","quantity":"0.128"},{"price":"11454.10","quantity":"2.736"},{"price":"11554.10","quantity":"1.033"},{"price":"11654.10","quantity":"1.003"},{"price":"55668.60","quantity":"0.002"},{"price":"61235.60","quantity":"0.328"},{"price":"61359.30","quantity":"1.368"},{"price":"61537.60","quantity":"0.348"},{"price":"61813.40","quantity":"0.062"},{"price":"61813.80","quantity":"0.115"},{"price":"61813.90","quantity":"0.104"},{"price":"61814.20","quantity":"0.277"},{"price":"61820.70","quantity":"0.616"},{"price":"61821.20","quantity":"0.101"},{"price":"61821.90","quantity":"0.912"},{"price":"61822.00","quantity":"0.437"},{"price":"61829.50","quantity":"1.202"},{"price":"61833.10","quantity":"0.405"},{"price":"61835.90","quantity":"1.056"},{"price":"61836.00","quantity":"0.066"},{"price":"61836.10","quantity":"0.053"},{"price":"61838.70","quantity":"1.123"},{"price":"61854.00","quantity":"0.333"},{"price":"61854.10","quantity":"17.495"}],"asks":[{"price":"61854.20","quantity":"1.666"},{"price":"61854.30","quantity":"0.034"},{"price":"61856.40","quantity":"0.078"},{"price":"61856.50","quantity":"0.013"},{"price":"61863.10","quantity":"0.000"},{"price":"61863.30","quantity":"0.813"},{"price":"61864.10","quantity":"0.968"},{"price":"61872.80","quantity":"0.128"},{"price":"61874.20","quantity":"0.002"},{"price":"61882.00","quantity":"3.590"},{"price":"61891.30","quantity":"0.330"},{"price":"61893.50","quantity":"0.580"},{"price":"61897.50","quantity":"0.296"},{"price":"61909.80","quantity":"0.000"},{"price":"61909.90","quantity":"0.221"},{"price":"61919.10","quantity":"0.186"},{"price":"61920.50","quantity":"25.042"},{"price":"61924.70","quantity":"0.000"},{"price":"61926.80","quantity":"0.891"},{"price":"61926.90","quantity":"0.021"},{"price":"62472.70","quantity":"1.678"},{"price":"62732.30","quantity":"0.955"},{"price":"63132.60","quantity":"0.699"}],"raw":{"e":"depthUpdate","E":1783517077922,"T":1783517077921,"s":"BTCUSDT","ps":"BTCUSDT","U":10999771607095,"u":10999771614337,"pu":10999771606958,"b":[["1000.00","207.692"],["11354.10","0.128"],["11454.10","2.736"],["11554.10","1.033"],["11654.10","1.003"],["55668.60","0.002"],["61235.60","0.328"],["61359.30","1.368"],["61537.60","0.348"],["61813.40","0.062"],["61813.80","0.115"],["61813.90","0.104"],["61814.20","0.277"],["61820.70","0.616"],["61821.20","0.101"],["61821.90","0.912"],["61822.00","0.437"],["61829.50","1.202"],["61833.10","0.405"],["61835.90","1.056"],["61836.00","0.066"],["61836.10","0.053"],["61838.70","1.123"],["61854.00","0.333"],["61854.10","17.495"]],"a":[["61854.20","1.666"],["61854.30","0.034"],["61856.40","0.078"],["61856.50","0.013"],["61863.10","0.000"],["61863.30","0.813"],["61864.10","0.968"],["61872.80","0.128"],["61874.20","0.002"],["61882.00","3.590"],["61891.30","0.330"],["61893.50","0.580"],["61897.50","0.296"],["61909.80","0.000"],["61909.90","0.221"],["61919.10","0.186"],["61920.50","25.042"],["61924.70","0.000"],["61926.80","0.891"],["61926.90","0.021"],["62472.70","1.678"],["62732.30","0.955"],["63132.60","0.699"]],"st":1}}
{"schema_version":"1.3.0","event_id":"66a7d3b9-5a09-4301-9a91-17d6dff2a274","event_type":"raw.depth_update","source":"binance_market_data_recorder","venue":"binance_usdm","market_type":"perpetual_futures","symbol":"BTCUSDT","event_time_ms":1783517078024,"received_time_ms":1783517078055,"trace_id":"57a88176-c40f-4071-b38d-dd3b70330047","first_update_id":10999771614517,"final_update_id":10999771625137,"previous_final_update_id":10999771614337,"bids":[{"price":"11354.10","quantity":"0.272"},{"price":"11454.10","quantity":"2.720"},{"price":"11554.10","quantity":"1.041"},{"price":"11654.10","quantity":"0.867"},{"price":"55668.60","quantity":"0.002"},{"price":"59379.90","quantity":"0.003"},{"price":"60864.40","quantity":"1.970"},{"price":"60926.20","quantity":"0.396"},{"price":"61235.60","quantity":"0.328"},{"price":"61723.70","quantity":"0.000"},{"price":"61798.60","quantity":"0.026"},{"price":"61806.50","quantity":"0.774"},{"price":"61825.80","quantity":"0.008"},{"price":"61827.20","quantity":"0.001"},{"price":"61827.80","quantity":"0.868"},{"price":"61829.00","quantity":"0.731"},{"price":"61840.50","quantity":"2.138"},{"price":"61848.40","quantity":"0.062"}],"asks":[{"price":"61854.20","quantity":"1.521"},{"price":"61854.30","quantity":"0.034"},{"price":"61856.40","quantity":"0.029"},{"price":"61860.40","quantity":"0.600"},{"price":"61866.60","quantity":"3.978"},{"price":"61868.70","quantity":"0.098"},{"price":"61869.80","quantity":"0.130"},{"price":"61870.40","quantity":"0.040"},{"price":"61871.60","quantity":"0.005"},{"price":"61872.80","quantity":"0.132"},{"price":"61891.30","quantity":"0.202"},{"price":"61926.90","quantity":"0.021"},{"price":"61985.10","quantity":"0.000"},{"price":"62472.70","quantity":"1.678"},{"price":"62685.20","quantity":"0.000"},{"price":"62782.00","quantity":"1.233"},{"price":"65874.70","quantity":"0.040"},{"price":"89523.20","quantity":"1.050"}],"raw":{"e":"depthUpdate","E":1783517078024,"T":1783517078021,"s":"BTCUSDT","ps":"BTCUSDT","U":10999771614517,"u":10999771625137,"pu":10999771614337,"b":[["11354.10","0.272"],["11454.10","2.720"],["11554.10","1.041"],["11654.10","0.867"],["55668.60","0.002"],["59379.90","0.003"],["60864.40","1.970"],["60926.20","0.396"],["61235.60","0.328"],["61723.70","0.000"],["61798.60","0.026"],["61806.50","0.774"],["61825.80","0.008"],["61827.20","0.001"],["61827.80","0.868"],["61829.00","0.731"],["61840.50","2.138"],["61848.40","0.062"]],"a":[["61854.20","1.521"],["61854.30","0.034"],["61856.40","0.029"],["61860.40","0.600"],["61866.60","3.978"],["61868.70","0.098"],["61869.80","0.130"],["61870.40","0.040"],["61871.60","0.005"],["61872.80","0.132"],["61891.30","0.202"],["61926.90","0.021"],["61985.10","0.000"],["62472.70","1.678"],["62685.20","0.000"],["62782.00","1.233"],["65874.70","0.040"],["89523.20","1.050"]],"st":1}}
{"schema_version":"1.3.0","event_id":"e26f04d7-30ab-40d0-96af-40b4ccac3f76","event_type":"raw.depth_update","source":"binance_market_data_recorder","venue":"binance_usdm","market_type":"perpetual_futures","symbol":"BTCUSDT","event_time_ms":1783517078126,"received_time_ms":1783517078126,"trace_id":"62dcb98c-fbdf-41c5-b330-ef10c6d0045c","first_update_id":10999771625442,"final_update_id":10999771633699,"previous_final_update_id":10999771625137,"bids":[{"price":"1000.00","quantity":"207.692"},{"price":"11354.10","quantity":"0.400"},{"price":"11454.10","quantity":"2.736"},{"price":"11554.10","quantity":"1.050"},{"price":"11654.10","quantity":"0.714"},{"price":"55668.60","quantity":"0.002"},{"price":"58761.50","quantity":"0.000"},{"price":"59379.90","quantity":"0.000"},{"price":"59888.00","quantity":"5.528"},{"price":"61235.60","quantity":"0.328"},{"price":"61544.80","quantity":"0.029"},{"price":"61723.70","quantity":"0.279"},{"price":"61751.20","quantity":"0.058"},{"price":"61751.30","quantity":"0.069"},{"price":"61823.30","quantity":"2.021"},{"price":"61826.80","quantity":"0.012"},{"price":"61830.50","quantity":"0.000"},{"price":"61831.80","quantity":"0.082"},{"price":"61831.90","quantity":"0.009"},{"price":"61833.10","quantity":"0.325"},{"price":"61839.10","quantity":"0.004"},{"price":"61840.30","quantity":"0.000"},{"price":"61840.50","quantity":"2.140"},{"price":"61843.00","quantity":"0.127"},{"price":"61854.10","quantity":"17.492"}],"asks":[{"price":"61854.20","quantity":"1.526"},{"price":"61855.20","quantity":"0.008"},{"price":"61856.00","quantity":"0.052"},{"price":"61860.40","quantity":"0.724"},{"price":"61861.20","quantity":"0.000"},{"price":"61865.30","quantity":"0.327"},{"price":"61866.60","quantity":"3.974"},{"price":"61868.70","quantity":"0.081"},{"price":"61871.60","quantity":"0.007"},{"price":"61872.80","quantity":"0.000"},{"price":"61873.70","quantity":"0.007"},{"price":"61878.90","quantity":"0.056"},{"price":"61897.50","quantity":"0.168"},{"price":"61909.40","quantity":"0.266"},{"price":"61926.90","quantity":"0.021"},{"price":"61985.10","quantity":"0.727"},{"price":"62000.00","quantity":"13.281"},{"price":"62029.50","quantity":"0.000"},{"price":"62029.60","quantity":"0.016"},{"price":"62084.40","quantity":"0.021"},{"price":"62087.90","quantity":"0.000"},{"price":"62100.00","quantity":"3.202"},{"price":"62472.70","quantity":"1.680"},{"price":"62592.30","quantity":"5.642"}],"raw":{"e":"depthUpdate","E":1783517078126,"T":1783517078125,"s":"BTCUSDT","ps":"BTCUSDT","U":10999771625442,"u":10999771633699,"pu":10999771625137,"b":[["1000.00","207.692"],["11354.10","0.400"],["11454.10","2.736"],["11554.10","1.050"],["11654.10","0.714"],["55668.60","0.002"],["58761.50","0.000"],["59379.90","0.000"],["59888.00","5.528"],["61235.60","0.328"],["61544.80","0.029"],["61723.70","0.279"],["61751.20","0.058"],["61751.30","0.069"],["61823.30","2.021"],["61826.80","0.012"],["61830.50","0.000"],["61831.80","0.082"],["61831.90","0.009"],["61833.10","0.325"],["61839.10","0.004"],["61840.30","0.000"],["61840.50","2.140"],["61843.00","0.127"],["61854.10","17.492"]],"a":[["61854.20","1.526"],["61855.20","0.008"],["61856.00","0.052"],["61860.40","0.724"],["61861.20","0.000"],["61865.30","0.327"],["61866.60","3.974"],["61868.70","0.081"],["61871.60","0.007"],["61872.80","0.000"],["61873.70","0.007"],["61878.90","0.056"],["61897.50","0.168"],["61909.40","0.266"],["61926.90","0.021"],["61985.10","0.727"],["62000.00","13.281"],["62029.50","0.000"],["62029.60","0.016"],["62084.40","0.021"],["62087.90","0.000"],["62100.00","3.202"],["62472.70","1.680"],["62592.30","5.642"]],"st":1}}
{"schema_version":"1.3.0","event_id":"ad500402-dfb5-45c7-aa21-bedab080a3e0","event_type":"raw.depth_update","source":"binance_market_data_recorder","venue":"binance_usdm","market_type":"perpetual_futures","symbol":"BTCUSDT","event_time_ms":1783517078228,"received_time_ms":1783517078223,"trace_id":"ee5b885d-d1a0-4f59-863b-d6c5535eee36","first_update_id":10999771633754,"final_update_id":10999771641926,"previous_final_update_id":10999771633699,"bids":[{"price":"11354.10","quantity":"0.608"},{"price":"11454.10","quantity":"2.592"},{"price":"11554.10","quantity":"1.122"},{"price":"11654.10","quantity":"0.578"},{"price":"49483.00","quantity":"0.000"},{"price":"55668.60","quantity":"0.002"},{"price":"58761.40","quantity":"0.023"},{"price":"59379.90","quantity":"0.003"},{"price":"60833.50","quantity":"0.739"},{"price":"60933.60","quantity":"1.137"},{"price":"61019.10","quantity":"3.187"},{"price":"61235.60","quantity":"0.328"},{"price":"61250.00","quantity":"18.056"},{"price":"61385.20","quantity":"0.000"},{"price":"61795.20","quantity":"1.501"},{"price":"61795.70","quantity":"0.034"},{"price":"61813.80","quantity":"0.115"},{"price":"61813.90","quantity":"0.003"},{"price":"61814.20","quantity":"0.277"},{"price":"61814.40","quantity":"0.211"},{"price":"61829.50","quantity":"0.879"},{"price":"61831.00","quantity":"0.000"},{"price":"61831.80","quantity":"0.002"},{"price":"61833.70","quantity":"3.516"},{"price":"61835.20","quantity":"0.002"},{"price":"61837.50","quantity":"3.763"},{"price":"61851.50","quantity":"0.000"},{"price":"61852.10","quantity":"0.002"},{"price":"61853.90","quantity":"0.291"},{"price":"61854.10","quantity":"17.492"}],"asks":[{"price":"61854.20","quantity":"1.525"},{"price":"61860.40","quantity":"0.322"},{"price":"61861.00","quantity":"0.712"},{"price":"61866.60","quantity":"3.392"},{"price":"61867.10","quantity":"0.582"},{"price":"61870.10","quantity":"0.146"},{"price":"61873.20","quantity":"0.292"},{"price":"61926.90","quantity":"0.118"},{"price":"62472.70","quantity":"1.678"},{"price":"62664.20","quantity":"0.797"},{"price":"62732.50","quantity":"0.556"},{"price":"63095.60","quantity":"0.678"},{"price":"89523.20","quantity":"1.056"}],"raw":{"e":"depthUpdate","E":1783517078228,"T":1783517078227,"s":"BTCUSDT","ps":"BTCUSDT","U":10999771633754,"u":10999771641926,"pu":10999771633699,"b":[["11354.10","0.608"],["11454.10","2.592"],["11554.10","1.122"],["11654.10","0.578"],["49483.00","0.000"],["55668.60","0.002"],["58761.40","0.023"],["59379.90","0.003"],["60833.50","0.739"],["60933.60","1.137"],["61019.10","3.187"],["61235.60","0.328"],["61250.00","18.056"],["61385.20","0.000"],["61795.20","1.501"],["61795.70","0.034"],["61813.80","0.115"],["61813.90","0.003"],["61814.20","0.277"],["61814.40","0.211"],["61829.50","0.879"],["61831.00","0.000"],["61831.80","0.002"],["61833.70","3.516"],["61835.20","0.002"],["61837.50","3.763"],["61851.50","0.000"],["61852.10","0.002"],["61853.90","0.291"],["61854.10","17.492"]],"a":[["61854.20","1.525"],["61860.40","0.322"],["61861.00","0.712"],["61866.60","3.392"],["61867.10","0.582"],["61870.10","0.146"],["61873.20","0.292"],["61926.90","0.118"],["62472.70","1.678"],["62664.20","0.797"],["62732.50","0.556"],["63095.60","0.678"],["89523.20","1.056"]],"st":1}}
{"schema_version":"1.3.0","event_id":"1b9b5a1b-ae01-4f5d-a8e9-9e02c2a36d07","event_type":"raw.depth_update","source":"binance_market_data_recorder","venue":"binance_usdm","market_type":"perpetual_futures","symbol":"BTCUSDT","event_time_ms":1783517078330,"received_time_ms":1783517078367,"trace_id":"6b1eafb0-8dcd-4ba5-a1ad-7c81491fd7fa","first_update_id":10999771642090,"final_update_id":10999771652793,"previous_final_update_id":10999771641926,"bids":[{"price":"11354.10","quantity":"0.880"},{"price":"11454.10","quantity":"2.320"},{"price":"11554.10","quantity":"1.275"},{"price":"11654.10","quantity":"0.425"},{"price":"55668.60","quantity":"0.002"},{"price":"58548.30","quantity":"0.000"},{"price":"58759.60","quantity":"0.000"},{"price":"60617.10","quantity":"0.036"},{"price":"61153.10","quantity":"0.000"},{"price":"61235.60","quantity":"0.328"},{"price":"61544.80","quantity":"0.039"},{"price":"61585.90","quantity":"0.000"},{"price":"61586.00","quantity":"0.060"},{"price":"61788.40","quantity":"0.002"},{"price":"61789.00","quantity":"1.484"},{"price":"61797.10","quantity":"0.336"},{"price":"61806.00","quantity":"0.043"},{"price":"61806.50","quantity":"0.564"},{"price":"61806.70","quantity":"0.013"},{"price":"61808.90","quantity":"0.110"},{"price":"61809.90","quantity":"0.101"},{"price":"61810.30","quantity":"1.692"},{"price":"61812.80","quantity":"0.037"},{"price":"61814.10","quantity":"0.569"},{"price":"61814.70","quantity":"0.004"},{"price":"61816.50","quantity":"0.171"},{"price":"61817.50","quantity":"0.490"},{"price":"61818.40","quantity":"0.014"},{"price":"61819.80","quantity":"0.881"},{"price":"61820.50","quantity":"0.220"},{"price":"61821.00","quantity":"0.274"},{"price":"61821.10","quantity":"0.247"},{"price":"61822.80","quantity":"0.314"},{"price":"61823.20","quantity":"0.437"},{"price":"61823.80","quantity":"0.170"},{"price":"61823.90","quantity":"0.129"},{"price":"61824.50","quantity":"0.324"},{"price":"61824.60","quantity":"0.100"},{"price":"61825.10","quantity":"0.263"},{"price":"61825.80","quantity":"0.000"},{"price":"61825.90","quantity":"0.002"},{"price":"61826.10","quantity":"1.189"},{"price":"61826.30","quantity":"0.049"},{"price":"61827.00","quantity":"1.298"},{"price":"61827.10","quantity":"0.006"},{"price":"61827.70","quantity":"0.014"},{"price":"61827.80","quantity":"0.286"},{"price":"61828.10","quantity":"0.008"},{"price":"61828.30","quantity":"0.001"},{"price":"61829.00","quantity":"0.610"},{"price":"61829.10","quantity":"0.268"},{"price":"61829.20","quantity":"0.411"},{"price":"61829.70","quantity":"0.003"},{"price":"61830.10","quantity":"0.009"},{"price":"61830.30","quantity":"0.165"},{"price":"61830.40","quantity":"0.050"},{"price":"61830.80","quantity":"0.013"},{"price":"61830.90","quantity":"0.969"},{"price":"61831.90","quantity":"0.001"},{"price":"61832.20","quantity":"0.012"},{"price":"61832.80","quantity":"0.343"},{"price":"61832.90","quantity":"0.001"},{"price":"61833.00","quantity":"0.014"},{"price":"61833.20","quantity":"0.875"},{"price":"61833.70","quantity":"2.548"},{"price":"61834.00","quantity":"1.374"},{"price":"61834.20","quantity":"0.567"},{"price":"61834.70","quantity":"0.013"},{"price":"61834.80","quantity":"0.039"},{"price":"61835.00","quantity":"0.041"},{"price":"61835.30","quantity":"0.324"},{"price":"61836.10","quantity":"0.003"},{"price":"61836.60","quantity":"1.241"},{"price":"61836.70","quantity":"0.003"},{"price":"61837.20","quantity":"0.526"},{"price":"61837.50","quantity":"3.197"},{"price":"61838.00","quantity":"1.122"},{"price":"61838.10","quantity":"0.004"},{"price":"61838.20","quantity":"0.002"},{"price":"61838.60","quantity":"0.156"},{"price":"61839.80","quantity":"0.360"},{"price":"61840.20","quantity":"0.001"},{"price":"61840.60","quantity":"0.568"},{"price":"61840.70","quantity":"1.464"},{"price":"61840.80","quantity":"0.131"},{"price":"61841.10","quantity":"0.001"},{"price":"61841.30","quantity":"0.105"},{"price":"61841.40","quantity":"0.952"},{"price":"61841.50","quantity":"0.350"},{"price":"61841.70","quantity":"0.390"},{"price":"61841.80","quantity":"1.123"},{"price":"61841.90","quantity":"0.421"},{"price":"61842.00","quantity":"0.046"},{"price":"61842.20","quantity":"0.246"},{"price":"61842.30","quantity":"0.000"},{"price":"61842.50","quantity":"0.002"},{"price":"61842.70","quantity":"0.001"},{"price":"61842.90","quantity":"1.124"},{"price":"61843.10","quantity":"0.052"},{"price":"61843.30","quantity":"0.013"},{"price":"61843.60","quantity":"0.062"},{"price":"61843.80","quantity":"0.006"},{"price":"61843.90","quantity":"0.000"},{"price":"61844.20","quantity":"0.002"},{"price":"61845.00","quantity":"1.131"},{"price":"61845.10","quantity":"0.033"},{"price":"61845.20","quantity":"0.000"},{"price":"61845.80","quantity":"0.000"},{"price":"61845.90","quantity":"0.001"},{"price":"61846.20","quantity":"0.051"},{"price":"61846.60","quantity":"0.001"},{"price":"61846.80","quantity":"0.000"},{"price":"61846.90","quantity":"0.002"},{"price":"61847.70","quantity":"0.003"},{"price":"61847.90","quantity":"0.000"},{"price":"61848.00","quantity":"0.192"},{"price":"61848.80","quantity":"0.042"},{"price":"61849.10","quantity":"0.010"},{"price":"61850.00","quantity":"1.632"},{"price":"61850.10","quantity":"0.050"},{"price":"61850.30","quantity":"0.002"},{"price":"61850.60","quantity":"0.000"},{"price":"61851.00","quantity":"1.025"},{"price":"61851.10","quantity":"0.000"},{"price":"61851.30","quantity":"0.001"},{"price":"61851.50","quantity":"0.000"},{"price":"61851.60","quantity":"0.048"},{"price":"61851.90","quantity":"0.001"},{"price":"61852.10","quantity":"0.000"},{"price":"61853.90","quantity":"0.001"},{"price":"61854.00","quantity":"0.005"},{"price":"61854.10","quantity":"4.165"}],"asks":[{"price":"61854.20","quantity":"9.530"},{"price":"61854.30","quantity":"0.157"},{"price":"61854.40","quantity":"0.006"},{"price":"61854.50","quantity":"0.016"},{"price":"61854.70","quantity":"1.639"},{"price":"61854.80","quantity":"1.973"},{"price":"61854.90","quantity":"0.045"},{"price":"61855.10","quantity":"0.003"},{"price":"61855.90","quantity":"0.693"},{"price":"61856.50","quantity":"0.009"},{"price":"61856.80","quantity":"0.906"},{"price":"61856.90","quantity":"1.124"},{"price":"61857.00","quantity":"0.711"},{"price":"61857.30","quantity":"0.274"},{"price":"61858.00","quantity":"2.305"},{"price":"61858.10","quantity":"3.348"},{"price":"61858.20","quantity":"0.131"},{"price":"61858.30","quantity":"0.013"},{"price":"61858.60","quantity":"0.003"},{"price":"61858.70","quantity":"0.051"},{"price":"61859.20","quantity":"0.013"},{"price":"61859.40","quantity":"0.128"},{"price":"61859.50","quantity":"1.515"},{"price":"61859.60","quantity":"0.000"},{"price":"61859.70","quantity":"0.164"},{"price":"61859.80","quantity":"0.002"},{"price":"61860.30","quantity":"0.002"},{"price":"61860.40","quantity":"1.160"},{"price":"61860.70","quantity":"0.119"},{"price":"61860.80","quantity":"0.031"},{"price":"61861.30","quantity":"0.000"},{"price":"61861.50","quantity":"2.299"},{"price":"61861.90","quantity":"0.974"},{"price":"61862.10","quantity":"0.013"},{"price":"61862.20","quantity":"0.001"},{"price":"61862.30","quantity":"0.002"},{"price":"61862.60","quantity":"0.575"},{"price":"61862.80","quantity":"0.343"},{"price":"61863.20","quantity":"0.081"},{"price":"61863.30","quantity":"0.004"},{"price":"61863.40","quantity":"0.074"},{"price":"61863.50","quantity":"0.586"},{"price":"61863.80","quantity":"0.001"},{"price":"61863.90","quantity":"1.725"},{"price":"61864.00","quantity":"2.155"},{"price":"61864.10","quantity":"0.000"},{"price":"61864.90","quantity":"0.171"},{"price":"61865.00","quantity":"0.003"},{"price":"61865.60","quantity":"0.004"},{"price":"61865.70","quantity":"0.472"},{"price":"61865.80","quantity":"0.002"},{"price":"61866.50","quantity":"0.004"},{"price":"61866.70","quantity":"0.760"},{"price":"61866.90","quantity":"0.020"},{"price":"61867.10","quantity":"0.000"},{"price":"61867.90","quantity":"0.002"},{"price":"61868.40","quantity":"0.013"},{"price":"61869.50","quantity":"0.003"},{"price":"61869.80","quantity":"0.009"},{"price":"61870.60","quantity":"0.020"},{"price":"61872.30","quantity":"0.015"},{"price":"61872.90","quantity":"0.334"},{"price":"61873.50","quantity":"0.001"},{"price":"61874.10","quantity":"0.823"},{"price":"61874.20","quantity":"0.000"},{"price":"61874.80","quantity":"0.362"},{"price":"61875.20","quantity":"0.320"},{"price":"61876.70","quantity":"0.035"},{"price":"61876.90","quantity":"0.652"},{"price":"61877.40","quantity":"0.003"},{"price":"61877.50","quantity":"0.000"},{"price":"61877.90","quantity":"0.264"},{"price":"61878.60","quantity":"1.024"},{"price":"61879.00","quantity":"0.717"},{"price":"61881.10","quantity":"0.010"},{"price":"61881.30","quantity":"0.681"},{"price":"61881.80","quantity":"0.029"},{"price":"61882.30","quantity":"0.799"},{"price":"61882.90","quantity":"0.017"},{"price":"61883.00","quantity":"0.092"},{"price":"61885.20","quantity":"0.004"},{"price":"61886.80","quantity":"3.536"},{"price":"61887.60","quantity":"0.336"},{"price":"61887.70","quantity":"0.140"},{"price":"61888.10","quantity":"0.120"},{"price":"61888.80","quantity":"0.175"},{"price":"61889.10","quantity":"0.095"},{"price":"61890.20","quantity":"0.012"},{"price":"61893.40","quantity":"0.507"},{"price":"61893.80","quantity":"2.459"},{"price":"61894.40","quantity":"0.574"},{"price":"61895.30","quantity":"0.000"},{"price":"61895.80","quantity":"0.030"},{"price":"61897.20","quantity":"0.001"},{"price":"61898.00","quantity":"0.006"},{"price":"61899.30","quantity":"0.485"},{"price":"61899.90","quantity":"0.015"},{"price":"61901.50","quantity":"1.276"},{"price":"61904.80","quantity":"0.487"},{"price":"61905.40","quantity":"0.029"},{"price":"61905.90","quantity":"0.003"},{"price":"61907.70","quantity":"0.401"},{"price":"61908.60","quantity":"0.012"},{"price":"61909.40","quantity":"0.002"},{"price":"61909.50","quantity":"2.795"},{"price":"61909.90","quantity":"0.120"},{"price":"61910.10","quantity":"0.036"},{"price":"61911.50","quantity":"0.002"},{"price":"61912.10","quantity":"0.031"},{"price":"61912.90","quantity":"0.248"},{"price":"61919.80","quantity":"0.006"},{"price":"61920.50","quantity":"0.000"},{"price":"61926.80","quantity":"25.763"},{"price":"61926.90","quantity":"0.118"},{"price":"61928.00","quantity":"0.000"},{"price":"61929.00","quantity":"1.359"},{"price":"61958.30","quantity":"0.747"},{"price":"61977.20","quantity":"0.027"},{"price":"61990.30","quantity":"0.310"},{"price":"62472.70","quantity":"1.678"},{"price":"62654.50","quantity":"0.638"},{"price":"63091.20","quantity":"0.083"}],"raw":{"e":"depthUpdate","E":1783517078330,"T":1783517078329,"s":"BTCUSDT","ps":"BTCUSDT","U":10999771642090,"u":10999771652793,"pu":10999771641926,"b":[["11354.10","0.880"],["11454.10","2.320"],["11554.10","1.275"],["11654.10","0.425"],["55668.60","0.002"],["58548.30","0.000"],["58759.60","0.000"],["60617.10","0.036"],["61153.10","0.000"],["61235.60","0.328"],["61544.80","0.039"],["61585.90","0.000"],["61586.00","0.060"],["61788.40","0.002"],["61789.00","1.484"],["61797.10","0.336"],["61806.00","0.043"],["61806.50","0.564"],["61806.70","0.013"],["61808.90","0.110"],["61809.90","0.101"],["61810.30","1.692"],["61812.80","0.037"],["61814.10","0.569"],["61814.70","0.004"],["61816.50","0.171"],["61817.50","0.490"],["61818.40","0.014"],["61819.80","0.881"],["61820.50","0.220"],["61821.00","0.274"],["61821.10","0.247"],["61822.80","0.314"],["61823.20","0.437"],["61823.80","0.170"],["61823.90","0.129"],["61824.50","0.324"],["61824.60","0.100"],["61825.10","0.263"],["61825.80","0.000"],["61825.90","0.002"],["61826.10","1.189"],["61826.30","0.049"],["61827.00","1.298"],["61827.10","0.006"],["61827.70","0.014"],["61827.80","0.286"],["61828.10","0.008"],["61828.30","0.001"],["61829.00","0.610"],["61829.10","0.268"],["61829.20","0.411"],["61829.70","0.003"],["61830.10","0.009"],["61830.30","0.165"],["61830.40","0.050"],["61830.80","0.013"],["61830.90","0.969"],["61831.90","0.001"],["61832.20","0.012"],["61832.80","0.343"],["61832.90","0.001"],["61833.00","0.014"],["61833.20","0.875"],["61833.70","2.548"],["61834.00","1.374"],["61834.20","0.567"],["61834.70","0.013"],["61834.80","0.039"],["61835.00","0.041"],["61835.30","0.324"],["61836.10","0.003"],["61836.60","1.241"],["61836.70","0.003"],["61837.20","0.526"],["61837.50","3.197"],["61838.00","1.122"],["61838.10","0.004"],["61838.20","0.002"],["61838.60","0.156"],["61839.80","0.360"],["61840.20","0.001"],["61840.60","0.568"],["61840.70","1.464"],["61840.80","0.131"],["61841.10","0.001"],["61841.30","0.105"],["61841.40","0.952"],["61841.50","0.350"],["61841.70","0.390"],["61841.80","1.123"],["61841.90","0.421"],["61842.00","0.046"],["61842.20","0.246"],["61842.30","0.000"],["61842.50","0.002"],["61842.70","0.001"],["61842.90","1.124"],["61843.10","0.052"],["61843.30","0.013"],["61843.60","0.062"],["61843.80","0.006"],["61843.90","0.000"],["61844.20","0.002"],["61845.00","1.131"],["61845.10","0.033"],["61845.20","0.000"],["61845.80","0.000"],["61845.90","0.001"],["61846.20","0.051"],["61846.60","0.001"],["61846.80","0.000"],["61846.90","0.002"],["61847.70","0.003"],["61847.90","0.000"],["61848.00","0.192"],["61848.80","0.042"],["61849.10","0.010"],["61850.00","1.632"],["61850.10","0.050"],["61850.30","0.002"],["61850.60","0.000"],["61851.00","1.025"],["61851.10","0.000"],["61851.30","0.001"],["61851.50","0.000"],["61851.60","0.048"],["61851.90","0.001"],["61852.10","0.000"],["61853.90","0.001"],["61854.00","0.005"],["61854.10","4.165"]],"a":[["61854.20","9.530"],["61854.30","0.157"],["61854.40","0.006"],["61854.50","0.016"],["61854.70","1.639"],["61854.80","1.973"],["61854.90","0.045"],["61855.10","0.003"],["61855.90","0.693"],["61856.50","0.009"],["61856.80","0.906"],["61856.90","1.124"],["61857.00","0.711"],["61857.30","0.274"],["61858.00","2.305"],["61858.10","3.348"],["61858.20","0.131"],["61858.30","0.013"],["61858.60","0.003"],["61858.70","0.051"],["61859.20","0.013"],["61859.40","0.128"],["61859.50","1.515"],["61859.60","0.000"],["61859.70","0.164"],["61859.80","0.002"],["61860.30","0.002"],["61860.40","1.160"],["61860.70","0.119"],["61860.80","0.031"],["61861.30","0.000"],["61861.50","2.299"],["61861.90","0.974"],["61862.10","0.013"],["61862.20","0.001"],["61862.30","0.002"],["61862.60","0.575"],["61862.80","0.343"],["61863.20","0.081"],["61863.30","0.004"],["61863.40","0.074"],["61863.50","0.586"],["61863.80","0.001"],["61863.90","1.725"],["61864.00","2.155"],["61864.10","0.000"],["61864.90","0.171"],["61865.00","0.003"],["61865.60","0.004"],["61865.70","0.472"],["61865.80","0.002"],["61866.50","0.004"],["61866.70","0.760"],["61866.90","0.020"],["61867.10","0.000"],["61867.90","0.002"],["61868.40","0.013"],["61869.50","0.003"],["61869.80","0.009"],["61870.60","0.020"],["61872.30","0.015"],["61872.90","0.334"],["61873.50","0.001"],["61874.10","0.823"],["61874.20","0.000"],["61874.80","0.362"],["61875.20","0.320"],["61876.70","0.035"],["61876.90","0.652"],["61877.40","0.003"],["61877.50","0.000"],["61877.90","0.264"],["61878.60","1.024"],["61879.00","0.717"],["61881.10","0.010"],["61881.30","0.681"],["61881.80","0.029"],["61882.30","0.799"],["61882.90","0.017"],["61883.00","0.092"],["61885.20","0.004"],["61886.80","3.536"],["61887.60","0.336"],["61887.70","0.140"],["61888.10","0.120"],["61888.80","0.175"],["61889.10","0.095"],["61890.20","0.012"],["61893.40","0.507"],["61893.80","2.459"],["61894.40","0.574"],["61895.30","0.000"],["61895.80","0.030"],["61897.20","0.001"],["61898.00","0.006"],["61899.30","0.485"],["61899.90","0.015"],["61901.50","1.276"],["61904.80","0.487"],["61905.40","0.029"],["61905.90","0.003"],["61907.70","0.401"],["61908.60","0.012"],["61909.40","0.002"],["61909.50","2.795"],["61909.90","0.120"],["61910.10","0.036"],["61911.50","0.002"],["61912.10","0.031"],["61912.90","0.248"],["61919.80","0.006"],["61920.50","0.000"],["61926.80","25.763"],["61926.90","0.118"],["61928.00","0.000"],["61929.00","1.359"],["61958.30","0.747"],["61977.20","0.027"],["61990.30","0.310"],["62472.70","1.678"],["62654.50","0.638"],["63091.20","0.083"]],"st":1}}
{"schema_version":"1.3.0","event_id":"79f402bb-9a70-4e35-8c92-374f13e47434","event_type":"raw.depth_update","source":"binance_market_data_recorder","venue":"binance_usdm","market_type":"perpetual_futures","symbol":"BTCUSDT","event_time_ms":1783517078432,"received_time_ms":1783517078427,"trace_id":"a65e6b5c-9f05-41de-8768-18499193f395","first_update_id":10999771652824,"final_update_id":10999771660474,"previous_final_update_id":10999771652793,"bids":[{"price":"1000.00","quantity":"207.692"},{"price":"11354.10","quantity":"1.152"},{"price":"11454.10","quantity":"2.048"},{"price":"11554.10","quantity":"1.411"},{"price":"11654.10","quantity":"0.289"},{"price":"55668.60","quantity":"0.002"},{"price":"59379.90","quantity":"0.000"},{"price":"60957.20","quantity":"2.133"},{"price":"60980.00","quantity":"3.238"},{"price":"60984.10","quantity":"8.317"},{"price":"61080.90","quantity":"4.427"},{"price":"61235.60","quantity":"0.328"},{"price":"61388.70","quantity":"0.163"},{"price":"61463.40","quantity":"0.274"},{"price":"61482.30","quantity":"0.005"},{"price":"61537.60","quantity":"0.348"},{"price":"61544.80","quantity":"0.040"},{"price":"61597.90","quantity":"0.877"},{"price":"61609.20","quantity":"0.324"},{"price":"61735.90","quantity":"0.000"},{"price":"61760.30","quantity":"0.158"},{"price":"61765.30","quantity":"33.106"},{"price":"61767.40","quantity":"0.000"},{"price":"61778.90","quantity":"0.882"},{"price":"61785.90","quantity":"0.223"},{"price":"61786.20","quantity":"0.000"},{"price":"61786.50","quantity":"0.022"},{"price":"61786.80","quantity":"0.000"},{"price":"61787.00","quantity":"0.190"},{"price":"61805.30","quantity":"1.313"},{"price":"61805.60","quantity":"0.338"},{"price":"61805.90","quantity":"0.002"},{"price":"61806.10","quantity":"4.509"},{"price":"61806.30","quantity":"0.050"},{"price":"61806.40","quantity":"0.001"},{"price":"61806.80","quantity":"1.258"},{"price":"61820.10","quantity":"10.663"},{"price":"61820.20","quantity":"0.134"},{"price":"61820.30","quantity":"0.467"},{"price":"61820.40","quantity":"0.621"},{"price":"61820.80","quantity":"0.050"},{"price":"61821.40","quantity":"0.004"},{"price":"61821.90","quantity":"0.790"},{"price":"61822.10","quantity":"0.003"},{"price":"61822.40","quantity":"0.448"},{"price":"61822.80","quantity":"0.435"},{"price":"61822.90","quantity":"0.005"},{"price":"61823.20","quantity":"0.591"},{"price":"61823.40","quantity":"0.009"},{"price":"61823.90","quantity":"0.008"},{"price":"61824.40","quantity":"0.583"},{"price":"61824.60","quantity":"0.005"},{"price":"61824.70","quantity":"0.001"},{"price":"61825.50","quantity":"0.097"},{"price":"61828.30","quantity":"0.009"},{"price":"61828.40","quantity":"0.968"},{"price":"61828.60","quantity":"0.553"},{"price":"61829.30","quantity":"0.052"},{"price":"61829.40","quantity":"2.288"},{"price":"61829.60","quantity":"0.039"},{"price":"61830.10","quantity":"0.001"},{"price":"61830.90","quantity":"0.001"},{"price":"61831.50","quantity":"0.935"},{"price":"61831.60","quantity":"0.608"},{"price":"61833.00","quantity":"0.034"},{"price":"61833.50","quantity":"0.000"},{"price":"61834.20","quantity":"0.001"},{"price":"61834.80","quantity":"0.019"},{"price":"61837.30","quantity":"0.805"},{"price":"61838.10","quantity":"0.327"},{"price":"61840.60","quantity":"0.566"},{"price":"61840.70","quantity":"1.125"},{"price":"61840.80","quantity":"0.024"},{"price":"61841.20","quantity":"0.326"},{"price":"61841.40","quantity":"0.928"},{"price":"61841.90","quantity":"0.420"},{"price":"61842.00","quantity":"0.046"},{"price":"61842.20","quantity":"0.266"},{"price":"61842.50","quantity":"0.325"},{"price":"61842.80","quantity":"0.002"},{"price":"61843.00","quantity":"2.262"},{"price":"61843.10","quantity":"1.017"},{"price":"61843.20","quantity":"0.068"},{"price":"61843.40","quantity":"0.002"},{"price":"61843.50","quantity":"0.002"},{"price":"61843.60","quantity":"0.002"},{"price":"61843.70","quantity":"0.003"},{"price":"61843.90","quantity":"0.060"},{"price":"61844.00","quantity":"0.001"},{"price":"61844.10","quantity":"0.060"},{"price":"61844.20","quantity":"0.001"},{"price":"61844.30","quantity":"0.002"},{"price":"61844.40","quantity":"0.169"},{"price":"61844.50","quantity":"0.003"},{"price":"61844.60","quantity":"0.128"},{"price":"61844.70","quantity":"0.002"},{"price":"61844.80","quantity":"0.017"},{"price":"61844.90","quantity":"0.931"},{"price":"61845.00","quantity":"1.163"},{"price":"61845.10","quantity":"0.001"},{"price":"61845.20","quantity":"0.000"},{"price":"61845.50","quantity":"0.033"},{"price":"61845.70","quantity":"1.122"},{"price":"61845.80","quantity":"0.000"},{"price":"61845.90","quantity":"0.131"},{"price":"61846.30","quantity":"0.005"},{"price":"61846.50","quantity":"0.010"},{"price":"61847.10","quantity":"1.123"},{"price":"61848.00","quantity":"0.745"},{"price":"61848.90","quantity":"0.006"},{"price":"61850.10","quantity":"0.050"},{"price":"61850.30","quantity":"0.051"},{"price":"61853.80","quantity":"0.006"},{"price":"61853.90","quantity":"0.002"},{"price":"61854.00","quantity":"0.004"},{"price":"61854.10","quantity":"4.123"}],"asks":[{"price":"61854.20","quantity":"8.955"},{"price":"61854.30","quantity":"1.651"},{"price":"61854.40","quantity":"0.006"},{"price":"61854.50","quantity":"0.016"},{"price":"61854.60","quantity":"0.003"},{"price":"61854.70","quantity":"0.023"},{"price":"61854.80","quantity":"0.622"},{"price":"61855.20","quantity":"0.067"},{"price":"61855.80","quantity":"0.030"},{"price":"61856.40","quantity":"0.005"},{"price":"61856.70","quantity":"0.001"},{"price":"61856.80","quantity":"0.001"},{"price":"61856.90","quantity":"0.002"},{"price":"61857.00","quantity":"0.751"},{"price":"61857.30","quantity":"0.276"},{"price":"61857.40","quantity":"0.005"},{"price":"61857.60","quantity":"0.014"},{"price":"61857.90","quantity":"0.905"},{"price":"61858.00","quantity":"1.404"},{"price":"61858.10","quantity":"2.226"},{"price":"61858.60","quantity":"0.001"},{"price":"61859.50","quantity":"1.505"},{"price":"61859.60","quantity":"0.000"},{"price":"61859.70","quantity":"0.001"},{"price":"61859.80","quantity":"0.165"},{"price":"61859.90","quantity":"0.180"},{"price":"61860.10","quantity":"0.005"},{"price":"61860.40","quantity":"0.856"},{"price":"61860.50","quantity":"2.391"},{"price":"61860.70","quantity":"0.093"},{"price":"61861.00","quantity":"0.028"},{"price":"61861.10","quantity":"0.371"},{"price":"61861.40","quantity":"0.573"},{"price":"61861.50","quantity":"2.317"},{"price":"61861.60","quantity":"0.214"},{"price":"61861.70","quantity":"0.230"},{"price":"61861.90","quantity":"0.006"},{"price":"61862.10","quantity":"0.011"},{"price":"61862.60","quantity":"0.091"},{"price":"61862.90","quantity":"0.000"},{"price":"61863.40","quantity":"0.224"},{"price":"61863.50","quantity":"0.004"},{"price":"61863.80","quantity":"0.001"},{"price":"61863.90","quantity":"1.660"},{"price":"61864.80","quantity":"0.925"},{"price":"61865.70","quantity":"0.472"},{"price":"61865.90","quantity":"0.406"},{"price":"61867.10","quantity":"0.008"},{"price":"61867.50","quantity":"0.267"},{"price":"61868.40","quantity":"0.013"},{"price":"61869.80","quantity":"0.044"},{"price":"61870.40","quantity":"0.032"},{"price":"61871.90","quantity":"0.364"},{"price":"61872.50","quantity":"0.000"},{"price":"61872.90","quantity":"0.070"},{"price":"61873.20","quantity":"0.294"},{"price":"61873.40","quantity":"2.988"},{"price":"61875.20","quantity":"0.318"},{"price":"61875.40","quantity":"0.110"},{"price":"61876.70","quantity":"0.000"},{"price":"61879.10","quantity":"0.166"},{"price":"61879.40","quantity":"0.341"},{"price":"61879.80","quantity":"0.082"},{"price":"61879.90","quantity":"1.772"},{"price":"61880.10","quantity":"0.002"},{"price":"61880.40","quantity":"0.285"},{"price":"61880.50","quantity":"0.004"},{"price":"61880.60","quantity":"0.300"},{"price":"61881.20","quantity":"0.122"},{"price":"61882.20","quantity":"0.751"},{"price":"61882.30","quantity":"0.008"},{"price":"61883.70","quantity":"0.002"},{"price":"61883.80","quantity":"0.019"},{"price":"61884.30","quantity":"0.003"},{"price":"61884.40","quantity":"0.005"},{"price":"61884.70","quantity":"0.278"},{"price":"61884.80","quantity":"0.421"},{"price":"61884.90","quantity":"0.014"},{"price":"61885.00","quantity":"0.220"},{"price":"61887.70","quantity":"0.050"},{"price":"61889.20","quantity":"0.021"},{"price":"61891.50","quantity":"0.018"},{"price":"61893.30","quantity":"0.473"},{"price":"61893.50","quantity":"0.580"},{"price":"61896.60","quantity":"0.264"},{"price":"61897.80","quantity":"0.013"},{"price":"61898.40","quantity":"1.204"},{"price":"61898.50","quantity":"0.221"},{"price":"61898.80","quantity":"0.000"},{"price":"61899.20","quantity":"0.000"},{"price":"61899.30","quantity":"0.591"},{"price":"61899.50","quantity":"0.001"},{"price":"61899.80","quantity":"0.000"},{"price":"61901.90","quantity":"0.001"},{"price":"61907.70","quantity":"0.502"},{"price":"61908.80","quantity":"0.325"},{"price":"61909.90","quantity":"0.221"},{"price":"61916.30","quantity":"0.149"},{"price":"61918.40","quantity":"24.872"},{"price":"61918.60","quantity":"0.027"},{"price":"61919.40","quantity":"0.311"},{"price":"61924.70","quantity":"0.000"},{"price":"61926.70","quantity":"0.098"},{"price":"61926.80","quantity":"0.891"},{"price":"61926.90","quantity":"0.021"},{"price":"61927.40","quantity":"0.056"},{"price":"61950.60","quantity":"1.628"},{"price":"61951.80","quantity":"0.000"},{"price":"62163.50","quantity":"2.408"},{"price":"62472.70","quantity":"1.678"},{"price":"62620.60","quantity":"0.002"},{"price":"62659.10","quantity":"0.319"},{"price":"63091.20","quantity":"0.086"},{"price":"89523.20","quantity":"1.062"}],"raw":{"e":"depthUpdate","E":1783517078432,"T":1783517078429,"s":"BTCUSDT","ps":"BTCUSDT","U":10999771652824,"u":10999771660474,"pu":10999771652793,"b":[["1000.00","207.692"],["11354.10","1.152"],["11454.10","2.048"],["11554.10","1.411"],["11654.10","0.289"],["55668.60","0.002"],["59379.90","0.000"],["60957.20","2.133"],["60980.00","3.238"],["60984.10","8.317"],["61080.90","4.427"],["61235.60","0.328"],["61388.70","0.163"],["61463.40","0.274"],["61482.30","0.005"],["61537.60","0.348"],["61544.80","0.040"],["61597.90","0.877"],["61609.20","0.324"],["61735.90","0.000"],["61760.30","0.158"],["61765.30","33.106"],["61767.40","0.000"],["61778.90","0.882"],["61785.90","0.223"],["61786.20","0.000"],["61786.50","0.022"],["61786.80","0.000"],["61787.00","0.190"],["61805.30","1.313"],["61805.60","0.338"],["61805.90","0.002"],["61806.10","4.509"],["61806.30","0.050"],["61806.40","0.001"],["61806.80","1.258"],["61820.10","10.663"],["61820.20","0.134"],["61820.30","0.467"],["61820.40","0.621"],["61820.80","0.050"],["61821.40","0.004"],["61821.90","0.790"],["61822.10","0.003"],["61822.40","0.448"],["61822.80","0.435"],["61822.90","0.005"],["61823.20","0.591"],["61823.40","0.009"],["61823.90","0.008"],["61824.40","0.583"],["61824.60","0.005"],["61824.70","0.001"],["61825.50","0.097"],["61828.30","0.009"],["61828.40","0.968"],["61828.60","0.553"],["61829.30","0.052"],["61829.40","2.288"],["61829.60","0.039"],["61830.10","0.001"],["61830.90","0.001"],["61831.50","0.935"],["61831.60","0.608"],["61833.00","0.034"],["61833.50","0.000"],["61834.20","0.001"],["61834.80","0.019"],["61837.30","0.805"],["61838.10","0.327"],["61840.60","0.566"],["61840.70","1.125"],["61840.80","0.024"],["61841.20","0.326"],["61841.40","0.928"],["61841.90","0.420"],["61842.00","0.046"],["61842.20","0.266"],["61842.50","0.325"],["61842.80","0.002"],["61843.00","2.262"],["61843.10","1.017"],["61843.20","0.068"],["61843.40","0.002"],["61843.50","0.002"],["61843.60","0.002"],["61843.70","0.003"],["61843.90","0.060"],["61844.00","0.001"],["61844.10","0.060"],["61844.20","0.001"],["61844.30","0.002"],["61844.40","0.169"],["61844.50","0.003"],["61844.60","0.128"],["61844.70","0.002"],["61844.80","0.017"],["61844.90","0.931"],["61845.00","1.163"],["61845.10","0.001"],["61845.20","0.000"],["61845.50","0.033"],["61845.70","1.122"],["61845.80","0.000"],["61845.90","0.131"],["61846.30","0.005"],["61846.50","0.010"],["61847.10","1.123"],["61848.00","0.745"],["61848.90","0.006"],["61850.10","0.050"],["61850.30","0.051"],["61853.80","0.006"],["61853.90","0.002"],["61854.00","0.004"],["61854.10","4.123"]],"a":[["61854.20","8.955"],["61854.30","1.651"],["61854.40","0.006"],["61854.50","0.016"],["61854.60","0.003"],["61854.70","0.023"],["61854.80","0.622"],["61855.20","0.067"],["61855.80","0.030"],["61856.40","0.005"],["61856.70","0.001"],["61856.80","0.001"],["61856.90","0.002"],["61857.00","0.751"],["61857.30","0.276"],["61857.40","0.005"],["61857.60","0.014"],["61857.90","0.905"],["61858.00","1.404"],["61858.10","2.226"],["61858.60","0.001"],["61859.50","1.505"],["61859.60","0.000"],["61859.70","0.001"],["61859.80","0.165"],["61859.90","0.180"],["61860.10","0.005"],["61860.40","0.856"],["61860.50","2.391"],["61860.70","0.093"],["61861.00","0.028"],["61861.10","0.371"],["61861.40","0.573"],["61861.50","2.317"],["61861.60","0.214"],["61861.70","0.230"],["61861.90","0.006"],["61862.10","0.011"],["61862.60","0.091"],["61862.90","0.000"],["61863.40","0.224"],["61863.50","0.004"],["61863.80","0.001"],["61863.90","1.660"],["61864.80","0.925"],["61865.70","0.472"],["61865.90","0.406"],["61867.10","0.008"],["61867.50","0.267"],["61868.40","0.013"],["61869.80","0.044"],["61870.40","0.032"],["61871.90","0.364"],["61872.50","0.000"],["61872.90","0.070"],["61873.20","0.294"],["61873.40","2.988"],["61875.20","0.318"],["61875.40","0.110"],["61876.70","0.000"],["61879.10","0.166"],["61879.40","0.341"],["61879.80","0.082"],["61879.90","1.772"],["61880.10","0.002"],["61880.40","0.285"],["61880.50","0.004"],["61880.60","0.300"],["61881.20","0.122"],["61882.20","0.751"],["61882.30","0.008"],["61883.70","0.002"],["61883.80","0.019"],["61884.30","0.003"],["61884.40","0.005"],["61884.70","0.278"],["61884.80","0.421"],["61884.90","0.014"],["61885.00","0.220"],["61887.70","0.050"],["61889.20","0.021"],["61891.50","0.018"],["61893.30","0.473"],["61893.50","0.580"],["61896.60","0.264"],["61897.80","0.013"],["61898.40","1.204"],["61898.50","0.221"],["61898.80","0.000"],["61899.20","0.000"],["61899.30","0.591"],["61899.50","0.001"],["61899.80","0.000"],["61901.90","0.001"],["61907.70","0.502"],["61908.80","0.325"],["61909.90","0.221"],["61916.30","0.149"],["61918.40","24.872"],["61918.60","0.027"],["61919.40","0.311"],["61924.70","0.000"],["61926.70","0.098"],["61926.80","0.891"],["61926.90","0.021"],["61927.40","0.056"],["61950.60","1.628"],["61951.80","0.000"],["62163.50","2.408"],["62472.70","1.678"],["62620.60","0.002"],["62659.10","0.319"],["63091.20","0.086"],["89523.20","1.062"]],"st":1}}
{"schema_version":"1.3.0","event_id":"7b893ca8-66fa-4c46-a914-0ec9a84d4ceb","event_type":"raw.depth_update","source":"binance_market_data_recorder","venue":"binance_usdm","market_type":"perpetual_futures","symbol":"BTCUSDT","event_time_ms":1783517078534,"received_time_ms":1783517078529,"trace_id":"fcb6b86f-f87f-4bae-a647-d3c87c734fa6","first_update_id":10999771660699,"final_update_id":10999771667032,"previous_final_update_id":10999771660474,"bids":[{"price":"11354.10","quantity":"1.424"},{"price":"11454.10","quantity":"1.776"},{"price":"11554.10","quantity":"1.564"},{"price":"11654.10","quantity":"0.136"},{"price":"55668.60","quantity":"0.002"},{"price":"59379.90","quantity":"0.003"},{"price":"60617.10","quantity":"0.039"},{"price":"61050.80","quantity":"1.716"},{"price":"61235.60","quantity":"0.328"},{"price":"61544.80","quantity":"0.039"},{"price":"61735.90","quantity":"0.100"},{"price":"61765.30","quantity":"0.072"},{"price":"61786.30","quantity":"33.085"},{"price":"61805.70","quantity":"0.032"},{"price":"61816.00","quantity":"0.004"},{"price":"61822.80","quantity":"0.314"},{"price":"61822.90","quantity":"0.003"},{"price":"61826.10","quantity":"1.310"},{"price":"61826.80","quantity":"0.004"},{"price":"61828.40","quantity":"0.000"},{"price":"61830.70","quantity":"0.970"},{"price":"61831.60","quantity":"0.042"},{"price":"61833.80","quantity":"0.566"},{"price":"61837.40","quantity":"0.812"},{"price":"61837.50","quantity":"3.199"},{"price":"61840.60","quantity":"0.564"},{"price":"61842.10","quantity":"0.002"},{"price":"61843.80","quantity":"0.066"},{"price":"61844.00","quantity":"0.061"},{"price":"61844.10","quantity":"0.120"},{"price":"61844.40","quantity":"0.261"},{"price":"61846.30","quantity":"0.001"},{"price":"61847.20","quantity":"0.186"},{"price":"61847.90","quantity":"0.004"},{"price":"61848.80","quantity":"0.001"},{"price":"61849.10","quantity":"0.003"},{"price":"61850.20","quantity":"0.042"},{"price":"61850.30","quantity":"0.375"},{"price":"61850.50","quantity":"0.007"},{"price":"61851.10","quantity":"0.641"},{"price":"61853.80","quantity":"0.002"},{"price":"61853.90","quantity":"0.004"},{"price":"61854.00","quantity":"0.006"},{"price":"61854.10","quantity":"4.125"}],"asks":[{"price":"61854.20","quantity":"7.713"},{"price":"61854.30","quantity":"0.035"},{"price":"61857.30","quantity":"0.402"},{"price":"61857.40","quantity":"1.621"},{"price":"61858.00","quantity":"0.974"},{"price":"61859.40","quantity":"0.558"},{"price":"61860.50","quantity":"1.423"},{"price":"61860.70","quantity":"0.013"},{"price":"61860.80","quantity":"0.033"},{"price":"61861.10","quantity":"1.446"},{"price":"61861.40","quantity":"0.198"},{"price":"61861.60","quantity":"0.376"},{"price":"61861.70","quantity":"0.410"},{"price":"61862.30","quantity":"0.970"},{"price":"61862.60","quantity":"0.091"},{"price":"61863.20","quantity":"0.404"},{"price":"61863.80","quantity":"0.567"},{"price":"61864.90","quantity":"0.050"},{"price":"61865.00","quantity":"0.083"},{"price":"61866.10","quantity":"0.121"},{"price":"61867.30","quantity":"0.067"},{"price":"61867.40","quantity":"0.691"},{"price":"61867.50","quantity":"0.202"},{"price":"61873.20","quantity":"0.292"},{"price":"61874.20","quantity":"0.002"},{"price":"61875.40","quantity":"0.051"},{"price":"61877.20","quantity":"0.003"},{"price":"61877.60","quantity":"0.060"},{"price":"61880.50","quantity":"0.270"},{"price":"61884.40","quantity":"0.003"},{"price":"61884.70","quantity":"0.470"},{"price":"61884.90","quantity":"0.176"},{"price":"61885.00","quantity":"0.400"},{"price":"61897.40","quantity":"0.004"},{"price":"61899.90","quantity":"0.101"},{"price":"61903.70","quantity":"0.035"},{"price":"62082.40","quantity":"0.906"},{"price":"62084.40","quantity":"0.003"},{"price":"62152.10","quantity":"0.101"},{"price":"62152.50","quantity":"0.113"},{"price":"62163.50","quantity":"2.409"},{"price":"62472.70","quantity":"1.678"},{"price":"62782.80","quantity":"0.485"}],"raw":{"e":"depthUpdate","E":1783517078534,"T":1783517078533,"s":"BTCUSDT","ps":"BTCUSDT","U":10999771660699,"u":10999771667032,"pu":10999771660474,"b":[["11354.10","1.424"],["11454.10","1.776"],["11554.10","1.564"],["11654.10","0.136"],["55668.60","0.002"],["59379.90","0.003"],["60617.10","0.039"],["61050.80","1.716"],["61235.60","0.328"],["61544.80","0.039"],["61735.90","0.100"],["61765.30","0.072"],["61786.30","33.085"],["61805.70","0.032"],["61816.00","0.004"],["61822.80","0.314"],["61822.90","0.003"],["61826.10","1.310"],["61826.80","0.004"],["61828.40","0.000"],["61830.70","0.970"],["61831.60","0.042"],["61833.80","0.566"],["61837.40","0.812"],["61837.50","3.199"],["61840.60","0.564"],["61842.10","0.002"],["61843.80","0.066"],["61844.00","0.061"],["61844.10","0.120"],["61844.40","0.261"],["61846.30","0.001"],["61847.20","0.186"],["61847.90","0.004"],["61848.80","0.001"],["61849.10","0.003"],["61850.20","0.042"],["61850.30","0.375"],["61850.50","0.007"],["61851.10","0.641"],["61853.80","0.002"],["61853.90","0.004"],["61854.00","0.006"],["61854.10","4.125"]],"a":[["61854.20","7.713"],["61854.30","0.035"],["61857.30","0.402"],["61857.40","1.621"],["61858.00","0.974"],["61859.40","0.558"],["61860.50","1.423"],["61860.70","0.013"],["61860.80","0.033"],["61861.10","1.446"],["61861.40","0.198"],["61861.60","0.376"],["61861.70","0.410"],["61862.30","0.970"],["61862.60","0.091"],["61863.20","0.404"],["61863.80","0.567"],["61864.90","0.050"],["61865.00","0.083"],["61866.10","0.121"],["61867.30","0.067"],["61867.40","0.691"],["61867.50","0.202"],["61873.20","0.292"],["61874.20","0.002"],["61875.40","0.051"],["61877.20","0.003"],["61877.60","0.060"],["61880.50","0.270"],["61884.40","0.003"],["61884.70","0.470"],["61884.90","0.176"],["61885.00","0.400"],["61897.40","0.004"],["61899.90","0.101"],["61903.70","0.035"],["62082.40","0.906"],["62084.40","0.003"],["62152.10","0.101"],["62152.50","0.113"],["62163.50","2.409"],["62472.70","1.678"],["62782.80","0.485"]],"st":1}}
{"schema_version":"1.3.0","event_id":"f7f1091c-5af5-4008-bf84-ff859142c24c","event_type":"raw.depth_update","source":"binance_market_data_recorder","venue":"binance_usdm","market_type":"perpetual_futures","symbol":"BTCUSDT","event_time_ms":1783517078636,"received_time_ms":1783517078631,"trace_id":"d06943d7-fc05-43f1-9193-29b69f795836","first_update_id":10999771667164,"final_update_id":10999771672807,"previous_final_update_id":10999771667032,"bids":[{"price":"11354.10","quantity":"1.696"},{"price":"11454.10","quantity":"1.504"},{"price":"11554.10","quantity":"1.700"},{"price":"11654.10","quantity":"0.000"},{"price":"55668.60","quantity":"0.002"},{"price":"59379.90","quantity":"0.000"},{"price":"61153.00","quantity":"0.512"},{"price":"61174.40","quantity":"3.243"},{"price":"61235.60","quantity":"0.328"},{"price":"61544.80","quantity":"0.039"},{"price":"61777.90","quantity":"33.180"},{"price":"61786.30","quantity":"0.051"},{"price":"61788.40","quantity":"0.002"},{"price":"61806.00","quantity":"0.075"},{"price":"61806.50","quantity":"0.596"},{"price":"61808.80","quantity":"0.452"},{"price":"61814.40","quantity":"0.110"},{"price":"61841.50","quantity":"0.354"},{"price":"61841.60","quantity":"1.064"},{"price":"61843.90","quantity":"0.120"},{"price":"61844.50","quantity":"0.063"},{"price":"61844.70","quantity":"0.034"},{"price":"61845.10","quantity":"0.061"},{"price":"61845.30","quantity":"0.037"},{"price":"61847.20","quantity":"0.000"},{"price":"61853.70","quantity":"0.057"},{"price":"61853.80","quantity":"0.006"},{"price":"61853.90","quantity":"0.002"},{"price":"61854.00","quantity":"0.004"}],"asks":[{"price":"61854.20","quantity":"7.442"},{"price":"61856.50","quantity":"0.135"},{"price":"61857.30","quantity":"0.276"},{"price":"61860.10","quantity":"0.133"},{"price":"61860.50","quantity":"1.621"},{"price":"61860.80","quantity":"0.139"},{"price":"61861.20","quantity":"0.138"},{"price":"61861.70","quantity":"0.578"},{"price":"61862.70","quantity":"2.745"},{"price":"61866.70","quantity":"0.825"},{"price":"61867.30","quantity":"0.002"},{"price":"61879.50","quantity":"0.217"},{"price":"61880.20","quantity":"0.106"},{"price":"61882.10","quantity":"0.805"},{"price":"61883.80","quantity":"0.217"},{"price":"61884.50","quantity":"0.141"},{"price":"61885.00","quantity":"0.568"},{"price":"61894.70","quantity":"1.972"},{"price":"61897.60","quantity":"4.504"},{"price":"61898.90","quantity":"0.136"},{"price":"61899.60","quantity":"0.106"},{"price":"61909.50","quantity":"2.896"},{"price":"61909.90","quantity":"0.120"},{"price":"61919.30","quantity":"8.002"},{"price":"61950.10","quantity":"0.036"},{"price":"61950.20","quantity":"11.095"},{"price":"61951.00","quantity":"0.000"},{"price":"62114.30","quantity":"0.002"},{"price":"62114.40","quantity":"0.002"},{"price":"62114.50","quantity":"0.002"},{"price":"62472.70","quantity":"1.678"},{"price":"62658.30","quantity":"1.913"},{"price":"62658.40","quantity":"1.594"},{"price":"62668.00","quantity":"10.395"},{"price":"62678.00","quantity":"0.316"},{"price":"68039.60","quantity":"0.003"},{"price":"89523.20","quantity":"1.068"}],"raw":{"e":"depthUpdate","E":1783517078636,"T":1783517078635,"s":"BTCUSDT","ps":"BTCUSDT","U":10999771667164,"u":10999771672807,"pu":10999771667032,"b":[["11354.10","1.696"],["11454.10","1.504"],["11554.10","1.700"],["11654.10","0.000"],["55668.60","0.002"],["59379.90","0.000"],["61153.00","0.512"],["61174.40","3.243"],["61235.60","0.328"],["61544.80","0.039"],["61777.90","33.180"],["61786.30","0.051"],["61788.40","0.002"],["61806.00","0.075"],["61806.50","0.596"],["61808.80","0.452"],["61814.40","0.110"],["61841.50","0.354"],["61841.60","1.064"],["61843.90","0.120"],["61844.50","0.063"],["61844.70","0.034"],["61845.10","0.061"],["61845.30","0.037"],["61847.20","0.000"],["61853.70","0.057"],["61853.80","0.006"],["61853.90","0.002"],["61854.00","0.004"]],"a":[["61854.20","7.442"],["61856.50","0.135"],["61857.30","0.276"],["61860.10","0.133"],["61860.50","1.621"],["61860.80","0.139"],["61861.20","0.138"],["61861.70","0.578"],["61862.70","2.745"],["61866.70","0.825"],["61867.30","0.002"],["61879.50","0.217"],["61880.20","0.106"],["61882.10","0.805"],["61883.80","0.217"],["61884.50","0.141"],["61885.00","0.568"],["61894.70","1.972"],["61897.60","4.504"],["61898.90","0.136"],["61899.60","0.106"],["61909.50","2.896"],["61909.90","0.120"],["61919.30","8.002"],["61950.10","0.036"],["61950.20","11.095"],["61951.00","0.000"],["62114.30","0.002"],["62114.40","0.002"],["62114.50","0.002"],["62472.70","1.678"],["62658.30","1.913"],["62658.40","1.594"],["62668.00","10.395"],["62678.00","0.316"],["68039.60","0.003"],["89523.20","1.068"]],"st":1}}
{"schema_version":"1.3.0","event_id":"c8d22c0c-f03a-411d-9e9b-c0ab2beeda66","event_type":"raw.depth_update","source":"binance_market_data_recorder","venue":"binance_usdm","market_type":"perpetual_futures","symbol":"BTCUSDT","event_time_ms":1783517078738,"received_time_ms":1783517078747,"trace_id":"3406732b-17b6-463d-8eae-272e076cfb10","first_update_id":10999771672841,"final_update_id":10999771683358,"previous_final_update_id":10999771672807,"bids":[{"price":"1000.00","quantity":"207.692"},{"price":"11354.10","quantity":"1.968"},{"price":"11454.10","quantity":"1.385"},{"price":"11554.10","quantity":"1.547"},{"price":"55668.60","quantity":"0.002"},{"price":"59379.90","quantity":"0.003"},{"price":"60617.10","quantity":"0.036"},{"price":"60927.10","quantity":"0.738"},{"price":"60988.10","quantity":"2.735"},{"price":"61050.00","quantity":"5.999"},{"price":"61235.60","quantity":"0.328"},{"price":"61777.90","quantity":"0.146"},{"price":"61779.20","quantity":"6.960"},{"price":"61786.30","quantity":"33.085"},{"price":"61786.90","quantity":"0.053"},{"price":"61787.40","quantity":"0.032"},{"price":"61808.80","quantity":"0.351"},{"price":"61808.90","quantity":"0.108"},{"price":"61813.80","quantity":"0.014"},{"price":"61814.20","quantity":"0.176"},{"price":"61828.60","quantity":"0.391"},{"price":"61829.50","quantity":"0.887"},{"price":"61844.50","quantity":"0.243"},{"price":"61845.10","quantity":"0.121"},{"price":"61847.90","quantity":"0.000"},{"price":"61849.50","quantity":"0.005"},{"price":"61852.30","quantity":"0.230"},{"price":"61853.70","quantity":"0.047"},{"price":"61853.80","quantity":"0.002"},{"price":"61853.90","quantity":"0.006"},{"price":"61854.10","quantity":"4.124"}],"asks":[{"price":"61854.20","quantity":"7.939"},{"price":"61854.40","quantity":"0.002"},{"price":"61855.80","quantity":"0.032"},{"price":"61856.10","quantity":"0.004"},{"price":"61856.50","quantity":"0.009"},{"price":"61860.50","quantity":"1.783"},{"price":"61861.10","quantity":"1.950"},{"price":"61862.80","quantity":"0.344"},{"price":"61880.00","quantity":"0.633"},{"price":"61880.50","quantity":"0.462"},{"price":"61883.80","quantity":"0.379"},{"price":"61884.40","quantity":"0.315"},{"price":"61893.20","quantity":"0.207"},{"price":"61893.40","quantity":"0.300"},{"price":"61897.50","quantity":"0.323"},{"price":"61909.50","quantity":"2.795"},{"price":"61913.10","quantity":"2.532"},{"price":"61916.40","quantity":"7.709"},{"price":"61919.10","quantity":"0.031"},{"price":"61947.40","quantity":"3.512"},{"price":"62457.30","quantity":"0.000"},{"price":"62472.70","quantity":"1.678"},{"price":"62782.00","quantity":"1.591"},{"price":"62804.10","quantity":"0.002"},{"price":"68039.60","quantity":"0.001"}],"raw":{"e":"depthUpdate","E":1783517078738,"T":1783517078737,"s":"BTCUSDT","ps":"BTCUSDT","U":10999771672841,"u":10999771683358,"pu":10999771672807,"b":[["1000.00","207.692"],["11354.10","1.968"],["11454.10","1.385"],["11554.10","1.547"],["55668.60","0.002"],["59379.90","0.003"],["60617.10","0.036"],["60927.10","0.738"],["60988.10","2.735"],["61050.00","5.999"],["61235.60","0.328"],["61777.90","0.146"],["61779.20","6.960"],["61786.30","33.085"],["61786.90","0.053"],["61787.40","0.032"],["61808.80","0.351"],["61808.90","0.108"],["61813.80","0.014"],["61814.20","0.176"],["61828.60","0.391"],["61829.50","0.887"],["61844.50","0.243"],["61845.10","0.121"],["61847.90","0.000"],["61849.50","0.005"],["61852.30","0.230"],["61853.70","0.047"],["61853.80","0.002"],["61853.90","0.006"],["61854.10","4.124"]],"a":[["61854.20","7.939"],["61854.40","0.002"],["61855.80","0.032"],["61856.10","0.004"],["61856.50","0.009"],["61860.50","1.783"],["61861.10","1.950"],["61862.80","0.344"],["61880.00","0.633"],["61880.50","0.462"],["61883.80","0.379"],["61884.40","0.315"],["61893.20","0.207"],["61893.40","0.300"],["61897.50","0.323"],["61909.50","2.795"],["61913.10","2.532"],["61916.40","7.709"],["61919.10","0.031"],["61947.40","3.512"],["62457.30","0.000"],["62472.70","1.678"],["62782.00","1.591"],["62804.10","0.002"],["68039.60","0.001"]],"st":1}}
{"schema_version":"1.3.0","event_id":"ea4245c4-87c1-4a85-8239-90be18521533","event_type":"raw.depth_update","source":"binance_market_data_recorder","venue":"binance_usdm","market_type":"perpetual_futures","symbol":"BTCUSDT","event_time_ms":1783517078840,"received_time_ms":1783517078836,"trace_id":"65c9d303-5510-4cfa-ae25-8fcec4e1e9e3","first_update_id":10999771683534,"final_update_id":10999771692500,"previous_final_update_id":10999771683358,"bids":[{"price":"11354.10","quantity":"2.240"},{"price":"11454.10","quantity":"1.249"},{"price":"11554.10","quantity":"1.411"},{"price":"49483.30","quantity":"0.000"},{"price":"55668.60","quantity":"0.002"},{"price":"61088.10","quantity":"18.704"},{"price":"61235.60","quantity":"0.328"},{"price":"61779.20","quantity":"2.205"},{"price":"61786.30","quantity":"33.117"},{"price":"61809.90","quantity":"0.101"},{"price":"61810.10","quantity":"0.106"},{"price":"61820.20","quantity":"0.570"},{"price":"61820.60","quantity":"0.080"},{"price":"61820.80","quantity":"0.110"},{"price":"61821.90","quantity":"0.354"},{"price":"61822.00","quantity":"0.001"},{"price":"61825.00","quantity":"1.347"},{"price":"61833.80","quantity":"0.000"},{"price":"61836.00","quantity":"0.632"},{"price":"61838.60","quantity":"0.000"},{"price":"61840.50","quantity":"2.138"},{"price":"61843.80","quantity":"0.126"},{"price":"61843.90","quantity":"0.180"},{"price":"61844.50","quantity":"0.303"},{"price":"61847.60","quantity":"0.001"},{"price":"61847.90","quantity":"0.003"},{"price":"61853.90","quantity":"0.004"},{"price":"61854.00","quantity":"0.006"}],"asks":[{"price":"61854.20","quantity":"7.936"},{"price":"61855.80","quantity":"0.032"},{"price":"61860.30","quantity":"0.004"},{"price":"61861.10","quantity":"2.130"},{"price":"61861.70","quantity":"0.782"},{"price":"61861.80","quantity":"0.156"},{"price":"61862.30","quantity":"0.002"},{"price":"61863.30","quantity":"0.972"},{"price":"61863.80","quantity":"0.001"},{"price":"61864.70","quantity":"0.567"},{"price":"61866.60","quantity":"3.457"},{"price":"61866.70","quantity":"0.760"},{"price":"61868.80","quantity":"0.060"},{"price":"61874.10","quantity":"0.821"},{"price":"61876.90","quantity":"0.632"},{"price":"61884.40","quantity":"0.495"},{"price":"61885.00","quantity":"0.772"},{"price":"61885.10","quantity":"0.277"},{"price":"61891.50","quantity":"0.004"},{"price":"61893.50","quantity":"0.373"},{"price":"61897.60","quantity":"4.506"},{"price":"61897.80","quantity":"0.011"},{"price":"61899.20","quantity":"0.014"},{"price":"61907.80","quantity":"4.850"},{"price":"61908.10","quantity":"0.001"},{"price":"61947.30","quantity":"0.008"},{"price":"61950.10","quantity":"0.028"},{"price":"62472.70","quantity":"1.678"},{"price":"62666.40","quantity":"1.601"},{"price":"62720.20","quantity":"2.939"},{"price":"89523.20","quantity":"1.074"}],"raw":{"e":"depthUpdate","E":1783517078840,"T":1783517078839,"s":"BTCUSDT","ps":"BTCUSDT","U":10999771683534,"u":10999771692500,"pu":10999771683358,"b":[["11354.10","2.240"],["11454.10","1.249"],["11554.10","1.411"],["49483.30","0.000"],["55668.60","0.002"],["61088.10","18.704"],["61235.60","0.328"],["61779.20","2.205"],["61786.30","33.117"],["61809.90","0.101"],["61810.10","0.106"],["61820.20","0.570"],["61820.60","0.080"],["61820.80","0.110"],["61821.90","0.354"],["61822.00","0.001"],["61825.00","1.347"],["61833.80","0.000"],["61836.00","0.632"],["61838.60","0.000"],["61840.50","2.138"],["61843.80","0.126"],["61843.90","0.180"],["61844.50","0.303"],["61847.60","0.001"],["61847.90","0.003"],["61853.90","0.004"],["61854.00","0.006"]],"a":[["61854.20","7.936"],["61855.80","0.032"],["61860.30","0.004"],["61861.10","2.130"],["61861.70","0.782"],["61861.80","0.156"],["61862.30","0.002"],["61863.30","0.972"],["61863.80","0.001"],["61864.70","0.567"],["61866.60","3.457"],["61866.70","0.760"],["61868.80","0.060"],["61874.10","0.821"],["61876.90","0.632"],["61884.40","0.495"],["61885.00","0.772"],["61885.10","0.277"],["61891.50","0.004"],["61893.50","0.373"],["61897.60","4.506"],["61897.80","0.011"],["61899.20","0.014"],["61907.80","4.850"],["61908.10","0.001"],["61947.30","0.008"],["61950.10","0.028"],["62472.70","1.678"],["62666.40","1.601"],["62720.20","2.939"],["89523.20","1.074"]],"st":1}}
{"schema_version":"1.3.0","event_id":"b9d8eaf2-c134-477e-9611-2783843f92b8","event_type":"raw.depth_update","source":"binance_market_data_recorder","venue":"binance_usdm","market_type":"perpetual_futures","symbol":"BTCUSDT","event_time_ms":1783517078942,"received_time_ms":1783517078937,"trace_id":"ce377fbb-b5e2-42c3-814d-13fbca1b5e8c","first_update_id":10999771692696,"final_update_id":10999771701433,"previous_final_update_id":10999771692500,"bids":[{"price":"11354.10","quantity":"2.512"},{"price":"11454.10","quantity":"1.130"},{"price":"11554.10","quantity":"1.258"},{"price":"55668.60","quantity":"0.002"},{"price":"58575.80","quantity":"0.041"},{"price":"59379.90","quantity":"0.000"},{"price":"60617.10","quantity":"0.033"},{"price":"60826.90","quantity":"0.000"},{"price":"61111.90","quantity":"11.014"},{"price":"61173.70","quantity":"1.050"},{"price":"61235.60","quantity":"0.328"},{"price":"61366.10","quantity":"0.107"},{"price":"61537.60","quantity":"0.348"},{"price":"61544.80","quantity":"0.029"},{"price":"61786.30","quantity":"0.083"},{"price":"61786.60","quantity":"0.032"},{"price":"61787.20","quantity":"0.034"},{"price":"61788.40","quantity":"33.036"},{"price":"61808.90","quantity":"0.108"},{"price":"61809.90","quantity":"0.000"},{"price":"61819.50","quantity":"0.702"},{"price":"61820.50","quantity":"0.280"},{"price":"61820.70","quantity":"0.676"},{"price":"61820.80","quantity":"0.170"},{"price":"61821.00","quantity":"0.710"},{"price":"61824.40","quantity":"0.001"},{"price":"61826.10","quantity":"1.189"},{"price":"61826.30","quantity":"0.049"},{"price":"61827.60","quantity":"0.589"},{"price":"61827.80","quantity":"0.407"},{"price":"61828.30","quantity":"0.001"},{"price":"61830.30","quantity":"0.173"},{"price":"61830.70","quantity":"0.002"},{"price":"61832.90","quantity":"0.969"},{"price":"61835.00","quantity":"0.037"},{"price":"61836.60","quantity":"1.237"},{"price":"61838.10","quantity":"0.323"},{"price":"61839.90","quantity":"0.135"},{"price":"61841.50","quantity":"0.358"},{"price":"61843.00","quantity":"2.428"},{"price":"61848.50","quantity":"1.044"},{"price":"61852.30","quantity":"0.230"},{"price":"61853.90","quantity":"0.002"},{"price":"61854.00","quantity":"0.004"}],"asks":[{"price":"61854.20","quantity":"7.935"},{"price":"61856.90","quantity":"1.941"},{"price":"61857.20","quantity":"0.000"},{"price":"61857.40","quantity":"0.005"},{"price":"61857.90","quantity":"0.582"},{"price":"61863.30","quantity":"0.004"},{"price":"61863.80","quantity":"0.324"},{"price":"61864.20","quantity":"0.977"},{"price":"61864.70","quantity":"0.001"},{"price":"61864.80","quantity":"0.343"},{"price":"61866.10","quantity":"0.000"},{"price":"61866.30","quantity":"0.000"},{"price":"61866.40","quantity":"0.569"},{"price":"61866.50","quantity":"0.586"},{"price":"61867.10","quantity":"0.000"},{"price":"61867.30","quantity":"0.002"},{"price":"61868.70","quantity":"0.081"},{"price":"61868.80","quantity":"0.060"},{"price":"61869.40","quantity":"0.128"},{"price":"61869.60","quantity":"0.009"},{"price":"61893.40","quantity":"0.507"},{"price":"61898.10","quantity":"5.002"},{"price":"61905.40","quantity":"0.130"},{"price":"61907.70","quantity":"0.401"},{"price":"61907.80","quantity":"4.749"},{"price":"61909.50","quantity":"2.640"},{"price":"61916.40","quantity":"3.237"},{"price":"61918.40","quantity":"0.000"},{"price":"61918.60","quantity":"0.067"},{"price":"61924.70","quantity":"24.872"},{"price":"61926.80","quantity":"0.891"},{"price":"62472.70","quantity":"1.678"},{"price":"62596.50","quantity":"0.271"},{"price":"62658.30","quantity":"2.869"},{"price":"62676.60","quantity":"0.000"}],"raw":{"e":"depthUpdate","E":1783517078942,"T":1783517078941,"s":"BTCUSDT","ps":"BTCUSDT","U":10999771692696,"u":10999771701433,"pu":10999771692500,"b":[["11354.10","2.512"],["11454.10","1.130"],["11554.10","1.258"],["55668.60","0.002"],["58575.80","0.041"],["59379.90","0.000"],["60617.10","0.033"],["60826.90","0.000"],["61111.90","11.014"],["61173.70","1.050"],["61235.60","0.328"],["61366.10","0.107"],["61537.60","0.348"],["61544.80","0.029"],["61786.30","0.083"],["61786.60","0.032"],["61787.20","0.034"],["61788.40","33.036"],["61808.90","0.108"],["61809.90","0.000"],["61819.50","0.702"],["61820.50","0.280"],["61820.70","0.676"],["61820.80","0.170"],["61821.00","0.710"],["61824.40","0.001"],["61826.10","1.189"],["61826.30","0.049"],["61827.60","0.589"],["61827.80","0.407"],["61828.30","0.001"],["61830.30","0.173"],["61830.70","0.002"],["61832.90","0.969"],["61835.00","0.037"],["61836.60","1.237"],["61838.10","0.323"],["61839.90","0.135"],["61841.50","0.358"],["61843.00","2.428"],["61848.50","1.044"],["61852.30","0.230"],["61853.90","0.002"],["61854.00","0.004"]],"a":[["61854.20","7.935"],["61856.90","1.941"],["61857.20","0.000"],["61857.40","0.005"],["61857.90","0.582"],["61863.30","0.004"],["61863.80","0.324"],["61864.20","0.977"],["61864.70","0.001"],["61864.80","0.343"],["61866.10","0.000"],["61866.30","0.000"],["61866.40","0.569"],["61866.50","0.586"],["61867.10","0.000"],["61867.30","0.002"],["61868.70","0.081"],["61868.80","0.060"],["61869.40","0.128"],["61869.60","0.009"],["61893.40","0.507"],["61898.10","5.002"],["61905.40","0.130"],["61907.70","0.401"],["61907.80","4.749"],["61909.50","2.640"],["61916.40","3.237"],["61918.40","0.000"],["61918.60","0.067"],["61924.70","24.872"],["61926.80","0.891"],["62472.70","1.678"],["62596.50","0.271"],["62658.30","2.869"],["62676.60","0.000"]],"st":1}}
{"schema_version":"1.3.0","event_id":"a12e4d32-9e59-4c7a-ab53-017fc6ce68fd","event_type":"raw.depth_update","source":"binance_market_data_recorder","venue":"binance_usdm","market_type":"perpetual_futures","symbol":"BTCUSDT","event_time_ms":1783517079044,"received_time_ms":1783517079041,"trace_id":"9fa86f4f-0f68-4c55-9513-caa79385f9f6","first_update_id":10999771701593,"final_update_id":10999771709572,"previous_final_update_id":10999771701433,"bids":[{"price":"1000.00","quantity":"207.692"},{"price":"11354.10","quantity":"2.720"},{"price":"11454.10","quantity":"1.026"},{"price":"11554.10","quantity":"1.122"},{"price":"11754.10","quantity":"0.032"},{"price":"55668.60","quantity":"0.002"},{"price":"58761.30","quantity":"0.020"},{"price":"58761.40","quantity":"0.026"},{"price":"59379.90","quantity":"0.003"},{"price":"60617.10","quantity":"0.036"},{"price":"60926.30","quantity":"1.107"},{"price":"61111.90","quantity":"12.648"},{"price":"61235.60","quantity":"0.328"},{"price":"61735.90","quantity":"0.000"},{"price":"61810.10","quantity":"0.106"},{"price":"61810.30","quantity":"1.591"},{"price":"61810.40","quantity":"0.214"},{"price":"61815.00","quantity":"0.715"},{"price":"61817.30","quantity":"1.757"},{"price":"61820.60","quantity":"0.140"},{"price":"61821.20","quantity":"0.161"},{"price":"61821.80","quantity":"0.777"},{"price":"61821.90","quantity":"0.414"},{"price":"61823.20","quantity":"0.511"},{"price":"61825.60","quantity":"0.140"},{"price":"61825.80","quantity":"0.582"},{"price":"61826.70","quantity":"0.011"},{"price":"61827.00","quantity":"1.298"},{"price":"61827.60","quantity":"0.007"},{"price":"61827.80","quantity":"0.286"},{"price":"61829.60","quantity":"0.053"},{"price":"61830.30","quantity":"0.173"},{"price":"61830.40","quantity":"0.130"},{"price":"61831.00","quantity":"0.968"},{"price":"61831.90","quantity":"0.001"},{"price":"61832.90","quantity":"0.001"},{"price":"61834.40","quantity":"0.688"},{"price":"61836.00","quantity":"0.066"},{"price":"61837.90","quantity":"1.484"},{"price":"61838.10","quantity":"0.485"},{"price":"61843.00","quantity":"2.271"},{"price":"61843.10","quantity":"0.957"},{"price":"61843.20","quantity":"0.008"},{"price":"61849.50","quantity":"0.001"},{"price":"61851.40","quantity":"0.004"},{"price":"61852.30","quantity":"0.007"},{"price":"61853.90","quantity":"0.004"},{"price":"61854.00","quantity":"0.006"},{"price":"61854.10","quantity":"3.218"}],"asks":[{"price":"61854.20","quantity":"7.936"},{"price":"61856.10","quantity":"0.000"},{"price":"61857.90","quantity":"0.586"},{"price":"61860.40","quantity":"0.860"},{"price":"61861.80","quantity":"1.124"},{"price":"61861.90","quantity":"0.002"},{"price":"61862.70","quantity":"2.745"},{"price":"61863.40","quantity":"0.220"},{"price":"61863.80","quantity":"0.890"},{"price":"61864.20","quantity":"0.009"},{"price":"61865.30","quantity":"0.332"},{"price":"61866.40","quantity":"0.003"},{"price":"61866.50","quantity":"0.707"},{"price":"61866.60","quantity":"3.461"},{"price":"61867.00","quantity":"0.288"},{"price":"61868.50","quantity":"0.757"},{"price":"61868.70","quantity":"0.098"},{"price":"61869.40","quantity":"0.007"},{"price":"61872.80","quantity":"0.004"},{"price":"61880.70","quantity":"0.074"},{"price":"61893.70","quantity":"0.882"},{"price":"61904.80","quantity":"0.386"},{"price":"61907.00","quantity":"0.028"},{"price":"61907.70","quantity":"0.502"},{"price":"62293.30","quantity":"0.017"},{"price":"62420.60","quantity":"6.799"},{"price":"62472.70","quantity":"1.678"},{"price":"62592.30","quantity":"5.371"},{"price":"62627.40","quantity":"1.783"},{"price":"62668.00","quantity":"8.004"},{"price":"62668.10","quantity":"0.000"},{"price":"62802.70","quantity":"0.358"},{"price":"89523.20","quantity":"1.080"}],"raw":{"e":"depthUpdate","E":1783517079044,"T":1783517079042,"s":"BTCUSDT","ps":"BTCUSDT","U":10999771701593,"u":10999771709572,"pu":10999771701433,"b":[["1000.00","207.692"],["11354.10","2.720"],["11454.10","1.026"],["11554.10","1.122"],["11754.10","0.032"],["55668.60","0.002"],["58761.30","0.020"],["58761.40","0.026"],["59379.90","0.003"],["60617.10","0.036"],["60926.30","1.107"],["61111.90","12.648"],["61235.60","0.328"],["61735.90","0.000"],["61810.10","0.106"],["61810.30","1.591"],["61810.40","0.214"],["61815.00","0.715"],["61817.30","1.757"],["61820.60","0.140"],["61821.20","0.161"],["61821.80","0.777"],["61821.90","0.414"],["61823.20","0.511"],["61825.60","0.140"],["61825.80","0.582"],["61826.70","0.011"],["61827.00","1.298"],["61827.60","0.007"],["61827.80","0.286"],["61829.60","0.053"],["61830.30","0.173"],["61830.40","0.130"],["61831.00","0.968"],["61831.90","0.001"],["61832.90","0.001"],["61834.40","0.688"],["61836.00","0.066"],["61837.90","1.484"],["61838.10","0.485"],["61843.00","2.271"],["61843.10","0.957"],["61843.20","0.008"],["61849.50","0.001"],["61851.40","0.004"],["61852.30","0.007"],["61853.90","0.004"],["61854.00","0.006"],["61854.10","3.218"]],"a":[["61854.20","7.936"],["61856.10","0.000"],["61857.90","0.586"],["61860.40","0.860"],["61861.80","1.124"],["61861.90","0.002"],["61862.70","2.745"],["61863.40","0.220"],["61863.80","0.890"],["61864.20","0.009"],["61865.30","0.332"],["61866.40","0.003"],["61866.50","0.707"],["61866.60","3.461"],["61867.00","0.288"],["61868.50","0.757"],["61868.70","0.098"],["61869.40","0.007"],["61872.80","0.004"],["61880.70","0.074"],["61893.70","0.882"],["61904.80","0.386"],["61907.00","0.028"],["61907.70","0.502"],["62293.30","0.017"],["62420.60","6.799"],["62472.70","1.678"],["62592.30","5.371"],["62627.40","1.783"],["62668.00","8.004"],["62668.10","0.000"],["62802.70","0.358"],["89523.20","1.080"]],"st":1}}
{"schema_version":"1.3.0","event_id":"8547b3f3-f450-4d6d-a125-229b822d2993","event_type":"raw.depth_update","source":"binance_market_data_recorder","venue":"binance_usdm","market_type":"perpetual_futures","symbol":"BTCUSDT","event_time_ms":1783517079146,"received_time_ms":1783517079146,"trace_id":"b09492b4-e3f2-451a-85a7-24d5f112b55e","first_update_id":10999771709716,"final_update_id":10999771717739,"previous_final_update_id":10999771709572,"bids":[{"price":"11354.10","quantity":"2.736"},{"price":"11454.10","quantity":"1.035"},{"price":"11554.10","quantity":"0.969"},{"price":"11754.10","quantity":"0.160"},{"price":"55668.60","quantity":"0.002"},{"price":"59379.90","quantity":"0.000"},{"price":"60887.90","quantity":"3.444"},{"price":"61235.60","quantity":"0.330"},{"price":"61283.10","quantity":"0.163"},{"price":"61806.70","quantity":"0.010"},{"price":"61806.90","quantity":"2.221"},{"price":"61807.00","quantity":"0.005"},{"price":"61808.70","quantity":"0.922"},{"price":"61808.80","quantity":"0.452"},{"price":"61809.90","quantity":"0.101"},{"price":"61814.70","quantity":"0.002"},{"price":"61814.80","quantity":"0.006"},{"price":"61819.60","quantity":"0.000"},{"price":"61819.90","quantity":"0.004"},{"price":"61820.60","quantity":"0.200"},{"price":"61821.20","quantity":"0.341"},{"price":"61823.50","quantity":"0.017"},{"price":"61823.90","quantity":"0.000"},{"price":"61824.50","quantity":"0.332"},{"price":"61824.80","quantity":"0.001"},{"price":"61825.10","quantity":"0.315"},{"price":"61830.30","quantity":"0.170"},{"price":"61830.50","quantity":"0.003"},{"price":"61838.00","quantity":"0.000"},{"price":"61838.70","quantity":"0.001"},{"price":"61840.50","quantity":"2.138"},{"price":"61840.70","quantity":"1.123"},{"price":"61842.50","quantity":"0.002"},{"price":"61843.00","quantity":"2.266"},{"price":"61844.00","quantity":"0.384"},{"price":"61845.90","quantity":"0.001"},{"price":"61846.10","quantity":"0.421"},{"price":"61849.10","quantity":"0.133"},{"price":"61850.00","quantity":"1.956"},{"price":"61850.30","quantity":"0.051"},{"price":"61852.20","quantity":"0.123"},{"price":"61853.70","quantity":"0.045"},{"price":"61853.90","quantity":"0.002"},{"price":"61854.00","quantity":"0.004"},{"price":"61854.10","quantity":"3.113"}],"asks":[{"price":"61854.20","quantity":"7.941"},{"price":"61859.50","quantity":"1.308"},{"price":"61860.30","quantity":"0.201"},{"price":"61860.40","quantity":"0.856"},{"price":"61860.80","quantity":"0.137"},{"price":"61863.90","quantity":"2.242"},{"price":"61865.30","quantity":"0.327"},{"price":"61866.50","quantity":"0.125"},{"price":"61866.60","quantity":"3.457"},{"price":"61868.70","quantity":"0.081"},{"price":"61871.60","quantity":"0.007"},{"price":"61872.80","quantity":"0.000"},{"price":"61880.40","quantity":"0.293"},{"price":"61880.80","quantity":"0.000"},{"price":"61881.10","quantity":"0.002"},{"price":"61882.00","quantity":"3.598"},{"price":"61882.30","quantity":"0.000"},{"price":"61891.20","quantity":"0.376"},{"price":"61891.40","quantity":"0.003"},{"price":"61893.20","quantity":"0.471"},{"price":"61893.40","quantity":"0.243"},{"price":"61894.40","quantity":"0.571"},{"price":"61894.60","quantity":"0.009"},{"price":"61896.30","quantity":"0.161"},{"price":"61896.60","quantity":"0.264"},{"price":"61898.00","quantity":"0.003"},{"price":"61898.10","quantity":"5.002"},{"price":"61898.30","quantity":"3.277"},{"price":"61905.90","quantity":"0.001"},{"price":"61906.00","quantity":"0.029"},{"price":"61906.20","quantity":"0.104"},{"price":"61907.70","quantity":"0.502"},{"price":"61912.10","quantity":"0.028"},{"price":"61912.20","quantity":"0.003"},{"price":"61920.50","quantity":"24.872"},{"price":"61924.70","quantity":"0.000"},{"price":"62356.00","quantity":"0.018"},{"price":"62472.70","quantity":"1.680"},{"price":"62556.80","quantity":"0.000"},{"price":"62680.00","quantity":"2.191"},{"price":"62729.90","quantity":"5.922"},{"price":"62782.80","quantity":"0.127"},{"price":"62791.80","quantity":"0.795"},{"price":"62819.70","quantity":"0.000"},{"price":"63091.20","quantity":"0.080"}],"raw":{"e":"depthUpdate","E":1783517079146,"T":1783517079145,"s":"BTCUSDT","ps":"BTCUSDT","U":10999771709716,"u":10999771717739,"pu":10999771709572,"b":[["11354.10","2.736"],["11454.10","1.035"],["11554.10","0.969"],["11754.10","0.160"],["55668.60","0.002"],["59379.90","0.000"],["60887.90","3.444"],["61235.60","0.330"],["61283.10","0.163"],["61806.70","0.010"],["61806.90","2.221"],["61807.00","0.005"],["61808.70","0.922"],["61808.80","0.452"],["61809.90","0.101"],["61814.70","0.002"],["61814.80","0.006"],["61819.60","0.000"],["61819.90","0.004"],["61820.60","0.200"],["61821.20","0.341"],["61823.50","0.017"],["61823.90","0.000"],["61824.50","0.332"],["61824.80","0.001"],["61825.10","0.315"],["61830.30","0.170"],["61830.50","0.003"],["61838.00","0.000"],["61838.70","0.001"],["61840.50","2.138"],["61840.70","1.123"],["61842.50","0.002"],["61843.00","2.266"],["61844.00","0.384"],["61845.90","0.001"],["61846.10","0.421"],["61849.10","0.133"],["61850.00","1.956"],["61850.30","0.051"],["61852.20","0.123"],["61853.70","0.045"],["61853.90","0.002"],["61854.00","0.004"],["61854.10","3.113"]],"a":[["61854.20","7.941"],["61859.50","1.308"],["61860.30","0.201"],["61860.40","0.856"],["61860.80","0.137"],["61863.90","2.242"],["61865.30","0.327"],["61866.50","0.125"],["61866.60","3.457"],["61868.70","0.081"],["61871.60","0.007"],["61872.80","0.000"],["61880.40","0.293"],["61880.80","0.000"],["61881.10","0.002"],["61882.00","3.598"],["61882.30","0.000"],["61891.20","0.376"],["61891.40","0.003"],["61893.20","0.471"],["61893.40","0.243"],["61894.40","0.571"],["61894.60","0.009"],["61896.30","0.161"],["61896.60","0.264"],["61898.00","0.003"],["61898.10","5.002"],["61898.30","3.277"],["61905.90","0.001"],["61906.00","0.029"],["61906.20","0.104"],["61907.70","0.502"],["61912.10","0.028"],["61912.20","0.003"],["61920.50","24.872"],["61924.70","0.000"],["62356.00","0.018"],["62472.70","1.680"],["62556.80","0.000"],["62680.00","2.191"],["62729.90","5.922"],["62782.80","0.127"],["62791.80","0.795"],["62819.70","0.000"],["63091.20","0.080"]],"st":1}}
{"schema_version":"1.3.0","event_id":"c91c555f-e082-43e3-affe-3797f10fb2d3","event_type":"raw.depth_update","source":"binance_market_data_recorder","venue":"binance_usdm","market_type":"perpetual_futures","symbol":"BTCUSDT","event_time_ms":1783517079248,"received_time_ms":1783517079246,"trace_id":"78550bf7-5689-4e68-976b-094867f0c003","first_update_id":10999771717783,"final_update_id":10999771725099,"previous_final_update_id":10999771717739,"bids":[{"price":"11354.10","quantity":"2.720"},{"price":"11454.10","quantity":"1.043"},{"price":"11554.10","quantity":"0.833"},{"price":"11754.10","quantity":"0.304"},{"price":"55668.60","quantity":"0.002"},{"price":"58759.70","quantity":"0.000"},{"price":"60888.10","quantity":"1.004"},{"price":"61093.40","quantity":"0.001"},{"price":"61235.60","quantity":"0.328"},{"price":"61544.80","quantity":"0.029"},{"price":"61820.60","quantity":"0.260"},{"price":"61823.40","quantity":"0.069"},{"price":"61843.20","quantity":"0.331"},{"price":"61844.00","quantity":"0.061"},{"price":"61846.10","quantity":"0.050"},{"price":"61850.30","quantity":"0.704"},{"price":"61851.10","quantity":"0.000"},{"price":"61853.90","quantity":"0.005"},{"price":"61854.00","quantity":"0.006"},{"price":"61854.10","quantity":"3.133"}],"asks":[{"price":"61854.20","quantity":"7.941"},{"price":"61862.80","quantity":"0.343"},{"price":"62057.60","quantity":"0.000"},{"price":"62096.50","quantity":"0.034"},{"price":"62410.90","quantity":"5.520"},{"price":"62420.60","quantity":"2.400"},{"price":"62472.70","quantity":"1.678"},{"price":"62619.70","quantity":"4.057"},{"price":"62658.30","quantity":"7.649"},{"price":"62659.10","quantity":"0.000"},{"price":"62665.40","quantity":"1.595"},{"price":"62668.00","quantity":"3.623"},{"price":"62678.40","quantity":"1.076"},{"price":"62820.00","quantity":"0.292"},{"price":"63091.20","quantity":"0.083"},{"price":"89523.20","quantity":"1.086"}],"raw":{"e":"depthUpdate","E":1783517079248,"T":1783517079245,"s":"BTCUSDT","ps":"BTCUSDT","U":10999771717783,"u":10999771725099,"pu":10999771717739,"b":[["11354.10","2.720"],["11454.10","1.043"],["11554.10","0.833"],["11754.10","0.304"],["55668.60","0.002"],["58759.70","0.000"],["60888.10","1.004"],["61093.40","0.001"],["61235.60","0.328"],["61544.80","0.029"],["61820.60","0.260"],["61823.40","0.069"],["61843.20","0.331"],["61844.00","0.061"],["61846.10","0.050"],["61850.30","0.704"],["61851.10","0.000"],["61853.90","0.005"],["61854.00","0.006"],["61854.10","3.133"]],"a":[["61854.20","7.941"],["61862.80","0.343"],["62057.60","0.000"],["62096.50","0.034"],["62410.90","5.520"],["62420.60","2.400"],["62472.70","1.678"],["62619.70","4.057"],["62658.30","7.649"],["62659.10","0.000"],["62665.40","1.595"],["62668.00","3.623"],["62678.40","1.076"],["62820.00","0.292"],["63091.20","0.083"],["89523.20","1.086"]],"st":1}}
{"schema_version":"1.3.0","event_id":"324d7050-fac2-4e0a-8184-29da9404e49a","event_type":"raw.depth_update","source":"binance_market_data_recorder","venue":"binance_usdm","market_type":"perpetual_futures","symbol":"BTCUSDT","event_time_ms":1783517079350,"received_time_ms":1783517079345,"trace_id":"2a6b669f-4ad0-4b03-83e7-84909aa560bf","first_update_id":10999771725321,"final_update_id":10999771732122,"previous_final_update_id":10999771725099,"bids":[{"price":"1000.00","quantity":"207.692"},{"price":"11354.10","quantity":"2.736"},{"price":"11454.10","quantity":"1.052"},{"price":"11554.10","quantity":"0.680"},{"price":"11754.10","quantity":"0.432"},{"price":"49483.00","quantity":"0.004"},{"price":"55668.60","quantity":"0.002"},{"price":"58761.40","quantity":"0.028"},{"price":"59379.90","quantity":"0.003"},{"price":"61235.60","quantity":"0.328"},{"price":"61835.70","quantity":"0.165"},{"price":"61841.90","quantity":"0.501"},{"price":"61853.80","quantity":"0.007"},{"price":"61853.90","quantity":"0.002"},{"price":"61854.00","quantity":"0.004"},{"price":"61854.10","quantity":"3.060"}],"asks":[{"price":"61854.20","quantity":"7.940"},{"price":"61861.80","quantity":"0.156"},{"price":"61862.70","quantity":"2.745"},{"price":"61862.90","quantity":"0.968"},{"price":"61865.00","quantity":"0.003"},{"price":"61866.60","quantity":"3.538"},{"price":"61867.40","quantity":"0.061"},{"price":"61868.80","quantity":"0.140"},{"price":"61872.80","quantity":"0.162"},{"price":"61879.00","quantity":"1.040"},{"price":"61883.50","quantity":"0.937"},{"price":"61884.40","quantity":"0.497"},{"price":"61893.30","quantity":"0.100"},{"price":"61907.70","quantity":"0.401"},{"price":"62307.60","quantity":"0.171"},{"price":"62309.40","quantity":"0.001"},{"price":"62472.70","quantity":"1.678"},{"price":"62487.60","quantity":"0.001"},{"price":"62555.40","quantity":"3.406"},{"price":"62677.80","quantity":"0.003"},{"price":"62751.10","quantity":"3.183"},{"price":"62782.10","quantity":"0.930"},{"price":"62796.90","quantity":"0.796"},{"price":"63091.20","quantity":"0.077"}],"raw":{"e":"depthUpdate","E":1783517079350,"T":1783517079349,"s":"BTCUSDT","ps":"BTCUSDT","U":10999771725321,"u":10999771732122,"pu":10999771725099,"b":[["1000.00","207.692"],["11354.10","2.736"],["11454.10","1.052"],["11554.10","0.680"],["11754.10","0.432"],["49483.00","0.004"],["55668.60","0.002"],["58761.40","0.028"],["59379.90","0.003"],["61235.60","0.328"],["61835.70","0.165"],["61841.90","0.501"],["61853.80","0.007"],["61853.90","0.002"],["61854.00","0.004"],["61854.10","3.060"]],"a":[["61854.20","7.940"],["61861.80","0.156"],["61862.70","2.745"],["61862.90","0.968"],["61865.00","0.003"],["61866.60","3.538"],["61867.40","0.061"],["61868.80","0.140"],["61872.80","0.162"],["61879.00","1.040"],["61883.50","0.937"],["61884.40","0.497"],["61893.30","0.100"],["61907.70","0.401"],["62307.60","0.171"],["62309.40","0.001"],["62472.70","1.678"],["62487.60","0.001"],["62555.40","3.406"],["62677.80","0.003"],["62751.10","3.183"],["62782.10","0.930"],["62796.90","0.796"],["63091.20","0.077"]],"st":1}}
{"schema_version":"1.3.0","event_id":"c631c0bd-4cd0-4f5c-825f-11d4acacbcf8","event_type":"raw.depth_update","source":"binance_market_data_recorder","venue":"binance_usdm","market_type":"perpetual_futures","symbol":"BTCUSDT","event_time_ms":1783517079452,"received_time_ms":1783517079450,"trace_id":"f3e6b137-85c7-4c37-9364-70575e148d31","first_update_id":10999771732185,"final_update_id":10999771739342,"previous_final_update_id":10999771732122,"bids":[{"price":"11354.10","quantity":"2.528"},{"price":"11454.10","quantity":"1.156"},{"price":"11554.10","quantity":"0.544"},{"price":"11754.10","quantity":"0.672"},{"price":"49483.00","quantity":"0.000"},{"price":"55668.60","quantity":"0.002"},{"price":"59379.90","quantity":"0.000"},{"price":"60927.00","quantity":"1.720"},{"price":"61019.10","quantity":"3.678"},{"price":"61118.00","quantity":"5.915"},{"price":"61235.60","quantity":"0.328"},{"price":"61489.80","quantity":"0.006"},{"price":"61491.40","quantity":"0.321"},{"price":"61537.60","quantity":"0.348"},{"price":"61544.80","quantity":"0.028"},{"price":"61582.20","quantity":"0.010"},{"price":"61583.10","quantity":"0.499"},{"price":"61792.20","quantity":"0.327"},{"price":"61800.90","quantity":"0.005"},{"price":"61811.20","quantity":"0.028"},{"price":"61835.70","quantity":"0.003"},{"price":"61835.90","quantity":"1.054"},{"price":"61836.00","quantity":"0.064"},{"price":"61836.10","quantity":"0.001"},{"price":"61841.90","quantity":"0.420"},{"price":"61853.80","quantity":"0.002"},{"price":"61853.90","quantity":"0.005"},{"price":"61854.00","quantity":"0.006"},{"price":"61854.10","quantity":"3.062"}],"asks":[{"price":"61862.10","quantity":"0.091"},{"price":"61866.60","quantity":"3.457"},{"price":"61868.80","quantity":"0.060"},{"price":"61872.80","quantity":"0.000"},{"price":"61916.10","quantity":"0.001"},{"price":"62127.10","quantity":"0.196"},{"price":"62127.20","quantity":"0.000"},{"price":"62127.80","quantity":"0.000"},{"price":"62220.50","quantity":"0.363"},{"price":"62220.90","quantity":"0.000"},{"price":"62221.00","quantity":"0.000"},{"price":"62332.90","quantity":"1.032"},{"price":"62400.00","quantity":"13.522"},{"price":"62410.90","quantity":"7.519"},{"price":"62472.70","quantity":"1.678"},{"price":"62476.20","quantity":"4.320"},{"price":"62627.40","quantity":"2.181"},{"price":"62658.30","quantity":"9.640"},{"price":"62689.20","quantity":"1.993"},{"price":"62770.60","quantity":"0.002"},{"price":"62782.00","quantity":"2.942"},{"price":"89523.20","quantity":"1.092"}],"raw":{"e":"depthUpdate","E":1783517079452,"T":1783517079449,"s":"BTCUSDT","ps":"BTCUSDT","U":10999771732185,"u":10999771739342,"pu":10999771732122,"b":[["11354.10","2.528"],["11454.10","1.156"],["11554.10","0.544"],["11754.10","0.672"],["49483.00","0.000"],["55668.60","0.002"],["59379.90","0.000"],["60927.00","1.720"],["61019.10","3.678"],["61118.00","5.915"],["61235.60","0.328"],["61489.80","0.006"],["61491.40","0.321"],["61537.60","0.348"],["61544.80","0.028"],["61582.20","0.010"],["61583.10","0.499"],["61792.20","0.327"],["61800.90","0.005"],["61811.20","0.028"],["61835.70","0.003"],["61835.90","1.054"],["61836.00","0.064"],["61836.10","0.001"],["61841.90","0.420"],["61853.80","0.002"],["61853.90","0.005"],["61854.00","0.006"],["61854.10","3.062"]],"a":[["61862.10","0.091"],["61866.60","3.457"],["61868.80","0.060"],["61872.80","0.000"],["61916.10","0.001"],["62127.10","0.196"],["62127.20","0.000"],["62127.80","0.000"],["62220.50","0.363"],["62220.90","0.000"],["62221.00","0.000"],["62332.90","1.032"],["62400.00","13.522"],["62410.90","7.519"],["62472.70","1.678"],["62476.20","4.320"],["62627.40","2.181"],["62658.30","9.640"],["62689.20","1.993"],["62770.60","0.002"],["62782.00","2.942"],["89523.20","1.092"]],"st":1}}
{"schema_version":"1.3.0","event_id":"65fb1d31-95b7-4ded-91b4-699a46ba3295","event_type":"raw.depth_update","source":"binance_market_data_recorder","venue":"binance_usdm","market_type":"perpetual_futures","symbol":"BTCUSDT","event_time_ms":1783517079554,"received_time_ms":1783517079550,"trace_id":"a38ed8c8-1f82-4123-af76-a639d95ffc53","first_update_id":10999771739592,"final_update_id":10999771748208,"previous_final_update_id":10999771739342,"bids":[{"price":"1000.00","quantity":"207.692"},{"price":"11354.10","quantity":"2.256"},{"price":"11454.10","quantity":"1.309"},{"price":"11554.10","quantity":"0.391"},{"price":"11754.10","quantity":"0.944"},{"price":"49483.00","quantity":"0.000"},{"price":"55668.60","quantity":"0.002"},{"price":"59379.90","quantity":"0.003"},{"price":"61235.60","quantity":"0.328"},{"price":"61544.80","quantity":"0.039"},{"price":"61723.70","quantity":"0.299"},{"price":"61751.30","quantity":"0.066"},{"price":"61751.40","quantity":"0.023"},{"price":"61853.80","quantity":"0.007"},{"price":"61853.90","quantity":"0.002"},{"price":"61854.00","quantity":"0.004"},{"price":"61854.10","quantity":"3.424"}],"asks":[{"price":"61854.20","quantity":"7.919"},{"price":"61862.70","quantity":"2.746"},{"price":"61866.50","quantity":"0.190"},{"price":"61866.60","quantity":"3.392"},{"price":"61879.00","quantity":"0.717"},{"price":"61880.80","quantity":"0.062"},{"price":"61985.10","quantity":"0.725"},{"price":"62029.60","quantity":"0.013"},{"price":"62029.70","quantity":"0.003"},{"price":"62163.50","quantity":"2.409"},{"price":"62308.00","quantity":"0.120"},{"price":"62410.90","quantity":"9.919"},{"price":"62472.70","quantity":"1.678"},{"price":"62658.30","quantity":"12.349"},{"price":"62666.80","quantity":"8.231"},{"price":"62782.00","quantity":"6.123"},{"price":"63091.20","quantity":"0.074"}],"raw":{"e":"depthUpdate","E":1783517079554,"T":1783517079553,"s":"BTCUSDT","ps":"BTCUSDT","U":10999771739592,"u":10999771748208,"pu":10999771739342,"b":[["1000.00","207.692"],["11354.10","2.256"],["11454.10","1.309"],["11554.10","0.391"],["11754.10","0.944"],["49483.00","0.000"],["55668.60","0.002"],["59379.90","0.003"],["61235.60","0.328"],["61544.80","0.039"],["61723.70","0.299"],["61751.30","0.066"],["61751.40","0.023"],["61853.80","0.007"],["61853.90","0.002"],["61854.00","0.004"],["61854.10","3.424"]],"a":[["61854.20","7.919"],["61862.70","2.746"],["61866.50","0.190"],["61866.60","3.392"],["61879.00","0.717"],["61880.80","0.062"],["61985.10","0.725"],["62029.60","0.013"],["62029.70","0.003"],["62163.50","2.409"],["62308.00","0.120"],["62410.90","9.919"],["62472.70","1.678"],["62658.30","12.349"],["62666.80","8.231"],["62782.00","6.123"],["63091.20","0.074"]],"st":1}}
{"schema_version":"1.3.0","event_id":"aec9f119-d58d-4817-8c72-b198760c242e","event_type":"raw.depth_update","source":"binance_market_data_recorder","venue":"binance_usdm","market_type":"perpetual_futures","symbol":"BTCUSDT","event_time_ms":1783517079656,"received_time_ms":1783517079651,"trace_id":"aac601cb-850c-4893-a866-5ac40c9cc08e","first_update_id":10999771748301,"final_update_id":10999771757072,"previous_final_update_id":10999771748208,"bids":[{"price":"1000.00","quantity":"207.692"},{"price":"11354.10","quantity":"1.984"},{"price":"11454.10","quantity":"1.445"},{"price":"11554.10","quantity":"0.255"},{"price":"11754.10","quantity":"1.216"},{"price":"55668.60","quantity":"0.002"},{"price":"59379.90","quantity":"0.000"},{"price":"60617.10","quantity":"0.033"},{"price":"61235.60","quantity":"0.328"},{"price":"61237.90","quantity":"0.000"},{"price":"61379.10","quantity":"0.000"},{"price":"61809.90","quantity":"0.000"},{"price":"61810.10","quantity":"0.005"},{"price":"61810.40","quantity":"0.113"},{"price":"61839.30","quantity":"0.006"},{"price":"61846.10","quantity":"0.050"},{"price":"61847.90","quantity":"0.000"},{"price":"61848.00","quantity":"0.748"},{"price":"61853.70","quantity":"0.040"},{"price":"61853.80","quantity":"0.002"},{"price":"61853.90","quantity":"0.005"},{"price":"61854.00","quantity":"0.006"},{"price":"61854.10","quantity":"3.440"}],"asks":[{"price":"61854.20","quantity":"7.444"},{"price":"61854.70","quantity":"0.023"},{"price":"61855.90","quantity":"0.324"},{"price":"61856.80","quantity":"0.001"},{"price":"61856.90","quantity":"1.941"},{"price":"61857.40","quantity":"0.005"},{"price":"61858.00","quantity":"0.976"},{"price":"61860.50","quantity":"1.785"},{"price":"61860.80","quantity":"0.133"},{"price":"61863.90","quantity":"1.660"},{"price":"61865.40","quantity":"0.582"},{"price":"61865.80","quantity":"0.006"},{"price":"61905.40","quantity":"0.029"},{"price":"62333.00","quantity":"0.690"},{"price":"62472.70","quantity":"4.076"},{"price":"62476.30","quantity":"0.000"},{"price":"62666.20","quantity":"1.594"},{"price":"62732.50","quantity":"0.834"},{"price":"62780.60","quantity":"0.794"},{"price":"63091.20","quantity":"0.074"},{"price":"89523.20","quantity":"1.098"}],"raw":{"e":"depthUpdate","E":1783517079656,"T":1783517079654,"s":"BTCUSDT","ps":"BTCUSDT","U":10999771748301,"u":10999771757072,"pu":10999771748208,"b":[["1000.00","207.692"],["11354.10","1.984"],["11454.10","1.445"],["11554.10","0.255"],["11754.10","1.216"],["55668.60","0.002"],["59379.90","0.000"],["60617.10","0.033"],["61235.60","0.328"],["61237.90","0.000"],["61379.10","0.000"],["61809.90","0.000"],["61810.10","0.005"],["61810.40","0.113"],["61839.30","0.006"],["61846.10","0.050"],["61847.90","0.000"],["61848.00","0.748"],["61853.70","0.040"],["61853.80","0.002"],["61853.90","0.005"],["61854.00","0.006"],["61854.10","3.440"]],"a":[["61854.20","7.444"],["61854.70","0.023"],["61855.90","0.324"],["61856.80","0.001"],["61856.90","1.941"],["61857.40","0.005"],["61858.00","0.976"],["61860.50","1.785"],["61860.80","0.133"],["61863.90","1.660"],["61865.40","0.582"],["61865.80","0.006"],["61905.40","0.029"],["62333.00","0.690"],["62472.70","4.076"],["62476.30","0.000"],["62666.20","1.594"],["62732.50","0.834"],["62780.60","0.794"],["63091.20","0.074"],["89523.20","1.098"]],"st":1}}
{"schema_version":"1.3.0","event_id":"b1993d20-2e34-4009-9b2a-9b8fed805fff","event_type":"raw.depth_update","source":"binance_market_data_recorder","venue":"binance_usdm","market_type":"perpetual_futures","symbol":"BTCUSDT","event_time_ms":1783517079758,"received_time_ms":1783517079753,"trace_id":"43a66181-7701-4956-9f13-8bec496a473d","first_update_id":10999771757201,"final_update_id":10999771765187,"previous_final_update_id":10999771757072,"bids":[{"price":"11354.10","quantity":"1.712"},{"price":"11454.10","quantity":"1.598"},{"price":"11554.10","quantity":"0.102"},{"price":"11754.10","quantity":"1.488"},{"price":"55668.60","quantity":"0.002"},{"price":"60617.10","quantity":"0.030"},{"price":"60926.30","quantity":"1.476"},{"price":"61054.20","quantity":"5.233"},{"price":"61235.60","quantity":"0.328"},{"price":"61789.00","quantity":"6.211"},{"price":"61797.10","quantity":"0.126"},{"price":"61804.70","quantity":"0.213"},{"price":"61808.70","quantity":"0.821"},{"price":"61808.80","quantity":"0.351"},{"price":"61846.10","quantity":"0.050"},{"price":"61847.90","quantity":"0.003"},{"price":"61848.00","quantity":"0.745"},{"price":"61853.80","quantity":"0.007"},{"price":"61853.90","quantity":"0.002"},{"price":"61854.00","quantity":"0.004"},{"price":"61854.10","quantity":"3.460"}],"asks":[{"price":"61854.20","quantity":"7.453"},{"price":"61860.60","quantity":"0.371"},{"price":"61863.80","quantity":"0.324"},{"price":"61865.30","quantity":"0.893"},{"price":"61866.50","quantity":"0.069"},{"price":"61868.10","quantity":"0.152"},{"price":"61884.40","quantity":"0.495"},{"price":"61893.20","quantity":"0.264"},{"price":"61893.50","quantity":"0.580"},{"price":"61906.20","quantity":"0.003"},{"price":"61919.90","quantity":"6.666"},{"price":"62056.60","quantity":"4.707"},{"price":"62056.70","quantity":"28.836"},{"price":"62056.90","quantity":"0.000"},{"price":"62472.70","quantity":"4.076"},{"price":"62540.60","quantity":"0.000"},{"price":"62663.80","quantity":"1.116"}],"raw":{"e":"depthUpdate","E":1783517079758,"T":1783517079757,"s":"BTCUSDT","ps":"BTCUSDT","U":10999771757201,"u":10999771765187,"pu":10999771757072,"b":[["11354.10","1.712"],["11454.10","1.598"],["11554.10","0.102"],["11754.10","1.488"],["55668.60","0.002"],["60617.10","0.030"],["60926.30","1.476"],["61054.20","5.233"],["61235.60","0.328"],["61789.00","6.211"],["61797.10","0.126"],["61804.70","0.213"],["61808.70","0.821"],["61808.80","0.351"],["61846.10","0.050"],["61847.90","0.003"],["61848.00","0.745"],["61853.80","0.007"],["61853.90","0.002"],["61854.00","0.004"],["61854.10","3.460"]],"a":[["61854.20","7.453"],["61860.60","0.371"],["61863.80","0.324"],["61865.30","0.893"],["61866.50","0.069"],["61868.10","0.152"],["61884.40","0.495"],["61893.20","0.264"],["61893.50","0.580"],["61906.20","0.003"],["61919.90","6.666"],["62056.60","4.707"],["62056.70","28.836"],["62056.90","0.000"],["62472.70","4.076"],["62540.60","0.000"],["62663.80","1.116"]],"st":1}}
{"schema_version":"1.3.0","event_id":"560802a0-bfb6-4224-9e6a-7774a4139185","event_type":"raw.depth_update","source":"binance_market_data_recorder","venue":"binance_usdm","market_type":"perpetual_futures","symbol":"BTCUSDT","event_time_ms":1783517079860,"received_time_ms":1783517079855,"trace_id":"18d296f6-0f10-467f-84f7-15e882c587a4","first_update_id":10999771765534,"final_update_id":10999771774168,"previous_final_update_id":10999771765187,"bids":[{"price":"1000.00","quantity":"207.692"},{"price":"11354.10","quantity":"1.474"},{"price":"11454.10","quantity":"1.666"},{"price":"11554.10","quantity":"0.000"},{"price":"11754.10","quantity":"1.760"},{"price":"49483.30","quantity":"0.000"},{"price":"55668.60","quantity":"0.002"},{"price":"59379.90","quantity":"0.003"},{"price":"60617.10","quantity":"0.027"},{"price":"60927.00","quantity":"0.982"},{"price":"61235.60","quantity":"0.328"},{"price":"61537.60","quantity":"0.351"},{"price":"61544.80","quantity":"0.039"},{"price":"61706.10","quantity":"0.108"},{"price":"61723.70","quantity":"0.000"},{"price":"61820.20","quantity":"0.134"},{"price":"61826.10","quantity":"1.140"},{"price":"61833.00","quantity":"0.083"},{"price":"61846.10","quantity":"0.050"},{"price":"61853.80","quantity":"0.002"},{"price":"61854.10","quantity":"3.458"}],"asks":[{"price":"61854.20","quantity":"7.903"},{"price":"61860.60","quantity":"0.537"},{"price":"61861.60","quantity":"0.164"},{"price":"61861.70","quantity":"0.782"},{"price":"61871.10","quantity":"0.074"},{"price":"61873.20","quantity":"0.699"},{"price":"61877.80","quantity":"0.073"},{"price":"61878.90","quantity":"0.002"},{"price":"61882.90","quantity":"0.186"},{"price":"61884.80","quantity":"0.772"},{"price":"61888.40","quantity":"0.842"},{"price":"61893.40","quantity":"0.243"},{"price":"61893.70","quantity":"0.868"},{"price":"61985.10","quantity":"0.000"},{"price":"62332.90","quantity":"0.168"},{"price":"62472.70","quantity":"5.293"},{"price":"62476.20","quantity":"0.000"},{"price":"62499.90","quantity":"1.364"},{"price":"62590.30","quantity":"0.000"},{"price":"63091.20","quantity":"0.068"},{"price":"63276.90","quantity":"4.955"},{"price":"89523.20","quantity":"1.104"}],"raw":{"e":"depthUpdate","E":1783517079860,"T":1783517079859,"s":"BTCUSDT","ps":"BTCUSDT","U":10999771765534,"u":10999771774168,"pu":10999771765187,"b":[["1000.00","207.692"],["11354.10","1.474"],["11454.10","1.666"],["11554.10","0.000"],["11754.10","1.760"],["49483.30","0.000"],["55668.60","0.002"],["59379.90","0.003"],["60617.10","0.027"],["60927.00","0.982"],["61235.60","0.328"],["61537.60","0.351"],["61544.80","0.039"],["61706.10","0.108"],["61723.70","0.000"],["61820.20","0.134"],["61826.10","1.140"],["61833.00","0.083"],["61846.10","0.050"],["61853.80","0.002"],["61854.10","3.458"]],"a":[["61854.20","7.903"],["61860.60","0.537"],["61861.60","0.164"],["61861.70","0.782"],["61871.10","0.074"],["61873.20","0.699"],["61877.80","0.073"],["61878.90","0.002"],["61882.90","0.186"],["61884.80","0.772"],["61888.40","0.842"],["61893.40","0.243"],["61893.70","0.868"],["61985.10","0.000"],["62332.90","0.168"],["62472.70","5.293"],["62476.20","0.000"],["62499.90","1.364"],["62590.30","0.000"],["63091.20","0.068"],["63276.90","4.955"],["89523.20","1.104"]],"st":1}}
{"schema_version":"1.3.0","event_id":"491fad0c-c49f-458f-abb3-2374084cb3d5","event_type":"raw.depth_update","source":"binance_market_data_recorder","venue":"binance_usdm","market_type":"perpetual_futures","symbol":"BTCUSDT","event_time_ms":1783517079962,"received_time_ms":1783517079958,"trace_id":"2db3fb95-c344-4f01-8ab2-abd0bd28df6b","first_update_id":10999771774217,"final_update_id":10999771781273,"previous_final_update_id":10999771774168,"bids":[{"price":"1000.00","quantity":"207.692"},{"price":"11354.10","quantity":"1.355"},{"price":"11454.10","quantity":"1.513"},{"price":"11754.10","quantity":"2.032"},{"price":"55668.60","quantity":"0.002"},{"price":"58761.40","quantity":"0.022"},{"price":"58761.50","quantity":"0.006"},{"price":"59379.90","quantity":"0.000"},{"price":"60844.70","quantity":"3.287"},{"price":"60937.40","quantity":"7.866"},{"price":"60964.50","quantity":"7.319"},{"price":"61020.00","quantity":"0.470"},{"price":"61235.60","quantity":"0.328"},{"price":"61252.50","quantity":"0.000"},{"price":"61537.60","quantity":"0.348"},{"price":"61702.20","quantity":"0.163"},{"price":"61702.30","quantity":"0.585"},{"price":"61723.70","quantity":"0.297"},{"price":"61841.10","quantity":"0.003"},{"price":"61841.60","quantity":"1.066"},{"price":"61846.10","quantity":"0.421"},{"price":"61854.10","quantity":"3.463"}],"asks":[{"price":"61854.20","quantity":"7.733"},{"price":"61857.60","quantity":"0.077"},{"price":"61857.90","quantity":"0.872"},{"price":"61861.60","quantity":"0.164"},{"price":"61861.70","quantity":"0.714"},{"price":"61862.30","quantity":"0.075"},{"price":"61862.90","quantity":"1.379"},{"price":"61866.70","quantity":"0.881"},{"price":"61868.10","quantity":"0.031"},{"price":"61869.20","quantity":"0.585"},{"price":"61871.10","quantity":"0.011"},{"price":"61871.20","quantity":"0.204"},{"price":"61873.20","quantity":"0.002"},{"price":"61877.70","quantity":"0.843"},{"price":"61877.80","quantity":"0.000"},{"price":"61880.20","quantity":"0.277"},{"price":"61882.90","quantity":"0.007"},{"price":"61884.80","quantity":"0.230"},{"price":"61888.10","quantity":"0.749"},{"price":"61888.40","quantity":"0.005"},{"price":"61892.60","quantity":"0.417"},{"price":"61895.90","quantity":"0.000"},{"price":"61985.00","quantity":"0.743"},{"price":"62006.50","quantity":"1.294"},{"price":"62006.60","quantity":"0.008"},{"price":"62436.30","quantity":"0.000"},{"price":"62472.70","quantity":"4.076"},{"price":"62555.00","quantity":"0.596"},{"price":"62596.50","quantity":"0.542"},{"price":"62627.20","quantity":"0.002"},{"price":"63091.20","quantity":"0.065"},{"price":"64300.00","quantity":"7.782"}],"raw":{"e":"depthUpdate","E":1783517079962,"T":1783517079961,"s":"BTCUSDT","ps":"BTCUSDT","U":10999771774217,"u":10999771781273,"pu":10999771774168,"b":[["1000.00","207.692"],["11354.10","1.355"],["11454.10","1.513"],["11754.10","2.032"],["55668.60","0.002"],["58761.40","0.022"],["58761.50","0.006"],["59379.90","0.000"],["60844.70","3.287"],["60937.40","7.866"],["60964.50","7.319"],["61020.00","0.470"],["61235.60","0.328"],["61252.50","0.000"],["61537.60","0.348"],["61702.20","0.163"],["61702.30","0.585"],["61723.70","0.297"],["61841.10","0.003"],["61841.60","1.066"],["61846.10","0.421"],["61854.10","3.463"]],"a":[["61854.20","7.733"],["61857.60","0.077"],["61857.90","0.872"],["61861.60","0.164"],["61861.70","0.714"],["61862.30","0.075"],["61862.90","1.379"],["61866.70","0.881"],["61868.10","0.031"],["61869.20","0.585"],["61871.10","0.011"],["61871.20","0.204"],["61873.20","0.002"],["61877.70","0.843"],["61877.80","0.000"],["61880.20","0.277"],["61882.90","0.007"],["61884.80","0.230"],["61888.10","0.749"],["61888.40","0.005"],["61892.60","0.417"],["61895.90","0.000"],["61985.00","0.743"],["62006.50","1.294"],["62006.60","0.008"],["62436.30","0.000"],["62472.70","4.076"],["62555.00","0.596"],["62596.50","0.542"],["62627.20","0.002"],["63091.20","0.065"],["64300.00","7.782"]],"st":1}}
{"schema_version":"1.3.0","event_id":"3b463201-9f61-4b4a-9e60-99255622f328","event_type":"raw.depth_update","source":"binance_market_data_recorder","venue":"binance_usdm","market_type":"perpetual_futures","symbol":"BTCUSDT","event_time_ms":1783517080064,"received_time_ms":1783517080060,"trace_id":"14a49223-154f-4047-ae24-82559b82ee0c","first_update_id":10999771781327,"final_update_id":10999771788995,"previous_final_update_id":10999771781273,"bids":[{"price":"11354.10","quantity":"1.219"},{"price":"11454.10","quantity":"1.377"},{"price":"11754.10","quantity":"2.304"},{"price":"55668.60","quantity":"0.002"},{"price":"59379.90","quantity":"0.003"},{"price":"60617.10","quantity":"0.027"},{"price":"61235.60","quantity":"0.328"},{"price":"61238.90","quantity":"0.742"},{"price":"61751.40","quantity":"0.020"},{"price":"61751.50","quantity":"0.005"},{"price":"61820.20","quantity":"0.675"},{"price":"61821.00","quantity":"0.710"},{"price":"61825.10","quantity":"0.436"},{"price":"61825.60","quantity":"0.019"},{"price":"61840.70","quantity":"0.001"},{"price":"61841.60","quantity":"1.064"},{"price":"61841.70","quantity":"0.518"},{"price":"61843.00","quantity":"2.367"},{"price":"61843.30","quantity":"0.114"},{"price":"61843.40","quantity":"0.103"},{"price":"61846.10","quantity":"0.421"},{"price":"61847.20","quantity":"0.186"},{"price":"61853.90","quantity":"0.000"},{"price":"61854.00","quantity":"0.006"},{"price":"61854.10","quantity":"2.627"}],"asks":[{"price":"61854.20","quantity":"7.727"},{"price":"61856.90","quantity":"2.067"},{"price":"61860.40","quantity":"0.856"},{"price":"61860.50","quantity":"2.304"},{"price":"61862.70","quantity":"2.745"},{"price":"61862.80","quantity":"0.909"},{"price":"61865.30","quantity":"0.327"},{"price":"61865.40","quantity":"0.582"},{"price":"61866.60","quantity":"3.392"},{"price":"61868.70","quantity":"0.097"},{"price":"61872.80","quantity":"0.000"},{"price":"61875.80","quantity":"0.128"},{"price":"61885.50","quantity":"0.105"},{"price":"61896.30","quantity":"0.199"},{"price":"61904.80","quantity":"0.487"},{"price":"62029.70","quantity":"0.000"},{"price":"62029.80","quantity":"0.018"},{"price":"62472.70","quantity":"4.076"},{"price":"62657.60","quantity":"0.000"},{"price":"62729.90","quantity":"5.731"},{"price":"63091.20","quantity":"0.062"},{"price":"89523.20","quantity":"1.110"}],"raw":{"e":"depthUpdate","E":1783517080064,"T":1783517080063,"s":"BTCUSDT","ps":"BTCUSDT","U":10999771781327,"u":10999771788995,"pu":10999771781273,"b":[["11354.10","1.219"],["11454.10","1.377"],["11754.10","2.304"],["55668.60","0.002"],["59379.90","0.003"],["60617.10","0.027"],["61235.60","0.328"],["61238.90","0.742"],["61751.40","0.020"],["61751.50","0.005"],["61820.20","0.675"],["61821.00","0.710"],["61825.10","0.436"],["61825.60","0.019"],["61840.70","0.001"],["61841.60","1.064"],["61841.70","0.518"],["61843.00","2.367"],["61843.30","0.114"],["61843.40","0.103"],["61846.10","0.421"],["61847.20","0.186"],["61853.90","0.000"],["61854.00","0.006"],["61854.10","2.627"]],"a":[["61854.20","7.727"],["61856.90","2.067"],["61860.40","0.856"],["61860.50","2.304"],["61862.70","2.745"],["61862.80","0.909"],["61865.30","0.327"],["61865.40","0.582"],["61866.60","3.392"],["61868.70","0.097"],["61872.80","0.000"],["61875.80","0.128"],["61885.50","0.105"],["61896.30","0.199"],["61904.80","0.487"],["62029.70","0.000"],["62029.80","0.018"],["62472.70","4.076"],["62657.60","0.000"],["62729.90","5.731"],["63091.20","0.062"],["89523.20","1.110"]],"st":1}}
{"schema_version":"1.3.0","event_id":"f292b417-8887-41e9-b50b-e2bef733d8de","event_type":"raw.depth_update","source":"binance_market_data_recorder","venue":"binance_usdm","market_type":"perpetual_futures","symbol":"BTCUSDT","event_time_ms":1783517080166,"received_time_ms":1783517080161,"trace_id":"e57eebe1-885b-4004-beab-0cabb42fdfde","first_update_id":10999771789090,"final_update_id":10999771797161,"previous_final_update_id":10999771788995,"bids":[{"price":"1000.00","quantity":"207.692"},{"price":"11354.10","quantity":"1.100"},{"price":"11454.10","quantity":"1.224"},{"price":"11754.10","quantity":"2.576"},{"price":"55668.60","quantity":"0.002"},{"price":"59379.90","quantity":"0.000"},{"price":"60503.00","quantity":"0.085"},{"price":"60926.20","quantity":"0.765"},{"price":"60926.30","quantity":"1.845"},{"price":"60982.00","quantity":"0.857"},{"price":"60988.10","quantity":"5.469"},{"price":"61181.90","quantity":"2.091"},{"price":"61235.60","quantity":"0.328"},{"price":"61524.80","quantity":"0.406"},{"price":"61544.80","quantity":"0.039"},{"price":"61798.30","quantity":"0.531"},{"price":"61804.70","quantity":"0.003"},{"price":"61808.30","quantity":"1.216"},{"price":"61825.00","quantity":"1.427"},{"price":"61825.20","quantity":"0.583"},{"price":"61825.80","quantity":"0.000"},{"price":"61829.50","quantity":"0.879"},{"price":"61830.40","quantity":"0.050"},{"price":"61836.10","quantity":"0.009"},{"price":"61840.50","quantity":"2.138"},{"price":"61846.10","quantity":"0.421"},{"price":"61853.80","quantity":"0.002"},{"price":"61853.90","quantity":"0.002"},{"price":"61854.00","quantity":"0.004"},{"price":"61854.10","quantity":"2.627"}],"asks":[{"price":"61854.20","quantity":"8.864"},{"price":"61856.80","quantity":"0.127"},{"price":"61856.90","quantity":"1.941"},{"price":"61860.50","quantity":"2.302"},{"price":"61861.10","quantity":"1.321"},{"price":"61862.80","quantity":"0.343"},{"price":"61863.20","quantity":"0.081"},{"price":"61863.60","quantity":"0.170"},{"price":"61863.80","quantity":"0.890"},{"price":"61864.10","quantity":"0.122"},{"price":"61864.70","quantity":"0.583"},{"price":"61865.40","quantity":"0.000"},{"price":"61865.70","quantity":"0.597"},{"price":"61867.20","quantity":"0.183"},{"price":"61868.70","quantity":"0.081"},{"price":"61868.80","quantity":"0.189"},{"price":"61871.60","quantity":"0.007"},{"price":"61872.80","quantity":"0.128"},{"price":"61875.80","quantity":"0.000"},{"price":"61877.00","quantity":"0.985"},{"price":"61883.40","quantity":"0.373"},{"price":"61883.80","quantity":"0.427"},{"price":"61884.10","quantity":"1.704"},{"price":"61884.60","quantity":"0.108"},{"price":"61884.70","quantity":"0.575"},{"price":"61884.80","quantity":"0.335"},{"price":"61884.90","quantity":"0.176"},{"price":"61885.50","quantity":"0.000"},{"price":"61893.40","quantity":"0.616"},{"price":"61893.50","quantity":"0.580"},{"price":"61904.50","quantity":"0.282"},{"price":"61904.70","quantity":"0.003"},{"price":"61904.80","quantity":"0.386"},{"price":"61918.20","quantity":"0.012"},{"price":"61932.00","quantity":"1.494"},{"price":"62472.70","quantity":"4.076"},{"price":"62592.20","quantity":"4.148"},{"price":"63091.20","quantity":"0.047"}],"raw":{"e":"depthUpdate","E":1783517080166,"T":1783517080165,"s":"BTCUSDT","ps":"BTCUSDT","U":10999771789090,"u":10999771797161,"pu":10999771788995,"b":[["1000.00","207.692"],["11354.10","1.100"],["11454.10","1.224"],["11754.10","2.576"],["55668.60","0.002"],["59379.90","0.000"],["60503.00","0.085"],["60926.20","0.765"],["60926.30","1.845"],["60982.00","0.857"],["60988.10","5.469"],["61181.90","2.091"],["61235.60","0.328"],["61524.80","0.406"],["61544.80","0.039"],["61798.30","0.531"],["61804.70","0.003"],["61808.30","1.216"],["61825.00","1.427"],["61825.20","0.583"],["61825.80","0.000"],["61829.50","0.879"],["61830.40","0.050"],["61836.10","0.009"],["61840.50","2.138"],["61846.10","0.421"],["61853.80","0.002"],["61853.90","0.002"],["61854.00","0.004"],["61854.10","2.627"]],"a":[["61854.20","8.864"],["61856.80","0.127"],["61856.90","1.941"],["61860.50","2.302"],["61861.10","1.321"],["61862.80","0.343"],["61863.20","0.081"],["61863.60","0.170"],["61863.80","0.890"],["61864.10","0.122"],["61864.70","0.583"],["61865.40","0.000"],["61865.70","0.597"],["61867.20","0.183"],["61868.70","0.081"],["61868.80","0.189"],["61871.60","0.007"],["61872.80","0.128"],["61875.80","0.000"],["61877.00","0.985"],["61883.40","0.373"],["61883.80","0.427"],["61884.10","1.704"],["61884.60","0.108"],["61884.70","0.575"],["61884.80","0.335"],["61884.90","0.176"],["61885.50","0.000"],["61893.40","0.616"],["61893.50","0.580"],["61904.50","0.282"],["61904.70","0.003"],["61904.80","0.386"],["61918.20","0.012"],["61932.00","1.494"],["62472.70","4.076"],["62592.20","4.148"],["63091.20","0.047"]],"st":1}}
{"schema_version":"1.3.0","event_id":"23107d85-7e50-46e0-8901-69a5fe12bbab","event_type":"raw.depth_update","source":"binance_market_data_recorder","venue":"binance_usdm","market_type":"perpetual_futures","symbol":"BTCUSDT","event_time_ms":1783517080268,"received_time_ms":1783517080265,"trace_id":"00f3d3e8-d10f-4732-8c81-b340110a5212","first_update_id":10999771797280,"final_update_id":10999771805013,"previous_final_update_id":10999771797161,"bids":[{"price":"1000.00","quantity":"207.692"},{"price":"11354.10","quantity":"1.028"},{"price":"11454.10","quantity":"1.088"},{"price":"11654.10","quantity":"0.064"},{"price":"11754.10","quantity":"2.720"},{"price":"55668.60","quantity":"0.002"},{"price":"60864.40","quantity":"3.119"},{"price":"60957.20","quantity":"3.280"},{"price":"61011.90","quantity":"1.638"},{"price":"61235.60","quantity":"0.328"},{"price":"61823.40","quantity":"0.009"},{"price":"61840.40","quantity":"0.002"},{"price":"61841.10","quantity":"0.001"},{"price":"61846.10","quantity":"0.050"},{"price":"61847.20","quantity":"0.000"},{"price":"61853.90","quantity":"0.000"},{"price":"61854.00","quantity":"0.006"},{"price":"61854.10","quantity":"2.628"}],"asks":[{"price":"61854.90","quantity":"0.171"},{"price":"61856.80","quantity":"0.001"},{"price":"61884.90","quantity":"0.178"},{"price":"62114.30","quantity":"0.000"},{"price":"62114.40","quantity":"0.000"},{"price":"62114.50","quantity":"0.000"},{"price":"62441.80","quantity":"4.237"},{"price":"62472.70","quantity":"4.076"},{"price":"62627.40","quantity":"2.419"},{"price":"89523.20","quantity":"1.116"}],"raw":{"e":"depthUpdate","E":1783517080268,"T":1783517080265,"s":"BTCUSDT","ps":"BTCUSDT","U":10999771797280,"u":10999771805013,"pu":10999771797161,"b":[["1000.00","207.692"],["11354.10","1.028"],["11454.10","1.088"],["11654.10","0.064"],["11754.10","2.720"],["55668.60","0.002"],["60864.40","3.119"],["60957.20","3.280"],["61011.90","1.638"],["61235.60","0.328"],["61823.40","0.009"],["61840.40","0.002"],["61841.10","0.001"],["61846.10","0.050"],["61847.20","0.000"],["61853.90","0.000"],["61854.00","0.006"],["61854.10","2.628"]],"a":[["61854.90","0.171"],["61856.80","0.001"],["61884.90","0.178"],["62114.30","0.000"],["62114.40","0.000"],["62114.50","0.000"],["62441.80","4.237"],["62472.70","4.076"],["62627.40","2.419"],["89523.20","1.116"]],"st":1}}
{"schema_version":"1.3.0","event_id":"78c399b5-e4f4-4c46-a956-1317b2d5e1fe","event_type":"raw.depth_update","source":"binance_market_data_recorder","venue":"binance_usdm","market_type":"perpetual_futures","symbol":"BTCUSDT","event_time_ms":1783517080370,"received_time_ms":1783517080365,"trace_id":"af3e4cfb-a89d-4a47-b83a-45c5222a40db","first_update_id":10999771805306,"final_update_id":10999771815315,"previous_final_update_id":10999771805013,"bids":[{"price":"11354.10","quantity":"1.037"},{"price":"11454.10","quantity":"0.935"},{"price":"11654.10","quantity":"0.192"},{"price":"11754.10","quantity":"2.736"},{"price":"55668.60","quantity":"0.002"},{"price":"58761.40","quantity":"0.020"},{"price":"59379.90","quantity":"0.003"},{"price":"60617.10","quantity":"0.021"},{"price":"60897.60","quantity":"2.115"},{"price":"61073.60","quantity":"0.004"},{"price":"61093.80","quantity":"0.003"},{"price":"61097.50","quantity":"0.409"},{"price":"61235.60","quantity":"0.328"},{"price":"61321.00","quantity":"0.500"},{"price":"61537.60","quantity":"0.348"},{"price":"61835.70","quantity":"0.165"},{"price":"61841.70","quantity":"0.518"},{"price":"61841.90","quantity":"0.501"},{"price":"61846.10","quantity":"0.421"},{"price":"61853.80","quantity":"0.002"},{"price":"61853.90","quantity":"0.002"},{"price":"61854.00","quantity":"0.004"},{"price":"61854.10","quantity":"2.608"}],"asks":[{"price":"61854.20","quantity":"8.863"},{"price":"61854.40","quantity":"0.371"},{"price":"61854.90","quantity":"0.045"},{"price":"61860.60","quantity":"0.168"},{"price":"61866.60","quantity":"3.473"},{"price":"61872.80","quantity":"0.290"},{"price":"61879.00","quantity":"1.095"},{"price":"61884.60","quantity":"0.003"},{"price":"61884.70","quantity":"0.470"},{"price":"61884.80","quantity":"0.230"},{"price":"61884.90","quantity":"0.176"},{"price":"61893.80","quantity":"2.473"},{"price":"61900.00","quantity":"1.555"},{"price":"61918.20","quantity":"0.000"},{"price":"61970.00","quantity":"0.016"},{"price":"62472.70","quantity":"4.076"},{"price":"62631.00","quantity":"1.127"},{"price":"62720.20","quantity":"3.130"},{"price":"62777.50","quantity":"3.183"},{"price":"63091.20","quantity":"0.032"}],"raw":{"e":"depthUpdate","E":1783517080370,"T":1783517080368,"s":"BTCUSDT","ps":"BTCUSDT","U":10999771805306,"u":10999771815315,"pu":10999771805013,"b":[["11354.10","1.037"],["11454.10","0.935"],["11654.10","0.192"],["11754.10","2.736"],["55668.60","0.002"],["58761.40","0.020"],["59379.90","0.003"],["60617.10","0.021"],["60897.60","2.115"],["61073.60","0.004"],["61093.80","0.003"],["61097.50","0.409"],["61235.60","0.328"],["61321.00","0.500"],["61537.60","0.348"],["61835.70","0.165"],["61841.70","0.518"],["61841.90","0.501"],["61846.10","0.421"],["61853.80","0.002"],["61853.90","0.002"],["61854.00","0.004"],["61854.10","2.608"]],"a":[["61854.20","8.863"],["61854.40","0.371"],["61854.90","0.045"],["61860.60","0.168"],["61866.60","3.473"],["61872.80","0.290"],["61879.00","1.095"],["61884.60","0.003"],["61884.70","0.470"],["61884.80","0.230"],["61884.90","0.176"],["61893.80","2.473"],["61900.00","1.555"],["61918.20","0.000"],["61970.00","0.016"],["62472.70","4.076"],["62631.00","1.127"],["62720.20","3.130"],["62777.50","3.183"],["63091.20","0.032"]],"st":1}}
{"schema_version":"1.3.0","event_id":"95c07b77-d5c3-46aa-ae21-f14645dd633a","event_type":"raw.depth_update","source":"binance_market_data_recorder","venue":"binance_usdm","market_type":"perpetual_futures","symbol":"BTCUSDT","event_time_ms":1783517080472,"received_time_ms":1783517080467,"trace_id":"d0df24dd-29c1-4eaa-8515-77202d8d8746","first_update_id":10999771815500,"final_update_id":10999771822743,"previous_final_update_id":10999771815315,"bids":[{"price":"1000.00","quantity":"207.692"},{"price":"11354.10","quantity":"1.045"},{"price":"11454.10","quantity":"0.799"},{"price":"11654.10","quantity":"0.336"},{"price":"11754.10","quantity":"2.720"},{"price":"49483.00","quantity":"0.000"},{"price":"55668.60","quantity":"0.002"},{"price":"59379.90","quantity":"0.000"},{"price":"60926.30","quantity":"2.214"},{"price":"61235.60","quantity":"0.328"},{"price":"61543.40","quantity":"1.429"},{"price":"61544.80","quantity":"0.039"},{"price":"61843.40","quantity":"0.002"},{"price":"61846.10","quantity":"0.050"},{"price":"61851.00","quantity":"1.065"},{"price":"61851.60","quantity":"0.008"}],"asks":[{"price":"61854.20","quantity":"8.862"},{"price":"61856.40","quantity":"0.045"},{"price":"61857.00","quantity":"0.711"},{"price":"61883.40","quantity":"0.375"},{"price":"61883.60","quantity":"0.112"},{"price":"61884.00","quantity":"0.004"},{"price":"61884.40","quantity":"0.600"},{"price":"61884.60","quantity":"0.108"},{"price":"62163.50","quantity":"2.408"},{"price":"62396.70","quantity":"0.064"},{"price":"62406.50","quantity":"0.001"},{"price":"62446.90","quantity":"1.585"},{"price":"62472.70","quantity":"4.078"},{"price":"62676.80","quantity":"0.003"},{"price":"62900.80","quantity":"0.001"},{"price":"89523.20","quantity":"1.122"}],"raw":{"e":"depthUpdate","E":1783517080472,"T":1783517080471,"s":"BTCUSDT","ps":"BTCUSDT","U":10999771815500,"u":10999771822743,"pu":10999771815315,"b":[["1000.00","207.692"],["11354.10","1.045"],["11454.10","0.799"],["11654.10","0.336"],["11754.10","2.720"],["49483.00","0.000"],["55668.60","0.002"],["59379.90","0.000"],["60926.30","2.214"],["61235.60","0.328"],["61543.40","1.429"],["61544.80","0.039"],["61843.40","0.002"],["61846.10","0.050"],["61851.00","1.065"],["61851.60","0.008"]],"a":[["61854.20","8.862"],["61856.40","0.045"],["61857.00","0.711"],["61883.40","0.375"],["61883.60","0.112"],["61884.00","0.004"],["61884.40","0.600"],["61884.60","0.108"],["62163.50","2.408"],["62396.70","0.064"],["62406.50","0.001"],["62446.90","1.585"],["62472.70","4.078"],["62676.80","0.003"],["62900.80","0.001"],["89523.20","1.122"]],"st":1}}
{"schema_version":"1.3.0","event_id":"080e7b09-8f11-4ccb-bf6d-bd8d32e81efc","event_type":"raw.depth_update","source":"binance_market_data_recorder","venue":"binance_usdm","market_type":"perpetual_futures","symbol":"BTCUSDT","event_time_ms":1783517080574,"received_time_ms":1783517080571,"trace_id":"7467db45-aad5-4a15-bf5a-5f56403f4f97","first_update_id":10999771822798,"final_update_id":10999771830089,"previous_final_update_id":10999771822743,"bids":[{"price":"1000.00","quantity":"207.692"},{"price":"11354.10","quantity":"1.054"},{"price":"11454.10","quantity":"0.646"},{"price":"11654.10","quantity":"0.464"},{"price":"11754.10","quantity":"2.736"},{"price":"55668.60","quantity":"0.002"},{"price":"59379.90","quantity":"0.003"},{"price":"61005.30","quantity":"0.308"},{"price":"61144.10","quantity":"4.055"},{"price":"61235.60","quantity":"0.328"},{"price":"61520.00","quantity":"3.061"},{"price":"61544.80","quantity":"0.039"},{"price":"61600.00","quantity":"56.939"},{"price":"61680.00","quantity":"0.853"},{"price":"61730.90","quantity":"0.100"},{"price":"61751.50","quantity":"0.002"},{"price":"61751.60","quantity":"0.005"},{"price":"61760.00","quantity":"1.062"},{"price":"61821.10","quantity":"0.307"},{"price":"61821.90","quantity":"0.354"},{"price":"61829.20","quantity":"0.368"},{"price":"61835.70","quantity":"0.003"},{"price":"61836.10","quantity":"0.001"},{"price":"61840.00","quantity":"0.200"},{"price":"61841.70","quantity":"0.518"},{"price":"61841.90","quantity":"0.420"},{"price":"61843.00","quantity":"2.266"},{"price":"61843.30","quantity":"0.013"},{"price":"61850.00","quantity":"1.632"},{"price":"61853.90","quantity":"0.002"},{"price":"61854.10","quantity":"2.446"}],"asks":[{"price":"61854.20","quantity":"8.916"},{"price":"61860.40","quantity":"0.984"},{"price":"61866.60","quantity":"3.392"},{"price":"61872.80","quantity":"0.128"},{"price":"61872.90","quantity":"0.334"},{"price":"61879.00","quantity":"0.772"},{"price":"61884.00","quantity":"0.109"},{"price":"61884.30","quantity":"0.108"},{"price":"61884.40","quantity":"0.495"},{"price":"61884.60","quantity":"0.108"},{"price":"61893.20","quantity":"0.000"},{"price":"61893.30","quantity":"0.364"},{"price":"61896.60","quantity":"0.000"},{"price":"61920.00","quantity":"1.314"},{"price":"62000.00","quantity":"13.245"},{"price":"62029.80","quantity":"0.015"},{"price":"62029.90","quantity":"0.823"},{"price":"62080.00","quantity":"0.431"},{"price":"62082.40","quantity":"0.888"},{"price":"62160.00","quantity":"0.426"},{"price":"62163.50","quantity":"2.409"},{"price":"62240.00","quantity":"0.421"},{"price":"62472.70","quantity":"4.076"},{"price":"62647.40","quantity":"0.006"}],"raw":{"e":"depthUpdate","E":1783517080574,"T":1783517080572,"s":"BTCUSDT","ps":"BTCUSDT","U":10999771822798,"u":10999771830089,"pu":10999771822743,"b":[["1000.00","207.692"],["11354.10","1.054"],["11454.10","0.646"],["11654.10","0.464"],["11754.10","2.736"],["55668.60","0.002"],["59379.90","0.003"],["61005.30","0.308"],["61144.10","4.055"],["61235.60","0.328"],["61520.00","3.061"],["61544.80","0.039"],["61600.00","56.939"],["61680.00","0.853"],["61730.90","0.100"],["61751.50","0.002"],["61751.60","0.005"],["61760.00","1.062"],["61821.10","0.307"],["61821.90","0.354"],["61829.20","0.368"],["61835.70","0.003"],["61836.10","0.001"],["61840.00","0.200"],["61841.70","0.518"],["61841.90","0.420"],["61843.00","2.266"],["61843.30","0.013"],["61850.00","1.632"],["61853.90","0.002"],["61854.10","2.446"]],"a":[["61854.20","8.916"],["61860.40","0.984"],["61866.60","3.392"],["61872.80","0.128"],["61872.90","0.334"],["61879.00","0.772"],["61884.00","0.109"],["61884.30","0.108"],["61884.40","0.495"],["61884.60","0.108"],["61893.20","0.000"],["61893.30","0.364"],["61896.60","0.000"],["61920.00","1.314"],["62000.00","13.245"],["62029.80","0.015"],["62029.90","0.823"],["62080.00","0.431"],["62082.40","0.888"],["62160.00","0.426"],["62163.50","2.409"],["62240.00","0.421"],["62472.70","4.076"],["62647.40","0.006"]],"st":1}}
{"schema_version":"1.3.0","event_id":"edf763cc-1dc8-46ae-a7bf-1758b8d3cc47","event_type":"raw.depth_update","source":"binance_market_data_recorder","venue":"binance_usdm","market_type":"perpetual_futures","symbol":"BTCUSDT","event_time_ms":1783517080676,"received_time_ms":1783517080672,"trace_id":"53cd9429-d9a9-41c6-9295-5b24a1ec6913","first_update_id":10999771830235,"final_update_id":10999771837263,"previous_final_update_id":10999771830089,"bids":[{"price":"11354.10","quantity":"1.190"},{"price":"11454.10","quantity":"0.510"},{"price":"11654.10","quantity":"0.736"},{"price":"11754.10","quantity":"2.464"},{"price":"55668.60","quantity":"0.002"},{"price":"60815.00","quantity":"1.272"},{"price":"61015.00","quantity":"0.066"},{"price":"61046.90","quantity":"0.398"},{"price":"61050.80","quantity":"1.389"},{"price":"61073.40","quantity":"3.415"},{"price":"61089.90","quantity":"1.338"},{"price":"61118.00","quantity":"6.895"},{"price":"61235.60","quantity":"0.328"},{"price":"61337.40","quantity":"0.978"},{"price":"61377.30","quantity":"49.174"},{"price":"61488.00","quantity":"43.805"},{"price":"61488.10","quantity":"6.745"},{"price":"61520.00","quantity":"3.079"},{"price":"61580.40","quantity":"35.676"},{"price":"61600.00","quantity":"56.957"},{"price":"61648.20","quantity":"28.972"},{"price":"61648.70","quantity":"5.164"},{"price":"61680.00","quantity":"0.871"},{"price":"61760.00","quantity":"1.080"},{"price":"61834.30","quantity":"0.666"},{"price":"61835.50","quantity":"0.015"},{"price":"61838.60","quantity":"0.128"},{"price":"61840.00","quantity":"0.218"},{"price":"61841.70","quantity":"0.390"},{"price":"61854.10","quantity":"2.415"}],"asks":[{"price":"61854.20","quantity":"8.916"},{"price":"61884.60","quantity":"0.108"},{"price":"61886.50","quantity":"0.291"},{"price":"61893.30","quantity":"0.100"},{"price":"61920.00","quantity":"1.332"},{"price":"62000.00","quantity":"13.263"},{"price":"62080.00","quantity":"0.449"},{"price":"62125.00","quantity":"33.885"},{"price":"62160.00","quantity":"0.444"},{"price":"62217.80","quantity":"6.801"},{"price":"62218.20","quantity":"40.538"},{"price":"62240.00","quantity":"0.439"},{"price":"62330.10","quantity":"50.089"},{"price":"62431.10","quantity":"1.039"},{"price":"62472.70","quantity":"4.076"},{"price":"62802.20","quantity":"0.278"},{"price":"63091.20","quantity":"0.035"},{"price":"89523.20","quantity":"1.128"}],"raw":{"e":"depthUpdate","E":1783517080676,"T":1783517080675,"s":"BTCUSDT","ps":"BTCUSDT","U":10999771830235,"u":10999771837263,"pu":10999771830089,"b":[["11354.10","1.190"],["11454.10","0.510"],["11654.10","0.736"],["11754.10","2.464"],["55668.60","0.002"],["60815.00","1.272"],["61015.00","0.066"],["61046.90","0.398"],["61050.80","1.389"],["61073.40","3.415"],["61089.90","1.338"],["61118.00","6.895"],["61235.60","0.328"],["61337.40","0.978"],["61377.30","49.174"],["61488.00","43.805"],["61488.10","6.745"],["61520.00","3.079"],["61580.40","35.676"],["61600.00","56.957"],["61648.20","28.972"],["61648.70","5.164"],["61680.00","0.871"],["61760.00","1.080"],["61834.30","0.666"],["61835.50","0.015"],["61838.60","0.128"],["61840.00","0.218"],["61841.70","0.390"],["61854.10","2.415"]],"a":[["61854.20","8.916"],["61884.60","0.108"],["61886.50","0.291"],["61893.30","0.100"],["61920.00","1.332"],["62000.00","13.263"],["62080.00","0.449"],["62125.00","33.885"],["62160.00","0.444"],["62217.80","6.801"],["62218.20","40.538"],["62240.00","0.439"],["62330.10","50.089"],["62431.10","1.039"],["62472.70","4.076"],["62802.20","0.278"],["63091.20","0.035"],["89523.20","1.128"]],"st":1}}
{"schema_version":"1.3.0","event_id":"994561fc-23a1-428c-a3dc-fdba40ca5473","event_type":"raw.depth_update","source":"binance_market_data_recorder","venue":"binance_usdm","market_type":"perpetual_futures","symbol":"BTCUSDT","event_time_ms":1783517080778,"received_time_ms":1783517080773,"trace_id":"b7a6d923-aa80-4533-a1ef-3cf90aad058d","first_update_id":10999771837439,"final_update_id":10999771843804,"previous_final_update_id":10999771837263,"bids":[{"price":"1000.00","quantity":"207.692"},{"price":"11354.10","quantity":"1.343"},{"price":"11454.10","quantity":"0.357"},{"price":"11654.10","quantity":"1.008"},{"price":"11754.10","quantity":"2.192"},{"price":"55668.60","quantity":"0.002"},{"price":"59379.90","quantity":"0.000"},{"price":"60842.90","quantity":"0.000"},{"price":"60922.20","quantity":"0.011"},{"price":"61049.90","quantity":"0.654"},{"price":"61235.60","quantity":"0.328"},{"price":"61544.80","quantity":"0.039"},{"price":"61581.20","quantity":"5.785"},{"price":"61784.60","quantity":"1.763"},{"price":"61820.20","quantity":"0.675"},{"price":"61821.90","quantity":"0.414"},{"price":"61843.10","quantity":"1.058"},{"price":"61854.10","quantity":"2.418"}],"asks":[{"price":"61864.70","quantity":"0.001"},{"price":"61865.60","quantity":"0.586"},{"price":"61872.80","quantity":"0.000"},{"price":"61893.30","quantity":"0.307"},{"price":"61893.50","quantity":"0.373"},{"price":"61926.30","quantity":"2.707"},{"price":"62114.30","quantity":"0.002"},{"price":"62114.40","quantity":"0.002"},{"price":"62114.50","quantity":"0.002"},{"price":"62124.20","quantity":"5.338"},{"price":"62218.10","quantity":"0.865"},{"price":"62330.00","quantity":"4.421"},{"price":"62472.70","quantity":"4.076"},{"price":"62499.90","quantity":"0.500"},{"price":"62596.50","quantity":"0.813"},{"price":"62689.50","quantity":"0.797"},{"price":"63276.90","quantity":"0.635"}],"raw":{"e":"depthUpdate","E":1783517080778,"T":1783517080777,"s":"BTCUSDT","ps":"BTCUSDT","U":10999771837439,"u":10999771843804,"pu":10999771837263,"b":[["1000.00","207.692"],["11354.10","1.343"],["11454.10","0.357"],["11654.10","1.008"],["11754.10","2.192"],["55668.60","0.002"],["59379.90","0.000"],["60842.90","0.000"],["60922.20","0.011"],["61049.90","0.654"],["61235.60","0.328"],["61544.80","0.039"],["61581.20","5.785"],["61784.60","1.763"],["61820.20","0.675"],["61821.90","0.414"],["61843.10","1.058"],["61854.10","2.418"]],"a":[["61864.70","0.001"],["61865.60","0.586"],["61872.80","0.000"],["61893.30","0.307"],["61893.50","0.373"],["61926.30","2.707"],["62114.30","0.002"],["62114.40","0.002"],["62114.50","0.002"],["62124.20","5.338"],["62218.10","0.865"],["62330.00","4.421"],["62472.70","4.076"],["62499.90","0.500"],["62596.50","0.813"],["62689.50","0.797"],["63276.90","0.635"]],"st":1}}
{"schema_version":"1.3.0","event_id":"4a6885b4-f689-4a24-b135-7cceb1cc7c48","event_type":"raw.depth_update","source":"binance_market_data_recorder","venue":"binance_usdm","market_type":"perpetual_futures","symbol":"BTCUSDT","event_time_ms":1783517080880,"received_time_ms":1783517080875,"trace_id":"49081295-8d02-4398-b589-bb66a5d44ff9","first_update_id":10999771843904,"final_update_id":10999771851688,"previous_final_update_id":10999771843804,"bids":[{"price":"1000.00","quantity":"207.692"},{"price":"11354.10","quantity":"1.479"},{"price":"11454.10","quantity":"0.221"},{"price":"11654.10","quantity":"1.280"},{"price":"11754.10","quantity":"1.920"},{"price":"49483.30","quantity":"0.000"},{"price":"55668.60","quantity":"0.002"},{"price":"59379.90","quantity":"0.003"},{"price":"61019.10","quantity":"4.087"},{"price":"61046.70","quantity":"0.980"},{"price":"61052.40","quantity":"74.181"},{"price":"61136.30","quantity":"0.911"},{"price":"61235.60","quantity":"0.328"},{"price":"61236.10","quantity":"61.115"},{"price":"61520.00","quantity":"3.097"},{"price":"61537.60","quantity":"0.348"},{"price":"61600.00","quantity":"56.975"},{"price":"61680.00","quantity":"0.889"},{"price":"61760.00","quantity":"1.098"},{"price":"61808.30","quantity":"1.216"},{"price":"61838.60","quantity":"0.000"},{"price":"61840.00","quantity":"0.236"},{"price":"61853.90","quantity":"0.002"},{"price":"61854.00","quantity":"0.006"},{"price":"61854.10","quantity":"2.419"}],"asks":[{"price":"61863.80","quantity":"0.324"},{"price":"61865.50","quantity":"0.580"},{"price":"61885.10","quantity":"0.405"},{"price":"61904.50","quantity":"0.282"},{"price":"61920.00","quantity":"1.350"},{"price":"62000.00","quantity":"13.281"},{"price":"62080.00","quantity":"0.467"},{"price":"62160.00","quantity":"0.462"},{"price":"62240.00","quantity":"0.457"},{"price":"62421.80","quantity":"1.360"},{"price":"62472.70","quantity":"4.076"},{"price":"62473.50","quantity":"60.154"},{"price":"62572.00","quantity":"5.545"},{"price":"62660.90","quantity":"71.447"},{"price":"62685.10","quantity":"2.691"},{"price":"89523.20","quantity":"1.134"}],"raw":{"e":"depthUpdate","E":1783517080880,"T":1783517080877,"s":"BTCUSDT","ps":"BTCUSDT","U":10999771843904,"u":10999771851688,"pu":10999771843804,"b":[["1000.00","207.692"],["11354.10","1.479"],["11454.10","0.221"],["11654.10","1.280"],["11754.10","1.920"],["49483.30","0.000"],["55668.60","0.002"],["59379.90","0.003"],["61019.10","4.087"],["61046.70","0.980"],["61052.40","74.181"],["61136.30","0.911"],["61235.60","0.328"],["61236.10","61.115"],["61520.00","3.097"],["61537.60","0.348"],["61600.00","56.975"],["61680.00","0.889"],["61760.00","1.098"],["61808.30","1.216"],["61838.60","0.000"],["61840.00","0.236"],["61853.90","0.002"],["61854.00","0.006"],["61854.10","2.419"]],"a":[["61863.80","0.324"],["61865.50","0.580"],["61885.10","0.405"],["61904.50","0.282"],["61920.00","1.350"],["62000.00","13.281"],["62080.00","0.467"],["62160.00","0.462"],["62240.00","0.457"],["62421.80","1.360"],["62472.70","4.076"],["62473.50","60.154"],["62572.00","5.545"],["62660.90","71.447"],["62685.10","2.691"],["89523.20","1.134"]],"st":1}}
{"schema_version":"1.3.0","event_id":"7d42b9d0-0fdd-4816-a73c-56294438a1ff","event_type":"raw.depth_update","source":"binance_market_data_recorder","venue":"binance_usdm","market_type":"perpetual_futures","symbol":"BTCUSDT","event_time_ms":1783517080982,"received_time_ms":1783517080977,"trace_id":"56adfb5f-25ad-4f3e-81a6-09e0831e3a00","first_update_id":10999771851953,"final_update_id":10999771858303,"previous_final_update_id":10999771851688,"bids":[{"price":"11354.10","quantity":"1.632"},{"price":"11454.10","quantity":"0.068"},{"price":"11654.10","quantity":"1.552"},{"price":"11754.10","quantity":"1.648"},{"price":"55668.60","quantity":"0.002"},{"price":"59379.90","quantity":"0.000"},{"price":"60833.50","quantity":"0.936"},{"price":"60926.30","quantity":"2.623"},{"price":"61049.90","quantity":"0.981"},{"price":"61050.00","quantity":"6.326"},{"price":"61235.60","quantity":"0.328"},{"price":"61239.50","quantity":"3.033"},{"price":"61273.50","quantity":"3.313"},{"price":"61723.70","quantity":"0.000"},{"price":"61825.20","quantity":"0.001"},{"price":"61826.40","quantity":"1.463"},{"price":"61844.80","quantity":"0.145"},{"price":"61853.90","quantity":"0.002"},{"price":"61854.00","quantity":"0.004"},{"price":"61854.10","quantity":"2.840"}],"asks":[{"price":"61854.20","quantity":"8.860"},{"price":"61860.40","quantity":"0.856"},{"price":"61872.90","quantity":"0.070"},{"price":"61884.90","quantity":"0.178"},{"price":"61893.40","quantity":"0.409"},{"price":"61893.50","quantity":"0.580"},{"price":"61896.60","quantity":"0.264"},{"price":"61985.00","quantity":"0.018"},{"price":"62000.60","quantity":"0.012"},{"price":"62016.80","quantity":"1.019"},{"price":"62391.50","quantity":"0.000"},{"price":"62472.70","quantity":"4.076"},{"price":"62627.40","quantity":"2.657"},{"price":"63091.20","quantity":"0.029"}],"raw":{"e":"depthUpdate","E":1783517080982,"T":1783517080981,"s":"BTCUSDT","ps":"BTCUSDT","U":10999771851953,"u":10999771858303,"pu":10999771851688,"b":[["11354.10","1.632"],["11454.10","0.068"],["11654.10","1.552"],["11754.10","1.648"],["55668.60","0.002"],["59379.90","0.000"],["60833.50","0.936"],["60926.30","2.623"],["61049.90","0.981"],["61050.00","6.326"],["61235.60","0.328"],["61239.50","3.033"],["61273.50","3.313"],["61723.70","0.000"],["61825.20","0.001"],["61826.40","1.463"],["61844.80","0.145"],["61853.90","0.002"],["61854.00","0.004"],["61854.10","2.840"]],"a":[["61854.20","8.860"],["61860.40","0.856"],["61872.90","0.070"],["61884.90","0.178"],["61893.40","0.409"],["61893.50","0.580"],["61896.60","0.264"],["61985.00","0.018"],["62000.60","0.012"],["62016.80","1.019"],["62391.50","0.000"],["62472.70","4.076"],["62627.40","2.657"],["63091.20","0.029"]],"st":1}}
{"schema_version":"1.3.0","event_id":"329631a6-17a4-4f8b-bca0-5e3e186d1343","event_type":"raw.depth_update","source":"binance_market_data_recorder","venue":"binance_usdm","market_type":"perpetual_futures","symbol":"BTCUSDT","event_time_ms":1783517081084,"received_time_ms":1783517081082,"trace_id":"034f0df5-ced3-42b5-86f0-84ac59448c2c","first_update_id":10999771858380,"final_update_id":10999771864075,"previous_final_update_id":10999771858303,"bids":[{"price":"1000.00","quantity":"207.692"},{"price":"11354.10","quantity":"1.632"},{"price":"11454.10","quantity":"0.000"},{"price":"11654.10","quantity":"1.824"},{"price":"11754.10","quantity":"1.444"},{"price":"55668.60","quantity":"0.002"},{"price":"59379.90","quantity":"0.003"},{"price":"61235.60","quantity":"0.328"},{"price":"61544.80","quantity":"0.029"},{"price":"61723.80","quantity":"0.299"},{"price":"61751.60","quantity":"0.002"},{"price":"61751.70","quantity":"0.013"},{"price":"61820.20","quantity":"0.239"},{"price":"61840.70","quantity":"0.009"},{"price":"61843.00","quantity":"2.266"},{"price":"61843.40","quantity":"0.103"},{"price":"61854.10","quantity":"2.835"}],"asks":[{"price":"61854.20","quantity":"8.859"},{"price":"61860.40","quantity":"0.856"},{"price":"61863.70","quantity":"0.170"},{"price":"61865.30","quantity":"0.327"},{"price":"61866.60","quantity":"3.392"},{"price":"61868.70","quantity":"0.098"},{"price":"61872.80","quantity":"0.000"},{"price":"61884.90","quantity":"0.178"},{"price":"61889.20","quantity":"3.460"},{"price":"61896.20","quantity":"0.531"},{"price":"61934.50","quantity":"0.001"},{"price":"61985.00","quantity":"0.743"},{"price":"62029.90","quantity":"0.820"},{"price":"62030.00","quantity":"0.163"},{"price":"62070.40","quantity":"0.018"},{"price":"62432.90","quantity":"0.001"},{"price":"62472.70","quantity":"4.076"},{"price":"62486.70","quantity":"0.151"},{"price":"89523.20","quantity":"1.140"}],"raw":{"e":"depthUpdate","E":1783517081084,"T":1783517081081,"s":"BTCUSDT","ps":"BTCUSDT","U":10999771858380,"u":10999771864075,"pu":10999771858303,"b":[["1000.00","207.692"],["11354.10","1.632"],["11454.10","0.000"],["11654.10","1.824"],["11754.10","1.444"],["55668.60","0.002"],["59379.90","0.003"],["61235.60","0.328"],["61544.80","0.029"],["61723.80","0.299"],["61751.60","0.002"],["61751.70","0.013"],["61820.20","0.239"],["61840.70","0.009"],["61843.00","2.266"],["61843.40","0.103"],["61854.10","2.835"]],"a":[["61854.20","8.859"],["61860.40","0.856"],["61863.70","0.170"],["61865.30","0.327"],["61866.60","3.392"],["61868.70","0.098"],["61872.80","0.000"],["61884.90","0.178"],["61889.20","3.460"],["61896.20","0.531"],["61934.50","0.001"],["61985.00","0.743"],["62029.90","0.820"],["62030.00","0.163"],["62070.40","0.018"],["62432.90","0.001"],["62472.70","4.076"],["62486.70","0.151"],["89523.20","1.140"]],"st":1}}
{"schema_version":"1.3.0","event_id":"49a31585-435e-481a-b0cb-c039aa98105b","event_type":"raw.depth_update","source":"binance_market_data_recorder","venue":"binance_usdm","market_type":"perpetual_futures","symbol":"BTCUSDT","event_time_ms":1783517081186,"received_time_ms":1783517081239,"trace_id":"edcd97fd-406c-4db9-95f7-f6d058d99c3b","first_update_id":10999771864417,"final_update_id":10999771874597,"previous_final_update_id":10999771864075,"bids":[{"price":"1000.00","quantity":"207.692"},{"price":"11354.10","quantity":"1.479"},{"price":"11654.10","quantity":"2.096"},{"price":"11754.10","quantity":"1.325"},{"price":"55668.60","quantity":"0.002"},{"price":"58761.40","quantity":"0.023"},{"price":"60968.30","quantity":"13.984"},{"price":"61050.80","quantity":"1.062"},{"price":"61073.40","quantity":"3.138"},{"price":"61235.60","quantity":"0.328"},{"price":"61755.90","quantity":"0.002"},{"price":"61768.30","quantity":"0.037"},{"price":"61780.70","quantity":"0.054"},{"price":"61793.10","quantity":"0.032"},{"price":"61798.30","quantity":"0.321"},{"price":"61800.00","quantity":"22.042"},{"price":"61805.30","quantity":"1.311"},{"price":"61806.10","quantity":"4.719"},{"price":"61808.10","quantity":"0.000"},{"price":"61825.10","quantity":"0.315"},{"price":"61825.80","quantity":"0.582"},{"price":"61826.40","quantity":"1.002"},{"price":"61830.20","quantity":"1.299"},{"price":"61840.50","quantity":"2.138"},{"price":"61843.00","quantity":"2.268"},{"price":"61843.30","quantity":"0.114"},{"price":"61843.50","quantity":"0.103"},{"price":"61850.60","quantity":"0.324"},{"price":"61853.90","quantity":"0.005"},{"price":"61854.10","quantity":"3.279"}],"asks":[{"price":"61854.20","quantity":"8.860"},{"price":"61866.70","quantity":"0.760"},{"price":"61867.30","quantity":"0.123"},{"price":"61868.70","quantity":"0.081"},{"price":"61871.60","quantity":"0.007"},{"price":"61883.40","quantity":"0.373"},{"price":"61883.60","quantity":"0.110"},{"price":"61884.00","quantity":"0.002"},{"price":"61884.30","quantity":"0.003"},{"price":"61884.90","quantity":"0.176"},{"price":"61886.50","quantity":"0.664"},{"price":"61888.90","quantity":"1.467"},{"price":"61893.40","quantity":"0.036"},{"price":"61893.50","quantity":"0.207"},{"price":"61904.40","quantity":"0.128"},{"price":"61932.10","quantity":"0.000"},{"price":"62410.90","quantity":"10.159"},{"price":"62472.70","quantity":"4.076"},{"price":"62472.80","quantity":"0.214"},{"price":"62514.20","quantity":"2.076"},{"price":"62596.50","quantity":"2.409"},{"price":"62746.30","quantity":"0.000"}],"raw":{"e":"depthUpdate","E":1783517081186,"T":1783517081185,"s":"BTCUSDT","ps":"BTCUSDT","U":10999771864417,"u":10999771874597,"pu":10999771864075,"b":[["1000.00","207.692"],["11354.10","1.479"],["11654.10","2.096"],["11754.10","1.325"],["55668.60","0.002"],["58761.40","0.023"],["60968.30","13.984"],["61050.80","1.062"],["61073.40","3.138"],["61235.60","0.328"],["61755.90","0.002"],["61768.30","0.037"],["61780.70","0.054"],["61793.10","0.032"],["61798.30","0.321"],["61800.00","22.042"],["61805.30","1.311"],["61806.10","4.719"],["61808.10","0.000"],["61825.10","0.315"],["61825.80","0.582"],["61826.40","1.002"],["61830.20","1.299"],["61840.50","2.138"],["61843.00","2.268"],["61843.30","0.114"],["61843.50","0.103"],["61850.60","0.324"],["61853.90","0.005"],["61854.10","3.279"]],"a":[["61854.20","8.860"],["61866.70","0.760"],["61867.30","0.123"],["61868.70","0.081"],["61871.60","0.007"],["61883.40","0.373"],["61883.60","0.110"],["61884.00","0.002"],["61884.30","0.003"],["61884.90","0.176"],["61886.50","0.664"],["61888.90","1.467"],["61893.40","0.036"],["61893.50","0.207"],["61904.40","0.128"],["61932.10","0.000"],["62410.90","10.159"],["62472.70","4.076"],["62472.80","0.214"],["62514.20","2.076"],["62596.50","2.409"],["62746.30","0.000"]],"st":1}}
{"schema_version":"1.3.0","event_id":"00502866-68c9-45c4-9149-40039d4eb1a9","event_type":"raw.depth_update","source":"binance_market_data_recorder","venue":"binance_usdm","market_type":"perpetual_futures","symbol":"BTCUSDT","event_time_ms":1783517081288,"received_time_ms":1783517081285,"trace_id":"7839d5f0-c0e1-4454-8189-7750be4bc24d","first_update_id":10999771874745,"final_update_id":10999771882974,"previous_final_update_id":10999771874597,"bids":[{"price":"11354.10","quantity":"1.343"},{"price":"11654.10","quantity":"2.368"},{"price":"11754.10","quantity":"1.189"},{"price":"55668.60","quantity":"0.002"},{"price":"58761.40","quantity":"0.022"},{"price":"58761.50","quantity":"0.009"},{"price":"59379.90","quantity":"0.000"},{"price":"60617.10","quantity":"0.024"},{"price":"61235.60","quantity":"0.328"},{"price":"61825.40","quantity":"0.995"},{"price":"61826.40","quantity":"0.881"},{"price":"61843.10","quantity":"0.957"},{"price":"61844.80","quantity":"0.145"},{"price":"61853.90","quantity":"0.000"},{"price":"61854.00","quantity":"0.006"},{"price":"61854.10","quantity":"2.817"}],"asks":[{"price":"61854.20","quantity":"8.880"},{"price":"61860.30","quantity":"0.203"},{"price":"61860.40","quantity":"0.854"},{"price":"61884.60","quantity":"0.003"},{"price":"61884.80","quantity":"0.335"},{"price":"61884.90","quantity":"0.281"},{"price":"61893.50","quantity":"0.580"},{"price":"61904.10","quantity":"2.048"},{"price":"61904.20","quantity":"0.403"},{"price":"61904.40","quantity":"0.027"},{"price":"61904.50","quantity":"0.181"},{"price":"62472.70","quantity":"4.076"},{"price":"63091.20","quantity":"0.026"},{"price":"89523.20","quantity":"1.146"}],"raw":{"e":"depthUpdate","E":1783517081288,"T":1783517081285,"s":"BTCUSDT","ps":"BTCUSDT","U":10999771874745,"u":10999771882974,"pu":10999771874597,"b":[["11354.10","1.343"],["11654.10","2.368"],["11754.10","1.189"],["55668.60","0.002"],["58761.40","0.022"],["58761.50","0.009"],["59379.90","0.000"],["60617.10","0.024"],["61235.60","0.328"],["61825.40","0.995"],["61826.40","0.881"],["61843.10","0.957"],["61844.80","0.145"],["61853.90","0.000"],["61854.00","0.006"],["61854.10","2.817"]],"a":[["61854.20","8.880"],["61860.30","0.203"],["61860.40","0.854"],["61884.60","0.003"],["61884.80","0.335"],["61884.90","0.281"],["61893.50","0.580"],["61904.10","2.048"],["61904.20","0.403"],["61904.40","0.027"],["61904.50","0.181"],["62472.70","4.076"],["63091.20","0.026"],["89523.20","1.146"]],"st":1}}
{"schema_version":"1.3.0","event_id":"a2cd0df2-949b-41b9-9a1c-15c14ad7fb1f","event_type":"raw.depth_update","source":"binance_market_data_recorder","venue":"binance_usdm","market_type":"perpetual_futures","symbol":"BTCUSDT","event_time_ms":1783517081390,"received_time_ms":1783517081390,"trace_id":"725dfdf7-5e1f-4831-b45e-a9d00d0271c1","first_update_id":10999771883125,"final_update_id":10999771890825,"previous_final_update_id":10999771882974,"bids":[{"price":"1000.00","quantity":"207.692"},{"price":"11354.10","quantity":"1.190"},{"price":"11654.10","quantity":"2.640"},{"price":"11754.10","quantity":"1.070"},{"price":"55668.60","quantity":"0.002"},{"price":"59379.90","quantity":"0.003"},{"price":"60927.10","quantity":"0.000"},{"price":"61050.00","quantity":"6.653"},{"price":"61235.60","quantity":"0.328"},{"price":"61537.60","quantity":"0.348"},{"price":"61544.80","quantity":"0.039"},{"price":"61853.80","quantity":"0.002"},{"price":"61853.90","quantity":"0.002"},{"price":"61854.00","quantity":"0.004"},{"price":"61854.10","quantity":"2.818"}],"asks":[{"price":"61854.20","quantity":"8.886"},{"price":"61862.70","quantity":"2.698"},{"price":"61878.60","quantity":"1.071"},{"price":"61890.60","quantity":"0.045"},{"price":"61899.20","quantity":"0.000"},{"price":"61939.80","quantity":"0.000"},{"price":"61997.60","quantity":"15.389"},{"price":"62158.30","quantity":"0.037"},{"price":"62431.60","quantity":"0.240"},{"price":"62472.70","quantity":"4.076"}],"raw":{"e":"depthUpdate","E":1783517081390,"T":1783517081389,"s":"BTCUSDT","ps":"BTCUSDT","U":10999771883125,"u":10999771890825,"pu":10999771882974,"b":[["1000.00","207.692"],["11354.10","1.190"],["11654.10","2.640"],["11754.10","1.070"],["55668.60","0.002"],["59379.90","0.003"],["60927.10","0.000"],["61050.00","6.653"],["61235.60","0.328"],["61537.60","0.348"],["61544.80","0.039"],["61853.80","0.002"],["61853.90","0.002"],["61854.00","0.004"],["61854.10","2.818"]],"a":[["61854.20","8.886"],["61862.70","2.698"],["61878.60","1.071"],["61890.60","0.045"],["61899.20","0.000"],["61939.80","0.000"],["61997.60","15.389"],["62158.30","0.037"],["62431.60","0.240"],["62472.70","4.076"]],"st":1}}
{"schema_version":"1.3.0","event_id":"0a7c1745-2eed-4ae1-94a0-576cb1d449ba","event_type":"raw.depth_update","source":"binance_market_data_recorder","venue":"binance_usdm","market_type":"perpetual_futures","symbol":"BTCUSDT","event_time_ms":1783517081492,"received_time_ms":1783517081490,"trace_id":"ffbf26fe-decc-49d8-a525-756889e5c6de","first_update_id":10999771890903,"final_update_id":10999771896969,"previous_final_update_id":10999771890825,"bids":[{"price":"1000.00","quantity":"207.692"},{"price":"11354.10","quantity":"1.054"},{"price":"11554.10","quantity":"0.096"},{"price":"11654.10","quantity":"2.720"},{"price":"11754.10","quantity":"1.030"},{"price":"55668.60","quantity":"0.002"},{"price":"57801.00","quantity":"0.057"},{"price":"59379.90","quantity":"0.000"},{"price":"60617.10","quantity":"0.027"},{"price":"60926.30","quantity":"2.992"},{"price":"61235.60","quantity":"0.328"},{"price":"61544.80","quantity":"0.038"},{"price":"61808.30","quantity":"1.115"},{"price":"61820.20","quantity":"0.239"},{"price":"61828.60","quantity":"0.553"},{"price":"61834.80","quantity":"0.019"},{"price":"61838.90","quantity":"0.425"},{"price":"61839.00","quantity":"0.007"},{"price":"61839.30","quantity":"0.003"},{"price":"61839.40","quantity":"0.460"},{"price":"61840.70","quantity":"0.001"},{"price":"61842.80","quantity":"0.010"},{"price":"61843.10","quantity":"1.058"},{"price":"61843.40","quantity":"0.002"},{"price":"61843.50","quantity":"0.002"},{"price":"61845.80","quantity":"0.000"},{"price":"61846.10","quantity":"0.050"},{"price":"61847.20","quantity":"0.000"},{"price":"61847.60","quantity":"0.001"},{"price":"61848.10","quantity":"0.000"},{"price":"61850.30","quantity":"0.051"},{"price":"61850.50","quantity":"0.331"},{"price":"61850.60","quantity":"0.000"},{"price":"61851.30","quantity":"0.001"},{"price":"61853.90","quantity":"0.002"},{"price":"61854.00","quantity":"0.004"},{"price":"61854.10","quantity":"2.399"}],"asks":[{"price":"61854.20","quantity":"8.288"},{"price":"61854.90","quantity":"0.171"},{"price":"61859.40","quantity":"0.436"},{"price":"61859.50","quantity":"1.308"},{"price":"61860.50","quantity":"2.424"},{"price":"61865.70","quantity":"0.597"},{"price":"61871.90","quantity":"0.364"},{"price":"61872.80","quantity":"0.128"},{"price":"61875.80","quantity":"0.128"},{"price":"61884.60","quantity":"0.108"},{"price":"61884.80","quantity":"0.230"},{"price":"61884.90","quantity":"0.281"},{"price":"61885.10","quantity":"0.277"},{"price":"61897.40","quantity":"0.000"},{"price":"61904.00","quantity":"0.104"},{"price":"61904.20","quantity":"0.302"},{"price":"61904.50","quantity":"0.282"},{"price":"61919.90","quantity":"3.755"},{"price":"61920.50","quantity":"0.000"},{"price":"61924.70","quantity":"25.247"},{"price":"61926.80","quantity":"0.891"},{"price":"62472.70","quantity":"4.076"},{"price":"62528.40","quantity":"1.197"},{"price":"62697.20","quantity":"1.719"},{"price":"62730.70","quantity":"4.177"},{"price":"62823.40","quantity":"2.385"},{"price":"89523.20","quantity":"1.152"}],"raw":{"e":"depthUpdate","E":1783517081492,"T":1783517081489,"s":"BTCUSDT","ps":"BTCUSDT","U":10999771890903,"u":10999771896969,"pu":10999771890825,"b":[["1000.00","207.692"],["11354.10","1.054"],["11554.10","0.096"],["11654.10","2.720"],["11754.10","1.030"],["55668.60","0.002"],["57801.00","0.057"],["59379.90","0.000"],["60617.10","0.027"],["60926.30","2.992"],["61235.60","0.328"],["61544.80","0.038"],["61808.30","1.115"],["61820.20","0.239"],["61828.60","0.553"],["61834.80","0.019"],["61838.90","0.425"],["61839.00","0.007"],["61839.30","0.003"],["61839.40","0.460"],["61840.70","0.001"],["61842.80","0.010"],["61843.10","1.058"],["61843.40","0.002"],["61843.50","0.002"],["61845.80","0.000"],["61846.10","0.050"],["61847.20","0.000"],["61847.60","0.001"],["61848.10","0.000"],["61850.30","0.051"],["61850.50","0.331"],["61850.60","0.000"],["61851.30","0.001"],["61853.90","0.002"],["61854.00","0.004"],["61854.10","2.399"]],"a":[["61854.20","8.288"],["61854.90","0.171"],["61859.40","0.436"],["61859.50","1.308"],["61860.50","2.424"],["61865.70","0.597"],["61871.90","0.364"],["61872.80","0.128"],["61875.80","0.128"],["61884.60","0.108"],["61884.80","0.230"],["61884.90","0.281"],["61885.10","0.277"],["61897.40","0.000"],["61904.00","0.104"],["61904.20","0.302"],["61904.50","0.282"],["61919.90","3.755"],["61920.50","0.000"],["61924.70","25.247"],["61926.80","0.891"],["62472.70","4.076"],["62528.40","1.197"],["62697.20","1.719"],["62730.70","4.177"],["62823.40","2.385"],["89523.20","1.152"]],"st":1}}
{"schema_version":"1.3.0","event_id":"9d8574f2-5add-44c4-87eb-b100ed225b7a","event_type":"raw.depth_update","source":"binance_market_data_recorder","venue":"binance_usdm","market_type":"perpetual_futures","symbol":"BTCUSDT","event_time_ms":1783517081594,"received_time_ms":1783517081589,"trace_id":"e3a57e21-9c31-4fca-bb8b-c722b1836d03","first_update_id":10999771897092,"final_update_id":10999771902160,"previous_final_update_id":10999771896969,"bids":[{"price":"11354.10","quantity":"0.901"},{"price":"11554.10","quantity":"0.224"},{"price":"11654.10","quantity":"2.736"},{"price":"11754.10","quantity":"1.039"},{"price":"55668.60","quantity":"0.002"},{"price":"59379.90","quantity":"0.003"},{"price":"60437.80","quantity":"0.000"},{"price":"61235.60","quantity":"0.328"},{"price":"61723.80","quantity":"0.000"},{"price":"61751.70","quantity":"0.010"},{"price":"61751.90","quantity":"0.007"},{"price":"61819.50","quantity":"0.804"},{"price":"61820.40","quantity":"0.701"},{"price":"61821.10","quantity":"0.247"},{"price":"61825.00","quantity":"1.347"},{"price":"61850.60","quantity":"0.662"},{"price":"61851.40","quantity":"0.005"},{"price":"61853.80","quantity":"0.002"}],"asks":[{"price":"61854.20","quantity":"8.287"},{"price":"61854.90","quantity":"0.045"},{"price":"61897.40","quantity":"0.004"},{"price":"61920.50","quantity":"25.247"},{"price":"61924.40","quantity":"1.537"},{"price":"61924.70","quantity":"0.000"},{"price":"61940.90","quantity":"2.735"},{"price":"61985.00","quantity":"0.018"},{"price":"62030.00","quantity":"0.160"},{"price":"62030.20","quantity":"0.003"},{"price":"62163.50","quantity":"2.409"},{"price":"62472.70","quantity":"4.076"},{"price":"62669.30","quantity":"0.000"}],"raw":{"e":"depthUpdate","E":1783517081594,"T":1783517081593,"s":"BTCUSDT","ps":"BTCUSDT","U":10999771897092,"u":10999771902160,"pu":10999771896969,"b":[["11354.10","0.901"],["11554.10","0.224"],["11654.10","2.736"],["11754.10","1.039"],["55668.60","0.002"],["59379.90","0.003"],["60437.80","0.000"],["61235.60","0.328"],["61723.80","0.000"],["61751.70","0.010"],["61751.90","0.007"],["61819.50","0.804"],["61820.40","0.701"],["61821.10","0.247"],["61825.00","1.347"],["61850.60","0.662"],["61851.40","0.005"],["61853.80","0.002"]],"a":[["61854.20","8.287"],["61854.90","0.045"],["61897.40","0.004"],["61920.50","25.247"],["61924.40","1.537"],["61924.70","0.000"],["61940.90","2.735"],["61985.00","0.018"],["62030.00","0.160"],["62030.20","0.003"],["62163.50","2.409"],["62472.70","4.076"],["62669.30","0.000"]],"st":1}}
{"schema_version":"1.3.0","event_id":"cc83ebf2-8a6d-4184-8261-06c43096dd69","event_type":"raw.depth_update","source":"binance_market_data_recorder","venue":"binance_usdm","market_type":"perpetual_futures","symbol":"BTCUSDT","event_time_ms":1783517081696,"received_time_ms":1783517081694,"trace_id":"3d9cda62-6397-4078-8f94-399ec19caac3","first_update_id":10999771902253,"final_update_id":10999771907396,"previous_final_update_id":10999771902160,"bids":[{"price":"1000.00","quantity":"207.692"},{"price":"11354.10","quantity":"0.765"},{"price":"11554.10","quantity":"0.368"},{"price":"11654.10","quantity":"2.720"},{"price":"11754.10","quantity":"1.047"},{"price":"55668.60","quantity":"0.002"},{"price":"60926.30","quantity":"3.361"},{"price":"61235.60","quantity":"0.328"},{"price":"61404.30","quantity":"0.105"},{"price":"61544.80","quantity":"0.029"},{"price":"61723.80","quantity":"0.300"},{"price":"61828.60","quantity":"0.391"},{"price":"61840.70","quantity":"0.001"},{"price":"61840.90","quantity":"0.005"},{"price":"61843.00","quantity":"2.266"},{"price":"61844.80","quantity":"0.145"},{"price":"61850.50","quantity":"0.007"},{"price":"61853.90","quantity":"0.000"},{"price":"61854.00","quantity":"0.006"},{"price":"61854.10","quantity":"2.368"}],"asks":[{"price":"61854.20","quantity":"8.287"},{"price":"61883.80","quantity":"0.429"},{"price":"61904.50","quantity":"0.282"},{"price":"61920.50","quantity":"25.247"},{"price":"61926.80","quantity":"0.891"},{"price":"61985.00","quantity":"0.743"},{"price":"62070.40","quantity":"0.000"},{"price":"62472.70","quantity":"4.076"},{"price":"62627.40","quantity":"2.895"},{"price":"62695.60","quantity":"1.580"},{"price":"89523.20","quantity":"1.158"}],"raw":{"e":"depthUpdate","E":1783517081696,"T":1783517081693,"s":"BTCUSDT","ps":"BTCUSDT","U":10999771902253,"u":10999771907396,"pu":10999771902160,"b":[["1000.00","207.692"],["11354.10","0.765"],["11554.10","0.368"],["11654.10","2.720"],["11754.10","1.047"],["55668.60","0.002"],["60926.30","3.361"],["61235.60","0.328"],["61404.30","0.105"],["61544.80","0.029"],["61723.80","0.300"],["61828.60","0.391"],["61840.70","0.001"],["61840.90","0.005"],["61843.00","2.266"],["61844.80","0.145"],["61850.50","0.007"],["61853.90","0.000"],["61854.00","0.006"],["61854.10","2.368"]],"a":[["61854.20","8.287"],["61883.80","0.429"],["61904.50","0.282"],["61920.50","25.247"],["61926.80","0.891"],["61985.00","0.743"],["62070.40","0.000"],["62472.70","4.076"],["62627.40","2.895"],["62695.60","1.580"],["89523.20","1.158"]],"st":1}}
{"schema_version":"1.3.0","event_id":"3d65f6d0-c050-4788-9c3c-c6e51d26dc6f","event_type":"raw.depth_update","source":"binance_market_data_recorder","venue":"binance_usdm","market_type":"perpetual_futures","symbol":"BTCUSDT","event_time_ms":1783517081798,"received_time_ms":1783517081794,"trace_id":"2a308fb3-9b46-4f7d-85e3-8bd00a962b6d","first_update_id":10999771907506,"final_update_id":10999771913988,"previous_final_update_id":10999771907396,"bids":[{"price":"1000.00","quantity":"207.692"},{"price":"11354.10","quantity":"0.612"},{"price":"11554.10","quantity":"0.528"},{"price":"11654.10","quantity":"2.672"},{"price":"11754.10","quantity":"1.088"},{"price":"49483.00","quantity":"0.000"},{"price":"55668.60","quantity":"0.002"},{"price":"59379.90","quantity":"0.000"},{"price":"61235.60","quantity":"0.328"},{"price":"61528.40","quantity":"3.029"},{"price":"61843.30","quantity":"0.013"},{"price":"61850.00","quantity":"1.592"},{"price":"61853.00","quantity":"0.040"},{"price":"61853.90","quantity":"0.002"},{"price":"61854.00","quantity":"0.004"},{"price":"61854.10","quantity":"2.369"}],"asks":[{"price":"61886.40","quantity":"0.210"},{"price":"61893.30","quantity":"0.100"},{"price":"61919.90","quantity":"6.722"},{"price":"62146.90","quantity":"0.644"},{"price":"62472.70","quantity":"4.076"},{"price":"62734.00","quantity":"7.181"},{"price":"62751.10","quantity":"4.297"},{"price":"62843.90","quantity":"1.113"}],"raw":{"e":"depthUpdate","E":1783517081798,"T":1783517081797,"s":"BTCUSDT","ps":"BTCUSDT","U":10999771907506,"u":10999771913988,"pu":10999771907396,"b":[["1000.00","207.692"],["11354.10","0.612"],["11554.10","0.528"],["11654.10","2.672"],["11754.10","1.088"],["49483.00","0.000"],["55668.60","0.002"],["59379.90","0.000"],["61235.60","0.328"],["61528.40","3.029"],["61843.30","0.013"],["61850.00","1.592"],["61853.00","0.040"],["61853.90","0.002"],["61854.00","0.004"],["61854.10","2.369"]],"a":[["61886.40","0.210"],["61893.30","0.100"],["61919.90","6.722"],["62146.90","0.644"],["62472.70","4.076"],["62734.00","7.181"],["62751.10","4.297"],["62843.90","1.113"]],"st":1}}
{"schema_version":"1.3.0","event_id":"b3b49dbd-06a4-421f-bc5b-49d347c86299","event_type":"raw.depth_update","source":"binance_market_data_recorder","venue":"binance_usdm","market_type":"perpetual_futures","symbol":"BTCUSDT","event_time_ms":1783517081900,"received_time_ms":1783517081897,"trace_id":"d8458db5-f737-4a91-b85a-55a1ee2cca5a","first_update_id":10999771914075,"final_update_id":10999771921239,"previous_final_update_id":10999771913988,"bids":[{"price":"11354.10","quantity":"0.476"},{"price":"11554.10","quantity":"0.800"},{"price":"11654.10","quantity":"2.400"},{"price":"11754.10","quantity":"1.224"},{"price":"49483.30","quantity":"0.000"},{"price":"55668.60","quantity":"0.002"},{"price":"58761.40","quantity":"0.025"},{"price":"59379.90","quantity":"0.003"},{"price":"61235.60","quantity":"0.328"},{"price":"61338.00","quantity":"0.431"},{"price":"61537.60","quantity":"0.348"},{"price":"61723.80","quantity":"0.000"},{"price":"61821.90","quantity":"0.414"},{"price":"61823.40","quantity":"0.069"},{"price":"61840.90","quantity":"0.003"},{"price":"61843.00","quantity":"2.367"},{"price":"61843.30","quantity":"0.114"},{"price":"61850.40","quantity":"0.324"},{"price":"61854.10","quantity":"2.369"}],"asks":[{"price":"61854.20","quantity":"7.670"},{"price":"61872.80","quantity":"0.000"},{"price":"61875.80","quantity":"0.000"},{"price":"61885.00","quantity":"0.877"},{"price":"61885.10","quantity":"0.405"},{"price":"61897.40","quantity":"0.000"},{"price":"61909.90","quantity":"0.248"},{"price":"61919.90","quantity":"3.755"},{"price":"61920.50","quantity":"0.000"},{"price":"61926.80","quantity":"26.138"},{"price":"61948.30","quantity":"0.026"},{"price":"61985.00","quantity":"0.018"},{"price":"61990.30","quantity":"0.335"},{"price":"62472.70","quantity":"4.076"},{"price":"62894.30","quantity":"0.000"},{"price":"63091.20","quantity":"0.029"},{"price":"89523.20","quantity":"1.164"}],"raw":{"e":"depthUpdate","E":1783517081900,"T":1783517081897,"s":"BTCUSDT","ps":"BTCUSDT","U":10999771914075,"u":10999771921239,"pu":10999771913988,"b":[["11354.10","0.476"],["11554.10","0.800"],["11654.10","2.400"],["11754.10","1.224"],["49483.30","0.000"],["55668.60","0.002"],["58761.40","0.025"],["59379.90","0.003"],["61235.60","0.328"],["61338.00","0.431"],["61537.60","0.348"],["61723.80","0.000"],["61821.90","0.414"],["61823.40","0.069"],["61840.90","0.003"],["61843.00","2.367"],["61843.30","0.114"],["61850.40","0.324"],["61854.10","2.369"]],"a":[["61854.20","7.670"],["61872.80","0.000"],["61875.80","0.000"],["61885.00","0.877"],["61885.10","0.405"],["61897.40","0.000"],["61909.90","0.248"],["61919.90","3.755"],["61920.50","0.000"],["61926.80","26.138"],["61948.30","0.026"],["61985.00","0.018"],["61990.30","0.335"],["62472.70","4.076"],["62894.30","0.000"],["63091.20","0.029"],["89523.20","1.164"]],"st":1}}
{"schema_version":"1.3.0","event_id":"936abf38-6321-44f9-81ef-ed91cc0d52f5","event_type":"raw.depth_update","source":"binance_market_data_recorder","venue":"binance_usdm","market_type":"perpetual_futures","symbol":"BTCUSDT","event_time_ms":1783517082002,"received_time_ms":1783517081998,"trace_id":"a53bc134-0d68-4983-b7c2-1765b510e789","first_update_id":10999771921459,"final_update_id":10999771928650,"previous_final_update_id":10999771921239,"bids":[{"price":"1000.00","quantity":"207.692"},{"price":"11354.10","quantity":"0.323"},{"price":"11554.10","quantity":"1.072"},{"price":"11654.10","quantity":"2.128"},{"price":"11754.10","quantity":"1.377"},{"price":"55668.60","quantity":"0.002"},{"price":"59379.90","quantity":"0.000"},{"price":"61235.60","quantity":"0.328"},{"price":"61544.80","quantity":"0.029"},{"price":"61799.00","quantity":"0.210"},{"price":"61806.10","quantity":"4.509"},{"price":"61822.40","quantity":"0.125"},{"price":"61843.10","quantity":"0.957"},{"price":"61853.90","quantity":"0.003"},{"price":"61854.00","quantity":"0.006"},{"price":"61854.10","quantity":"2.368"}],"asks":[{"price":"61854.20","quantity":"8.628"},{"price":"61860.40","quantity":"0.858"},{"price":"61866.60","quantity":"3.396"},{"price":"61868.70","quantity":"0.098"},{"price":"61872.80","quantity":"0.004"},{"price":"61885.10","quantity":"0.277"},{"price":"61891.30","quantity":"0.330"},{"price":"61893.50","quantity":"0.373"},{"price":"61897.40","quantity":"0.004"},{"price":"61904.10","quantity":"1.947"},{"price":"61904.40","quantity":"0.128"},{"price":"61924.70","quantity":"25.247"},{"price":"61926.80","quantity":"0.891"},{"price":"61990.30","quantity":"0.310"},{"price":"61992.90","quantity":"0.000"},{"price":"62011.80","quantity":"0.019"},{"price":"62472.70","quantity":"4.076"},{"price":"62514.20","quantity":"1.358"},{"price":"62720.20","quantity":"5.519"},{"price":"64946.90","quantity":"0.002"}],"raw":{"e":"depthUpdate","E":1783517082002,"T":1783517082001,"s":"BTCUSDT","ps":"BTCUSDT","U":10999771921459,"u":10999771928650,"pu":10999771921239,"b":[["1000.00","207.692"],["11354.10","0.323"],["11554.10","1.072"],["11654.10","2.128"],["11754.10","1.377"],["55668.60","0.002"],["59379.90","0.000"],["61235.60","0.328"],["61544.80","0.029"],["61799.00","0.210"],["61806.10","4.509"],["61822.40","0.125"],["61843.10","0.957"],["61853.90","0.003"],["61854.00","0.006"],["61854.10","2.368"]],"a":[["61854.20","8.628"],["61860.40","0.858"],["61866.60","3.396"],["61868.70","0.098"],["61872.80","0.004"],["61885.10","0.277"],["61891.30","0.330"],["61893.50","0.373"],["61897.40","0.004"],["61904.10","1.947"],["61904.40","0.128"],["61924.70","25.247"],["61926.80","0.891"],["61990.30","0.310"],["61992.90","0.000"],["62011.80","0.019"],["62472.70","4.076"],["62514.20","1.358"],["62720.20","5.519"],["64946.90","0.002"]],"st":1}}
{"schema_version":"1.3.0","event_id":"827d6b73-09a2-4f2c-afa4-7753a184194b","event_type":"raw.depth_update","source":"binance_market_data_recorder","venue":"binance_usdm","market_type":"perpetual_futures","symbol":"BTCUSDT","event_time_ms":1783517082104,"received_time_ms":1783517082099,"trace_id":"fd1898d8-c331-480c-bfce-f0a046db0501","first_update_id":10999771928890,"final_update_id":10999771935013,"previous_final_update_id":10999771928650,"bids":[{"price":"1000.00","quantity":"207.692"},{"price":"11354.10","quantity":"0.187"},{"price":"11554.10","quantity":"1.344"},{"price":"11654.10","quantity":"1.856"},{"price":"11754.10","quantity":"1.513"},{"price":"55668.60","quantity":"0.002"},{"price":"61050.80","quantity":"0.735"},{"price":"61235.60","quantity":"0.328"},{"price":"61723.80","quantity":"0.306"},{"price":"61751.90","quantity":"0.004"},{"price":"61752.00","quantity":"1.143"},{"price":"61839.10","quantity":"0.000"},{"price":"61840.00","quantity":"0.241"},{"price":"61842.80","quantity":"0.002"},{"price":"61843.00","quantity":"2.367"},{"price":"61843.50","quantity":"0.103"},{"price":"61843.90","quantity":"0.281"},{"price":"61844.80","quantity":"0.145"},{"price":"61845.00","quantity":"1.264"},{"price":"61850.40","quantity":"0.000"},{"price":"61850.60","quantity":"0.000"},{"price":"61853.70","quantity":"0.020"},{"price":"61853.80","quantity":"0.006"},{"price":"61853.90","quantity":"0.002"},{"price":"61854.00","quantity":"0.004"},{"price":"61854.10","quantity":"2.384"}],"asks":[{"price":"61854.20","quantity":"8.977"},{"price":"61860.40","quantity":"0.854"},{"price":"61865.30","quantity":"0.327"},{"price":"61866.60","quantity":"3.392"},{"price":"61868.70","quantity":"0.081"},{"price":"61872.80","quantity":"0.000"},{"price":"61904.20","quantity":"0.403"},{"price":"61904.40","quantity":"0.027"},{"price":"61904.50","quantity":"0.181"},{"price":"61920.50","quantity":"25.247"},{"price":"61924.70","quantity":"0.000"},{"price":"61957.60","quantity":"3.914"},{"price":"61985.00","quantity":"0.743"},{"price":"61999.90","quantity":"0.001"},{"price":"62030.20","quantity":"0.000"},{"price":"62030.30","quantity":"0.003"},{"price":"62472.70","quantity":"4.076"},{"price":"62472.80","quantity":"0.213"},{"price":"62482.40","quantity":"0.000"},{"price":"62729.90","quantity":"1.752"},{"price":"62778.70","quantity":"0.358"},{"price":"64946.90","quantity":"0.000"},{"price":"89523.20","quantity":"1.170"}],"raw":{"e":"depthUpdate","E":1783517082104,"T":1783517082101,"s":"BTCUSDT","ps":"BTCUSDT","U":10999771928890,"u":10999771935013,"pu":10999771928650,"b":[["1000.00","207.692"],["11354.10","0.187"],["11554.10","1.344"],["11654.10","1.856"],["11754.10","1.513"],["55668.60","0.002"],["61050.80","0.735"],["61235.60","0.328"],["61723.80","0.306"],["61751.90","0.004"],["61752.00","1.143"],["61839.10","0.000"],["61840.00","0.241"],["61842.80","0.002"],["61843.00","2.367"],["61843.50","0.103"],["61843.90","0.281"],["61844.80","0.145"],["61845.00","1.264"],["61850.40","0.000"],["61850.60","0.000"],["61853.70","0.020"],["61853.80","0.006"],["61853.90","0.002"],["61854.00","0.004"],["61854.10","2.384"]],"a":[["61854.20","8.977"],["61860.40","0.854"],["61865.30","0.327"],["61866.60","3.392"],["61868.70","0.081"],["61872.80","0.000"],["61904.20","0.403"],["61904.40","0.027"],["61904.50","0.181"],["61920.50","25.247"],["61924.70","0.000"],["61957.60","3.914"],["61985.00","0.743"],["61999.90","0.001"],["62030.20","0.000"],["62030.30","0.003"],["62472.70","4.076"],["62472.80","0.213"],["62482.40","0.000"],["62729.90","1.752"],["62778.70","0.358"],["64946.90","0.000"],["89523.20","1.170"]],"st":1}}
{"schema_version":"1.3.0","event_id":"7f433eb0-a81b-4338-8b97-6c515caa80c2","event_type":"raw.depth_update","source":"binance_market_data_recorder","venue":"binance_usdm","market_type":"perpetual_futures","symbol":"BTCUSDT","event_time_ms":1783517082206,"received_time_ms":1783517082201,"trace_id":"93e5af3c-b812-49bb-998f-940a2f697ed9","first_update_id":10999771935226,"final_update_id":10999771941811,"previous_final_update_id":10999771935013,"bids":[{"price":"11354.10","quantity":"0.034"},{"price":"11554.10","quantity":"1.616"},{"price":"11654.10","quantity":"1.584"},{"price":"11754.10","quantity":"1.666"},{"price":"55668.60","quantity":"0.002"},{"price":"58760.60","quantity":"0.001"},{"price":"59379.90","quantity":"0.003"},{"price":"60897.60","quantity":"1.746"},{"price":"61019.10","quantity":"4.659"},{"price":"61050.00","quantity":"6.980"},{"price":"61073.40","quantity":"2.860"},{"price":"61235.60","quantity":"0.328"},{"price":"61787.70","quantity":"0.061"},{"price":"61788.80","quantity":"0.097"},{"price":"61820.20","quantity":"0.239"},{"price":"61824.70","quantity":"0.122"},{"price":"61825.20","quantity":"0.583"},{"price":"61825.40","quantity":"0.874"},{"price":"61825.80","quantity":"0.000"},{"price":"61840.50","quantity":"2.138"},{"price":"61853.80","quantity":"0.002"},{"price":"61853.90","quantity":"0.004"},{"price":"61854.00","quantity":"0.006"},{"price":"61854.10","quantity":"2.384"}],"asks":[{"price":"61854.80","quantity":"0.671"},{"price":"61862.60","quantity":"0.091"},{"price":"61863.50","quantity":"0.570"},{"price":"61863.60","quantity":"0.170"},{"price":"61864.70","quantity":"0.583"},{"price":"61865.50","quantity":"0.014"},{"price":"61865.60","quantity":"0.004"},{"price":"61865.80","quantity":"0.127"},{"price":"61867.30","quantity":"0.002"},{"price":"61867.40","quantity":"0.064"},{"price":"61870.10","quantity":"0.140"},{"price":"61871.60","quantity":"0.007"},{"price":"61883.40","quantity":"0.375"},{"price":"61883.50","quantity":"0.939"},{"price":"61884.60","quantity":"0.003"},{"price":"61884.80","quantity":"0.232"},{"price":"61885.00","quantity":"0.772"},{"price":"61893.50","quantity":"0.000"},{"price":"61904.00","quantity":"0.003"},{"price":"61904.40","quantity":"0.128"},{"price":"61904.50","quantity":"0.282"},{"price":"62472.70","quantity":"4.076"},{"price":"62588.80","quantity":"9.094"},{"price":"62623.20","quantity":"1.756"},{"price":"62839.70","quantity":"0.501"},{"price":"63000.00","quantity":"46.584"}],"raw":{"e":"depthUpdate","E":1783517082206,"T":1783517082205,"s":"BTCUSDT","ps":"BTCUSDT","U":10999771935226,"u":10999771941811,"pu":10999771935013,"b":[["11354.10","0.034"],["11554.10","1.616"],["11654.10","1.584"],["11754.10","1.666"],["55668.60","0.002"],["58760.60","0.001"],["59379.90","0.003"],["60897.60","1.746"],["61019.10","4.659"],["61050.00","6.980"],["61073.40","2.860"],["61235.60","0.328"],["61787.70","0.061"],["61788.80","0.097"],["61820.20","0.239"],["61824.70","0.122"],["61825.20","0.583"],["61825.40","0.874"],["61825.80","0.000"],["61840.50","2.138"],["61853.80","0.002"],["61853.90","0.004"],["61854.00","0.006"],["61854.10","2.384"]],"a":[["61854.80","0.671"],["61862.60","0.091"],["61863.50","0.570"],["61863.60","0.170"],["61864.70","0.583"],["61865.50","0.014"],["61865.60","0.004"],["61865.80","0.127"],["61867.30","0.002"],["61867.40","0.064"],["61870.10","0.140"],["61871.60","0.007"],["61883.40","0.375"],["61883.50","0.939"],["61884.60","0.003"],["61884.80","0.232"],["61885.00","0.772"],["61893.50","0.000"],["61904.00","0.003"],["61904.40","0.128"],["61904.50","0.282"],["62472.70","4.076"],["62588.80","9.094"],["62623.20","1.756"],["62839.70","0.501"],["63000.00","46.584"]],"st":1}}
{"schema_version":"1.3.0","event_id":"8dd267b6-c477-4390-be80-fe95cf244eb8","event_type":"raw.depth_update","source":"binance_market_data_recorder","venue":"binance_usdm","market_type":"perpetual_futures","symbol":"BTCUSDT","event_time_ms":1783517082308,"received_time_ms":1783517082306,"trace_id":"eed44e59-e39b-45f2-9656-0ce2e478cbda","first_update_id":10999771941884,"final_update_id":10999771948312,"previous_final_update_id":10999771941811,"bids":[{"price":"1000.00","quantity":"207.692"},{"price":"11354.10","quantity":"0.000"},{"price":"11554.10","quantity":"1.888"},{"price":"11654.10","quantity":"1.414"},{"price":"11754.10","quantity":"1.598"},{"price":"55668.60","quantity":"0.002"},{"price":"58761.40","quantity":"0.023"},{"price":"59379.90","quantity":"0.000"},{"price":"61235.60","quantity":"0.330"},{"price":"61528.40","quantity":"2.867"},{"price":"61544.80","quantity":"0.039"},{"price":"61825.20","quantity":"0.001"},{"price":"61826.50","quantity":"1.540"},{"price":"61845.80","quantity":"0.373"},{"price":"61853.80","quantity":"0.006"},{"price":"61853.90","quantity":"0.002"},{"price":"61854.00","quantity":"0.004"},{"price":"61854.10","quantity":"2.387"}],"asks":[{"price":"61854.20","quantity":"8.978"},{"price":"61865.80","quantity":"0.006"},{"price":"61866.50","quantity":"0.190"},{"price":"61884.70","quantity":"0.575"},{"price":"61884.90","quantity":"0.176"},{"price":"61885.10","quantity":"0.405"},{"price":"61893.50","quantity":"0.207"},{"price":"61909.90","quantity":"0.120"},{"price":"62114.30","quantity":"0.000"},{"price":"62114.40","quantity":"0.000"},{"price":"62114.50","quantity":"0.000"},{"price":"62472.70","quantity":"4.078"},{"price":"62528.40","quantity":"1.915"},{"price":"62596.50","quantity":"3.685"},{"price":"62668.00","quantity":"1.233"},{"price":"62689.20","quantity":"2.549"},{"price":"63091.20","quantity":"0.032"},{"price":"74998.90","quantity":"0.050"},{"price":"89523.20","quantity":"1.176"}],"raw":{"e":"depthUpdate","E":1783517082308,"T":1783517082307,"s":"BTCUSDT","ps":"BTCUSDT","U":10999771941884,"u":10999771948312,"pu":10999771941811,"b":[["1000.00","207.692"],["11354.10","0.000"],["11554.10","1.888"],["11654.10","1.414"],["11754.10","1.598"],["55668.60","0.002"],["58761.40","0.023"],["59379.90","0.000"],["61235.60","0.330"],["61528.40","2.867"],["61544.80","0.039"],["61825.20","0.001"],["61826.50","1.540"],["61845.80","0.373"],["61853.80","0.006"],["61853.90","0.002"],["61854.00","0.004"],["61854.10","2.387"]],"a":[["61854.20","8.978"],["61865.80","0.006"],["61866.50","0.190"],["61884.70","0.575"],["61884.90","0.176"],["61885.10","0.405"],["61893.50","0.207"],["61909.90","0.120"],["62114.30","0.000"],["62114.40","0.000"],["62114.50","0.000"],["62472.70","4.078"],["62528.40","1.915"],["62596.50","3.685"],["62668.00","1.233"],["62689.20","2.549"],["63091.20","0.032"],["74998.90","0.050"],["89523.20","1.176"]],"st":1}}
{"schema_version":"1.3.0","event_id":"2170cc81-75f4-4642-a494-0a4f13e78098","event_type":"raw.depth_update","source":"binance_market_data_recorder","venue":"binance_usdm","market_type":"perpetual_futures","symbol":"BTCUSDT","event_time_ms":1783517082410,"received_time_ms":1783517082407,"trace_id":"9e497f4b-1ab6-4b50-a67f-888bbc74c864","first_update_id":10999771948316,"final_update_id":10999771956000,"previous_final_update_id":10999771948312,"bids":[{"price":"1000.00","quantity":"207.692"},{"price":"11554.10","quantity":"2.160"},{"price":"11654.10","quantity":"1.295"},{"price":"11754.10","quantity":"1.445"},{"price":"55668.60","quantity":"0.002"},{"price":"59379.90","quantity":"0.003"},{"price":"60987.90","quantity":"0.575"},{"price":"61080.90","quantity":"4.835"},{"price":"61235.60","quantity":"0.328"},{"price":"61554.10","quantity":"0.632"},{"price":"61843.00","quantity":"2.266"},{"price":"61843.30","quantity":"0.013"},{"price":"61843.90","quantity":"0.180"},{"price":"61845.80","quantity":"0.101"},{"price":"61853.80","quantity":"0.002"},{"price":"61854.10","quantity":"2.386"}],"asks":[{"price":"61891.30","quantity":"0.202"},{"price":"61920.50","quantity":"25.412"},{"price":"61926.80","quantity":"0.891"},{"price":"62472.70","quantity":"4.078"},{"price":"62782.00","quantity":"6.481"},{"price":"62969.90","quantity":"0.000"}],"raw":{"e":"depthUpdate","E":1783517082410,"T":1783517082409,"s":"BTCUSDT","ps":"BTCUSDT","U":10999771948316,"u":10999771956000,"pu":10999771948312,"b":[["1000.00","207.692"],["11554.10","2.160"],["11654.10","1.295"],["11754.10","1.445"],["55668.60","0.002"],["59379.90","0.003"],["60987.90","0.575"],["61080.90","4.835"],["61235.60","0.328"],["61554.10","0.632"],["61843.00","2.266"],["61843.30","0.013"],["61843.90","0.180"],["61845.80","0.101"],["61853.80","0.002"],["61854.10","2.386"]],"a":[["61891.30","0.202"],["61920.50","25.412"],["61926.80","0.891"],["62472.70","4.078"],["62782.00","6.481"],["62969.90","0.000"]],"st":1}}
{"schema_version":"1.3.0","event_id":"bbc2eb82-941f-456c-bc3e-f1d46358dfc3","event_type":"raw.depth_update","source":"binance_market_data_recorder","venue":"binance_usdm","market_type":"perpetual_futures","symbol":"BTCUSDT","event_time_ms":1783517082512,"received_time_ms":1783517082508,"trace_id":"93b811dc-f5a1-448e-befc-bce51165a5c8","first_update_id":10999771956058,"final_update_id":10999771960916,"previous_final_update_id":10999771956000,"bids":[{"price":"11554.10","quantity":"2.432"},{"price":"11654.10","quantity":"1.159"},{"price":"11754.10","quantity":"1.309"},{"price":"49483.00","quantity":"0.000"},{"price":"55668.60","quantity":"0.002"},{"price":"59379.90","quantity":"0.000"},{"price":"60926.30","quantity":"3.730"},{"price":"60988.10","quantity":"6.778"},{"price":"61235.60","quantity":"0.328"},{"price":"61825.60","quantity":"0.601"},{"price":"61826.50","quantity":"0.958"},{"price":"61844.80","quantity":"0.017"},{"price":"61853.90","quantity":"0.006"}],"asks":[{"price":"61865.50","quantity":"0.014"},{"price":"62472.70","quantity":"4.076"},{"price":"62734.30","quantity":"3.344"},{"price":"62827.10","quantity":"1.477"},{"price":"62843.90","quantity":"1.906"},{"price":"89523.20","quantity":"1.182"}],"raw":{"e":"depthUpdate","E":1783517082512,"T":1783517082509,"s":"BTCUSDT","ps":"BTCUSDT","U":10999771956058,"u":10999771960916,"pu":10999771956000,"b":[["11554.10","2.432"],["11654.10","1.159"],["11754.10","1.309"],["49483.00","0.000"],["55668.60","0.002"],["59379.90","0.000"],["60926.30","3.730"],["60988.10","6.778"],["61235.60","0.328"],["61825.60","0.601"],["61826.50","0.958"],["61844.80","0.017"],["61853.90","0.006"]],"a":[["61865.50","0.014"],["62472.70","4.076"],["62734.30","3.344"],["62827.10","1.477"],["62843.90","1.906"],["89523.20","1.182"]],"st":1}}
{"schema_version":"1.3.0","event_id":"52b25f6e-b2d0-44a2-8677-b2b73a3b2d93","event_type":"raw.depth_update","source":"binance_market_data_recorder","venue":"binance_usdm","market_type":"perpetual_futures","symbol":"BTCUSDT","event_time_ms":1783517082614,"received_time_ms":1783517082611,"trace_id":"de866e98-c0e7-4854-bfde-0eeb9b4abc84","first_update_id":10999771961173,"final_update_id":10999771966511,"previous_final_update_id":10999771960916,"bids":[{"price":"1000.00","quantity":"207.692"},{"price":"11554.10","quantity":"2.704"},{"price":"11654.10","quantity":"1.040"},{"price":"11754.10","quantity":"1.156"},{"price":"55668.60","quantity":"0.002"},{"price":"61235.60","quantity":"0.328"},{"price":"61544.80","quantity":"0.030"},{"price":"61829.50","quantity":"1.202"},{"price":"61835.70","quantity":"0.165"},{"price":"61841.40","quantity":"0.952"},{"price":"61841.90","quantity":"0.501"},{"price":"61843.50","quantity":"0.103"},{"price":"61843.90","quantity":"0.281"},{"price":"61844.80","quantity":"0.145"},{"price":"61851.30","quantity":"0.081"},{"price":"61853.90","quantity":"0.000"},{"price":"61854.00","quantity":"0.006"},{"price":"61854.10","quantity":"2.387"}],"asks":[{"price":"61866.60","quantity":"3.473"},{"price":"61872.80","quantity":"0.162"},{"price":"61879.00","quantity":"1.095"},{"price":"61884.40","quantity":"0.600"},{"price":"61884.60","quantity":"0.108"},{"price":"61884.70","quantity":"0.470"},{"price":"61884.80","quantity":"0.230"},{"price":"61904.00","quantity":"0.104"},{"price":"61904.10","quantity":"2.048"},{"price":"61904.20","quantity":"0.302"},{"price":"61904.40","quantity":"0.027"},{"price":"61904.50","quantity":"0.181"},{"price":"62163.50","quantity":"2.408"},{"price":"62464.50","quantity":"0.002"},{"price":"62472.70","quantity":"4.076"},{"price":"62606.20","quantity":"4.066"},{"price":"62731.20","quantity":"0.000"},{"price":"62773.20","quantity":"0.013"},{"price":"64797.60","quantity":"0.150"}],"raw":{"e":"depthUpdate","E":1783517082614,"T":1783517082612,"s":"BTCUSDT","ps":"BTCUSDT","U":10999771961173,"u":10999771966511,"pu":10999771960916,"b":[["1000.00","207.692"],["11554.10","2.704"],["11654.10","1.040"],["11754.10","1.156"],["55668.60","0.002"],["61235.60","0.328"],["61544.80","0.030"],["61829.50","1.202"],["61835.70","0.165"],["61841.40","0.952"],["61841.90","0.501"],["61843.50","0.103"],["61843.90","0.281"],["61844.80","0.145"],["61851.30","0.081"],["61853.90","0.000"],["61854.00","0.006"],["61854.10","2.387"]],"a":[["61866.60","3.473"],["61872.80","0.162"],["61879.00","1.095"],["61884.40","0.600"],["61884.60","0.108"],["61884.70","0.470"],["61884.80","0.230"],["61904.00","0.104"],["61904.10","2.048"],["61904.20","0.302"],["61904.40","0.027"],["61904.50","0.181"],["62163.50","2.408"],["62464.50","0.002"],["62472.70","4.076"],["62606.20","4.066"],["62731.20","0.000"],["62773.20","0.013"],["64797.60","0.150"]],"st":1}}
