{"schema_version":"1.3.0","event_id":"845c7bca-0fba-4dad-b7cb-74c7aaaa04e6","event_type":"raw.depth_update","source":"binance_market_data_recorder","venue":"binance_usdm","market_type":"perpetual_futures","symbol":"BTCUSDT","event_time_ms":1783517072312,"received_time_ms":1783517072307,"trace_id":"b95fb113-470a-4420-9522-c4cd85080bf0","first_update_id":10999771064470,"final_update_id":10999771075156,"previous_final_update_id":10999771064414,"bids":[{"price":"11354.10","quantity":"0.832"},{"price":"11454.10","quantity":"2.368"},{"price":"11554.10","quantity":"1.241"},{"price":"11654.10","quantity":"0.459"},{"price":"49483.00","quantity":"0.000"},{"price":"55668.60","quantity":"0.002"},{"price":"58759.60","quantity":"0.000"},{"price":"59379.90","quantity":"0.003"},{"price":"61152.50","quantity":"0.490"},{"price":"61173.70","quantity":"0.315"},{"price":"61235.10","quantity":"0.002"},{"price":"61235.60","quantity":"0.328"},{"price":"61266.20","quantity":"3.234"},{"price":"61585.90","quantity":"0.008"},{"price":"61586.00","quantity":"0.052"},{"price":"61799.00","quantity":"0.008"},{"price":"61815.40","quantity":"0.004"},{"price":"61815.70","quantity":"0.002"},{"price":"61823.80","quantity":"0.150"},{"price":"61828.10","quantity":"0.008"},{"price":"61830.40","quantity":"0.130"},{"price":"61835.90","quantity":"1.054"},{"price":"61836.00","quantity":"0.064"},{"price":"61836.10","quantity":"0.001"},{"price":"61841.40","quantity":"0.928"},{"price":"61843.10","quantity":"0.090"},{"price":"61843.20","quantity":"0.308"},{"price":"61854.10","quantity":"17.096"}],"asks":[{"price":"61854.20","quantity":"2.609"},{"price":"61854.30","quantity":"0.026"},{"price":"61855.40","quantity":"0.243"},{"price":"61856.30","quantity":"0.035"},{"price":"61859.00","quantity":"0.174"},{"price":"61860.00","quantity":"0.176"},{"price":"61860.40","quantity":"0.308"},{"price":"61866.80","quantity":"1.292"},{"price":"61872.80","quantity":"0.000"},{"price":"61891.30","quantity":"0.202"},{"price":"61893.30","quantity":"0.307"},{"price":"61893.40","quantity":"0.472"},{"price":"61908.10","quantity":"0.001"},{"price":"61908.60","quantity":"0.001"},{"price":"61926.60","quantity":"0.001"},{"price":"62112.10","quantity":"0.018"},{"price":"62472.70","quantity":"0.084"},{"price":"63091.20","quantity":"0.032"}],"raw":{"e":"depthUpdate","E":1783517072312,"T":1783517072311,"s":"BTCUSDT","ps":"BTCUSDT","U":10999771064470,"u":10999771075156,"pu":10999771064414,"b":[["11354.10","0.832"],["11454.10","2.368"],["11554.10","1.241"],["11654.10","0.459"],["49483.00","0.000"],["55668.60","0.002"],["58759.60","0.000"],["59379.90","0.003"],["61152.50","0.490"],["61173.70","0.315"],["61235.10","0.002"],["61235.60","0.328"],["61266.20","3.234"],["61585.90","0.008"],["61586.00","0.052"],["61799.00","0.008"],["61815.40","0.004"],["61815.70","0.002"],["61823.80","0.150"],["61828.10","0.008"],["61830.40","0.130"],["61835.90","1.054"],["61836.00","0.064"],["61836.10","0.001"],["61841.40","0.928"],["61843.10","0.090"],["61843.20","0.308"],["61854.10","17.096"]],"a":[["61854.20","2.609"],["61854.30","0.026"],["61855.40","0.243"],["61856.30","0.035"],["61859.00","0.174"],["61860.00","0.176"],["61860.40","0.308"],["61866.80","1.292"],["61872.80","0.000"],["61891.30","0.202"],["61893.30","0.307"],["61893.40","0.472"],["61908.10","0.001"],["61908.60","0.001"],["61926.60","0.001"],["62112.10","0.018"],["62472.70","0.084"],["63091.20","0.032"]],"st":1}}
{"schema_version":"1.3.0","event_id":"4ba91312-2971-4587-a6aa-12718c6e8790","event_type":"raw.depth_update","source":"binance_market_data_recorder","venue":"binance_usdm","market_type":"perpetual_futures","symbol":"BTCUSDT","event_time_ms":1783517072414,"received_time_ms":1783517072409,"trace_id":"2cc36813-a8c3-4f49-9742-a5b0f4bbe5d0","first_update_id":10999771075173,"final_update_id":10999771085376,"previous_final_update_id":10999771075156,"bids":[{"price":"1000.00","quantity":"207.692"},{"price":"11354.10","quantity":"1.104"},{"price":"11454.10","quantity":"2.096"},{"price":"11554.10","quantity":"1.394"},{"price":"11654.10","quantity":"0.306"},{"price":"49483.00","quantity":"0.000"},{"price":"55668.60","quantity":"0.002"},{"price":"59379.90","quantity":"0.000"},{"price":"61235.60","quantity":"0.328"},{"price":"61544.80","quantity":"0.039"},{"price":"61785.60","quantity":"0.009"},{"price":"61785.90","quantity":"0.223"},{"price":"61786.20","quantity":"0.000"},{"price":"61786.50","quantity":"0.022"},{"price":"61786.70","quantity":"0.057"},{"price":"61805.00","quantity":"6.582"},{"price":"61805.30","quantity":"1.313"},{"price":"61805.60","quantity":"0.354"},{"price":"61805.90","quantity":"0.002"},{"price":"61806.10","quantity":"0.007"},{"price":"61813.40","quantity":"0.163"},{"price":"61813.80","quantity":"0.014"},{"price":"61813.90","quantity":"0.003"},{"price":"61814.20","quantity":"0.277"},{"price":"61815.10","quantity":"0.004"},{"price":"61819.90","quantity":"0.001"},{"price":"61820.10","quantity":"10.663"},{"price":"61820.20","quantity":"0.134"},{"price":"61820.50","quantity":"0.220"},{"price":"61820.60","quantity":"0.020"},{"price":"61821.10","quantity":"0.683"},{"price":"61823.40","quantity":"0.451"},{"price":"61823.50","quantity":"0.092"},{"price":"61824.40","quantity":"0.001"},{"price":"61828.70","quantity":"0.250"},{"price":"61830.00","quantity":"0.006"},{"price":"61843.20","quantity":"0.008"},{"price":"61843.40","quantity":"0.002"},{"price":"61843.50","quantity":"0.002"},{"price":"61843.70","quantity":"0.063"},{"price":"61843.80","quantity":"0.323"},{"price":"61843.90","quantity":"0.000"},{"price":"61844.00","quantity":"0.000"},{"price":"61844.40","quantity":"0.020"},{"price":"61844.60","quantity":"0.005"},{"price":"61844.90","quantity":"0.809"},{"price":"61846.00","quantity":"0.332"},{"price":"61849.90","quantity":"0.000"},{"price":"61850.00","quantity":"1.020"}],"asks":[{"price":"61858.10","quantity":"0.093"},{"price":"61859.60","quantity":"0.016"},{"price":"61860.00","quantity":"0.174"},{"price":"61860.30","quantity":"0.002"},{"price":"61860.40","quantity":"0.018"},{"price":"61860.60","quantity":"0.002"},{"price":"61860.70","quantity":"0.126"},{"price":"61860.90","quantity":"0.000"},{"price":"61861.00","quantity":"0.004"},{"price":"61861.30","quantity":"0.000"},{"price":"61861.40","quantity":"2.322"},{"price":"61861.50","quantity":"0.004"},{"price":"61861.60","quantity":"0.002"},{"price":"61869.70","quantity":"0.211"},{"price":"61872.80","quantity":"0.128"},{"price":"61879.00","quantity":"0.010"},{"price":"61879.40","quantity":"0.341"},{"price":"61879.70","quantity":"0.046"},{"price":"61880.00","quantity":"0.013"},{"price":"61880.30","quantity":"0.819"},{"price":"61880.40","quantity":"0.285"},{"price":"61883.60","quantity":"0.110"},{"price":"61883.70","quantity":"0.002"},{"price":"61884.20","quantity":"0.003"},{"price":"61884.30","quantity":"0.784"},{"price":"61884.60","quantity":"0.003"},{"price":"61884.70","quantity":"0.458"},{"price":"61884.80","quantity":"0.241"},{"price":"61884.90","quantity":"0.014"},{"price":"61890.30","quantity":"0.838"},{"price":"61897.50","quantity":"0.168"},{"price":"61898.40","quantity":"1.206"},{"price":"61898.70","quantity":"0.098"},{"price":"61899.10","quantity":"0.031"},{"price":"61899.40","quantity":"2.428"},{"price":"61899.70","quantity":"4.503"},{"price":"61909.90","quantity":"0.376"},{"price":"61926.60","quantity":"0.098"},{"price":"62427.60","quantity":"3.116"},{"price":"62472.70","quantity":"0.082"},{"price":"62716.00","quantity":"9.598"},{"price":"63047.00","quantity":"0.016"},{"price":"89523.20","quantity":"0.888"}],"raw":{"e":"depthUpdate","E":1783517072414,"T":1783517072413,"s":"BTCUSDT","ps":"BTCUSDT","U":10999771075173,"u":10999771085376,"pu":10999771075156,"b":[["1000.00","207.692"],["11354.10","1.104"],["11454.10","2.096"],["11554.10","1.394"],["11654.10","0.306"],["49483.00","0.000"],["55668.60","0.002"],["59379.90","0.000"],["61235.60","0.328"],["61544.80","0.039"],["61785.60","0.009"],["61785.90","0.223"],["61786.20","0.000"],["61786.50","0.022"],["61786.70","0.057"],["61805.00","6.582"],["61805.30","1.313"],["61805.60","0.354"],["61805.90","0.002"],["61806.10","0.007"],["61813.40","0.163"],["61813.80","0.014"],["61813.90","0.003"],["61814.20","0.277"],["61815.10","0.004"],["61819.90","0.001"],["61820.10","10.663"],["61820.20","0.134"],["61820.50","0.220"],["61820.60","0.020"],["61821.10","0.683"],["61823.40","0.451"],["61823.50","0.092"],["61824.40","0.001"],["61828.70","0.250"],["61830.00","0.006"],["61843.20","0.008"],["61843.40","0.002"],["61843.50","0.002"],["61843.70","0.063"],["61843.80","0.323"],["61843.90","0.000"],["61844.00","0.000"],["61844.40","0.020"],["61844.60","0.005"],["61844.90","0.809"],["61846.00","0.332"],["61849.90","0.000"],["61850.00","1.020"]],"a":[["61858.10","0.093"],["61859.60","0.016"],["61860.00","0.174"],["61860.30","0.002"],["61860.40","0.018"],["61860.60","0.002"],["61860.70","0.126"],["61860.90","0.000"],["61861.00","0.004"],["61861.30","0.000"],["61861.40","2.322"],["61861.50","0.004"],["61861.60","0.002"],["61869.70","0.211"],["61872.80","0.128"],["61879.00","0.010"],["61879.40","0.341"],["61879.70","0.046"],["61880.00","0.013"],["61880.30","0.819"],["61880.40","0.285"],["61883.60","0.110"],["61883.70","0.002"],["61884.20","0.003"],["61884.30","0.784"],["61884.60","0.003"],["61884.70","0.458"],["61884.80","0.241"],["61884.90","0.014"],["61890.30","0.838"],["61897.50","0.168"],["61898.40","1.206"],["61898.70","0.098"],["61899.10","0.031"],["61899.40","2.428"],["61899.70","4.503"],["61909.90","0.376"],["61926.60","0.098"],["62427.60","3.116"],["62472.70","0.082"],["62716.00","9.598"],["63047.00","0.016"],["89523.20","0.888"]],"st":1}}
{"schema_version":"1.3.0","event_id":"92656899-2e00-4b10-8c56-3a71b5cc677e","event_type":"raw.depth_update","source":"binance_market_data_recorder","venue":"binance_usdm","market_type":"perpetual_futures","symbol":"BTCUSDT","event_time_ms":1783517072516,"received_time_ms":1783517072511,"trace_id":"3be2579a-d18a-40ce-99db-29ac99d45eef","first_update_id":10999771085385,"final_update_id":10999771098342,"previous_final_update_id":10999771085376,"bids":[{"price":"1000.00","quantity":"207.692"},{"price":"11354.10","quantity":"1.376"},{"price":"11454.10","quantity":"1.824"},{"price":"11554.10","quantity":"1.530"},{"price":"11654.10","quantity":"0.170"},{"price":"55668.60","quantity":"0.002"},{"price":"59379.90","quantity":"0.003"},{"price":"60307.70","quantity":"0.085"},{"price":"61080.90","quantity":"0.408"},{"price":"61235.60","quantity":"0.328"},{"price":"61805.30","quantity":"1.345"},{"price":"61806.40","quantity":"0.033"},{"price":"61822.70","quantity":"0.118"},{"price":"61822.90","quantity":"0.108"},{"price":"61823.30","quantity":"2.021"},{"price":"61826.70","quantity":"0.011"},{"price":"61828.10","quantity":"0.088"},{"price":"61830.40","quantity":"0.050"},{"price":"61835.90","quantity":"1.056"},{"price":"61836.00","quantity":"0.066"},{"price":"61836.10","quantity":"0.003"},{"price":"61843.10","quantity":"0.979"},{"price":"61843.20","quantity":"0.008"},{"price":"61843.40","quantity":"0.062"},{"price":"61843.60","quantity":"0.062"},{"price":"61843.70","quantity":"0.123"},{"price":"61843.80","quantity":"0.327"},{"price":"61844.00","quantity":"0.092"},{"price":"61845.10","quantity":"0.317"},{"price":"61847.60","quantity":"0.004"},{"price":"61850.40","quantity":"0.000"},{"price":"61851.70","quantity":"0.005"},{"price":"61853.50","quantity":"0.000"},{"price":"61854.10","quantity":"16.774"}],"asks":[{"price":"61854.20","quantity":"2.605"},{"price":"61854.80","quantity":"0.001"},{"price":"61855.40","quantity":"0.001"},{"price":"61855.80","quantity":"0.247"},{"price":"61857.10","quantity":"0.325"},{"price":"61859.70","quantity":"0.164"},{"price":"61859.90","quantity":"0.306"},{"price":"61860.00","quantity":"1.054"},{"price":"61860.40","quantity":"0.146"},{"price":"61861.10","quantity":"0.638"},{"price":"61861.40","quantity":"2.514"},{"price":"61861.50","quantity":"0.166"},{"price":"61861.60","quantity":"0.182"},{"price":"61863.50","quantity":"0.130"},{"price":"61865.90","quantity":"0.406"},{"price":"61869.20","quantity":"0.043"},{"price":"61878.30","quantity":"0.000"},{"price":"61879.10","quantity":"0.166"},{"price":"61880.40","quantity":"0.465"},{"price":"61880.50","quantity":"0.090"},{"price":"61884.70","quantity":"0.650"},{"price":"61884.80","quantity":"0.403"},{"price":"61884.90","quantity":"0.194"},{"price":"61889.40","quantity":"0.020"},{"price":"61890.30","quantity":"0.836"},{"price":"61898.20","quantity":"0.265"},{"price":"61898.40","quantity":"1.369"},{"price":"61899.80","quantity":"0.086"},{"price":"61926.60","quantity":"0.001"},{"price":"61926.70","quantity":"0.098"},{"price":"61952.30","quantity":"0.000"},{"price":"62410.90","quantity":"0.480"},{"price":"62472.70","quantity":"1.678"},{"price":"62530.80","quantity":"0.240"},{"price":"62576.30","quantity":"0.003"},{"price":"63423.90","quantity":"0.000"}],"raw":{"e":"depthUpdate","E":1783517072516,"T":1783517072513,"s":"BTCUSDT","ps":"BTCUSDT","U":10999771085385,"u":10999771098342,"pu":10999771085376,"b":[["1000.00","207.692"],["11354.10","1.376"],["11454.10","1.824"],["11554.10","1.530"],["11654.10","0.170"],["55668.60","0.002"],["59379.90","0.003"],["60307.70","0.085"],["61080.90","0.408"],["61235.60","0.328"],["61805.30","1.345"],["61806.40","0.033"],["61822.70","0.118"],["61822.90","0.108"],["61823.30","2.021"],["61826.70","0.011"],["61828.10","0.088"],["61830.40","0.050"],["61835.90","1.056"],["61836.00","0.066"],["61836.10","0.003"],["61843.10","0.979"],["61843.20","0.008"],["61843.40","0.062"],["61843.60","0.062"],["61843.70","0.123"],["61843.80","0.327"],["61844.00","0.092"],["61845.10","0.317"],["61847.60","0.004"],["61850.40","0.000"],["61851.70","0.005"],["61853.50","0.000"],["61854.10","16.774"]],"a":[["61854.20","2.605"],["61854.80","0.001"],["61855.40","0.001"],["61855.80","0.247"],["61857.10","0.325"],["61859.70","0.164"],["61859.90","0.306"],["61860.00","1.054"],["61860.40","0.146"],["61861.10","0.638"],["61861.40","2.514"],["61861.50","0.166"],["61861.60","0.182"],["61863.50","0.130"],["61865.90","0.406"],["61869.20","0.043"],["61878.30","0.000"],["61879.10","0.166"],["61880.40","0.465"],["61880.50","0.090"],["61884.70","0.650"],["61884.80","0.403"],["61884.90","0.194"],["61889.40","0.020"],["61890.30","0.836"],["61898.20","0.265"],["61898.40","1.369"],["61899.80","0.086"],["61926.60","0.001"],["61926.70","0.098"],["61952.30","0.000"],["62410.90","0.480"],["62472.70","1.678"],["62530.80","0.240"],["62576.30","0.003"],["63423.90","0.000"]],"st":1}}
{"schema_version":"1.3.0","event_id":"a9ac3dcd-c27d-4634-8bfd-efb1a24a72f1","event_type":"raw.depth_update","source":"binance_market_data_recorder","venue":"binance_usdm","market_type":"perpetual_futures","symbol":"BTCUSDT","event_time_ms":1783517072618,"received_time_ms":1783517072613,"trace_id":"e694d6fe-a4c9-47b6-8a78-1677b910d256","first_update_id":10999771098591,"final_update_id":10999771107302,"previous_final_update_id":10999771098342,"bids":[{"price":"11354.10","quantity":"1.648"},{"price":"11454.10","quantity":"1.552"},{"price":"11554.10","quantity":"1.683"},{"price":"11654.10","quantity":"0.017"},{"price":"55668.60","quantity":"0.002"},{"price":"60804.70","quantity":"0.001"},{"price":"61076.90","quantity":"2.845"},{"price":"61156.80","quantity":"7.594"},{"price":"61235.60","quantity":"0.328"},{"price":"61380.60","quantity":"2.000"},{"price":"61544.80","quantity":"0.029"},{"price":"61724.90","quantity":"0.001"},{"price":"61749.70","quantity":"0.010"},{"price":"61805.60","quantity":"0.386"},{"price":"61806.10","quantity":"0.039"},{"price":"61821.00","quantity":"0.745"},{"price":"61822.60","quantity":"0.106"},{"price":"61822.70","quantity":"0.118"},{"price":"61823.10","quantity":"0.000"},{"price":"61823.40","quantity":"0.075"},{"price":"61823.80","quantity":"0.090"},{"price":"61828.10","quantity":"0.088"},{"price":"61830.40","quantity":"0.050"},{"price":"61838.60","quantity":"0.000"},{"price":"61842.20","quantity":"0.025"},{"price":"61843.10","quantity":"0.979"},{"price":"61843.50","quantity":"0.062"},{"price":"61844.00","quantity":"0.092"},{"price":"61844.10","quantity":"0.060"},{"price":"61844.30","quantity":"0.034"},{"price":"61844.70","quantity":"0.062"},{"price":"61844.90","quantity":"0.841"},{"price":"61853.90","quantity":"0.244"},{"price":"61854.10","quantity":"16.748"}],"asks":[{"price":"61854.20","quantity":"2.630"},{"price":"61854.30","quantity":"0.027"},{"price":"61856.00","quantity":"0.004"},{"price":"61856.40","quantity":"0.029"},{"price":"61856.60","quantity":"0.284"},{"price":"61857.10","quantity":"0.001"},{"price":"61859.90","quantity":"0.180"},{"price":"61860.10","quantity":"1.749"},{"price":"61860.40","quantity":"0.344"},{"price":"61860.70","quantity":"0.232"},{"price":"61861.10","quantity":"0.776"},{"price":"61861.60","quantity":"0.350"},{"price":"61864.00","quantity":"2.153"},{"price":"61866.10","quantity":"0.566"},{"price":"61872.80","quantity":"0.000"},{"price":"61879.40","quantity":"0.469"},{"price":"61880.10","quantity":"0.108"},{"price":"61883.70","quantity":"0.200"},{"price":"61884.40","quantity":"0.143"},{"price":"61884.90","quantity":"0.362"},{"price":"61888.80","quantity":"0.127"},{"price":"61889.00","quantity":"0.002"},{"price":"61889.40","quantity":"0.018"},{"price":"61898.80","quantity":"0.128"},{"price":"61899.50","quantity":"0.107"},{"price":"62059.50","quantity":"0.001"},{"price":"62350.70","quantity":"0.000"},{"price":"62441.80","quantity":"1.841"},{"price":"62472.70","quantity":"1.678"},{"price":"62968.60","quantity":"0.793"},{"price":"89523.20","quantity":"0.894"}],"raw":{"e":"depthUpdate","E":1783517072618,"T":1783517072617,"s":"BTCUSDT","ps":"BTCUSDT","U":10999771098591,"u":10999771107302,"pu":10999771098342,"b":[["11354.10","1.648"],["11454.10","1.552"],["11554.10","1.683"],["11654.10","0.017"],["55668.60","0.002"],["60804.70","0.001"],["61076.90","2.845"],["61156.80","7.594"],["61235.60","0.328"],["61380.60","2.000"],["61544.80","0.029"],["61724.90","0.001"],["61749.70","0.010"],["61805.60","0.386"],["61806.10","0.039"],["61821.00","0.745"],["61822.60","0.106"],["61822.70","0.118"],["61823.10","0.000"],["61823.40","0.075"],["61823.80","0.090"],["61828.10","0.088"],["61830.40","0.050"],["61838.60","0.000"],["61842.20","0.025"],["61843.10","0.979"],["61843.50","0.062"],["61844.00","0.092"],["61844.10","0.060"],["61844.30","0.034"],["61844.70","0.062"],["61844.90","0.841"],["61853.90","0.244"],["61854.10","16.748"]],"a":[["61854.20","2.630"],["61854.30","0.027"],["61856.00","0.004"],["61856.40","0.029"],["61856.60","0.284"],["61857.10","0.001"],["61859.90","0.180"],["61860.10","1.749"],["61860.40","0.344"],["61860.70","0.232"],["61861.10","0.776"],["61861.60","0.350"],["61864.00","2.153"],["61866.10","0.566"],["61872.80","0.000"],["61879.40","0.469"],["61880.10","0.108"],["61883.70","0.200"],["61884.40","0.143"],["61884.90","0.362"],["61888.80","0.127"],["61889.00","0.002"],["61889.40","0.018"],["61898.80","0.128"],["61899.50","0.107"],["62059.50","0.001"],["62350.70","0.000"],["62441.80","1.841"],["62472.70","1.678"],["62968.60","0.793"],["89523.20","0.894"]],"st":1}}
{"schema_version":"1.3.0","event_id":"34fbec85-0060-4aaf-bda4-218b2851df06","event_type":"raw.depth_update","source":"binance_market_data_recorder","venue":"binance_usdm","market_type":"perpetual_futures","symbol":"BTCUSDT","event_time_ms":1783517072720,"received_time_ms":1783517072715,"trace_id":"bc4d31a9-a538-40b5-96c3-0079bcfeafa0","first_update_id":10999771107325,"final_update_id":10999771116221,"previous_final_update_id":10999771107302,"bids":[{"price":"1000.00","quantity":"207.842"},{"price":"11354.10","quantity":"1.920"},{"price":"11454.10","quantity":"1.399"},{"price":"11554.10","quantity":"1.581"},{"price":"11654.10","quantity":"0.000"},{"price":"55668.60","quantity":"0.002"},{"price":"59379.90","quantity":"0.000"},{"price":"61111.90","quantity":"6.538"},{"price":"61235.60","quantity":"0.328"},{"price":"61544.80","quantity":"0.039"},{"price":"61750.40","quantity":"0.013"},{"price":"61750.50","quantity":"0.003"},{"price":"61787.00","quantity":"0.222"},{"price":"61789.00","quantity":"6.221"},{"price":"61805.90","quantity":"0.034"},{"price":"61821.10","quantity":"0.247"},{"price":"61821.20","quantity":"0.537"},{"price":"61822.60","quantity":"0.001"},{"price":"61822.70","quantity":"0.013"},{"price":"61822.90","quantity":"0.003"},{"price":"61823.10","quantity":"0.105"},{"price":"61828.10","quantity":"0.088"},{"price":"61830.40","quantity":"0.050"},{"price":"61838.60","quantity":"0.128"},{"price":"61842.10","quantity":"0.001"},{"price":"61842.20","quantity":"0.001"},{"price":"61843.10","quantity":"0.987"},{"price":"61844.10","quantity":"0.240"},{"price":"61844.60","quantity":"0.037"},{"price":"61844.70","quantity":"0.122"},{"price":"61845.10","quantity":"0.317"},{"price":"61845.30","quantity":"0.005"},{"price":"61845.40","quantity":"0.000"},{"price":"61845.80","quantity":"0.000"},{"price":"61850.40","quantity":"0.122"},{"price":"61851.70","quantity":"0.001"},{"price":"61853.60","quantity":"0.004"},{"price":"61854.10","quantity":"17.070"}],"asks":[{"price":"61854.20","quantity":"2.517"},{"price":"61855.80","quantity":"0.005"},{"price":"61856.10","quantity":"0.242"},{"price":"61856.50","quantity":"0.058"},{"price":"61856.60","quantity":"0.235"},{"price":"61858.10","quantity":"0.089"},{"price":"61859.70","quantity":"0.168"},{"price":"61859.90","quantity":"0.180"},{"price":"61860.40","quantity":"0.450"},{"price":"61860.50","quantity":"1.479"},{"price":"61861.00","quantity":"0.508"},{"price":"61863.50","quantity":"0.002"},{"price":"61863.90","quantity":"1.694"},{"price":"61869.70","quantity":"0.083"},{"price":"61879.80","quantity":"0.188"},{"price":"61880.40","quantity":"0.657"},{"price":"61883.80","quantity":"0.181"},{"price":"61884.30","quantity":"1.096"},{"price":"61887.20","quantity":"0.002"},{"price":"61888.80","quantity":"0.230"},{"price":"61899.20","quantity":"0.106"},{"price":"62028.70","quantity":"0.001"},{"price":"62028.80","quantity":"0.004"},{"price":"62472.70","quantity":"1.678"},{"price":"62577.90","quantity":"0.559"},{"price":"63276.80","quantity":"0.316"},{"price":"63427.50","quantity":"2.283"}],"raw":{"e":"depthUpdate","E":1783517072720,"T":1783517072718,"s":"BTCUSDT","ps":"BTCUSDT","U":10999771107325,"u":10999771116221,"pu":10999771107302,"b":[["1000.00","207.842"],["11354.10","1.920"],["11454.10","1.399"],["11554.10","1.581"],["11654.10","0.000"],["55668.60","0.002"],["59379.90","0.000"],["61111.90","6.538"],["61235.60","0.328"],["61544.80","0.039"],["61750.40","0.013"],["61750.50","0.003"],["61787.00","0.222"],["61789.00","6.221"],["61805.90","0.034"],["61821.10","0.247"],["61821.20","0.537"],["61822.60","0.001"],["61822.70","0.013"],["61822.90","0.003"],["61823.10","0.105"],["61828.10","0.088"],["61830.40","0.050"],["61838.60","0.128"],["61842.10","0.001"],["61842.20","0.001"],["61843.10","0.987"],["61844.10","0.240"],["61844.60","0.037"],["61844.70","0.122"],["61845.10","0.317"],["61845.30","0.005"],["61845.40","0.000"],["61845.80","0.000"],["61850.40","0.122"],["61851.70","0.001"],["61853.60","0.004"],["61854.10","17.070"]],"a":[["61854.20","2.517"],["61855.80","0.005"],["61856.10","0.242"],["61856.50","0.058"],["61856.60","0.235"],["61858.10","0.089"],["61859.70","0.168"],["61859.90","0.180"],["61860.40","0.450"],["61860.50","1.479"],["61861.00","0.508"],["61863.50","0.002"],["61863.90","1.694"],["61869.70","0.083"],["61879.80","0.188"],["61880.40","0.657"],["61883.80","0.181"],["61884.30","1.096"],["61887.20","0.002"],["61888.80","0.230"],["61899.20","0.106"],["62028.70","0.001"],["62028.80","0.004"],["62472.70","1.678"],["62577.90","0.559"],["63276.80","0.316"],["63427.50","2.283"]],"st":1}}
{"schema_version":"1.3.0","event_id":"1c96183a-6ddc-4804-82dc-daffcdc29e0a","event_type":"raw.depth_update","source":"binance_market_data_recorder","venue":"binance_usdm","market_type":"perpetual_futures","symbol":"BTCUSDT","event_time_ms":1783517072822,"received_time_ms":1783517072817,"trace_id":"2980ecbc-7648-4981-b5ab-a14309b1db96","first_update_id":10999771116380,"final_update_id":10999771125602,"previous_final_update_id":10999771116221,"bids":[{"price":"1000.00","quantity":"207.692"},{"price":"11354.10","quantity":"2.192"},{"price":"11454.10","quantity":"1.280"},{"price":"11554.10","quantity":"1.428"},{"price":"49483.30","quantity":"0.000"},{"price":"55668.60","quantity":"0.002"},{"price":"59379.90","quantity":"0.003"},{"price":"60695.40","quantity":"1.596"},{"price":"61111.90","quantity":"7.191"},{"price":"61173.70","quantity":"0.560"},{"price":"61235.60","quantity":"0.328"},{"price":"61359.30","quantity":"0.717"},{"price":"61400.30","quantity":"0.211"},{"price":"61785.90","quantity":"0.255"},{"price":"61799.00","quantity":"0.000"},{"price":"61801.40","quantity":"0.044"},{"price":"61820.40","quantity":"1.489"},{"price":"61828.10","quantity":"0.008"},{"price":"61830.40","quantity":"0.050"},{"price":"61843.10","quantity":"0.178"},{"price":"61843.40","quantity":"0.122"},{"price":"61843.50","quantity":"0.182"},{"price":"61844.10","quantity":"0.300"},{"price":"61845.10","quantity":"0.640"},{"price":"61845.30","quantity":"0.571"},{"price":"61854.10","quantity":"17.038"}],"asks":[{"price":"61854.20","quantity":"2.517"},{"price":"61855.60","quantity":"0.242"},{"price":"61856.10","quantity":"0.000"},{"price":"61859.90","quantity":"0.180"},{"price":"61861.00","quantity":"0.688"},{"price":"61861.60","quantity":"0.554"},{"price":"61861.70","quantity":"0.318"},{"price":"61884.30","quantity":"1.276"},{"price":"61884.90","quantity":"0.566"},{"price":"61885.00","quantity":"0.376"},{"price":"61887.20","quantity":"0.107"},{"price":"61887.50","quantity":"0.110"},{"price":"61887.80","quantity":"0.286"},{"price":"61887.90","quantity":"0.379"},{"price":"61888.00","quantity":"0.494"},{"price":"61888.80","quantity":"0.125"},{"price":"61909.50","quantity":"2.896"},{"price":"61909.90","quantity":"0.275"},{"price":"62112.10","quantity":"0.000"},{"price":"62184.20","quantity":"0.002"},{"price":"62472.70","quantity":"1.678"},{"price":"62534.60","quantity":"0.240"},{"price":"89523.20","quantity":"0.900"}],"raw":{"e":"depthUpdate","E":1783517072822,"T":1783517072821,"s":"BTCUSDT","ps":"BTCUSDT","U":10999771116380,"u":10999771125602,"pu":10999771116221,"b":[["1000.00","207.692"],["11354.10","2.192"],["11454.10","1.280"],["11554.10","1.428"],["49483.30","0.000"],["55668.60","0.002"],["59379.90","0.003"],["60695.40","1.596"],["61111.90","7.191"],["61173.70","0.560"],["61235.60","0.328"],["61359.30","0.717"],["61400.30","0.211"],["61785.90","0.255"],["61799.00","0.000"],["61801.40","0.044"],["61820.40","1.489"],["61828.10","0.008"],["61830.40","0.050"],["61843.10","0.178"],["61843.40","0.122"],["61843.50","0.182"],["61844.10","0.300"],["61845.10","0.640"],["61845.30","0.571"],["61854.10","17.038"]],"a":[["61854.20","2.517"],["61855.60","0.242"],["61856.10","0.000"],["61859.90","0.180"],["61861.00","0.688"],["61861.60","0.554"],["61861.70","0.318"],["61884.30","1.276"],["61884.90","0.566"],["61885.00","0.376"],["61887.20","0.107"],["61887.50","0.110"],["61887.80","0.286"],["61887.90","0.379"],["61888.00","0.494"],["61888.80","0.125"],["61909.50","2.896"],["61909.90","0.275"],["62112.10","0.000"],["62184.20","0.002"],["62472.70","1.678"],["62534.60","0.240"],["89523.20","0.900"]],"st":1}}
{"schema_version":"1.3.0","event_id":"0a42c140-c9d3-4b50-b491-e16eeadf3eab","event_type":"raw.depth_update","source":"binance_market_data_recorder","venue":"binance_usdm","market_type":"perpetual_futures","symbol":"BTCUSDT","event_time_ms":1783517072924,"received_time_ms":1783517072918,"trace_id":"8455ba81-28e2-4be1-8b6e-a1a1caee87f2","first_update_id":10999771125763,"final_update_id":10999771132778,"previous_final_update_id":10999771125602,"bids":[{"price":"11354.10","quantity":"2.464"},{"price":"11454.10","quantity":"1.144"},{"price":"11554.10","quantity":"1.292"},{"price":"55668.60","quantity":"0.002"},{"price":"59379.90","quantity":"0.000"},{"price":"60616.70","quantity":"0.026"},{"price":"61107.80","quantity":"5.640"},{"price":"61235.60","quantity":"0.328"},{"price":"61243.70","quantity":"0.000"},{"price":"61360.00","quantity":"2.306"},{"price":"61391.50","quantity":"0.002"},{"price":"61506.20","quantity":"0.001"},{"price":"61544.80","quantity":"0.039"},{"price":"61649.80","quantity":"0.009"},{"price":"61688.90","quantity":"0.000"},{"price":"61766.80","quantity":"0.000"},{"price":"61786.20","quantity":"0.032"},{"price":"61786.80","quantity":"0.032"},{"price":"61794.20","quantity":"0.022"},{"price":"61820.10","quantity":"10.723"},{"price":"61820.30","quantity":"0.527"},{"price":"61820.40","quantity":"1.549"},{"price":"61824.60","quantity":"0.065"},{"price":"61826.60","quantity":"0.695"},{"price":"61827.20","quantity":"0.001"},{"price":"61828.10","quantity":"0.088"},{"price":"61839.40","quantity":"0.537"},{"price":"61840.50","quantity":"2.140"},{"price":"61843.10","quantity":"0.098"},{"price":"61854.10","quantity":"17.040"}],"asks":[{"price":"61854.20","quantity":"2.540"},{"price":"61855.20","quantity":"0.250"},{"price":"61855.60","quantity":"0.000"},{"price":"61859.90","quantity":"0.306"},{"price":"61860.00","quantity":"1.054"},{"price":"61860.40","quantity":"0.450"},{"price":"61863.90","quantity":"1.694"},{"price":"61865.00","quantity":"0.573"},{"price":"61865.10","quantity":"0.220"},{"price":"61866.10","quantity":"0.000"},{"price":"61866.20","quantity":"0.584"},{"price":"61871.60","quantity":"0.006"},{"price":"61874.20","quantity":"0.002"},{"price":"61884.50","quantity":"0.003"},{"price":"61887.60","quantity":"0.431"},{"price":"61887.80","quantity":"0.288"},{"price":"61893.50","quantity":"0.373"},{"price":"61912.50","quantity":"0.018"},{"price":"61981.60","quantity":"0.000"},{"price":"62109.70","quantity":"33.947"},{"price":"62140.20","quantity":"0.000"},{"price":"62370.90","quantity":"0.960"},{"price":"62406.40","quantity":"0.016"},{"price":"62472.70","quantity":"1.678"}],"raw":{"e":"depthUpdate","E":1783517072924,"T":1783517072921,"s":"BTCUSDT","ps":"BTCUSDT","U":10999771125763,"u":10999771132778,"pu":10999771125602,"b":[["11354.10","2.464"],["11454.10","1.144"],["11554.10","1.292"],["55668.60","0.002"],["59379.90","0.000"],["60616.70","0.026"],["61107.80","5.640"],["61235.60","0.328"],["61243.70","0.000"],["61360.00","2.306"],["61391.50","0.002"],["61506.20","0.001"],["61544.80","0.039"],["61649.80","0.009"],["61688.90","0.000"],["61766.80","0.000"],["61786.20","0.032"],["61786.80","0.032"],["61794.20","0.022"],["61820.10","10.723"],["61820.30","0.527"],["61820.40","1.549"],["61824.60","0.065"],["61826.60","0.695"],["61827.20","0.001"],["61828.10","0.088"],["61839.40","0.537"],["61840.50","2.140"],["61843.10","0.098"],["61854.10","17.040"]],"a":[["61854.20","2.540"],["61855.20","0.250"],["61855.60","0.000"],["61859.90","0.306"],["61860.00","1.054"],["61860.40","0.450"],["61863.90","1.694"],["61865.00","0.573"],["61865.10","0.220"],["61866.10","0.000"],["61866.20","0.584"],["61871.60","0.006"],["61874.20","0.002"],["61884.50","0.003"],["61887.60","0.431"],["61887.80","0.288"],["61893.50","0.373"],["61912.50","0.018"],["61981.60","0.000"],["62109.70","33.947"],["62140.20","0.000"],["62370.90","0.960"],["62406.40","0.016"],["62472.70","1.678"]],"st":1}}
{"schema_version":"1.3.0","event_id":"9bdefe1b-a731-4115-9eed-04aa35c88f79","event_type":"raw.depth_update","source":"binance_market_data_recorder","venue":"binance_usdm","market_type":"perpetual_futures","symbol":"BTCUSDT","event_time_ms":1783517073026,"received_time_ms":1783517073021,"trace_id":"dd4c108f-a16d-4ab7-aebc-0a135f120833","first_update_id":10999771132921,"final_update_id":10999771142616,"previous_final_update_id":10999771132778,"bids":[{"price":"1000.00","quantity":"207.692"},{"price":"11354.10","quantity":"2.736"},{"price":"11454.10","quantity":"1.025"},{"price":"11554.10","quantity":"1.139"},{"price":"55668.60","quantity":"0.002"},{"price":"61235.60","quantity":"0.328"},{"price":"61786.50","quantity":"0.054"},{"price":"61796.30","quantity":"0.001"},{"price":"61804.10","quantity":"2.348"},{"price":"61808.30","quantity":"1.119"},{"price":"61813.50","quantity":"0.118"},{"price":"61814.50","quantity":"0.003"},{"price":"61820.20","quantity":"0.194"},{"price":"61820.80","quantity":"0.110"},{"price":"61821.40","quantity":"0.064"},{"price":"61824.80","quantity":"0.001"},{"price":"61828.10","quantity":"0.088"},{"price":"61830.40","quantity":"0.050"},{"price":"61833.00","quantity":"0.063"},{"price":"61833.20","quantity":"0.967"},{"price":"61839.40","quantity":"0.457"},{"price":"61843.10","quantity":"0.098"},{"price":"61843.50","quantity":"0.182"}],"asks":[{"price":"61856.50","quantity":"0.009"},{"price":"61859.90","quantity":"0.180"},{"price":"61860.40","quantity":"0.454"},{"price":"61865.00","quantity":"0.007"},{"price":"61866.10","quantity":"0.566"},{"price":"61866.60","quantity":"3.360"},{"price":"61868.60","quantity":"0.021"},{"price":"61872.80","quantity":"0.003"},{"price":"61887.80","quantity":"0.286"},{"price":"62472.70","quantity":"1.678"},{"price":"89523.20","quantity":"0.906"}],"raw":{"e":"depthUpdate","E":1783517073026,"T":1783517073025,"s":"BTCUSDT","ps":"BTCUSDT","U":10999771132921,"u":10999771142616,"pu":10999771132778,"b":[["1000.00","207.692"],["11354.10","2.736"],["11454.10","1.025"],["11554.10","1.139"],["55668.60","0.002"],["61235.60","0.328"],["61786.50","0.054"],["61796.30","0.001"],["61804.10","2.348"],["61808.30","1.119"],["61813.50","0.118"],["61814.50","0.003"],["61820.20","0.194"],["61820.80","0.110"],["61821.40","0.064"],["61824.80","0.001"],["61828.10","0.088"],["61830.40","0.050"],["61833.00","0.063"],["61833.20","0.967"],["61839.40","0.457"],["61843.10","0.098"],["61843.50","0.182"]],"a":[["61856.50","0.009"],["61859.90","0.180"],["61860.40","0.454"],["61865.00","0.007"],["61866.10","0.566"],["61866.60","3.360"],["61868.60","0.021"],["61872.80","0.003"],["61887.80","0.286"],["62472.70","1.678"],["89523.20","0.906"]],"st":1}}
{"schema_version":"1.3.0","event_id":"269fd32a-ad4c-48a8-b31d-1cf2632b56a7","event_type":"raw.depth_update","source":"binance_market_data_recorder","venue":"binance_usdm","market_type":"perpetual_futures","symbol":"BTCUSDT","event_time_ms":1783517073128,"received_time_ms":1783517073123,"trace_id":"66bddd09-eed1-4d3f-8bf5-8a7210bb9859","first_update_id":10999771142830,"final_update_id":10999771152408,"previous_final_update_id":10999771142616,"bids":[{"price":"11354.10","quantity":"2.720"},{"price":"11454.10","quantity":"1.033"},{"price":"11554.10","quantity":"1.003"},{"price":"11754.10","quantity":"0.144"},{"price":"55668.60","quantity":"0.002"},{"price":"59379.90","quantity":"0.003"},{"price":"60616.70","quantity":"0.023"},{"price":"60886.30","quantity":"0.000"},{"price":"60894.00","quantity":"0.000"},{"price":"61235.60","quantity":"0.328"},{"price":"61328.00","quantity":"0.085"},{"price":"61544.80","quantity":"0.038"},{"price":"61805.50","quantity":"0.021"},{"price":"61805.60","quantity":"0.370"},{"price":"61813.40","quantity":"0.062"},{"price":"61813.50","quantity":"0.017"},{"price":"61813.80","quantity":"0.115"},{"price":"61814.20","quantity":"0.176"},{"price":"61820.80","quantity":"0.230"},{"price":"61821.40","quantity":"0.124"},{"price":"61824.70","quantity":"0.061"},{"price":"61833.20","quantity":"0.887"},{"price":"61836.30","quantity":"0.082"},{"price":"61843.00","quantity":"0.001"},{"price":"61854.10","quantity":"17.050"}],"asks":[{"price":"61854.50","quantity":"0.001"},{"price":"61856.50","quantity":"0.058"},{"price":"61859.90","quantity":"0.306"},{"price":"61860.40","quantity":"0.450"},{"price":"61864.00","quantity":"2.153"},{"price":"61865.30","quantity":"0.456"},{"price":"61866.10","quantity":"0.566"},{"price":"61866.60","quantity":"3.356"},{"price":"61868.60","quantity":"0.004"},{"price":"61872.80","quantity":"0.000"},{"price":"61887.80","quantity":"0.288"},{"price":"62163.50","quantity":"0.000"},{"price":"62340.10","quantity":"0.000"},{"price":"62454.50","quantity":"0.335"},{"price":"62472.70","quantity":"1.678"},{"price":"62818.10","quantity":"0.000"},{"price":"63090.80","quantity":"0.006"}],"raw":{"e":"depthUpdate","E":1783517073128,"T":1783517073125,"s":"BTCUSDT","ps":"BTCUSDT","U":10999771142830,"u":10999771152408,"pu":10999771142616,"b":[["11354.10","2.720"],["11454.10","1.033"],["11554.10","1.003"],["11754.10","0.144"],["55668.60","0.002"],["59379.90","0.003"],["60616.70","0.023"],["60886.30","0.000"],["60894.00","0.000"],["61235.60","0.328"],["61328.00","0.085"],["61544.80","0.038"],["61805.50","0.021"],["61805.60","0.370"],["61813.40","0.062"],["61813.50","0.017"],["61813.80","0.115"],["61814.20","0.176"],["61820.80","0.230"],["61821.40","0.124"],["61824.70","0.061"],["61833.20","0.887"],["61836.30","0.082"],["61843.00","0.001"],["61854.10","17.050"]],"a":[["61854.50","0.001"],["61856.50","0.058"],["61859.90","0.306"],["61860.40","0.450"],["61864.00","2.153"],["61865.30","0.456"],["61866.10","0.566"],["61866.60","3.356"],["61868.60","0.004"],["61872.80","0.000"],["61887.80","0.288"],["62163.50","0.000"],["62340.10","0.000"],["62454.50","0.335"],["62472.70","1.678"],["62818.10","0.000"],["63090.80","0.006"]],"st":1}}
{"schema_version":"1.3.0","event_id":"1425ba68-6de6-492c-81ca-1a6da76a2b1d","event_type":"raw.depth_update","source":"binance_market_data_recorder","venue":"binance_usdm","market_type":"perpetual_futures","symbol":"BTCUSDT","event_time_ms":1783517073230,"received_time_ms":1783517073225,"trace_id":"fc25def6-cfbb-4462-8b66-88d07820f93c","first_update_id":10999771152668,"final_update_id":10999771160339,"previous_final_update_id":10999771152408,"bids":[{"price":"11354.10","quantity":"2.736"},{"price":"11454.10","quantity":"1.042"},{"price":"11554.10","quantity":"0.850"},{"price":"11754.10","quantity":"0.272"},{"price":"55668.60","quantity":"0.002"},{"price":"59379.90","quantity":"0.000"},{"price":"60888.10","quantity":"0.991"},{"price":"60895.40","quantity":"1.148"},{"price":"61098.20","quantity":"4.905"},{"price":"61235.60","quantity":"0.330"},{"price":"61263.70","quantity":"0.661"},{"price":"61348.00","quantity":"0.473"},{"price":"61544.80","quantity":"0.039"},{"price":"61723.60","quantity":"0.004"},{"price":"61723.70","quantity":"0.281"},{"price":"61770.60","quantity":"2.426"},{"price":"61784.70","quantity":"0.839"},{"price":"61815.80","quantity":"2.461"},{"price":"61820.10","quantity":"10.783"},{"price":"61820.20","quantity":"0.314"},{"price":"61820.80","quantity":"0.290"},{"price":"61821.90","quantity":"0.575"},{"price":"61828.10","quantity":"0.008"},{"price":"61829.60","quantity":"0.119"},{"price":"61830.40","quantity":"0.130"},{"price":"61836.30","quantity":"0.002"},{"price":"61838.60","quantity":"0.128"},{"price":"61841.00","quantity":"0.083"},{"price":"61842.80","quantity":"0.889"},{"price":"61843.10","quantity":"0.018"},{"price":"61845.10","quantity":"0.317"},{"price":"61845.30","quantity":"0.005"},{"price":"61850.00","quantity":"1.060"}],"asks":[{"price":"61854.20","quantity":"3.501"},{"price":"61854.40","quantity":"0.001"},{"price":"61859.50","quantity":"0.084"},{"price":"61859.90","quantity":"0.306"},{"price":"61864.50","quantity":"0.002"},{"price":"61865.60","quantity":"0.327"},{"price":"61869.40","quantity":"0.128"},{"price":"61870.90","quantity":"0.133"},{"price":"61887.50","quantity":"0.005"},{"price":"61887.60","quantity":"0.326"},{"price":"61887.80","quantity":"0.286"},{"price":"61893.40","quantity":"0.306"},{"price":"61893.70","quantity":"1.777"},{"price":"61909.40","quantity":"0.367"},{"price":"61915.70","quantity":"0.302"},{"price":"61944.00","quantity":"0.622"},{"price":"61985.30","quantity":"2.830"},{"price":"62163.50","quantity":"0.001"},{"price":"62360.30","quantity":"0.321"},{"price":"62472.70","quantity":"1.678"},{"price":"62820.00","quantity":"0.279"},{"price":"89523.20","quantity":"0.912"}],"raw":{"e":"depthUpdate","E":1783517073230,"T":1783517073229,"s":"BTCUSDT","ps":"BTCUSDT","U":10999771152668,"u":10999771160339,"pu":10999771152408,"b":[["11354.10","2.736"],["11454.10","1.042"],["11554.10","0.850"],["11754.10","0.272"],["55668.60","0.002"],["59379.90","0.000"],["60888.10","0.991"],["60895.40","1.148"],["61098.20","4.905"],["61235.60","0.330"],["61263.70","0.661"],["61348.00","0.473"],["61544.80","0.039"],["61723.60","0.004"],["61723.70","0.281"],["61770.60","2.426"],["61784.70","0.839"],["61815.80","2.461"],["61820.10","10.783"],["61820.20","0.314"],["61820.80","0.290"],["61821.90","0.575"],["61828.10","0.008"],["61829.60","0.119"],["61830.40","0.130"],["61836.30","0.002"],["61838.60","0.128"],["61841.00","0.083"],["61842.80","0.889"],["61843.10","0.018"],["61845.10","0.317"],["61845.30","0.005"],["61850.00","1.060"]],"a":[["61854.20","3.501"],["61854.40","0.001"],["61859.50","0.084"],["61859.90","0.306"],["61864.50","0.002"],["61865.60","0.327"],["61869.40","0.128"],["61870.90","0.133"],["61887.50","0.005"],["61887.60","0.326"],["61887.80","0.286"],["61893.40","0.306"],["61893.70","1.777"],["61909.40","0.367"],["61915.70","0.302"],["61944.00","0.622"],["61985.30","2.830"],["62163.50","0.001"],["62360.30","0.321"],["62472.70","1.678"],["62820.00","0.279"],["89523.20","0.912"]],"st":1}}
{"schema_version":"1.3.0","event_id":"4d337fbf-2893-431a-8629-a0804224b566","event_type":"raw.depth_update","source":"binance_market_data_recorder","venue":"binance_usdm","market_type":"perpetual_futures","symbol":"BTCUSDT","event_time_ms":1783517073332,"received_time_ms":1783517073327,"trace_id":"f23f5e67-0702-4a7d-83e1-1f21525089aa","first_update_id":10999771160408,"final_update_id":10999771168540,"previous_final_update_id":10999771160339,"bids":[{"price":"1000.00","quantity":"207.692"},{"price":"11354.10","quantity":"2.720"},{"price":"11454.10","quantity":"1.050"},{"price":"11554.10","quantity":"0.714"},{"price":"11754.10","quantity":"0.416"},{"price":"55668.60","quantity":"0.002"},{"price":"58759.60","quantity":"0.002"},{"price":"58761.30","quantity":"0.020"},{"price":"59379.90","quantity":"0.003"},{"price":"61033.10","quantity":"3.108"},{"price":"61118.00","quantity":"1.013"},{"price":"61169.90","quantity":"0.001"},{"price":"61235.60","quantity":"0.328"},{"price":"61829.60","quantity":"0.039"},{"price":"61842.80","quantity":"0.889"},{"price":"61842.90","quantity":"0.000"},{"price":"61843.00","quantity":"0.001"},{"price":"61845.10","quantity":"0.317"},{"price":"61845.30","quantity":"0.005"}],"asks":[{"price":"61854.70","quantity":"0.611"},{"price":"61855.20","quantity":"0.008"},{"price":"61856.50","quantity":"0.184"},{"price":"61856.90","quantity":"0.002"},{"price":"61857.90","quantity":"0.968"},{"price":"61859.90","quantity":"0.553"},{"price":"61860.10","quantity":"3.038"},{"price":"61886.70","quantity":"0.105"},{"price":"61887.20","quantity":"0.002"},{"price":"61893.30","quantity":"0.100"},{"price":"61893.50","quantity":"0.000"},{"price":"62200.00","quantity":"3.569"},{"price":"62472.70","quantity":"1.678"}],"raw":{"e":"depthUpdate","E":1783517073332,"T":1783517073331,"s":"BTCUSDT","ps":"BTCUSDT","U":10999771160408,"u":10999771168540,"pu":10999771160339,"b":[["1000.00","207.692"],["11354.10","2.720"],["11454.10","1.050"],["11554.10","0.714"],["11754.10","0.416"],["55668.60","0.002"],["58759.60","0.002"],["58761.30","0.020"],["59379.90","0.003"],["61033.10","3.108"],["61118.00","1.013"],["61169.90","0.001"],["61235.60","0.328"],["61829.60","0.039"],["61842.80","0.889"],["61842.90","0.000"],["61843.00","0.001"],["61845.10","0.317"],["61845.30","0.005"]],"a":[["61854.70","0.611"],["61855.20","0.008"],["61856.50","0.184"],["61856.90","0.002"],["61857.90","0.968"],["61859.90","0.553"],["61860.10","3.038"],["61886.70","0.105"],["61887.20","0.002"],["61893.30","0.100"],["61893.50","0.000"],["62200.00","3.569"],["62472.70","1.678"]],"st":1}}
{"schema_version":"1.3.0","event_id":"62435663-dd68-444a-bee5-00227befcb6e","event_type":"raw.depth_update","source":"binance_market_data_recorder","venue":"binance_usdm","market_type":"perpetual_futures","symbol":"BTCUSDT","event_time_ms":1783517073434,"received_time_ms":1783517073429,"trace_id":"271db8f1-89d6-4eb5-904a-b2057a09989a","first_update_id":10999771168613,"final_update_id":10999771175511,"previous_final_update_id":10999771168540,"bids":[{"price":"11354.10","quantity":"2.576"},{"price":"11454.10","quantity":"1.139"},{"price":"11554.10","quantity":"0.561"},{"price":"11754.10","quantity":"0.624"},{"price":"49483.00","quantity":"0.000"},{"price":"55668.60","quantity":"0.002"},{"price":"59379.90","quantity":"0.000"},{"price":"61050.00","quantity":"3.464"},{"price":"61235.60","quantity":"0.328"},{"price":"61276.10","quantity":"0.262"},{"price":"61808.30","quantity":"1.115"},{"price":"61812.60","quantity":"0.134"},{"price":"61821.90","quantity":"0.680"},{"price":"61823.10","quantity":"0.105"},{"price":"61835.20","quantity":"0.568"},{"price":"61836.70","quantity":"0.003"},{"price":"61842.00","quantity":"0.392"},{"price":"61842.80","quantity":"0.566"},{"price":"61845.00","quantity":"0.009"},{"price":"61845.70","quantity":"0.000"},{"price":"61848.00","quantity":"0.726"},{"price":"61848.10","quantity":"0.000"},{"price":"61850.40","quantity":"0.000"},{"price":"61854.10","quantity":"16.726"}],"asks":[{"price":"61854.20","quantity":"3.674"},{"price":"61856.20","quantity":"0.325"},{"price":"61856.50","quantity":"0.058"},{"price":"61859.70","quantity":"0.168"},{"price":"61859.80","quantity":"1.124"},{"price":"61860.50","quantity":"1.601"},{"price":"61863.80","quantity":"0.003"},{"price":"61866.10","quantity":"0.566"},{"price":"61869.40","quantity":"0.007"},{"price":"61870.10","quantity":"0.261"},{"price":"61893.50","quantity":"0.580"},{"price":"61908.70","quantity":"0.117"},{"price":"61909.00","quantity":"0.032"},{"price":"61909.40","quantity":"0.266"},{"price":"61909.50","quantity":"2.795"},{"price":"61909.90","quantity":"0.120"},{"price":"62331.80","quantity":"0.000"},{"price":"62460.40","quantity":"1.038"},{"price":"62472.70","quantity":"1.678"},{"price":"62654.50","quantity":"0.957"},{"price":"89523.20","quantity":"0.918"}],"raw":{"e":"depthUpdate","E":1783517073434,"T":1783517073433,"s":"BTCUSDT","ps":"BTCUSDT","U":10999771168613,"u":10999771175511,"pu":10999771168540,"b":[["11354.10","2.576"],["11454.10","1.139"],["11554.10","0.561"],["11754.10","0.624"],["49483.00","0.000"],["55668.60","0.002"],["59379.90","0.000"],["61050.00","3.464"],["61235.60","0.328"],["61276.10","0.262"],["61808.30","1.115"],["61812.60","0.134"],["61821.90","0.680"],["61823.10","0.105"],["61835.20","0.568"],["61836.70","0.003"],["61842.00","0.392"],["61842.80","0.566"],["61845.00","0.009"],["61845.70","0.000"],["61848.00","0.726"],["61848.10","0.000"],["61850.40","0.000"],["61854.10","16.726"]],"a":[["61854.20","3.674"],["61856.20","0.325"],["61856.50","0.058"],["61859.70","0.168"],["61859.80","1.124"],["61860.50","1.601"],["61863.80","0.003"],["61866.10","0.566"],["61869.40","0.007"],["61870.10","0.261"],["61893.50","0.580"],["61908.70","0.117"],["61909.00","0.032"],["61909.40","0.266"],["61909.50","2.795"],["61909.90","0.120"],["62331.80","0.000"],["62460.40","1.038"],["62472.70","1.678"],["62654.50","0.957"],["89523.20","0.918"]],"st":1}}
{"schema_version":"1.3.0","event_id":"1a6b7b79-1446-4da4-9a2e-e9b413f225aa","event_type":"raw.depth_update","source":"binance_market_data_recorder","venue":"binance_usdm","market_type":"perpetual_futures","symbol":"BTCUSDT","event_time_ms":1783517073536,"received_time_ms":1783517073531,"trace_id":"de6e0347-c51b-4a3d-a613-1c2fecaf1c42","first_update_id":10999771175622,"final_update_id":10999771184581,"previous_final_update_id":10999771175511,"bids":[{"price":"11354.10","quantity":"2.304"},{"price":"11454.10","quantity":"1.275"},{"price":"11554.10","quantity":"0.425"},{"price":"11754.10","quantity":"0.896"},{"price":"55668.60","quantity":"0.002"},{"price":"60922.50","quantity":"7.479"},{"price":"61173.70","quantity":"0.805"},{"price":"61235.60","quantity":"0.330"},{"price":"61544.80","quantity":"0.039"},{"price":"61713.10","quantity":"0.001"},{"price":"61725.40","quantity":"0.222"},{"price":"61750.50","quantity":"0.000"},{"price":"61750.60","quantity":"0.003"},{"price":"61801.40","quantity":"0.036"},{"price":"61805.00","quantity":"6.590"},{"price":"61812.50","quantity":"1.034"},{"price":"61814.50","quantity":"0.007"},{"price":"61824.30","quantity":"0.093"},{"price":"61825.90","quantity":"0.092"},{"price":"61830.00","quantity":"0.229"},{"price":"61852.40","quantity":"0.006"},{"price":"61852.50","quantity":"0.037"},{"price":"61853.70","quantity":"0.082"},{"price":"61854.10","quantity":"16.591"}],"asks":[{"price":"61857.30","quantity":"1.128"},{"price":"61858.10","quantity":"0.093"},{"price":"61859.70","quantity":"0.164"},{"price":"61897.50","quantity":"0.323"},{"price":"61908.20","quantity":"0.665"},{"price":"61908.70","quantity":"0.117"},{"price":"61908.80","quantity":"0.381"},{"price":"62028.80","quantity":"0.001"},{"price":"62028.90","quantity":"0.004"},{"price":"62106.20","quantity":"0.211"},{"price":"62109.70","quantity":"33.929"},{"price":"62472.70","quantity":"1.678"},{"price":"62658.30","quantity":"1.275"},{"price":"62689.30","quantity":"0.477"},{"price":"62732.30","quantity":"1.233"}],"raw":{"e":"depthUpdate","E":1783517073536,"T":1783517073535,"s":"BTCUSDT","ps":"BTCUSDT","U":10999771175622,"u":10999771184581,"pu":10999771175511,"b":[["11354.10","2.304"],["11454.10","1.275"],["11554.10","0.425"],["11754.10","0.896"],["55668.60","0.002"],["60922.50","7.479"],["61173.70","0.805"],["61235.60","0.330"],["61544.80","0.039"],["61713.10","0.001"],["61725.40","0.222"],["61750.50","0.000"],["61750.60","0.003"],["61801.40","0.036"],["61805.00","6.590"],["61812.50","1.034"],["61814.50","0.007"],["61824.30","0.093"],["61825.90","0.092"],["61830.00","0.229"],["61852.40","0.006"],["61852.50","0.037"],["61853.70","0.082"],["61854.10","16.591"]],"a":[["61857.30","1.128"],["61858.10","0.093"],["61859.70","0.164"],["61897.50","0.323"],["61908.20","0.665"],["61908.70","0.117"],["61908.80","0.381"],["62028.80","0.001"],["62028.90","0.004"],["62106.20","0.211"],["62109.70","33.929"],["62472.70","1.678"],["62658.30","1.275"],["62689.30","0.477"],["62732.30","1.233"]],"st":1}}
{"schema_version":"1.3.0","event_id":"240dbd34-6a02-40ad-bf50-d6225d3071a0","event_type":"raw.depth_update","source":"binance_market_data_recorder","venue":"binance_usdm","market_type":"perpetual_futures","symbol":"BTCUSDT","event_time_ms":1783517073638,"received_time_ms":1783517073782,"trace_id":"902957c0-06af-4242-a5a2-ff65e02a302a","first_update_id":10999771184639,"final_update_id":10999771198025,"previous_final_update_id":10999771184581,"bids":[{"price":"1000.00","quantity":"207.692"},{"price":"11354.10","quantity":"2.032"},{"price":"11454.10","quantity":"1.428"},{"price":"11554.10","quantity":"0.272"},{"price":"11754.10","quantity":"1.168"},{"price":"49483.00","quantity":"0.000"},{"price":"55668.60","quantity":"0.002"},{"price":"58761.10","quantity":"0.003"},{"price":"59379.90","quantity":"0.003"},{"price":"60349.40","quantity":"0.000"},{"price":"60616.70","quantity":"0.017"},{"price":"60617.10","quantity":"0.012"},{"price":"61077.10","quantity":"5.197"},{"price":"61100.00","quantity":"123.915"},{"price":"61235.60","quantity":"0.328"},{"price":"61700.30","quantity":"0.000"},{"price":"61702.20","quantity":"0.710"},{"price":"61723.70","quantity":"0.281"},{"price":"61797.70","quantity":"0.843"},{"price":"61800.50","quantity":"0.210"},{"price":"61804.10","quantity":"2.138"},{"price":"61806.90","quantity":"2.221"},{"price":"61812.50","quantity":"0.933"},{"price":"61812.60","quantity":"0.134"},{"price":"61813.10","quantity":"0.110"},{"price":"61813.40","quantity":"0.163"},{"price":"61821.90","quantity":"0.518"},{"price":"61822.00","quantity":"0.106"},{"price":"61823.40","quantity":"0.015"},{"price":"61828.90","quantity":"1.131"},{"price":"61829.60","quantity":"0.099"},{"price":"61836.10","quantity":"0.053"},{"price":"61837.60","quantity":"1.225"},{"price":"61838.00","quantity":"1.182"},{"price":"61838.60","quantity":"0.128"},{"price":"61840.70","quantity":"1.092"},{"price":"61841.80","quantity":"0.571"},{"price":"61842.10","quantity":"1.123"},{"price":"61842.80","quantity":"0.000"},{"price":"61845.00","quantity":"1.101"},{"price":"61851.20","quantity":"0.123"},{"price":"61854.10","quantity":"16.882"}],"asks":[{"price":"61854.20","quantity":"2.219"},{"price":"61854.30","quantity":"0.026"},{"price":"61854.50","quantity":"0.000"},{"price":"61854.60","quantity":"0.002"},{"price":"61854.70","quantity":"0.242"},{"price":"61854.80","quantity":"0.000"},{"price":"61854.90","quantity":"0.016"},{"price":"61856.10","quantity":"0.000"},{"price":"61856.20","quantity":"0.001"},{"price":"61856.40","quantity":"0.078"},{"price":"61856.50","quantity":"0.009"},{"price":"61857.00","quantity":"0.713"},{"price":"61857.30","quantity":"1.000"},{"price":"61858.20","quantity":"0.131"},{"price":"61859.60","quantity":"0.142"},{"price":"61859.70","quantity":"0.164"},{"price":"61859.90","quantity":"0.000"},{"price":"61860.10","quantity":"1.749"},{"price":"61860.40","quantity":"0.322"},{"price":"61860.50","quantity":"1.479"},{"price":"61861.10","quantity":"0.776"},{"price":"61861.20","quantity":"0.000"},{"price":"61861.40","quantity":"0.379"},{"price":"61863.50","quantity":"0.130"},{"price":"61865.10","quantity":"0.589"},{"price":"61869.70","quantity":"0.211"},{"price":"61872.80","quantity":"0.128"},{"price":"61898.50","quantity":"0.058"},{"price":"61904.90","quantity":"2.487"},{"price":"61908.60","quantity":"0.001"},{"price":"61908.70","quantity":"0.117"},{"price":"61909.00","quantity":"0.133"},{"price":"61985.30","quantity":"2.830"},{"price":"62006.80","quantity":"1.036"},{"price":"62008.30","quantity":"0.073"},{"price":"62472.70","quantity":"1.680"},{"price":"63091.20","quantity":"0.035"},{"price":"89523.20","quantity":"0.924"}],"raw":{"e":"depthUpdate","E":1783517073638,"T":1783517073637,"s":"BTCUSDT","ps":"BTCUSDT","U":10999771184639,"u":10999771198025,"pu":10999771184581,"b":[["1000.00","207.692"],["11354.10","2.032"],["11454.10","1.428"],["11554.10","0.272"],["11754.10","1.168"],["49483.00","0.000"],["55668.60","0.002"],["58761.10","0.003"],["59379.90","0.003"],["60349.40","0.000"],["60616.70","0.017"],["60617.10","0.012"],["61077.10","5.197"],["61100.00","123.915"],["61235.60","0.328"],["61700.30","0.000"],["61702.20","0.710"],["61723.70","0.281"],["61797.70","0.843"],["61800.50","0.210"],["61804.10","2.138"],["61806.90","2.221"],["61812.50","0.933"],["61812.60","0.134"],["61813.10","0.110"],["61813.40","0.163"],["61821.90","0.518"],["61822.00","0.106"],["61823.40","0.015"],["61828.90","1.131"],["61829.60","0.099"],["61836.10","0.053"],["61837.60","1.225"],["61838.00","1.182"],["61838.60","0.128"],["61840.70","1.092"],["61841.80","0.571"],["61842.10","1.123"],["61842.80","0.000"],["61845.00","1.101"],["61851.20","0.123"],["61854.10","16.882"]],"a":[["61854.20","2.219"],["61854.30","0.026"],["61854.50","0.000"],["61854.60","0.002"],["61854.70","0.242"],["61854.80","0.000"],["61854.90","0.016"],["61856.10","0.000"],["61856.20","0.001"],["61856.40","0.078"],["61856.50","0.009"],["61857.00","0.713"],["61857.30","1.000"],["61858.20","0.131"],["61859.60","0.142"],["61859.70","0.164"],["61859.90","0.000"],["61860.10","1.749"],["61860.40","0.322"],["61860.50","1.479"],["61861.10","0.776"],["61861.20","0.000"],["61861.40","0.379"],["61863.50","0.130"],["61865.10","0.589"],["61869.70","0.211"],["61872.80","0.128"],["61898.50","0.058"],["61904.90","2.487"],["61908.60","0.001"],["61908.70","0.117"],["61909.00","0.133"],["61985.30","2.830"],["62006.80","1.036"],["62008.30","0.073"],["62472.70","1.680"],["63091.20","0.035"],["89523.20","0.924"]],"st":1}}
{"schema_version":"1.3.0","event_id":"e32efe13-a897-4e47-96b7-b40bd14a50b9","event_type":"raw.depth_update","source":"binance_market_data_recorder","venue":"binance_usdm","market_type":"perpetual_futures","symbol":"BTCUSDT","event_time_ms":1783517073740,"received_time_ms":1783517073826,"trace_id":"c474e532-e0af-4a78-82b0-47dbcace3ac0","first_update_id":10999771198140,"final_update_id":10999771210198,"previous_final_update_id":10999771198025,"bids":[{"price":"11354.10","quantity":"1.760"},{"price":"11454.10","quantity":"1.564"},{"price":"11554.10","quantity":"0.136"},{"price":"11754.10","quantity":"1.440"},{"price":"49483.30","quantity":"0.000"},{"price":"55668.60","quantity":"0.002"},{"price":"59379.90","quantity":"0.000"},{"price":"60926.30","quantity":"0.369"},{"price":"61080.70","quantity":"0.015"},{"price":"61235.60","quantity":"0.328"},{"price":"61784.00","quantity":"1.580"},{"price":"61794.20","quantity":"0.232"},{"price":"61800.50","quantity":"0.000"},{"price":"61808.00","quantity":"4.420"},{"price":"61812.60","quantity":"0.033"},{"price":"61813.10","quantity":"0.009"},{"price":"61813.40","quantity":"0.062"},{"price":"61813.80","quantity":"0.014"},{"price":"61814.20","quantity":"0.176"},{"price":"61814.30","quantity":"0.230"},{"price":"61815.10","quantity":"0.105"},{"price":"61819.70","quantity":"0.025"},{"price":"61821.00","quantity":"0.745"},{"price":"61821.20","quantity":"0.101"},{"price":"61821.90","quantity":"0.413"},{"price":"61822.00","quantity":"0.001"},{"price":"61822.20","quantity":"1.013"},{"price":"61823.10","quantity":"0.000"},{"price":"61823.30","quantity":"2.126"},{"price":"61823.40","quantity":"0.556"},{"price":"61829.20","quantity":"0.422"},{"price":"61836.60","quantity":"1.307"},{"price":"61841.80","quantity":"0.005"},{"price":"61842.00","quantity":"0.069"},{"price":"61843.90","quantity":"0.004"},{"price":"61845.30","quantity":"0.894"},{"price":"61845.70","quantity":"1.122"},{"price":"61848.00","quantity":"1.069"},{"price":"61854.10","quantity":"16.882"}],"asks":[{"price":"61854.20","quantity":"1.225"},{"price":"61854.30","quantity":"0.025"},{"price":"61854.70","quantity":"0.000"},{"price":"61855.40","quantity":"0.243"},{"price":"61855.80","quantity":"0.007"},{"price":"61856.40","quantity":"0.029"},{"price":"61856.50","quantity":"0.009"},{"price":"61857.20","quantity":"0.219"},{"price":"61857.90","quantity":"0.000"},{"price":"61858.10","quantity":"0.089"},{"price":"61858.30","quantity":"0.013"},{"price":"61858.50","quantity":"0.000"},{"price":"61859.00","quantity":"0.114"},{"price":"61859.60","quantity":"1.632"},{"price":"61859.70","quantity":"0.739"},{"price":"61860.00","quantity":"1.058"},{"price":"61860.10","quantity":"0.133"},{"price":"61861.00","quantity":"0.708"},{"price":"61863.50","quantity":"0.002"},{"price":"61863.70","quantity":"1.149"},{"price":"61865.20","quantity":"0.020"},{"price":"61865.60","quantity":"0.004"},{"price":"61865.90","quantity":"0.586"},{"price":"61869.70","quantity":"0.211"},{"price":"61887.80","quantity":"0.391"},{"price":"61888.20","quantity":"0.001"},{"price":"61888.60","quantity":"0.117"},{"price":"61888.80","quantity":"0.127"},{"price":"61898.20","quantity":"0.001"},{"price":"61953.80","quantity":"0.426"},{"price":"62349.00","quantity":"0.470"},{"price":"62472.70","quantity":"1.678"},{"price":"62689.20","quantity":"1.197"}],"raw":{"e":"depthUpdate","E":1783517073740,"T":1783517073737,"s":"BTCUSDT","ps":"BTCUSDT","U":10999771198140,"u":10999771210198,"pu":10999771198025,"b":[["11354.10","1.760"],["11454.10","1.564"],["11554.10","0.136"],["11754.10","1.440"],["49483.30","0.000"],["55668.60","0.002"],["59379.90","0.000"],["60926.30","0.369"],["61080.70","0.015"],["61235.60","0.328"],["61784.00","1.580"],["61794.20","0.232"],["61800.50","0.000"],["61808.00","4.420"],["61812.60","0.033"],["61813.10","0.009"],["61813.40","0.062"],["61813.80","0.014"],["61814.20","0.176"],["61814.30","0.230"],["61815.10","0.105"],["61819.70","0.025"],["61821.00","0.745"],["61821.20","0.101"],["61821.90","0.413"],["61822.00","0.001"],["61822.20","1.013"],["61823.10","0.000"],["61823.30","2.126"],["61823.40","0.556"],["61829.20","0.422"],["61836.60","1.307"],["61841.80","0.005"],["61842.00","0.069"],["61843.90","0.004"],["61845.30","0.894"],["61845.70","1.122"],["61848.00","1.069"],["61854.10","16.882"]],"a":[["61854.20","1.225"],["61854.30","0.025"],["61854.70","0.000"],["61855.40","0.243"],["61855.80","0.007"],["61856.40","0.029"],["61856.50","0.009"],["61857.20","0.219"],["61857.90","0.000"],["61858.10","0.089"],["61858.30","0.013"],["61858.50","0.000"],["61859.00","0.114"],["61859.60","1.632"],["61859.70","0.739"],["61860.00","1.058"],["61860.10","0.133"],["61861.00","0.708"],["61863.50","0.002"],["61863.70","1.149"],["61865.20","0.020"],["61865.60","0.004"],["61865.90","0.586"],["61869.70","0.211"],["61887.80","0.391"],["61888.20","0.001"],["61888.60","0.117"],["61888.80","0.127"],["61898.20","0.001"],["61953.80","0.426"],["62349.00","0.470"],["62472.70","1.678"],["62689.20","1.197"]],"st":1}}
{"schema_version":"1.3.0","event_id":"825c5d2c-4de5-4414-b48c-d244653015a0","event_type":"raw.depth_update","source":"binance_market_data_recorder","venue":"binance_usdm","market_type":"perpetual_futures","symbol":"BTCUSDT","event_time_ms":1783517073842,"received_time_ms":1783517073882,"trace_id":"e9839f5e-b1ca-47b9-837b-3511fc9c0e36","first_update_id":10999771210505,"final_update_id":10999771226504,"previous_final_update_id":10999771210198,"bids":[{"price":"11354.10","quantity":"1.505"},{"price":"11454.10","quantity":"1.683"},{"price":"11554.10","quantity":"0.000"},{"price":"11754.10","quantity":"1.712"},{"price":"49483.00","quantity":"0.000"},{"price":"55668.60","quantity":"0.002"},{"price":"59379.90","quantity":"0.003"},{"price":"61028.60","quantity":"0.007"},{"price":"61133.30","quantity":"0.015"},{"price":"61235.00","quantity":"0.834"},{"price":"61235.60","quantity":"0.328"},{"price":"61300.10","quantity":"0.000"},{"price":"61300.50","quantity":"0.044"},{"price":"61453.30","quantity":"0.013"},{"price":"61453.70","quantity":"0.008"},{"price":"61523.80","quantity":"0.609"},{"price":"61544.80","quantity":"0.039"},{"price":"61607.00","quantity":"0.071"},{"price":"61607.40","quantity":"0.006"},{"price":"61697.00","quantity":"0.305"},{"price":"61761.00","quantity":"0.033"},{"price":"61761.40","quantity":"0.832"},{"price":"61772.00","quantity":"0.016"},{"price":"61777.90","quantity":"0.146"},{"price":"61784.20","quantity":"33.150"},{"price":"61786.30","quantity":"0.002"},{"price":"61789.00","quantity":"1.484"},{"price":"61800.90","quantity":"0.030"},{"price":"61815.10","quantity":"0.105"},{"price":"61815.30","quantity":"1.173"},{"price":"61815.40","quantity":"0.105"},{"price":"61815.70","quantity":"0.103"},{"price":"61823.30","quantity":"2.021"},{"price":"61823.40","quantity":"0.556"},{"price":"61823.50","quantity":"0.197"},{"price":"61823.80","quantity":"0.195"},{"price":"61824.10","quantity":"0.107"},{"price":"61826.60","quantity":"0.113"},{"price":"61827.10","quantity":"0.588"},{"price":"61827.90","quantity":"0.743"},{"price":"61828.30","quantity":"0.001"},{"price":"61828.70","quantity":"0.129"},{"price":"61830.40","quantity":"0.050"},{"price":"61830.50","quantity":"0.000"},{"price":"61831.80","quantity":"0.010"},{"price":"61835.20","quantity":"0.002"},{"price":"61836.70","quantity":"0.569"},{"price":"61837.60","quantity":"1.225"},{"price":"61841.80","quantity":"0.085"},{"price":"61842.20","quantity":"0.025"},{"price":"61842.30","quantity":"0.004"},{"price":"61843.10","quantity":"0.018"},{"price":"61843.80","quantity":"0.323"},{"price":"61845.30","quantity":"0.005"},{"price":"61845.40","quantity":"0.323"},{"price":"61845.80","quantity":"0.566"},{"price":"61847.60","quantity":"0.008"},{"price":"61850.40","quantity":"0.122"},{"price":"61850.90","quantity":"0.003"},{"price":"61851.20","quantity":"0.001"},{"price":"61852.10","quantity":"0.002"},{"price":"61852.40","quantity":"0.000"},{"price":"61852.50","quantity":"0.001"},{"price":"61853.70","quantity":"0.088"},{"price":"61853.80","quantity":"0.038"},{"price":"61853.90","quantity":"0.244"},{"price":"61854.10","quantity":"17.520"}],"asks":[{"price":"61854.20","quantity":"2.521"},{"price":"61854.30","quantity":"0.025"},{"price":"61854.80","quantity":"0.369"},{"price":"61855.00","quantity":"1.948"},{"price":"61855.10","quantity":"0.243"},{"price":"61855.30","quantity":"0.025"},{"price":"61855.40","quantity":"0.001"},{"price":"61856.20","quantity":"0.050"},{"price":"61856.40","quantity":"0.029"},{"price":"61857.20","quantity":"0.218"},{"price":"61857.30","quantity":"0.000"},{"price":"61857.50","quantity":"1.001"},{"price":"61858.40","quantity":"0.164"},{"price":"61858.50","quantity":"0.000"},{"price":"61858.70","quantity":"0.066"},{"price":"61858.80","quantity":"2.505"},{"price":"61858.90","quantity":"0.919"},{"price":"61859.50","quantity":"0.124"},{"price":"61859.60","quantity":"0.016"},{"price":"61859.70","quantity":"0.164"},{"price":"61860.20","quantity":"0.067"},{"price":"61860.40","quantity":"0.450"},{"price":"61861.50","quantity":"2.301"},{"price":"61863.50","quantity":"0.130"},{"price":"61864.00","quantity":"2.155"},{"price":"61864.70","quantity":"0.001"},{"price":"61865.00","quantity":"0.007"},{"price":"61865.10","quantity":"0.220"},{"price":"61865.80","quantity":"0.566"},{"price":"61866.10","quantity":"0.000"},{"price":"61866.20","quantity":"0.002"},{"price":"61867.10","quantity":"0.905"},{"price":"61868.50","quantity":"0.753"},{"price":"61869.60","quantity":"0.001"},{"price":"61870.10","quantity":"0.140"},{"price":"61870.30","quantity":"0.121"},{"price":"61872.80","quantity":"0.128"},{"price":"61886.70","quantity":"0.000"},{"price":"61887.20","quantity":"0.107"},{"price":"61887.50","quantity":"0.005"},{"price":"61887.80","quantity":"0.286"},{"price":"61887.90","quantity":"0.379"},{"price":"61888.00","quantity":"0.494"},{"price":"61888.60","quantity":"0.012"},{"price":"61888.80","quantity":"0.125"},{"price":"61890.10","quantity":"0.022"},{"price":"61897.10","quantity":"0.154"},{"price":"61897.50","quantity":"0.323"},{"price":"61908.70","quantity":"0.129"},{"price":"61909.30","quantity":"0.116"},{"price":"61918.00","quantity":"0.695"},{"price":"61946.50","quantity":"0.003"},{"price":"61946.90","quantity":"0.002"},{"price":"61950.50","quantity":"0.264"},{"price":"61953.80","quantity":"0.162"},{"price":"61990.30","quantity":"0.310"},{"price":"62101.40","quantity":"0.002"},{"price":"62101.80","quantity":"0.004"},{"price":"62157.30","quantity":"0.069"},{"price":"62256.60","quantity":"0.000"},{"price":"62257.00","quantity":"0.513"},{"price":"62412.30","quantity":"0.000"},{"price":"62412.70","quantity":"0.016"},{"price":"62435.60","quantity":"0.117"},{"price":"62472.70","quantity":"1.678"},{"price":"89523.20","quantity":"0.930"}],"raw":{"e":"depthUpdate","E":1783517073842,"T":1783517073841,"s":"BTCUSDT","ps":"BTCUSDT","U":10999771210505,"u":10999771226504,"pu":10999771210198,"b":[["11354.10","1.505"],["11454.10","1.683"],["11554.10","0.000"],["11754.10","1.712"],["49483.00","0.000"],["55668.60","0.002"],["59379.90","0.003"],["61028.60","0.007"],["61133.30","0.015"],["61235.00","0.834"],["61235.60","0.328"],["61300.10","0.000"],["61300.50","0.044"],["61453.30","0.013"],["61453.70","0.008"],["61523.80","0.609"],["61544.80","0.039"],["61607.00","0.071"],["61607.40","0.006"],["61697.00","0.305"],["61761.00","0.033"],["61761.40","0.832"],["61772.00","0.016"],["61777.90","0.146"],["61784.20","33.150"],["61786.30","0.002"],["61789.00","1.484"],["61800.90","0.030"],["61815.10","0.105"],["61815.30","1.173"],["61815.40","0.105"],["61815.70","0.103"],["61823.30","2.021"],["61823.40","0.556"],["61823.50","0.197"],["61823.80","0.195"],["61824.10","0.107"],["61826.60","0.113"],["61827.10","0.588"],["61827.90","0.743"],["61828.30","0.001"],["61828.70","0.129"],["61830.40","0.050"],["61830.50","0.000"],["61831.80","0.010"],["61835.20","0.002"],["61836.70","0.569"],["61837.60","1.225"],["61841.80","0.085"],["61842.20","0.025"],["61842.30","0.004"],["61843.10","0.018"],["61843.80","0.323"],["61845.30","0.005"],["61845.40","0.323"],["61845.80","0.566"],["61847.60","0.008"],["61850.40","0.122"],["61850.90","0.003"],["61851.20","0.001"],["61852.10","0.002"],["61852.40","0.000"],["61852.50","0.001"],["61853.70","0.088"],["61853.80","0.038"],["61853.90","0.244"],["61854.10","17.520"]],"a":[["61854.20","2.521"],["61854.30","0.025"],["61854.80","0.369"],["61855.00","1.948"],["61855.10","0.243"],["61855.30","0.025"],["61855.40","0.001"],["61856.20","0.050"],["61856.40","0.029"],["61857.20","0.218"],["61857.30","0.000"],["61857.50","1.001"],["61858.40","0.164"],["61858.50","0.000"],["61858.70","0.066"],["61858.80","2.505"],["61858.90","0.919"],["61859.50","0.124"],["61859.60","0.016"],["61859.70","0.164"],["61860.20","0.067"],["61860.40","0.450"],["61861.50","2.301"],["61863.50","0.130"],["61864.00","2.155"],["61864.70","0.001"],["61865.00","0.007"],["61865.10","0.220"],["61865.80","0.566"],["61866.10","0.000"],["61866.20","0.002"],["61867.10","0.905"],["61868.50","0.753"],["61869.60","0.001"],["61870.10","0.140"],["61870.30","0.121"],["61872.80","0.128"],["61886.70","0.000"],["61887.20","0.107"],["61887.50","0.005"],["61887.80","0.286"],["61887.90","0.379"],["61888.00","0.494"],["61888.60","0.012"],["61888.80","0.125"],["61890.10","0.022"],["61897.10","0.154"],["61897.50","0.323"],["61908.70","0.129"],["61909.30","0.116"],["61918.00","0.695"],["61946.50","0.003"],["61946.90","0.002"],["61950.50","0.264"],["61953.80","0.162"],["61990.30","0.310"],["62101.40","0.002"],["62101.80","0.004"],["62157.30","0.069"],["62256.60","0.000"],["62257.00","0.513"],["62412.30","0.000"],["62412.70","0.016"],["62435.60","0.117"],["62472.70","1.678"],["89523.20","0.930"]],"st":1}}
{"schema_version":"1.3.0","event_id":"bac30481-b2ca-45a5-a5a8-80d3df7dfabc","event_type":"raw.depth_update","source":"binance_market_data_recorder","venue":"binance_usdm","market_type":"perpetual_futures","symbol":"BTCUSDT","event_time_ms":1783517073944,"received_time_ms":1783517073939,"trace_id":"6e200380-ff5a-47ef-aec3-dc33db79302a","first_update_id":10999771226560,"final_update_id":10999771234366,"previous_final_update_id":10999771226504,"bids":[{"price":"1000.00","quantity":"207.692"},{"price":"11354.10","quantity":"1.369"},{"price":"11454.10","quantity":"1.547"},{"price":"11754.10","quantity":"1.984"},{"price":"55668.60","quantity":"0.002"},{"price":"58759.70","quantity":"0.006"},{"price":"59379.90","quantity":"0.000"},{"price":"60617.10","quantity":"0.015"},{"price":"61100.60","quantity":"0.490"},{"price":"61121.30","quantity":"0.000"},{"price":"61235.60","quantity":"0.330"},{"price":"61260.70","quantity":"0.754"},{"price":"61769.50","quantity":"0.092"},{"price":"61771.60","quantity":"33.149"},{"price":"61784.20","quantity":"0.002"},{"price":"61786.30","quantity":"0.002"},{"price":"61825.90","quantity":"0.674"},{"price":"61827.10","quantity":"0.006"},{"price":"61828.10","quantity":"0.088"},{"price":"61830.40","quantity":"0.130"},{"price":"61830.50","quantity":"0.008"},{"price":"61831.30","quantity":"3.105"},{"price":"61831.80","quantity":"0.002"},{"price":"61832.10","quantity":"0.065"},{"price":"61835.20","quantity":"0.568"},{"price":"61836.70","quantity":"0.003"},{"price":"61840.50","quantity":"2.140"},{"price":"61841.00","quantity":"0.003"},{"price":"61841.80","quantity":"0.005"},{"price":"61854.10","quantity":"17.517"}],"asks":[{"price":"61854.20","quantity":"2.199"},{"price":"61854.30","quantity":"0.026"},{"price":"61854.50","quantity":"0.016"},{"price":"61856.10","quantity":"0.000"},{"price":"61856.20","quantity":"0.001"},{"price":"61856.50","quantity":"0.058"},{"price":"61858.60","quantity":"0.878"},{"price":"61858.70","quantity":"0.389"},{"price":"61858.80","quantity":"1.616"},{"price":"61858.90","quantity":"0.053"},{"price":"61859.40","quantity":"0.006"},{"price":"61859.50","quantity":"0.019"},{"price":"61859.70","quantity":"0.730"},{"price":"61859.90","quantity":"0.180"},{"price":"61860.20","quantity":"0.068"},{"price":"61860.40","quantity":"0.450"},{"price":"61863.60","quantity":"0.170"},{"price":"61864.60","quantity":"0.567"},{"price":"61864.70","quantity":"0.001"},{"price":"61865.20","quantity":"0.016"},{"price":"61865.80","quantity":"0.000"},{"price":"61865.90","quantity":"0.406"},{"price":"61866.20","quantity":"0.584"},{"price":"61867.10","quantity":"0.323"},{"price":"61868.30","quantity":"0.009"},{"price":"61869.20","quantity":"0.164"},{"price":"61869.70","quantity":"0.083"},{"price":"61870.30","quantity":"0.000"},{"price":"61871.60","quantity":"0.005"},{"price":"61896.50","quantity":"0.003"},{"price":"61897.10","quantity":"0.154"},{"price":"62472.70","quantity":"1.678"},{"price":"62606.20","quantity":"6.458"}],"raw":{"e":"depthUpdate","E":1783517073944,"T":1783517073943,"s":"BTCUSDT","ps":"BTCUSDT","U":10999771226560,"u":10999771234366,"pu":10999771226504,"b":[["1000.00","207.692"],["11354.10","1.369"],["11454.10","1.547"],["11754.10","1.984"],["55668.60","0.002"],["58759.70","0.006"],["59379.90","0.000"],["60617.10","0.015"],["61100.60","0.490"],["61121.30","0.000"],["61235.60","0.330"],["61260.70","0.754"],["61769.50","0.092"],["61771.60","33.149"],["61784.20","0.002"],["61786.30","0.002"],["61825.90","0.674"],["61827.10","0.006"],["61828.10","0.088"],["61830.40","0.130"],["61830.50","0.008"],["61831.30","3.105"],["61831.80","0.002"],["61832.10","0.065"],["61835.20","0.568"],["61836.70","0.003"],["61840.50","2.140"],["61841.00","0.003"],["61841.80","0.005"],["61854.10","17.517"]],"a":[["61854.20","2.199"],["61854.30","0.026"],["61854.50","0.016"],["61856.10","0.000"],["61856.20","0.001"],["61856.50","0.058"],["61858.60","0.878"],["61858.70","0.389"],["61858.80","1.616"],["61858.90","0.053"],["61859.40","0.006"],["61859.50","0.019"],["61859.70","0.730"],["61859.90","0.180"],["61860.20","0.068"],["61860.40","0.450"],["61863.60","0.170"],["61864.60","0.567"],["61864.70","0.001"],["61865.20","0.016"],["61865.80","0.000"],["61865.90","0.406"],["61866.20","0.584"],["61867.10","0.323"],["61868.30","0.009"],["61869.20","0.164"],["61869.70","0.083"],["61870.30","0.000"],["61871.60","0.005"],["61896.50","0.003"],["61897.10","0.154"],["62472.70","1.678"],["62606.20","6.458"]],"st":1}}
{"schema_version":"1.3.0","event_id":"ea1e72fb-ec1d-445f-a325-5e3693059570","event_type":"raw.depth_update","source":"binance_market_data_recorder","venue":"binance_usdm","market_type":"perpetual_futures","symbol":"BTCUSDT","event_time_ms":1783517074046,"received_time_ms":1783517074041,"trace_id":"9086f21e-07d7-4e4c-9eb6-cb2c9003788c","first_update_id":10999771234404,"final_update_id":10999771255080,"previous_final_update_id":10999771234366,"bids":[{"price":"11354.10","quantity":"1.250"},{"price":"11454.10","quantity":"1.394"},{"price":"11754.10","quantity":"2.256"},{"price":"55668.60","quantity":"0.002"},{"price":"60616.70","quantity":"0.011"},{"price":"61041.60","quantity":"0.818"},{"price":"61235.60","quantity":"0.328"},{"price":"61266.50","quantity":"0.734"},{"price":"61314.60","quantity":"0.000"},{"price":"61487.10","quantity":"0.000"},{"price":"61771.60","quantity":"0.001"},{"price":"61782.10","quantity":"0.122"},{"price":"61784.20","quantity":"33.150"},{"price":"61794.20","quantity":"0.022"},{"price":"61795.30","quantity":"4.905"},{"price":"61801.50","quantity":"0.021"},{"price":"61815.10","quantity":"0.004"},{"price":"61815.40","quantity":"0.105"},{"price":"61815.50","quantity":"0.104"},{"price":"61822.30","quantity":"0.002"},{"price":"61823.40","quantity":"0.556"},{"price":"61823.50","quantity":"0.197"},{"price":"61823.80","quantity":"0.195"},{"price":"61823.90","quantity":"0.000"},{"price":"61824.00","quantity":"0.326"},{"price":"61824.10","quantity":"0.107"},{"price":"61824.60","quantity":"0.170"},{"price":"61828.10","quantity":"0.088"},{"price":"61828.90","quantity":"1.011"},{"price":"61829.20","quantity":"0.542"},{"price":"61830.40","quantity":"0.050"},{"price":"61831.30","quantity":"2.137"},{"price":"61831.60","quantity":"0.016"},{"price":"61832.90","quantity":"0.969"},{"price":"61833.80","quantity":"0.000"},{"price":"61834.30","quantity":"0.669"},{"price":"61835.20","quantity":"0.002"},{"price":"61835.90","quantity":"1.054"},{"price":"61836.00","quantity":"0.064"},{"price":"61836.10","quantity":"0.051"},{"price":"61836.60","quantity":"1.227"},{"price":"61836.70","quantity":"0.569"},{"price":"61837.60","quantity":"1.225"},{"price":"61838.60","quantity":"0.000"},{"price":"61839.20","quantity":"0.081"},{"price":"61841.30","quantity":"0.140"},{"price":"61841.70","quantity":"0.518"},{"price":"61841.80","quantity":"0.005"},{"price":"61842.20","quantity":"0.001"},{"price":"61843.00","quantity":"0.006"},{"price":"61843.10","quantity":"0.018"},{"price":"61843.60","quantity":"0.060"},{"price":"61845.40","quantity":"0.000"},{"price":"61845.80","quantity":"0.002"},{"price":"61845.90","quantity":"1.136"},{"price":"61846.30","quantity":"0.081"},{"price":"61848.10","quantity":"0.218"},{"price":"61852.10","quantity":"0.002"},{"price":"61853.90","quantity":"0.244"},{"price":"61854.10","quantity":"17.547"}],"asks":[{"price":"61854.20","quantity":"1.796"},{"price":"61854.30","quantity":"0.026"},{"price":"61854.80","quantity":"0.000"},{"price":"61855.10","quantity":"0.001"},{"price":"61855.30","quantity":"0.002"},{"price":"61855.40","quantity":"0.024"},{"price":"61856.00","quantity":"0.003"},{"price":"61856.30","quantity":"0.035"},{"price":"61856.50","quantity":"0.009"},{"price":"61857.20","quantity":"0.000"},{"price":"61857.30","quantity":"0.000"},{"price":"61857.40","quantity":"0.005"},{"price":"61857.50","quantity":"0.001"},{"price":"61858.10","quantity":"1.705"},{"price":"61858.30","quantity":"0.013"},{"price":"61858.40","quantity":"0.229"},{"price":"61858.50","quantity":"0.218"},{"price":"61858.60","quantity":"1.001"},{"price":"61858.70","quantity":"0.001"},{"price":"61858.80","quantity":"0.000"},{"price":"61859.50","quantity":"0.019"},{"price":"61859.60","quantity":"0.339"},{"price":"61859.90","quantity":"0.000"},{"price":"61860.00","quantity":"0.052"},{"price":"61860.40","quantity":"0.326"},{"price":"61861.20","quantity":"0.004"},{"price":"61863.40","quantity":"0.399"},{"price":"61863.50","quantity":"0.002"},{"price":"61863.80","quantity":"0.001"},{"price":"61864.10","quantity":"0.000"},{"price":"61864.60","quantity":"0.001"},{"price":"61864.90","quantity":"1.018"},{"price":"61865.30","quantity":"0.461"},{"price":"61865.70","quantity":"0.474"},{"price":"61865.90","quantity":"0.586"},{"price":"61866.50","quantity":"0.570"},{"price":"61866.60","quantity":"3.360"},{"price":"61868.70","quantity":"0.096"},{"price":"61869.20","quantity":"0.043"},{"price":"61870.30","quantity":"0.000"},{"price":"61871.10","quantity":"0.027"},{"price":"61871.80","quantity":"0.122"},{"price":"61872.80","quantity":"0.004"},{"price":"61877.30","quantity":"0.264"},{"price":"61881.60","quantity":"0.173"},{"price":"61887.60","quantity":"0.431"},{"price":"61887.80","quantity":"0.286"},{"price":"61887.90","quantity":"0.381"},{"price":"61888.50","quantity":"0.131"},{"price":"61888.80","quantity":"0.160"},{"price":"61895.40","quantity":"0.166"},{"price":"61896.10","quantity":"0.002"},{"price":"61896.50","quantity":"0.002"},{"price":"61897.50","quantity":"0.451"},{"price":"61926.70","quantity":"0.001"},{"price":"61926.90","quantity":"0.021"},{"price":"62013.20","quantity":"0.002"},{"price":"62016.20","quantity":"0.001"},{"price":"62472.70","quantity":"1.678"},{"price":"62552.10","quantity":"0.846"},{"price":"62561.40","quantity":"0.000"},{"price":"62720.20","quantity":"0.279"},{"price":"63091.20","quantity":"0.041"},{"price":"89523.20","quantity":"0.936"}],"raw":{"e":"depthUpdate","E":1783517074046,"T":1783517074045,"s":"BTCUSDT","ps":"BTCUSDT","U":10999771234404,"u":10999771255080,"pu":10999771234366,"b":[["11354.10","1.250"],["11454.10","1.394"],["11754.10","2.256"],["55668.60","0.002"],["60616.70","0.011"],["61041.60","0.818"],["61235.60","0.328"],["61266.50","0.734"],["61314.60","0.000"],["61487.10","0.000"],["61771.60","0.001"],["61782.10","0.122"],["61784.20","33.150"],["61794.20","0.022"],["61795.30","4.905"],["61801.50","0.021"],["61815.10","0.004"],["61815.40","0.105"],["61815.50","0.104"],["61822.30","0.002"],["61823.40","0.556"],["61823.50","0.197"],["61823.80","0.195"],["61823.90","0.000"],["61824.00","0.326"],["61824.10","0.107"],["61824.60","0.170"],["61828.10","0.088"],["61828.90","1.011"],["61829.20","0.542"],["61830.40","0.050"],["61831.30","2.137"],["61831.60","0.016"],["61832.90","0.969"],["61833.80","0.000"],["61834.30","0.669"],["61835.20","0.002"],["61835.90","1.054"],["61836.00","0.064"],["61836.10","0.051"],["61836.60","1.227"],["61836.70","0.569"],["61837.60","1.225"],["61838.60","0.000"],["61839.20","0.081"],["61841.30","0.140"],["61841.70","0.518"],["61841.80","0.005"],["61842.20","0.001"],["61843.00","0.006"],["61843.10","0.018"],["61843.60","0.060"],["61845.40","0.000"],["61845.80","0.002"],["61845.90","1.136"],["61846.30","0.081"],["61848.10","0.218"],["61852.10","0.002"],["61853.90","0.244"],["61854.10","17.547"]],"a":[["61854.20","1.796"],["61854.30","0.026"],["61854.80","0.000"],["61855.10","0.001"],["61855.30","0.002"],["61855.40","0.024"],["61856.00","0.003"],["61856.30","0.035"],["61856.50","0.009"],["61857.20","0.000"],["61857.30","0.000"],["61857.40","0.005"],["61857.50","0.001"],["61858.10","1.705"],["61858.30","0.013"],["61858.40","0.229"],["61858.50","0.218"],["61858.60","1.001"],["61858.70","0.001"],["61858.80","0.000"],["61859.50","0.019"],["61859.60","0.339"],["61859.90","0.000"],["61860.00","0.052"],["61860.40","0.326"],["61861.20","0.004"],["61863.40","0.399"],["61863.50","0.002"],["61863.80","0.001"],["61864.10","0.000"],["61864.60","0.001"],["61864.90","1.018"],["61865.30","0.461"],["61865.70","0.474"],["61865.90","0.586"],["61866.50","0.570"],["61866.60","3.360"],["61868.70","0.096"],["61869.20","0.043"],["61870.30","0.000"],["61871.10","0.027"],["61871.80","0.122"],["61872.80","0.004"],["61877.30","0.264"],["61881.60","0.173"],["61887.60","0.431"],["61887.80","0.286"],["61887.90","0.381"],["61888.50","0.131"],["61888.80","0.160"],["61895.40","0.166"],["61896.10","0.002"],["61896.50","0.002"],["61897.50","0.451"],["61926.70","0.001"],["61926.90","0.021"],["62013.20","0.002"],["62016.20","0.001"],["62472.70","1.678"],["62552.10","0.846"],["62561.40","0.000"],["62720.20","0.279"],["63091.20","0.041"],["89523.20","0.936"]],"st":1}}
{"schema_version":"1.3.0","event_id":"566e1a8d-b4f2-42ae-9efb-824aa3e6ef12","event_type":"raw.depth_update","source":"binance_market_data_recorder","venue":"binance_usdm","market_type":"perpetual_futures","symbol":"BTCUSDT","event_time_ms":1783517074148,"received_time_ms":1783517074144,"trace_id":"ac75476e-e943-4202-adf4-74396a43b77a","first_update_id":10999771255260,"final_update_id":10999771264079,"previous_final_update_id":10999771255080,"bids":[{"price":"1000.00","quantity":"207.692"},{"price":"11354.10","quantity":"1.114"},{"price":"11454.10","quantity":"1.258"},{"price":"11754.10","quantity":"2.528"},{"price":"55668.60","quantity":"0.002"},{"price":"59379.90","quantity":"0.003"},{"price":"60616.70","quantity":"0.008"},{"price":"61153.00","quantity":"0.267"},{"price":"61235.60","quantity":"0.328"},{"price":"61245.30","quantity":"0.000"},{"price":"61544.80","quantity":"0.039"},{"price":"61784.20","quantity":"0.002"},{"price":"61786.30","quantity":"33.150"},{"price":"61822.50","quantity":"0.061"},{"price":"61824.00","quantity":"1.026"},{"price":"61828.10","quantity":"0.008"},{"price":"61830.40","quantity":"0.130"},{"price":"61832.70","quantity":"0.089"},{"price":"61839.20","quantity":"0.001"},{"price":"61839.50","quantity":"0.124"},{"price":"61840.30","quantity":"0.127"},{"price":"61842.60","quantity":"0.104"},{"price":"61843.00","quantity":"0.001"},{"price":"61843.10","quantity":"0.098"},{"price":"61845.30","quantity":"0.005"},{"price":"61846.30","quantity":"0.001"}],"asks":[{"price":"61854.20","quantity":"1.798"},{"price":"61854.90","quantity":"0.019"},{"price":"61856.60","quantity":"0.477"},{"price":"61857.60","quantity":"1.667"},{"price":"61857.70","quantity":"0.007"},{"price":"61857.80","quantity":"0.001"},{"price":"61857.90","quantity":"0.000"},{"price":"61858.00","quantity":"0.011"},{"price":"61858.10","quantity":"0.089"},{"price":"61859.00","quantity":"0.154"},{"price":"61859.50","quantity":"0.019"},{"price":"61860.40","quantity":"0.322"},{"price":"61863.70","quantity":"1.109"},{"price":"61865.30","quantity":"0.456"},{"price":"61866.60","quantity":"3.356"},{"price":"61866.80","quantity":"1.292"},{"price":"61868.70","quantity":"0.081"},{"price":"61870.40","quantity":"0.032"},{"price":"61872.50","quantity":"0.080"},{"price":"61872.80","quantity":"0.000"},{"price":"61873.20","quantity":"0.109"},{"price":"61881.60","quantity":"0.222"},{"price":"61888.00","quantity":"0.599"},{"price":"61888.50","quantity":"0.082"},{"price":"61888.80","quantity":"0.055"},{"price":"61897.50","quantity":"0.451"},{"price":"62016.20","quantity":"0.000"},{"price":"62472.70","quantity":"1.678"},{"price":"62530.80","quantity":"0.000"},{"price":"62766.10","quantity":"0.000"},{"price":"63091.20","quantity":"0.044"},{"price":"63501.60","quantity":"0.000"},{"price":"64005.20","quantity":"0.001"}],"raw":{"e":"depthUpdate","E":1783517074148,"T":1783517074145,"s":"BTCUSDT","ps":"BTCUSDT","U":10999771255260,"u":10999771264079,"pu":10999771255080,"b":[["1000.00","207.692"],["11354.10","1.114"],["11454.10","1.258"],["11754.10","2.528"],["55668.60","0.002"],["59379.90","0.003"],["60616.70","0.008"],["61153.00","0.267"],["61235.60","0.328"],["61245.30","0.000"],["61544.80","0.039"],["61784.20","0.002"],["61786.30","33.150"],["61822.50","0.061"],["61824.00","1.026"],["61828.10","0.008"],["61830.40","0.130"],["61832.70","0.089"],["61839.20","0.001"],["61839.50","0.124"],["61840.30","0.127"],["61842.60","0.104"],["61843.00","0.001"],["61843.10","0.098"],["61845.30","0.005"],["61846.30","0.001"]],"a":[["61854.20","1.798"],["61854.90","0.019"],["61856.60","0.477"],["61857.60","1.667"],["61857.70","0.007"],["61857.80","0.001"],["61857.90","0.000"],["61858.00","0.011"],["61858.10","0.089"],["61859.00","0.154"],["61859.50","0.019"],["61860.40","0.322"],["61863.70","1.109"],["61865.30","0.456"],["61866.60","3.356"],["61866.80","1.292"],["61868.70","0.081"],["61870.40","0.032"],["61872.50","0.080"],["61872.80","0.000"],["61873.20","0.109"],["61881.60","0.222"],["61888.00","0.599"],["61888.50","0.082"],["61888.80","0.055"],["61897.50","0.451"],["62016.20","0.000"],["62472.70","1.678"],["62530.80","0.000"],["62766.10","0.000"],["63091.20","0.044"],["63501.60","0.000"],["64005.20","0.001"]],"st":1}}
{"schema_version":"1.3.0","event_id":"9947111d-d6fc-4cad-ace8-5e5306d48cb6","event_type":"raw.depth_update","source":"binance_market_data_recorder","venue":"binance_usdm","market_type":"perpetual_futures","symbol":"BTCUSDT","event_time_ms":1783517074250,"received_time_ms":1783517074245,"trace_id":"04e74e51-80cb-4a31-b66c-eb865db05f22","first_update_id":10999771264559,"final_update_id":10999771275006,"previous_final_update_id":10999771264079,"bids":[{"price":"1000.00","quantity":"207.692"},{"price":"11354.10","quantity":"1.027"},{"price":"11454.10","quantity":"1.105"},{"price":"11654.10","quantity":"0.032"},{"price":"11754.10","quantity":"2.736"},{"price":"55668.60","quantity":"0.002"},{"price":"59379.90","quantity":"0.000"},{"price":"61235.60","quantity":"0.328"},{"price":"61272.10","quantity":"0.001"},{"price":"61544.80","quantity":"0.038"},{"price":"61777.90","quantity":"33.294"},{"price":"61786.30","quantity":"0.002"},{"price":"61796.80","quantity":"0.014"},{"price":"61800.00","quantity":"21.541"},{"price":"61823.40","quantity":"0.451"},{"price":"61823.50","quantity":"0.092"},{"price":"61832.70","quantity":"0.009"},{"price":"61839.30","quantity":"0.634"}],"asks":[{"price":"61855.90","quantity":"0.369"},{"price":"61857.50","quantity":"0.001"},{"price":"61857.60","quantity":"0.051"},{"price":"61858.20","quantity":"0.196"},{"price":"61858.30","quantity":"0.013"},{"price":"61858.40","quantity":"0.164"},{"price":"61858.50","quantity":"0.218"},{"price":"61859.50","quantity":"1.635"},{"price":"61860.40","quantity":"0.450"},{"price":"61863.40","quantity":"0.030"},{"price":"61888.00","quantity":"0.599"},{"price":"61888.10","quantity":"0.240"},{"price":"61893.40","quantity":"0.099"},{"price":"61895.40","quantity":"0.096"},{"price":"61896.80","quantity":"0.445"},{"price":"61908.20","quantity":"0.564"},{"price":"61909.80","quantity":"0.000"},{"price":"61909.90","quantity":"0.221"},{"price":"62163.50","quantity":"0.001"},{"price":"62472.70","quantity":"1.678"},{"price":"62555.80","quantity":"0.240"},{"price":"62742.40","quantity":"0.962"},{"price":"64188.10","quantity":"0.000"},{"price":"89523.20","quantity":"0.942"}],"raw":{"e":"depthUpdate","E":1783517074250,"T":1783517074249,"s":"BTCUSDT","ps":"BTCUSDT","U":10999771264559,"u":10999771275006,"pu":10999771264079,"b":[["1000.00","207.692"],["11354.10","1.027"],["11454.10","1.105"],["11654.10","0.032"],["11754.10","2.736"],["55668.60","0.002"],["59379.90","0.000"],["61235.60","0.328"],["61272.10","0.001"],["61544.80","0.038"],["61777.90","33.294"],["61786.30","0.002"],["61796.80","0.014"],["61800.00","21.541"],["61823.40","0.451"],["61823.50","0.092"],["61832.70","0.009"],["61839.30","0.634"]],"a":[["61855.90","0.369"],["61857.50","0.001"],["61857.60","0.051"],["61858.20","0.196"],["61858.30","0.013"],["61858.40","0.164"],["61858.50","0.218"],["61859.50","1.635"],["61860.40","0.450"],["61863.40","0.030"],["61888.00","0.599"],["61888.10","0.240"],["61893.40","0.099"],["61895.40","0.096"],["61896.80","0.445"],["61908.20","0.564"],["61909.80","0.000"],["61909.90","0.221"],["62163.50","0.001"],["62472.70","1.678"],["62555.80","0.240"],["62742.40","0.962"],["64188.10","0.000"],["89523.20","0.942"]],"st":1}}
{"schema_version":"1.3.0","event_id":"5d02750f-0dad-4633-908d-a1f3bac1ec44","event_type":"raw.depth_update","source":"binance_market_data_recorder","venue":"binance_usdm","market_type":"perpetual_futures","symbol":"BTCUSDT","event_time_ms":1783517074352,"received_time_ms":1783517074347,"trace_id":"bd088be9-fcd3-4498-adb5-cd4dd0dc922e","first_update_id":10999771275207,"final_update_id":10999771286994,"previous_final_update_id":10999771275006,"bids":[{"price":"11354.10","quantity":"1.035"},{"price":"11454.10","quantity":"0.969"},{"price":"11654.10","quantity":"0.176"},{"price":"11754.10","quantity":"2.720"},{"price":"55668.60","quantity":"0.002"},{"price":"58759.60","quantity":"0.000"},{"price":"59379.90","quantity":"0.003"},{"price":"60790.20","quantity":"0.574"},{"price":"61235.60","quantity":"0.328"},{"price":"61346.90","quantity":"0.454"},{"price":"61544.80","quantity":"0.039"},{"price":"61750.60","quantity":"0.000"},{"price":"61750.70","quantity":"0.003"},{"price":"61777.90","quantity":"0.146"},{"price":"61784.20","quantity":"33.150"},{"price":"61792.20","quantity":"0.327"},{"price":"61798.70","quantity":"0.005"},{"price":"61815.40","quantity":"0.004"},{"price":"61815.50","quantity":"0.003"},{"price":"61823.40","quantity":"0.445"},{"price":"61823.50","quantity":"0.003"},{"price":"61823.80","quantity":"0.090"},{"price":"61834.90","quantity":"0.081"},{"price":"61835.80","quantity":"0.165"},{"price":"61842.00","quantity":"0.150"},{"price":"61852.10","quantity":"0.000"},{"price":"61853.90","quantity":"0.246"},{"price":"61854.10","quantity":"18.704"}],"asks":[{"price":"61854.20","quantity":"1.791"},{"price":"61858.40","quantity":"0.163"},{"price":"61858.50","quantity":"1.116"},{"price":"61860.40","quantity":"0.450"},{"price":"61862.50","quantity":"0.324"},{"price":"61865.10","quantity":"0.222"},{"price":"61867.00","quantity":"0.310"},{"price":"61867.10","quantity":"0.000"},{"price":"61873.20","quantity":"0.109"},{"price":"61879.40","quantity":"0.469"},{"price":"61887.80","quantity":"0.391"},{"price":"61888.00","quantity":"0.494"},{"price":"61893.40","quantity":"0.306"},{"price":"61896.80","quantity":"0.449"},{"price":"61897.50","quantity":"0.323"},{"price":"61908.70","quantity":"0.028"},{"price":"61909.00","quantity":"0.032"},{"price":"61909.50","quantity":"2.896"},{"price":"61909.90","quantity":"0.120"},{"price":"61916.10","quantity":"0.002"},{"price":"61926.90","quantity":"0.021"},{"price":"61986.10","quantity":"0.280"},{"price":"62028.90","quantity":"0.001"},{"price":"62029.00","quantity":"0.924"},{"price":"62472.70","quantity":"1.678"},{"price":"62534.60","quantity":"0.480"},{"price":"65245.50","quantity":"0.050"},{"price":"66412.80","quantity":"0.001"}],"raw":{"e":"depthUpdate","E":1783517074352,"T":1783517074351,"s":"BTCUSDT","ps":"BTCUSDT","U":10999771275207,"u":10999771286994,"pu":10999771275006,"b":[["11354.10","1.035"],["11454.10","0.969"],["11654.10","0.176"],["11754.10","2.720"],["55668.60","0.002"],["58759.60","0.000"],["59379.90","0.003"],["60790.20","0.574"],["61235.60","0.328"],["61346.90","0.454"],["61544.80","0.039"],["61750.60","0.000"],["61750.70","0.003"],["61777.90","0.146"],["61784.20","33.150"],["61792.20","0.327"],["61798.70","0.005"],["61815.40","0.004"],["61815.50","0.003"],["61823.40","0.445"],["61823.50","0.003"],["61823.80","0.090"],["61834.90","0.081"],["61835.80","0.165"],["61842.00","0.150"],["61852.10","0.000"],["61853.90","0.246"],["61854.10","18.704"]],"a":[["61854.20","1.791"],["61858.40","0.163"],["61858.50","1.116"],["61860.40","0.450"],["61862.50","0.324"],["61865.10","0.222"],["61867.00","0.310"],["61867.10","0.000"],["61873.20","0.109"],["61879.40","0.469"],["61887.80","0.391"],["61888.00","0.494"],["61893.40","0.306"],["61896.80","0.449"],["61897.50","0.323"],["61908.70","0.028"],["61909.00","0.032"],["61909.50","2.896"],["61909.90","0.120"],["61916.10","0.002"],["61926.90","0.021"],["61986.10","0.280"],["62028.90","0.001"],["62029.00","0.924"],["62472.70","1.678"],["62534.60","0.480"],["65245.50","0.050"],["66412.80","0.001"]],"st":1}}
{"schema_version":"1.3.0","event_id":"a52ad087-051e-426d-afaa-da4f212258dc","event_type":"raw.depth_update","source":"binance_market_data_recorder","venue":"binance_usdm","market_type":"perpetual_futures","symbol":"BTCUSDT","event_time_ms":1783517074454,"received_time_ms":1783517074449,"trace_id":"852404c0-3f2b-41df-b567-bb328f70d548","first_update_id":10999771287248,"final_update_id":10999771299076,"previous_final_update_id":10999771286994,"bids":[{"price":"1000.00","quantity":"207.692"},{"price":"11354.10","quantity":"1.044"},{"price":"11454.10","quantity":"0.816"},{"price":"11654.10","quantity":"0.304"},{"price":"11754.10","quantity":"2.736"},{"price":"49483.00","quantity":"0.000"},{"price":"55668.60","quantity":"0.002"},{"price":"60909.40","quantity":"16.427"},{"price":"61080.90","quantity":"0.652"},{"price":"61235.60","quantity":"0.328"},{"price":"61276.10","quantity":"0.507"},{"price":"61330.40","quantity":"0.000"},{"price":"61544.80","quantity":"0.039"},{"price":"61831.10","quantity":"0.081"},{"price":"61834.90","quantity":"0.001"},{"price":"61835.90","quantity":"1.056"},{"price":"61836.00","quantity":"0.066"},{"price":"61836.10","quantity":"0.053"},{"price":"61854.10","quantity":"18.707"}],"asks":[{"price":"61854.20","quantity":"1.792"},{"price":"61856.20","quantity":"0.001"},{"price":"61856.30","quantity":"0.035"},{"price":"61856.40","quantity":"0.029"},{"price":"61897.50","quantity":"0.168"},{"price":"61926.90","quantity":"0.021"},{"price":"62472.70","quantity":"1.678"},{"price":"62623.20","quantity":"1.994"},{"price":"62778.20","quantity":"0.000"},{"price":"67826.30","quantity":"0.000"},{"price":"89523.20","quantity":"0.948"}],"raw":{"e":"depthUpdate","E":1783517074454,"T":1783517074453,"s":"BTCUSDT","ps":"BTCUSDT","U":10999771287248,"u":10999771299076,"pu":10999771286994,"b":[["1000.00","207.692"],["11354.10","1.044"],["11454.10","0.816"],["11654.10","0.304"],["11754.10","2.736"],["49483.00","0.000"],["55668.60","0.002"],["60909.40","16.427"],["61080.90","0.652"],["61235.60","0.328"],["61276.10","0.507"],["61330.40","0.000"],["61544.80","0.039"],["61831.10","0.081"],["61834.90","0.001"],["61835.90","1.056"],["61836.00","0.066"],["61836.10","0.053"],["61854.10","18.707"]],"a":[["61854.20","1.792"],["61856.20","0.001"],["61856.30","0.035"],["61856.40","0.029"],["61897.50","0.168"],["61926.90","0.021"],["62472.70","1.678"],["62623.20","1.994"],["62778.20","0.000"],["67826.30","0.000"],["89523.20","0.948"]],"st":1}}
{"schema_version":"1.3.0","event_id":"e3784353-7daa-4090-a184-b68fb0bebdb3","event_type":"raw.depth_update","source":"binance_market_data_recorder","venue":"binance_usdm","market_type":"perpetual_futures","symbol":"BTCUSDT","event_time_ms":1783517074556,"received_time_ms":1783517074648,"trace_id":"88518396-382b-4c8e-ba38-f64d2daec44c","first_update_id":10999771299304,"final_update_id":10999771321293,"previous_final_update_id":10999771299076,"bids":[{"price":"1000.00","quantity":"207.692"},{"price":"11354.10","quantity":"1.052"},{"price":"11454.10","quantity":"0.680"},{"price":"11654.10","quantity":"0.448"},{"price":"11754.10","quantity":"2.720"},{"price":"55668.60","quantity":"0.002"},{"price":"59379.90","quantity":"0.000"},{"price":"60616.70","quantity":"0.005"},{"price":"60617.10","quantity":"0.018"},{"price":"61235.60","quantity":"0.330"},{"price":"61795.30","quantity":"4.695"},{"price":"61805.00","quantity":"6.800"},{"price":"61815.70","quantity":"0.103"},{"price":"61815.90","quantity":"0.103"},{"price":"61819.70","quantity":"0.000"},{"price":"61823.70","quantity":"1.308"},{"price":"61823.80","quantity":"0.001"},{"price":"61824.10","quantity":"0.196"},{"price":"61824.30","quantity":"0.093"},{"price":"61824.50","quantity":"0.332"},{"price":"61824.60","quantity":"0.065"},{"price":"61824.70","quantity":"0.061"},{"price":"61825.10","quantity":"0.360"},{"price":"61825.20","quantity":"0.106"},{"price":"61825.50","quantity":"0.113"},{"price":"61827.40","quantity":"0.593"},{"price":"61828.10","quantity":"0.008"},{"price":"61831.10","quantity":"0.001"},{"price":"61831.60","quantity":"0.002"},{"price":"61834.80","quantity":"0.074"},{"price":"61835.60","quantity":"0.000"},{"price":"61835.80","quantity":"0.003"},{"price":"61837.20","quantity":"0.122"},{"price":"61837.70","quantity":"0.456"},{"price":"61838.70","quantity":"0.001"},{"price":"61839.90","quantity":"0.131"},{"price":"61840.30","quantity":"0.004"},{"price":"61841.30","quantity":"0.105"},{"price":"61841.50","quantity":"0.350"},{"price":"61842.00","quantity":"0.069"},{"price":"61842.40","quantity":"0.373"},{"price":"61842.60","quantity":"0.081"},{"price":"61843.00","quantity":"0.127"},{"price":"61843.10","quantity":"0.018"},{"price":"61844.60","quantity":"0.160"},{"price":"61846.00","quantity":"0.328"},{"price":"61849.10","quantity":"0.083"},{"price":"61850.20","quantity":"0.006"},{"price":"61854.10","quantity":"19.084"}],"asks":[{"price":"61854.20","quantity":"0.822"},{"price":"61854.30","quantity":"0.025"},{"price":"61855.70","quantity":"0.242"},{"price":"61856.30","quantity":"0.030"},{"price":"61856.50","quantity":"0.010"},{"price":"61856.60","quantity":"0.235"},{"price":"61857.30","quantity":"0.000"},{"price":"61857.80","quantity":"0.005"},{"price":"61859.00","quantity":"0.114"},{"price":"61860.00","quantity":"0.048"},{"price":"61860.40","quantity":"0.322"},{"price":"61860.70","quantity":"0.109"},{"price":"61861.90","quantity":"0.006"},{"price":"61862.20","quantity":"0.198"},{"price":"61863.40","quantity":"0.070"},{"price":"61863.70","quantity":"0.980"},{"price":"61865.30","quantity":"0.327"},{"price":"61869.90","quantity":"0.825"},{"price":"61872.80","quantity":"0.128"},{"price":"61876.30","quantity":"0.351"},{"price":"61876.70","quantity":"0.000"},{"price":"61877.00","quantity":"0.002"},{"price":"61887.20","quantity":"0.002"},{"price":"61888.60","quantity":"0.115"},{"price":"61888.80","quantity":"0.057"},{"price":"61897.50","quantity":"0.168"},{"price":"61897.90","quantity":"0.156"},{"price":"61904.90","quantity":"2.462"},{"price":"61909.90","quantity":"0.376"},{"price":"61913.50","quantity":"1.898"},{"price":"61913.90","quantity":"0.000"},{"price":"61926.90","quantity":"0.021"},{"price":"62472.70","quantity":"1.680"},{"price":"63090.80","quantity":"0.003"},{"price":"63091.20","quantity":"0.053"}],"raw":{"e":"depthUpdate","E":1783517074556,"T":1783517074555,"s":"BTCUSDT","ps":"BTCUSDT","U":10999771299304,"u":10999771321293,"pu":10999771299076,"b":[["1000.00","207.692"],["11354.10","1.052"],["11454.10","0.680"],["11654.10","0.448"],["11754.10","2.720"],["55668.60","0.002"],["59379.90","0.000"],["60616.70","0.005"],["60617.10","0.018"],["61235.60","0.330"],["61795.30","4.695"],["61805.00","6.800"],["61815.70","0.103"],["61815.90","0.103"],["61819.70","0.000"],["61823.70","1.308"],["61823.80","0.001"],["61824.10","0.196"],["61824.30","0.093"],["61824.50","0.332"],["61824.60","0.065"],["61824.70","0.061"],["61825.10","0.360"],["61825.20","0.106"],["61825.50","0.113"],["61827.40","0.593"],["61828.10","0.008"],["61831.10","0.001"],["61831.60","0.002"],["61834.80","0.074"],["61835.60","0.000"],["61835.80","0.003"],["61837.20","0.122"],["61837.70","0.456"],["61838.70","0.001"],["61839.90","0.131"],["61840.30","0.004"],["61841.30","0.105"],["61841.50","0.350"],["61842.00","0.069"],["61842.40","0.373"],["61842.60","0.081"],["61843.00","0.127"],["61843.10","0.018"],["61844.60","0.160"],["61846.00","0.328"],["61849.10","0.083"],["61850.20","0.006"],["61854.10","19.084"]],"a":[["61854.20","0.822"],["61854.30","0.025"],["61855.70","0.242"],["61856.30","0.030"],["61856.50","0.010"],["61856.60","0.235"],["61857.30","0.000"],["61857.80","0.005"],["61859.00","0.114"],["61860.00","0.048"],["61860.40","0.322"],["61860.70","0.109"],["61861.90","0.006"],["61862.20","0.198"],["61863.40","0.070"],["61863.70","0.980"],["61865.30","0.327"],["61869.90","0.825"],["61872.80","0.128"],["61876.30","0.351"],["61876.70","0.000"],["61877.00","0.002"],["61887.20","0.002"],["61888.60","0.115"],["61888.80","0.057"],["61897.50","0.168"],["61897.90","0.156"],["61904.90","2.462"],["61909.90","0.376"],["61913.50","1.898"],["61913.90","0.000"],["61926.90","0.021"],["62472.70","1.680"],["63090.80","0.003"],["63091.20","0.053"]],"st":1}}
{"schema_version":"1.3.0","event_id":"f2224f1e-0b82-4102-b418-0caea74a54aa","event_type":"raw.depth_update","source":"binance_market_data_recorder","venue":"binance_usdm","market_type":"perpetual_futures","symbol":"BTCUSDT","event_time_ms":1783517074658,"received_time_ms":1783517074809,"trace_id":"bddf376c-535b-43a8-9e14-fca412b79c82","first_update_id":10999771321371,"final_update_id":10999771336878,"previous_final_update_id":10999771321293,"bids":[{"price":"11354.10","quantity":"1.173"},{"price":"11454.10","quantity":"0.527"},{"price":"11654.10","quantity":"0.688"},{"price":"11754.10","quantity":"2.512"},{"price":"46375.50","quantity":"0.000"},{"price":"55668.60","quantity":"0.002"},{"price":"58155.00","quantity":"0.189"},{"price":"58760.50","quantity":"0.000"},{"price":"58760.60","quantity":"0.004"},{"price":"59379.90","quantity":"0.003"},{"price":"61111.90","quantity":"7.469"},{"price":"61235.60","quantity":"0.328"},{"price":"61359.30","quantity":"1.368"},{"price":"61784.00","quantity":"0.000"},{"price":"61784.30","quantity":"6.632"},{"price":"61808.30","quantity":"1.115"},{"price":"61814.50","quantity":"0.003"},{"price":"61823.40","quantity":"0.009"},{"price":"61823.80","quantity":"0.090"},{"price":"61838.00","quantity":"1.122"},{"price":"61847.20","quantity":"0.080"},{"price":"61849.10","quantity":"0.003"},{"price":"61854.10","quantity":"18.898"}],"asks":[{"price":"61887.60","quantity":"0.326"},{"price":"61887.90","quantity":"0.379"},{"price":"61889.00","quantity":"0.107"},{"price":"62472.70","quantity":"1.688"},{"price":"62621.50","quantity":"0.000"},{"price":"62782.00","quantity":"0.517"},{"price":"63091.20","quantity":"0.062"},{"price":"89523.20","quantity":"0.954"}],"raw":{"e":"depthUpdate","E":1783517074658,"T":1783517074657,"s":"BTCUSDT","ps":"BTCUSDT","U":10999771321371,"u":10999771336878,"pu":10999771321293,"b":[["11354.10","1.173"],["11454.10","0.527"],["11654.10","0.688"],["11754.10","2.512"],["46375.50","0.000"],["55668.60","0.002"],["58155.00","0.189"],["58760.50","0.000"],["58760.60","0.004"],["59379.90","0.003"],["61111.90","7.469"],["61235.60","0.328"],["61359.30","1.368"],["61784.00","0.000"],["61784.30","6.632"],["61808.30","1.115"],["61814.50","0.003"],["61823.40","0.009"],["61823.80","0.090"],["61838.00","1.122"],["61847.20","0.080"],["61849.10","0.003"],["61854.10","18.898"]],"a":[["61887.60","0.326"],["61887.90","0.379"],["61889.00","0.107"],["62472.70","1.688"],["62621.50","0.000"],["62782.00","0.517"],["63091.20","0.062"],["89523.20","0.954"]],"st":1}}
{"schema_version":"1.3.0","event_id":"01f649a2-d512-4a27-ade1-f6f4867dbe2b","event_type":"raw.depth_update","source":"binance_market_data_recorder","venue":"binance_usdm","market_type":"perpetual_futures","symbol":"BTCUSDT","event_time_ms":1783517074760,"received_time_ms":1783517074984,"trace_id":"f9e8191b-7985-4363-b083-584c4273c55e","first_update_id":10999771336923,"final_update_id":10999771360929,"previous_final_update_id":10999771336878,"bids":[{"price":"1000.00","quantity":"207.692"},{"price":"11354.10","quantity":"1.309"},{"price":"11454.10","quantity":"0.391"},{"price":"11654.10","quantity":"0.960"},{"price":"11754.10","quantity":"2.240"},{"price":"49483.30","quantity":"0.000"},{"price":"55668.60","quantity":"0.002"},{"price":"59379.90","quantity":"0.000"},{"price":"60617.10","quantity":"0.027"},{"price":"60926.30","quantity":"0.738"},{"price":"60967.80","quantity":"0.000"},{"price":"61052.60","quantity":"0.819"},{"price":"61235.60","quantity":"0.338"},{"price":"61544.80","quantity":"0.029"},{"price":"61740.90","quantity":"0.747"},{"price":"61814.50","quantity":"0.007"},{"price":"61815.50","quantity":"0.003"},{"price":"61815.70","quantity":"0.103"},{"price":"61821.00","quantity":"0.309"},{"price":"61821.10","quantity":"0.683"},{"price":"61823.80","quantity":"0.001"},{"price":"61824.10","quantity":"0.002"},{"price":"61824.30","quantity":"0.093"},{"price":"61825.10","quantity":"0.360"},{"price":"61825.20","quantity":"0.001"},{"price":"61825.50","quantity":"0.202"},{"price":"61829.60","quantity":"0.099"},{"price":"61833.80","quantity":"0.016"},{"price":"61837.60","quantity":"1.227"},{"price":"61838.10","quantity":"0.496"},{"price":"61842.20","quantity":"0.024"},{"price":"61847.20","quantity":"0.000"},{"price":"61852.60","quantity":"0.082"},{"price":"61854.10","quantity":"20.457"}],"asks":[{"price":"61854.20","quantity":"0.820"},{"price":"61854.30","quantity":"0.025"},{"price":"61855.30","quantity":"0.244"},{"price":"61855.70","quantity":"0.000"},{"price":"61856.20","quantity":"0.001"},{"price":"61856.30","quantity":"0.030"},{"price":"61856.50","quantity":"0.009"},{"price":"61858.40","quantity":"0.164"},{"price":"61860.40","quantity":"0.450"},{"price":"61866.20","quantity":"0.002"},{"price":"61867.90","quantity":"0.584"},{"price":"61872.80","quantity":"0.128"},{"price":"61888.80","quantity":"0.160"},{"price":"61889.00","quantity":"0.006"},{"price":"61893.50","quantity":"0.580"},{"price":"61926.90","quantity":"0.021"},{"price":"62472.70","quantity":"1.678"},{"price":"62946.40","quantity":"2.604"},{"price":"63091.20","quantity":"0.065"}],"raw":{"e":"depthUpdate","E":1783517074760,"T":1783517074759,"s":"BTCUSDT","ps":"BTCUSDT","U":10999771336923,"u":10999771360929,"pu":10999771336878,"b":[["1000.00","207.692"],["11354.10","1.309"],["11454.10","0.391"],["11654.10","0.960"],["11754.10","2.240"],["49483.30","0.000"],["55668.60","0.002"],["59379.90","0.000"],["60617.10","0.027"],["60926.30","0.738"],["60967.80","0.000"],["61052.60","0.819"],["61235.60","0.338"],["61544.80","0.029"],["61740.90","0.747"],["61814.50","0.007"],["61815.50","0.003"],["61815.70","0.103"],["61821.00","0.309"],["61821.10","0.683"],["61823.80","0.001"],["61824.10","0.002"],["61824.30","0.093"],["61825.10","0.360"],["61825.20","0.001"],["61825.50","0.202"],["61829.60","0.099"],["61833.80","0.016"],["61837.60","1.227"],["61838.10","0.496"],["61842.20","0.024"],["61847.20","0.000"],["61852.60","0.082"],["61854.10","20.457"]],"a":[["61854.20","0.820"],["61854.30","0.025"],["61855.30","0.244"],["61855.70","0.000"],["61856.20","0.001"],["61856.30","0.030"],["61856.50","0.009"],["61858.40","0.164"],["61860.40","0.450"],["61866.20","0.002"],["61867.90","0.584"],["61872.80","0.128"],["61888.80","0.160"],["61889.00","0.006"],["61893.50","0.580"],["61926.90","0.021"],["62472.70","1.678"],["62946.40","2.604"],["63091.20","0.065"]],"st":1}}
{"schema_version":"1.3.0","event_id":"e36c0270-fc9f-4e98-9a89-cf9e136c2903","event_type":"raw.depth_update","source":"binance_market_data_recorder","venue":"binance_usdm","market_type":"perpetual_futures","symbol":"BTCUSDT","event_time_ms":1783517074862,"received_time_ms":1783517075128,"trace_id":"4bc42142-5899-40ad-94aa-ddb1df0e26e2","first_update_id":10999771360954,"final_update_id":10999771379763,"previous_final_update_id":10999771360929,"bids":[{"price":"1000.00","quantity":"207.692"},{"price":"11354.10","quantity":"1.462"},{"price":"11454.10","quantity":"0.238"},{"price":"11654.10","quantity":"1.232"},{"price":"11754.10","quantity":"1.968"},{"price":"30926.80","quantity":"0.002"},{"price":"55668.60","quantity":"0.002"},{"price":"58761.00","quantity":"0.003"},{"price":"58761.10","quantity":"0.006"},{"price":"59379.90","quantity":"0.003"},{"price":"61235.60","quantity":"0.330"},{"price":"61487.10","quantity":"0.001"},{"price":"61784.20","quantity":"0.002"},{"price":"61784.30","quantity":"0.078"},{"price":"61786.30","quantity":"33.150"},{"price":"61815.70","quantity":"0.103"},{"price":"61823.80","quantity":"0.001"},{"price":"61824.10","quantity":"0.002"},{"price":"61824.30","quantity":"0.004"},{"price":"61825.10","quantity":"0.255"},{"price":"61825.20","quantity":"0.001"},{"price":"61825.90","quantity":"0.092"},{"price":"61827.10","quantity":"0.588"},{"price":"61827.80","quantity":"0.286"},{"price":"61827.90","quantity":"0.622"},{"price":"61830.10","quantity":"0.122"},{"price":"61830.50","quantity":"0.000"},{"price":"61832.20","quantity":"0.010"},{"price":"61833.80","quantity":"0.000"},{"price":"61836.00","quantity":"0.082"},{"price":"61837.60","quantity":"1.231"},{"price":"61842.50","quantity":"0.002"},{"price":"61845.10","quantity":"0.640"},{"price":"61845.90","quantity":"0.813"},{"price":"61847.20","quantity":"0.004"},{"price":"61852.60","quantity":"0.002"},{"price":"61853.70","quantity":"0.082"},{"price":"61853.80","quantity":"0.002"},{"price":"61854.10","quantity":"20.892"}],"asks":[{"price":"61854.20","quantity":"0.366"},{"price":"61857.30","quantity":"0.000"},{"price":"61858.10","quantity":"1.705"},{"price":"61858.30","quantity":"0.013"},{"price":"61858.50","quantity":"0.218"},{"price":"61859.50","quantity":"0.019"},{"price":"61860.40","quantity":"0.322"},{"price":"61865.80","quantity":"0.000"},{"price":"61866.60","quantity":"3.938"},{"price":"61867.90","quantity":"0.002"},{"price":"61872.80","quantity":"0.000"},{"price":"61891.30","quantity":"0.330"},{"price":"61897.50","quantity":"0.168"},{"price":"61926.90","quantity":"0.021"},{"price":"62472.70","quantity":"1.682"},{"price":"62621.60","quantity":"0.000"},{"price":"63091.20","quantity":"0.077"},{"price":"89523.20","quantity":"0.960"}],"raw":{"e":"depthUpdate","E":1783517074862,"T":1783517074861,"s":"BTCUSDT","ps":"BTCUSDT","U":10999771360954,"u":10999771379763,"pu":10999771360929,"b":[["1000.00","207.692"],["11354.10","1.462"],["11454.10","0.238"],["11654.10","1.232"],["11754.10","1.968"],["30926.80","0.002"],["55668.60","0.002"],["58761.00","0.003"],["58761.10","0.006"],["59379.90","0.003"],["61235.60","0.330"],["61487.10","0.001"],["61784.20","0.002"],["61784.30","0.078"],["61786.30","33.150"],["61815.70","0.103"],["61823.80","0.001"],["61824.10","0.002"],["61824.30","0.004"],["61825.10","0.255"],["61825.20","0.001"],["61825.90","0.092"],["61827.10","0.588"],["61827.80","0.286"],["61827.90","0.622"],["61830.10","0.122"],["61830.50","0.000"],["61832.20","0.010"],["61833.80","0.000"],["61836.00","0.082"],["61837.60","1.231"],["61842.50","0.002"],["61845.10","0.640"],["61845.90","0.813"],["61847.20","0.004"],["61852.60","0.002"],["61853.70","0.082"],["61853.80","0.002"],["61854.10","20.892"]],"a":[["61854.20","0.366"],["61857.30","0.000"],["61858.10","1.705"],["61858.30","0.013"],["61858.50","0.218"],["61859.50","0.019"],["61860.40","0.322"],["61865.80","0.000"],["61866.60","3.938"],["61867.90","0.002"],["61872.80","0.000"],["61891.30","0.330"],["61897.50","0.168"],["61926.90","0.021"],["62472.70","1.682"],["62621.60","0.000"],["63091.20","0.077"],["89523.20","0.960"]],"st":1}}
{"schema_version":"1.3.0","event_id":"62427448-0acd-4c6b-ab44-6d0a45f32787","event_type":"raw.depth_update","source":"binance_market_data_recorder","venue":"binance_usdm","market_type":"perpetual_futures","symbol":"BTCUSDT","event_time_ms":1783517074964,"received_time_ms":1783517075328,"trace_id":"0834d265-5e98-4902-99f4-0de62b4d74d7","first_update_id":10999771379774,"final_update_id":10999771400760,"previous_final_update_id":10999771379763,"bids":[{"price":"11354.10","quantity":"1.598"},{"price":"11454.10","quantity":"0.102"},{"price":"11654.10","quantity":"1.504"},{"price":"11754.10","quantity":"1.696"},{"price":"55668.60","quantity":"0.002"},{"price":"60616.70","quantity":"0.002"},{"price":"60617.10","quantity":"0.030"},{"price":"61012.90","quantity":"1.635"},{"price":"61076.90","quantity":"2.567"},{"price":"61098.20","quantity":"3.924"},{"price":"61235.30","quantity":"0.059"},{"price":"61235.60","quantity":"0.332"},{"price":"61387.60","quantity":"0.025"},{"price":"61526.60","quantity":"0.035"},{"price":"61614.30","quantity":"0.343"},{"price":"61633.00","quantity":"0.551"},{"price":"61701.40","quantity":"2.161"},{"price":"61777.10","quantity":"0.141"},{"price":"61777.90","quantity":"0.146"},{"price":"61786.30","quantity":"33.065"},{"price":"61794.30","quantity":"0.028"},{"price":"61795.50","quantity":"0.040"},{"price":"61799.80","quantity":"1.056"},{"price":"61804.50","quantity":"0.089"},{"price":"61805.00","quantity":"6.590"},{"price":"61805.20","quantity":"0.228"},{"price":"61810.20","quantity":"0.095"},{"price":"61811.90","quantity":"0.030"},{"price":"61815.50","quantity":"0.003"},{"price":"61815.70","quantity":"0.103"},{"price":"61821.00","quantity":"0.334"},{"price":"61823.80","quantity":"0.001"},{"price":"61824.10","quantity":"0.091"},{"price":"61824.30","quantity":"0.093"},{"price":"61825.10","quantity":"0.255"},{"price":"61827.40","quantity":"0.568"},{"price":"61832.40","quantity":"0.001"},{"price":"61840.50","quantity":"2.140"},{"price":"61840.60","quantity":"0.566"},{"price":"61840.80","quantity":"0.141"},{"price":"61842.20","quantity":"0.001"},{"price":"61843.80","quantity":"0.329"},{"price":"61847.90","quantity":"2.135"},{"price":"61848.10","quantity":"0.000"},{"price":"61854.10","quantity":"19.013"}],"asks":[{"price":"61854.20","quantity":"0.783"},{"price":"61854.60","quantity":"0.002"},{"price":"61855.20","quantity":"0.032"},{"price":"61855.30","quantity":"0.002"},{"price":"61855.40","quantity":"0.001"},{"price":"61855.80","quantity":"0.249"},{"price":"61857.30","quantity":"0.000"},{"price":"61857.60","quantity":"1.667"},{"price":"61857.70","quantity":"0.007"},{"price":"61857.80","quantity":"0.005"},{"price":"61857.90","quantity":"0.000"},{"price":"61858.00","quantity":"0.011"},{"price":"61858.10","quantity":"0.089"},{"price":"61858.30","quantity":"0.013"},{"price":"61859.50","quantity":"0.019"},{"price":"61860.40","quantity":"0.322"},{"price":"61865.80","quantity":"0.002"},{"price":"61870.60","quantity":"0.242"},{"price":"61871.30","quantity":"0.119"},{"price":"61871.60","quantity":"0.005"},{"price":"61872.80","quantity":"0.000"},{"price":"61887.80","quantity":"0.286"},{"price":"61891.30","quantity":"0.330"},{"price":"61895.40","quantity":"0.098"},{"price":"61897.50","quantity":"0.168"},{"price":"61923.00","quantity":"0.006"},{"price":"61926.90","quantity":"0.118"},{"price":"61957.70","quantity":"0.000"},{"price":"61958.10","quantity":"0.039"},{"price":"61994.70","quantity":"0.015"},{"price":"62160.10","quantity":"0.036"},{"price":"62435.80","quantity":"0.058"},{"price":"62472.70","quantity":"1.680"},{"price":"62627.40","quantity":"0.987"},{"price":"62936.60","quantity":"1.273"},{"price":"63091.20","quantity":"0.092"}],"raw":{"e":"depthUpdate","E":1783517074964,"T":1783517074963,"s":"BTCUSDT","ps":"BTCUSDT","U":10999771379774,"u":10999771400760,"pu":10999771379763,"b":[["11354.10","1.598"],["11454.10","0.102"],["11654.10","1.504"],["11754.10","1.696"],["55668.60","0.002"],["60616.70","0.002"],["60617.10","0.030"],["61012.90","1.635"],["61076.90","2.567"],["61098.20","3.924"],["61235.30","0.059"],["61235.60","0.332"],["61387.60","0.025"],["61526.60","0.035"],["61614.30","0.343"],["61633.00","0.551"],["61701.40","2.161"],["61777.10","0.141"],["61777.90","0.146"],["61786.30","33.065"],["61794.30","0.028"],["61795.50","0.040"],["61799.80","1.056"],["61804.50","0.089"],["61805.00","6.590"],["61805.20","0.228"],["61810.20","0.095"],["61811.90","0.030"],["61815.50","0.003"],["61815.70","0.103"],["61821.00","0.334"],["61823.80","0.001"],["61824.10","0.091"],["61824.30","0.093"],["61825.10","0.255"],["61827.40","0.568"],["61832.40","0.001"],["61840.50","2.140"],["61840.60","0.566"],["61840.80","0.141"],["61842.20","0.001"],["61843.80","0.329"],["61847.90","2.135"],["61848.10","0.000"],["61854.10","19.013"]],"a":[["61854.20","0.783"],["61854.60","0.002"],["61855.20","0.032"],["61855.30","0.002"],["61855.40","0.001"],["61855.80","0.249"],["61857.30","0.000"],["61857.60","1.667"],["61857.70","0.007"],["61857.80","0.005"],["61857.90","0.000"],["61858.00","0.011"],["61858.10","0.089"],["61858.30","0.013"],["61859.50","0.019"],["61860.40","0.322"],["61865.80","0.002"],["61870.60","0.242"],["61871.30","0.119"],["61871.60","0.005"],["61872.80","0.000"],["61887.80","0.286"],["61891.30","0.330"],["61895.40","0.098"],["61897.50","0.168"],["61923.00","0.006"],["61926.90","0.118"],["61957.70","0.000"],["61958.10","0.039"],["61994.70","0.015"],["62160.10","0.036"],["62435.80","0.058"],["62472.70","1.680"],["62627.40","0.987"],["62936.60","1.273"],["63091.20","0.092"]],"st":1}}
{"schema_version":"1.3.0","event_id":"7e0971c6-75df-4f05-89b3-83e457d9565d","event_type":"raw.depth_update","source":"binance_market_data_recorder","venue":"binance_usdm","market_type":"perpetual_futures","symbol":"BTCUSDT","event_time_ms":1783517075066,"received_time_ms":1783517075402,"trace_id":"8b65752d-cec0-43f7-8187-8799be1f0aba","first_update_id":10999771400773,"final_update_id":10999771414142,"previous_final_update_id":10999771400760,"bids":[{"price":"1000.00","quantity":"207.692"},{"price":"11354.10","quantity":"1.649"},{"price":"11454.10","quantity":"0.000"},{"price":"11654.10","quantity":"1.776"},{"price":"11754.10","quantity":"1.475"},{"price":"55668.60","quantity":"0.002"},{"price":"58761.10","quantity":"0.003"},{"price":"58761.40","quantity":"0.017"},{"price":"58761.50","quantity":"0.003"},{"price":"59379.90","quantity":"0.000"},{"price":"60617.10","quantity":"0.036"},{"price":"60788.00","quantity":"6.732"},{"price":"60954.70","quantity":"0.819"},{"price":"61033.10","quantity":"2.781"},{"price":"61085.60","quantity":"0.681"},{"price":"61098.20","quantity":"2.943"},{"price":"61111.80","quantity":"5.580"},{"price":"61235.60","quantity":"0.328"},{"price":"61544.80","quantity":"0.039"},{"price":"61798.60","quantity":"0.236"},{"price":"61801.60","quantity":"0.034"},{"price":"61805.20","quantity":"0.018"},{"price":"61810.20","quantity":"0.080"},{"price":"61813.70","quantity":"1.406"},{"price":"61814.30","quantity":"0.331"},{"price":"61815.40","quantity":"0.105"},{"price":"61815.50","quantity":"0.003"},{"price":"61815.70","quantity":"0.103"},{"price":"61821.00","quantity":"0.309"},{"price":"61821.10","quantity":"1.168"},{"price":"61822.80","quantity":"0.470"},{"price":"61823.50","quantity":"0.009"},{"price":"61823.80","quantity":"0.090"},{"price":"61824.00","quantity":"0.326"},{"price":"61824.10","quantity":"0.091"},{"price":"61824.30","quantity":"0.093"},{"price":"61825.50","quantity":"0.902"},{"price":"61828.10","quantity":"0.008"},{"price":"61829.20","quantity":"0.472"},{"price":"61829.30","quantity":"0.169"},{"price":"61830.10","quantity":"0.001"},{"price":"61830.40","quantity":"0.050"},{"price":"61834.00","quantity":"1.374"},{"price":"61836.00","quantity":"0.066"},{"price":"61838.00","quantity":"0.000"},{"price":"61838.60","quantity":"0.128"},{"price":"61840.70","quantity":"0.003"},{"price":"61841.70","quantity":"0.390"},{"price":"61842.00","quantity":"0.149"},{"price":"61842.10","quantity":"0.001"},{"price":"61842.40","quantity":"0.293"},{"price":"61842.70","quantity":"0.890"},{"price":"61843.00","quantity":"0.127"},{"price":"61843.20","quantity":"0.168"},{"price":"61845.10","quantity":"0.317"},{"price":"61845.90","quantity":"0.247"},{"price":"61847.50","quantity":"0.422"},{"price":"61851.80","quantity":"0.048"},{"price":"61854.10","quantity":"18.378"}],"asks":[{"price":"61854.20","quantity":"1.751"},{"price":"61854.30","quantity":"0.026"},{"price":"61854.70","quantity":"0.023"},{"price":"61855.20","quantity":"0.032"},{"price":"61855.80","quantity":"0.007"},{"price":"61856.50","quantity":"0.058"},{"price":"61857.10","quantity":"0.325"},{"price":"61857.30","quantity":"0.000"},{"price":"61857.50","quantity":"0.001"},{"price":"61857.60","quantity":"0.051"},{"price":"61858.30","quantity":"1.952"},{"price":"61858.40","quantity":"0.163"},{"price":"61858.50","quantity":"1.304"},{"price":"61859.20","quantity":"0.014"},{"price":"61859.50","quantity":"0.019"},{"price":"61859.60","quantity":"0.016"},{"price":"61859.90","quantity":"0.180"},{"price":"61860.30","quantity":"1.291"},{"price":"61860.40","quantity":"0.450"},{"price":"61861.90","quantity":"0.002"},{"price":"61865.40","quantity":"0.000"},{"price":"61865.90","quantity":"0.406"},{"price":"61866.60","quantity":"3.938"},{"price":"61868.70","quantity":"0.097"},{"price":"61869.80","quantity":"0.009"},{"price":"61871.60","quantity":"0.007"},{"price":"61872.80","quantity":"0.000"},{"price":"61878.50","quantity":"0.488"},{"price":"61888.60","quantity":"0.012"},{"price":"61888.80","quantity":"0.055"},{"price":"61889.00","quantity":"0.002"},{"price":"61891.30","quantity":"0.202"},{"price":"61897.50","quantity":"0.296"},{"price":"61909.50","quantity":"2.896"},{"price":"61909.90","quantity":"0.275"},{"price":"61926.90","quantity":"0.021"},{"price":"61950.50","quantity":"0.000"},{"price":"62472.70","quantity":"1.678"},{"price":"62568.90","quantity":"0.798"},{"price":"62596.40","quantity":"0.703"},{"price":"62946.40","quantity":"1.335"},{"price":"63501.60","quantity":"0.017"},{"price":"89523.20","quantity":"0.966"}],"raw":{"e":"depthUpdate","E":1783517075066,"T":1783517075065,"s":"BTCUSDT","ps":"BTCUSDT","U":10999771400773,"u":10999771414142,"pu":10999771400760,"b":[["1000.00","207.692"],["11354.10","1.649"],["11454.10","0.000"],["11654.10","1.776"],["11754.10","1.475"],["55668.60","0.002"],["58761.10","0.003"],["58761.40","0.017"],["58761.50","0.003"],["59379.90","0.000"],["60617.10","0.036"],["60788.00","6.732"],["60954.70","0.819"],["61033.10","2.781"],["61085.60","0.681"],["61098.20","2.943"],["61111.80","5.580"],["61235.60","0.328"],["61544.80","0.039"],["61798.60","0.236"],["61801.60","0.034"],["61805.20","0.018"],["61810.20","0.080"],["61813.70","1.406"],["61814.30","0.331"],["61815.40","0.105"],["61815.50","0.003"],["61815.70","0.103"],["61821.00","0.309"],["61821.10","1.168"],["61822.80","0.470"],["61823.50","0.009"],["61823.80","0.090"],["61824.00","0.326"],["61824.10","0.091"],["61824.30","0.093"],["61825.50","0.902"],["61828.10","0.008"],["61829.20","0.472"],["61829.30","0.169"],["61830.10","0.001"],["61830.40","0.050"],["61834.00","1.374"],["61836.00","0.066"],["61838.00","0.000"],["61838.60","0.128"],["61840.70","0.003"],["61841.70","0.390"],["61842.00","0.149"],["61842.10","0.001"],["61842.40","0.293"],["61842.70","0.890"],["61843.00","0.127"],["61843.20","0.168"],["61845.10","0.317"],["61845.90","0.247"],["61847.50","0.422"],["61851.80","0.048"],["61854.10","18.378"]],"a":[["61854.20","1.751"],["61854.30","0.026"],["61854.70","0.023"],["61855.20","0.032"],["61855.80","0.007"],["61856.50","0.058"],["61857.10","0.325"],["61857.30","0.000"],["61857.50","0.001"],["61857.60","0.051"],["61858.30","1.952"],["61858.40","0.163"],["61858.50","1.304"],["61859.20","0.014"],["61859.50","0.019"],["61859.60","0.016"],["61859.90","0.180"],["61860.30","1.291"],["61860.40","0.450"],["61861.90","0.002"],["61865.40","0.000"],["61865.90","0.406"],["61866.60","3.938"],["61868.70","0.097"],["61869.80","0.009"],["61871.60","0.007"],["61872.80","0.000"],["61878.50","0.488"],["61888.60","0.012"],["61888.80","0.055"],["61889.00","0.002"],["61891.30","0.202"],["61897.50","0.296"],["61909.50","2.896"],["61909.90","0.275"],["61926.90","0.021"],["61950.50","0.000"],["62472.70","1.678"],["62568.90","0.798"],["62596.40","0.703"],["62946.40","1.335"],["63501.60","0.017"],["89523.20","0.966"]],"st":1}}
{"schema_version":"1.3.0","event_id":"6af7ad96-be61-4ba0-8976-b355116d586a","event_type":"raw.depth_update","source":"binance_market_data_recorder","venue":"binance_usdm","market_type":"perpetual_futures","symbol":"BTCUSDT","event_time_ms":1783517075168,"received_time_ms":1783517075420,"trace_id":"db17dd06-e729-4ccc-8424-1171a4cd7e11","first_update_id":10999771414192,"final_update_id":10999771422069,"previous_final_update_id":10999771414142,"bids":[{"price":"1000.00","quantity":"207.692"},{"price":"11354.10","quantity":"1.513"},{"price":"11654.10","quantity":"2.048"},{"price":"11754.10","quantity":"1.339"},{"price":"30926.80","quantity":"0.000"},{"price":"55668.60","quantity":"0.002"},{"price":"59379.90","quantity":"0.003"},{"price":"61101.50","quantity":"0.001"},{"price":"61118.00","quantity":"1.993"},{"price":"61235.60","quantity":"0.329"},{"price":"61400.10","quantity":"10.460"},{"price":"61472.90","quantity":"0.000"},{"price":"61473.00","quantity":"0.401"},{"price":"61565.30","quantity":"0.052"},{"price":"61565.80","quantity":"1.444"},{"price":"61633.10","quantity":"0.000"},{"price":"61633.40","quantity":"0.776"},{"price":"61790.30","quantity":"0.000"},{"price":"61805.00","quantity":"6.582"},{"price":"61812.20","quantity":"1.195"},{"price":"61813.50","quantity":"0.118"},{"price":"61813.80","quantity":"0.016"},{"price":"61813.90","quantity":"0.104"},{"price":"61815.80","quantity":"2.138"},{"price":"61815.90","quantity":"0.002"},{"price":"61825.50","quantity":"0.797"},{"price":"61826.00","quantity":"2.724"},{"price":"61827.10","quantity":"0.006"},{"price":"61828.10","quantity":"0.008"},{"price":"61828.30","quantity":"0.122"},{"price":"61829.30","quantity":"0.048"},{"price":"61830.40","quantity":"0.130"},{"price":"61831.20","quantity":"0.969"},{"price":"61831.40","quantity":"0.339"},{"price":"61832.10","quantity":"0.065"},{"price":"61832.20","quantity":"0.002"},{"price":"61832.90","quantity":"0.001"},{"price":"61834.40","quantity":"0.688"},{"price":"61835.20","quantity":"0.002"},{"price":"61836.70","quantity":"0.003"},{"price":"61839.30","quantity":"0.714"},{"price":"61841.20","quantity":"0.003"},{"price":"61842.00","quantity":"0.392"},{"price":"61842.70","quantity":"0.567"},{"price":"61843.20","quantity":"0.008"},{"price":"61845.00","quantity":"0.009"},{"price":"61845.70","quantity":"0.000"},{"price":"61848.00","quantity":"0.726"},{"price":"61850.40","quantity":"0.000"},{"price":"61851.50","quantity":"0.002"},{"price":"61852.10","quantity":"0.000"},{"price":"61853.90","quantity":"0.244"},{"price":"61854.10","quantity":"16.459"}],"asks":[{"price":"61854.20","quantity":"4.639"},{"price":"61854.90","quantity":"0.025"},{"price":"61855.10","quantity":"0.002"},{"price":"61856.50","quantity":"0.062"},{"price":"61856.70","quantity":"1.617"},{"price":"61856.80","quantity":"0.001"},{"price":"61856.90","quantity":"0.002"},{"price":"61857.30","quantity":"0.000"},{"price":"61857.50","quantity":"1.001"},{"price":"61857.80","quantity":"0.001"},{"price":"61858.20","quantity":"1.170"},{"price":"61858.30","quantity":"0.013"},{"price":"61858.50","quantity":"0.219"},{"price":"61858.60","quantity":"0.001"},{"price":"61859.60","quantity":"0.016"},{"price":"61859.70","quantity":"1.053"},{"price":"61860.50","quantity":"1.601"},{"price":"61862.90","quantity":"0.969"},{"price":"61863.70","quantity":"0.171"},{"price":"61863.80","quantity":"0.567"},{"price":"61864.90","quantity":"0.050"},{"price":"61866.50","quantity":"0.004"},{"price":"61866.60","quantity":"3.940"},{"price":"61866.80","quantity":"1.290"},{"price":"61867.90","quantity":"0.037"},{"price":"61868.70","quantity":"0.081"},{"price":"61869.80","quantity":"0.130"},{"price":"61869.90","quantity":"0.890"},{"price":"61871.80","quantity":"0.001"},{"price":"61872.60","quantity":"0.085"},{"price":"61872.80","quantity":"0.128"},{"price":"61877.30","quantity":"0.229"},{"price":"61897.50","quantity":"0.296"},{"price":"61899.30","quantity":"0.749"},{"price":"61909.40","quantity":"0.367"},{"price":"61923.20","quantity":"0.003"},{"price":"61926.90","quantity":"0.021"},{"price":"62040.50","quantity":"0.472"},{"price":"62041.50","quantity":"0.000"},{"price":"62109.20","quantity":"0.503"},{"price":"62109.70","quantity":"0.018"},{"price":"62202.70","quantity":"0.139"},{"price":"62202.80","quantity":"0.866"},{"price":"62202.90","quantity":"0.000"},{"price":"62472.70","quantity":"1.678"},{"price":"63083.10","quantity":"0.000"},{"price":"63091.20","quantity":"0.089"}],"raw":{"e":"depthUpdate","E":1783517075168,"T":1783517075165,"s":"BTCUSDT","ps":"BTCUSDT","U":10999771414192,"u":10999771422069,"pu":10999771414142,"b":[["1000.00","207.692"],["11354.10","1.513"],["11654.10","2.048"],["11754.10","1.339"],["30926.80","0.000"],["55668.60","0.002"],["59379.90","0.003"],["61101.50","0.001"],["61118.00","1.993"],["61235.60","0.329"],["61400.10","10.460"],["61472.90","0.000"],["61473.00","0.401"],["61565.30","0.052"],["61565.80","1.444"],["61633.10","0.000"],["61633.40","0.776"],["61790.30","0.000"],["61805.00","6.582"],["61812.20","1.195"],["61813.50","0.118"],["61813.80","0.016"],["61813.90","0.104"],["61815.80","2.138"],["61815.90","0.002"],["61825.50","0.797"],["61826.00","2.724"],["61827.10","0.006"],["61828.10","0.008"],["61828.30","0.122"],["61829.30","0.048"],["61830.40","0.130"],["61831.20","0.969"],["61831.40","0.339"],["61832.10","0.065"],["61832.20","0.002"],["61832.90","0.001"],["61834.40","0.688"],["61835.20","0.002"],["61836.70","0.003"],["61839.30","0.714"],["61841.20","0.003"],["61842.00","0.392"],["61842.70","0.567"],["61843.20","0.008"],["61845.00","0.009"],["61845.70","0.000"],["61848.00","0.726"],["61850.40","0.000"],["61851.50","0.002"],["61852.10","0.000"],["61853.90","0.244"],["61854.10","16.459"]],"a":[["61854.20","4.639"],["61854.90","0.025"],["61855.10","0.002"],["61856.50","0.062"],["61856.70","1.617"],["61856.80","0.001"],["61856.90","0.002"],["61857.30","0.000"],["61857.50","1.001"],["61857.80","0.001"],["61858.20","1.170"],["61858.30","0.013"],["61858.50","0.219"],["61858.60","0.001"],["61859.60","0.016"],["61859.70","1.053"],["61860.50","1.601"],["61862.90","0.969"],["61863.70","0.171"],["61863.80","0.567"],["61864.90","0.050"],["61866.50","0.004"],["61866.60","3.940"],["61866.80","1.290"],["61867.90","0.037"],["61868.70","0.081"],["61869.80","0.130"],["61869.90","0.890"],["61871.80","0.001"],["61872.60","0.085"],["61872.80","0.128"],["61877.30","0.229"],["61897.50","0.296"],["61899.30","0.749"],["61909.40","0.367"],["61923.20","0.003"],["61926.90","0.021"],["62040.50","0.472"],["62041.50","0.000"],["62109.20","0.503"],["62109.70","0.018"],["62202.70","0.139"],["62202.80","0.866"],["62202.90","0.000"],["62472.70","1.678"],["63083.10","0.000"],["63091.20","0.089"]],"st":1}}
{"schema_version":"1.3.0","event_id":"90a4af21-876c-4f16-b03e-b20d13fa7aea","event_type":"raw.depth_update","source":"binance_market_data_recorder","venue":"binance_usdm","market_type":"perpetual_futures","symbol":"BTCUSDT","event_time_ms":1783517075270,"received_time_ms":1783517075429,"trace_id":"bfbbbf2c-644e-4817-b9ac-18b9ae8a594e","first_update_id":10999771422241,"final_update_id":10999771428558,"previous_final_update_id":10999771422069,"bids":[{"price":"11354.10","quantity":"1.360"},{"price":"11654.10","quantity":"2.320"},{"price":"11754.10","quantity":"1.220"},{"price":"55668.60","quantity":"0.002"},{"price":"58759.60","quantity":"0.002"},{"price":"59379.90","quantity":"0.000"},{"price":"61050.00","quantity":"3.791"},{"price":"61111.90","quantity":"9.103"},{"price":"61235.60","quantity":"0.329"},{"price":"61400.00","quantity":"71.552"},{"price":"61544.80","quantity":"0.038"},{"price":"61777.90","quantity":"33.209"},{"price":"61786.30","quantity":"0.002"},{"price":"61788.40","quantity":"0.002"},{"price":"61830.40","quantity":"0.130"},{"price":"61831.20","quantity":"0.001"},{"price":"61832.00","quantity":"1.317"},{"price":"61833.30","quantity":"0.000"},{"price":"61834.40","quantity":"0.122"},{"price":"61835.20","quantity":"0.568"},{"price":"61836.70","quantity":"0.003"},{"price":"61841.20","quantity":"0.003"},{"price":"61853.70","quantity":"0.083"},{"price":"61854.10","quantity":"17.777"}],"asks":[{"price":"61854.20","quantity":"2.587"},{"price":"61854.90","quantity":"0.026"},{"price":"61856.40","quantity":"0.029"},{"price":"61856.50","quantity":"0.062"},{"price":"61856.60","quantity":"0.235"},{"price":"61856.70","quantity":"0.001"},{"price":"61858.10","quantity":"0.154"},{"price":"61858.30","quantity":"0.014"},{"price":"61859.60","quantity":"1.632"},{"price":"61860.20","quantity":"0.067"},{"price":"61862.90","quantity":"0.001"},{"price":"61863.80","quantity":"0.567"},{"price":"61864.10","quantity":"0.968"},{"price":"61866.50","quantity":"0.004"},{"price":"61869.80","quantity":"0.009"},{"price":"61869.90","quantity":"0.825"},{"price":"61871.10","quantity":"0.148"},{"price":"61873.60","quantity":"0.017"},{"price":"62041.40","quantity":"0.802"},{"price":"62051.10","quantity":"0.353"},{"price":"62163.50","quantity":"0.000"},{"price":"62472.70","quantity":"1.678"},{"price":"62732.50","quantity":"0.278"},{"price":"64005.20","quantity":"0.020"},{"price":"89523.20","quantity":"0.972"}],"raw":{"e":"depthUpdate","E":1783517075270,"T":1783517075269,"s":"BTCUSDT","ps":"BTCUSDT","U":10999771422241,"u":10999771428558,"pu":10999771422069,"b":[["11354.10","1.360"],["11654.10","2.320"],["11754.10","1.220"],["55668.60","0.002"],["58759.60","0.002"],["59379.90","0.000"],["61050.00","3.791"],["61111.90","9.103"],["61235.60","0.329"],["61400.00","71.552"],["61544.80","0.038"],["61777.90","33.209"],["61786.30","0.002"],["61788.40","0.002"],["61830.40","0.130"],["61831.20","0.001"],["61832.00","1.317"],["61833.30","0.000"],["61834.40","0.122"],["61835.20","0.568"],["61836.70","0.003"],["61841.20","0.003"],["61853.70","0.083"],["61854.10","17.777"]],"a":[["61854.20","2.587"],["61854.90","0.026"],["61856.40","0.029"],["61856.50","0.062"],["61856.60","0.235"],["61856.70","0.001"],["61858.10","0.154"],["61858.30","0.014"],["61859.60","1.632"],["61860.20","0.067"],["61862.90","0.001"],["61863.80","0.567"],["61864.10","0.968"],["61866.50","0.004"],["61869.80","0.009"],["61869.90","0.825"],["61871.10","0.148"],["61873.60","0.017"],["62041.40","0.802"],["62051.10","0.353"],["62163.50","0.000"],["62472.70","1.678"],["62732.50","0.278"],["64005.20","0.020"],["89523.20","0.972"]],"st":1}}
{"schema_version":"1.3.0","event_id":"741f7aa6-248d-411d-94c7-2cf7cbc41aa6","event_type":"raw.depth_update","source":"binance_market_data_recorder","venue":"binance_usdm","market_type":"perpetual_futures","symbol":"BTCUSDT","event_time_ms":1783517075372,"received_time_ms":1783517075432,"trace_id":"2ca105aa-8016-4d45-a1de-2c63252b3652","first_update_id":10999771428628,"final_update_id":10999771435548,"previous_final_update_id":10999771428558,"bids":[{"price":"1000.00","quantity":"207.692"},{"price":"11354.10","quantity":"1.224"},{"price":"11654.10","quantity":"2.592"},{"price":"11754.10","quantity":"1.084"},{"price":"55668.60","quantity":"0.002"},{"price":"59379.90","quantity":"0.003"},{"price":"61118.00","quantity":"3.954"},{"price":"61224.50","quantity":"0.000"},{"price":"61235.60","quantity":"0.329"},{"price":"61362.30","quantity":"0.000"},{"price":"61544.80","quantity":"0.029"},{"price":"61763.60","quantity":"0.153"},{"price":"61777.90","quantity":"0.146"},{"price":"61786.30","quantity":"33.065"},{"price":"61817.50","quantity":"0.052"},{"price":"61829.60","quantity":"0.422"},{"price":"61835.80","quantity":"0.165"},{"price":"61841.70","quantity":"0.424"},{"price":"61841.90","quantity":"0.501"},{"price":"61852.20","quantity":"0.393"},{"price":"61853.70","quantity":"0.082"},{"price":"61854.10","quantity":"17.779"}],"asks":[{"price":"61863.80","quantity":"0.001"},{"price":"61863.90","quantity":"1.660"},{"price":"61864.00","quantity":"2.721"},{"price":"61866.50","quantity":"0.004"},{"price":"61866.90","quantity":"0.097"},{"price":"61873.10","quantity":"0.165"},{"price":"61879.30","quantity":"1.912"},{"price":"61893.40","quantity":"0.306"},{"price":"61926.90","quantity":"0.021"},{"price":"62163.50","quantity":"0.001"},{"price":"62314.90","quantity":"0.000"},{"price":"62458.20","quantity":"0.144"},{"price":"62472.70","quantity":"1.678"},{"price":"62936.60","quantity":"2.543"}],"raw":{"e":"depthUpdate","E":1783517075372,"T":1783517075369,"s":"BTCUSDT","ps":"BTCUSDT","U":10999771428628,"u":10999771435548,"pu":10999771428558,"b":[["1000.00","207.692"],["11354.10","1.224"],["11654.10","2.592"],["11754.10","1.084"],["55668.60","0.002"],["59379.90","0.003"],["61118.00","3.954"],["61224.50","0.000"],["61235.60","0.329"],["61362.30","0.000"],["61544.80","0.029"],["61763.60","0.153"],["61777.90","0.146"],["61786.30","33.065"],["61817.50","0.052"],["61829.60","0.422"],["61835.80","0.165"],["61841.70","0.424"],["61841.90","0.501"],["61852.20","0.393"],["61853.70","0.082"],["61854.10","17.779"]],"a":[["61863.80","0.001"],["61863.90","1.660"],["61864.00","2.721"],["61866.50","0.004"],["61866.90","0.097"],["61873.10","0.165"],["61879.30","1.912"],["61893.40","0.306"],["61926.90","0.021"],["62163.50","0.001"],["62314.90","0.000"],["62458.20","0.144"],["62472.70","1.678"],["62936.60","2.543"]],"st":1}}
{"schema_version":"1.3.0","event_id":"202e1c96-5ccb-4533-b992-03e200e5559a","event_type":"raw.depth_update","source":"binance_market_data_recorder","venue":"binance_usdm","market_type":"perpetual_futures","symbol":"BTCUSDT","event_time_ms":1783517075474,"received_time_ms":1783517075475,"trace_id":"30b75c55-53e0-4458-be35-7f9a91aada24","first_update_id":10999771435683,"final_update_id":10999771442128,"previous_final_update_id":10999771435548,"bids":[{"price":"1000.00","quantity":"207.692"},{"price":"11354.10","quantity":"1.071"},{"price":"11554.10","quantity":"0.064"},{"price":"11654.10","quantity":"2.736"},{"price":"11754.10","quantity":"1.029"},{"price":"49483.00","quantity":"0.000"},{"price":"55668.60","quantity":"0.002"},{"price":"58761.30","quantity":"0.000"},{"price":"60617.10","quantity":"0.033"},{"price":"60860.40","quantity":"0.246"},{"price":"61040.80","quantity":"0.006"},{"price":"61235.60","quantity":"0.329"},{"price":"61272.40","quantity":"0.038"},{"price":"61520.00","quantity":"3.079"},{"price":"61600.00","quantity":"56.957"},{"price":"61680.00","quantity":"0.871"},{"price":"61760.00","quantity":"1.080"},{"price":"61770.60","quantity":"2.473"},{"price":"61817.50","quantity":"0.005"},{"price":"61838.60","quantity":"0.000"},{"price":"61840.00","quantity":"0.414"},{"price":"61854.10","quantity":"17.781"}],"asks":[{"price":"61854.20","quantity":"3.022"},{"price":"61854.80","quantity":"0.001"},{"price":"61855.80","quantity":"0.008"},{"price":"61857.30","quantity":"0.128"},{"price":"61858.50","quantity":"0.218"},{"price":"61863.80","quantity":"0.567"},{"price":"61864.00","quantity":"2.155"},{"price":"61866.50","quantity":"0.004"},{"price":"61920.00","quantity":"1.332"},{"price":"61926.90","quantity":"0.021"},{"price":"62000.00","quantity":"13.183"},{"price":"62080.00","quantity":"0.449"},{"price":"62160.00","quantity":"0.444"},{"price":"62202.70","quantity":"0.001"},{"price":"62202.80","quantity":"0.002"},{"price":"62240.00","quantity":"0.439"},{"price":"62458.10","quantity":"0.004"},{"price":"62472.70","quantity":"1.678"},{"price":"62499.90","quantity":"1.364"},{"price":"62645.50","quantity":"4.320"},{"price":"62645.60","quantity":"0.000"},{"price":"63078.90","quantity":"0.633"},{"price":"64188.10","quantity":"0.020"}],"raw":{"e":"depthUpdate","E":1783517075474,"T":1783517075473,"s":"BTCUSDT","ps":"BTCUSDT","U":10999771435683,"u":10999771442128,"pu":10999771435548,"b":[["1000.00","207.692"],["11354.10","1.071"],["11554.10","0.064"],["11654.10","2.736"],["11754.10","1.029"],["49483.00","0.000"],["55668.60","0.002"],["58761.30","0.000"],["60617.10","0.033"],["60860.40","0.246"],["61040.80","0.006"],["61235.60","0.329"],["61272.40","0.038"],["61520.00","3.079"],["61600.00","56.957"],["61680.00","0.871"],["61760.00","1.080"],["61770.60","2.473"],["61817.50","0.005"],["61838.60","0.000"],["61840.00","0.414"],["61854.10","17.781"]],"a":[["61854.20","3.022"],["61854.80","0.001"],["61855.80","0.008"],["61857.30","0.128"],["61858.50","0.218"],["61863.80","0.567"],["61864.00","2.155"],["61866.50","0.004"],["61920.00","1.332"],["61926.90","0.021"],["62000.00","13.183"],["62080.00","0.449"],["62160.00","0.444"],["62202.70","0.001"],["62202.80","0.002"],["62240.00","0.439"],["62458.10","0.004"],["62472.70","1.678"],["62499.90","1.364"],["62645.50","4.320"],["62645.60","0.000"],["63078.90","0.633"],["64188.10","0.020"]],"st":1}}
{"schema_version":"1.3.0","event_id":"24d7ba83-c899-4478-b794-7218e04077b5","event_type":"raw.depth_update","source":"binance_market_data_recorder","venue":"binance_usdm","market_type":"perpetual_futures","symbol":"BTCUSDT","event_time_ms":1783517075576,"received_time_ms":1783517075604,"trace_id":"0e4fba8a-7cb4-4760-bc4a-7d8175dd4495","first_update_id":10999771442152,"final_update_id":10999771446518,"previous_final_update_id":10999771442128,"bids":[{"price":"11354.10","quantity":"0.935"},{"price":"11554.10","quantity":"0.208"},{"price":"11654.10","quantity":"2.720"},{"price":"11754.10","quantity":"1.037"},{"price":"55668.60","quantity":"0.002"},{"price":"58761.30","quantity":"0.000"},{"price":"59379.90","quantity":"0.000"},{"price":"60864.40","quantity":"0.821"},{"price":"61235.60","quantity":"0.329"},{"price":"61260.70","quantity":"0.022"},{"price":"61800.00","quantity":"21.542"},{"price":"61841.70","quantity":"0.552"}],"asks":[{"price":"61854.20","quantity":"3.023"},{"price":"61855.80","quantity":"0.006"},{"price":"61866.40","quantity":"0.003"},{"price":"61926.90","quantity":"0.118"},{"price":"62098.90","quantity":"0.019"},{"price":"62106.20","quantity":"0.193"},{"price":"62472.70","quantity":"1.678"},{"price":"62565.50","quantity":"0.398"},{"price":"62760.80","quantity":"3.604"},{"price":"89523.20","quantity":"0.978"}],"raw":{"e":"depthUpdate","E":1783517075576,"T":1783517075573,"s":"BTCUSDT","ps":"BTCUSDT","U":10999771442152,"u":10999771446518,"pu":10999771442128,"b":[["11354.10","0.935"],["11554.10","0.208"],["11654.10","2.720"],["11754.10","1.037"],["55668.60","0.002"],["58761.30","0.000"],["59379.90","0.000"],["60864.40","0.821"],["61235.60","0.329"],["61260.70","0.022"],["61800.00","21.542"],["61841.70","0.552"]],"a":[["61854.20","3.023"],["61855.80","0.006"],["61866.40","0.003"],["61926.90","0.118"],["62098.90","0.019"],["62106.20","0.193"],["62472.70","1.678"],["62565.50","0.398"],["62760.80","3.604"],["89523.20","0.978"]],"st":1}}
{"schema_version":"1.3.0","event_id":"764ce4b4-6237-4421-9ba0-9d2b4eeeef32","event_type":"raw.depth_update","source":"binance_market_data_recorder","venue":"binance_usdm","market_type":"perpetual_futures","symbol":"BTCUSDT","event_time_ms":1783517075678,"received_time_ms":1783517075673,"trace_id":"b36fe195-e91d-4325-b7cd-6e66c505cb48","first_update_id":10999771446651,"final_update_id":10999771455393,"previous_final_update_id":10999771446518,"bids":[{"price":"1000.00","quantity":"207.692"},{"price":"11354.10","quantity":"0.782"},{"price":"11554.10","quantity":"0.336"},{"price":"11654.10","quantity":"2.736"},{"price":"11754.10","quantity":"1.046"},{"price":"49483.00","quantity":"0.000"},{"price":"55668.60","quantity":"0.002"},{"price":"58761.30","quantity":"0.000"},{"price":"59379.90","quantity":"0.003"},{"price":"61080.90","quantity":"3.905"},{"price":"61235.60","quantity":"0.328"},{"price":"61440.00","quantity":"0.158"},{"price":"61520.00","quantity":"2.919"},{"price":"61544.80","quantity":"0.039"},{"price":"61600.00","quantity":"56.797"},{"price":"61680.00","quantity":"0.711"},{"price":"61722.70","quantity":"0.000"},{"price":"61723.70","quantity":"0.000"},{"price":"61725.60","quantity":"2.827"},{"price":"61750.70","quantity":"0.000"},{"price":"61750.80","quantity":"0.033"},{"price":"61753.90","quantity":"0.819"},{"price":"61756.90","quantity":"0.637"},{"price":"61760.00","quantity":"0.920"},{"price":"61789.00","quantity":"6.210"},{"price":"61792.20","quantity":"0.328"},{"price":"61813.40","quantity":"0.163"},{"price":"61815.40","quantity":"0.004"},{"price":"61815.70","quantity":"0.002"},{"price":"61821.10","quantity":"0.732"},{"price":"61821.20","quantity":"0.537"},{"price":"61823.40","quantity":"0.069"},{"price":"61829.60","quantity":"0.362"},{"price":"61838.10","quantity":"0.000"},{"price":"61840.00","quantity":"0.236"},{"price":"61840.20","quantity":"0.005"},{"price":"61841.80","quantity":"0.009"},{"price":"61841.90","quantity":"0.420"},{"price":"61843.30","quantity":"0.019"},{"price":"61847.20","quantity":"0.000"},{"price":"61847.60","quantity":"0.004"},{"price":"61850.20","quantity":"0.002"},{"price":"61854.10","quantity":"17.781"}],"asks":[{"price":"61854.20","quantity":"2.845"},{"price":"61856.80","quantity":"1.617"},{"price":"61856.90","quantity":"0.002"},{"price":"61857.30","quantity":"0.000"},{"price":"61859.60","quantity":"0.016"},{"price":"61860.40","quantity":"0.450"},{"price":"61863.80","quantity":"0.567"},{"price":"61866.50","quantity":"0.004"},{"price":"61866.90","quantity":"0.016"},{"price":"61872.80","quantity":"0.000"},{"price":"61897.50","quantity":"0.168"},{"price":"61908.70","quantity":"0.043"},{"price":"61909.30","quantity":"0.052"},{"price":"61920.00","quantity":"1.172"},{"price":"61926.90","quantity":"0.021"},{"price":"61950.00","quantity":"1.170"},{"price":"61950.30","quantity":"0.816"},{"price":"61981.50","quantity":"0.816"},{"price":"61982.70","quantity":"0.843"},{"price":"61985.30","quantity":"2.135"},{"price":"62000.00","quantity":"13.023"},{"price":"62029.00","quantity":"0.921"},{"price":"62029.10","quantity":"0.822"},{"price":"62080.00","quantity":"0.289"},{"price":"62160.00","quantity":"0.284"},{"price":"62240.00","quantity":"0.279"},{"price":"62472.70","quantity":"1.678"},{"price":"62764.70","quantity":"12.920"},{"price":"63090.80","quantity":"0.000"},{"price":"63091.20","quantity":"0.086"}],"raw":{"e":"depthUpdate","E":1783517075678,"T":1783517075677,"s":"BTCUSDT","ps":"BTCUSDT","U":10999771446651,"u":10999771455393,"pu":10999771446518,"b":[["1000.00","207.692"],["11354.10","0.782"],["11554.10","0.336"],["11654.10","2.736"],["11754.10","1.046"],["49483.00","0.000"],["55668.60","0.002"],["58761.30","0.000"],["59379.90","0.003"],["61080.90","3.905"],["61235.60","0.328"],["61440.00","0.158"],["61520.00","2.919"],["61544.80","0.039"],["61600.00","56.797"],["61680.00","0.711"],["61722.70","0.000"],["61723.70","0.000"],["61725.60","2.827"],["61750.70","0.000"],["61750.80","0.033"],["61753.90","0.819"],["61756.90","0.637"],["61760.00","0.920"],["61789.00","6.210"],["61792.20","0.328"],["61813.40","0.163"],["61815.40","0.004"],["61815.70","0.002"],["61821.10","0.732"],["61821.20","0.537"],["61823.40","0.069"],["61829.60","0.362"],["61838.10","0.000"],["61840.00","0.236"],["61840.20","0.005"],["61841.80","0.009"],["61841.90","0.420"],["61843.30","0.019"],["61847.20","0.000"],["61847.60","0.004"],["61850.20","0.002"],["61854.10","17.781"]],"a":[["61854.20","2.845"],["61856.80","1.617"],["61856.90","0.002"],["61857.30","0.000"],["61859.60","0.016"],["61860.40","0.450"],["61863.80","0.567"],["61866.50","0.004"],["61866.90","0.016"],["61872.80","0.000"],["61897.50","0.168"],["61908.70","0.043"],["61909.30","0.052"],["61920.00","1.172"],["61926.90","0.021"],["61950.00","1.170"],["61950.30","0.816"],["61981.50","0.816"],["61982.70","0.843"],["61985.30","2.135"],["62000.00","13.023"],["62029.00","0.921"],["62029.10","0.822"],["62080.00","0.289"],["62160.00","0.284"],["62240.00","0.279"],["62472.70","1.678"],["62764.70","12.920"],["63090.80","0.000"],["63091.20","0.086"]],"st":1}}
{"schema_version":"1.3.0","event_id":"63e1a12f-e674-413c-b6fd-038db7bd07d2","event_type":"raw.depth_update","source":"binance_market_data_recorder","venue":"binance_usdm","market_type":"perpetual_futures","symbol":"BTCUSDT","event_time_ms":1783517075780,"received_time_ms":1783517075775,"trace_id":"7acafe1e-86f9-41bb-a70f-dfbad7127877","first_update_id":10999771455449,"final_update_id":10999771462406,"previous_final_update_id":10999771455393,"bids":[{"price":"1000.00","quantity":"207.692"},{"price":"11354.10","quantity":"0.646"},{"price":"11554.10","quantity":"0.480"},{"price":"11654.10","quantity":"2.720"},{"price":"11754.10","quantity":"1.054"},{"price":"49483.30","quantity":"0.000"},{"price":"55668.60","quantity":"0.002"},{"price":"59379.90","quantity":"0.000"},{"price":"60449.00","quantity":"0.000"},{"price":"60860.20","quantity":"0.492"},{"price":"61005.20","quantity":"1.393"},{"price":"61235.60","quantity":"0.328"},{"price":"61276.40","quantity":"0.250"},{"price":"61440.00","quantity":"0.336"},{"price":"61520.00","quantity":"3.097"},{"price":"61600.00","quantity":"56.975"},{"price":"61680.00","quantity":"0.889"},{"price":"61723.70","quantity":"0.287"},{"price":"61760.00","quantity":"1.098"},{"price":"61767.40","quantity":"32.949"},{"price":"61786.30","quantity":"0.002"},{"price":"61813.90","quantity":"0.003"},{"price":"61814.30","quantity":"0.230"},{"price":"61829.60","quantity":"0.422"},{"price":"61830.90","quantity":"0.969"},{"price":"61832.00","quantity":"0.349"},{"price":"61834.40","quantity":"0.688"},{"price":"61835.20","quantity":"0.002"},{"price":"61850.00","quantity":"1.706"}],"asks":[{"price":"61854.20","quantity":"2.996"},{"price":"61854.60","quantity":"0.003"},{"price":"61856.20","quantity":"1.617"},{"price":"61856.30","quantity":"0.030"},{"price":"61856.40","quantity":"0.029"},{"price":"61856.50","quantity":"0.062"},{"price":"61856.70","quantity":"0.001"},{"price":"61856.80","quantity":"0.001"},{"price":"61859.60","quantity":"0.016"},{"price":"61861.90","quantity":"0.970"},{"price":"61864.10","quantity":"0.000"},{"price":"61893.40","quantity":"0.281"},{"price":"61893.50","quantity":"0.580"},{"price":"61909.50","quantity":"2.896"},{"price":"61916.40","quantity":"3.237"},{"price":"61918.40","quantity":"0.000"},{"price":"61920.00","quantity":"1.350"},{"price":"61926.80","quantity":"26.078"},{"price":"61926.90","quantity":"0.021"},{"price":"61950.70","quantity":"0.004"},{"price":"61985.20","quantity":"1.797"},{"price":"62000.00","quantity":"13.201"},{"price":"62080.00","quantity":"0.467"},{"price":"62160.00","quantity":"0.462"},{"price":"62240.00","quantity":"0.457"},{"price":"62472.70","quantity":"1.678"},{"price":"62641.00","quantity":"5.739"},{"price":"62645.50","quantity":"0.000"},{"price":"62751.10","quantity":"0.955"},{"price":"63091.20","quantity":"0.089"},{"price":"63276.90","quantity":"4.955"},{"price":"89523.20","quantity":"0.984"}],"raw":{"e":"depthUpdate","E":1783517075780,"T":1783517075777,"s":"BTCUSDT","ps":"BTCUSDT","U":10999771455449,"u":10999771462406,"pu":10999771455393,"b":[["1000.00","207.692"],["11354.10","0.646"],["11554.10","0.480"],["11654.10","2.720"],["11754.10","1.054"],["49483.30","0.000"],["55668.60","0.002"],["59379.90","0.000"],["60449.00","0.000"],["60860.20","0.492"],["61005.20","1.393"],["61235.60","0.328"],["61276.40","0.250"],["61440.00","0.336"],["61520.00","3.097"],["61600.00","56.975"],["61680.00","0.889"],["61723.70","0.287"],["61760.00","1.098"],["61767.40","32.949"],["61786.30","0.002"],["61813.90","0.003"],["61814.30","0.230"],["61829.60","0.422"],["61830.90","0.969"],["61832.00","0.349"],["61834.40","0.688"],["61835.20","0.002"],["61850.00","1.706"]],"a":[["61854.20","2.996"],["61854.60","0.003"],["61856.20","1.617"],["61856.30","0.030"],["61856.40","0.029"],["61856.50","0.062"],["61856.70","0.001"],["61856.80","0.001"],["61859.60","0.016"],["61861.90","0.970"],["61864.10","0.000"],["61893.40","0.281"],["61893.50","0.580"],["61909.50","2.896"],["61916.40","3.237"],["61918.40","0.000"],["61920.00","1.350"],["61926.80","26.078"],["61926.90","0.021"],["61950.70","0.004"],["61985.20","1.797"],["62000.00","13.201"],["62080.00","0.467"],["62160.00","0.462"],["62240.00","0.457"],["62472.70","1.678"],["62641.00","5.739"],["62645.50","0.000"],["62751.10","0.955"],["63091.20","0.089"],["63276.90","4.955"],["89523.20","0.984"]],"st":1}}
{"schema_version":"1.3.0","event_id":"4983a0c7-5ac7-4451-85a9-048e2633b8e6","event_type":"raw.depth_update","source":"binance_market_data_recorder","venue":"binance_usdm","market_type":"perpetual_futures","symbol":"BTCUSDT","event_time_ms":1783517075882,"received_time_ms":1783517075877,"trace_id":"08fa6613-570a-45a2-bfd3-7a2245a1025b","first_update_id":10999771462599,"final_update_id":10999771468978,"previous_final_update_id":10999771462406,"bids":[{"price":"11354.10","quantity":"0.493"},{"price":"11554.10","quantity":"0.752"},{"price":"11654.10","quantity":"2.448"},{"price":"11754.10","quantity":"1.207"},{"price":"55668.60","quantity":"0.002"},{"price":"58761.30","quantity":"0.020"},{"price":"59379.90","quantity":"0.003"},{"price":"61235.60","quantity":"0.328"},{"price":"61254.10","quantity":"0.979"},{"price":"61266.50","quantity":"1.466"},{"price":"61723.70","quantity":"0.287"},{"price":"61767.40","quantity":"0.000"},{"price":"61767.50","quantity":"2.323"},{"price":"61784.20","quantity":"0.002"},{"price":"61786.30","quantity":"32.951"},{"price":"61789.00","quantity":"1.484"},{"price":"61812.20","quantity":"1.187"},{"price":"61813.50","quantity":"0.017"},{"price":"61813.80","quantity":"0.014"},{"price":"61827.20","quantity":"0.122"},{"price":"61828.30","quantity":"0.001"},{"price":"61829.60","quantity":"0.099"},{"price":"61835.80","quantity":"0.003"},{"price":"61851.90","quantity":"0.005"},{"price":"61853.60","quantity":"0.000"},{"price":"61854.10","quantity":"17.581"}],"asks":[{"price":"61854.20","quantity":"3.342"},{"price":"61856.20","quantity":"0.001"},{"price":"61859.60","quantity":"1.632"},{"price":"61861.90","quantity":"0.002"},{"price":"61862.80","quantity":"1.314"},{"price":"61868.80","quantity":"0.161"},{"price":"61869.80","quantity":"0.017"},{"price":"61871.10","quantity":"0.027"},{"price":"61871.30","quantity":"0.111"},{"price":"61897.50","quantity":"0.296"},{"price":"61909.40","quantity":"0.266"},{"price":"61909.90","quantity":"0.120"},{"price":"61919.10","quantity":"0.186"},{"price":"61920.50","quantity":"0.000"},{"price":"61925.70","quantity":"0.001"},{"price":"61926.80","quantity":"0.891"},{"price":"61926.90","quantity":"0.118"},{"price":"61931.00","quantity":"25.231"},{"price":"61985.20","quantity":"1.797"},{"price":"62098.90","quantity":"0.001"},{"price":"62472.70","quantity":"1.678"},{"price":"62695.70","quantity":"8.719"}],"raw":{"e":"depthUpdate","E":1783517075882,"T":1783517075881,"s":"BTCUSDT","ps":"BTCUSDT","U":10999771462599,"u":10999771468978,"pu":10999771462406,"b":[["11354.10","0.493"],["11554.10","0.752"],["11654.10","2.448"],["11754.10","1.207"],["55668.60","0.002"],["58761.30","0.020"],["59379.90","0.003"],["61235.60","0.328"],["61254.10","0.979"],["61266.50","1.466"],["61723.70","0.287"],["61767.40","0.000"],["61767.50","2.323"],["61784.20","0.002"],["61786.30","32.951"],["61789.00","1.484"],["61812.20","1.187"],["61813.50","0.017"],["61813.80","0.014"],["61827.20","0.122"],["61828.30","0.001"],["61829.60","0.099"],["61835.80","0.003"],["61851.90","0.005"],["61853.60","0.000"],["61854.10","17.581"]],"a":[["61854.20","3.342"],["61856.20","0.001"],["61859.60","1.632"],["61861.90","0.002"],["61862.80","1.314"],["61868.80","0.161"],["61869.80","0.017"],["61871.10","0.027"],["61871.30","0.111"],["61897.50","0.296"],["61909.40","0.266"],["61909.90","0.120"],["61919.10","0.186"],["61920.50","0.000"],["61925.70","0.001"],["61926.80","0.891"],["61926.90","0.118"],["61931.00","25.231"],["61985.20","1.797"],["62098.90","0.001"],["62472.70","1.678"],["62695.70","8.719"]],"st":1}}
{"schema_version":"1.3.0","event_id":"6cfe6fab-cdb0-49a3-812d-25a58da9f42d","event_type":"raw.depth_update","source":"binance_market_data_recorder","venue":"binance_usdm","market_type":"perpetual_futures","symbol":"BTCUSDT","event_time_ms":1783517075984,"received_time_ms":1783517075980,"trace_id":"df9d52ff-1db8-47c0-bb69-0d9ae44efa67","first_update_id":10999771469102,"final_update_id":10999771476348,"previous_final_update_id":10999771468978,"bids":[{"price":"1000.00","quantity":"207.692"},{"price":"11354.10","quantity":"0.357"},{"price":"11554.10","quantity":"1.024"},{"price":"11654.10","quantity":"2.176"},{"price":"11754.10","quantity":"1.343"},{"price":"55668.60","quantity":"0.002"},{"price":"61046.20","quantity":"5.199"},{"price":"61098.20","quantity":"1.962"},{"price":"61235.60","quantity":"0.328"},{"price":"61544.80","quantity":"0.039"},{"price":"61723.70","quantity":"0.287"},{"price":"61812.60","quantity":"0.134"},{"price":"61821.10","quantity":"0.732"},{"price":"61835.90","quantity":"1.054"},{"price":"61836.00","quantity":"0.064"},{"price":"61836.10","quantity":"0.051"},{"price":"61837.70","quantity":"0.356"},{"price":"61840.50","quantity":"2.138"},{"price":"61841.70","quantity":"0.552"},{"price":"61854.10","quantity":"16.252"}],"asks":[{"price":"61854.20","quantity":"4.500"},{"price":"61854.30","quantity":"0.035"},{"price":"61863.80","quantity":"0.001"},{"price":"61864.70","quantity":"0.001"},{"price":"61865.50","quantity":"0.580"},{"price":"61865.60","quantity":"0.586"},{"price":"61866.60","quantity":"3.358"},{"price":"61871.60","quantity":"0.005"},{"price":"61872.80","quantity":"0.128"},{"price":"61893.40","quantity":"0.243"},{"price":"61897.50","quantity":"0.168"},{"price":"61909.40","quantity":"0.367"},{"price":"61918.60","quantity":"0.039"},{"price":"61922.60","quantity":"0.660"},{"price":"61924.70","quantity":"25.187"},{"price":"61926.90","quantity":"0.021"},{"price":"61931.00","quantity":"0.044"},{"price":"61985.20","quantity":"1.797"},{"price":"61990.30","quantity":"0.335"},{"price":"62472.70","quantity":"1.678"},{"price":"62658.30","quantity":"1.594"},{"price":"62782.00","quantity":"0.875"},{"price":"62884.60","quantity":"0.000"},{"price":"89523.20","quantity":"0.990"}],"raw":{"e":"depthUpdate","E":1783517075984,"T":1783517075981,"s":"BTCUSDT","ps":"BTCUSDT","U":10999771469102,"u":10999771476348,"pu":10999771468978,"b":[["1000.00","207.692"],["11354.10","0.357"],["11554.10","1.024"],["11654.10","2.176"],["11754.10","1.343"],["55668.60","0.002"],["61046.20","5.199"],["61098.20","1.962"],["61235.60","0.328"],["61544.80","0.039"],["61723.70","0.287"],["61812.60","0.134"],["61821.10","0.732"],["61835.90","1.054"],["61836.00","0.064"],["61836.10","0.051"],["61837.70","0.356"],["61840.50","2.138"],["61841.70","0.552"],["61854.10","16.252"]],"a":[["61854.20","4.500"],["61854.30","0.035"],["61863.80","0.001"],["61864.70","0.001"],["61865.50","0.580"],["61865.60","0.586"],["61866.60","3.358"],["61871.60","0.005"],["61872.80","0.128"],["61893.40","0.243"],["61897.50","0.168"],["61909.40","0.367"],["61918.60","0.039"],["61922.60","0.660"],["61924.70","25.187"],["61926.90","0.021"],["61931.00","0.044"],["61985.20","1.797"],["61990.30","0.335"],["62472.70","1.678"],["62658.30","1.594"],["62782.00","0.875"],["62884.60","0.000"],["89523.20","0.990"]],"st":1}}
{"schema_version":"1.3.0","event_id":"924a83b6-0014-43d2-aac0-53d11b211b58","event_type":"raw.depth_update","source":"binance_market_data_recorder","venue":"binance_usdm","market_type":"perpetual_futures","symbol":"BTCUSDT","event_time_ms":1783517076086,"received_time_ms":1783517076081,"trace_id":"c0e98d98-b42f-4728-9a96-485e5415c4a1","first_update_id":10999771476572,"final_update_id":10999771485140,"previous_final_update_id":10999771476348,"bids":[{"price":"1000.00","quantity":"207.692"},{"price":"11354.10","quantity":"0.204"},{"price":"11554.10","quantity":"1.296"},{"price":"11654.10","quantity":"1.904"},{"price":"11754.10","quantity":"1.496"},{"price":"55668.60","quantity":"0.002"},{"price":"59379.90","quantity":"0.000"},{"price":"60617.10","quantity":"0.030"},{"price":"60864.30","quantity":"0.410"},{"price":"61000.00","quantity":"182.536"},{"price":"61235.50","quantity":"0.443"},{"price":"61235.60","quantity":"0.328"},{"price":"61750.80","quantity":"0.030"},{"price":"61750.90","quantity":"1.636"},{"price":"61786.30","quantity":"0.002"},{"price":"61788.40","quantity":"32.951"},{"price":"61826.00","quantity":"2.142"},{"price":"61828.00","quantity":"1.302"},{"price":"61830.50","quantity":"0.008"},{"price":"61830.90","quantity":"0.001"},{"price":"61831.40","quantity":"0.331"},{"price":"61833.20","quantity":"1.855"},{"price":"61834.40","quantity":"0.122"},{"price":"61836.70","quantity":"0.569"},{"price":"61840.50","quantity":"2.140"},{"price":"61843.00","quantity":"0.127"},{"price":"61854.10","quantity":"16.252"}],"asks":[{"price":"61854.20","quantity":"4.421"},{"price":"61854.90","quantity":"0.040"},{"price":"61860.40","quantity":"0.322"},{"price":"61862.60","quantity":"0.484"},{"price":"61862.80","quantity":"0.346"},{"price":"61864.40","quantity":"0.968"},{"price":"61865.30","quantity":"0.327"},{"price":"61865.50","quantity":"0.014"},{"price":"61865.60","quantity":"0.004"},{"price":"61866.50","quantity":"0.570"},{"price":"61866.60","quantity":"3.940"},{"price":"61867.00","quantity":"0.352"},{"price":"61868.70","quantity":"0.096"},{"price":"61871.10","quantity":"0.085"},{"price":"61871.60","quantity":"0.007"},{"price":"61872.80","quantity":"0.128"},{"price":"61877.80","quantity":"0.082"},{"price":"61897.50","quantity":"0.296"},{"price":"61926.90","quantity":"0.118"},{"price":"62029.10","quantity":"0.819"},{"price":"62029.20","quantity":"0.004"},{"price":"62427.60","quantity":"2.077"},{"price":"62472.70","quantity":"1.688"},{"price":"63091.20","quantity":"0.092"}],"raw":{"e":"depthUpdate","E":1783517076086,"T":1783517076085,"s":"BTCUSDT","ps":"BTCUSDT","U":10999771476572,"u":10999771485140,"pu":10999771476348,"b":[["1000.00","207.692"],["11354.10","0.204"],["11554.10","1.296"],["11654.10","1.904"],["11754.10","1.496"],["55668.60","0.002"],["59379.90","0.000"],["60617.10","0.030"],["60864.30","0.410"],["61000.00","182.536"],["61235.50","0.443"],["61235.60","0.328"],["61750.80","0.030"],["61750.90","1.636"],["61786.30","0.002"],["61788.40","32.951"],["61826.00","2.142"],["61828.00","1.302"],["61830.50","0.008"],["61830.90","0.001"],["61831.40","0.331"],["61833.20","1.855"],["61834.40","0.122"],["61836.70","0.569"],["61840.50","2.140"],["61843.00","0.127"],["61854.10","16.252"]],"a":[["61854.20","4.421"],["61854.90","0.040"],["61860.40","0.322"],["61862.60","0.484"],["61862.80","0.346"],["61864.40","0.968"],["61865.30","0.327"],["61865.50","0.014"],["61865.60","0.004"],["61866.50","0.570"],["61866.60","3.940"],["61867.00","0.352"],["61868.70","0.096"],["61871.10","0.085"],["61871.60","0.007"],["61872.80","0.128"],["61877.80","0.082"],["61897.50","0.296"],["61926.90","0.118"],["62029.10","0.819"],["62029.20","0.004"],["62427.60","2.077"],["62472.70","1.688"],["63091.20","0.092"]],"st":1}}
{"schema_version":"1.3.0","event_id":"00910be0-5963-41ee-a633-d4e7aaa571be","event_type":"raw.depth_update","source":"binance_market_data_recorder","venue":"binance_usdm","market_type":"perpetual_futures","symbol":"BTCUSDT","event_time_ms":1783517076188,"received_time_ms":1783517076183,"trace_id":"c11e3274-0e42-480f-b958-69911fff080f","first_update_id":10999771485290,"final_update_id":10999771492323,"previous_final_update_id":10999771485140,"bids":[{"price":"11354.10","quantity":"0.068"},{"price":"11554.10","quantity":"1.568"},{"price":"11654.10","quantity":"1.632"},{"price":"11754.10","quantity":"1.632"},{"price":"55668.60","quantity":"0.002"},{"price":"59379.90","quantity":"0.003"},{"price":"61050.00","quantity":"4.118"},{"price":"61118.00","quantity":"4.934"},{"price":"61235.60","quantity":"0.328"},{"price":"61237.90","quantity":"58.034"},{"price":"61379.10","quantity":"48.931"},{"price":"61489.80","quantity":"41.612"},{"price":"61491.40","quantity":"6.509"},{"price":"61582.20","quantity":"35.224"},{"price":"61583.10","quantity":"5.691"},{"price":"61600.80","quantity":"0.010"},{"price":"61621.20","quantity":"1.264"},{"price":"61826.80","quantity":"0.586"},{"price":"61828.00","quantity":"0.720"},{"price":"61828.10","quantity":"0.008"},{"price":"61832.20","quantity":"0.970"},{"price":"61833.20","quantity":"0.887"},{"price":"61835.20","quantity":"0.568"},{"price":"61836.70","quantity":"0.003"},{"price":"61839.30","quantity":"0.634"},{"price":"61841.30","quantity":"0.185"}],"asks":[{"price":"61854.20","quantity":"4.703"},{"price":"61859.60","quantity":"1.632"},{"price":"61860.40","quantity":"0.450"},{"price":"61864.30","quantity":"0.568"},{"price":"61866.40","quantity":"0.003"},{"price":"61866.50","quantity":"0.004"},{"price":"61868.70","quantity":"0.081"},{"price":"61868.80","quantity":"0.040"},{"price":"61869.80","quantity":"0.138"},{"price":"61873.60","quantity":"0.019"},{"price":"61897.50","quantity":"0.168"},{"price":"61926.90","quantity":"0.021"},{"price":"62127.70","quantity":"5.529"},{"price":"62127.80","quantity":"35.947"},{"price":"62128.80","quantity":"0.000"},{"price":"62220.50","quantity":"6.526"},{"price":"62221.00","quantity":"41.602"},{"price":"62333.00","quantity":"52.722"},{"price":"62417.40","quantity":"0.948"},{"price":"62472.70","quantity":"1.688"},{"price":"62476.30","quantity":"59.752"},{"price":"62627.40","quantity":"1.385"},{"price":"89523.20","quantity":"0.996"}],"raw":{"e":"depthUpdate","E":1783517076188,"T":1783517076185,"s":"BTCUSDT","ps":"BTCUSDT","U":10999771485290,"u":10999771492323,"pu":10999771485140,"b":[["11354.10","0.068"],["11554.10","1.568"],["11654.10","1.632"],["11754.10","1.632"],["55668.60","0.002"],["59379.90","0.003"],["61050.00","4.118"],["61118.00","4.934"],["61235.60","0.328"],["61237.90","58.034"],["61379.10","48.931"],["61489.80","41.612"],["61491.40","6.509"],["61582.20","35.224"],["61583.10","5.691"],["61600.80","0.010"],["61621.20","1.264"],["61826.80","0.586"],["61828.00","0.720"],["61828.10","0.008"],["61832.20","0.970"],["61833.20","0.887"],["61835.20","0.568"],["61836.70","0.003"],["61839.30","0.634"],["61841.30","0.185"]],"a":[["61854.20","4.703"],["61859.60","1.632"],["61860.40","0.450"],["61864.30","0.568"],["61866.40","0.003"],["61866.50","0.004"],["61868.70","0.081"],["61868.80","0.040"],["61869.80","0.138"],["61873.60","0.019"],["61897.50","0.168"],["61926.90","0.021"],["62127.70","5.529"],["62127.80","35.947"],["62128.80","0.000"],["62220.50","6.526"],["62221.00","41.602"],["62333.00","52.722"],["62417.40","0.948"],["62472.70","1.688"],["62476.30","59.752"],["62627.40","1.385"],["89523.20","0.996"]],"st":1}}
{"schema_version":"1.3.0","event_id":"adcc7b33-5a7c-4a75-9852-eaeed2b5dc50","event_type":"raw.depth_update","source":"binance_market_data_recorder","venue":"binance_usdm","market_type":"perpetual_futures","symbol":"BTCUSDT","event_time_ms":1783517076290,"received_time_ms":1783517076286,"trace_id":"71b67009-7b4e-456c-a5bc-14c2d49a240e","first_update_id":10999771492648,"final_update_id":10999771502026,"previous_final_update_id":10999771492323,"bids":[{"price":"1000.00","quantity":"207.692"},{"price":"11354.10","quantity":"0.000"},{"price":"11554.10","quantity":"1.840"},{"price":"11654.10","quantity":"1.445"},{"price":"11754.10","quantity":"1.615"},{"price":"55668.60","quantity":"0.002"},{"price":"58759.60","quantity":"0.000"},{"price":"59379.90","quantity":"0.000"},{"price":"60847.50","quantity":"1.642"},{"price":"61015.00","quantity":"0.475"},{"price":"61235.60","quantity":"0.328"},{"price":"61544.80","quantity":"0.039"},{"price":"61812.30","quantity":"0.118"},{"price":"61813.40","quantity":"0.062"},{"price":"61817.40","quantity":"0.018"},{"price":"61823.70","quantity":"1.294"},{"price":"61825.50","quantity":"0.097"},{"price":"61838.60","quantity":"0.128"},{"price":"61841.70","quantity":"0.424"}],"asks":[{"price":"61866.60","quantity":"3.974"},{"price":"61872.80","quantity":"0.000"},{"price":"61926.90","quantity":"0.021"},{"price":"62309.20","quantity":"0.001"},{"price":"62441.80","quantity":"2.879"},{"price":"62472.70","quantity":"1.688"},{"price":"62663.80","quantity":"76.136"},{"price":"62874.80","quantity":"0.715"},{"price":"89523.20","quantity":"1.002"}],"raw":{"e":"depthUpdate","E":1783517076290,"T":1783517076289,"s":"BTCUSDT","ps":"BTCUSDT","U":10999771492648,"u":10999771502026,"pu":10999771492323,"b":[["1000.00","207.692"],["11354.10","0.000"],["11554.10","1.840"],["11654.10","1.445"],["11754.10","1.615"],["55668.60","0.002"],["58759.60","0.000"],["59379.90","0.000"],["60847.50","1.642"],["61015.00","0.475"],["61235.60","0.328"],["61544.80","0.039"],["61812.30","0.118"],["61813.40","0.062"],["61817.40","0.018"],["61823.70","1.294"],["61825.50","0.097"],["61838.60","0.128"],["61841.70","0.424"]],"a":[["61866.60","3.974"],["61872.80","0.000"],["61926.90","0.021"],["62309.20","0.001"],["62441.80","2.879"],["62472.70","1.688"],["62663.80","76.136"],["62874.80","0.715"],["89523.20","1.002"]],"st":1}}
{"schema_version":"1.3.0","event_id":"19c2f60f-6d18-4eb8-b9a5-e8d6a693bd2b","event_type":"raw.depth_update","source":"binance_market_data_recorder","venue":"binance_usdm","market_type":"perpetual_futures","symbol":"BTCUSDT","event_time_ms":1783517076392,"received_time_ms":1783517076387,"trace_id":"b5ba29cf-ed2f-40cd-99c0-4240a7f9bc51","first_update_id":10999771502098,"final_update_id":10999771508803,"previous_final_update_id":10999771502026,"bids":[{"price":"1000.00","quantity":"207.692"},{"price":"11554.10","quantity":"2.112"},{"price":"11654.10","quantity":"1.309"},{"price":"11754.10","quantity":"1.479"},{"price":"55668.60","quantity":"0.002"},{"price":"59379.90","quantity":"0.003"},{"price":"61054.20","quantity":"78.297"},{"price":"61235.60","quantity":"0.328"},{"price":"61544.80","quantity":"0.039"},{"price":"61582.20","quantity":"70.915"},{"price":"61585.90","quantity":"0.000"},{"price":"61586.00","quantity":"0.060"},{"price":"61812.30","quantity":"0.017"},{"price":"61812.50","quantity":"1.034"},{"price":"61818.40","quantity":"0.012"},{"price":"61825.80","quantity":"0.590"},{"price":"61826.80","quantity":"0.004"},{"price":"61827.90","quantity":"0.002"},{"price":"61829.50","quantity":"1.202"},{"price":"61831.00","quantity":"0.968"},{"price":"61832.20","quantity":"0.002"},{"price":"61834.10","quantity":"2.800"},{"price":"61835.60","quantity":"0.162"},{"price":"61841.80","quantity":"0.090"},{"price":"61852.60","quantity":"0.042"},{"price":"61852.70","quantity":"0.007"},{"price":"61854.10","quantity":"16.203"}],"asks":[{"price":"61854.20","quantity":"4.701"},{"price":"61859.60","quantity":"1.632"},{"price":"61862.10","quantity":"0.971"},{"price":"61863.50","quantity":"0.130"},{"price":"61864.40","quantity":"0.000"},{"price":"61866.70","quantity":"0.845"},{"price":"61872.80","quantity":"0.128"},{"price":"61893.40","quantity":"0.036"},{"price":"61910.10","quantity":"0.246"},{"price":"61917.00","quantity":"0.019"},{"price":"61926.90","quantity":"0.021"},{"price":"62092.80","quantity":"0.033"},{"price":"62127.20","quantity":"35.125"},{"price":"62163.50","quantity":"0.001"},{"price":"62220.90","quantity":"0.864"},{"price":"62332.90","quantity":"4.488"},{"price":"62472.70","quantity":"1.688"},{"price":"62499.90","quantity":"0.500"},{"price":"62728.40","quantity":"0.278"},{"price":"63276.90","quantity":"0.635"},{"price":"65245.50","quantity":"0.066"}],"raw":{"e":"depthUpdate","E":1783517076392,"T":1783517076389,"s":"BTCUSDT","ps":"BTCUSDT","U":10999771502098,"u":10999771508803,"pu":10999771502026,"b":[["1000.00","207.692"],["11554.10","2.112"],["11654.10","1.309"],["11754.10","1.479"],["55668.60","0.002"],["59379.90","0.003"],["61054.20","78.297"],["61235.60","0.328"],["61544.80","0.039"],["61582.20","70.915"],["61585.90","0.000"],["61586.00","0.060"],["61812.30","0.017"],["61812.50","1.034"],["61818.40","0.012"],["61825.80","0.590"],["61826.80","0.004"],["61827.90","0.002"],["61829.50","1.202"],["61831.00","0.968"],["61832.20","0.002"],["61834.10","2.800"],["61835.60","0.162"],["61841.80","0.090"],["61852.60","0.042"],["61852.70","0.007"],["61854.10","16.203"]],"a":[["61854.20","4.701"],["61859.60","1.632"],["61862.10","0.971"],["61863.50","0.130"],["61864.40","0.000"],["61866.70","0.845"],["61872.80","0.128"],["61893.40","0.036"],["61910.10","0.246"],["61917.00","0.019"],["61926.90","0.021"],["62092.80","0.033"],["62127.20","35.125"],["62163.50","0.001"],["62220.90","0.864"],["62332.90","4.488"],["62472.70","1.688"],["62499.90","0.500"],["62728.40","0.278"],["63276.90","0.635"],["65245.50","0.066"]],"st":1}}
{"schema_version":"1.3.0","event_id":"caffb6fd-7a1c-494f-a555-9573ddabd471","event_type":"raw.depth_update","source":"binance_market_data_recorder","venue":"binance_usdm","market_type":"perpetual_futures","symbol":"BTCUSDT","event_time_ms":1783517076494,"received_time_ms":1783517076489,"trace_id":"d8210298-efc6-41d0-b94e-348e5fb0a723","first_update_id":10999771509081,"final_update_id":10999771514548,"previous_final_update_id":10999771508803,"bids":[{"price":"11554.10","quantity":"2.384"},{"price":"11654.10","quantity":"1.190"},{"price":"11754.10","quantity":"1.326"},{"price":"55668.60","quantity":"0.002"},{"price":"60775.10","quantity":"0.034"},{"price":"61033.10","quantity":"2.454"},{"price":"61235.60","quantity":"0.328"},{"price":"61520.00","quantity":"2.919"},{"price":"61600.00","quantity":"56.797"},{"price":"61680.00","quantity":"0.711"},{"price":"61735.90","quantity":"0.100"},{"price":"61760.00","quantity":"0.920"},{"price":"61812.30","quantity":"0.118"},{"price":"61840.00","quantity":"0.058"},{"price":"61854.10","quantity":"16.202"}],"asks":[{"price":"61862.10","quantity":"0.003"},{"price":"61863.10","quantity":"0.968"},{"price":"61879.10","quantity":"0.786"},{"price":"61920.00","quantity":"1.172"},{"price":"61926.90","quantity":"0.021"},{"price":"62000.00","quantity":"13.023"},{"price":"62080.00","quantity":"0.289"},{"price":"62160.00","quantity":"0.284"},{"price":"62240.00","quantity":"0.279"},{"price":"62308.30","quantity":"0.120"},{"price":"62431.30","quantity":"0.240"},{"price":"62472.70","quantity":"1.688"},{"price":"66412.80","quantity":"0.017"},{"price":"89523.20","quantity":"1.008"}],"raw":{"e":"depthUpdate","E":1783517076494,"T":1783517076493,"s":"BTCUSDT","ps":"BTCUSDT","U":10999771509081,"u":10999771514548,"pu":10999771508803,"b":[["11554.10","2.384"],["11654.10","1.190"],["11754.10","1.326"],["55668.60","0.002"],["60775.10","0.034"],["61033.10","2.454"],["61235.60","0.328"],["61520.00","2.919"],["61600.00","56.797"],["61680.00","0.711"],["61735.90","0.100"],["61760.00","0.920"],["61812.30","0.118"],["61840.00","0.058"],["61854.10","16.202"]],"a":[["61862.10","0.003"],["61863.10","0.968"],["61879.10","0.786"],["61920.00","1.172"],["61926.90","0.021"],["62000.00","13.023"],["62080.00","0.289"],["62160.00","0.284"],["62240.00","0.279"],["62308.30","0.120"],["62431.30","0.240"],["62472.70","1.688"],["66412.80","0.017"],["89523.20","1.008"]],"st":1}}
{"schema_version":"1.3.0","event_id":"4a8d56a9-469f-4c36-8988-af60a87c3e66","event_type":"raw.depth_update","source":"binance_market_data_recorder","venue":"binance_usdm","market_type":"perpetual_futures","symbol":"BTCUSDT","event_time_ms":1783517076596,"received_time_ms":1783517076591,"trace_id":"eec7780d-00e5-4080-92f5-38316d51fbd0","first_update_id":10999771514619,"final_update_id":10999771520683,"previous_final_update_id":10999771514548,"bids":[{"price":"1000.00","quantity":"207.692"},{"price":"11554.10","quantity":"2.656"},{"price":"11654.10","quantity":"1.054"},{"price":"11754.10","quantity":"1.190"},{"price":"55668.60","quantity":"0.002"},{"price":"59379.90","quantity":"0.000"},{"price":"60654.40","quantity":"0.000"},{"price":"60708.10","quantity":"0.824"},{"price":"60905.30","quantity":"0.007"},{"price":"60961.90","quantity":"0.000"},{"price":"61088.80","quantity":"0.436"},{"price":"61235.60","quantity":"0.328"},{"price":"61544.80","quantity":"0.039"},{"price":"61723.70","quantity":"0.000"},{"price":"61854.10","quantity":"16.202"}],"asks":[{"price":"61863.50","quantity":"0.002"},{"price":"61879.10","quantity":"0.166"},{"price":"61926.90","quantity":"0.118"},{"price":"61985.20","quantity":"1.071"},{"price":"62146.10","quantity":"0.180"},{"price":"62146.90","quantity":"0.805"},{"price":"62472.70","quantity":"1.688"},{"price":"62683.50","quantity":"0.001"},{"price":"63091.20","quantity":"0.089"}],"raw":{"e":"depthUpdate","E":1783517076596,"T":1783517076593,"s":"BTCUSDT","ps":"BTCUSDT","U":10999771514619,"u":10999771520683,"pu":10999771514548,"b":[["1000.00","207.692"],["11554.10","2.656"],["11654.10","1.054"],["11754.10","1.190"],["55668.60","0.002"],["59379.90","0.000"],["60654.40","0.000"],["60708.10","0.824"],["60905.30","0.007"],["60961.90","0.000"],["61088.80","0.436"],["61235.60","0.328"],["61544.80","0.039"],["61723.70","0.000"],["61854.10","16.202"]],"a":[["61863.50","0.002"],["61879.10","0.166"],["61926.90","0.118"],["61985.20","1.071"],["62146.10","0.180"],["62146.90","0.805"],["62472.70","1.688"],["62683.50","0.001"],["63091.20","0.089"]],"st":1}}
{"schema_version":"1.3.0","event_id":"3c32491a-297c-471d-8ae0-ced6aede4d3f","event_type":"raw.depth_update","source":"binance_market_data_recorder","venue":"binance_usdm","market_type":"perpetual_futures","symbol":"BTCUSDT","event_time_ms":1783517076698,"received_time_ms":1783517076693,"trace_id":"ea02b25c-c918-463d-9900-5a3842f6ccaf","first_update_id":10999771520830,"final_update_id":10999771525871,"previous_final_update_id":10999771520683,"bids":[{"price":"1000.00","quantity":"207.692"},{"price":"11454.10","quantity":"0.096"},{"price":"11554.10","quantity":"2.736"},{"price":"11654.10","quantity":"1.031"},{"price":"11754.10","quantity":"1.037"},{"price":"49483.00","quantity":"0.000"},{"price":"55668.60","quantity":"0.002"},{"price":"58759.70","quantity":"0.003"},{"price":"59379.90","quantity":"0.003"},{"price":"60617.10","quantity":"0.027"},{"price":"60933.60","quantity":"2.274"},{"price":"60988.10","quantity":"2.457"},{"price":"61076.90","quantity":"2.323"},{"price":"61080.90","quantity":"4.183"},{"price":"61235.60","quantity":"0.328"},{"price":"61520.00","quantity":"3.097"},{"price":"61600.00","quantity":"56.975"},{"price":"61680.00","quantity":"0.889"},{"price":"61723.70","quantity":"0.291"},{"price":"61750.90","quantity":"1.633"},{"price":"61751.10","quantity":"0.004"},{"price":"61760.00","quantity":"1.098"},{"price":"61789.00","quantity":"6.193"},{"price":"61812.30","quantity":"0.118"},{"price":"61812.60","quantity":"0.134"},{"price":"61818.40","quantity":"0.004"},{"price":"61825.50","quantity":"0.797"},{"price":"61839.30","quantity":"0.004"},{"price":"61840.00","quantity":"0.236"},{"price":"61841.80","quantity":"0.009"},{"price":"61854.10","quantity":"16.217"}],"asks":[{"price":"61854.20","quantity":"5.022"},{"price":"61860.40","quantity":"0.450"},{"price":"61862.50","quantity":"0.001"},{"price":"61893.40","quantity":"0.243"},{"price":"61909.40","quantity":"0.367"},{"price":"61920.00","quantity":"1.350"},{"price":"61926.90","quantity":"0.021"},{"price":"61985.10","quantity":"0.726"},{"price":"62000.00","quantity":"13.201"},{"price":"62029.20","quantity":"0.001"},{"price":"62029.40","quantity":"0.022"},{"price":"62080.00","quantity":"0.467"},{"price":"62160.00","quantity":"0.462"},{"price":"62162.10","quantity":"0.522"},{"price":"62163.50","quantity":"2.409"},{"price":"62240.00","quantity":"0.457"},{"price":"62472.70","quantity":"1.688"},{"price":"62662.90","quantity":"0.799"},{"price":"62946.40","quantity":"0.066"},{"price":"67826.30","quantity":"0.016"},{"price":"89523.20","quantity":"1.014"}],"raw":{"e":"depthUpdate","E":1783517076698,"T":1783517076697,"s":"BTCUSDT","ps":"BTCUSDT","U":10999771520830,"u":10999771525871,"pu":10999771520683,"b":[["1000.00","207.692"],["11454.10","0.096"],["11554.10","2.736"],["11654.10","1.031"],["11754.10","1.037"],["49483.00","0.000"],["55668.60","0.002"],["58759.70","0.003"],["59379.90","0.003"],["60617.10","0.027"],["60933.60","2.274"],["60988.10","2.457"],["61076.90","2.323"],["61080.90","4.183"],["61235.60","0.328"],["61520.00","3.097"],["61600.00","56.975"],["61680.00","0.889"],["61723.70","0.291"],["61750.90","1.633"],["61751.10","0.004"],["61760.00","1.098"],["61789.00","6.193"],["61812.30","0.118"],["61812.60","0.134"],["61818.40","0.004"],["61825.50","0.797"],["61839.30","0.004"],["61840.00","0.236"],["61841.80","0.009"],["61854.10","16.217"]],"a":[["61854.20","5.022"],["61860.40","0.450"],["61862.50","0.001"],["61893.40","0.243"],["61909.40","0.367"],["61920.00","1.350"],["61926.90","0.021"],["61985.10","0.726"],["62000.00","13.201"],["62029.20","0.001"],["62029.40","0.022"],["62080.00","0.467"],["62160.00","0.462"],["62162.10","0.522"],["62163.50","2.409"],["62240.00","0.457"],["62472.70","1.688"],["62662.90","0.799"],["62946.40","0.066"],["67826.30","0.016"],["89523.20","1.014"]],"st":1}}
{"schema_version":"1.3.0","event_id":"079aed43-5690-4cce-9e67-375d11e96d4a","event_type":"raw.depth_update","source":"binance_market_data_recorder","venue":"binance_usdm","market_type":"perpetual_futures","symbol":"BTCUSDT","event_time_ms":1783517076800,"received_time_ms":1783517076797,"trace_id":"9da05d2e-3c1b-4c6c-86ac-58921d7a99ee","first_update_id":10999771525948,"final_update_id":10999771531713,"previous_final_update_id":10999771525871,"bids":[{"price":"11454.10","quantity":"0.240"},{"price":"11554.10","quantity":"2.720"},{"price":"11654.10","quantity":"1.039"},{"price":"11754.10","quantity":"0.901"},{"price":"45000.00","quantity":"155.615"},{"price":"49483.30","quantity":"0.000"},{"price":"55668.60","quantity":"0.002"},{"price":"58761.40","quantity":"0.020"},{"price":"59379.90","quantity":"0.000"},{"price":"60617.10","quantity":"0.030"},{"price":"60654.60","quantity":"0.156"},{"price":"60833.30","quantity":"0.907"},{"price":"61050.00","quantity":"4.445"},{"price":"61075.00","quantity":"0.851"},{"price":"61235.60","quantity":"0.328"},{"price":"61439.80","quantity":"0.024"},{"price":"61639.80","quantity":"0.000"},{"price":"61822.50","quantity":"0.023"},{"price":"61829.60","quantity":"0.039"}],"asks":[{"price":"61864.20","quantity":"0.009"},{"price":"61864.30","quantity":"0.002"},{"price":"61866.50","quantity":"0.570"},{"price":"61872.80","quantity":"0.000"},{"price":"61893.50","quantity":"0.373"},{"price":"61926.90","quantity":"0.118"},{"price":"62436.00","quantity":"0.005"}],"raw":{"e":"depthUpdate","E":1783517076800,"T":1783517076798,"s":"BTCUSDT","ps":"BTCUSDT","U":10999771525948,"u":10999771531713,"pu":10999771525871,"b":[["11454.10","0.240"],["11554.10","2.720"],["11654.10","1.039"],["11754.10","0.901"],["45000.00","155.615"],["49483.30","0.000"],["55668.60","0.002"],["58761.40","0.020"],["59379.90","0.000"],["60617.10","0.030"],["60654.60","0.156"],["60833.30","0.907"],["61050.00","4.445"],["61075.00","0.851"],["61235.60","0.328"],["61439.80","0.024"],["61639.80","0.000"],["61822.50","0.023"],["61829.60","0.039"]],"a":[["61864.20","0.009"],["61864.30","0.002"],["61866.50","0.570"],["61872.80","0.000"],["61893.50","0.373"],["61926.90","0.118"],["62436.00","0.005"]],"st":1}}
{"schema_version":"1.3.0","event_id":"9d7045fe-36e3-4cbe-a23e-cb06fb3729ff","event_type":"raw.depth_update","source":"binance_market_data_recorder","venue":"binance_usdm","market_type":"perpetual_futures","symbol":"BTCUSDT","event_time_ms":1783517076902,"received_time_ms":1783517076897,"trace_id":"1d28541d-060b-462f-94ec-280b40f229a6","first_update_id":10999771531776,"final_update_id":10999771536925,"previous_final_update_id":10999771531713,"bids":[{"price":"1000.00","quantity":"207.692"},{"price":"11454.10","quantity":"0.368"},{"price":"11554.10","quantity":"2.736"},{"price":"11654.10","quantity":"1.048"},{"price":"11754.10","quantity":"0.748"},{"price":"49483.00","quantity":"0.000"},{"price":"55668.60","quantity":"0.002"},{"price":"58761.30","quantity":"0.002"},{"price":"60957.20","quantity":"0.986"},{"price":"61235.60","quantity":"0.330"},{"price":"61544.80","quantity":"0.029"},{"price":"61838.60","quantity":"0.128"},{"price":"61844.40","quantity":"0.189"},{"price":"61854.10","quantity":"16.216"}],"asks":[{"price":"61863.80","quantity":"0.567"},{"price":"61866.50","quantity":"0.004"},{"price":"61893.50","quantity":"0.580"},{"price":"61897.50","quantity":"0.323"},{"price":"61919.10","quantity":"0.031"},{"price":"61926.90","quantity":"0.021"},{"price":"62411.70","quantity":"0.169"},{"price":"62472.70","quantity":"1.688"},{"price":"62683.20","quantity":"0.000"},{"price":"62721.60","quantity":"15.943"},{"price":"89523.20","quantity":"1.020"}],"raw":{"e":"depthUpdate","E":1783517076902,"T":1783517076901,"s":"BTCUSDT","ps":"BTCUSDT","U":10999771531776,"u":10999771536925,"pu":10999771531713,"b":[["1000.00","207.692"],["11454.10","0.368"],["11554.10","2.736"],["11654.10","1.048"],["11754.10","0.748"],["49483.00","0.000"],["55668.60","0.002"],["58761.30","0.002"],["60957.20","0.986"],["61235.60","0.330"],["61544.80","0.029"],["61838.60","0.128"],["61844.40","0.189"],["61854.10","16.216"]],"a":[["61863.80","0.567"],["61866.50","0.004"],["61893.50","0.580"],["61897.50","0.323"],["61919.10","0.031"],["61926.90","0.021"],["62411.70","0.169"],["62472.70","1.688"],["62683.20","0.000"],["62721.60","15.943"],["89523.20","1.020"]],"st":1}}
{"schema_version":"1.3.0","event_id":"a242a732-7ca7-4bc6-bae4-07d259226932","event_type":"raw.depth_update","source":"binance_market_data_recorder","venue":"binance_usdm","market_type":"perpetual_futures","symbol":"BTCUSDT","event_time_ms":1783517077004,"received_time_ms":1783517076999,"trace_id":"14247740-8521-42e8-9bfb-a4f5a0cbdc91","first_update_id":10999771536947,"final_update_id":10999771542684,"previous_final_update_id":10999771536925,"bids":[{"price":"1000.00","quantity":"207.692"},{"price":"11454.10","quantity":"0.544"},{"price":"11554.10","quantity":"2.656"},{"price":"11654.10","quantity":"1.088"},{"price":"11754.10","quantity":"0.612"},{"price":"55668.60","quantity":"0.002"},{"price":"58761.30","quantity":"0.010"},{"price":"59379.90","quantity":"0.003"},{"price":"61235.60","quantity":"0.328"},{"price":"61723.70","quantity":"0.286"},{"price":"61783.30","quantity":"0.002"},{"price":"61805.00","quantity":"2.082"},{"price":"61812.50","quantity":"0.933"},{"price":"61820.40","quantity":"0.741"},{"price":"61840.50","quantity":"2.138"}],"asks":[{"price":"61854.20","quantity":"5.230"},{"price":"61859.50","quantity":"0.019"},{"price":"61860.40","quantity":"0.454"},{"price":"61861.60","quantity":"0.766"},{"price":"61861.70","quantity":"0.386"},{"price":"61861.80","quantity":"0.000"},{"price":"61862.60","quantity":"0.439"},{"price":"61866.60","quantity":"3.978"},{"price":"61867.00","quantity":"0.284"},{"price":"61868.70","quantity":"0.096"},{"price":"61870.60","quantity":"0.030"},{"price":"61871.60","quantity":"0.005"},{"price":"61872.80","quantity":"0.132"},{"price":"61873.20","quantity":"0.299"},{"price":"61882.90","quantity":"0.947"},{"price":"61883.00","quantity":"0.100"},{"price":"61884.30","quantity":"0.495"},{"price":"61897.90","quantity":"0.153"},{"price":"61899.70","quantity":"0.003"},{"price":"61909.50","quantity":"2.795"},{"price":"61909.90","quantity":"0.221"},{"price":"61921.40","quantity":"0.016"},{"price":"61926.90","quantity":"0.118"},{"price":"61985.10","quantity":"0.726"},{"price":"62441.80","quantity":"3.518"},{"price":"62472.70","quantity":"1.678"},{"price":"62522.50","quantity":"0.003"},{"price":"62677.60","quantity":"0.279"},{"price":"62685.00","quantity":"0.797"},{"price":"62936.60","quantity":"3.813"}],"raw":{"e":"depthUpdate","E":1783517077004,"T":1783517077001,"s":"BTCUSDT","ps":"BTCUSDT","U":10999771536947,"u":10999771542684,"pu":10999771536925,"b":[["1000.00","207.692"],["11454.10","0.544"],["11554.10","2.656"],["11654.10","1.088"],["11754.10","0.612"],["55668.60","0.002"],["58761.30","0.010"],["59379.90","0.003"],["61235.60","0.328"],["61723.70","0.286"],["61783.30","0.002"],["61805.00","2.082"],["61812.50","0.933"],["61820.40","0.741"],["61840.50","2.138"]],"a":[["61854.20","5.230"],["61859.50","0.019"],["61860.40","0.454"],["61861.60","0.766"],["61861.70","0.386"],["61861.80","0.000"],["61862.60","0.439"],["61866.60","3.978"],["61867.00","0.284"],["61868.70","0.096"],["61870.60","0.030"],["61871.60","0.005"],["61872.80","0.132"],["61873.20","0.299"],["61882.90","0.947"],["61883.00","0.100"],["61884.30","0.495"],["61897.90","0.153"],["61899.70","0.003"],["61909.50","2.795"],["61909.90","0.221"],["61921.40","0.016"],["61926.90","0.118"],["61985.10","0.726"],["62441.80","3.518"],["62472.70","1.678"],["62522.50","0.003"],["62677.60","0.279"],["62685.00","0.797"],["62936.60","3.813"]],"st":1}}
{"schema_version":"1.3.0","event_id":"edaf3875-3749-432f-86f4-fc79167e0578","event_type":"raw.depth_update","source":"binance_market_data_recorder","venue":"binance_usdm","market_type":"perpetual_futures","symbol":"BTCUSDT","event_time_ms":1783517077106,"received_time_ms":1783517077101,"trace_id":"2ea466a7-e7f6-46c6-a02b-72495f7a04f7","first_update_id":10999771542865,"final_update_id":10999771548293,"previous_final_update_id":10999771542684,"bids":[{"price":"11454.10","quantity":"0.816"},{"price":"11554.10","quantity":"2.384"},{"price":"11654.10","quantity":"1.241"},{"price":"11754.10","quantity":"0.459"},{"price":"55668.60","quantity":"0.002"},{"price":"59379.90","quantity":"0.000"},{"price":"61045.00","quantity":"0.053"},{"price":"61235.50","quantity":"0.442"},{"price":"61235.60","quantity":"0.328"},{"price":"61293.60","quantity":"0.556"},{"price":"61300.00","quantity":"79.030"},{"price":"61752.40","quantity":"0.012"},{"price":"61754.80","quantity":"1.367"},{"price":"61788.40","quantity":"0.002"},{"price":"61789.00","quantity":"1.484"},{"price":"61790.50","quantity":"34.063"},{"price":"61810.00","quantity":"1.962"},{"price":"61828.80","quantity":"2.758"},{"price":"61840.50","quantity":"2.140"},{"price":"61843.00","quantity":"0.127"}],"asks":[{"price":"61854.20","quantity":"5.231"},{"price":"61860.40","quantity":"0.450"},{"price":"61865.30","quantity":"0.327"},{"price":"61866.60","quantity":"3.974"},{"price":"61868.70","quantity":"0.081"},{"price":"61871.60","quantity":"0.007"},{"price":"61872.80","quantity":"0.128"},{"price":"61920.50","quantity":"25.187"},{"price":"61924.70","quantity":"0.000"},{"price":"61926.90","quantity":"0.118"},{"price":"61950.60","quantity":"1.628"},{"price":"61952.40","quantity":"0.000"},{"price":"62092.80","quantity":"0.015"},{"price":"62472.70","quantity":"1.678"},{"price":"62751.10","quantity":"2.069"},{"price":"63091.20","quantity":"0.089"},{"price":"89523.20","quantity":"1.026"}],"raw":{"e":"depthUpdate","E":1783517077106,"T":1783517077105,"s":"BTCUSDT","ps":"BTCUSDT","U":10999771542865,"u":10999771548293,"pu":10999771542684,"b":[["11454.10","0.816"],["11554.10","2.384"],["11654.10","1.241"],["11754.10","0.459"],["55668.60","0.002"],["59379.90","0.000"],["61045.00","0.053"],["61235.50","0.442"],["61235.60","0.328"],["61293.60","0.556"],["61300.00","79.030"],["61752.40","0.012"],["61754.80","1.367"],["61788.40","0.002"],["61789.00","1.484"],["61790.50","34.063"],["61810.00","1.962"],["61828.80","2.758"],["61840.50","2.140"],["61843.00","0.127"]],"a":[["61854.20","5.231"],["61860.40","0.450"],["61865.30","0.327"],["61866.60","3.974"],["61868.70","0.081"],["61871.60","0.007"],["61872.80","0.128"],["61920.50","25.187"],["61924.70","0.000"],["61926.90","0.118"],["61950.60","1.628"],["61952.40","0.000"],["62092.80","0.015"],["62472.70","1.678"],["62751.10","2.069"],["63091.20","0.089"],["89523.20","1.026"]],"st":1}}
{"schema_version":"1.3.0","event_id":"1401dab9-ce17-4fc0-99e9-032cddababd2","event_type":"raw.depth_update","source":"binance_market_data_recorder","venue":"binance_usdm","market_type":"perpetual_futures","symbol":"BTCUSDT","event_time_ms":1783517077208,"received_time_ms":1783517077205,"trace_id":"9f4957ab-ae6f-4cd3-8dea-941d47c035c2","first_update_id":10999771548382,"final_update_id":10999771555934,"previous_final_update_id":10999771548293,"bids":[{"price":"1000.00","quantity":"207.692"},{"price":"11454.10","quantity":"1.088"},{"price":"11554.10","quantity":"2.112"},{"price":"11654.10","quantity":"1.377"},{"price":"11754.10","quantity":"0.323"},{"price":"55668.60","quantity":"0.002"},{"price":"59379.90","quantity":"0.003"},{"price":"61005.20","quantity":"0.575"},{"price":"61059.50","quantity":"9.896"},{"price":"61088.10","quantity":"20.325"},{"price":"61235.60","quantity":"0.328"},{"price":"61544.80","quantity":"0.039"},{"price":"61777.90","quantity":"32.959"},{"price":"61784.50","quantity":"8.000"},{"price":"61790.50","quantity":"1.114"},{"price":"61806.10","quantity":"4.539"},{"price":"61812.30","quantity":"0.118"},{"price":"61812.50","quantity":"1.034"},{"price":"61821.60","quantity":"0.797"},{"price":"61828.80","quantity":"2.138"},{"price":"61841.70","quantity":"0.390"},{"price":"61853.80","quantity":"0.003"},{"price":"61854.00","quantity":"0.008"},{"price":"61854.10","quantity":"16.165"}],"asks":[{"price":"61854.20","quantity":"5.483"},{"price":"61854.90","quantity":"0.045"},{"price":"61858.10","quantity":"0.089"},{"price":"61859.50","quantity":"0.145"},{"price":"61860.40","quantity":"0.724"},{"price":"61870.20","quantity":"0.077"},{"price":"61882.30","quantity":"0.791"},{"price":"61897.80","quantity":"4.511"},{"price":"61909.90","quantity":"0.120"},{"price":"61919.40","quantity":"8.311"},{"price":"61920.50","quantity":"0.000"},{"price":"61924.70","quantity":"25.232"},{"price":"61926.80","quantity":"0.891"},{"price":"61926.90","quantity":"0.118"},{"price":"62410.90","quantity":"0.720"},{"price":"62472.70","quantity":"1.678"},{"price":"62528.40","quantity":"0.719"},{"price":"62679.30","quantity":"0.280"}],"raw":{"e":"depthUpdate","E":1783517077208,"T":1783517077206,"s":"BTCUSDT","ps":"BTCUSDT","U":10999771548382,"u":10999771555934,"pu":10999771548293,"b":[["1000.00","207.692"],["11454.10","1.088"],["11554.10","2.112"],["11654.10","1.377"],["11754.10","0.323"],["55668.60","0.002"],["59379.90","0.003"],["61005.20","0.575"],["61059.50","9.896"],["61088.10","20.325"],["61235.60","0.328"],["61544.80","0.039"],["61777.90","32.959"],["61784.50","8.000"],["61790.50","1.114"],["61806.10","4.539"],["61812.30","0.118"],["61812.50","1.034"],["61821.60","0.797"],["61828.80","2.138"],["61841.70","0.390"],["61853.80","0.003"],["61854.00","0.008"],["61854.10","16.165"]],"a":[["61854.20","5.483"],["61854.90","0.045"],["61858.10","0.089"],["61859.50","0.145"],["61860.40","0.724"],["61870.20","0.077"],["61882.30","0.791"],["61897.80","4.511"],["61909.90","0.120"],["61919.40","8.311"],["61920.50","0.000"],["61924.70","25.232"],["61926.80","0.891"],["61926.90","0.118"],["62410.90","0.720"],["62472.70","1.678"],["62528.40","0.719"],["62679.30","0.280"]],"st":1}}
{"schema_version":"1.3.0","event_id":"337ab646-accf-4282-ae46-f4cc9b5ee9aa","event_type":"raw.depth_update","source":"binance_market_data_recorder","venue":"binance_usdm","market_type":"perpetual_futures","symbol":"BTCUSDT","event_time_ms":1783517077310,"received_time_ms":1783517077306,"trace_id":"353dc3c3-aff0-475a-9ad4-89b2ae50c903","first_update_id":10999771556083,"final_update_id":10999771563613,"previous_final_update_id":10999771555934,"bids":[{"price":"1000.00","quantity":"207.692"},{"price":"11454.10","quantity":"1.360"},{"price":"11554.10","quantity":"1.840"},{"price":"11654.10","quantity":"1.530"},{"price":"11754.10","quantity":"0.170"},{"price":"55668.60","quantity":"0.002"},{"price":"58759.60","quantity":"0.002"},{"price":"59379.90","quantity":"0.000"},{"price":"61049.90","quantity":"0.327"},{"price":"61235.60","quantity":"0.328"},{"price":"61400.40","quantity":"0.000"},{"price":"61585.90","quantity":"0.008"},{"price":"61586.00","quantity":"0.052"},{"price":"61751.10","quantity":"0.001"},{"price":"61751.20","quantity":"0.061"},{"price":"61753.60","quantity":"11.162"},{"price":"61777.90","quantity":"0.146"},{"price":"61788.40","quantity":"32.815"},{"price":"61852.70","quantity":"0.000"},{"price":"61853.90","quantity":"0.251"},{"price":"61854.10","quantity":"16.173"}],"asks":[{"price":"61854.20","quantity":"5.456"},{"price":"61859.50","quantity":"0.145"},{"price":"61860.40","quantity":"0.724"},{"price":"61873.60","quantity":"0.017"},{"price":"61920.50","quantity":"25.232"},{"price":"61924.70","quantity":"0.000"},{"price":"61926.90","quantity":"0.118"},{"price":"61950.60","quantity":"3.064"},{"price":"61951.80","quantity":"11.000"},{"price":"62029.40","quantity":"0.019"},{"price":"62029.50","quantity":"0.003"},{"price":"62472.70","quantity":"1.678"},{"price":"62478.70","quantity":"0.000"},{"price":"62494.40","quantity":"4.546"},{"price":"62517.30","quantity":"7.428"},{"price":"62627.20","quantity":"0.240"},{"price":"63436.00","quantity":"0.000"},{"price":"89523.20","quantity":"1.032"}],"raw":{"e":"depthUpdate","E":1783517077310,"T":1783517077309,"s":"BTCUSDT","ps":"BTCUSDT","U":10999771556083,"u":10999771563613,"pu":10999771555934,"b":[["1000.00","207.692"],["11454.10","1.360"],["11554.10","1.840"],["11654.10","1.530"],["11754.10","0.170"],["55668.60","0.002"],["58759.60","0.002"],["59379.90","0.000"],["61049.90","0.327"],["61235.60","0.328"],["61400.40","0.000"],["61585.90","0.008"],["61586.00","0.052"],["61751.10","0.001"],["61751.20","0.061"],["61753.60","11.162"],["61777.90","0.146"],["61788.40","32.815"],["61852.70","0.000"],["61853.90","0.251"],["61854.10","16.173"]],"a":[["61854.20","5.456"],["61859.50","0.145"],["61860.40","0.724"],["61873.60","0.017"],["61920.50","25.232"],["61924.70","0.000"],["61926.90","0.118"],["61950.60","3.064"],["61951.80","11.000"],["62029.40","0.019"],["62029.50","0.003"],["62472.70","1.678"],["62478.70","0.000"],["62494.40","4.546"],["62517.30","7.428"],["62627.20","0.240"],["63436.00","0.000"],["89523.20","1.032"]],"st":1}}
