{"schema_version":"1.3.0","event_id":"aefe8995-8dc5-44d4-8acd-abbea451b1a3","event_type":"raw.depth_update","source":"binance_market_data_recorder","venue":"binance_usdm","market_type":"perpetual_futures","symbol":"BTCUSDT","event_time_ms":1783517067414,"received_time_ms":1783517067408,"trace_id":"e26f3eeb-4252-4e5f-9595-33c96c8c9c23","first_update_id":10999770625642,"final_update_id":10999770634790,"previous_final_update_id":10999770625502,"bids":[{"price":"1000.00","quantity":"207.692"},{"price":"11353.70","quantity":"2.128"},{"price":"11452.20","quantity":"0.000"},{"price":"11453.70","quantity":"1.105"},{"price":"11552.20","quantity":"0.595"},{"price":"11753.70","quantity":"0.576"},{"price":"55668.30","quantity":"0.002"},{"price":"59379.50","quantity":"0.004"},{"price":"61130.00","quantity":"1.987"},{"price":"61235.20","quantity":"0.025"},{"price":"61537.60","quantity":"0.348"},{"price":"61814.80","quantity":"0.004"},{"price":"61818.00","quantity":"2.958"},{"price":"61819.90","quantity":"0.301"},{"price":"61822.20","quantity":"1.083"},{"price":"61825.70","quantity":"0.012"},{"price":"61830.00","quantity":"0.974"},{"price":"61831.30","quantity":"2.137"},{"price":"61835.00","quantity":"1.037"},{"price":"61841.80","quantity":"0.166"},{"price":"61841.90","quantity":"0.383"},{"price":"61848.90","quantity":"0.002"},{"price":"61850.20","quantity":"0.051"},{"price":"61850.40","quantity":"0.000"},{"price":"61851.70","quantity":"0.001"},{"price":"61852.30","quantity":"0.002"},{"price":"61853.70","quantity":"2.600"}],"asks":[{"price":"61858.10","quantity":"0.089"},{"price":"61858.30","quantity":"0.013"},{"price":"61861.00","quantity":"0.408"},{"price":"61861.70","quantity":"0.440"},{"price":"61862.00","quantity":"1.131"},{"price":"61862.90","quantity":"0.000"},{"price":"61863.10","quantity":"0.582"},{"price":"61865.60","quantity":"0.004"},{"price":"61880.50","quantity":"0.198"},{"price":"62472.30","quantity":"0.000"},{"price":"62678.00","quantity":"1.910"},{"price":"62691.10","quantity":"0.796"},{"price":"62754.30","quantity":"0.796"}],"raw":{"e":"depthUpdate","E":1783517067414,"T":1783517067413,"s":"BTCUSDT","ps":"BTCUSDT","U":10999770625642,"u":10999770634790,"pu":10999770625502,"b":[["1000.00","207.692"],["11353.70","2.128"],["11452.20","0.000"],["11453.70","1.105"],["11552.20","0.595"],["11753.70","0.576"],["55668.30","0.002"],["59379.50","0.004"],["61130.00","1.987"],["61235.20","0.025"],["61537.60","0.348"],["61814.80","0.004"],["61818.00","2.958"],["61819.90","0.301"],["61822.20","1.083"],["61825.70","0.012"],["61830.00","0.974"],["61831.30","2.137"],["61835.00","1.037"],["61841.80","0.166"],["61841.90","0.383"],["61848.90","0.002"],["61850.20","0.051"],["61850.40","0.000"],["61851.70","0.001"],["61852.30","0.002"],["61853.70","2.600"]],"a":[["61858.10","0.089"],["61858.30","0.013"],["61861.00","0.408"],["61861.70","0.440"],["61862.00","1.131"],["61862.90","0.000"],["61863.10","0.582"],["61865.60","0.004"],["61880.50","0.198"],["62472.30","0.000"],["62678.00","1.910"],["62691.10","0.796"],["62754.30","0.796"]],"st":1}}
{"schema_version":"1.3.0","event_id":"e114dcb3-5c81-4ca1-b771-ab2be3ccf0d6","event_type":"raw.trade","source":"binance_market_data_recorder","venue":"binance_usdm","market_type":"perpetual_futures","symbol":"BTCUSDT","event_time_ms":1783517067470,"received_time_ms":1783517067465,"trace_id":"fe069266-8a18-4b64-90a2-bb0f74f1e036","trade_id":7881418052,"price":"61853.80","quantity":"0.007","trade_time_ms":1783517067470,"is_buyer_maker":false,"aggressor_side":"buy","raw":{"e":"trade","E":1783517067470,"T":1783517067470,"s":"BTCUSDT","t":7881418052,"p":"61853.80","q":"0.007","X":"MARKET","m":false,"st":1}}
{"schema_version":"1.3.0","event_id":"1ce75518-c69e-4d08-a465-9e4aed3aa735","event_type":"raw.depth_update","source":"binance_market_data_recorder","venue":"binance_usdm","market_type":"perpetual_futures","symbol":"ETHUSDT","event_time_ms":1783517067478,"received_time_ms":1783517067472,"trace_id":"15728fc7-a504-4102-9b11-d09bcfc2125a","first_update_id":10999770631816,"final_update_id":10999770638173,"previous_final_update_id":10999770631686,"bids":[{"price":"200.00","quantity":"7.594"},{"price":"1211.12","quantity":"6.881"},{"price":"1216.13","quantity":"0.352"},{"price":"1216.16","quantity":"0.000"},{"price":"1562.50","quantity":"1.060"},{"price":"1562.51","quantity":"8.880"},{"price":"1650.00","quantity":"1681.405"},{"price":"1666.60","quantity":"1.193"},{"price":"1701.40","quantity":"0.373"},{"price":"1718.04","quantity":"86.464"},{"price":"1733.71","quantity":"84.523"},{"price":"1734.06","quantity":"474.207"},{"price":"1734.12","quantity":"111.586"},{"price":"1734.21","quantity":"18.716"},{"price":"1734.24","quantity":"1.565"},{"price":"1734.37","quantity":"9.825"},{"price":"1734.38","quantity":"13.652"},{"price":"1734.49","quantity":"272.500"},{"price":"1734.62","quantity":"119.370"},{"price":"1734.63","quantity":"1.545"},{"price":"1734.64","quantity":"55.338"},{"price":"1734.75","quantity":"68.153"},{"price":"1734.84","quantity":"272.872"},{"price":"1735.28","quantity":"43.898"},{"price":"1735.32","quantity":"26.988"},{"price":"1735.33","quantity":"16.517"},{"price":"1735.34","quantity":"0.098"},{"price":"1735.35","quantity":"20.776"},{"price":"1735.62","quantity":"10.466"},{"price":"1735.65","quantity":"20.572"},{"price":"1735.73","quantity":"26.154"},{"price":"1735.76","quantity":"15.145"},{"price":"1735.77","quantity":"19.397"},{"price":"1735.87","quantity":"1.139"},{"price":"1735.90","quantity":"4.458"},{"price":"1735.91","quantity":"32.141"},{"price":"1735.92","quantity":"26.525"},{"price":"1735.93","quantity":"0.778"},{"price":"1735.94","quantity":"1.255"},{"price":"1735.97","quantity":"3.186"},{"price":"1735.99","quantity":"0.052"},{"price":"1736.00","quantity":"5.731"},{"price":"1736.06","quantity":"0.026"},{"price":"1736.07","quantity":"0.048"},{"price":"1736.08","quantity":"0.735"},{"price":"1736.09","quantity":"0.942"},{"price":"1736.12","quantity":"18.426"}],"asks":[{"price":"1736.17","quantity":"0.036"},{"price":"1736.18","quantity":"1.769"},{"price":"1736.23","quantity":"22.068"},{"price":"1736.25","quantity":"4.477"},{"price":"1736.33","quantity":"1.712"},{"price":"1736.37","quantity":"10.715"},{"price":"1736.44","quantity":"10.857"},{"price":"1736.63","quantity":"10.262"},{"price":"1736.86","quantity":"0.322"},{"price":"1736.88","quantity":"3.621"},{"price":"1736.89","quantity":"9.594"},{"price":"1736.91","quantity":"86.466"},{"price":"1737.16","quantity":"13.024"},{"price":"1737.26","quantity":"6.884"},{"price":"1737.43","quantity":"11.221"},{"price":"1737.69","quantity":"27.123"},{"price":"1737.88","quantity":"36.568"},{"price":"1738.07","quantity":"32.889"},{"price":"1738.15","quantity":"24.452"},{"price":"1738.20","quantity":"0.256"},{"price":"1738.25","quantity":"410.177"},{"price":"1738.41","quantity":"4.196"},{"price":"1738.71","quantity":"38.346"},{"price":"1738.97","quantity":"181.920"},{"price":"1740.16","quantity":"0.026"},{"price":"1768.81","quantity":"71.211"},{"price":"1773.23","quantity":"63.843"},{"price":"1779.54","quantity":"157.303"},{"price":"2634.85","quantity":"0.001"},{"price":"2634.94","quantity":"0.081"}],"raw":{"e":"depthUpdate","E":1783517067478,"T":1783517067477,"s":"ETHUSDT","ps":"ETHUSDT","U":10999770631816,"u":10999770638173,"pu":10999770631686,"b":[["200.00","7.594"],["1211.12","6.881"],["1216.13","0.352"],["1216.16","0.000"],["1562.50","1.060"],["1562.51","8.880"],["1650.00","1681.405"],["1666.60","1.193"],["1701.40","0.373"],["1718.04","86.464"],["1733.71","84.523"],["1734.06","474.207"],["1734.12","111.586"],["1734.21","18.716"],["1734.24","1.565"],["1734.37","9.825"],["1734.38","13.652"],["1734.49","272.500"],["1734.62","119.370"],["1734.63","1.545"],["1734.64","55.338"],["1734.75","68.153"],["1734.84","272.872"],["1735.28","43.898"],["1735.32","26.988"],["1735.33","16.517"],["1735.34","0.098"],["1735.35","20.776"],["1735.62","10.466"],["1735.65","20.572"],["1735.73","26.154"],["1735.76","15.145"],["1735.77","19.397"],["1735.87","1.139"],["1735.90","4.458"],["1735.91","32.141"],["1735.92","26.525"],["1735.93","0.778"],["1735.94","1.255"],["1735.97","3.186"],["1735.99","0.052"],["1736.00","5.731"],["1736.06","0.026"],["1736.07","0.048"],["1736.08","0.735"],["1736.09","0.942"],["1736.12","18.426"]],"a":[["1736.17","0.036"],["1736.18","1.769"],["1736.23","22.068"],["1736.25","4.477"],["1736.33","1.712"],["1736.37","10.715"],["1736.44","10.857"],["1736.63","10.262"],["1736.86","0.322"],["1736.88","3.621"],["1736.89","9.594"],["1736.91","86.466"],["1737.16","13.024"],["1737.26","6.884"],["1737.43","11.221"],["1737.69","27.123"],["1737.88","36.568"],["1738.07","32.889"],["1738.15","24.452"],["1738.20","0.256"],["1738.25","410.177"],["1738.41","4.196"],["1738.71","38.346"],["1738.97","181.920"],["1740.16","0.026"],["1768.81","71.211"],["1773.23","63.843"],["1779.54","157.303"],["2634.85","0.001"],["2634.94","0.081"]],"st":1}}
{"schema_version":"1.3.0","event_id":"80d228b0-3d88-4ac7-bda5-57d88bd77eab","event_type":"raw.depth_update","source":"binance_market_data_recorder","venue":"binance_usdm","market_type":"perpetual_futures","symbol":"BTCUSDT","event_time_ms":1783517067516,"received_time_ms":1783517067510,"trace_id":"d6d9890a-7740-4968-9a70-106743a6960c","first_update_id":10999770634812,"final_update_id":10999770642587,"previous_final_update_id":10999770634790,"bids":[{"price":"11353.70","quantity":"1.856"},{"price":"11453.70","quantity":"1.241"},{"price":"11552.20","quantity":"0.459"},{"price":"11753.70","quantity":"0.848"},{"price":"55668.30","quantity":"0.002"},{"price":"59379.50","quantity":"0.001"},{"price":"60275.60","quantity":"0.000"},{"price":"61034.70","quantity":"0.010"},{"price":"61235.20","quantity":"0.025"},{"price":"61544.40","quantity":"0.013"},{"price":"61673.70","quantity":"0.012"},{"price":"61674.20","quantity":"1.644"},{"price":"61704.50","quantity":"0.000"},{"price":"61705.10","quantity":"0.739"},{"price":"61735.40","quantity":"0.000"},{"price":"61735.80","quantity":"1.411"},{"price":"61750.80","quantity":"0.030"},{"price":"61766.30","quantity":"0.003"},{"price":"61775.80","quantity":"36.037"},{"price":"61776.80","quantity":"7.491"},{"price":"61786.30","quantity":"0.002"},{"price":"61788.40","quantity":"0.002"},{"price":"61789.00","quantity":"1.484"},{"price":"61821.90","quantity":"0.291"},{"price":"61828.90","quantity":"1.061"},{"price":"61837.80","quantity":"2.139"},{"price":"61838.00","quantity":"0.162"},{"price":"61838.80","quantity":"0.009"},{"price":"61839.00","quantity":"0.084"},{"price":"61841.90","quantity":"0.385"},{"price":"61842.00","quantity":"0.147"},{"price":"61844.80","quantity":"0.441"},{"price":"61850.10","quantity":"0.001"},{"price":"61853.70","quantity":"1.918"}],"asks":[{"price":"61853.80","quantity":"8.441"},{"price":"61854.50","quantity":"0.528"},{"price":"61863.10","quantity":"0.000"},{"price":"61864.50","quantity":"0.582"},{"price":"61883.90","quantity":"0.020"},{"price":"61884.00","quantity":"0.002"},{"price":"61890.20","quantity":"0.012"},{"price":"61896.40","quantity":"0.017"},{"price":"61904.80","quantity":"0.487"},{"price":"62136.50","quantity":"0.072"},{"price":"62136.70","quantity":"0.000"},{"price":"62152.10","quantity":"0.214"},{"price":"62472.30","quantity":"0.000"},{"price":"62838.80","quantity":"0.087"},{"price":"89523.20","quantity":"0.744"}],"raw":{"e":"depthUpdate","E":1783517067516,"T":1783517067513,"s":"BTCUSDT","ps":"BTCUSDT","U":10999770634812,"u":10999770642587,"pu":10999770634790,"b":[["11353.70","1.856"],["11453.70","1.241"],["11552.20","0.459"],["11753.70","0.848"],["55668.30","0.002"],["59379.50","0.001"],["60275.60","0.000"],["61034.70","0.010"],["61235.20","0.025"],["61544.40","0.013"],["61673.70","0.012"],["61674.20","1.644"],["61704.50","0.000"],["61705.10","0.739"],["61735.40","0.000"],["61735.80","1.411"],["61750.80","0.030"],["61766.30","0.003"],["61775.80","36.037"],["61776.80","7.491"],["61786.30","0.002"],["61788.40","0.002"],["61789.00","1.484"],["61821.90","0.291"],["61828.90","1.061"],["61837.80","2.139"],["61838.00","0.162"],["61838.80","0.009"],["61839.00","0.084"],["61841.90","0.385"],["61842.00","0.147"],["61844.80","0.441"],["61850.10","0.001"],["61853.70","1.918"]],"a":[["61853.80","8.441"],["61854.50","0.528"],["61863.10","0.000"],["61864.50","0.582"],["61883.90","0.020"],["61884.00","0.002"],["61890.20","0.012"],["61896.40","0.017"],["61904.80","0.487"],["62136.50","0.072"],["62136.70","0.000"],["62152.10","0.214"],["62472.30","0.000"],["62838.80","0.087"],["89523.20","0.744"]],"st":1}}
{"schema_version":"1.3.0","event_id":"59f573e6-103b-445c-aa42-9bc397575500","event_type":"raw.depth_update","source":"binance_market_data_recorder","venue":"binance_usdm","market_type":"perpetual_futures","symbol":"ETHUSDT","event_time_ms":1783517067580,"received_time_ms":1783517067578,"trace_id":"d61d00a9-33ac-4806-bd82-688fe7ef946a","first_update_id":10999770638293,"final_update_id":10999770649894,"previous_final_update_id":10999770638173,"bids":[{"price":"201.00","quantity":"2.300"},{"price":"1211.12","quantity":"7.361"},{"price":"1216.12","quantity":"2.272"},{"price":"1216.13","quantity":"0.000"},{"price":"1231.12","quantity":"0.160"},{"price":"1562.50","quantity":"1.060"},{"price":"1562.51","quantity":"8.880"},{"price":"1666.60","quantity":"1.078"},{"price":"1698.07","quantity":"0.207"},{"price":"1734.06","quantity":"54.181"},{"price":"1734.12","quantity":"55.897"},{"price":"1734.49","quantity":"53.070"},{"price":"1734.57","quantity":"29.351"},{"price":"1734.60","quantity":"0.309"},{"price":"1734.62","quantity":"119.388"},{"price":"1734.63","quantity":"23.322"},{"price":"1734.64","quantity":"0.556"},{"price":"1734.75","quantity":"68.153"},{"price":"1734.84","quantity":"272.872"},{"price":"1734.86","quantity":"258.509"},{"price":"1735.01","quantity":"19.586"},{"price":"1735.35","quantity":"20.788"},{"price":"1735.61","quantity":"8.774"},{"price":"1735.65","quantity":"20.560"},{"price":"1735.67","quantity":"20.051"},{"price":"1735.71","quantity":"0.050"},{"price":"1735.73","quantity":"26.047"},{"price":"1735.76","quantity":"15.145"},{"price":"1735.79","quantity":"4.090"},{"price":"1735.82","quantity":"0.866"},{"price":"1735.86","quantity":"68.396"},{"price":"1735.87","quantity":"1.139"},{"price":"1735.90","quantity":"3.012"},{"price":"1735.91","quantity":"9.957"},{"price":"1735.92","quantity":"30.835"},{"price":"1735.93","quantity":"22.962"},{"price":"1735.94","quantity":"6.510"},{"price":"1735.95","quantity":"2.378"},{"price":"1735.96","quantity":"2.280"},{"price":"1735.97","quantity":"3.095"},{"price":"1736.00","quantity":"7.546"},{"price":"1736.01","quantity":"0.050"},{"price":"1736.03","quantity":"0.153"},{"price":"1736.04","quantity":"1.227"},{"price":"1736.06","quantity":"0.014"},{"price":"1736.07","quantity":"0.036"},{"price":"1736.08","quantity":"0.735"},{"price":"1736.09","quantity":"0.942"},{"price":"1736.12","quantity":"113.423"}],"asks":[{"price":"1736.13","quantity":"121.857"},{"price":"1736.18","quantity":"1.858"},{"price":"1736.20","quantity":"2.828"},{"price":"1736.21","quantity":"0.032"},{"price":"1736.22","quantity":"20.213"},{"price":"1736.23","quantity":"21.780"},{"price":"1736.25","quantity":"3.977"},{"price":"1736.27","quantity":"0.814"},{"price":"1736.32","quantity":"0.130"},{"price":"1736.36","quantity":"5.168"},{"price":"1736.37","quantity":"10.715"},{"price":"1736.44","quantity":"10.857"},{"price":"1736.49","quantity":"3.015"},{"price":"1736.50","quantity":"0.114"},{"price":"1736.56","quantity":"9.096"},{"price":"1736.63","quantity":"10.262"},{"price":"1736.75","quantity":"78.830"},{"price":"1736.79","quantity":"0.096"},{"price":"1736.89","quantity":"9.594"},{"price":"1737.00","quantity":"71.577"},{"price":"1737.04","quantity":"29.478"},{"price":"1737.05","quantity":"0.797"},{"price":"1737.13","quantity":"7.142"},{"price":"1737.35","quantity":"42.850"},{"price":"1737.39","quantity":"2.576"},{"price":"1737.52","quantity":"2.666"},{"price":"1737.54","quantity":"1.118"},{"price":"1737.55","quantity":"37.237"},{"price":"1737.57","quantity":"42.677"},{"price":"1737.61","quantity":"12.960"},{"price":"1737.80","quantity":"31.254"},{"price":"1737.87","quantity":"7.926"},{"price":"1737.89","quantity":"7.279"},{"price":"1737.92","quantity":"0.730"},{"price":"1738.13","quantity":"21.531"},{"price":"1738.27","quantity":"15.155"},{"price":"1738.35","quantity":"0.047"},{"price":"1738.88","quantity":"1.079"},{"price":"1738.91","quantity":"3.541"},{"price":"1738.94","quantity":"7.156"},{"price":"1738.96","quantity":"3.196"},{"price":"1739.42","quantity":"25.430"},{"price":"1740.16","quantity":"9.755"},{"price":"1740.58","quantity":"8.287"},{"price":"1747.12","quantity":"0.000"},{"price":"2634.83","quantity":"0.001"},{"price":"2634.84","quantity":"0.399"},{"price":"2634.92","quantity":"0.019"},{"price":"2634.93","quantity":"0.000"}],"raw":{"e":"depthUpdate","E":1783517067580,"T":1783517067577,"s":"ETHUSDT","ps":"ETHUSDT","U":10999770638293,"u":10999770649894,"pu":10999770638173,"b":[["201.00","2.300"],["1211.12","7.361"],["1216.12","2.272"],["1216.13","0.000"],["1231.12","0.160"],["1562.50","1.060"],["1562.51","8.880"],["1666.60","1.078"],["1698.07","0.207"],["1734.06","54.181"],["1734.12","55.897"],["1734.49","53.070"],["1734.57","29.351"],["1734.60","0.309"],["1734.62","119.388"],["1734.63","23.322"],["1734.64","0.556"],["1734.75","68.153"],["1734.84","272.872"],["1734.86","258.509"],["1735.01","19.586"],["1735.35","20.788"],["1735.61","8.774"],["1735.65","20.560"],["1735.67","20.051"],["1735.71","0.050"],["1735.73","26.047"],["1735.76","15.145"],["1735.79","4.090"],["1735.82","0.866"],["1735.86","68.396"],["1735.87","1.139"],["1735.90","3.012"],["1735.91","9.957"],["1735.92","30.835"],["1735.93","22.962"],["1735.94","6.510"],["1735.95","2.378"],["1735.96","2.280"],["1735.97","3.095"],["1736.00","7.546"],["1736.01","0.050"],["1736.03","0.153"],["1736.04","1.227"],["1736.06","0.014"],["1736.07","0.036"],["1736.08","0.735"],["1736.09","0.942"],["1736.12","113.423"]],"a":[["1736.13","121.857"],["1736.18","1.858"],["1736.20","2.828"],["1736.21","0.032"],["1736.22","20.213"],["1736.23","21.780"],["1736.25","3.977"],["1736.27","0.814"],["1736.32","0.130"],["1736.36","5.168"],["1736.37","10.715"],["1736.44","10.857"],["1736.49","3.015"],["1736.50","0.114"],["1736.56","9.096"],["1736.63","10.262"],["1736.75","78.830"],["1736.79","0.096"],["1736.89","9.594"],["1737.00","71.577"],["1737.04","29.478"],["1737.05","0.797"],["1737.13","7.142"],["1737.35","42.850"],["1737.39","2.576"],["1737.52","2.666"],["1737.54","1.118"],["1737.55","37.237"],["1737.57","42.677"],["1737.61","12.960"],["1737.80","31.254"],["1737.87","7.926"],["1737.89","7.279"],["1737.92","0.730"],["1738.13","21.531"],["1738.27","15.155"],["1738.35","0.047"],["1738.88","1.079"],["1738.91","3.541"],["1738.94","7.156"],["1738.96","3.196"],["1739.42","25.430"],["1740.16","9.755"],["1740.58","8.287"],["1747.12","0.000"],["2634.83","0.001"],["2634.84","0.399"],["2634.92","0.019"],["2634.93","0.000"]],"st":1}}
{"schema_version":"1.3.0","event_id":"f0554dfb-70b9-4440-b1af-e115eb312c65","event_type":"raw.depth_update","source":"binance_market_data_recorder","venue":"binance_usdm","market_type":"perpetual_futures","symbol":"BTCUSDT","event_time_ms":1783517067618,"received_time_ms":1783517067612,"trace_id":"78be09f5-49e8-498e-88a3-e864ca133689","first_update_id":10999770643081,"final_update_id":10999770654358,"previous_final_update_id":10999770642587,"bids":[{"price":"1000.00","quantity":"207.692"},{"price":"11353.70","quantity":"1.584"},{"price":"11453.70","quantity":"1.394"},{"price":"11552.20","quantity":"0.306"},{"price":"11753.70","quantity":"1.120"},{"price":"49483.00","quantity":"0.000"},{"price":"55668.30","quantity":"0.002"},{"price":"59379.50","quantity":"0.004"},{"price":"60280.60","quantity":"2.403"},{"price":"61235.20","quantity":"0.025"},{"price":"61380.40","quantity":"0.005"},{"price":"61841.30","quantity":"0.819"},{"price":"61842.50","quantity":"0.674"},{"price":"61842.60","quantity":"0.420"},{"price":"61844.80","quantity":"0.118"},{"price":"61844.90","quantity":"0.033"},{"price":"61845.00","quantity":"0.009"},{"price":"61852.30","quantity":"0.264"},{"price":"61853.70","quantity":"2.218"}],"asks":[{"price":"61860.20","quantity":"1.295"},{"price":"61893.30","quantity":"0.473"},{"price":"61899.20","quantity":"0.000"},{"price":"62472.30","quantity":"0.002"},{"price":"63090.80","quantity":"0.012"}],"raw":{"e":"depthUpdate","E":1783517067618,"T":1783517067617,"s":"BTCUSDT","ps":"BTCUSDT","U":10999770643081,"u":10999770654358,"pu":10999770642587,"b":[["1000.00","207.692"],["11353.70","1.584"],["11453.70","1.394"],["11552.20","0.306"],["11753.70","1.120"],["49483.00","0.000"],["55668.30","0.002"],["59379.50","0.004"],["60280.60","2.403"],["61235.20","0.025"],["61380.40","0.005"],["61841.30","0.819"],["61842.50","0.674"],["61842.60","0.420"],["61844.80","0.118"],["61844.90","0.033"],["61845.00","0.009"],["61852.30","0.264"],["61853.70","2.218"]],"a":[["61860.20","1.295"],["61893.30","0.473"],["61899.20","0.000"],["62472.30","0.002"],["63090.80","0.012"]],"st":1}}
{"schema_version":"1.3.0","event_id":"0e59475d-808d-45db-9015-1d9d0d62a2c4","event_type":"raw.depth_update","source":"binance_market_data_recorder","venue":"binance_usdm","market_type":"perpetual_futures","symbol":"ETHUSDT","event_time_ms":1783517067682,"received_time_ms":1783517067676,"trace_id":"d8759f16-9be4-403f-a616-a72256d5e4d6","first_update_id":10999770650079,"final_update_id":10999770659499,"previous_final_update_id":10999770649894,"bids":[{"price":"1211.12","quantity":"7.489"},{"price":"1216.12","quantity":"1.792"},{"price":"1231.12","quantity":"0.512"},{"price":"1562.50","quantity":"1.060"},{"price":"1562.51","quantity":"9.008"},{"price":"1701.39","quantity":"32.216"},{"price":"1712.87","quantity":"0.193"},{"price":"1718.09","quantity":"0.000"},{"price":"1718.75","quantity":"151.963"},{"price":"1720.00","quantity":"1507.920"},{"price":"1720.83","quantity":"23.210"},{"price":"1734.18","quantity":"0.070"},{"price":"1734.54","quantity":"17.709"},{"price":"1735.12","quantity":"96.297"},{"price":"1735.35","quantity":"20.776"},{"price":"1735.66","quantity":"0.169"},{"price":"1735.70","quantity":"0.025"},{"price":"1735.74","quantity":"57.898"},{"price":"1735.81","quantity":"6.958"},{"price":"1735.89","quantity":"14.523"},{"price":"1735.92","quantity":"39.475"},{"price":"1735.93","quantity":"0.778"},{"price":"1735.94","quantity":"6.452"},{"price":"1736.00","quantity":"4.479"},{"price":"1736.01","quantity":"22.234"},{"price":"1736.05","quantity":"0.063"},{"price":"1736.06","quantity":"0.026"},{"price":"1736.07","quantity":"0.048"},{"price":"1736.10","quantity":"3.738"},{"price":"1736.11","quantity":"4.307"},{"price":"1736.12","quantity":"113.493"}],"asks":[{"price":"1736.16","quantity":"0.267"},{"price":"1736.18","quantity":"0.130"},{"price":"1736.19","quantity":"0.032"},{"price":"1736.22","quantity":"17.678"},{"price":"1736.27","quantity":"0.314"},{"price":"1736.29","quantity":"1.710"},{"price":"1736.36","quantity":"5.168"},{"price":"1736.39","quantity":"0.098"},{"price":"1736.43","quantity":"56.447"},{"price":"1736.50","quantity":"0.102"},{"price":"1738.66","quantity":"3.806"},{"price":"1781.57","quantity":"0.013"},{"price":"2634.81","quantity":"0.001"},{"price":"2634.82","quantity":"0.001"},{"price":"2634.90","quantity":"0.000"},{"price":"2634.91","quantity":"0.000"}],"raw":{"e":"depthUpdate","E":1783517067682,"T":1783517067681,"s":"ETHUSDT","ps":"ETHUSDT","U":10999770650079,"u":10999770659499,"pu":10999770649894,"b":[["1211.12","7.489"],["1216.12","1.792"],["1231.12","0.512"],["1562.50","1.060"],["1562.51","9.008"],["1701.39","32.216"],["1712.87","0.193"],["1718.09","0.000"],["1718.75","151.963"],["1720.00","1507.920"],["1720.83","23.210"],["1734.18","0.070"],["1734.54","17.709"],["1735.12","96.297"],["1735.35","20.776"],["1735.66","0.169"],["1735.70","0.025"],["1735.74","57.898"],["1735.81","6.958"],["1735.89","14.523"],["1735.92","39.475"],["1735.93","0.778"],["1735.94","6.452"],["1736.00","4.479"],["1736.01","22.234"],["1736.05","0.063"],["1736.06","0.026"],["1736.07","0.048"],["1736.10","3.738"],["1736.11","4.307"],["1736.12","113.493"]],"a":[["1736.16","0.267"],["1736.18","0.130"],["1736.19","0.032"],["1736.22","17.678"],["1736.27","0.314"],["1736.29","1.710"],["1736.36","5.168"],["1736.39","0.098"],["1736.43","56.447"],["1736.50","0.102"],["1738.66","3.806"],["1781.57","0.013"],["2634.81","0.001"],["2634.82","0.001"],["2634.90","0.000"],["2634.91","0.000"]],"st":1}}
{"schema_version":"1.3.0","event_id":"f824cbb9-8978-483a-9487-66421205b44c","event_type":"raw.depth_update","source":"binance_market_data_recorder","venue":"binance_usdm","market_type":"perpetual_futures","symbol":"BTCUSDT","event_time_ms":1783517067720,"received_time_ms":1783517067715,"trace_id":"3eee21d6-94d7-4cd5-9630-1726050a229a","first_update_id":10999770654454,"final_update_id":10999770663056,"previous_final_update_id":10999770654358,"bids":[{"price":"11353.70","quantity":"1.312"},{"price":"11453.70","quantity":"1.530"},{"price":"11552.20","quantity":"0.170"},{"price":"11753.70","quantity":"1.392"},{"price":"49483.00","quantity":"0.000"},{"price":"55668.30","quantity":"0.002"},{"price":"59379.50","quantity":"0.001"},{"price":"61235.20","quantity":"0.025"},{"price":"61289.60","quantity":"0.004"},{"price":"61830.00","quantity":"0.006"},{"price":"61831.30","quantity":"3.105"},{"price":"61832.20","quantity":"0.002"},{"price":"61835.00","quantity":"0.037"},{"price":"61838.20","quantity":"0.481"},{"price":"61839.20","quantity":"0.001"},{"price":"61839.80","quantity":"0.360"},{"price":"61840.10","quantity":"0.000"},{"price":"61842.50","quantity":"0.673"},{"price":"61843.70","quantity":"0.004"},{"price":"61847.50","quantity":"0.418"},{"price":"61850.00","quantity":"0.858"},{"price":"61852.30","quantity":"0.002"},{"price":"61853.70","quantity":"2.218"}],"asks":[{"price":"61853.80","quantity":"8.069"},{"price":"61854.70","quantity":"0.370"},{"price":"61856.60","quantity":"0.163"},{"price":"61862.00","quantity":"0.163"},{"price":"61863.20","quantity":"1.423"},{"price":"61871.20","quantity":"0.025"},{"price":"61904.50","quantity":"0.181"},{"price":"61904.60","quantity":"4.189"},{"price":"62163.10","quantity":"0.001"},{"price":"62472.30","quantity":"0.000"},{"price":"62565.30","quantity":"12.337"},{"price":"62756.90","quantity":"0.397"},{"price":"62771.90","quantity":"0.000"},{"price":"62775.60","quantity":"0.578"},{"price":"89523.20","quantity":"0.750"}],"raw":{"e":"depthUpdate","E":1783517067720,"T":1783517067718,"s":"BTCUSDT","ps":"BTCUSDT","U":10999770654454,"u":10999770663056,"pu":10999770654358,"b":[["11353.70","1.312"],["11453.70","1.530"],["11552.20","0.170"],["11753.70","1.392"],["49483.00","0.000"],["55668.30","0.002"],["59379.50","0.001"],["61235.20","0.025"],["61289.60","0.004"],["61830.00","0.006"],["61831.30","3.105"],["61832.20","0.002"],["61835.00","0.037"],["61838.20","0.481"],["61839.20","0.001"],["61839.80","0.360"],["61840.10","0.000"],["61842.50","0.673"],["61843.70","0.004"],["61847.50","0.418"],["61850.00","0.858"],["61852.30","0.002"],["61853.70","2.218"]],"a":[["61853.80","8.069"],["61854.70","0.370"],["61856.60","0.163"],["61862.00","0.163"],["61863.20","1.423"],["61871.20","0.025"],["61904.50","0.181"],["61904.60","4.189"],["62163.10","0.001"],["62472.30","0.000"],["62565.30","12.337"],["62756.90","0.397"],["62771.90","0.000"],["62775.60","0.578"],["89523.20","0.750"]],"st":1}}
{"schema_version":"1.3.0","event_id":"d05a67ac-3d7f-4506-abeb-8c80a43c009c","event_type":"raw.depth_update","source":"binance_market_data_recorder","venue":"binance_usdm","market_type":"perpetual_futures","symbol":"ETHUSDT","event_time_ms":1783517067784,"received_time_ms":1783517067780,"trace_id":"5754bfa1-c7b6-4078-9194-81dba43fff51","first_update_id":10999770659591,"final_update_id":10999770667926,"previous_final_update_id":10999770659499,"bids":[{"price":"200.00","quantity":"7.594"},{"price":"1211.12","quantity":"7.201"},{"price":"1216.12","quantity":"1.536"},{"price":"1231.12","quantity":"1.056"},{"price":"1562.50","quantity":"1.060"},{"price":"1562.51","quantity":"9.008"},{"price":"1666.60","quantity":"1.193"},{"price":"1701.39","quantity":"32.187"},{"price":"1704.85","quantity":"11.997"},{"price":"1718.75","quantity":"169.394"},{"price":"1733.72","quantity":"1.615"},{"price":"1734.84","quantity":"269.416"},{"price":"1734.86","quantity":"39.120"},{"price":"1734.87","quantity":"239.191"},{"price":"1735.17","quantity":"6.739"},{"price":"1735.25","quantity":"0.189"},{"price":"1735.70","quantity":"0.037"},{"price":"1735.79","quantity":"4.440"},{"price":"1735.90","quantity":"11.661"},{"price":"1735.93","quantity":"0.800"},{"price":"1735.94","quantity":"5.006"},{"price":"1736.12","quantity":"113.495"}],"asks":[{"price":"1736.32","quantity":"0.130"},{"price":"1736.50","quantity":"0.114"},{"price":"1736.82","quantity":"26.995"},{"price":"1736.91","quantity":"88.160"},{"price":"1737.13","quantity":"7.142"},{"price":"1737.43","quantity":"8.581"},{"price":"1737.88","quantity":"34.874"},{"price":"1738.70","quantity":"0.197"},{"price":"1738.71","quantity":"35.150"},{"price":"2634.80","quantity":"0.001"},{"price":"2634.89","quantity":"0.000"}],"raw":{"e":"depthUpdate","E":1783517067784,"T":1783517067783,"s":"ETHUSDT","ps":"ETHUSDT","U":10999770659591,"u":10999770667926,"pu":10999770659499,"b":[["200.00","7.594"],["1211.12","7.201"],["1216.12","1.536"],["1231.12","1.056"],["1562.50","1.060"],["1562.51","9.008"],["1666.60","1.193"],["1701.39","32.187"],["1704.85","11.997"],["1718.75","169.394"],["1733.72","1.615"],["1734.84","269.416"],["1734.86","39.120"],["1734.87","239.191"],["1735.17","6.739"],["1735.25","0.189"],["1735.70","0.037"],["1735.79","4.440"],["1735.90","11.661"],["1735.93","0.800"],["1735.94","5.006"],["1736.12","113.495"]],"a":[["1736.32","0.130"],["1736.50","0.114"],["1736.82","26.995"],["1736.91","88.160"],["1737.13","7.142"],["1737.43","8.581"],["1737.88","34.874"],["1738.70","0.197"],["1738.71","35.150"],["2634.80","0.001"],["2634.89","0.000"]],"st":1}}
{"schema_version":"1.3.0","event_id":"06f6042b-a535-4784-a2b4-6ff742f7534d","event_type":"raw.trade","source":"binance_market_data_recorder","venue":"binance_usdm","market_type":"perpetual_futures","symbol":"BTCUSDT","event_time_ms":1783517067792,"received_time_ms":1783517067788,"trace_id":"dbb3150f-fb07-4a7c-b3ba-5c5b94ab08f3","trade_id":7881418053,"price":"61853.80","quantity":"0.031","trade_time_ms":1783517067791,"is_buyer_maker":false,"aggressor_side":"buy","raw":{"e":"trade","E":1783517067792,"T":1783517067791,"s":"BTCUSDT","t":7881418053,"p":"61853.80","q":"0.031","X":"MARKET","m":false,"st":1}}
{"schema_version":"1.3.0","event_id":"31ed665b-d6e3-4cf3-888a-bdb4838f5186","event_type":"raw.trade","source":"binance_market_data_recorder","venue":"binance_usdm","market_type":"perpetual_futures","symbol":"ETHUSDT","event_time_ms":1783517067792,"received_time_ms":1783517067789,"trace_id":"283a432b-4d1f-4fe1-be22-8dc1f15079f5","trade_id":8429826856,"price":"1736.12","quantity":"0.060","trade_time_ms":1783517067792,"is_buyer_maker":true,"aggressor_side":"sell","raw":{"e":"trade","E":1783517067792,"T":1783517067792,"s":"ETHUSDT","t":8429826856,"p":"1736.12","q":"0.060","X":"MARKET","m":true,"st":1}}
{"schema_version":"1.3.0","event_id":"ef071488-7de2-4471-8ca0-eb2e9ddf7adf","event_type":"raw.trade","source":"binance_market_data_recorder","venue":"binance_usdm","market_type":"perpetual_futures","symbol":"BTCUSDT","event_time_ms":1783517067796,"received_time_ms":1783517067793,"trace_id":"752c9e93-ae64-4214-af49-a9271e094b77","trade_id":7881418054,"price":"61853.70","quantity":"0.015","trade_time_ms":1783517067795,"is_buyer_maker":true,"aggressor_side":"sell","raw":{"e":"trade","E":1783517067796,"T":1783517067795,"s":"BTCUSDT","t":7881418054,"p":"61853.70","q":"0.015","X":"MARKET","m":true,"st":1}}
{"schema_version":"1.3.0","event_id":"7b06ef10-d335-4ffa-98e0-86b45ebb36a1","event_type":"raw.depth_update","source":"binance_market_data_recorder","venue":"binance_usdm","market_type":"perpetual_futures","symbol":"BTCUSDT","event_time_ms":1783517067822,"received_time_ms":1783517067817,"trace_id":"ce3d2aec-2885-4793-b764-228ad3df3a59","first_update_id":10999770663190,"final_update_id":10999770672081,"previous_final_update_id":10999770663056,"bids":[{"price":"11353.70","quantity":"1.040"},{"price":"11453.70","quantity":"1.683"},{"price":"11552.20","quantity":"0.017"},{"price":"11753.70","quantity":"1.664"},{"price":"49483.00","quantity":"0.000"},{"price":"55668.30","quantity":"0.002"},{"price":"60615.20","quantity":"0.027"},{"price":"61235.20","quantity":"0.025"},{"price":"61358.90","quantity":"1.217"},{"price":"61399.60","quantity":"0.207"},{"price":"61544.40","quantity":"0.013"},{"price":"61606.30","quantity":"0.823"},{"price":"61722.70","quantity":"0.551"},{"price":"61722.90","quantity":"0.387"},{"price":"61748.90","quantity":"0.281"},{"price":"61749.00","quantity":"0.029"},{"price":"61757.60","quantity":"0.002"},{"price":"61775.20","quantity":"0.047"},{"price":"61777.90","quantity":"0.154"},{"price":"61816.10","quantity":"0.047"},{"price":"61823.60","quantity":"0.323"},{"price":"61825.10","quantity":"0.837"},{"price":"61825.50","quantity":"0.008"},{"price":"61829.40","quantity":"1.821"},{"price":"61829.80","quantity":"0.178"},{"price":"61830.50","quantity":"0.989"},{"price":"61830.60","quantity":"0.009"},{"price":"61831.30","quantity":"2.137"},{"price":"61836.00","quantity":"0.145"},{"price":"61840.10","quantity":"0.002"},{"price":"61842.50","quantity":"0.572"},{"price":"61843.10","quantity":"0.053"},{"price":"61843.70","quantity":"0.003"},{"price":"61846.30","quantity":"0.001"},{"price":"61851.60","quantity":"0.072"},{"price":"61853.70","quantity":"1.886"}],"asks":[{"price":"61853.80","quantity":"8.038"},{"price":"61854.40","quantity":"1.619"},{"price":"61854.80","quantity":"0.001"},{"price":"61861.40","quantity":"0.165"},{"price":"61863.50","quantity":"0.082"},{"price":"61864.40","quantity":"0.582"},{"price":"61864.50","quantity":"0.000"},{"price":"61866.50","quantity":"0.125"},{"price":"61867.60","quantity":"0.507"},{"price":"61867.80","quantity":"0.084"},{"price":"61871.20","quantity":"0.027"},{"price":"61873.80","quantity":"1.615"},{"price":"61880.50","quantity":"0.067"},{"price":"61881.80","quantity":"0.029"},{"price":"61899.30","quantity":"0.485"},{"price":"61899.40","quantity":"2.534"},{"price":"61985.80","quantity":"0.744"},{"price":"62027.20","quantity":"0.000"},{"price":"62027.30","quantity":"0.003"},{"price":"62133.20","quantity":"0.018"},{"price":"62136.00","quantity":"0.016"},{"price":"62163.10","quantity":"0.002"},{"price":"62472.30","quantity":"0.000"},{"price":"62565.70","quantity":"2.856"},{"price":"62781.70","quantity":"0.375"},{"price":"62805.50","quantity":"0.000"},{"price":"62819.10","quantity":"0.810"},{"price":"62922.30","quantity":"0.000"}],"raw":{"e":"depthUpdate","E":1783517067822,"T":1783517067821,"s":"BTCUSDT","ps":"BTCUSDT","U":10999770663190,"u":10999770672081,"pu":10999770663056,"b":[["11353.70","1.040"],["11453.70","1.683"],["11552.20","0.017"],["11753.70","1.664"],["49483.00","0.000"],["55668.30","0.002"],["60615.20","0.027"],["61235.20","0.025"],["61358.90","1.217"],["61399.60","0.207"],["61544.40","0.013"],["61606.30","0.823"],["61722.70","0.551"],["61722.90","0.387"],["61748.90","0.281"],["61749.00","0.029"],["61757.60","0.002"],["61775.20","0.047"],["61777.90","0.154"],["61816.10","0.047"],["61823.60","0.323"],["61825.10","0.837"],["61825.50","0.008"],["61829.40","1.821"],["61829.80","0.178"],["61830.50","0.989"],["61830.60","0.009"],["61831.30","2.137"],["61836.00","0.145"],["61840.10","0.002"],["61842.50","0.572"],["61843.10","0.053"],["61843.70","0.003"],["61846.30","0.001"],["61851.60","0.072"],["61853.70","1.886"]],"a":[["61853.80","8.038"],["61854.40","1.619"],["61854.80","0.001"],["61861.40","0.165"],["61863.50","0.082"],["61864.40","0.582"],["61864.50","0.000"],["61866.50","0.125"],["61867.60","0.507"],["61867.80","0.084"],["61871.20","0.027"],["61873.80","1.615"],["61880.50","0.067"],["61881.80","0.029"],["61899.30","0.485"],["61899.40","2.534"],["61985.80","0.744"],["62027.20","0.000"],["62027.30","0.003"],["62133.20","0.018"],["62136.00","0.016"],["62163.10","0.002"],["62472.30","0.000"],["62565.70","2.856"],["62781.70","0.375"],["62805.50","0.000"],["62819.10","0.810"],["62922.30","0.000"]],"st":1}}
{"schema_version":"1.3.0","event_id":"eb3e18c4-6b32-4a3e-8e94-9b136c3737dd","event_type":"raw.depth_update","source":"binance_market_data_recorder","venue":"binance_usdm","market_type":"perpetual_futures","symbol":"ETHUSDT","event_time_ms":1783517067886,"received_time_ms":1783517067881,"trace_id":"4bf6566b-542f-4c38-a2a4-a7289d4282af","first_update_id":10999770668098,"final_update_id":10999770676439,"previous_final_update_id":10999770667926,"bids":[{"price":"1211.12","quantity":"6.945"},{"price":"1216.12","quantity":"1.248"},{"price":"1231.12","quantity":"1.600"},{"price":"1562.50","quantity":"1.060"},{"price":"1562.51","quantity":"8.894"},{"price":"1666.60","quantity":"1.078"},{"price":"1684.04","quantity":"35.838"},{"price":"1712.92","quantity":"13.119"},{"price":"1722.23","quantity":"0.020"},{"price":"1733.65","quantity":"428.877"},{"price":"1733.70","quantity":"16.600"},{"price":"1733.72","quantity":"0.169"},{"price":"1733.76","quantity":"94.780"},{"price":"1733.85","quantity":"89.846"},{"price":"1733.86","quantity":"5.287"},{"price":"1734.98","quantity":"289.248"},{"price":"1735.02","quantity":"93.353"},{"price":"1735.03","quantity":"0.065"},{"price":"1735.18","quantity":"0.385"},{"price":"1735.21","quantity":"36.547"},{"price":"1735.22","quantity":"17.353"},{"price":"1735.58","quantity":"0.094"},{"price":"1735.63","quantity":"6.343"},{"price":"1735.77","quantity":"16.201"},{"price":"1736.12","quantity":"115.408"}],"asks":[{"price":"1736.15","quantity":"0.101"},{"price":"1736.18","quantity":"0.041"},{"price":"1736.91","quantity":"84.799"},{"price":"1737.01","quantity":"74.995"},{"price":"1737.37","quantity":"29.259"},{"price":"1737.43","quantity":"0.643"},{"price":"1737.88","quantity":"36.568"},{"price":"1738.00","quantity":"88.971"},{"price":"1738.04","quantity":"1.906"},{"price":"1738.08","quantity":"408.649"},{"price":"1738.13","quantity":"19.864"},{"price":"1738.17","quantity":"7.677"},{"price":"1738.25","quantity":"2.878"},{"price":"1743.10","quantity":"7.467"},{"price":"1747.12","quantity":"15.000"},{"price":"1762.00","quantity":"133.397"},{"price":"1780.00","quantity":"1285.325"},{"price":"1780.29","quantity":"81.353"},{"price":"2634.79","quantity":"0.001"},{"price":"2634.88","quantity":"0.000"}],"raw":{"e":"depthUpdate","E":1783517067886,"T":1783517067885,"s":"ETHUSDT","ps":"ETHUSDT","U":10999770668098,"u":10999770676439,"pu":10999770667926,"b":[["1211.12","6.945"],["1216.12","1.248"],["1231.12","1.600"],["1562.50","1.060"],["1562.51","8.894"],["1666.60","1.078"],["1684.04","35.838"],["1712.92","13.119"],["1722.23","0.020"],["1733.65","428.877"],["1733.70","16.600"],["1733.72","0.169"],["1733.76","94.780"],["1733.85","89.846"],["1733.86","5.287"],["1734.98","289.248"],["1735.02","93.353"],["1735.03","0.065"],["1735.18","0.385"],["1735.21","36.547"],["1735.22","17.353"],["1735.58","0.094"],["1735.63","6.343"],["1735.77","16.201"],["1736.12","115.408"]],"a":[["1736.15","0.101"],["1736.18","0.041"],["1736.91","84.799"],["1737.01","74.995"],["1737.37","29.259"],["1737.43","0.643"],["1737.88","36.568"],["1738.00","88.971"],["1738.04","1.906"],["1738.08","408.649"],["1738.13","19.864"],["1738.17","7.677"],["1738.25","2.878"],["1743.10","7.467"],["1747.12","15.000"],["1762.00","133.397"],["1780.00","1285.325"],["1780.29","81.353"],["2634.79","0.001"],["2634.88","0.000"]],"st":1}}
{"schema_version":"1.3.0","event_id":"bc9bd7a5-5524-4c93-ae17-86c2b918ace7","event_type":"raw.depth_update","source":"binance_market_data_recorder","venue":"binance_usdm","market_type":"perpetual_futures","symbol":"BTCUSDT","event_time_ms":1783517067924,"received_time_ms":1783517067918,"trace_id":"9193e4d0-18d4-4a2a-8498-e71bb5ac7d00","first_update_id":10999770672253,"final_update_id":10999770680289,"previous_final_update_id":10999770672081,"bids":[{"price":"1000.00","quantity":"207.692"},{"price":"11352.20","quantity":"0.400"},{"price":"11353.20","quantity":"0.016"},{"price":"11353.70","quantity":"0.967"},{"price":"11453.70","quantity":"1.581"},{"price":"11552.20","quantity":"0.000"},{"price":"11753.70","quantity":"1.936"},{"price":"55668.30","quantity":"0.002"},{"price":"59379.50","quantity":"0.004"},{"price":"61171.80","quantity":"4.737"},{"price":"61235.20","quantity":"0.025"},{"price":"61537.60","quantity":"0.348"},{"price":"61722.90","quantity":"0.108"},{"price":"61723.00","quantity":"0.983"},{"price":"61759.10","quantity":"0.047"},{"price":"61775.80","quantity":"2.135"},{"price":"61776.80","quantity":"2.746"},{"price":"61786.30","quantity":"0.002"},{"price":"61788.40","quantity":"33.904"},{"price":"61789.00","quantity":"6.379"},{"price":"61816.10","quantity":"0.000"},{"price":"61825.00","quantity":"1.415"},{"price":"61825.40","quantity":"0.995"},{"price":"61825.80","quantity":"0.000"},{"price":"61835.40","quantity":"0.001"},{"price":"61835.50","quantity":"0.012"},{"price":"61841.90","quantity":"0.484"},{"price":"61842.00","quantity":"0.369"},{"price":"61842.10","quantity":"0.001"},{"price":"61842.50","quantity":"0.673"},{"price":"61842.60","quantity":"0.097"},{"price":"61843.10","quantity":"0.154"},{"price":"61844.80","quantity":"0.017"}],"asks":[{"price":"61853.80","quantity":"8.384"},{"price":"61856.60","quantity":"0.001"},{"price":"61858.90","quantity":"0.103"},{"price":"61873.70","quantity":"0.007"},{"price":"61878.10","quantity":"0.005"},{"price":"61893.20","quantity":"0.373"},{"price":"61893.30","quantity":"0.307"},{"price":"61893.40","quantity":"1.280"},{"price":"61985.80","quantity":"0.744"},{"price":"62407.10","quantity":"0.720"},{"price":"62472.30","quantity":"0.000"},{"price":"62526.90","quantity":"0.240"},{"price":"62723.10","quantity":"0.000"},{"price":"62747.90","quantity":"0.795"},{"price":"89523.20","quantity":"0.756"}],"raw":{"e":"depthUpdate","E":1783517067924,"T":1783517067923,"s":"BTCUSDT","ps":"BTCUSDT","U":10999770672253,"u":10999770680289,"pu":10999770672081,"b":[["1000.00","207.692"],["11352.20","0.400"],["11353.20","0.016"],["11353.70","0.967"],["11453.70","1.581"],["11552.20","0.000"],["11753.70","1.936"],["55668.30","0.002"],["59379.50","0.004"],["61171.80","4.737"],["61235.20","0.025"],["61537.60","0.348"],["61722.90","0.108"],["61723.00","0.983"],["61759.10","0.047"],["61775.80","2.135"],["61776.80","2.746"],["61786.30","0.002"],["61788.40","33.904"],["61789.00","6.379"],["61816.10","0.000"],["61825.00","1.415"],["61825.40","0.995"],["61825.80","0.000"],["61835.40","0.001"],["61835.50","0.012"],["61841.90","0.484"],["61842.00","0.369"],["61842.10","0.001"],["61842.50","0.673"],["61842.60","0.097"],["61843.10","0.154"],["61844.80","0.017"]],"a":[["61853.80","8.384"],["61856.60","0.001"],["61858.90","0.103"],["61873.70","0.007"],["61878.10","0.005"],["61893.20","0.373"],["61893.30","0.307"],["61893.40","1.280"],["61985.80","0.744"],["62407.10","0.720"],["62472.30","0.000"],["62526.90","0.240"],["62723.10","0.000"],["62747.90","0.795"],["89523.20","0.756"]],"st":1}}
{"schema_version":"1.3.0","event_id":"5e38d967-ad57-4ad4-bdf0-09e3cf23c887","event_type":"raw.trade","source":"binance_market_data_recorder","venue":"binance_usdm","market_type":"perpetual_futures","symbol":"BTCUSDT","event_time_ms":1783517067972,"received_time_ms":1783517067969,"trace_id":"74cab331-8ebb-4ff1-bd72-52458f7c084e","trade_id":7881418055,"price":"61853.80","quantity":"0.002","trade_time_ms":1783517067972,"is_buyer_maker":false,"aggressor_side":"buy","raw":{"e":"trade","E":1783517067972,"T":1783517067972,"s":"BTCUSDT","t":7881418055,"p":"61853.80","q":"0.002","X":"MARKET","m":false,"st":1}}
{"schema_version":"1.3.0","event_id":"2ae7fe9e-d3b7-4d97-b76d-2ce32ea0505c","event_type":"raw.depth_update","source":"binance_market_data_recorder","venue":"binance_usdm","market_type":"perpetual_futures","symbol":"ETHUSDT","event_time_ms":1783517067990,"received_time_ms":1783517067986,"trace_id":"626de289-e674-4eb7-8fcd-307068f1f45f","first_update_id":10999770676599,"final_update_id":10999770685130,"previous_final_update_id":10999770676439,"bids":[{"price":"200.00","quantity":"7.594"},{"price":"1211.12","quantity":"6.689"},{"price":"1216.12","quantity":"0.960"},{"price":"1231.12","quantity":"2.144"},{"price":"1562.50","quantity":"1.060"},{"price":"1562.51","quantity":"8.894"},{"price":"1666.60","quantity":"1.193"},{"price":"1701.39","quantity":"32.216"},{"price":"1730.66","quantity":"16.417"},{"price":"1730.81","quantity":"2.353"},{"price":"1733.65","quantity":"9.919"},{"price":"1733.66","quantity":"23.837"},{"price":"1733.71","quantity":"84.523"},{"price":"1733.76","quantity":"94.780"},{"price":"1733.88","quantity":"463.674"},{"price":"1734.18","quantity":"0.012"},{"price":"1734.57","quantity":"29.409"},{"price":"1734.98","quantity":"69.905"},{"price":"1735.02","quantity":"53.535"},{"price":"1735.12","quantity":"96.297"},{"price":"1736.12","quantity":"115.420"}],"asks":[{"price":"1736.13","quantity":"129.795"},{"price":"1736.32","quantity":"0.130"},{"price":"1736.90","quantity":"40.769"},{"price":"1737.52","quantity":"0.026"},{"price":"1741.42","quantity":"27.631"},{"price":"1741.64","quantity":"23.317"},{"price":"1769.11","quantity":"15.393"},{"price":"2634.77","quantity":"0.001"},{"price":"2634.78","quantity":"0.022"},{"price":"2634.86","quantity":"0.000"},{"price":"2634.87","quantity":"0.000"}],"raw":{"e":"depthUpdate","E":1783517067990,"T":1783517067989,"s":"ETHUSDT","ps":"ETHUSDT","U":10999770676599,"u":10999770685130,"pu":10999770676439,"b":[["200.00","7.594"],["1211.12","6.689"],["1216.12","0.960"],["1231.12","2.144"],["1562.50","1.060"],["1562.51","8.894"],["1666.60","1.193"],["1701.39","32.216"],["1730.66","16.417"],["1730.81","2.353"],["1733.65","9.919"],["1733.66","23.837"],["1733.71","84.523"],["1733.76","94.780"],["1733.88","463.674"],["1734.18","0.012"],["1734.57","29.409"],["1734.98","69.905"],["1735.02","53.535"],["1735.12","96.297"],["1736.12","115.420"]],"a":[["1736.13","129.795"],["1736.32","0.130"],["1736.90","40.769"],["1737.52","0.026"],["1741.42","27.631"],["1741.64","23.317"],["1769.11","15.393"],["2634.77","0.001"],["2634.78","0.022"],["2634.86","0.000"],["2634.87","0.000"]],"st":1}}
{"schema_version":"1.3.0","event_id":"758d0569-7a99-40aa-b073-9074f46360a2","event_type":"raw.trade","source":"binance_market_data_recorder","venue":"binance_usdm","market_type":"perpetual_futures","symbol":"ETHUSDT","event_time_ms":1783517068010,"received_time_ms":1783517068009,"trace_id":"d03d9d32-27b5-4108-9c4f-e4e160dd16fe","trade_id":8429826857,"price":"1736.12","quantity":"0.476","trade_time_ms":1783517068010,"is_buyer_maker":true,"aggressor_side":"sell","raw":{"e":"trade","E":1783517068010,"T":1783517068010,"s":"ETHUSDT","t":8429826857,"p":"1736.12","q":"0.476","X":"MARKET","m":true,"st":1}}
{"schema_version":"1.3.0","event_id":"4a2279cb-8bba-4143-8bd1-954a80facd96","event_type":"raw.trade","source":"binance_market_data_recorder","venue":"binance_usdm","market_type":"perpetual_futures","symbol":"ETHUSDT","event_time_ms":1783517068010,"received_time_ms":1783517068009,"trace_id":"9f019113-646b-4ea3-b95a-e6d282a45e26","trade_id":8429826858,"price":"1736.12","quantity":"0.088","trade_time_ms":1783517068010,"is_buyer_maker":true,"aggressor_side":"sell","raw":{"e":"trade","E":1783517068010,"T":1783517068010,"s":"ETHUSDT","t":8429826858,"p":"1736.12","q":"0.088","X":"MARKET","m":true,"st":1}}
{"schema_version":"1.3.0","event_id":"4588a527-c8c7-44e0-b2e2-d8f879b672c1","event_type":"raw.trade","source":"binance_market_data_recorder","venue":"binance_usdm","market_type":"perpetual_futures","symbol":"ETHUSDT","event_time_ms":1783517068010,"received_time_ms":1783517068010,"trace_id":"91d59fd5-68a0-438c-8865-04ff899709a6","trade_id":8429826859,"price":"1736.12","quantity":"0.660","trade_time_ms":1783517068010,"is_buyer_maker":true,"aggressor_side":"sell","raw":{"e":"trade","E":1783517068010,"T":1783517068010,"s":"ETHUSDT","t":8429826859,"p":"1736.12","q":"0.660","X":"MARKET","m":true,"st":1}}
{"schema_version":"1.3.0","event_id":"8b0c2ba4-9086-4f65-b291-9fe159f2af1d","event_type":"raw.trade","source":"binance_market_data_recorder","venue":"binance_usdm","market_type":"perpetual_futures","symbol":"ETHUSDT","event_time_ms":1783517068010,"received_time_ms":1783517068011,"trace_id":"83727e9a-5b7a-4cb2-9873-d0f40293a848","trade_id":8429826860,"price":"1736.12","quantity":"1.039","trade_time_ms":1783517068010,"is_buyer_maker":true,"aggressor_side":"sell","raw":{"e":"trade","E":1783517068010,"T":1783517068010,"s":"ETHUSDT","t":8429826860,"p":"1736.12","q":"1.039","X":"MARKET","m":true,"st":1}}
{"schema_version":"1.3.0","event_id":"ad8cf61c-383c-412e-9117-d06e556ba572","event_type":"raw.trade","source":"binance_market_data_recorder","venue":"binance_usdm","market_type":"perpetual_futures","symbol":"ETHUSDT","event_time_ms":1783517068010,"received_time_ms":1783517068011,"trace_id":"8536139d-96da-4035-8b9c-420aa22c4325","trade_id":8429826861,"price":"1736.12","quantity":"2.734","trade_time_ms":1783517068010,"is_buyer_maker":true,"aggressor_side":"sell","raw":{"e":"trade","E":1783517068010,"T":1783517068010,"s":"ETHUSDT","t":8429826861,"p":"1736.12","q":"2.734","X":"MARKET","m":true,"st":1}}
{"schema_version":"1.3.0","event_id":"17fdc9f8-fffd-418d-992f-c4fb82eac45c","event_type":"raw.trade","source":"binance_market_data_recorder","venue":"binance_usdm","market_type":"perpetual_futures","symbol":"ETHUSDT","event_time_ms":1783517068010,"received_time_ms":1783517068011,"trace_id":"6d312f65-68e9-43fe-a91d-bde63b709c16","trade_id":8429826862,"price":"1736.12","quantity":"0.013","trade_time_ms":1783517068010,"is_buyer_maker":true,"aggressor_side":"sell","raw":{"e":"trade","E":1783517068010,"T":1783517068010,"s":"ETHUSDT","t":8429826862,"p":"1736.12","q":"0.013","X":"MARKET","m":true,"st":1}}
{"schema_version":"1.3.0","event_id":"2c453058-0a58-445f-ba53-a3b22fcbea4d","event_type":"raw.trade","source":"binance_market_data_recorder","venue":"binance_usdm","market_type":"perpetual_futures","symbol":"ETHUSDT","event_time_ms":1783517068010,"received_time_ms":1783517068012,"trace_id":"f214242b-9e80-42df-81c5-46dd570dfa39","trade_id":8429826863,"price":"1736.12","quantity":"0.140","trade_time_ms":1783517068010,"is_buyer_maker":true,"aggressor_side":"sell","raw":{"e":"trade","E":1783517068010,"T":1783517068010,"s":"ETHUSDT","t":8429826863,"p":"1736.12","q":"0.140","X":"MARKET","m":true,"st":1}}
{"schema_version":"1.3.0","event_id":"92ce9b95-7c4a-4c94-80b1-400fb2175e1a","event_type":"raw.trade","source":"binance_market_data_recorder","venue":"binance_usdm","market_type":"perpetual_futures","symbol":"ETHUSDT","event_time_ms":1783517068010,"received_time_ms":1783517068013,"trace_id":"53def6b8-1775-4cd4-8286-145ccd9c4203","trade_id":8429826864,"price":"1736.12","quantity":"0.001","trade_time_ms":1783517068010,"is_buyer_maker":true,"aggressor_side":"sell","raw":{"e":"trade","E":1783517068010,"T":1783517068010,"s":"ETHUSDT","t":8429826864,"p":"1736.12","q":"0.001","X":"MARKET","m":true,"st":1}}
{"schema_version":"1.3.0","event_id":"32768e1b-cbe1-4551-bfff-bfc10d2d390a","event_type":"raw.trade","source":"binance_market_data_recorder","venue":"binance_usdm","market_type":"perpetual_futures","symbol":"ETHUSDT","event_time_ms":1783517068010,"received_time_ms":1783517068013,"trace_id":"acf58b1b-4ce9-4fcd-a942-f8d1b1eefdde","trade_id":8429826865,"price":"1736.12","quantity":"0.001","trade_time_ms":1783517068010,"is_buyer_maker":true,"aggressor_side":"sell","raw":{"e":"trade","E":1783517068010,"T":1783517068010,"s":"ETHUSDT","t":8429826865,"p":"1736.12","q":"0.001","X":"MARKET","m":true,"st":1}}
{"schema_version":"1.3.0","event_id":"1c49897b-aa30-47dc-9ee0-a023fd4b4d2a","event_type":"raw.trade","source":"binance_market_data_recorder","venue":"binance_usdm","market_type":"perpetual_futures","symbol":"ETHUSDT","event_time_ms":1783517068010,"received_time_ms":1783517068014,"trace_id":"6346a824-d985-47cd-a26d-820cf6c2d3e1","trade_id":8429826866,"price":"1736.12","quantity":"0.001","trade_time_ms":1783517068010,"is_buyer_maker":true,"aggressor_side":"sell","raw":{"e":"trade","E":1783517068010,"T":1783517068010,"s":"ETHUSDT","t":8429826866,"p":"1736.12","q":"0.001","X":"MARKET","m":true,"st":1}}
{"schema_version":"1.3.0","event_id":"17a8e95f-a8e6-4fd4-a9af-08c8b9a15f9d","event_type":"raw.trade","source":"binance_market_data_recorder","venue":"binance_usdm","market_type":"perpetual_futures","symbol":"ETHUSDT","event_time_ms":1783517068010,"received_time_ms":1783517068014,"trace_id":"0f9e608b-ca81-4df3-8b46-a69b480c023d","trade_id":8429826867,"price":"1736.12","quantity":"0.001","trade_time_ms":1783517068010,"is_buyer_maker":true,"aggressor_side":"sell","raw":{"e":"trade","E":1783517068010,"T":1783517068010,"s":"ETHUSDT","t":8429826867,"p":"1736.12","q":"0.001","X":"MARKET","m":true,"st":1}}
{"schema_version":"1.3.0","event_id":"3823830b-abd7-4a61-9b99-6d17470d792e","event_type":"raw.trade","source":"binance_market_data_recorder","venue":"binance_usdm","market_type":"perpetual_futures","symbol":"ETHUSDT","event_time_ms":1783517068010,"received_time_ms":1783517068015,"trace_id":"544bc23b-9ca8-41e0-852a-978f68ba0c2f","trade_id":8429826868,"price":"1736.12","quantity":"0.001","trade_time_ms":1783517068010,"is_buyer_maker":true,"aggressor_side":"sell","raw":{"e":"trade","E":1783517068010,"T":1783517068010,"s":"ETHUSDT","t":8429826868,"p":"1736.12","q":"0.001","X":"MARKET","m":true,"st":1}}
{"schema_version":"1.3.0","event_id":"f375c0a4-2400-48f9-a344-d14e506d4d89","event_type":"raw.trade","source":"binance_market_data_recorder","venue":"binance_usdm","market_type":"perpetual_futures","symbol":"ETHUSDT","event_time_ms":1783517068010,"received_time_ms":1783517068015,"trace_id":"b3e7a24a-be6f-4e6f-9a98-d9357411122f","trade_id":8429826869,"price":"1736.12","quantity":"0.001","trade_time_ms":1783517068010,"is_buyer_maker":true,"aggressor_side":"sell","raw":{"e":"trade","E":1783517068010,"T":1783517068010,"s":"ETHUSDT","t":8429826869,"p":"1736.12","q":"0.001","X":"MARKET","m":true,"st":1}}
{"schema_version":"1.3.0","event_id":"2c85cc42-47b5-45f7-86a4-d064d213716d","event_type":"raw.trade","source":"binance_market_data_recorder","venue":"binance_usdm","market_type":"perpetual_futures","symbol":"ETHUSDT","event_time_ms":1783517068010,"received_time_ms":1783517068016,"trace_id":"cc7d2691-220b-43eb-b78d-254911fd45c8","trade_id":8429826870,"price":"1736.12","quantity":"0.001","trade_time_ms":1783517068010,"is_buyer_maker":true,"aggressor_side":"sell","raw":{"e":"trade","E":1783517068010,"T":1783517068010,"s":"ETHUSDT","t":8429826870,"p":"1736.12","q":"0.001","X":"MARKET","m":true,"st":1}}
{"schema_version":"1.3.0","event_id":"f3b4d193-5cd7-4549-850c-6f1a99421866","event_type":"raw.trade","source":"binance_market_data_recorder","venue":"binance_usdm","market_type":"perpetual_futures","symbol":"ETHUSDT","event_time_ms":1783517068010,"received_time_ms":1783517068016,"trace_id":"0471823f-fead-4a9a-81b8-10816e150a86","trade_id":8429826871,"price":"1736.12","quantity":"0.001","trade_time_ms":1783517068010,"is_buyer_maker":true,"aggressor_side":"sell","raw":{"e":"trade","E":1783517068010,"T":1783517068010,"s":"ETHUSDT","t":8429826871,"p":"1736.12","q":"0.001","X":"MARKET","m":true,"st":1}}
{"schema_version":"1.3.0","event_id":"ac3e5532-8c59-4d17-b968-3e4b152046b3","event_type":"raw.trade","source":"binance_market_data_recorder","venue":"binance_usdm","market_type":"perpetual_futures","symbol":"ETHUSDT","event_time_ms":1783517068010,"received_time_ms":1783517068017,"trace_id":"3d069ea8-5c79-430a-bbda-5b37c974de6b","trade_id":8429826872,"price":"1736.12","quantity":"0.001","trade_time_ms":1783517068010,"is_buyer_maker":true,"aggressor_side":"sell","raw":{"e":"trade","E":1783517068010,"T":1783517068010,"s":"ETHUSDT","t":8429826872,"p":"1736.12","q":"0.001","X":"MARKET","m":true,"st":1}}
{"schema_version":"1.3.0","event_id":"6910237d-8fda-4275-8076-030ac84c528e","event_type":"raw.trade","source":"binance_market_data_recorder","venue":"binance_usdm","market_type":"perpetual_futures","symbol":"ETHUSDT","event_time_ms":1783517068010,"received_time_ms":1783517068017,"trace_id":"8fa99184-8ca0-459b-ab15-2320f11d4798","trade_id":8429826873,"price":"1736.12","quantity":"0.001","trade_time_ms":1783517068010,"is_buyer_maker":true,"aggressor_side":"sell","raw":{"e":"trade","E":1783517068010,"T":1783517068010,"s":"ETHUSDT","t":8429826873,"p":"1736.12","q":"0.001","X":"MARKET","m":true,"st":1}}
{"schema_version":"1.3.0","event_id":"c326cb1d-90ce-4823-b438-3505d6ce8931","event_type":"raw.trade","source":"binance_market_data_recorder","venue":"binance_usdm","market_type":"perpetual_futures","symbol":"ETHUSDT","event_time_ms":1783517068010,"received_time_ms":1783517068017,"trace_id":"e47f9104-6fc4-4a9d-89da-25295625925e","trade_id":8429826874,"price":"1736.12","quantity":"0.001","trade_time_ms":1783517068010,"is_buyer_maker":true,"aggressor_side":"sell","raw":{"e":"trade","E":1783517068010,"T":1783517068010,"s":"ETHUSDT","t":8429826874,"p":"1736.12","q":"0.001","X":"MARKET","m":true,"st":1}}
{"schema_version":"1.3.0","event_id":"30002a6d-1e53-4e50-8f7b-9c3c6312fbff","event_type":"raw.trade","source":"binance_market_data_recorder","venue":"binance_usdm","market_type":"perpetual_futures","symbol":"ETHUSDT","event_time_ms":1783517068010,"received_time_ms":1783517068018,"trace_id":"87341574-78a3-42df-a391-f9604e4f84ff","trade_id":8429826875,"price":"1736.12","quantity":"0.001","trade_time_ms":1783517068010,"is_buyer_maker":true,"aggressor_side":"sell","raw":{"e":"trade","E":1783517068010,"T":1783517068010,"s":"ETHUSDT","t":8429826875,"p":"1736.12","q":"0.001","X":"MARKET","m":true,"st":1}}
{"schema_version":"1.3.0","event_id":"780e8869-3caa-47a6-92d2-5ee5658bad53","event_type":"raw.trade","source":"binance_market_data_recorder","venue":"binance_usdm","market_type":"perpetual_futures","symbol":"ETHUSDT","event_time_ms":1783517068010,"received_time_ms":1783517068018,"trace_id":"fc4ec6c0-3480-43ce-afe9-f9596f9feba7","trade_id":8429826876,"price":"1736.12","quantity":"0.001","trade_time_ms":1783517068010,"is_buyer_maker":true,"aggressor_side":"sell","raw":{"e":"trade","E":1783517068010,"T":1783517068010,"s":"ETHUSDT","t":8429826876,"p":"1736.12","q":"0.001","X":"MARKET","m":true,"st":1}}
{"schema_version":"1.3.0","event_id":"ecdce1c3-9aec-4616-b826-109268d7e12c","event_type":"raw.trade","source":"binance_market_data_recorder","venue":"binance_usdm","market_type":"perpetual_futures","symbol":"ETHUSDT","event_time_ms":1783517068010,"received_time_ms":1783517068019,"trace_id":"28d38ce9-7cd9-4e4a-8b26-1112f3d934c2","trade_id":8429826877,"price":"1736.12","quantity":"0.001","trade_time_ms":1783517068010,"is_buyer_maker":true,"aggressor_side":"sell","raw":{"e":"trade","E":1783517068010,"T":1783517068010,"s":"ETHUSDT","t":8429826877,"p":"1736.12","q":"0.001","X":"MARKET","m":true,"st":1}}
{"schema_version":"1.3.0","event_id":"0b8341c7-35b4-4867-9631-529a8e821c93","event_type":"raw.trade","source":"binance_market_data_recorder","venue":"binance_usdm","market_type":"perpetual_futures","symbol":"ETHUSDT","event_time_ms":1783517068010,"received_time_ms":1783517068019,"trace_id":"1b220fb8-b16e-4c37-9a6d-5c418a434293","trade_id":8429826878,"price":"1736.12","quantity":"0.001","trade_time_ms":1783517068010,"is_buyer_maker":true,"aggressor_side":"sell","raw":{"e":"trade","E":1783517068010,"T":1783517068010,"s":"ETHUSDT","t":8429826878,"p":"1736.12","q":"0.001","X":"MARKET","m":true,"st":1}}
{"schema_version":"1.3.0","event_id":"941118e9-5e9a-47a8-b2ed-3ee17f73a6e5","event_type":"raw.trade","source":"binance_market_data_recorder","venue":"binance_usdm","market_type":"perpetual_futures","symbol":"ETHUSDT","event_time_ms":1783517068010,"received_time_ms":1783517068020,"trace_id":"135ef225-0b67-4b3c-bdfb-c57bea5cbc33","trade_id":8429826879,"price":"1736.12","quantity":"0.001","trade_time_ms":1783517068010,"is_buyer_maker":true,"aggressor_side":"sell","raw":{"e":"trade","E":1783517068010,"T":1783517068010,"s":"ETHUSDT","t":8429826879,"p":"1736.12","q":"0.001","X":"MARKET","m":true,"st":1}}
{"schema_version":"1.3.0","event_id":"cbcc8e1b-6cba-4f95-a600-7c6e75a8361a","event_type":"raw.trade","source":"binance_market_data_recorder","venue":"binance_usdm","market_type":"perpetual_futures","symbol":"ETHUSDT","event_time_ms":1783517068010,"received_time_ms":1783517068020,"trace_id":"41100720-3e73-4650-8743-36e106cdc50e","trade_id":8429826880,"price":"1736.12","quantity":"0.001","trade_time_ms":1783517068010,"is_buyer_maker":true,"aggressor_side":"sell","raw":{"e":"trade","E":1783517068010,"T":1783517068010,"s":"ETHUSDT","t":8429826880,"p":"1736.12","q":"0.001","X":"MARKET","m":true,"st":1}}
{"schema_version":"1.3.0","event_id":"b0c938b0-5bde-4720-84ae-bc832c6588d7","event_type":"raw.trade","source":"binance_market_data_recorder","venue":"binance_usdm","market_type":"perpetual_futures","symbol":"ETHUSDT","event_time_ms":1783517068010,"received_time_ms":1783517068020,"trace_id":"ffd67125-0dbd-47bb-8618-54eca2daffa5","trade_id":8429826881,"price":"1736.12","quantity":"0.001","trade_time_ms":1783517068010,"is_buyer_maker":true,"aggressor_side":"sell","raw":{"e":"trade","E":1783517068010,"T":1783517068010,"s":"ETHUSDT","t":8429826881,"p":"1736.12","q":"0.001","X":"MARKET","m":true,"st":1}}
{"schema_version":"1.3.0","event_id":"79dd3376-7917-49bf-9b85-638058589c1a","event_type":"raw.trade","source":"binance_market_data_recorder","venue":"binance_usdm","market_type":"perpetual_futures","symbol":"ETHUSDT","event_time_ms":1783517068010,"received_time_ms":1783517068021,"trace_id":"ac18a6bb-7193-4895-a3d4-07a034f0c2a8","trade_id":8429826882,"price":"1736.12","quantity":"0.200","trade_time_ms":1783517068010,"is_buyer_maker":true,"aggressor_side":"sell","raw":{"e":"trade","E":1783517068010,"T":1783517068010,"s":"ETHUSDT","t":8429826882,"p":"1736.12","q":"0.200","X":"MARKET","m":true,"st":1}}
{"schema_version":"1.3.0","event_id":"13eb5de9-b959-403c-b713-f5152c908364","event_type":"raw.trade","source":"binance_market_data_recorder","venue":"binance_usdm","market_type":"perpetual_futures","symbol":"ETHUSDT","event_time_ms":1783517068010,"received_time_ms":1783517068022,"trace_id":"8291bf9c-8aaf-4180-bbca-5c94d9abe477","trade_id":8429826883,"price":"1736.12","quantity":"0.012","trade_time_ms":1783517068010,"is_buyer_maker":true,"aggressor_side":"sell","raw":{"e":"trade","E":1783517068010,"T":1783517068010,"s":"ETHUSDT","t":8429826883,"p":"1736.12","q":"0.012","X":"MARKET","m":true,"st":1}}
{"schema_version":"1.3.0","event_id":"1dab7b7e-c46d-4393-ae54-cafddd88ba08","event_type":"raw.trade","source":"binance_market_data_recorder","venue":"binance_usdm","market_type":"perpetual_futures","symbol":"ETHUSDT","event_time_ms":1783517068010,"received_time_ms":1783517068022,"trace_id":"bf328117-874a-4585-bb67-e89638300145","trade_id":8429826884,"price":"1736.12","quantity":"0.012","trade_time_ms":1783517068010,"is_buyer_maker":true,"aggressor_side":"sell","raw":{"e":"trade","E":1783517068010,"T":1783517068010,"s":"ETHUSDT","t":8429826884,"p":"1736.12","q":"0.012","X":"MARKET","m":true,"st":1}}
{"schema_version":"1.3.0","event_id":"cf5f57a7-3244-4183-9e26-4bbbb6d8f8ae","event_type":"raw.trade","source":"binance_market_data_recorder","venue":"binance_usdm","market_type":"perpetual_futures","symbol":"ETHUSDT","event_time_ms":1783517068011,"received_time_ms":1783517068022,"trace_id":"df57581f-b99a-4785-be03-1153d5869623","trade_id":8429826885,"price":"1736.12","quantity":"0.921","trade_time_ms":1783517068010,"is_buyer_maker":true,"aggressor_side":"sell","raw":{"e":"trade","E":1783517068011,"T":1783517068010,"s":"ETHUSDT","t":8429826885,"p":"1736.12","q":"0.921","X":"MARKET","m":true,"st":1}}
{"schema_version":"1.3.0","event_id":"be5edca6-70e6-4548-88a1-e08b65fa46da","event_type":"raw.trade","source":"binance_market_data_recorder","venue":"binance_usdm","market_type":"perpetual_futures","symbol":"ETHUSDT","event_time_ms":1783517068011,"received_time_ms":1783517068023,"trace_id":"aa235ebd-7592-46dd-8024-da8a0f73d4e2","trade_id":8429826886,"price":"1736.12","quantity":"0.012","trade_time_ms":1783517068010,"is_buyer_maker":true,"aggressor_side":"sell","raw":{"e":"trade","E":1783517068011,"T":1783517068010,"s":"ETHUSDT","t":8429826886,"p":"1736.12","q":"0.012","X":"MARKET","m":true,"st":1}}
{"schema_version":"1.3.0","event_id":"a22a6e0b-f101-44a8-9347-9a141aae0916","event_type":"raw.trade","source":"binance_market_data_recorder","venue":"binance_usdm","market_type":"perpetual_futures","symbol":"ETHUSDT","event_time_ms":1783517068011,"received_time_ms":1783517068023,"trace_id":"513737ff-d36e-4542-8c53-c8592659ce2e","trade_id":8429826887,"price":"1736.12","quantity":"0.012","trade_time_ms":1783517068010,"is_buyer_maker":true,"aggressor_side":"sell","raw":{"e":"trade","E":1783517068011,"T":1783517068010,"s":"ETHUSDT","t":8429826887,"p":"1736.12","q":"0.012","X":"MARKET","m":true,"st":1}}
{"schema_version":"1.3.0","event_id":"7c625746-849b-4442-97a5-0efcce02756a","event_type":"raw.trade","source":"binance_market_data_recorder","venue":"binance_usdm","market_type":"perpetual_futures","symbol":"ETHUSDT","event_time_ms":1783517068011,"received_time_ms":1783517068023,"trace_id":"6bc6e859-0c73-4554-ac0a-dd87a7a0a531","trade_id":8429826888,"price":"1736.12","quantity":"0.012","trade_time_ms":1783517068010,"is_buyer_maker":true,"aggressor_side":"sell","raw":{"e":"trade","E":1783517068011,"T":1783517068010,"s":"ETHUSDT","t":8429826888,"p":"1736.12","q":"0.012","X":"MARKET","m":true,"st":1}}
{"schema_version":"1.3.0","event_id":"90c2e57a-5f86-4519-93fb-dff1fe858aef","event_type":"raw.trade","source":"binance_market_data_recorder","venue":"binance_usdm","market_type":"perpetual_futures","symbol":"ETHUSDT","event_time_ms":1783517068011,"received_time_ms":1783517068024,"trace_id":"fa0b8f78-3233-40ab-8d71-af949caae8d0","trade_id":8429826889,"price":"1736.12","quantity":"0.013","trade_time_ms":1783517068010,"is_buyer_maker":true,"aggressor_side":"sell","raw":{"e":"trade","E":1783517068011,"T":1783517068010,"s":"ETHUSDT","t":8429826889,"p":"1736.12","q":"0.013","X":"MARKET","m":true,"st":1}}
{"schema_version":"1.3.0","event_id":"45835704-1acf-4547-9972-84ad50a3c1c9","event_type":"raw.trade","source":"binance_market_data_recorder","venue":"binance_usdm","market_type":"perpetual_futures","symbol":"ETHUSDT","event_time_ms":1783517068011,"received_time_ms":1783517068024,"trace_id":"8eef7f3b-e0be-4a3a-afb3-bb6884471c4d","trade_id":8429826890,"price":"1736.12","quantity":"0.165","trade_time_ms":1783517068010,"is_buyer_maker":true,"aggressor_side":"sell","raw":{"e":"trade","E":1783517068011,"T":1783517068010,"s":"ETHUSDT","t":8429826890,"p":"1736.12","q":"0.165","X":"MARKET","m":true,"st":1}}
{"schema_version":"1.3.0","event_id":"26b394f9-b10f-44ed-947d-adf27c952be7","event_type":"raw.trade","source":"binance_market_data_recorder","venue":"binance_usdm","market_type":"perpetual_futures","symbol":"ETHUSDT","event_time_ms":1783517068011,"received_time_ms":1783517068025,"trace_id":"722eb36d-1b0e-4139-bca7-2792e81d0d47","trade_id":8429826891,"price":"1736.12","quantity":"0.014","trade_time_ms":1783517068010,"is_buyer_maker":true,"aggressor_side":"sell","raw":{"e":"trade","E":1783517068011,"T":1783517068010,"s":"ETHUSDT","t":8429826891,"p":"1736.12","q":"0.014","X":"MARKET","m":true,"st":1}}
{"schema_version":"1.3.0","event_id":"d54b494e-8e3f-4423-a4bc-c7a216d1d478","event_type":"raw.trade","source":"binance_market_data_recorder","venue":"binance_usdm","market_type":"perpetual_futures","symbol":"ETHUSDT","event_time_ms":1783517068011,"received_time_ms":1783517068025,"trace_id":"10e48b22-fa4a-4621-9396-f748170e1ad8","trade_id":8429826892,"price":"1736.12","quantity":"0.012","trade_time_ms":1783517068010,"is_buyer_maker":true,"aggressor_side":"sell","raw":{"e":"trade","E":1783517068011,"T":1783517068010,"s":"ETHUSDT","t":8429826892,"p":"1736.12","q":"0.012","X":"MARKET","m":true,"st":1}}
{"schema_version":"1.3.0","event_id":"110803a8-8a53-43f0-b055-b824ad86882b","event_type":"raw.trade","source":"binance_market_data_recorder","venue":"binance_usdm","market_type":"perpetual_futures","symbol":"ETHUSDT","event_time_ms":1783517068011,"received_time_ms":1783517068025,"trace_id":"80ca84f8-cf20-4f79-b843-37980c3a385c","trade_id":8429826893,"price":"1736.12","quantity":"0.012","trade_time_ms":1783517068010,"is_buyer_maker":true,"aggressor_side":"sell","raw":{"e":"trade","E":1783517068011,"T":1783517068010,"s":"ETHUSDT","t":8429826893,"p":"1736.12","q":"0.012","X":"MARKET","m":true,"st":1}}
{"schema_version":"1.3.0","event_id":"0f997ef4-b696-4621-96d3-6aaeb561fec7","event_type":"raw.trade","source":"binance_market_data_recorder","venue":"binance_usdm","market_type":"perpetual_futures","symbol":"ETHUSDT","event_time_ms":1783517068011,"received_time_ms":1783517068026,"trace_id":"8fddaec0-ec4a-406f-87f8-d90b328c8968","trade_id":8429826894,"price":"1736.12","quantity":"0.178","trade_time_ms":1783517068010,"is_buyer_maker":true,"aggressor_side":"sell","raw":{"e":"trade","E":1783517068011,"T":1783517068010,"s":"ETHUSDT","t":8429826894,"p":"1736.12","q":"0.178","X":"MARKET","m":true,"st":1}}
{"schema_version":"1.3.0","event_id":"167057d9-981b-4b33-acb1-e4e2b88513ce","event_type":"raw.trade","source":"binance_market_data_recorder","venue":"binance_usdm","market_type":"perpetual_futures","symbol":"ETHUSDT","event_time_ms":1783517068011,"received_time_ms":1783517068026,"trace_id":"0bb79897-46f2-4f38-9832-bb348b87bbd7","trade_id":8429826895,"price":"1736.12","quantity":"0.055","trade_time_ms":1783517068010,"is_buyer_maker":true,"aggressor_side":"sell","raw":{"e":"trade","E":1783517068011,"T":1783517068010,"s":"ETHUSDT","t":8429826895,"p":"1736.12","q":"0.055","X":"MARKET","m":true,"st":1}}
{"schema_version":"1.3.0","event_id":"7188e6be-7083-4f5c-ab9f-e066db1c1cea","event_type":"raw.trade","source":"binance_market_data_recorder","venue":"binance_usdm","market_type":"perpetual_futures","symbol":"ETHUSDT","event_time_ms":1783517068011,"received_time_ms":1783517068027,"trace_id":"3ca2bca1-85f0-4f11-ba7a-368b4148ef00","trade_id":8429826896,"price":"1736.12","quantity":"0.057","trade_time_ms":1783517068010,"is_buyer_maker":true,"aggressor_side":"sell","raw":{"e":"trade","E":1783517068011,"T":1783517068010,"s":"ETHUSDT","t":8429826896,"p":"1736.12","q":"0.057","X":"MARKET","m":true,"st":1}}
{"schema_version":"1.3.0","event_id":"85de6c72-951a-4dcb-9fa2-61c7c1841478","event_type":"raw.trade","source":"binance_market_data_recorder","venue":"binance_usdm","market_type":"perpetual_futures","symbol":"ETHUSDT","event_time_ms":1783517068011,"received_time_ms":1783517068027,"trace_id":"c1f49258-5356-49e2-bfe4-021ad5ecc330","trade_id":8429826897,"price":"1736.12","quantity":"0.066","trade_time_ms":1783517068010,"is_buyer_maker":true,"aggressor_side":"sell","raw":{"e":"trade","E":1783517068011,"T":1783517068010,"s":"ETHUSDT","t":8429826897,"p":"1736.12","q":"0.066","X":"MARKET","m":true,"st":1}}
{"schema_version":"1.3.0","event_id":"48cd6754-9c6e-4b06-8df7-048da4c9fa8b","event_type":"raw.trade","source":"binance_market_data_recorder","venue":"binance_usdm","market_type":"perpetual_futures","symbol":"ETHUSDT","event_time_ms":1783517068011,"received_time_ms":1783517068027,"trace_id":"ca3ca06b-8028-4e33-a74c-6f82c668e23b","trade_id":8429826898,"price":"1736.12","quantity":"10.633","trade_time_ms":1783517068010,"is_buyer_maker":true,"aggressor_side":"sell","raw":{"e":"trade","E":1783517068011,"T":1783517068010,"s":"ETHUSDT","t":8429826898,"p":"1736.12","q":"10.633","X":"MARKET","m":true,"st":1}}
{"schema_version":"1.3.0","event_id":"b266132e-2b5c-4fe3-9822-c7b76d1c609e","event_type":"raw.trade","source":"binance_market_data_recorder","venue":"binance_usdm","market_type":"perpetual_futures","symbol":"ETHUSDT","event_time_ms":1783517068011,"received_time_ms":1783517068028,"trace_id":"1db4cdc3-8a10-47ee-9abb-4182702d6c47","trade_id":8429826899,"price":"1736.12","quantity":"0.126","trade_time_ms":1783517068010,"is_buyer_maker":true,"aggressor_side":"sell","raw":{"e":"trade","E":1783517068011,"T":1783517068010,"s":"ETHUSDT","t":8429826899,"p":"1736.12","q":"0.126","X":"MARKET","m":true,"st":1}}
{"schema_version":"1.3.0","event_id":"aa73139b-cf41-40eb-8084-e8b96ce372be","event_type":"raw.trade","source":"binance_market_data_recorder","venue":"binance_usdm","market_type":"perpetual_futures","symbol":"ETHUSDT","event_time_ms":1783517068011,"received_time_ms":1783517068028,"trace_id":"cbd85eb2-8768-4859-a918-bd9e1d7b70b4","trade_id":8429826900,"price":"1736.12","quantity":"0.643","trade_time_ms":1783517068010,"is_buyer_maker":true,"aggressor_side":"sell","raw":{"e":"trade","E":1783517068011,"T":1783517068010,"s":"ETHUSDT","t":8429826900,"p":"1736.12","q":"0.643","X":"MARKET","m":true,"st":1}}
{"schema_version":"1.3.0","event_id":"07dff173-c3b6-4831-a5bc-c73a679ead06","event_type":"raw.trade","source":"binance_market_data_recorder","venue":"binance_usdm","market_type":"perpetual_futures","symbol":"ETHUSDT","event_time_ms":1783517068011,"received_time_ms":1783517068029,"trace_id":"c9b66ba4-d79e-4516-a5c4-e3469a07402d","trade_id":8429826901,"price":"1736.12","quantity":"10.476","trade_time_ms":1783517068010,"is_buyer_maker":true,"aggressor_side":"sell","raw":{"e":"trade","E":1783517068011,"T":1783517068010,"s":"ETHUSDT","t":8429826901,"p":"1736.12","q":"10.476","X":"MARKET","m":true,"st":1}}
{"schema_version":"1.3.0","event_id":"74e0fb88-9718-42ec-ac18-3c4c28acc14e","event_type":"raw.depth_update","source":"binance_market_data_recorder","venue":"binance_usdm","market_type":"perpetual_futures","symbol":"BTCUSDT","event_time_ms":1783517068026,"received_time_ms":1783517068040,"trace_id":"40a05289-3a69-41aa-b209-59073a86b298","first_update_id":10999770680381,"final_update_id":10999770688919,"previous_final_update_id":10999770680289,"bids":[{"price":"11352.20","quantity":"0.256"},{"price":"11353.70","quantity":"0.992"},{"price":"11453.70","quantity":"1.428"},{"price":"11753.70","quantity":"2.208"},{"price":"55668.30","quantity":"0.002"},{"price":"58761.00","quantity":"0.006"},{"price":"59379.50","quantity":"0.001"},{"price":"61080.50","quantity":"0.246"},{"price":"61180.00","quantity":"1.630"},{"price":"61235.20","quantity":"0.025"},{"price":"61295.00","quantity":"1.173"},{"price":"61608.80","quantity":"0.202"},{"price":"61723.00","quantity":"0.709"},{"price":"61821.00","quantity":"0.999"},{"price":"61821.10","quantity":"0.863"},{"price":"61821.20","quantity":"0.597"},{"price":"61835.40","quantity":"0.003"},{"price":"61835.50","quantity":"1.014"},{"price":"61835.60","quantity":"0.131"},{"price":"61836.00","quantity":"0.064"},{"price":"61836.50","quantity":"0.023"},{"price":"61836.70","quantity":"0.003"},{"price":"61837.10","quantity":"0.002"},{"price":"61838.40","quantity":"0.014"},{"price":"61838.80","quantity":"0.012"},{"price":"61841.80","quantity":"0.106"},{"price":"61842.00","quantity":"0.371"},{"price":"61842.50","quantity":"0.674"},{"price":"61843.10","quantity":"0.153"},{"price":"61843.80","quantity":"0.272"},{"price":"61844.80","quantity":"0.118"},{"price":"61844.90","quantity":"0.033"},{"price":"61850.10","quantity":"0.050"},{"price":"61850.20","quantity":"0.002"},{"price":"61853.60","quantity":"0.002"},{"price":"61853.70","quantity":"2.513"}],"asks":[{"price":"61853.80","quantity":"8.383"},{"price":"61860.00","quantity":"0.467"},{"price":"61866.20","quantity":"0.570"},{"price":"61867.60","quantity":"0.345"},{"price":"61868.20","quantity":"0.065"},{"price":"61872.40","quantity":"0.007"},{"price":"61873.80","quantity":"1.292"},{"price":"61949.40","quantity":"0.021"},{"price":"61985.80","quantity":"0.008"},{"price":"61986.30","quantity":"0.345"},{"price":"62472.30","quantity":"0.000"},{"price":"62700.60","quantity":"0.796"},{"price":"62812.50","quantity":"1.127"},{"price":"62844.20","quantity":"0.682"}],"raw":{"e":"depthUpdate","E":1783517068026,"T":1783517068025,"s":"BTCUSDT","ps":"BTCUSDT","U":10999770680381,"u":10999770688919,"pu":10999770680289,"b":[["11352.20","0.256"],["11353.70","0.992"],["11453.70","1.428"],["11753.70","2.208"],["55668.30","0.002"],["58761.00","0.006"],["59379.50","0.001"],["61080.50","0.246"],["61180.00","1.630"],["61235.20","0.025"],["61295.00","1.173"],["61608.80","0.202"],["61723.00","0.709"],["61821.00","0.999"],["61821.10","0.863"],["61821.20","0.597"],["61835.40","0.003"],["61835.50","1.014"],["61835.60","0.131"],["61836.00","0.064"],["61836.50","0.023"],["61836.70","0.003"],["61837.10","0.002"],["61838.40","0.014"],["61838.80","0.012"],["61841.80","0.106"],["61842.00","0.371"],["61842.50","0.674"],["61843.10","0.153"],["61843.80","0.272"],["61844.80","0.118"],["61844.90","0.033"],["61850.10","0.050"],["61850.20","0.002"],["61853.60","0.002"],["61853.70","2.513"]],"a":[["61853.80","8.383"],["61860.00","0.467"],["61866.20","0.570"],["61867.60","0.345"],["61868.20","0.065"],["61872.40","0.007"],["61873.80","1.292"],["61949.40","0.021"],["61985.80","0.008"],["61986.30","0.345"],["62472.30","0.000"],["62700.60","0.796"],["62812.50","1.127"],["62844.20","0.682"]],"st":1}}
{"schema_version":"1.3.0","event_id":"0a8bfaa3-ee45-430a-aada-876aa42c2d49","event_type":"raw.trade","source":"binance_market_data_recorder","venue":"binance_usdm","market_type":"perpetual_futures","symbol":"BTCUSDT","event_time_ms":1783517068066,"received_time_ms":1783517068061,"trace_id":"0a472d51-5302-4bfd-ba5e-e0b4aac58801","trade_id":7881418056,"price":"61853.80","quantity":"0.095","trade_time_ms":1783517068066,"is_buyer_maker":false,"aggressor_side":"buy","raw":{"e":"trade","E":1783517068066,"T":1783517068066,"s":"BTCUSDT","t":7881418056,"p":"61853.80","q":"0.095","X":"MARKET","m":false,"st":1}}
{"schema_version":"1.3.0","event_id":"e32fe19c-a85b-44e5-89a3-df66d4d4b90e","event_type":"raw.trade","source":"binance_market_data_recorder","venue":"binance_usdm","market_type":"perpetual_futures","symbol":"ETHUSDT","event_time_ms":1783517068072,"received_time_ms":1783517068081,"trace_id":"2a105fe7-26d3-44ef-8b25-205e05eb09fc","trade_id":8429826902,"price":"1736.12","quantity":"0.101","trade_time_ms":1783517068072,"is_buyer_maker":true,"aggressor_side":"sell","raw":{"e":"trade","E":1783517068072,"T":1783517068072,"s":"ETHUSDT","t":8429826902,"p":"1736.12","q":"0.101","X":"MARKET","m":true,"st":1}}
{"schema_version":"1.3.0","event_id":"bb4194db-6a94-4b49-9912-4c206601aece","event_type":"raw.trade","source":"binance_market_data_recorder","venue":"binance_usdm","market_type":"perpetual_futures","symbol":"ETHUSDT","event_time_ms":1783517068072,"received_time_ms":1783517068081,"trace_id":"0179b590-8359-401d-9ce6-781325e0d82f","trade_id":8429826903,"price":"1736.12","quantity":"0.021","trade_time_ms":1783517068072,"is_buyer_maker":true,"aggressor_side":"sell","raw":{"e":"trade","E":1783517068072,"T":1783517068072,"s":"ETHUSDT","t":8429826903,"p":"1736.12","q":"0.021","X":"MARKET","m":true,"st":1}}
{"schema_version":"1.3.0","event_id":"375df6ef-9184-463d-a742-5ca23f87084c","event_type":"raw.trade","source":"binance_market_data_recorder","venue":"binance_usdm","market_type":"perpetual_futures","symbol":"ETHUSDT","event_time_ms":1783517068072,"received_time_ms":1783517068082,"trace_id":"abf14176-3af8-4262-b20e-f7da88cd1d5e","trade_id":8429826904,"price":"1736.12","quantity":"0.015","trade_time_ms":1783517068072,"is_buyer_maker":true,"aggressor_side":"sell","raw":{"e":"trade","E":1783517068072,"T":1783517068072,"s":"ETHUSDT","t":8429826904,"p":"1736.12","q":"0.015","X":"MARKET","m":true,"st":1}}
{"schema_version":"1.3.0","event_id":"ee7a16e2-ea6d-4027-9278-df978f88290f","event_type":"raw.trade","source":"binance_market_data_recorder","venue":"binance_usdm","market_type":"perpetual_futures","symbol":"ETHUSDT","event_time_ms":1783517068072,"received_time_ms":1783517068083,"trace_id":"af7604a9-25fd-48b5-83e5-3aaac88d19ad","trade_id":8429826905,"price":"1736.12","quantity":"0.012","trade_time_ms":1783517068072,"is_buyer_maker":true,"aggressor_side":"sell","raw":{"e":"trade","E":1783517068072,"T":1783517068072,"s":"ETHUSDT","t":8429826905,"p":"1736.12","q":"0.012","X":"MARKET","m":true,"st":1}}
{"schema_version":"1.3.0","event_id":"a95f999b-fd1d-4215-98d8-68b9e77b6796","event_type":"raw.trade","source":"binance_market_data_recorder","venue":"binance_usdm","market_type":"perpetual_futures","symbol":"ETHUSDT","event_time_ms":1783517068072,"received_time_ms":1783517068083,"trace_id":"a61d2981-4ad7-4456-8916-d154e53e5a2a","trade_id":8429826906,"price":"1736.12","quantity":"0.014","trade_time_ms":1783517068072,"is_buyer_maker":true,"aggressor_side":"sell","raw":{"e":"trade","E":1783517068072,"T":1783517068072,"s":"ETHUSDT","t":8429826906,"p":"1736.12","q":"0.014","X":"MARKET","m":true,"st":1}}
{"schema_version":"1.3.0","event_id":"00fecc2f-33c4-4107-9370-78d118ba891f","event_type":"raw.trade","source":"binance_market_data_recorder","venue":"binance_usdm","market_type":"perpetual_futures","symbol":"ETHUSDT","event_time_ms":1783517068072,"received_time_ms":1783517068083,"trace_id":"176ae917-0975-4d16-8dc5-28972cedcd18","trade_id":8429826907,"price":"1736.12","quantity":"0.012","trade_time_ms":1783517068072,"is_buyer_maker":true,"aggressor_side":"sell","raw":{"e":"trade","E":1783517068072,"T":1783517068072,"s":"ETHUSDT","t":8429826907,"p":"1736.12","q":"0.012","X":"MARKET","m":true,"st":1}}
{"schema_version":"1.3.0","event_id":"caa83bf9-6333-435d-ac18-c47e66265c42","event_type":"raw.trade","source":"binance_market_data_recorder","venue":"binance_usdm","market_type":"perpetual_futures","symbol":"ETHUSDT","event_time_ms":1783517068072,"received_time_ms":1783517068084,"trace_id":"d48fb8d6-ac82-46cf-9808-ec1a6b772f90","trade_id":8429826908,"price":"1736.12","quantity":"0.018","trade_time_ms":1783517068072,"is_buyer_maker":true,"aggressor_side":"sell","raw":{"e":"trade","E":1783517068072,"T":1783517068072,"s":"ETHUSDT","t":8429826908,"p":"1736.12","q":"0.018","X":"MARKET","m":true,"st":1}}
{"schema_version":"1.3.0","event_id":"f31cb2f8-aebc-44bc-9a18-f8ef8c8d02fa","event_type":"raw.trade","source":"binance_market_data_recorder","venue":"binance_usdm","market_type":"perpetual_futures","symbol":"ETHUSDT","event_time_ms":1783517068072,"received_time_ms":1783517068084,"trace_id":"43bb2fc8-2e77-471d-8a80-1601ba245168","trade_id":8429826909,"price":"1736.12","quantity":"0.028","trade_time_ms":1783517068072,"is_buyer_maker":true,"aggressor_side":"sell","raw":{"e":"trade","E":1783517068072,"T":1783517068072,"s":"ETHUSDT","t":8429826909,"p":"1736.12","q":"0.028","X":"MARKET","m":true,"st":1}}
{"schema_version":"1.3.0","event_id":"a841c3d0-0a27-45a0-ba59-52d272a51766","event_type":"raw.depth_update","source":"binance_market_data_recorder","venue":"binance_usdm","market_type":"perpetual_futures","symbol":"ETHUSDT","event_time_ms":1783517068092,"received_time_ms":1783517068247,"trace_id":"846d6c94-497c-408f-9b57-4c7d33a0bf44","first_update_id":10999770685188,"final_update_id":10999770697543,"previous_final_update_id":10999770685130,"bids":[{"price":"200.00","quantity":"7.594"},{"price":"1211.11","quantity":"0.069"},{"price":"1211.12","quantity":"6.369"},{"price":"1216.12","quantity":"0.704"},{"price":"1231.11","quantity":"0.096"},{"price":"1231.12","quantity":"2.592"},{"price":"1236.11","quantity":"0.315"},{"price":"1562.04","quantity":"0.154"},{"price":"1562.49","quantity":"0.026"},{"price":"1562.50","quantity":"1.162"},{"price":"1562.51","quantity":"5.708"},{"price":"1666.60","quantity":"1.078"},{"price":"1695.52","quantity":"0.465"},{"price":"1701.39","quantity":"32.187"},{"price":"1701.40","quantity":"20.919"},{"price":"1704.97","quantity":"29.286"},{"price":"1730.55","quantity":"5.326"},{"price":"1732.10","quantity":"10.440"},{"price":"1732.26","quantity":"20.837"},{"price":"1733.50","quantity":"13.855"},{"price":"1733.65","quantity":"428.877"},{"price":"1733.66","quantity":"82.471"},{"price":"1733.71","quantity":"85.969"},{"price":"1733.72","quantity":"3.365"},{"price":"1733.76","quantity":"35.799"},{"price":"1733.85","quantity":"88.400"},{"price":"1733.86","quantity":"2.091"},{"price":"1733.88","quantity":"44.716"},{"price":"1733.89","quantity":"0.765"},{"price":"1733.94","quantity":"29.283"},{"price":"1734.15","quantity":"0.778"},{"price":"1734.32","quantity":"11.730"},{"price":"1734.44","quantity":"56.236"},{"price":"1734.56","quantity":"3.962"},{"price":"1734.57","quantity":"29.409"},{"price":"1734.68","quantity":"8.509"},{"price":"1734.73","quantity":"316.159"},{"price":"1734.74","quantity":"11.549"},{"price":"1734.78","quantity":"0.444"},{"price":"1734.83","quantity":"6.893"},{"price":"1734.86","quantity":"38.717"},{"price":"1734.87","quantity":"19.838"},{"price":"1734.88","quantity":"59.476"},{"price":"1734.91","quantity":"1.346"},{"price":"1734.92","quantity":"62.428"},{"price":"1734.93","quantity":"68.155"},{"price":"1734.95","quantity":"8.820"},{"price":"1735.00","quantity":"216.833"},{"price":"1735.02","quantity":"53.535"},{"price":"1735.08","quantity":"7.016"},{"price":"1735.12","quantity":"95.456"},{"price":"1735.16","quantity":"4.709"},{"price":"1735.18","quantity":"0.559"},{"price":"1735.20","quantity":"46.708"},{"price":"1735.21","quantity":"35.605"},{"price":"1735.22","quantity":"18.363"},{"price":"1735.23","quantity":"43.841"},{"price":"1735.25","quantity":"0.169"},{"price":"1735.26","quantity":"0.209"},{"price":"1735.27","quantity":"68.102"},{"price":"1735.28","quantity":"4.962"},{"price":"1735.30","quantity":"29.159"},{"price":"1735.34","quantity":"0.110"},{"price":"1735.35","quantity":"17.788"},{"price":"1735.37","quantity":"3.595"},{"price":"1735.43","quantity":"4.390"},{"price":"1735.47","quantity":"16.796"},{"price":"1735.52","quantity":"77.961"},{"price":"1735.53","quantity":"8.517"},{"price":"1735.54","quantity":"0.027"},{"price":"1735.56","quantity":"27.796"},{"price":"1735.61","quantity":"8.774"},{"price":"1735.63","quantity":"6.343"},{"price":"1735.64","quantity":"76.667"},{"price":"1735.65","quantity":"20.560"},{"price":"1735.67","quantity":"0.051"},{"price":"1735.68","quantity":"35.169"},{"price":"1735.69","quantity":"4.774"},{"price":"1735.70","quantity":"28.871"},{"price":"1735.71","quantity":"0.050"},{"price":"1735.73","quantity":"27.850"},{"price":"1735.74","quantity":"29.064"},{"price":"1735.76","quantity":"11.833"},{"price":"1735.77","quantity":"10.978"},{"price":"1735.79","quantity":"4.333"},{"price":"1735.82","quantity":"0.842"},{"price":"1735.86","quantity":"1.436"},{"price":"1735.87","quantity":"1.157"},{"price":"1735.88","quantity":"67.266"},{"price":"1735.89","quantity":"14.235"},{"price":"1735.90","quantity":"4.012"},{"price":"1735.91","quantity":"14.267"},{"price":"1735.92","quantity":"35.165"},{"price":"1735.93","quantity":"0.800"},{"price":"1735.94","quantity":"3.854"},{"price":"1735.95","quantity":"2.436"},{"price":"1735.96","quantity":"2.280"},{"price":"1735.98","quantity":"1.214"},{"price":"1735.99","quantity":"0.052"},{"price":"1736.00","quantity":"26.663"},{"price":"1736.01","quantity":"0.050"},{"price":"1736.03","quantity":"1.134"},{"price":"1736.04","quantity":"0.012"},{"price":"1736.05","quantity":"0.051"},{"price":"1736.06","quantity":"0.014"},{"price":"1736.07","quantity":"0.042"},{"price":"1736.08","quantity":"0.730"},{"price":"1736.09","quantity":"0.930"},{"price":"1736.10","quantity":"3.753"},{"price":"1736.11","quantity":"105.448"},{"price":"1736.12","quantity":"0.000"}],"asks":[{"price":"1736.12","quantity":"304.261"},{"price":"1736.13","quantity":"10.898"},{"price":"1736.14","quantity":"0.040"},{"price":"1736.15","quantity":"0.012"},{"price":"1736.16","quantity":"0.279"},{"price":"1736.17","quantity":"1.764"},{"price":"1736.20","quantity":"3.980"},{"price":"1736.21","quantity":"0.032"},{"price":"1736.22","quantity":"20.900"},{"price":"1736.24","quantity":"0.617"},{"price":"1736.26","quantity":"13.609"},{"price":"1736.27","quantity":"0.314"},{"price":"1736.28","quantity":"40.972"},{"price":"1736.31","quantity":"22.927"},{"price":"1736.33","quantity":"1.712"},{"price":"1736.34","quantity":"67.271"},{"price":"1736.36","quantity":"5.168"},{"price":"1736.38","quantity":"0.278"},{"price":"1736.39","quantity":"0.098"},{"price":"1736.40","quantity":"21.386"},{"price":"1736.41","quantity":"9.508"},{"price":"1736.42","quantity":"7.578"},{"price":"1736.43","quantity":"49.743"},{"price":"1736.46","quantity":"37.917"},{"price":"1736.47","quantity":"2.139"},{"price":"1736.48","quantity":"12.772"},{"price":"1736.49","quantity":"2.992"},{"price":"1736.50","quantity":"1.814"},{"price":"1736.56","quantity":"18.977"},{"price":"1736.84","quantity":"5.069"},{"price":"1736.95","quantity":"0.434"},{"price":"1736.99","quantity":"21.442"},{"price":"1737.01","quantity":"77.995"},{"price":"1737.02","quantity":"25.859"},{"price":"1737.05","quantity":"0.797"},{"price":"1737.13","quantity":"7.142"},{"price":"1737.16","quantity":"11.330"},{"price":"1737.17","quantity":"1.527"},{"price":"1737.18","quantity":"23.455"},{"price":"1737.21","quantity":"0.022"},{"price":"1737.22","quantity":"5.290"},{"price":"1737.25","quantity":"71.600"},{"price":"1737.34","quantity":"17.549"},{"price":"1737.36","quantity":"68.335"},{"price":"1737.38","quantity":"87.911"},{"price":"1737.42","quantity":"6.315"},{"price":"1737.51","quantity":"0.218"},{"price":"1737.52","quantity":"0.026"},{"price":"1737.55","quantity":"38.237"},{"price":"1737.61","quantity":"10.320"},{"price":"1737.86","quantity":"2.288"},{"price":"1737.94","quantity":"0.012"},{"price":"1738.00","quantity":"30.118"},{"price":"1738.04","quantity":"0.239"},{"price":"1738.08","quantity":"1.684"},{"price":"1738.15","quantity":"14.723"},{"price":"1738.36","quantity":"81.145"},{"price":"1738.38","quantity":"407.011"},{"price":"1738.39","quantity":"18.325"},{"price":"1738.56","quantity":"1.984"},{"price":"1738.64","quantity":"11.058"},{"price":"1738.78","quantity":"7.305"},{"price":"1738.88","quantity":"1.079"},{"price":"1738.89","quantity":"56.549"},{"price":"1738.91","quantity":"0.345"},{"price":"1738.94","quantity":"3.960"},{"price":"1738.96","quantity":"0.000"},{"price":"1739.20","quantity":"8.656"},{"price":"1739.27","quantity":"7.087"},{"price":"1739.36","quantity":"3.344"},{"price":"1739.42","quantity":"17.925"},{"price":"1739.60","quantity":"38.666"},{"price":"1739.61","quantity":"20.766"},{"price":"1740.16","quantity":"19.743"},{"price":"1740.47","quantity":"21.804"},{"price":"1740.48","quantity":"17.056"},{"price":"1740.58","quantity":"18.016"},{"price":"1741.33","quantity":"2.652"},{"price":"1741.34","quantity":"16.480"},{"price":"1742.20","quantity":"8.201"},{"price":"1742.21","quantity":"50.659"},{"price":"1743.07","quantity":"18.540"},{"price":"1743.08","quantity":"4.747"},{"price":"1747.12","quantity":"0.000"},{"price":"1835.74","quantity":"0.000"},{"price":"1835.77","quantity":"0.083"},{"price":"1835.78","quantity":"0.019"},{"price":"1836.12","quantity":"0.163"},{"price":"2634.75","quantity":"0.001"},{"price":"2634.76","quantity":"0.001"},{"price":"2634.84","quantity":"0.398"},{"price":"2634.85","quantity":"0.000"}],"raw":{"e":"depthUpdate","E":1783517068092,"T":1783517068091,"s":"ETHUSDT","ps":"ETHUSDT","U":10999770685188,"u":10999770697543,"pu":10999770685130,"b":[["200.00","7.594"],["1211.11","0.069"],["1211.12","6.369"],["1216.12","0.704"],["1231.11","0.096"],["1231.12","2.592"],["1236.11","0.315"],["1562.04","0.154"],["1562.49","0.026"],["1562.50","1.162"],["1562.51","5.708"],["1666.60","1.078"],["1695.52","0.465"],["1701.39","32.187"],["1701.40","20.919"],["1704.97","29.286"],["1730.55","5.326"],["1732.10","10.440"],["1732.26","20.837"],["1733.50","13.855"],["1733.65","428.877"],["1733.66","82.471"],["1733.71","85.969"],["1733.72","3.365"],["1733.76","35.799"],["1733.85","88.400"],["1733.86","2.091"],["1733.88","44.716"],["1733.89","0.765"],["1733.94","29.283"],["1734.15","0.778"],["1734.32","11.730"],["1734.44","56.236"],["1734.56","3.962"],["1734.57","29.409"],["1734.68","8.509"],["1734.73","316.159"],["1734.74","11.549"],["1734.78","0.444"],["1734.83","6.893"],["1734.86","38.717"],["1734.87","19.838"],["1734.88","59.476"],["1734.91","1.346"],["1734.92","62.428"],["1734.93","68.155"],["1734.95","8.820"],["1735.00","216.833"],["1735.02","53.535"],["1735.08","7.016"],["1735.12","95.456"],["1735.16","4.709"],["1735.18","0.559"],["1735.20","46.708"],["1735.21","35.605"],["1735.22","18.363"],["1735.23","43.841"],["1735.25","0.169"],["1735.26","0.209"],["1735.27","68.102"],["1735.28","4.962"],["1735.30","29.159"],["1735.34","0.110"],["1735.35","17.788"],["1735.37","3.595"],["1735.43","4.390"],["1735.47","16.796"],["1735.52","77.961"],["1735.53","8.517"],["1735.54","0.027"],["1735.56","27.796"],["1735.61","8.774"],["1735.63","6.343"],["1735.64","76.667"],["1735.65","20.560"],["1735.67","0.051"],["1735.68","35.169"],["1735.69","4.774"],["1735.70","28.871"],["1735.71","0.050"],["1735.73","27.850"],["1735.74","29.064"],["1735.76","11.833"],["1735.77","10.978"],["1735.79","4.333"],["1735.82","0.842"],["1735.86","1.436"],["1735.87","1.157"],["1735.88","67.266"],["1735.89","14.235"],["1735.90","4.012"],["1735.91","14.267"],["1735.92","35.165"],["1735.93","0.800"],["1735.94","3.854"],["1735.95","2.436"],["1735.96","2.280"],["1735.98","1.214"],["1735.99","0.052"],["1736.00","26.663"],["1736.01","0.050"],["1736.03","1.134"],["1736.04","0.012"],["1736.05","0.051"],["1736.06","0.014"],["1736.07","0.042"],["1736.08","0.730"],["1736.09","0.930"],["1736.10","3.753"],["1736.11","105.448"],["1736.12","0.000"]],"a":[["1736.12","304.261"],["1736.13","10.898"],["1736.14","0.040"],["1736.15","0.012"],["1736.16","0.279"],["1736.17","1.764"],["1736.20","3.980"],["1736.21","0.032"],["1736.22","20.900"],["1736.24","0.617"],["1736.26","13.609"],["1736.27","0.314"],["1736.28","40.972"],["1736.31","22.927"],["1736.33","1.712"],["1736.34","67.271"],["1736.36","5.168"],["1736.38","0.278"],["1736.39","0.098"],["1736.40","21.386"],["1736.41","9.508"],["1736.42","7.578"],["1736.43","49.743"],["1736.46","37.917"],["1736.47","2.139"],["1736.48","12.772"],["1736.49","2.992"],["1736.50","1.814"],["1736.56","18.977"],["1736.84","5.069"],["1736.95","0.434"],["1736.99","21.442"],["1737.01","77.995"],["1737.02","25.859"],["1737.05","0.797"],["1737.13","7.142"],["1737.16","11.330"],["1737.17","1.527"],["1737.18","23.455"],["1737.21","0.022"],["1737.22","5.290"],["1737.25","71.600"],["1737.34","17.549"],["1737.36","68.335"],["1737.38","87.911"],["1737.42","6.315"],["1737.51","0.218"],["1737.52","0.026"],["1737.55","38.237"],["1737.61","10.320"],["1737.86","2.288"],["1737.94","0.012"],["1738.00","30.118"],["1738.04","0.239"],["1738.08","1.684"],["1738.15","14.723"],["1738.36","81.145"],["1738.38","407.011"],["1738.39","18.325"],["1738.56","1.984"],["1738.64","11.058"],["1738.78","7.305"],["1738.88","1.079"],["1738.89","56.549"],["1738.91","0.345"],["1738.94","3.960"],["1738.96","0.000"],["1739.20","8.656"],["1739.27","7.087"],["1739.36","3.344"],["1739.42","17.925"],["1739.60","38.666"],["1739.61","20.766"],["1740.16","19.743"],["1740.47","21.804"],["1740.48","17.056"],["1740.58","18.016"],["1741.33","2.652"],["1741.34","16.480"],["1742.20","8.201"],["1742.21","50.659"],["1743.07","18.540"],["1743.08","4.747"],["1747.12","0.000"],["1835.74","0.000"],["1835.77","0.083"],["1835.78","0.019"],["1836.12","0.163"],["2634.75","0.001"],["2634.76","0.001"],["2634.84","0.398"],["2634.85","0.000"]],"st":1}}
{"schema_version":"1.3.0","event_id":"dbc00230-79d9-42a1-9471-c60ab40beb39","event_type":"raw.depth_update","source":"binance_market_data_recorder","venue":"binance_usdm","market_type":"perpetual_futures","symbol":"BTCUSDT","event_time_ms":1783517068128,"received_time_ms":1783517068256,"trace_id":"458ed856-95b2-4216-aeee-437730754566","first_update_id":10999770688984,"final_update_id":10999770701625,"previous_final_update_id":10999770688919,"bids":[{"price":"11352.20","quantity":"0.128"},{"price":"11353.70","quantity":"0.984"},{"price":"11453.70","quantity":"1.292"},{"price":"11753.70","quantity":"2.480"},{"price":"55668.30","quantity":"0.002"},{"price":"58761.00","quantity":"0.006"},{"price":"59379.50","quantity":"0.004"},{"price":"60615.20","quantity":"0.021"},{"price":"60616.70","quantity":"0.020"},{"price":"61235.20","quantity":"0.025"},{"price":"61544.40","quantity":"0.013"},{"price":"61723.00","quantity":"0.983"},{"price":"61749.00","quantity":"0.026"},{"price":"61749.10","quantity":"0.006"},{"price":"61771.60","quantity":"0.001"},{"price":"61773.60","quantity":"7.988"},{"price":"61777.90","quantity":"0.146"},{"price":"61779.20","quantity":"2.213"},{"price":"61784.20","quantity":"33.904"},{"price":"61788.40","quantity":"0.002"},{"price":"61789.00","quantity":"1.484"},{"price":"61795.30","quantity":"4.695"},{"price":"61796.40","quantity":"0.046"},{"price":"61819.50","quantity":"0.002"},{"price":"61824.70","quantity":"0.122"},{"price":"61825.40","quantity":"0.874"},{"price":"61829.00","quantity":"0.118"},{"price":"61830.50","quantity":"0.969"},{"price":"61842.60","quantity":"0.097"},{"price":"61850.00","quantity":"0.907"},{"price":"61850.10","quantity":"0.001"},{"price":"61853.50","quantity":"0.001"},{"price":"61853.60","quantity":"0.005"},{"price":"61853.70","quantity":"2.501"}],"asks":[{"price":"61853.80","quantity":"8.347"},{"price":"61856.60","quantity":"0.163"},{"price":"61860.00","quantity":"0.463"},{"price":"61861.40","quantity":"1.133"},{"price":"61862.50","quantity":"0.001"},{"price":"61863.00","quantity":"0.283"},{"price":"61863.20","quantity":"0.455"},{"price":"61864.90","quantity":"0.054"},{"price":"61866.20","quantity":"0.566"},{"price":"61868.20","quantity":"0.048"},{"price":"61872.40","quantity":"0.003"},{"price":"61875.10","quantity":"2.218"},{"price":"61880.90","quantity":"0.169"},{"price":"61881.60","quantity":"0.052"},{"price":"61887.90","quantity":"0.379"},{"price":"61904.40","quantity":"0.237"},{"price":"61914.10","quantity":"0.051"},{"price":"61985.80","quantity":"0.744"},{"price":"62027.30","quantity":"0.000"},{"price":"62027.40","quantity":"0.003"},{"price":"62410.50","quantity":"0.240"},{"price":"62472.30","quantity":"0.000"},{"price":"62534.20","quantity":"0.240"},{"price":"62760.70","quantity":"0.000"},{"price":"89523.20","quantity":"0.762"}],"raw":{"e":"depthUpdate","E":1783517068128,"T":1783517068127,"s":"BTCUSDT","ps":"BTCUSDT","U":10999770688984,"u":10999770701625,"pu":10999770688919,"b":[["11352.20","0.128"],["11353.70","0.984"],["11453.70","1.292"],["11753.70","2.480"],["55668.30","0.002"],["58761.00","0.006"],["59379.50","0.004"],["60615.20","0.021"],["60616.70","0.020"],["61235.20","0.025"],["61544.40","0.013"],["61723.00","0.983"],["61749.00","0.026"],["61749.10","0.006"],["61771.60","0.001"],["61773.60","7.988"],["61777.90","0.146"],["61779.20","2.213"],["61784.20","33.904"],["61788.40","0.002"],["61789.00","1.484"],["61795.30","4.695"],["61796.40","0.046"],["61819.50","0.002"],["61824.70","0.122"],["61825.40","0.874"],["61829.00","0.118"],["61830.50","0.969"],["61842.60","0.097"],["61850.00","0.907"],["61850.10","0.001"],["61853.50","0.001"],["61853.60","0.005"],["61853.70","2.501"]],"a":[["61853.80","8.347"],["61856.60","0.163"],["61860.00","0.463"],["61861.40","1.133"],["61862.50","0.001"],["61863.00","0.283"],["61863.20","0.455"],["61864.90","0.054"],["61866.20","0.566"],["61868.20","0.048"],["61872.40","0.003"],["61875.10","2.218"],["61880.90","0.169"],["61881.60","0.052"],["61887.90","0.379"],["61904.40","0.237"],["61914.10","0.051"],["61985.80","0.744"],["62027.30","0.000"],["62027.40","0.003"],["62410.50","0.240"],["62472.30","0.000"],["62534.20","0.240"],["62760.70","0.000"],["89523.20","0.762"]],"st":1}}
{"schema_version":"1.3.0","event_id":"301e2921-4855-4829-a51f-b778931ac938","event_type":"raw.depth_update","source":"binance_market_data_recorder","venue":"binance_usdm","market_type":"perpetual_futures","symbol":"ETHUSDT","event_time_ms":1783517068194,"received_time_ms":1783517068261,"trace_id":"26f0d0d1-a370-4f39-aa56-b2ee59673937","first_update_id":10999770697550,"final_update_id":10999770707218,"previous_final_update_id":10999770697543,"bids":[{"price":"1211.11","quantity":"0.357"},{"price":"1211.12","quantity":"5.825"},{"price":"1216.12","quantity":"0.416"},{"price":"1231.11","quantity":"0.640"},{"price":"1562.49","quantity":"0.026"},{"price":"1562.50","quantity":"1.546"},{"price":"1701.39","quantity":"32.216"},{"price":"1732.77","quantity":"76.302"},{"price":"1733.65","quantity":"9.919"},{"price":"1733.71","quantity":"504.927"},{"price":"1734.66","quantity":"12.726"},{"price":"1734.72","quantity":"223.510"},{"price":"1734.73","quantity":"97.067"},{"price":"1734.74","quantity":"11.949"},{"price":"1735.00","quantity":"223.240"},{"price":"1735.11","quantity":"45.389"},{"price":"1735.12","quantity":"95.441"},{"price":"1735.15","quantity":"6.663"},{"price":"1735.16","quantity":"8.164"},{"price":"1735.17","quantity":"3.284"},{"price":"1735.18","quantity":"0.982"},{"price":"1735.31","quantity":"33.996"},{"price":"1735.34","quantity":"0.098"},{"price":"1735.35","quantity":"21.053"},{"price":"1735.44","quantity":"27.914"},{"price":"1735.55","quantity":"6.304"},{"price":"1735.73","quantity":"26.150"},{"price":"1735.79","quantity":"3.983"},{"price":"1735.88","quantity":"75.933"},{"price":"1735.89","quantity":"13.995"},{"price":"1735.90","quantity":"2.994"},{"price":"1735.91","quantity":"9.957"},{"price":"1735.97","quantity":"25.279"},{"price":"1736.00","quantity":"7.910"},{"price":"1736.04","quantity":"0.024"},{"price":"1736.05","quantity":"0.063"},{"price":"1736.06","quantity":"0.026"},{"price":"1736.07","quantity":"0.059"},{"price":"1736.10","quantity":"3.741"},{"price":"1736.11","quantity":"105.628"}],"asks":[{"price":"1736.12","quantity":"298.719"},{"price":"1736.13","quantity":"9.651"},{"price":"1736.15","quantity":"0.024"},{"price":"1736.18","quantity":"0.053"},{"price":"1736.25","quantity":"4.477"},{"price":"1736.29","quantity":"1.210"},{"price":"1736.30","quantity":"13.550"},{"price":"1736.31","quantity":"22.895"},{"price":"1736.32","quantity":"0.143"},{"price":"1736.33","quantity":"1.735"},{"price":"1736.34","quantity":"67.289"},{"price":"1736.36","quantity":"5.180"},{"price":"1736.40","quantity":"21.369"},{"price":"1736.42","quantity":"10.075"},{"price":"1736.50","quantity":"0.114"},{"price":"1736.68","quantity":"6.405"},{"price":"1736.81","quantity":"22.200"},{"price":"1736.89","quantity":"9.582"},{"price":"1737.16","quantity":"17.090"},{"price":"1737.35","quantity":"43.850"},{"price":"1737.51","quantity":"14.378"},{"price":"1737.55","quantity":"37.237"},{"price":"1737.86","quantity":"5.136"},{"price":"1737.94","quantity":"1.679"},{"price":"1737.95","quantity":"86.265"},{"price":"1738.19","quantity":"423.285"},{"price":"1738.38","quantity":"0.046"},{"price":"1738.89","quantity":"59.745"},{"price":"1739.42","quantity":"20.408"},{"price":"1740.62","quantity":"1.223"},{"price":"1744.82","quantity":"0.066"},{"price":"1774.55","quantity":"0.038"},{"price":"2634.74","quantity":"0.001"},{"price":"2634.83","quantity":"0.000"}],"raw":{"e":"depthUpdate","E":1783517068194,"T":1783517068193,"s":"ETHUSDT","ps":"ETHUSDT","U":10999770697550,"u":10999770707218,"pu":10999770697543,"b":[["1211.11","0.357"],["1211.12","5.825"],["1216.12","0.416"],["1231.11","0.640"],["1562.49","0.026"],["1562.50","1.546"],["1701.39","32.216"],["1732.77","76.302"],["1733.65","9.919"],["1733.71","504.927"],["1734.66","12.726"],["1734.72","223.510"],["1734.73","97.067"],["1734.74","11.949"],["1735.00","223.240"],["1735.11","45.389"],["1735.12","95.441"],["1735.15","6.663"],["1735.16","8.164"],["1735.17","3.284"],["1735.18","0.982"],["1735.31","33.996"],["1735.34","0.098"],["1735.35","21.053"],["1735.44","27.914"],["1735.55","6.304"],["1735.73","26.150"],["1735.79","3.983"],["1735.88","75.933"],["1735.89","13.995"],["1735.90","2.994"],["1735.91","9.957"],["1735.97","25.279"],["1736.00","7.910"],["1736.04","0.024"],["1736.05","0.063"],["1736.06","0.026"],["1736.07","0.059"],["1736.10","3.741"],["1736.11","105.628"]],"a":[["1736.12","298.719"],["1736.13","9.651"],["1736.15","0.024"],["1736.18","0.053"],["1736.25","4.477"],["1736.29","1.210"],["1736.30","13.550"],["1736.31","22.895"],["1736.32","0.143"],["1736.33","1.735"],["1736.34","67.289"],["1736.36","5.180"],["1736.40","21.369"],["1736.42","10.075"],["1736.50","0.114"],["1736.68","6.405"],["1736.81","22.200"],["1736.89","9.582"],["1737.16","17.090"],["1737.35","43.850"],["1737.51","14.378"],["1737.55","37.237"],["1737.86","5.136"],["1737.94","1.679"],["1737.95","86.265"],["1738.19","423.285"],["1738.38","0.046"],["1738.89","59.745"],["1739.42","20.408"],["1740.62","1.223"],["1744.82","0.066"],["1774.55","0.038"],["2634.74","0.001"],["2634.83","0.000"]],"st":1}}
{"schema_version":"1.3.0","event_id":"4ed39e2a-b58e-44b6-991d-2e56ec974fac","event_type":"raw.depth_update","source":"binance_market_data_recorder","venue":"binance_usdm","market_type":"perpetual_futures","symbol":"BTCUSDT","event_time_ms":1783517068230,"received_time_ms":1783517068267,"trace_id":"c957cf7e-57e6-439a-9099-8bbcfa7e531b","first_update_id":10999770701799,"final_update_id":10999770711116,"previous_final_update_id":10999770701625,"bids":[{"price":"1000.00","quantity":"207.692"},{"price":"11352.20","quantity":"0.000"},{"price":"11353.70","quantity":"1.009"},{"price":"11453.70","quantity":"1.139"},{"price":"11653.70","quantity":"0.016"},{"price":"11753.70","quantity":"2.720"},{"price":"55668.30","quantity":"0.002"},{"price":"58761.00","quantity":"0.006"},{"price":"59379.50","quantity":"0.001"},{"price":"61111.50","quantity":"11.685"},{"price":"61235.20","quantity":"0.025"},{"price":"61293.60","quantity":"1.532"},{"price":"61771.60","quantity":"33.903"},{"price":"61773.60","quantity":"7.988"},{"price":"61784.00","quantity":"1.582"},{"price":"61784.20","quantity":"0.002"},{"price":"61784.30","quantity":"0.078"},{"price":"61786.30","quantity":"0.002"},{"price":"61789.00","quantity":"1.484"},{"price":"61821.10","quantity":"0.803"},{"price":"61821.30","quantity":"0.120"},{"price":"61841.90","quantity":"0.482"},{"price":"61853.40","quantity":"0.007"},{"price":"61853.50","quantity":"0.002"},{"price":"61853.60","quantity":"0.003"},{"price":"61853.70","quantity":"2.501"}],"asks":[{"price":"61853.80","quantity":"8.291"},{"price":"61860.80","quantity":"0.025"},{"price":"61861.90","quantity":"0.002"},{"price":"61862.40","quantity":"0.005"},{"price":"61871.70","quantity":"0.002"},{"price":"61872.70","quantity":"0.012"},{"price":"61893.10","quantity":"0.208"},{"price":"61893.30","quantity":"0.680"},{"price":"61893.50","quantity":"0.015"},{"price":"61904.80","quantity":"0.487"},{"price":"62328.80","quantity":"0.002"},{"price":"62472.30","quantity":"0.000"},{"price":"62544.40","quantity":"0.000"}],"raw":{"e":"depthUpdate","E":1783517068230,"T":1783517068229,"s":"BTCUSDT","ps":"BTCUSDT","U":10999770701799,"u":10999770711116,"pu":10999770701625,"b":[["1000.00","207.692"],["11352.20","0.000"],["11353.70","1.009"],["11453.70","1.139"],["11653.70","0.016"],["11753.70","2.720"],["55668.30","0.002"],["58761.00","0.006"],["59379.50","0.001"],["61111.50","11.685"],["61235.20","0.025"],["61293.60","1.532"],["61771.60","33.903"],["61773.60","7.988"],["61784.00","1.582"],["61784.20","0.002"],["61784.30","0.078"],["61786.30","0.002"],["61789.00","1.484"],["61821.10","0.803"],["61821.30","0.120"],["61841.90","0.482"],["61853.40","0.007"],["61853.50","0.002"],["61853.60","0.003"],["61853.70","2.501"]],"a":[["61853.80","8.291"],["61860.80","0.025"],["61861.90","0.002"],["61862.40","0.005"],["61871.70","0.002"],["61872.70","0.012"],["61893.10","0.208"],["61893.30","0.680"],["61893.50","0.015"],["61904.80","0.487"],["62328.80","0.002"],["62472.30","0.000"],["62544.40","0.000"]],"st":1}}
{"schema_version":"1.3.0","event_id":"e2f8ca9e-d465-43f9-93da-21245ea4567b","event_type":"raw.depth_update","source":"binance_market_data_recorder","venue":"binance_usdm","market_type":"perpetual_futures","symbol":"ETHUSDT","event_time_ms":1783517068298,"received_time_ms":1783517068292,"trace_id":"ce0066c5-e036-449a-b751-1961f2ab4f8d","first_update_id":10999770707369,"final_update_id":10999770716754,"previous_final_update_id":10999770707218,"bids":[{"price":"200.00","quantity":"7.594"},{"price":"1211.11","quantity":"0.613"},{"price":"1211.12","quantity":"5.249"},{"price":"1216.12","quantity":"0.160"},{"price":"1231.11","quantity":"1.216"},{"price":"1562.49","quantity":"0.026"},{"price":"1562.50","quantity":"2.186"},{"price":"1666.60","quantity":"1.193"},{"price":"1684.88","quantity":"106.260"},{"price":"1701.39","quantity":"32.187"},{"price":"1704.65","quantity":"1.906"},{"price":"1710.34","quantity":"116.832"},{"price":"1727.42","quantity":"0.629"},{"price":"1733.66","quantity":"23.837"},{"price":"1733.71","quantity":"84.523"},{"price":"1733.72","quantity":"0.169"},{"price":"1733.74","quantity":"19.608"},{"price":"1733.76","quantity":"95.473"},{"price":"1733.82","quantity":"421.533"},{"price":"1734.72","quantity":"2.933"},{"price":"1734.84","quantity":"490.019"},{"price":"1734.89","quantity":"0.168"},{"price":"1735.00","quantity":"217.480"},{"price":"1735.13","quantity":"3.144"},{"price":"1735.23","quantity":"4.905"},{"price":"1735.30","quantity":"68.094"},{"price":"1735.35","quantity":"18.173"},{"price":"1735.82","quantity":"0.866"},{"price":"1735.89","quantity":"16.299"},{"price":"1735.90","quantity":"2.994"},{"price":"1735.95","quantity":"1.284"},{"price":"1736.11","quantity":"122.095"}],"asks":[{"price":"1736.17","quantity":"0.036"},{"price":"1736.19","quantity":"0.012"},{"price":"1736.25","quantity":"3.977"},{"price":"1736.27","quantity":"0.814"},{"price":"1736.40","quantity":"21.538"},{"price":"1736.42","quantity":"10.157"},{"price":"1736.55","quantity":"31.365"},{"price":"1736.64","quantity":"76.115"},{"price":"1736.81","quantity":"19.320"},{"price":"1737.16","quantity":"11.330"},{"price":"1737.51","quantity":"2.858"},{"price":"1738.17","quantity":"67.763"},{"price":"1738.36","quantity":"23.590"},{"price":"1740.63","quantity":"1.411"},{"price":"1744.82","quantity":"0.054"},{"price":"1747.75","quantity":"9.020"},{"price":"1747.76","quantity":"37.449"},{"price":"1747.77","quantity":"0.000"},{"price":"1781.63","quantity":"0.369"},{"price":"2634.72","quantity":"0.001"},{"price":"2634.73","quantity":"0.021"},{"price":"2634.81","quantity":"0.000"},{"price":"2634.82","quantity":"0.000"}],"raw":{"e":"depthUpdate","E":1783517068298,"T":1783517068297,"s":"ETHUSDT","ps":"ETHUSDT","U":10999770707369,"u":10999770716754,"pu":10999770707218,"b":[["200.00","7.594"],["1211.11","0.613"],["1211.12","5.249"],["1216.12","0.160"],["1231.11","1.216"],["1562.49","0.026"],["1562.50","2.186"],["1666.60","1.193"],["1684.88","106.260"],["1701.39","32.187"],["1704.65","1.906"],["1710.34","116.832"],["1727.42","0.629"],["1733.66","23.837"],["1733.71","84.523"],["1733.72","0.169"],["1733.74","19.608"],["1733.76","95.473"],["1733.82","421.533"],["1734.72","2.933"],["1734.84","490.019"],["1734.89","0.168"],["1735.00","217.480"],["1735.13","3.144"],["1735.23","4.905"],["1735.30","68.094"],["1735.35","18.173"],["1735.82","0.866"],["1735.89","16.299"],["1735.90","2.994"],["1735.95","1.284"],["1736.11","122.095"]],"a":[["1736.17","0.036"],["1736.19","0.012"],["1736.25","3.977"],["1736.27","0.814"],["1736.40","21.538"],["1736.42","10.157"],["1736.55","31.365"],["1736.64","76.115"],["1736.81","19.320"],["1737.16","11.330"],["1737.51","2.858"],["1738.17","67.763"],["1738.36","23.590"],["1740.63","1.411"],["1744.82","0.054"],["1747.75","9.020"],["1747.76","37.449"],["1747.77","0.000"],["1781.63","0.369"],["2634.72","0.001"],["2634.73","0.021"],["2634.81","0.000"],["2634.82","0.000"]],"st":1}}
{"schema_version":"1.3.0","event_id":"dca9fd58-fc67-46bb-bb25-fd34e66f4ded","event_type":"raw.trade","source":"binance_market_data_recorder","venue":"binance_usdm","market_type":"perpetual_futures","symbol":"ETHUSDT","event_time_ms":1783517068311,"received_time_ms":1783517068308,"trace_id":"fb85aa29-16ff-4fdf-950f-49612b3ef228","trade_id":8429826910,"price":"1736.11","quantity":"0.012","trade_time_ms":1783517068311,"is_buyer_maker":true,"aggressor_side":"sell","raw":{"e":"trade","E":1783517068311,"T":1783517068311,"s":"ETHUSDT","t":8429826910,"p":"1736.11","q":"0.012","X":"MARKET","m":true,"st":1}}
{"schema_version":"1.3.0","event_id":"8a7b0982-7035-4526-8c83-4d9f6a4d6bc4","event_type":"raw.trade","source":"binance_market_data_recorder","venue":"binance_usdm","market_type":"perpetual_futures","symbol":"ETHUSDT","event_time_ms":1783517068311,"received_time_ms":1783517068308,"trace_id":"8bce7118-057c-4f87-839f-26abf6e93433","trade_id":8429826911,"price":"1736.11","quantity":"0.019","trade_time_ms":1783517068311,"is_buyer_maker":true,"aggressor_side":"sell","raw":{"e":"trade","E":1783517068311,"T":1783517068311,"s":"ETHUSDT","t":8429826911,"p":"1736.11","q":"0.019","X":"MARKET","m":true,"st":1}}
{"schema_version":"1.3.0","event_id":"a2a66c03-ea39-4eea-8391-89ce605cd5b1","event_type":"raw.trade","source":"binance_market_data_recorder","venue":"binance_usdm","market_type":"perpetual_futures","symbol":"BTCUSDT","event_time_ms":1783517068315,"received_time_ms":1783517068311,"trace_id":"9b7f34eb-6693-4dbd-a84a-c1961337b1a5","trade_id":7881418057,"price":"61853.80","quantity":"0.015","trade_time_ms":1783517068315,"is_buyer_maker":false,"aggressor_side":"buy","raw":{"e":"trade","E":1783517068315,"T":1783517068315,"s":"BTCUSDT","t":7881418057,"p":"61853.80","q":"0.015","X":"MARKET","m":false,"st":1}}
{"schema_version":"1.3.0","event_id":"6860a062-b7fb-4b0c-9715-50533456591b","event_type":"raw.trade","source":"binance_market_data_recorder","venue":"binance_usdm","market_type":"perpetual_futures","symbol":"BTCUSDT","event_time_ms":1783517068315,"received_time_ms":1783517068312,"trace_id":"cd17f4c8-de79-47e5-803f-d9f0d0b174af","trade_id":7881418058,"price":"61853.80","quantity":"0.069","trade_time_ms":1783517068315,"is_buyer_maker":false,"aggressor_side":"buy","raw":{"e":"trade","E":1783517068315,"T":1783517068315,"s":"BTCUSDT","t":7881418058,"p":"61853.80","q":"0.069","X":"MARKET","m":false,"st":1}}
{"schema_version":"1.3.0","event_id":"4c8880eb-63c0-4995-a285-7b8159628fb6","event_type":"raw.depth_update","source":"binance_market_data_recorder","venue":"binance_usdm","market_type":"perpetual_futures","symbol":"BTCUSDT","event_time_ms":1783517068332,"received_time_ms":1783517068326,"trace_id":"3c4f60be-f5d8-4461-9e16-c96d9f3bd780","first_update_id":10999770711335,"final_update_id":10999770719502,"previous_final_update_id":10999770711116,"bids":[{"price":"11353.70","quantity":"1.001"},{"price":"11453.70","quantity":"1.003"},{"price":"11653.70","quantity":"0.144"},{"price":"11753.70","quantity":"2.736"},{"price":"34000.00","quantity":"13.622"},{"price":"55668.30","quantity":"0.002"},{"price":"58759.60","quantity":"0.009"},{"price":"58761.00","quantity":"0.006"},{"price":"59525.10","quantity":"0.002"},{"price":"61235.20","quantity":"0.025"},{"price":"61297.00","quantity":"2.276"},{"price":"61735.90","quantity":"0.100"},{"price":"61771.60","quantity":"0.001"},{"price":"61773.60","quantity":"3.357"},{"price":"61784.00","quantity":"0.000"},{"price":"61784.20","quantity":"33.904"},{"price":"61784.30","quantity":"6.747"},{"price":"61786.30","quantity":"0.002"},{"price":"61789.00","quantity":"1.484"},{"price":"61828.10","quantity":"0.041"},{"price":"61828.60","quantity":"0.411"},{"price":"61831.60","quantity":"0.002"},{"price":"61833.00","quantity":"0.014"},{"price":"61843.10","quantity":"0.052"},{"price":"61853.40","quantity":"0.006"},{"price":"61853.50","quantity":"0.001"},{"price":"61853.60","quantity":"0.005"},{"price":"61853.70","quantity":"2.469"}],"asks":[{"price":"61853.80","quantity":"8.207"},{"price":"61861.40","quantity":"0.165"},{"price":"61862.20","quantity":"0.127"},{"price":"61862.90","quantity":"0.001"},{"price":"61863.20","quantity":"1.423"},{"price":"61866.50","quantity":"0.004"},{"price":"61867.30","quantity":"0.123"},{"price":"61870.00","quantity":"0.411"},{"price":"62472.30","quantity":"0.002"},{"price":"62732.10","quantity":"0.314"},{"price":"63089.30","quantity":"0.132"},{"price":"89523.20","quantity":"0.768"}],"raw":{"e":"depthUpdate","E":1783517068332,"T":1783517068330,"s":"BTCUSDT","ps":"BTCUSDT","U":10999770711335,"u":10999770719502,"pu":10999770711116,"b":[["11353.70","1.001"],["11453.70","1.003"],["11653.70","0.144"],["11753.70","2.736"],["34000.00","13.622"],["55668.30","0.002"],["58759.60","0.009"],["58761.00","0.006"],["59525.10","0.002"],["61235.20","0.025"],["61297.00","2.276"],["61735.90","0.100"],["61771.60","0.001"],["61773.60","3.357"],["61784.00","0.000"],["61784.20","33.904"],["61784.30","6.747"],["61786.30","0.002"],["61789.00","1.484"],["61828.10","0.041"],["61828.60","0.411"],["61831.60","0.002"],["61833.00","0.014"],["61843.10","0.052"],["61853.40","0.006"],["61853.50","0.001"],["61853.60","0.005"],["61853.70","2.469"]],"a":[["61853.80","8.207"],["61861.40","0.165"],["61862.20","0.127"],["61862.90","0.001"],["61863.20","1.423"],["61866.50","0.004"],["61867.30","0.123"],["61870.00","0.411"],["62472.30","0.002"],["62732.10","0.314"],["63089.30","0.132"],["89523.20","0.768"]],"st":1}}
{"schema_version":"1.3.0","event_id":"b0e22d89-bd78-4866-ab07-c14ab4be1275","event_type":"raw.trade","source":"binance_market_data_recorder","venue":"binance_usdm","market_type":"perpetual_futures","symbol":"ETHUSDT","event_time_ms":1783517068382,"received_time_ms":1783517068377,"trace_id":"d77f82cf-503e-4fc7-9a02-5ca868f6503a","trade_id":8429826912,"price":"1736.11","quantity":"2.103","trade_time_ms":1783517068382,"is_buyer_maker":true,"aggressor_side":"sell","raw":{"e":"trade","E":1783517068382,"T":1783517068382,"s":"ETHUSDT","t":8429826912,"p":"1736.11","q":"2.103","X":"MARKET","m":true,"st":1}}
{"schema_version":"1.3.0","event_id":"315566b2-9364-45d1-8979-ba25c5b755de","event_type":"raw.depth_update","source":"binance_market_data_recorder","venue":"binance_usdm","market_type":"perpetual_futures","symbol":"ETHUSDT","event_time_ms":1783517068400,"received_time_ms":1783517068395,"trace_id":"2d5a85c6-fe32-4613-b22c-8243eb3c5aa4","first_update_id":10999770716849,"final_update_id":10999770725639,"previous_final_update_id":10999770716754,"bids":[{"price":"200.00","quantity":"7.594"},{"price":"1211.11","quantity":"0.773"},{"price":"1211.12","quantity":"4.609"},{"price":"1216.12","quantity":"0.000"},{"price":"1231.11","quantity":"1.856"},{"price":"1562.49","quantity":"0.026"},{"price":"1562.50","quantity":"2.840"},{"price":"1666.60","quantity":"1.078"},{"price":"1698.08","quantity":"5.889"},{"price":"1703.81","quantity":"0.284"},{"price":"1719.04","quantity":"5.845"},{"price":"1719.95","quantity":"0.000"},{"price":"1720.51","quantity":"429.909"},{"price":"1727.42","quantity":"0.641"},{"price":"1732.09","quantity":"40.542"},{"price":"1732.17","quantity":"144.024"},{"price":"1732.43","quantity":"0.105"},{"price":"1732.50","quantity":"23.728"},{"price":"1733.50","quantity":"10.855"},{"price":"1733.59","quantity":"22.671"},{"price":"1733.66","quantity":"23.837"},{"price":"1733.70","quantity":"16.600"},{"price":"1733.74","quantity":"19.608"},{"price":"1733.76","quantity":"95.257"},{"price":"1733.82","quantity":"2.575"},{"price":"1733.83","quantity":"2.008"},{"price":"1733.88","quantity":"463.674"},{"price":"1734.32","quantity":"11.558"},{"price":"1734.66","quantity":"1.206"},{"price":"1734.74","quantity":"232.581"},{"price":"1734.80","quantity":"11.203"},{"price":"1734.81","quantity":"19.312"},{"price":"1734.84","quantity":"269.416"},{"price":"1735.07","quantity":"6.117"},{"price":"1735.21","quantity":"33.697"},{"price":"1735.22","quantity":"17.409"},{"price":"1735.24","quantity":"7.546"},{"price":"1735.82","quantity":"0.842"},{"price":"1735.90","quantity":"2.994"},{"price":"1735.97","quantity":"25.567"},{"price":"1736.11","quantity":"104.558"}],"asks":[{"price":"1736.12","quantity":"293.382"},{"price":"1736.27","quantity":"0.026"},{"price":"1736.29","quantity":"1.998"},{"price":"1736.31","quantity":"22.895"},{"price":"1736.91","quantity":"68.123"},{"price":"1737.01","quantity":"79.981"},{"price":"1737.02","quantity":"24.439"},{"price":"1737.03","quantity":"83.757"},{"price":"1737.12","quantity":"7.826"},{"price":"1737.13","quantity":"7.127"},{"price":"1737.34","quantity":"14.909"},{"price":"1737.68","quantity":"17.646"},{"price":"1739.98","quantity":"32.614"},{"price":"1739.99","quantity":"144.299"},{"price":"1740.24","quantity":"29.962"},{"price":"1740.26","quantity":"16.353"},{"price":"1745.04","quantity":"0.390"},{"price":"1745.15","quantity":"0.074"},{"price":"1747.12","quantity":"15.000"},{"price":"1748.17","quantity":"0.319"},{"price":"1748.28","quantity":"0.000"},{"price":"1770.15","quantity":"15.234"},{"price":"2634.70","quantity":"0.001"},{"price":"2634.71","quantity":"0.001"},{"price":"2634.79","quantity":"0.000"},{"price":"2634.80","quantity":"0.000"}],"raw":{"e":"depthUpdate","E":1783517068400,"T":1783517068397,"s":"ETHUSDT","ps":"ETHUSDT","U":10999770716849,"u":10999770725639,"pu":10999770716754,"b":[["200.00","7.594"],["1211.11","0.773"],["1211.12","4.609"],["1216.12","0.000"],["1231.11","1.856"],["1562.49","0.026"],["1562.50","2.840"],["1666.60","1.078"],["1698.08","5.889"],["1703.81","0.284"],["1719.04","5.845"],["1719.95","0.000"],["1720.51","429.909"],["1727.42","0.641"],["1732.09","40.542"],["1732.17","144.024"],["1732.43","0.105"],["1732.50","23.728"],["1733.50","10.855"],["1733.59","22.671"],["1733.66","23.837"],["1733.70","16.600"],["1733.74","19.608"],["1733.76","95.257"],["1733.82","2.575"],["1733.83","2.008"],["1733.88","463.674"],["1734.32","11.558"],["1734.66","1.206"],["1734.74","232.581"],["1734.80","11.203"],["1734.81","19.312"],["1734.84","269.416"],["1735.07","6.117"],["1735.21","33.697"],["1735.22","17.409"],["1735.24","7.546"],["1735.82","0.842"],["1735.90","2.994"],["1735.97","25.567"],["1736.11","104.558"]],"a":[["1736.12","293.382"],["1736.27","0.026"],["1736.29","1.998"],["1736.31","22.895"],["1736.91","68.123"],["1737.01","79.981"],["1737.02","24.439"],["1737.03","83.757"],["1737.12","7.826"],["1737.13","7.127"],["1737.34","14.909"],["1737.68","17.646"],["1739.98","32.614"],["1739.99","144.299"],["1740.24","29.962"],["1740.26","16.353"],["1745.04","0.390"],["1745.15","0.074"],["1747.12","15.000"],["1748.17","0.319"],["1748.28","0.000"],["1770.15","15.234"],["2634.70","0.001"],["2634.71","0.001"],["2634.79","0.000"],["2634.80","0.000"]],"st":1}}
{"schema_version":"1.3.0","event_id":"cc4e8450-f9d0-45d5-b3a5-ebcfd8659f40","event_type":"raw.depth_update","source":"binance_market_data_recorder","venue":"binance_usdm","market_type":"perpetual_futures","symbol":"BTCUSDT","event_time_ms":1783517068434,"received_time_ms":1783517068429,"trace_id":"d13e8a50-e914-4012-ae50-f2f1fe73468c","first_update_id":10999770719588,"final_update_id":10999770728171,"previous_final_update_id":10999770719502,"bids":[{"price":"11353.70","quantity":"1.026"},{"price":"11453.70","quantity":"0.850"},{"price":"11653.70","quantity":"0.288"},{"price":"11753.70","quantity":"2.720"},{"price":"55668.30","quantity":"0.002"},{"price":"58761.00","quantity":"0.006"},{"price":"59379.50","quantity":"0.004"},{"price":"61235.20","quantity":"0.025"},{"price":"61298.60","quantity":"0.449"},{"price":"61300.10","quantity":"0.016"},{"price":"61451.90","quantity":"0.000"},{"price":"61453.30","quantity":"0.021"},{"price":"61537.60","quantity":"0.348"},{"price":"61544.40","quantity":"0.013"},{"price":"61605.50","quantity":"0.000"},{"price":"61607.00","quantity":"0.075"},{"price":"61759.50","quantity":"0.029"},{"price":"61761.00","quantity":"0.035"},{"price":"61821.90","quantity":"0.291"},{"price":"61826.10","quantity":"1.457"},{"price":"61828.10","quantity":"0.001"},{"price":"61830.50","quantity":"0.001"},{"price":"61831.40","quantity":"1.299"},{"price":"61832.30","quantity":"0.002"},{"price":"61839.00","quantity":"0.004"},{"price":"61839.10","quantity":"0.080"},{"price":"61848.40","quantity":"0.002"},{"price":"61849.70","quantity":"0.008"},{"price":"61853.40","quantity":"0.007"},{"price":"61853.50","quantity":"0.002"},{"price":"61853.60","quantity":"0.003"},{"price":"61853.70","quantity":"2.471"}],"asks":[{"price":"61859.50","quantity":"0.019"},{"price":"61864.40","quantity":"0.000"},{"price":"61865.60","quantity":"0.586"},{"price":"61883.10","quantity":"0.002"},{"price":"61945.00","quantity":"0.001"},{"price":"61946.50","quantity":"0.005"},{"price":"62099.90","quantity":"0.598"},{"price":"62101.40","quantity":"0.006"},{"price":"62255.10","quantity":"0.000"},{"price":"62256.60","quantity":"0.008"},{"price":"62410.70","quantity":"0.037"},{"price":"62412.30","quantity":"0.016"},{"price":"62472.30","quantity":"0.000"},{"price":"62598.00","quantity":"0.025"},{"price":"62627.00","quantity":"3.828"},{"price":"62750.70","quantity":"0.960"},{"price":"62776.20","quantity":"0.000"},{"price":"63089.30","quantity":"0.129"}],"raw":{"e":"depthUpdate","E":1783517068434,"T":1783517068433,"s":"BTCUSDT","ps":"BTCUSDT","U":10999770719588,"u":10999770728171,"pu":10999770719502,"b":[["11353.70","1.026"],["11453.70","0.850"],["11653.70","0.288"],["11753.70","2.720"],["55668.30","0.002"],["58761.00","0.006"],["59379.50","0.004"],["61235.20","0.025"],["61298.60","0.449"],["61300.10","0.016"],["61451.90","0.000"],["61453.30","0.021"],["61537.60","0.348"],["61544.40","0.013"],["61605.50","0.000"],["61607.00","0.075"],["61759.50","0.029"],["61761.00","0.035"],["61821.90","0.291"],["61826.10","1.457"],["61828.10","0.001"],["61830.50","0.001"],["61831.40","1.299"],["61832.30","0.002"],["61839.00","0.004"],["61839.10","0.080"],["61848.40","0.002"],["61849.70","0.008"],["61853.40","0.007"],["61853.50","0.002"],["61853.60","0.003"],["61853.70","2.471"]],"a":[["61859.50","0.019"],["61864.40","0.000"],["61865.60","0.586"],["61883.10","0.002"],["61945.00","0.001"],["61946.50","0.005"],["62099.90","0.598"],["62101.40","0.006"],["62255.10","0.000"],["62256.60","0.008"],["62410.70","0.037"],["62412.30","0.016"],["62472.30","0.000"],["62598.00","0.025"],["62627.00","3.828"],["62750.70","0.960"],["62776.20","0.000"],["63089.30","0.129"]],"st":1}}
{"schema_version":"1.3.0","event_id":"f42f430f-3466-482f-b004-8742c386faeb","event_type":"raw.trade","source":"binance_market_data_recorder","venue":"binance_usdm","market_type":"perpetual_futures","symbol":"BTCUSDT","event_time_ms":1783517068445,"received_time_ms":1783517068441,"trace_id":"02be31e2-0bc4-4b51-b3b3-ca1980a38ea8","trade_id":7881418059,"price":"61853.80","quantity":"0.002","trade_time_ms":1783517068445,"is_buyer_maker":false,"aggressor_side":"buy","raw":{"e":"trade","E":1783517068445,"T":1783517068445,"s":"BTCUSDT","t":7881418059,"p":"61853.80","q":"0.002","X":"MARKET","m":false,"st":1}}
{"schema_version":"1.3.0","event_id":"bc3e664e-29ca-47c3-b5ab-f56992173382","event_type":"raw.trade","source":"binance_market_data_recorder","venue":"binance_usdm","market_type":"perpetual_futures","symbol":"BTCUSDT","event_time_ms":1783517068445,"received_time_ms":1783517068441,"trace_id":"18b63938-fb26-431e-9325-bdf2c0fb4711","trade_id":7881418060,"price":"61853.80","quantity":"0.029","trade_time_ms":1783517068445,"is_buyer_maker":false,"aggressor_side":"buy","raw":{"e":"trade","E":1783517068445,"T":1783517068445,"s":"BTCUSDT","t":7881418060,"p":"61853.80","q":"0.029","X":"MARKET","m":false,"st":1}}
{"schema_version":"1.3.0","event_id":"c022ec4b-bb00-49dc-b5dd-c1ab6341eb4d","event_type":"raw.trade","source":"binance_market_data_recorder","venue":"binance_usdm","market_type":"perpetual_futures","symbol":"BTCUSDT","event_time_ms":1783517068445,"received_time_ms":1783517068442,"trace_id":"9cb14333-4e45-4f64-8bc8-33421e66cc14","trade_id":7881418061,"price":"61853.80","quantity":"0.028","trade_time_ms":1783517068445,"is_buyer_maker":false,"aggressor_side":"buy","raw":{"e":"trade","E":1783517068445,"T":1783517068445,"s":"BTCUSDT","t":7881418061,"p":"61853.80","q":"0.028","X":"MARKET","m":false,"st":1}}
{"schema_version":"1.3.0","event_id":"c442e868-109a-453b-85c8-b9244b303406","event_type":"raw.trade","source":"binance_market_data_recorder","venue":"binance_usdm","market_type":"perpetual_futures","symbol":"BTCUSDT","event_time_ms":1783517068445,"received_time_ms":1783517068443,"trace_id":"221c7678-49c1-4762-9dde-8b0ee98c064e","trade_id":7881418062,"price":"61853.80","quantity":"0.006","trade_time_ms":1783517068445,"is_buyer_maker":false,"aggressor_side":"buy","raw":{"e":"trade","E":1783517068445,"T":1783517068445,"s":"BTCUSDT","t":7881418062,"p":"61853.80","q":"0.006","X":"MARKET","m":false,"st":1}}
{"schema_version":"1.3.0","event_id":"2a60a236-0ea1-4c13-b4e8-843fd8039aa0","event_type":"raw.trade","source":"binance_market_data_recorder","venue":"binance_usdm","market_type":"perpetual_futures","symbol":"BTCUSDT","event_time_ms":1783517068484,"received_time_ms":1783517068480,"trace_id":"97bd0017-4b36-4829-8382-6b9ad00169b2","trade_id":7881418063,"price":"61853.70","quantity":"0.005","trade_time_ms":1783517068483,"is_buyer_maker":true,"aggressor_side":"sell","raw":{"e":"trade","E":1783517068484,"T":1783517068483,"s":"BTCUSDT","t":7881418063,"p":"61853.70","q":"0.005","X":"MARKET","m":true,"st":1}}
{"schema_version":"1.3.0","event_id":"794b2dd4-210b-4147-a145-9d30e62c8e45","event_type":"raw.trade","source":"binance_market_data_recorder","venue":"binance_usdm","market_type":"perpetual_futures","symbol":"BTCUSDT","event_time_ms":1783517068484,"received_time_ms":1783517068481,"trace_id":"5df316e7-1085-4b76-aa16-af43fc3493a1","trade_id":7881418064,"price":"61853.70","quantity":"0.001","trade_time_ms":1783517068483,"is_buyer_maker":true,"aggressor_side":"sell","raw":{"e":"trade","E":1783517068484,"T":1783517068483,"s":"BTCUSDT","t":7881418064,"p":"61853.70","q":"0.001","X":"MARKET","m":true,"st":1}}
{"schema_version":"1.3.0","event_id":"fe155708-a4ca-4119-b302-e65f22375242","event_type":"raw.depth_update","source":"binance_market_data_recorder","venue":"binance_usdm","market_type":"perpetual_futures","symbol":"ETHUSDT","event_time_ms":1783517068502,"received_time_ms":1783517068496,"trace_id":"87727928-4d59-4066-9968-c8d2997bcb04","first_update_id":10999770725989,"final_update_id":10999770732928,"previous_final_update_id":10999770725639,"bids":[{"price":"201.00","quantity":"2.400"},{"price":"1211.12","quantity":"3.777"},{"price":"1231.11","quantity":"2.688"},{"price":"1562.49","quantity":"0.026"},{"price":"1562.50","quantity":"3.480"},{"price":"1666.60","quantity":"1.193"},{"price":"1701.38","quantity":"43.670"},{"price":"1709.04","quantity":"49.318"},{"price":"1733.74","quantity":"16.412"},{"price":"1733.76","quantity":"35.799"},{"price":"1733.83","quantity":"0.562"},{"price":"1733.88","quantity":"44.716"},{"price":"1733.89","quantity":"0.765"},{"price":"1733.94","quantity":"29.283"},{"price":"1733.95","quantity":"5.388"},{"price":"1734.06","quantity":"473.139"},{"price":"1734.12","quantity":"111.427"},{"price":"1734.62","quantity":"340.024"},{"price":"1734.63","quantity":"53.475"},{"price":"1734.74","quantity":"11.949"},{"price":"1735.11","quantity":"45.389"},{"price":"1735.90","quantity":"2.994"},{"price":"1736.11","quantity":"100.765"}],"asks":[{"price":"1736.33","quantity":"1.735"},{"price":"1736.37","quantity":"7.833"},{"price":"1736.44","quantity":"9.416"},{"price":"1736.49","quantity":"2.851"},{"price":"1736.63","quantity":"8.821"},{"price":"1736.89","quantity":"8.141"},{"price":"1737.35","quantity":"17.720"},{"price":"1737.42","quantity":"3.675"},{"price":"1738.13","quantity":"78.702"},{"price":"1738.14","quantity":"423.260"},{"price":"1738.17","quantity":"7.677"},{"price":"1738.19","quantity":"16.320"},{"price":"1738.64","quantity":"7.862"},{"price":"1739.42","quantity":"30.137"},{"price":"1740.58","quantity":"8.287"},{"price":"1764.65","quantity":"0.034"},{"price":"1771.88","quantity":"36.427"},{"price":"1776.79","quantity":"28.045"},{"price":"1780.32","quantity":"81.351"},{"price":"2634.69","quantity":"0.001"},{"price":"2634.78","quantity":"0.021"}],"raw":{"e":"depthUpdate","E":1783517068502,"T":1783517068501,"s":"ETHUSDT","ps":"ETHUSDT","U":10999770725989,"u":10999770732928,"pu":10999770725639,"b":[["201.00","2.400"],["1211.12","3.777"],["1231.11","2.688"],["1562.49","0.026"],["1562.50","3.480"],["1666.60","1.193"],["1701.38","43.670"],["1709.04","49.318"],["1733.74","16.412"],["1733.76","35.799"],["1733.83","0.562"],["1733.88","44.716"],["1733.89","0.765"],["1733.94","29.283"],["1733.95","5.388"],["1734.06","473.139"],["1734.12","111.427"],["1734.62","340.024"],["1734.63","53.475"],["1734.74","11.949"],["1735.11","45.389"],["1735.90","2.994"],["1736.11","100.765"]],"a":[["1736.33","1.735"],["1736.37","7.833"],["1736.44","9.416"],["1736.49","2.851"],["1736.63","8.821"],["1736.89","8.141"],["1737.35","17.720"],["1737.42","3.675"],["1738.13","78.702"],["1738.14","423.260"],["1738.17","7.677"],["1738.19","16.320"],["1738.64","7.862"],["1739.42","30.137"],["1740.58","8.287"],["1764.65","0.034"],["1771.88","36.427"],["1776.79","28.045"],["1780.32","81.351"],["2634.69","0.001"],["2634.78","0.021"]],"st":1}}
{"schema_version":"1.3.0","event_id":"42ccffc7-499f-4b78-87a7-ce18f98d10f0","event_type":"raw.depth_update","source":"binance_market_data_recorder","venue":"binance_usdm","market_type":"perpetual_futures","symbol":"BTCUSDT","event_time_ms":1783517068536,"received_time_ms":1783517068530,"trace_id":"2ae9a667-40d0-4466-8869-f095270eb0c9","first_update_id":10999770728257,"final_update_id":10999770734850,"previous_final_update_id":10999770728171,"bids":[{"price":"1000.00","quantity":"207.692"},{"price":"11353.70","quantity":"1.018"},{"price":"11453.70","quantity":"0.714"},{"price":"11653.70","quantity":"0.416"},{"price":"11753.70","quantity":"2.736"},{"price":"49482.00","quantity":"0.000"},{"price":"55668.30","quantity":"0.002"},{"price":"58761.00","quantity":"0.009"},{"price":"59379.50","quantity":"0.001"},{"price":"60615.20","quantity":"0.015"},{"price":"60616.70","quantity":"0.023"},{"price":"60924.50","quantity":"0.003"},{"price":"61235.20","quantity":"0.025"},{"price":"61396.50","quantity":"0.000"},{"price":"61779.20","quantity":"2.205"},{"price":"61829.00","quantity":"0.364"},{"price":"61829.80","quantity":"0.016"},{"price":"61835.50","quantity":"0.014"},{"price":"61836.50","quantity":"1.023"},{"price":"61841.90","quantity":"0.484"},{"price":"61842.00","quantity":"0.470"},{"price":"61842.10","quantity":"0.102"},{"price":"61842.50","quantity":"0.572"},{"price":"61844.00","quantity":"0.033"},{"price":"61844.80","quantity":"0.017"},{"price":"61849.30","quantity":"0.000"},{"price":"61851.00","quantity":"1.001"},{"price":"61851.10","quantity":"0.631"},{"price":"61853.40","quantity":"0.006"},{"price":"61853.50","quantity":"0.001"},{"price":"61853.60","quantity":"0.005"},{"price":"61853.70","quantity":"2.622"}],"asks":[{"price":"61853.80","quantity":"8.854"},{"price":"61856.60","quantity":"0.398"},{"price":"61861.70","quantity":"0.278"},{"price":"61862.00","quantity":"0.001"},{"price":"61863.90","quantity":"0.308"},{"price":"61872.90","quantity":"0.070"},{"price":"61904.70","quantity":"0.104"},{"price":"62133.20","quantity":"0.000"},{"price":"62348.60","quantity":"4.003"},{"price":"62472.30","quantity":"0.000"},{"price":"62555.30","quantity":"0.240"},{"price":"62637.20","quantity":"0.008"},{"price":"62946.40","quantity":"3.873"},{"price":"63089.30","quantity":"0.117"},{"price":"89523.20","quantity":"0.774"}],"raw":{"e":"depthUpdate","E":1783517068536,"T":1783517068533,"s":"BTCUSDT","ps":"BTCUSDT","U":10999770728257,"u":10999770734850,"pu":10999770728171,"b":[["1000.00","207.692"],["11353.70","1.018"],["11453.70","0.714"],["11653.70","0.416"],["11753.70","2.736"],["49482.00","0.000"],["55668.30","0.002"],["58761.00","0.009"],["59379.50","0.001"],["60615.20","0.015"],["60616.70","0.023"],["60924.50","0.003"],["61235.20","0.025"],["61396.50","0.000"],["61779.20","2.205"],["61829.00","0.364"],["61829.80","0.016"],["61835.50","0.014"],["61836.50","1.023"],["61841.90","0.484"],["61842.00","0.470"],["61842.10","0.102"],["61842.50","0.572"],["61844.00","0.033"],["61844.80","0.017"],["61849.30","0.000"],["61851.00","1.001"],["61851.10","0.631"],["61853.40","0.006"],["61853.50","0.001"],["61853.60","0.005"],["61853.70","2.622"]],"a":[["61853.80","8.854"],["61856.60","0.398"],["61861.70","0.278"],["61862.00","0.001"],["61863.90","0.308"],["61872.90","0.070"],["61904.70","0.104"],["62133.20","0.000"],["62348.60","4.003"],["62472.30","0.000"],["62555.30","0.240"],["62637.20","0.008"],["62946.40","3.873"],["63089.30","0.117"],["89523.20","0.774"]],"st":1}}
{"schema_version":"1.3.0","event_id":"80427b28-a227-474e-ab23-48fdeac390fc","event_type":"raw.depth_update","source":"binance_market_data_recorder","venue":"binance_usdm","market_type":"perpetual_futures","symbol":"ETHUSDT","event_time_ms":1783517068604,"received_time_ms":1783517068598,"trace_id":"b8c57e67-dde3-403d-9155-21e893a30004","first_update_id":10999770732953,"final_update_id":10999770740981,"previous_final_update_id":10999770732928,"bids":[{"price":"200.00","quantity":"7.594"},{"price":"201.00","quantity":"2.300"},{"price":"1211.12","quantity":"2.977"},{"price":"1231.11","quantity":"3.488"},{"price":"1562.49","quantity":"0.026"},{"price":"1562.50","quantity":"3.992"},{"price":"1666.60","quantity":"1.078"},{"price":"1684.89","quantity":"53.141"},{"price":"1692.97","quantity":"0.140"},{"price":"1694.99","quantity":"0.032"},{"price":"1698.25","quantity":"0.784"},{"price":"1701.38","quantity":"43.641"},{"price":"1703.30","quantity":"25.227"},{"price":"1704.53","quantity":"88.023"},{"price":"1706.12","quantity":"29.285"},{"price":"1713.91","quantity":"18.756"},{"price":"1730.66","quantity":"0.000"},{"price":"1730.67","quantity":"16.462"},{"price":"1733.59","quantity":"22.671"},{"price":"1733.66","quantity":"23.837"},{"price":"1733.71","quantity":"504.899"},{"price":"1733.74","quantity":"17.858"},{"price":"1733.76","quantity":"95.207"},{"price":"1733.95","quantity":"7.138"},{"price":"1734.06","quantity":"54.181"},{"price":"1734.12","quantity":"55.897"},{"price":"1734.62","quantity":"119.388"},{"price":"1734.63","quantity":"23.322"},{"price":"1734.73","quantity":"317.705"},{"price":"1734.85","quantity":"222.145"},{"price":"1736.11","quantity":"102.177"}],"asks":[{"price":"1736.12","quantity":"293.394"},{"price":"1736.13","quantity":"9.663"},{"price":"1736.14","quantity":"0.028"},{"price":"1736.31","quantity":"22.895"},{"price":"1736.93","quantity":"16.386"},{"price":"1737.12","quantity":"7.826"},{"price":"1737.35","quantity":"1.044"},{"price":"1737.51","quantity":"2.858"},{"price":"1737.73","quantity":"4.742"},{"price":"1738.00","quantity":"89.072"},{"price":"1738.08","quantity":"409.324"},{"price":"1738.13","quantity":"19.864"},{"price":"1738.14","quantity":"16.295"},{"price":"1738.78","quantity":"4.109"},{"price":"1738.89","quantity":"59.745"},{"price":"1741.41","quantity":"24.723"},{"price":"1741.42","quantity":"13.266"},{"price":"1747.12","quantity":"0.000"},{"price":"2634.67","quantity":"0.001"},{"price":"2634.68","quantity":"0.001"},{"price":"2634.76","quantity":"0.000"},{"price":"2634.77","quantity":"0.000"}],"raw":{"e":"depthUpdate","E":1783517068604,"T":1783517068601,"s":"ETHUSDT","ps":"ETHUSDT","U":10999770732953,"u":10999770740981,"pu":10999770732928,"b":[["200.00","7.594"],["201.00","2.300"],["1211.12","2.977"],["1231.11","3.488"],["1562.49","0.026"],["1562.50","3.992"],["1666.60","1.078"],["1684.89","53.141"],["1692.97","0.140"],["1694.99","0.032"],["1698.25","0.784"],["1701.38","43.641"],["1703.30","25.227"],["1704.53","88.023"],["1706.12","29.285"],["1713.91","18.756"],["1730.66","0.000"],["1730.67","16.462"],["1733.59","22.671"],["1733.66","23.837"],["1733.71","504.899"],["1733.74","17.858"],["1733.76","95.207"],["1733.95","7.138"],["1734.06","54.181"],["1734.12","55.897"],["1734.62","119.388"],["1734.63","23.322"],["1734.73","317.705"],["1734.85","222.145"],["1736.11","102.177"]],"a":[["1736.12","293.394"],["1736.13","9.663"],["1736.14","0.028"],["1736.31","22.895"],["1736.93","16.386"],["1737.12","7.826"],["1737.35","1.044"],["1737.51","2.858"],["1737.73","4.742"],["1738.00","89.072"],["1738.08","409.324"],["1738.13","19.864"],["1738.14","16.295"],["1738.78","4.109"],["1738.89","59.745"],["1741.41","24.723"],["1741.42","13.266"],["1747.12","0.000"],["2634.67","0.001"],["2634.68","0.001"],["2634.76","0.000"],["2634.77","0.000"]],"st":1}}
{"schema_version":"1.3.0","event_id":"4a57e5e9-fc15-4e86-b35f-cf57eb779982","event_type":"raw.depth_update","source":"binance_market_data_recorder","venue":"binance_usdm","market_type":"perpetual_futures","symbol":"BTCUSDT","event_time_ms":1783517068638,"received_time_ms":1783517068632,"trace_id":"e5d68c67-d928-4234-8fee-41671764e9a0","first_update_id":10999770735067,"final_update_id":10999770745594,"previous_final_update_id":10999770734850,"bids":[{"price":"11353.20","quantity":"0.000"},{"price":"11353.70","quantity":"1.139"},{"price":"11453.70","quantity":"0.561"},{"price":"11653.70","quantity":"0.640"},{"price":"11753.70","quantity":"2.560"},{"price":"55668.30","quantity":"0.002"},{"price":"58759.60","quantity":"0.006"},{"price":"58759.70","quantity":"0.006"},{"price":"58761.00","quantity":"0.009"},{"price":"59379.50","quantity":"0.004"},{"price":"61235.20","quantity":"0.025"},{"price":"61319.70","quantity":"0.000"},{"price":"61321.10","quantity":"0.011"},{"price":"61548.50","quantity":"0.001"},{"price":"61550.00","quantity":"9.669"},{"price":"61730.40","quantity":"0.019"},{"price":"61778.10","quantity":"0.008"},{"price":"61784.20","quantity":"0.002"},{"price":"61784.30","quantity":"0.078"},{"price":"61786.30","quantity":"33.857"},{"price":"61789.00","quantity":"6.372"},{"price":"61808.60","quantity":"0.065"},{"price":"61841.80","quantity":"0.005"},{"price":"61850.00","quantity":"0.907"},{"price":"61853.20","quantity":"0.000"},{"price":"61853.50","quantity":"0.002"},{"price":"61853.60","quantity":"0.003"},{"price":"61853.70","quantity":"2.650"}],"asks":[{"price":"61853.80","quantity":"8.857"},{"price":"61888.20","quantity":"0.071"},{"price":"62472.30","quantity":"0.000"},{"price":"62815.00","quantity":"0.874"},{"price":"62936.20","quantity":"0.733"}],"raw":{"e":"depthUpdate","E":1783517068638,"T":1783517068637,"s":"BTCUSDT","ps":"BTCUSDT","U":10999770735067,"u":10999770745594,"pu":10999770734850,"b":[["11353.20","0.000"],["11353.70","1.139"],["11453.70","0.561"],["11653.70","0.640"],["11753.70","2.560"],["55668.30","0.002"],["58759.60","0.006"],["58759.70","0.006"],["58761.00","0.009"],["59379.50","0.004"],["61235.20","0.025"],["61319.70","0.000"],["61321.10","0.011"],["61548.50","0.001"],["61550.00","9.669"],["61730.40","0.019"],["61778.10","0.008"],["61784.20","0.002"],["61784.30","0.078"],["61786.30","33.857"],["61789.00","6.372"],["61808.60","0.065"],["61841.80","0.005"],["61850.00","0.907"],["61853.20","0.000"],["61853.50","0.002"],["61853.60","0.003"],["61853.70","2.650"]],"a":[["61853.80","8.857"],["61888.20","0.071"],["62472.30","0.000"],["62815.00","0.874"],["62936.20","0.733"]],"st":1}}
{"schema_version":"1.3.0","event_id":"1e4aa3f4-a63a-4c27-8bd5-2f2bb47b0fce","event_type":"raw.trade","source":"binance_market_data_recorder","venue":"binance_usdm","market_type":"perpetual_futures","symbol":"ETHUSDT","event_time_ms":1783517068649,"received_time_ms":1783517068645,"trace_id":"cb405f13-bbaf-4539-9dd9-f35e02d6d577","trade_id":8429826913,"price":"1736.11","quantity":"0.012","trade_time_ms":1783517068649,"is_buyer_maker":true,"aggressor_side":"sell","raw":{"e":"trade","E":1783517068649,"T":1783517068649,"s":"ETHUSDT","t":8429826913,"p":"1736.11","q":"0.012","X":"MARKET","m":true,"st":1}}
{"schema_version":"1.3.0","event_id":"ce0b4dc5-28cb-4e14-af8f-abd4df0aebe5","event_type":"raw.depth_update","source":"binance_market_data_recorder","venue":"binance_usdm","market_type":"perpetual_futures","symbol":"ETHUSDT","event_time_ms":1783517068706,"received_time_ms":1783517068700,"trace_id":"97e3a45d-2a77-44cf-93d3-be1573457cbe","first_update_id":10999770741624,"final_update_id":10999770751353,"previous_final_update_id":10999770740981,"bids":[{"price":"200.00","quantity":"7.594"},{"price":"1211.12","quantity":"2.145"},{"price":"1231.11","quantity":"4.320"},{"price":"1562.49","quantity":"0.026"},{"price":"1562.50","quantity":"4.262"},{"price":"1701.38","quantity":"43.670"},{"price":"1703.10","quantity":"11.729"},{"price":"1714.21","quantity":"0.001"},{"price":"1717.88","quantity":"23.267"},{"price":"1718.55","quantity":"31.975"},{"price":"1724.98","quantity":"0.895"},{"price":"1725.00","quantity":"1296.212"},{"price":"1727.24","quantity":"3.387"},{"price":"1727.26","quantity":"0.517"},{"price":"1730.67","quantity":"0.000"},{"price":"1733.71","quantity":"84.523"},{"price":"1733.74","quantity":"16.412"},{"price":"1733.76","quantity":"35.799"},{"price":"1733.82","quantity":"2.575"},{"price":"1733.88","quantity":"465.092"},{"price":"1733.94","quantity":"93.267"},{"price":"1734.80","quantity":"9.123"},{"price":"1734.81","quantity":"18.272"},{"price":"1734.85","quantity":"1.504"},{"price":"1734.87","quantity":"21.930"},{"price":"1734.88","quantity":"60.522"},{"price":"1735.39","quantity":"0.565"},{"price":"1735.70","quantity":"28.859"},{"price":"1735.86","quantity":"5.986"},{"price":"1736.11","quantity":"102.192"}],"asks":[{"price":"1736.12","quantity":"293.407"},{"price":"1736.20","quantity":"3.992"},{"price":"1736.50","quantity":"0.102"},{"price":"1738.00","quantity":"30.118"},{"price":"1738.08","quantity":"1.684"},{"price":"1738.13","quantity":"78.803"},{"price":"1738.14","quantity":"423.935"},{"price":"1741.41","quantity":"10.358"},{"price":"1757.83","quantity":"33.502"},{"price":"2634.66","quantity":"0.001"},{"price":"2634.75","quantity":"0.000"}],"raw":{"e":"depthUpdate","E":1783517068706,"T":1783517068705,"s":"ETHUSDT","ps":"ETHUSDT","U":10999770741624,"u":10999770751353,"pu":10999770740981,"b":[["200.00","7.594"],["1211.12","2.145"],["1231.11","4.320"],["1562.49","0.026"],["1562.50","4.262"],["1701.38","43.670"],["1703.10","11.729"],["1714.21","0.001"],["1717.88","23.267"],["1718.55","31.975"],["1724.98","0.895"],["1725.00","1296.212"],["1727.24","3.387"],["1727.26","0.517"],["1730.67","0.000"],["1733.71","84.523"],["1733.74","16.412"],["1733.76","35.799"],["1733.82","2.575"],["1733.88","465.092"],["1733.94","93.267"],["1734.80","9.123"],["1734.81","18.272"],["1734.85","1.504"],["1734.87","21.930"],["1734.88","60.522"],["1735.39","0.565"],["1735.70","28.859"],["1735.86","5.986"],["1736.11","102.192"]],"a":[["1736.12","293.407"],["1736.20","3.992"],["1736.50","0.102"],["1738.00","30.118"],["1738.08","1.684"],["1738.13","78.803"],["1738.14","423.935"],["1741.41","10.358"],["1757.83","33.502"],["2634.66","0.001"],["2634.75","0.000"]],"st":1}}
{"schema_version":"1.3.0","event_id":"04026bcc-64fc-41e2-aef9-4360571b3c1f","event_type":"raw.depth_update","source":"binance_market_data_recorder","venue":"binance_usdm","market_type":"perpetual_futures","symbol":"BTCUSDT","event_time_ms":1783517068740,"received_time_ms":1783517068735,"trace_id":"f6d49980-7cdd-4ea6-9278-15a87e592541","first_update_id":10999770745812,"final_update_id":10999770753660,"previous_final_update_id":10999770745594,"bids":[{"price":"1000.00","quantity":"207.842"},{"price":"11353.70","quantity":"1.275"},{"price":"11453.70","quantity":"0.425"},{"price":"11653.70","quantity":"0.912"},{"price":"11753.70","quantity":"2.288"},{"price":"49483.00","quantity":"0.000"},{"price":"55668.30","quantity":"0.002"},{"price":"58759.70","quantity":"0.003"},{"price":"61235.20","quantity":"0.025"},{"price":"61388.40","quantity":"0.007"},{"price":"61399.20","quantity":"0.123"},{"price":"61544.40","quantity":"0.013"},{"price":"61759.10","quantity":"0.000"},{"price":"61767.30","quantity":"0.001"},{"price":"61767.40","quantity":"0.000"},{"price":"61767.50","quantity":"2.323"},{"price":"61784.00","quantity":"0.000"},{"price":"61784.20","quantity":"33.857"},{"price":"61784.30","quantity":"6.740"},{"price":"61786.30","quantity":"0.002"},{"price":"61789.00","quantity":"1.484"},{"price":"61816.10","quantity":"0.047"},{"price":"61824.70","quantity":"0.001"},{"price":"61825.70","quantity":"0.133"},{"price":"61830.30","quantity":"1.130"},{"price":"61831.40","quantity":"0.331"},{"price":"61837.60","quantity":"1.229"},{"price":"61842.00","quantity":"0.468"},{"price":"61853.70","quantity":"2.652"}],"asks":[{"price":"61853.80","quantity":"8.063"},{"price":"61861.30","quantity":"1.385"},{"price":"61863.20","quantity":"0.455"},{"price":"61864.00","quantity":"3.301"},{"price":"61865.60","quantity":"0.004"},{"price":"61866.40","quantity":"0.122"},{"price":"61867.30","quantity":"0.002"},{"price":"62472.30","quantity":"0.000"},{"price":"62599.40","quantity":"0.798"},{"price":"62618.00","quantity":"1.321"},{"price":"62744.40","quantity":"0.005"},{"price":"89523.20","quantity":"0.780"}],"raw":{"e":"depthUpdate","E":1783517068740,"T":1783517068739,"s":"BTCUSDT","ps":"BTCUSDT","U":10999770745812,"u":10999770753660,"pu":10999770745594,"b":[["1000.00","207.842"],["11353.70","1.275"],["11453.70","0.425"],["11653.70","0.912"],["11753.70","2.288"],["49483.00","0.000"],["55668.30","0.002"],["58759.70","0.003"],["61235.20","0.025"],["61388.40","0.007"],["61399.20","0.123"],["61544.40","0.013"],["61759.10","0.000"],["61767.30","0.001"],["61767.40","0.000"],["61767.50","2.323"],["61784.00","0.000"],["61784.20","33.857"],["61784.30","6.740"],["61786.30","0.002"],["61789.00","1.484"],["61816.10","0.047"],["61824.70","0.001"],["61825.70","0.133"],["61830.30","1.130"],["61831.40","0.331"],["61837.60","1.229"],["61842.00","0.468"],["61853.70","2.652"]],"a":[["61853.80","8.063"],["61861.30","1.385"],["61863.20","0.455"],["61864.00","3.301"],["61865.60","0.004"],["61866.40","0.122"],["61867.30","0.002"],["62472.30","0.000"],["62599.40","0.798"],["62618.00","1.321"],["62744.40","0.005"],["89523.20","0.780"]],"st":1}}
{"schema_version":"1.3.0","event_id":"8b89374e-1b47-4fd8-90df-ed94e50480d4","event_type":"raw.depth_update","source":"binance_market_data_recorder","venue":"binance_usdm","market_type":"perpetual_futures","symbol":"ETHUSDT","event_time_ms":1783517068808,"received_time_ms":1783517068803,"trace_id":"5a3c48a0-8a07-4589-ae61-37db43e5bc96","first_update_id":10999770751441,"final_update_id":10999770758332,"previous_final_update_id":10999770751353,"bids":[{"price":"1211.12","quantity":"1.569"},{"price":"1226.11","quantity":"0.224"},{"price":"1231.11","quantity":"4.896"},{"price":"1231.12","quantity":"2.368"},{"price":"1562.49","quantity":"0.026"},{"price":"1562.50","quantity":"4.390"},{"price":"1666.60","quantity":"1.193"},{"price":"1680.19","quantity":"0.020"},{"price":"1701.38","quantity":"43.641"},{"price":"1712.88","quantity":"13.577"},{"price":"1730.67","quantity":"16.462"},{"price":"1733.89","quantity":"2.211"},{"price":"1734.42","quantity":"0.858"},{"price":"1735.11","quantity":"45.389"},{"price":"1735.70","quantity":"28.871"}],"asks":[{"price":"1736.25","quantity":"4.265"},{"price":"1736.29","quantity":"1.710"},{"price":"1736.42","quantity":"7.674"},{"price":"1736.50","quantity":"0.114"},{"price":"1736.88","quantity":"5.315"},{"price":"1736.91","quantity":"69.817"},{"price":"1737.34","quantity":"13.215"},{"price":"1737.86","quantity":"3.469"},{"price":"1737.88","quantity":"34.874"},{"price":"1737.94","quantity":"0.012"},{"price":"1738.00","quantity":"31.032"},{"price":"1738.03","quantity":"1.667"},{"price":"1739.29","quantity":"2.017"},{"price":"1739.30","quantity":"3.887"},{"price":"1741.41","quantity":"24.723"},{"price":"1770.42","quantity":"19.745"},{"price":"1797.77","quantity":"0.048"},{"price":"2634.64","quantity":"0.001"},{"price":"2634.65","quantity":"0.001"},{"price":"2634.73","quantity":"0.020"},{"price":"2634.74","quantity":"0.000"}],"raw":{"e":"depthUpdate","E":1783517068808,"T":1783517068806,"s":"ETHUSDT","ps":"ETHUSDT","U":10999770751441,"u":10999770758332,"pu":10999770751353,"b":[["1211.12","1.569"],["1226.11","0.224"],["1231.11","4.896"],["1231.12","2.368"],["1562.49","0.026"],["1562.50","4.390"],["1666.60","1.193"],["1680.19","0.020"],["1701.38","43.641"],["1712.88","13.577"],["1730.67","16.462"],["1733.89","2.211"],["1734.42","0.858"],["1735.11","45.389"],["1735.70","28.871"]],"a":[["1736.25","4.265"],["1736.29","1.710"],["1736.42","7.674"],["1736.50","0.114"],["1736.88","5.315"],["1736.91","69.817"],["1737.34","13.215"],["1737.86","3.469"],["1737.88","34.874"],["1737.94","0.012"],["1738.00","31.032"],["1738.03","1.667"],["1739.29","2.017"],["1739.30","3.887"],["1741.41","24.723"],["1770.42","19.745"],["1797.77","0.048"],["2634.64","0.001"],["2634.65","0.001"],["2634.73","0.020"],["2634.74","0.000"]],"st":1}}
{"schema_version":"1.3.0","event_id":"274ace75-bb63-4fd4-9b32-ab8de3060978","event_type":"raw.depth_update","source":"binance_market_data_recorder","venue":"binance_usdm","market_type":"perpetual_futures","symbol":"BTCUSDT","event_time_ms":1783517068842,"received_time_ms":1783517068836,"trace_id":"b3cfb27a-6d6f-47b2-a89f-8caf9caf31fe","first_update_id":10999770753707,"final_update_id":10999770764209,"previous_final_update_id":10999770753660,"bids":[{"price":"1000.00","quantity":"207.692"},{"price":"11353.70","quantity":"1.428"},{"price":"11453.70","quantity":"0.272"},{"price":"11653.70","quantity":"1.184"},{"price":"11753.70","quantity":"2.016"},{"price":"55668.30","quantity":"0.002"},{"price":"58761.00","quantity":"0.009"},{"price":"59379.50","quantity":"0.001"},{"price":"60615.20","quantity":"0.003"},{"price":"61235.20","quantity":"0.025"},{"price":"61544.40","quantity":"0.012"},{"price":"61784.00","quantity":"1.582"},{"price":"61784.20","quantity":"0.002"},{"price":"61784.30","quantity":"0.078"},{"price":"61786.30","quantity":"33.857"},{"price":"61789.00","quantity":"6.372"},{"price":"61808.10","quantity":"0.101"},{"price":"61822.00","quantity":"0.081"},{"price":"61822.80","quantity":"0.400"},{"price":"61823.60","quantity":"0.000"},{"price":"61824.50","quantity":"0.445"},{"price":"61825.00","quantity":"1.335"},{"price":"61825.10","quantity":"0.255"},{"price":"61825.20","quantity":"0.001"},{"price":"61825.60","quantity":"0.601"},{"price":"61825.70","quantity":"0.012"},{"price":"61826.40","quantity":"0.881"},{"price":"61829.00","quantity":"0.364"},{"price":"61835.20","quantity":"0.002"},{"price":"61838.00","quantity":"0.000"},{"price":"61838.20","quantity":"0.325"},{"price":"61839.00","quantity":"0.004"},{"price":"61839.10","quantity":"0.080"},{"price":"61839.20","quantity":"0.001"},{"price":"61840.10","quantity":"0.002"},{"price":"61840.70","quantity":"0.090"},{"price":"61841.40","quantity":"1.281"},{"price":"61842.20","quantity":"0.001"},{"price":"61843.10","quantity":"0.053"},{"price":"61844.00","quantity":"0.032"},{"price":"61846.90","quantity":"0.082"},{"price":"61850.00","quantity":"0.534"},{"price":"61851.10","quantity":"0.000"},{"price":"61852.30","quantity":"0.007"},{"price":"61853.40","quantity":"0.004"},{"price":"61853.60","quantity":"0.002"},{"price":"61853.70","quantity":"1.020"}],"asks":[{"price":"61853.80","quantity":"9.171"},{"price":"61854.00","quantity":"0.024"},{"price":"61854.80","quantity":"0.906"},{"price":"61854.90","quantity":"2.366"},{"price":"61855.10","quantity":"0.061"},{"price":"61856.40","quantity":"0.031"},{"price":"61856.60","quantity":"0.398"},{"price":"61856.70","quantity":"0.012"},{"price":"61857.30","quantity":"0.001"},{"price":"61860.40","quantity":"0.178"},{"price":"61861.30","quantity":"0.417"},{"price":"61862.20","quantity":"0.693"},{"price":"61862.30","quantity":"0.970"},{"price":"61862.40","quantity":"0.004"},{"price":"61864.00","quantity":"2.153"},{"price":"61864.50","quantity":"0.582"},{"price":"61866.80","quantity":"3.427"},{"price":"61871.20","quantity":"0.027"},{"price":"61872.90","quantity":"0.334"},{"price":"61873.00","quantity":"2.056"},{"price":"61879.20","quantity":"0.005"},{"price":"61893.10","quantity":"0.472"},{"price":"61893.40","quantity":"1.016"},{"price":"61898.20","quantity":"0.001"},{"price":"61904.50","quantity":"0.282"},{"price":"61904.60","quantity":"4.290"},{"price":"61904.70","quantity":"0.003"},{"price":"61904.80","quantity":"0.487"},{"price":"62163.10","quantity":"0.001"},{"price":"62353.50","quantity":"0.008"},{"price":"62472.30","quantity":"0.000"},{"price":"63089.30","quantity":"0.099"},{"price":"63979.20","quantity":"0.000"}],"raw":{"e":"depthUpdate","E":1783517068842,"T":1783517068841,"s":"BTCUSDT","ps":"BTCUSDT","U":10999770753707,"u":10999770764209,"pu":10999770753660,"b":[["1000.00","207.692"],["11353.70","1.428"],["11453.70","0.272"],["11653.70","1.184"],["11753.70","2.016"],["55668.30","0.002"],["58761.00","0.009"],["59379.50","0.001"],["60615.20","0.003"],["61235.20","0.025"],["61544.40","0.012"],["61784.00","1.582"],["61784.20","0.002"],["61784.30","0.078"],["61786.30","33.857"],["61789.00","6.372"],["61808.10","0.101"],["61822.00","0.081"],["61822.80","0.400"],["61823.60","0.000"],["61824.50","0.445"],["61825.00","1.335"],["61825.10","0.255"],["61825.20","0.001"],["61825.60","0.601"],["61825.70","0.012"],["61826.40","0.881"],["61829.00","0.364"],["61835.20","0.002"],["61838.00","0.000"],["61838.20","0.325"],["61839.00","0.004"],["61839.10","0.080"],["61839.20","0.001"],["61840.10","0.002"],["61840.70","0.090"],["61841.40","1.281"],["61842.20","0.001"],["61843.10","0.053"],["61844.00","0.032"],["61846.90","0.082"],["61850.00","0.534"],["61851.10","0.000"],["61852.30","0.007"],["61853.40","0.004"],["61853.60","0.002"],["61853.70","1.020"]],"a":[["61853.80","9.171"],["61854.00","0.024"],["61854.80","0.906"],["61854.90","2.366"],["61855.10","0.061"],["61856.40","0.031"],["61856.60","0.398"],["61856.70","0.012"],["61857.30","0.001"],["61860.40","0.178"],["61861.30","0.417"],["61862.20","0.693"],["61862.30","0.970"],["61862.40","0.004"],["61864.00","2.153"],["61864.50","0.582"],["61866.80","3.427"],["61871.20","0.027"],["61872.90","0.334"],["61873.00","2.056"],["61879.20","0.005"],["61893.10","0.472"],["61893.40","1.016"],["61898.20","0.001"],["61904.50","0.282"],["61904.60","4.290"],["61904.70","0.003"],["61904.80","0.487"],["62163.10","0.001"],["62353.50","0.008"],["62472.30","0.000"],["63089.30","0.099"],["63979.20","0.000"]],"st":1}}
{"schema_version":"1.3.0","event_id":"2dd3b8ad-bd01-41cb-9979-5f946f2e1bbf","event_type":"raw.trade","source":"binance_market_data_recorder","venue":"binance_usdm","market_type":"perpetual_futures","symbol":"BTCUSDT","event_time_ms":1783517068880,"received_time_ms":1783517068875,"trace_id":"8dcb5ee7-39b9-4d60-9242-95f950b8b1e6","trade_id":7881418065,"price":"61853.70","quantity":"0.005","trade_time_ms":1783517068879,"is_buyer_maker":true,"aggressor_side":"sell","raw":{"e":"trade","E":1783517068880,"T":1783517068879,"s":"BTCUSDT","t":7881418065,"p":"61853.70","q":"0.005","X":"MARKET","m":true,"st":1}}
{"schema_version":"1.3.0","event_id":"e1fdc1d7-d31f-4574-952b-1672570a00dd","event_type":"raw.trade","source":"binance_market_data_recorder","venue":"binance_usdm","market_type":"perpetual_futures","symbol":"BTCUSDT","event_time_ms":1783517068880,"received_time_ms":1783517068877,"trace_id":"1fcb8f28-1634-4c72-8eab-6cdba22177d6","trade_id":7881418066,"price":"61853.70","quantity":"0.001","trade_time_ms":1783517068879,"is_buyer_maker":true,"aggressor_side":"sell","raw":{"e":"trade","E":1783517068880,"T":1783517068879,"s":"BTCUSDT","t":7881418066,"p":"61853.70","q":"0.001","X":"MARKET","m":true,"st":1}}
{"schema_version":"1.3.0","event_id":"0a62f4be-4595-42fd-bfb6-0d24cc3d5cab","event_type":"raw.trade","source":"binance_market_data_recorder","venue":"binance_usdm","market_type":"perpetual_futures","symbol":"BTCUSDT","event_time_ms":1783517068880,"received_time_ms":1783517068877,"trace_id":"18a9d923-0f46-4647-ba2e-765915ad6845","trade_id":7881418067,"price":"61853.70","quantity":"0.042","trade_time_ms":1783517068879,"is_buyer_maker":true,"aggressor_side":"sell","raw":{"e":"trade","E":1783517068880,"T":1783517068879,"s":"BTCUSDT","t":7881418067,"p":"61853.70","q":"0.042","X":"MARKET","m":true,"st":1}}
{"schema_version":"1.3.0","event_id":"35214492-8f81-4c09-bde0-c1e59eb42f41","event_type":"raw.depth_update","source":"binance_market_data_recorder","venue":"binance_usdm","market_type":"perpetual_futures","symbol":"ETHUSDT","event_time_ms":1783517068910,"received_time_ms":1783517068905,"trace_id":"2f38b937-3e56-4ba2-9b73-eb716016a9fd","first_update_id":10999770758453,"final_update_id":10999770775364,"previous_final_update_id":10999770758332,"bids":[{"price":"200.00","quantity":"7.594"},{"price":"1211.12","quantity":"1.185"},{"price":"1226.11","quantity":"0.672"},{"price":"1231.11","quantity":"5.280"},{"price":"1231.12","quantity":"1.920"},{"price":"1562.49","quantity":"0.026"},{"price":"1562.50","quantity":"4.262"},{"price":"1666.60","quantity":"1.078"},{"price":"1701.38","quantity":"43.670"},{"price":"1707.85","quantity":"29.252"},{"price":"1730.67","quantity":"16.462"},{"price":"1732.09","quantity":"37.542"},{"price":"1733.50","quantity":"13.855"},{"price":"1733.88","quantity":"44.716"},{"price":"1733.89","quantity":"0.765"},{"price":"1733.95","quantity":"3.942"},{"price":"1734.18","quantity":"420.446"},{"price":"1734.23","quantity":"60.276"},{"price":"1734.24","quantity":"1.474"},{"price":"1734.30","quantity":"50.741"},{"price":"1734.31","quantity":"17.757"},{"price":"1734.53","quantity":"255.561"},{"price":"1734.57","quantity":"29.351"},{"price":"1734.61","quantity":"0.240"},{"price":"1734.71","quantity":"206.715"},{"price":"1734.73","quantity":"97.085"},{"price":"1734.74","quantity":"11.549"},{"price":"1735.14","quantity":"9.918"},{"price":"1735.17","quantity":"3.284"},{"price":"1735.23","quantity":"43.841"},{"price":"1735.24","quantity":"7.526"},{"price":"1735.30","quantity":"29.159"},{"price":"1735.33","quantity":"16.529"},{"price":"1735.34","quantity":"0.110"},{"price":"1735.37","quantity":"3.595"},{"price":"1735.46","quantity":"21.336"},{"price":"1735.53","quantity":"5.205"},{"price":"1735.56","quantity":"33.563"},{"price":"1735.58","quantity":"0.094"},{"price":"1735.61","quantity":"8.774"},{"price":"1735.63","quantity":"0.588"},{"price":"1735.64","quantity":"76.667"},{"price":"1735.65","quantity":"20.560"},{"price":"1735.66","quantity":"29.107"},{"price":"1735.68","quantity":"15.169"},{"price":"1735.70","quantity":"0.037"},{"price":"1735.71","quantity":"0.038"},{"price":"1735.73","quantity":"26.047"},{"price":"1735.76","quantity":"11.257"},{"price":"1735.81","quantity":"7.246"},{"price":"1735.83","quantity":"21.004"},{"price":"1735.84","quantity":"8.707"},{"price":"1735.86","quantity":"27.882"},{"price":"1735.87","quantity":"0.757"},{"price":"1735.88","quantity":"0.254"},{"price":"1735.89","quantity":"81.225"},{"price":"1735.90","quantity":"1.266"},{"price":"1735.91","quantity":"10.048"},{"price":"1735.92","quantity":"25.525"},{"price":"1735.93","quantity":"10.246"},{"price":"1735.95","quantity":"0.074"},{"price":"1735.96","quantity":"0.552"},{"price":"1735.97","quantity":"3.383"},{"price":"1735.98","quantity":"1.036"},{"price":"1736.00","quantity":"3.544"},{"price":"1736.03","quantity":"1.122"},{"price":"1736.04","quantity":"0.012"},{"price":"1736.05","quantity":"0.051"},{"price":"1736.07","quantity":"0.047"},{"price":"1736.11","quantity":"12.408"}],"asks":[{"price":"1736.12","quantity":"301.409"},{"price":"1736.15","quantity":"0.048"},{"price":"1736.16","quantity":"1.431"},{"price":"1736.18","quantity":"1.781"},{"price":"1736.20","quantity":"4.780"},{"price":"1736.24","quantity":"9.257"},{"price":"1736.25","quantity":"3.977"},{"price":"1736.29","quantity":"1.210"},{"price":"1736.31","quantity":"22.895"},{"price":"1736.33","quantity":"1.735"},{"price":"1736.36","quantity":"34.003"},{"price":"1736.37","quantity":"17.728"},{"price":"1736.42","quantity":"7.674"},{"price":"1736.43","quantity":"20.921"},{"price":"1736.65","quantity":"22.453"},{"price":"1736.90","quantity":"57.445"},{"price":"1736.98","quantity":"16.096"},{"price":"1737.01","quantity":"76.981"},{"price":"1737.12","quantity":"7.826"},{"price":"1737.19","quantity":"6.167"},{"price":"1737.35","quantity":"0.044"},{"price":"1737.37","quantity":"30.259"},{"price":"1737.54","quantity":"27.248"},{"price":"1737.57","quantity":"42.677"},{"price":"1737.80","quantity":"5.124"},{"price":"1737.89","quantity":"17.008"},{"price":"1737.94","quantity":"1.679"},{"price":"1738.00","quantity":"90.234"},{"price":"1738.03","quantity":"0.000"},{"price":"1738.08","quantity":"409.324"},{"price":"1738.12","quantity":"21.565"},{"price":"1738.13","quantity":"19.864"},{"price":"1738.14","quantity":"16.295"},{"price":"1738.80","quantity":"8.359"},{"price":"1738.88","quantity":"8.584"},{"price":"1739.42","quantity":"20.408"},{"price":"1740.16","quantity":"2.509"},{"price":"1740.58","quantity":"0.782"},{"price":"1741.41","quantity":"24.723"},{"price":"1747.12","quantity":"15.000"},{"price":"2634.63","quantity":"0.010"},{"price":"2634.72","quantity":"0.000"}],"raw":{"e":"depthUpdate","E":1783517068910,"T":1783517068909,"s":"ETHUSDT","ps":"ETHUSDT","U":10999770758453,"u":10999770775364,"pu":10999770758332,"b":[["200.00","7.594"],["1211.12","1.185"],["1226.11","0.672"],["1231.11","5.280"],["1231.12","1.920"],["1562.49","0.026"],["1562.50","4.262"],["1666.60","1.078"],["1701.38","43.670"],["1707.85","29.252"],["1730.67","16.462"],["1732.09","37.542"],["1733.50","13.855"],["1733.88","44.716"],["1733.89","0.765"],["1733.95","3.942"],["1734.18","420.446"],["1734.23","60.276"],["1734.24","1.474"],["1734.30","50.741"],["1734.31","17.757"],["1734.53","255.561"],["1734.57","29.351"],["1734.61","0.240"],["1734.71","206.715"],["1734.73","97.085"],["1734.74","11.549"],["1735.14","9.918"],["1735.17","3.284"],["1735.23","43.841"],["1735.24","7.526"],["1735.30","29.159"],["1735.33","16.529"],["1735.34","0.110"],["1735.37","3.595"],["1735.46","21.336"],["1735.53","5.205"],["1735.56","33.563"],["1735.58","0.094"],["1735.61","8.774"],["1735.63","0.588"],["1735.64","76.667"],["1735.65","20.560"],["1735.66","29.107"],["1735.68","15.169"],["1735.70","0.037"],["1735.71","0.038"],["1735.73","26.047"],["1735.76","11.257"],["1735.81","7.246"],["1735.83","21.004"],["1735.84","8.707"],["1735.86","27.882"],["1735.87","0.757"],["1735.88","0.254"],["1735.89","81.225"],["1735.90","1.266"],["1735.91","10.048"],["1735.92","25.525"],["1735.93","10.246"],["1735.95","0.074"],["1735.96","0.552"],["1735.97","3.383"],["1735.98","1.036"],["1736.00","3.544"],["1736.03","1.122"],["1736.04","0.012"],["1736.05","0.051"],["1736.07","0.047"],["1736.11","12.408"]],"a":[["1736.12","301.409"],["1736.15","0.048"],["1736.16","1.431"],["1736.18","1.781"],["1736.20","4.780"],["1736.24","9.257"],["1736.25","3.977"],["1736.29","1.210"],["1736.31","22.895"],["1736.33","1.735"],["1736.36","34.003"],["1736.37","17.728"],["1736.42","7.674"],["1736.43","20.921"],["1736.65","22.453"],["1736.90","57.445"],["1736.98","16.096"],["1737.01","76.981"],["1737.12","7.826"],["1737.19","6.167"],["1737.35","0.044"],["1737.37","30.259"],["1737.54","27.248"],["1737.57","42.677"],["1737.80","5.124"],["1737.89","17.008"],["1737.94","1.679"],["1738.00","90.234"],["1738.03","0.000"],["1738.08","409.324"],["1738.12","21.565"],["1738.13","19.864"],["1738.14","16.295"],["1738.80","8.359"],["1738.88","8.584"],["1739.42","20.408"],["1740.16","2.509"],["1740.58","0.782"],["1741.41","24.723"],["1747.12","15.000"],["2634.63","0.010"],["2634.72","0.000"]],"st":1}}
{"schema_version":"1.3.0","event_id":"1ccad710-e31b-4502-85f8-ef1859547f35","event_type":"raw.depth_update","source":"binance_market_data_recorder","venue":"binance_usdm","market_type":"perpetual_futures","symbol":"BTCUSDT","event_time_ms":1783517068944,"received_time_ms":1783517068940,"trace_id":"439451ec-6699-46f2-a8ab-0ef99ba7350c","first_update_id":10999770764375,"final_update_id":10999770780155,"previous_final_update_id":10999770764209,"bids":[{"price":"11353.70","quantity":"1.564"},{"price":"11453.70","quantity":"0.136"},{"price":"11653.70","quantity":"1.456"},{"price":"11753.70","quantity":"1.744"},{"price":"55668.30","quantity":"0.002"},{"price":"58761.00","quantity":"0.009"},{"price":"59379.50","quantity":"0.004"},{"price":"60616.70","quantity":"0.026"},{"price":"60984.10","quantity":"9.904"},{"price":"61045.00","quantity":"0.380"},{"price":"61235.20","quantity":"0.025"},{"price":"61537.60","quantity":"0.348"},{"price":"61544.40","quantity":"0.013"},{"price":"61730.00","quantity":"0.457"},{"price":"61748.20","quantity":"0.016"},{"price":"61749.10","quantity":"0.003"},{"price":"61749.20","quantity":"0.005"},{"price":"61768.20","quantity":"0.066"},{"price":"61798.00","quantity":"0.062"},{"price":"61808.60","quantity":"0.018"},{"price":"61810.20","quantity":"0.080"},{"price":"61816.10","quantity":"0.000"},{"price":"61820.20","quantity":"0.343"},{"price":"61822.00","quantity":"0.001"},{"price":"61822.80","quantity":"0.400"},{"price":"61824.60","quantity":"0.587"},{"price":"61825.00","quantity":"1.415"},{"price":"61825.60","quantity":"0.019"},{"price":"61829.90","quantity":"0.013"},{"price":"61830.60","quantity":"0.001"},{"price":"61835.40","quantity":"1.003"},{"price":"61836.50","quantity":"0.023"},{"price":"61837.90","quantity":"1.645"},{"price":"61838.50","quantity":"0.095"},{"price":"61839.10","quantity":"0.000"},{"price":"61841.20","quantity":"0.003"},{"price":"61841.80","quantity":"0.106"},{"price":"61842.30","quantity":"0.001"},{"price":"61843.10","quantity":"0.052"},{"price":"61848.40","quantity":"0.008"},{"price":"61849.70","quantity":"0.002"},{"price":"61850.60","quantity":"0.000"},{"price":"61852.20","quantity":"0.630"},{"price":"61853.60","quantity":"0.002"},{"price":"61853.70","quantity":"0.981"}],"asks":[{"price":"61853.80","quantity":"10.124"},{"price":"61854.00","quantity":"0.266"},{"price":"61854.80","quantity":"0.905"},{"price":"61854.90","quantity":"2.366"},{"price":"61855.00","quantity":"1.953"},{"price":"61855.10","quantity":"0.063"},{"price":"61856.40","quantity":"0.029"},{"price":"61856.50","quantity":"0.050"},{"price":"61856.60","quantity":"0.397"},{"price":"61856.70","quantity":"0.010"},{"price":"61859.50","quantity":"0.019"},{"price":"61860.20","quantity":"1.297"},{"price":"61868.60","quantity":"0.002"},{"price":"61869.70","quantity":"0.011"},{"price":"61872.90","quantity":"0.070"},{"price":"61884.30","quantity":"0.141"},{"price":"61893.00","quantity":"0.580"},{"price":"61893.10","quantity":"0.208"},{"price":"61893.20","quantity":"0.000"},{"price":"61893.30","quantity":"0.473"},{"price":"61895.90","quantity":"0.051"},{"price":"61897.20","quantity":"0.001"},{"price":"62027.40","quantity":"0.000"},{"price":"62027.50","quantity":"0.003"},{"price":"62163.10","quantity":"0.002"},{"price":"62316.20","quantity":"0.007"},{"price":"62472.30","quantity":"0.000"},{"price":"62534.00","quantity":"0.023"},{"price":"62623.20","quantity":"2.392"},{"price":"89523.20","quantity":"0.786"}],"raw":{"e":"depthUpdate","E":1783517068944,"T":1783517068943,"s":"BTCUSDT","ps":"BTCUSDT","U":10999770764375,"u":10999770780155,"pu":10999770764209,"b":[["11353.70","1.564"],["11453.70","0.136"],["11653.70","1.456"],["11753.70","1.744"],["55668.30","0.002"],["58761.00","0.009"],["59379.50","0.004"],["60616.70","0.026"],["60984.10","9.904"],["61045.00","0.380"],["61235.20","0.025"],["61537.60","0.348"],["61544.40","0.013"],["61730.00","0.457"],["61748.20","0.016"],["61749.10","0.003"],["61749.20","0.005"],["61768.20","0.066"],["61798.00","0.062"],["61808.60","0.018"],["61810.20","0.080"],["61816.10","0.000"],["61820.20","0.343"],["61822.00","0.001"],["61822.80","0.400"],["61824.60","0.587"],["61825.00","1.415"],["61825.60","0.019"],["61829.90","0.013"],["61830.60","0.001"],["61835.40","1.003"],["61836.50","0.023"],["61837.90","1.645"],["61838.50","0.095"],["61839.10","0.000"],["61841.20","0.003"],["61841.80","0.106"],["61842.30","0.001"],["61843.10","0.052"],["61848.40","0.008"],["61849.70","0.002"],["61850.60","0.000"],["61852.20","0.630"],["61853.60","0.002"],["61853.70","0.981"]],"a":[["61853.80","10.124"],["61854.00","0.266"],["61854.80","0.905"],["61854.90","2.366"],["61855.00","1.953"],["61855.10","0.063"],["61856.40","0.029"],["61856.50","0.050"],["61856.60","0.397"],["61856.70","0.010"],["61859.50","0.019"],["61860.20","1.297"],["61868.60","0.002"],["61869.70","0.011"],["61872.90","0.070"],["61884.30","0.141"],["61893.00","0.580"],["61893.10","0.208"],["61893.20","0.000"],["61893.30","0.473"],["61895.90","0.051"],["61897.20","0.001"],["62027.40","0.000"],["62027.50","0.003"],["62163.10","0.002"],["62316.20","0.007"],["62472.30","0.000"],["62534.00","0.023"],["62623.20","2.392"],["89523.20","0.786"]],"st":1}}
{"schema_version":"1.3.0","event_id":"8676c6a5-f438-4862-a8d8-4dc4e2e3d210","event_type":"raw.trade","source":"binance_market_data_recorder","venue":"binance_usdm","market_type":"perpetual_futures","symbol":"BTCUSDT","event_time_ms":1783517068956,"received_time_ms":1783517068958,"trace_id":"35f8fc8c-abc5-474b-bc66-489488ecacaa","trade_id":7881418068,"price":"61853.80","quantity":"0.001","trade_time_ms":1783517068956,"is_buyer_maker":false,"aggressor_side":"buy","raw":{"e":"trade","E":1783517068956,"T":1783517068956,"s":"BTCUSDT","t":7881418068,"p":"61853.80","q":"0.001","X":"MARKET","m":false,"st":1}}
{"schema_version":"1.3.0","event_id":"5a9fc054-fec0-43e7-ad8c-9a7381e94319","event_type":"raw.trade","source":"binance_market_data_recorder","venue":"binance_usdm","market_type":"perpetual_futures","symbol":"ETHUSDT","event_time_ms":1783517068965,"received_time_ms":1783517068964,"trace_id":"ffda89d8-7f93-436c-a0c9-f3f0438d15ca","trade_id":8429826914,"price":"1736.11","quantity":"0.058","trade_time_ms":1783517068965,"is_buyer_maker":true,"aggressor_side":"sell","raw":{"e":"trade","E":1783517068965,"T":1783517068965,"s":"ETHUSDT","t":8429826914,"p":"1736.11","q":"0.058","X":"MARKET","m":true,"st":1}}
{"schema_version":"1.3.0","event_id":"a54dd25d-0d52-413b-b073-fb3a5652b269","event_type":"raw.trade","source":"binance_market_data_recorder","venue":"binance_usdm","market_type":"perpetual_futures","symbol":"ETHUSDT","event_time_ms":1783517068965,"received_time_ms":1783517068964,"trace_id":"fd4f82ff-92bf-400b-a24a-500b63181fc9","trade_id":8429826915,"price":"1736.11","quantity":"0.012","trade_time_ms":1783517068965,"is_buyer_maker":true,"aggressor_side":"sell","raw":{"e":"trade","E":1783517068965,"T":1783517068965,"s":"ETHUSDT","t":8429826915,"p":"1736.11","q":"0.012","X":"MARKET","m":true,"st":1}}
{"schema_version":"1.3.0","event_id":"6a7af957-f14e-4a0e-9b75-a8e9fed07981","event_type":"raw.trade","source":"binance_market_data_recorder","venue":"binance_usdm","market_type":"perpetual_futures","symbol":"ETHUSDT","event_time_ms":1783517068965,"received_time_ms":1783517068965,"trace_id":"d82f201d-4c7a-4438-a103-1a2891a9195a","trade_id":8429826916,"price":"1736.11","quantity":"0.012","trade_time_ms":1783517068965,"is_buyer_maker":true,"aggressor_side":"sell","raw":{"e":"trade","E":1783517068965,"T":1783517068965,"s":"ETHUSDT","t":8429826916,"p":"1736.11","q":"0.012","X":"MARKET","m":true,"st":1}}
{"schema_version":"1.3.0","event_id":"a820a53a-63ee-4049-a363-7a1b719e89a4","event_type":"raw.trade","source":"binance_market_data_recorder","venue":"binance_usdm","market_type":"perpetual_futures","symbol":"ETHUSDT","event_time_ms":1783517068965,"received_time_ms":1783517068965,"trace_id":"3ef36a5e-1f91-4c20-b51c-f9a35c605d7d","trade_id":8429826917,"price":"1736.11","quantity":"0.013","trade_time_ms":1783517068965,"is_buyer_maker":true,"aggressor_side":"sell","raw":{"e":"trade","E":1783517068965,"T":1783517068965,"s":"ETHUSDT","t":8429826917,"p":"1736.11","q":"0.013","X":"MARKET","m":true,"st":1}}
{"schema_version":"1.3.0","event_id":"2eb6411b-74fd-40cd-b2db-d4ddaad84458","event_type":"raw.trade","source":"binance_market_data_recorder","venue":"binance_usdm","market_type":"perpetual_futures","symbol":"ETHUSDT","event_time_ms":1783517068965,"received_time_ms":1783517068966,"trace_id":"35293aca-3a0e-4829-8be5-0ebde00e1c49","trade_id":8429826918,"price":"1736.11","quantity":"0.149","trade_time_ms":1783517068965,"is_buyer_maker":true,"aggressor_side":"sell","raw":{"e":"trade","E":1783517068965,"T":1783517068965,"s":"ETHUSDT","t":8429826918,"p":"1736.11","q":"0.149","X":"MARKET","m":true,"st":1}}
{"schema_version":"1.3.0","event_id":"72f60533-ccd2-4951-ab31-76ebcbc3fced","event_type":"raw.trade","source":"binance_market_data_recorder","venue":"binance_usdm","market_type":"perpetual_futures","symbol":"ETHUSDT","event_time_ms":1783517068965,"received_time_ms":1783517068967,"trace_id":"ff56c85d-05ad-4398-976a-c6099060b2b8","trade_id":8429826919,"price":"1736.11","quantity":"0.018","trade_time_ms":1783517068965,"is_buyer_maker":true,"aggressor_side":"sell","raw":{"e":"trade","E":1783517068965,"T":1783517068965,"s":"ETHUSDT","t":8429826919,"p":"1736.11","q":"0.018","X":"MARKET","m":true,"st":1}}
{"schema_version":"1.3.0","event_id":"7768cdf0-ddd2-45f1-a1a7-59778dcd82bc","event_type":"raw.trade","source":"binance_market_data_recorder","venue":"binance_usdm","market_type":"perpetual_futures","symbol":"ETHUSDT","event_time_ms":1783517068965,"received_time_ms":1783517068967,"trace_id":"bf98a0a4-4668-43bd-a7a6-f689a785bf94","trade_id":8429826920,"price":"1736.11","quantity":"0.014","trade_time_ms":1783517068965,"is_buyer_maker":true,"aggressor_side":"sell","raw":{"e":"trade","E":1783517068965,"T":1783517068965,"s":"ETHUSDT","t":8429826920,"p":"1736.11","q":"0.014","X":"MARKET","m":true,"st":1}}
{"schema_version":"1.3.0","event_id":"597ee2f8-433d-43cf-8b2a-3beb03f4789a","event_type":"raw.trade","source":"binance_market_data_recorder","venue":"binance_usdm","market_type":"perpetual_futures","symbol":"ETHUSDT","event_time_ms":1783517068965,"received_time_ms":1783517068968,"trace_id":"933da974-6f01-4930-8621-246c08861f0f","trade_id":8429826921,"price":"1736.11","quantity":"0.060","trade_time_ms":1783517068965,"is_buyer_maker":true,"aggressor_side":"sell","raw":{"e":"trade","E":1783517068965,"T":1783517068965,"s":"ETHUSDT","t":8429826921,"p":"1736.11","q":"0.060","X":"MARKET","m":true,"st":1}}
{"schema_version":"1.3.0","event_id":"feec497e-dc3e-46f5-8ce9-1c55517fd835","event_type":"raw.trade","source":"binance_market_data_recorder","venue":"binance_usdm","market_type":"perpetual_futures","symbol":"ETHUSDT","event_time_ms":1783517068965,"received_time_ms":1783517068968,"trace_id":"9520a918-0327-46d3-984f-5da0d4c1d65e","trade_id":8429826922,"price":"1736.11","quantity":"0.029","trade_time_ms":1783517068965,"is_buyer_maker":true,"aggressor_side":"sell","raw":{"e":"trade","E":1783517068965,"T":1783517068965,"s":"ETHUSDT","t":8429826922,"p":"1736.11","q":"0.029","X":"MARKET","m":true,"st":1}}
{"schema_version":"1.3.0","event_id":"f8f08ca2-c1b8-441f-9879-3ec2fbf9cebe","event_type":"raw.depth_update","source":"binance_market_data_recorder","venue":"binance_usdm","market_type":"perpetual_futures","symbol":"ETHUSDT","event_time_ms":1783517069012,"received_time_ms":1783517069007,"trace_id":"280fb0f3-19b3-44f6-bd35-8651f630fb75","first_update_id":10999770775501,"final_update_id":10999770790546,"previous_final_update_id":10999770775364,"bids":[{"price":"200.00","quantity":"7.594"},{"price":"1211.12","quantity":"0.897"},{"price":"1226.11","quantity":"1.184"},{"price":"1231.11","quantity":"5.568"},{"price":"1231.12","quantity":"1.408"},{"price":"1236.11","quantity":"0.295"},{"price":"1562.49","quantity":"0.026"},{"price":"1562.50","quantity":"4.276"},{"price":"1650.00","quantity":"1681.223"},{"price":"1666.60","quantity":"1.193"},{"price":"1701.38","quantity":"43.641"},{"price":"1733.65","quantity":"430.295"},{"price":"1733.66","quantity":"23.837"},{"price":"1733.67","quantity":"5.201"},{"price":"1733.94","quantity":"29.283"},{"price":"1734.18","quantity":"0.070"},{"price":"1734.21","quantity":"79.399"},{"price":"1734.23","quantity":"60.276"},{"price":"1734.24","quantity":"1.474"},{"price":"1734.30","quantity":"21.202"},{"price":"1734.31","quantity":"17.757"},{"price":"1734.33","quantity":"240.475"},{"price":"1734.37","quantity":"41.529"},{"price":"1734.41","quantity":"80.351"},{"price":"1734.53","quantity":"34.922"},{"price":"1734.57","quantity":"29.351"},{"price":"1734.63","quantity":"25.416"},{"price":"1734.64","quantity":"1.603"},{"price":"1734.87","quantity":"19.838"},{"price":"1734.88","quantity":"59.476"},{"price":"1735.11","quantity":"45.389"},{"price":"1735.29","quantity":"29.658"},{"price":"1735.30","quantity":"29.171"},{"price":"1735.31","quantity":"34.008"},{"price":"1735.32","quantity":"27.000"},{"price":"1735.84","quantity":"0.058"},{"price":"1735.88","quantity":"0.236"},{"price":"1735.89","quantity":"81.243"},{"price":"1735.93","quantity":"7.050"},{"price":"1736.11","quantity":"1.611"}],"asks":[{"price":"1736.12","quantity":"300.040"},{"price":"1736.21","quantity":"2.515"},{"price":"1736.33","quantity":"1.735"},{"price":"1736.88","quantity":"3.621"},{"price":"1736.91","quantity":"68.123"},{"price":"1737.16","quantity":"13.024"},{"price":"1737.35","quantity":"26.174"},{"price":"1737.42","quantity":"6.315"},{"price":"1737.51","quantity":"2.858"},{"price":"1737.68","quantity":"0.970"},{"price":"1737.88","quantity":"36.568"},{"price":"1738.00","quantity":"31.032"},{"price":"1738.08","quantity":"1.684"},{"price":"1738.13","quantity":"78.803"},{"price":"1738.14","quantity":"423.935"},{"price":"1738.88","quantity":"11.780"},{"price":"1739.59","quantity":"2.304"},{"price":"1739.60","quantity":"36.362"},{"price":"1740.46","quantity":"2.304"},{"price":"1740.47","quantity":"19.500"},{"price":"1741.32","quantity":"18.212"},{"price":"1741.33","quantity":"0.348"},{"price":"1742.19","quantity":"4.827"},{"price":"1742.20","quantity":"5.897"},{"price":"1743.06","quantity":"2.402"},{"price":"1743.07","quantity":"16.236"},{"price":"1763.28","quantity":"41.091"},{"price":"2634.61","quantity":"0.119"},{"price":"2634.62","quantity":"0.001"},{"price":"2634.70","quantity":"0.000"},{"price":"2634.71","quantity":"0.000"}],"raw":{"e":"depthUpdate","E":1783517069012,"T":1783517069010,"s":"ETHUSDT","ps":"ETHUSDT","U":10999770775501,"u":10999770790546,"pu":10999770775364,"b":[["200.00","7.594"],["1211.12","0.897"],["1226.11","1.184"],["1231.11","5.568"],["1231.12","1.408"],["1236.11","0.295"],["1562.49","0.026"],["1562.50","4.276"],["1650.00","1681.223"],["1666.60","1.193"],["1701.38","43.641"],["1733.65","430.295"],["1733.66","23.837"],["1733.67","5.201"],["1733.94","29.283"],["1734.18","0.070"],["1734.21","79.399"],["1734.23","60.276"],["1734.24","1.474"],["1734.30","21.202"],["1734.31","17.757"],["1734.33","240.475"],["1734.37","41.529"],["1734.41","80.351"],["1734.53","34.922"],["1734.57","29.351"],["1734.63","25.416"],["1734.64","1.603"],["1734.87","19.838"],["1734.88","59.476"],["1735.11","45.389"],["1735.29","29.658"],["1735.30","29.171"],["1735.31","34.008"],["1735.32","27.000"],["1735.84","0.058"],["1735.88","0.236"],["1735.89","81.243"],["1735.93","7.050"],["1736.11","1.611"]],"a":[["1736.12","300.040"],["1736.21","2.515"],["1736.33","1.735"],["1736.88","3.621"],["1736.91","68.123"],["1737.16","13.024"],["1737.35","26.174"],["1737.42","6.315"],["1737.51","2.858"],["1737.68","0.970"],["1737.88","36.568"],["1738.00","31.032"],["1738.08","1.684"],["1738.13","78.803"],["1738.14","423.935"],["1738.88","11.780"],["1739.59","2.304"],["1739.60","36.362"],["1740.46","2.304"],["1740.47","19.500"],["1741.32","18.212"],["1741.33","0.348"],["1742.19","4.827"],["1742.20","5.897"],["1743.06","2.402"],["1743.07","16.236"],["1763.28","41.091"],["2634.61","0.119"],["2634.62","0.001"],["2634.70","0.000"],["2634.71","0.000"]],"st":1}}
{"schema_version":"1.3.0","event_id":"c9ab21fa-514d-4aa6-8253-44d2106cd9b8","event_type":"raw.depth_update","source":"binance_market_data_recorder","venue":"binance_usdm","market_type":"perpetual_futures","symbol":"BTCUSDT","event_time_ms":1783517069046,"received_time_ms":1783517069045,"trace_id":"6ad056ad-b16c-493c-8557-5633cf00a612","first_update_id":10999770780449,"final_update_id":10999770794616,"previous_final_update_id":10999770780155,"bids":[{"price":"1000.00","quantity":"207.692"},{"price":"11353.70","quantity":"1.683"},{"price":"11453.70","quantity":"0.000"},{"price":"11653.70","quantity":"1.728"},{"price":"11753.70","quantity":"1.489"},{"price":"55668.30","quantity":"0.002"},{"price":"58761.00","quantity":"0.009"},{"price":"59379.50","quantity":"0.001"},{"price":"60616.70","quantity":"0.029"},{"price":"60703.90","quantity":"0.000"},{"price":"60704.30","quantity":"0.823"},{"price":"61048.20","quantity":"3.408"},{"price":"61235.20","quantity":"0.025"},{"price":"61280.50","quantity":"3.713"},{"price":"61431.00","quantity":"0.010"},{"price":"61544.40","quantity":"0.013"},{"price":"61771.60","quantity":"0.001"},{"price":"61773.60","quantity":"3.357"},{"price":"61784.00","quantity":"0.000"},{"price":"61784.20","quantity":"0.002"},{"price":"61784.30","quantity":"6.740"},{"price":"61786.30","quantity":"33.857"},{"price":"61789.00","quantity":"1.484"},{"price":"61810.20","quantity":"0.080"},{"price":"61821.20","quantity":"0.161"},{"price":"61828.60","quantity":"0.391"},{"price":"61834.80","quantity":"0.039"},{"price":"61842.60","quantity":"0.102"},{"price":"61848.80","quantity":"0.001"},{"price":"61852.20","quantity":"0.630"},{"price":"61853.60","quantity":"0.002"},{"price":"61853.70","quantity":"0.998"}],"asks":[{"price":"61853.80","quantity":"10.058"},{"price":"61854.70","quantity":"0.370"},{"price":"61854.80","quantity":"0.000"},{"price":"61856.70","quantity":"0.915"},{"price":"61858.20","quantity":"0.131"},{"price":"61859.50","quantity":"0.019"},{"price":"61860.00","quantity":"0.467"},{"price":"61862.20","quantity":"0.127"},{"price":"61863.90","quantity":"0.874"},{"price":"61864.90","quantity":"0.059"},{"price":"61866.20","quantity":"0.570"},{"price":"61868.20","quantity":"0.065"},{"price":"61872.40","quantity":"0.007"},{"price":"61872.90","quantity":"0.070"},{"price":"61892.20","quantity":"0.268"},{"price":"61893.20","quantity":"0.264"},{"price":"62361.00","quantity":"0.320"},{"price":"62472.30","quantity":"0.000"},{"price":"62725.90","quantity":"1.432"},{"price":"63089.30","quantity":"0.096"}],"raw":{"e":"depthUpdate","E":1783517069046,"T":1783517069045,"s":"BTCUSDT","ps":"BTCUSDT","U":10999770780449,"u":10999770794616,"pu":10999770780155,"b":[["1000.00","207.692"],["11353.70","1.683"],["11453.70","0.000"],["11653.70","1.728"],["11753.70","1.489"],["55668.30","0.002"],["58761.00","0.009"],["59379.50","0.001"],["60616.70","0.029"],["60703.90","0.000"],["60704.30","0.823"],["61048.20","3.408"],["61235.20","0.025"],["61280.50","3.713"],["61431.00","0.010"],["61544.40","0.013"],["61771.60","0.001"],["61773.60","3.357"],["61784.00","0.000"],["61784.20","0.002"],["61784.30","6.740"],["61786.30","33.857"],["61789.00","1.484"],["61810.20","0.080"],["61821.20","0.161"],["61828.60","0.391"],["61834.80","0.039"],["61842.60","0.102"],["61848.80","0.001"],["61852.20","0.630"],["61853.60","0.002"],["61853.70","0.998"]],"a":[["61853.80","10.058"],["61854.70","0.370"],["61854.80","0.000"],["61856.70","0.915"],["61858.20","0.131"],["61859.50","0.019"],["61860.00","0.467"],["61862.20","0.127"],["61863.90","0.874"],["61864.90","0.059"],["61866.20","0.570"],["61868.20","0.065"],["61872.40","0.007"],["61872.90","0.070"],["61892.20","0.268"],["61893.20","0.264"],["62361.00","0.320"],["62472.30","0.000"],["62725.90","1.432"],["63089.30","0.096"]],"st":1}}
{"schema_version":"1.3.0","event_id":"3df8c81a-1bec-4e8f-b4bc-5f40c3ebc3e4","event_type":"raw.trade","source":"binance_market_data_recorder","venue":"binance_usdm","market_type":"perpetual_futures","symbol":"ETHUSDT","event_time_ms":1783517069076,"received_time_ms":1783517069072,"trace_id":"bc09582a-e3f9-4119-9c93-8efdd51476d3","trade_id":8429826923,"price":"1736.11","quantity":"0.026","trade_time_ms":1783517069076,"is_buyer_maker":true,"aggressor_side":"sell","raw":{"e":"trade","E":1783517069076,"T":1783517069076,"s":"ETHUSDT","t":8429826923,"p":"1736.11","q":"0.026","X":"MARKET","m":true,"st":1}}
{"schema_version":"1.3.0","event_id":"1c22bf71-ba6c-4d96-9351-03a72143f45c","event_type":"raw.trade","source":"binance_market_data_recorder","venue":"binance_usdm","market_type":"perpetual_futures","symbol":"BTCUSDT","event_time_ms":1783517069087,"received_time_ms":1783517069084,"trace_id":"23a1d678-fb59-4a6b-987d-251968758143","trade_id":7881418069,"price":"61853.70","quantity":"0.001","trade_time_ms":1783517069087,"is_buyer_maker":true,"aggressor_side":"sell","raw":{"e":"trade","E":1783517069087,"T":1783517069087,"s":"BTCUSDT","t":7881418069,"p":"61853.70","q":"0.001","X":"MARKET","m":true,"st":1}}
{"schema_version":"1.3.0","event_id":"174663d8-662c-4bc6-ab98-d9b7ba72e134","event_type":"raw.depth_update","source":"binance_market_data_recorder","venue":"binance_usdm","market_type":"perpetual_futures","symbol":"ETHUSDT","event_time_ms":1783517069114,"received_time_ms":1783517069110,"trace_id":"0380a3a7-b7e0-4ce0-a468-523d15562a53","first_update_id":10999770790801,"final_update_id":10999770805757,"previous_final_update_id":10999770790546,"bids":[{"price":"1211.12","quantity":"0.641"},{"price":"1226.11","quantity":"1.760"},{"price":"1231.11","quantity":"5.824"},{"price":"1231.12","quantity":"0.832"},{"price":"1562.49","quantity":"0.026"},{"price":"1562.50","quantity":"4.418"},{"price":"1666.60","quantity":"1.078"},{"price":"1696.13","quantity":"29.523"},{"price":"1705.90","quantity":"13.794"},{"price":"1711.51","quantity":"13.853"},{"price":"1712.76","quantity":"0.870"},{"price":"1732.13","quantity":"183.379"},{"price":"1732.14","quantity":"37.402"},{"price":"1732.17","quantity":"0.024"},{"price":"1733.65","quantity":"9.919"},{"price":"1733.66","quantity":"23.837"},{"price":"1733.67","quantity":"5.201"},{"price":"1733.83","quantity":"2.290"},{"price":"1733.86","quantity":"0.363"},{"price":"1733.88","quantity":"465.092"},{"price":"1733.89","quantity":"3.961"},{"price":"1733.94","quantity":"93.009"},{"price":"1734.21","quantity":"18.716"},{"price":"1734.22","quantity":"17.049"},{"price":"1734.24","quantity":"1.565"},{"price":"1734.31","quantity":"17.666"},{"price":"1734.33","quantity":"19.867"},{"price":"1734.37","quantity":"9.825"},{"price":"1734.38","quantity":"13.652"},{"price":"1734.45","quantity":"0.656"},{"price":"1734.46","quantity":"25.640"},{"price":"1734.49","quantity":"53.052"},{"price":"1734.63","quantity":"1.527"},{"price":"1734.64","quantity":"221.128"},{"price":"1734.65","quantity":"68.581"},{"price":"1734.71","quantity":"206.733"},{"price":"1734.73","quantity":"97.067"},{"price":"1734.86","quantity":"38.717"},{"price":"1735.06","quantity":"2.219"},{"price":"1735.07","quantity":"7.163"},{"price":"1735.23","quantity":"4.905"},{"price":"1735.28","quantity":"4.974"},{"price":"1735.31","quantity":"72.943"},{"price":"1735.56","quantity":"27.796"},{"price":"1735.60","quantity":"4.613"},{"price":"1735.63","quantity":"6.355"},{"price":"1735.65","quantity":"40.560"},{"price":"1735.66","quantity":"29.004"},{"price":"1735.71","quantity":"0.136"},{"price":"1735.76","quantity":"15.145"},{"price":"1735.83","quantity":"21.004"},{"price":"1735.86","quantity":"5.698"},{"price":"1735.90","quantity":"2.266"},{"price":"1735.91","quantity":"11.685"},{"price":"1735.92","quantity":"25.525"},{"price":"1735.93","quantity":"3.162"},{"price":"1735.95","quantity":"1.226"},{"price":"1735.96","quantity":"0.730"},{"price":"1735.99","quantity":"22.235"},{"price":"1736.06","quantity":"0.014"},{"price":"1736.07","quantity":"0.035"},{"price":"1736.11","quantity":"125.972"}],"asks":[{"price":"1736.12","quantity":"285.297"},{"price":"1736.15","quantity":"0.024"},{"price":"1736.16","quantity":"0.279"},{"price":"1736.20","quantity":"3.992"},{"price":"1736.21","quantity":"0.032"},{"price":"1736.22","quantity":"20.900"},{"price":"1736.25","quantity":"4.765"},{"price":"1736.31","quantity":"22.895"},{"price":"1736.33","quantity":"1.735"},{"price":"1736.35","quantity":"4.537"},{"price":"1736.36","quantity":"5.180"},{"price":"1736.39","quantity":"28.921"},{"price":"1736.47","quantity":"2.139"},{"price":"1736.67","quantity":"12.217"},{"price":"1736.73","quantity":"7.063"},{"price":"1736.77","quantity":"39.064"},{"price":"1736.96","quantity":"3.499"},{"price":"1737.12","quantity":"7.826"},{"price":"1737.34","quantity":"29.891"},{"price":"1738.00","quantity":"31.032"},{"price":"1738.08","quantity":"1.684"},{"price":"1738.12","quantity":"14.060"},{"price":"1738.13","quantity":"19.864"},{"price":"1738.14","quantity":"16.295"},{"price":"1738.17","quantity":"67.863"},{"price":"1738.25","quantity":"410.518"},{"price":"1738.37","quantity":"89.779"},{"price":"1738.39","quantity":"16.597"},{"price":"1738.89","quantity":"59.745"},{"price":"1739.42","quantity":"27.913"},{"price":"1739.97","quantity":"32.859"},{"price":"1739.98","quantity":"145.446"},{"price":"1739.99","quantity":"0.299"},{"price":"1763.30","quantity":"43.606"},{"price":"1764.34","quantity":"283.150"},{"price":"2634.59","quantity":"0.001"},{"price":"2634.60","quantity":"0.001"},{"price":"2634.68","quantity":"0.000"},{"price":"2634.69","quantity":"0.000"}],"raw":{"e":"depthUpdate","E":1783517069114,"T":1783517069113,"s":"ETHUSDT","ps":"ETHUSDT","U":10999770790801,"u":10999770805757,"pu":10999770790546,"b":[["1211.12","0.641"],["1226.11","1.760"],["1231.11","5.824"],["1231.12","0.832"],["1562.49","0.026"],["1562.50","4.418"],["1666.60","1.078"],["1696.13","29.523"],["1705.90","13.794"],["1711.51","13.853"],["1712.76","0.870"],["1732.13","183.379"],["1732.14","37.402"],["1732.17","0.024"],["1733.65","9.919"],["1733.66","23.837"],["1733.67","5.201"],["1733.83","2.290"],["1733.86","0.363"],["1733.88","465.092"],["1733.89","3.961"],["1733.94","93.009"],["1734.21","18.716"],["1734.22","17.049"],["1734.24","1.565"],["1734.31","17.666"],["1734.33","19.867"],["1734.37","9.825"],["1734.38","13.652"],["1734.45","0.656"],["1734.46","25.640"],["1734.49","53.052"],["1734.63","1.527"],["1734.64","221.128"],["1734.65","68.581"],["1734.71","206.733"],["1734.73","97.067"],["1734.86","38.717"],["1735.06","2.219"],["1735.07","7.163"],["1735.23","4.905"],["1735.28","4.974"],["1735.31","72.943"],["1735.56","27.796"],["1735.60","4.613"],["1735.63","6.355"],["1735.65","40.560"],["1735.66","29.004"],["1735.71","0.136"],["1735.76","15.145"],["1735.83","21.004"],["1735.86","5.698"],["1735.90","2.266"],["1735.91","11.685"],["1735.92","25.525"],["1735.93","3.162"],["1735.95","1.226"],["1735.96","0.730"],["1735.99","22.235"],["1736.06","0.014"],["1736.07","0.035"],["1736.11","125.972"]],"a":[["1736.12","285.297"],["1736.15","0.024"],["1736.16","0.279"],["1736.20","3.992"],["1736.21","0.032"],["1736.22","20.900"],["1736.25","4.765"],["1736.31","22.895"],["1736.33","1.735"],["1736.35","4.537"],["1736.36","5.180"],["1736.39","28.921"],["1736.47","2.139"],["1736.67","12.217"],["1736.73","7.063"],["1736.77","39.064"],["1736.96","3.499"],["1737.12","7.826"],["1737.34","29.891"],["1738.00","31.032"],["1738.08","1.684"],["1738.12","14.060"],["1738.13","19.864"],["1738.14","16.295"],["1738.17","67.863"],["1738.25","410.518"],["1738.37","89.779"],["1738.39","16.597"],["1738.89","59.745"],["1739.42","27.913"],["1739.97","32.859"],["1739.98","145.446"],["1739.99","0.299"],["1763.30","43.606"],["1764.34","283.150"],["2634.59","0.001"],["2634.60","0.001"],["2634.68","0.000"],["2634.69","0.000"]],"st":1}}
{"schema_version":"1.3.0","event_id":"186ae67b-4620-4824-9207-8143b1a40e90","event_type":"raw.depth_update","source":"binance_market_data_recorder","venue":"binance_usdm","market_type":"perpetual_futures","symbol":"BTCUSDT","event_time_ms":1783517069148,"received_time_ms":1783517069143,"trace_id":"f1ac8330-e96f-4aa0-92a2-5d488193800b","first_update_id":10999770794824,"final_update_id":10999770808923,"previous_final_update_id":10999770794616,"bids":[{"price":"1000.00","quantity":"207.692"},{"price":"11353.70","quantity":"1.547"},{"price":"11653.70","quantity":"2.000"},{"price":"11753.70","quantity":"1.353"},{"price":"55668.30","quantity":"0.002"},{"price":"58761.00","quantity":"0.012"},{"price":"59379.50","quantity":"0.004"},{"price":"60616.70","quantity":"0.032"},{"price":"61235.20","quantity":"0.025"},{"price":"61749.20","quantity":"0.002"},{"price":"61749.30","quantity":"0.003"},{"price":"61771.60","quantity":"0.001"},{"price":"61773.60","quantity":"3.357"},{"price":"61784.00","quantity":"1.582"},{"price":"61784.30","quantity":"0.078"},{"price":"61786.30","quantity":"33.857"},{"price":"61789.00","quantity":"6.372"},{"price":"61810.80","quantity":"0.008"},{"price":"61830.30","quantity":"0.162"},{"price":"61832.40","quantity":"0.975"},{"price":"61841.90","quantity":"0.383"},{"price":"61842.00","quantity":"0.369"},{"price":"61842.10","quantity":"0.001"},{"price":"61842.50","quantity":"0.673"},{"price":"61842.60","quantity":"0.097"},{"price":"61850.10","quantity":"0.050"},{"price":"61851.10","quantity":"0.583"},{"price":"61853.50","quantity":"0.001"},{"price":"61853.60","quantity":"0.005"},{"price":"61853.70","quantity":"1.814"}],"asks":[{"price":"61853.80","quantity":"9.237"},{"price":"61854.80","quantity":"0.000"},{"price":"61856.50","quantity":"0.955"},{"price":"61856.70","quantity":"0.010"},{"price":"61860.00","quantity":"0.463"},{"price":"61862.30","quantity":"0.002"},{"price":"61863.40","quantity":"0.998"},{"price":"61864.50","quantity":"0.000"},{"price":"61864.90","quantity":"0.054"},{"price":"61865.60","quantity":"0.586"},{"price":"61866.20","quantity":"0.566"},{"price":"61868.20","quantity":"0.048"},{"price":"61871.70","quantity":"0.000"},{"price":"61872.40","quantity":"0.003"},{"price":"61872.70","quantity":"0.010"},{"price":"62027.50","quantity":"0.000"},{"price":"62027.60","quantity":"0.011"},{"price":"62441.40","quantity":"3.221"},{"price":"62472.30","quantity":"0.000"},{"price":"62780.10","quantity":"0.361"},{"price":"89523.20","quantity":"0.792"}],"raw":{"e":"depthUpdate","E":1783517069148,"T":1783517069145,"s":"BTCUSDT","ps":"BTCUSDT","U":10999770794824,"u":10999770808923,"pu":10999770794616,"b":[["1000.00","207.692"],["11353.70","1.547"],["11653.70","2.000"],["11753.70","1.353"],["55668.30","0.002"],["58761.00","0.012"],["59379.50","0.004"],["60616.70","0.032"],["61235.20","0.025"],["61749.20","0.002"],["61749.30","0.003"],["61771.60","0.001"],["61773.60","3.357"],["61784.00","1.582"],["61784.30","0.078"],["61786.30","33.857"],["61789.00","6.372"],["61810.80","0.008"],["61830.30","0.162"],["61832.40","0.975"],["61841.90","0.383"],["61842.00","0.369"],["61842.10","0.001"],["61842.50","0.673"],["61842.60","0.097"],["61850.10","0.050"],["61851.10","0.583"],["61853.50","0.001"],["61853.60","0.005"],["61853.70","1.814"]],"a":[["61853.80","9.237"],["61854.80","0.000"],["61856.50","0.955"],["61856.70","0.010"],["61860.00","0.463"],["61862.30","0.002"],["61863.40","0.998"],["61864.50","0.000"],["61864.90","0.054"],["61865.60","0.586"],["61866.20","0.566"],["61868.20","0.048"],["61871.70","0.000"],["61872.40","0.003"],["61872.70","0.010"],["62027.50","0.000"],["62027.60","0.011"],["62441.40","3.221"],["62472.30","0.000"],["62780.10","0.361"],["89523.20","0.792"]],"st":1}}
