{"schema_version":"1.3.0","event_id":"e4073cc7-498d-412a-8f7c-2b36407ea4cc","event_type":"raw.depth_update","source":"binance_market_data_recorder","venue":"binance_usdm","market_type":"perpetual_futures","symbol":"ETHUSDT","event_time_ms":1783517069218,"received_time_ms":1783517069212,"trace_id":"55d0f705-a75b-4253-a700-f2c1eb34b19e","first_update_id":10999770806036,"final_update_id":10999770817136,"previous_final_update_id":10999770805757,"bids":[{"price":"200.00","quantity":"7.594"},{"price":"1211.12","quantity":"0.353"},{"price":"1226.11","quantity":"2.304"},{"price":"1231.11","quantity":"6.112"},{"price":"1231.12","quantity":"0.288"},{"price":"1562.49","quantity":"0.026"},{"price":"1562.50","quantity":"4.290"},{"price":"1690.42","quantity":"105.508"},{"price":"1701.38","quantity":"43.670"},{"price":"1706.13","quantity":"20.490"},{"price":"1733.59","quantity":"443.047"},{"price":"1733.66","quantity":"82.683"},{"price":"1733.74","quantity":"16.412"},{"price":"1733.88","quantity":"44.716"},{"price":"1733.94","quantity":"29.283"},{"price":"1733.99","quantity":"0.014"},{"price":"1734.44","quantity":"56.254"},{"price":"1734.45","quantity":"0.638"},{"price":"1734.46","quantity":"25.640"},{"price":"1734.62","quantity":"119.370"},{"price":"1734.64","quantity":"221.146"},{"price":"1734.66","quantity":"221.822"},{"price":"1734.80","quantity":"9.123"},{"price":"1735.15","quantity":"6.663"},{"price":"1735.28","quantity":"4.962"},{"price":"1735.29","quantity":"29.646"},{"price":"1735.30","quantity":"29.159"},{"price":"1735.31","quantity":"72.931"},{"price":"1735.32","quantity":"26.988"},{"price":"1735.33","quantity":"16.517"},{"price":"1735.34","quantity":"0.098"},{"price":"1735.63","quantity":"6.343"},{"price":"1735.67","quantity":"0.063"},{"price":"1735.71","quantity":"0.136"},{"price":"1735.90","quantity":"1.266"},{"price":"1735.96","quantity":"22.914"},{"price":"1735.99","quantity":"0.052"},{"price":"1736.00","quantity":"6.548"},{"price":"1736.04","quantity":"0.024"},{"price":"1736.05","quantity":"0.063"},{"price":"1736.06","quantity":"0.026"},{"price":"1736.07","quantity":"0.047"},{"price":"1736.11","quantity":"89.118"}],"asks":[{"price":"1736.12","quantity":"285.168"},{"price":"1736.16","quantity":"0.291"},{"price":"1736.24","quantity":"9.300"},{"price":"1736.25","quantity":"4.265"},{"price":"1736.27","quantity":"0.526"},{"price":"1736.61","quantity":"13.962"},{"price":"1736.65","quantity":"18.214"},{"price":"1736.96","quantity":"9.259"},{"price":"1736.97","quantity":"2.975"},{"price":"1737.31","quantity":"20.947"},{"price":"1738.13","quantity":"78.803"},{"price":"1738.14","quantity":"423.935"},{"price":"1738.17","quantity":"7.677"},{"price":"1738.25","quantity":"2.878"},{"price":"1738.34","quantity":"10.619"},{"price":"1747.12","quantity":"0.000"},{"price":"1764.46","quantity":"31.242"},{"price":"1769.55","quantity":"82.979"},{"price":"2634.58","quantity":"0.001"},{"price":"2634.67","quantity":"0.000"}],"raw":{"e":"depthUpdate","E":1783517069218,"T":1783517069217,"s":"ETHUSDT","ps":"ETHUSDT","U":10999770806036,"u":10999770817136,"pu":10999770805757,"b":[["200.00","7.594"],["1211.12","0.353"],["1226.11","2.304"],["1231.11","6.112"],["1231.12","0.288"],["1562.49","0.026"],["1562.50","4.290"],["1690.42","105.508"],["1701.38","43.670"],["1706.13","20.490"],["1733.59","443.047"],["1733.66","82.683"],["1733.74","16.412"],["1733.88","44.716"],["1733.94","29.283"],["1733.99","0.014"],["1734.44","56.254"],["1734.45","0.638"],["1734.46","25.640"],["1734.62","119.370"],["1734.64","221.146"],["1734.66","221.822"],["1734.80","9.123"],["1735.15","6.663"],["1735.28","4.962"],["1735.29","29.646"],["1735.30","29.159"],["1735.31","72.931"],["1735.32","26.988"],["1735.33","16.517"],["1735.34","0.098"],["1735.63","6.343"],["1735.67","0.063"],["1735.71","0.136"],["1735.90","1.266"],["1735.96","22.914"],["1735.99","0.052"],["1736.00","6.548"],["1736.04","0.024"],["1736.05","0.063"],["1736.06","0.026"],["1736.07","0.047"],["1736.11","89.118"]],"a":[["1736.12","285.168"],["1736.16","0.291"],["1736.24","9.300"],["1736.25","4.265"],["1736.27","0.526"],["1736.61","13.962"],["1736.65","18.214"],["1736.96","9.259"],["1736.97","2.975"],["1737.31","20.947"],["1738.13","78.803"],["1738.14","423.935"],["1738.17","7.677"],["1738.25","2.878"],["1738.34","10.619"],["1747.12","0.000"],["1764.46","31.242"],["1769.55","82.979"],["2634.58","0.001"],["2634.67","0.000"]],"st":1}}
{"schema_version":"1.3.0","event_id":"7a55ef5f-8c96-4acd-a94b-efe6e53a2de4","event_type":"raw.depth_update","source":"binance_market_data_recorder","venue":"binance_usdm","market_type":"perpetual_futures","symbol":"BTCUSDT","event_time_ms":1783517069250,"received_time_ms":1783517069245,"trace_id":"7f9ae5dd-9ad9-433f-b512-a41bfa3fe2b2","first_update_id":10999770809124,"final_update_id":10999770821184,"previous_final_update_id":10999770808923,"bids":[{"price":"11353.70","quantity":"1.394"},{"price":"11653.70","quantity":"2.272"},{"price":"11753.70","quantity":"1.234"},{"price":"55668.30","quantity":"0.002"},{"price":"58761.00","quantity":"0.012"},{"price":"61149.10","quantity":"0.003"},{"price":"61235.20","quantity":"0.027"},{"price":"61293.60","quantity":"1.288"},{"price":"61297.00","quantity":"2.520"},{"price":"61771.60","quantity":"0.001"},{"price":"61773.60","quantity":"3.357"},{"price":"61786.30","quantity":"33.857"},{"price":"61789.00","quantity":"1.484"},{"price":"61790.30","quantity":"0.001"},{"price":"61808.00","quantity":"4.445"},{"price":"61821.30","quantity":"0.060"},{"price":"61822.00","quantity":"0.001"},{"price":"61838.50","quantity":"0.015"},{"price":"61838.60","quantity":"0.096"},{"price":"61853.40","quantity":"0.005"},{"price":"61853.50","quantity":"0.002"},{"price":"61853.60","quantity":"0.003"},{"price":"61853.70","quantity":"1.813"}],"asks":[{"price":"61863.90","quantity":"0.308"},{"price":"61864.60","quantity":"0.632"},{"price":"61866.40","quantity":"0.001"},{"price":"61867.60","quantity":"0.466"},{"price":"61893.10","quantity":"0.001"},{"price":"61893.20","quantity":"0.471"},{"price":"61914.20","quantity":"0.080"},{"price":"62472.30","quantity":"0.000"},{"price":"62528.00","quantity":"0.655"}],"raw":{"e":"depthUpdate","E":1783517069250,"T":1783517069249,"s":"BTCUSDT","ps":"BTCUSDT","U":10999770809124,"u":10999770821184,"pu":10999770808923,"b":[["11353.70","1.394"],["11653.70","2.272"],["11753.70","1.234"],["55668.30","0.002"],["58761.00","0.012"],["61149.10","0.003"],["61235.20","0.027"],["61293.60","1.288"],["61297.00","2.520"],["61771.60","0.001"],["61773.60","3.357"],["61786.30","33.857"],["61789.00","1.484"],["61790.30","0.001"],["61808.00","4.445"],["61821.30","0.060"],["61822.00","0.001"],["61838.50","0.015"],["61838.60","0.096"],["61853.40","0.005"],["61853.50","0.002"],["61853.60","0.003"],["61853.70","1.813"]],"a":[["61863.90","0.308"],["61864.60","0.632"],["61866.40","0.001"],["61867.60","0.466"],["61893.10","0.001"],["61893.20","0.471"],["61914.20","0.080"],["62472.30","0.000"],["62528.00","0.655"]],"st":1}}
{"schema_version":"1.3.0","event_id":"f6347de9-339a-4a17-acd1-6d01ec107777","event_type":"raw.trade","source":"binance_market_data_recorder","venue":"binance_usdm","market_type":"perpetual_futures","symbol":"BTCUSDT","event_time_ms":1783517069315,"received_time_ms":1783517069316,"trace_id":"c9df72b7-5a44-4cdc-8281-b1825b184201","trade_id":7881418070,"price":"61853.80","quantity":"0.037","trade_time_ms":1783517069315,"is_buyer_maker":false,"aggressor_side":"buy","raw":{"e":"trade","E":1783517069315,"T":1783517069315,"s":"BTCUSDT","t":7881418070,"p":"61853.80","q":"0.037","X":"MARKET","m":false,"st":1}}
{"schema_version":"1.3.0","event_id":"f94ea7f5-b146-4cb7-ac69-fe367d1eb9f5","event_type":"raw.depth_update","source":"binance_market_data_recorder","venue":"binance_usdm","market_type":"perpetual_futures","symbol":"ETHUSDT","event_time_ms":1783517069320,"received_time_ms":1783517069320,"trace_id":"f2ebb8d5-9fb8-4e86-94ea-6bde77c02a61","first_update_id":10999770817295,"final_update_id":10999770830523,"previous_final_update_id":10999770817136,"bids":[{"price":"200.00","quantity":"7.594"},{"price":"1211.11","quantity":"0.677"},{"price":"1211.12","quantity":"0.193"},{"price":"1226.11","quantity":"2.848"},{"price":"1231.11","quantity":"6.112"},{"price":"1231.12","quantity":"0.000"},{"price":"1562.49","quantity":"0.026"},{"price":"1562.50","quantity":"4.162"},{"price":"1666.60","quantity":"1.193"},{"price":"1701.38","quantity":"43.641"},{"price":"1703.00","quantity":"194.417"},{"price":"1706.60","quantity":"57.976"},{"price":"1708.81","quantity":"15.781"},{"price":"1708.97","quantity":"9.593"},{"price":"1710.24","quantity":"172.251"},{"price":"1718.74","quantity":"57.612"},{"price":"1727.42","quantity":"0.629"},{"price":"1727.89","quantity":"10.013"},{"price":"1727.91","quantity":"2.673"},{"price":"1727.94","quantity":"0.176"},{"price":"1733.59","quantity":"22.671"},{"price":"1733.60","quantity":"68.107"},{"price":"1733.66","quantity":"23.837"},{"price":"1733.68","quantity":"18.785"},{"price":"1733.82","quantity":"2.575"},{"price":"1733.89","quantity":"0.765"},{"price":"1734.12","quantity":"55.897"},{"price":"1734.18","quantity":"0.012"},{"price":"1734.44","quantity":"56.236"},{"price":"1734.47","quantity":"4.441"},{"price":"1734.49","quantity":"53.070"},{"price":"1734.57","quantity":"29.409"},{"price":"1734.62","quantity":"119.388"},{"price":"1734.64","quantity":"0.556"},{"price":"1734.65","quantity":"13.554"},{"price":"1734.66","quantity":"1.206"},{"price":"1734.72","quantity":"2.933"},{"price":"1734.98","quantity":"290.505"},{"price":"1735.11","quantity":"45.389"},{"price":"1735.13","quantity":"3.178"},{"price":"1735.32","quantity":"27.000"},{"price":"1735.33","quantity":"16.529"},{"price":"1735.34","quantity":"0.110"},{"price":"1735.56","quantity":"27.796"},{"price":"1735.59","quantity":"4.353"},{"price":"1735.62","quantity":"10.466"},{"price":"1735.63","quantity":"6.343"},{"price":"1735.65","quantity":"20.560"},{"price":"1735.66","quantity":"20.169"},{"price":"1735.67","quantity":"0.051"},{"price":"1735.71","quantity":"0.050"},{"price":"1735.73","quantity":"54.881"},{"price":"1735.75","quantity":"71.542"},{"price":"1735.76","quantity":"15.145"},{"price":"1735.77","quantity":"14.174"},{"price":"1735.78","quantity":"3.944"},{"price":"1735.82","quantity":"0.866"},{"price":"1735.87","quantity":"9.406"},{"price":"1735.88","quantity":"0.236"},{"price":"1735.89","quantity":"9.703"},{"price":"1735.90","quantity":"5.576"},{"price":"1735.92","quantity":"18.813"},{"price":"1735.93","quantity":"0.858"},{"price":"1735.94","quantity":"5.006"},{"price":"1735.95","quantity":"0.074"},{"price":"1735.96","quantity":"0.552"},{"price":"1735.97","quantity":"5.111"},{"price":"1735.98","quantity":"23.220"},{"price":"1735.99","quantity":"0.230"},{"price":"1736.00","quantity":"2.489"},{"price":"1736.03","quantity":"1.134"},{"price":"1736.05","quantity":"0.051"},{"price":"1736.06","quantity":"0.014"},{"price":"1736.07","quantity":"0.035"},{"price":"1736.10","quantity":"3.755"},{"price":"1736.11","quantity":"145.507"}],"asks":[{"price":"1736.12","quantity":"265.351"},{"price":"1736.14","quantity":"0.028"},{"price":"1736.18","quantity":"0.053"},{"price":"1736.21","quantity":"0.044"},{"price":"1736.24","quantity":"0.660"},{"price":"1736.25","quantity":"3.977"},{"price":"1736.27","quantity":"0.026"},{"price":"1736.28","quantity":"41.260"},{"price":"1736.31","quantity":"22.895"},{"price":"1736.33","quantity":"1.735"},{"price":"1736.39","quantity":"0.098"},{"price":"1736.42","quantity":"36.496"},{"price":"1736.52","quantity":"5.845"},{"price":"1736.55","quantity":"31.365"},{"price":"1736.60","quantity":"5.055"},{"price":"1736.61","quantity":"11.082"},{"price":"1736.88","quantity":"3.633"},{"price":"1736.90","quantity":"57.445"},{"price":"1736.96","quantity":"3.499"},{"price":"1737.16","quantity":"11.330"},{"price":"1737.31","quantity":"9.427"},{"price":"1737.51","quantity":"2.858"},{"price":"1737.83","quantity":"33.086"},{"price":"1737.88","quantity":"34.874"},{"price":"1740.55","quantity":"6.242"},{"price":"1742.19","quantity":"3.099"},{"price":"1744.33","quantity":"2.075"},{"price":"1744.34","quantity":"10.023"},{"price":"1744.38","quantity":"2.137"},{"price":"1744.39","quantity":"0.000"},{"price":"1744.81","quantity":"0.154"},{"price":"1762.00","quantity":"153.236"},{"price":"1763.23","quantity":"15.531"},{"price":"2634.56","quantity":"0.001"},{"price":"2634.57","quantity":"0.001"},{"price":"2634.65","quantity":"0.000"},{"price":"2634.66","quantity":"0.000"}],"raw":{"e":"depthUpdate","E":1783517069320,"T":1783517069319,"s":"ETHUSDT","ps":"ETHUSDT","U":10999770817295,"u":10999770830523,"pu":10999770817136,"b":[["200.00","7.594"],["1211.11","0.677"],["1211.12","0.193"],["1226.11","2.848"],["1231.11","6.112"],["1231.12","0.000"],["1562.49","0.026"],["1562.50","4.162"],["1666.60","1.193"],["1701.38","43.641"],["1703.00","194.417"],["1706.60","57.976"],["1708.81","15.781"],["1708.97","9.593"],["1710.24","172.251"],["1718.74","57.612"],["1727.42","0.629"],["1727.89","10.013"],["1727.91","2.673"],["1727.94","0.176"],["1733.59","22.671"],["1733.60","68.107"],["1733.66","23.837"],["1733.68","18.785"],["1733.82","2.575"],["1733.89","0.765"],["1734.12","55.897"],["1734.18","0.012"],["1734.44","56.236"],["1734.47","4.441"],["1734.49","53.070"],["1734.57","29.409"],["1734.62","119.388"],["1734.64","0.556"],["1734.65","13.554"],["1734.66","1.206"],["1734.72","2.933"],["1734.98","290.505"],["1735.11","45.389"],["1735.13","3.178"],["1735.32","27.000"],["1735.33","16.529"],["1735.34","0.110"],["1735.56","27.796"],["1735.59","4.353"],["1735.62","10.466"],["1735.63","6.343"],["1735.65","20.560"],["1735.66","20.169"],["1735.67","0.051"],["1735.71","0.050"],["1735.73","54.881"],["1735.75","71.542"],["1735.76","15.145"],["1735.77","14.174"],["1735.78","3.944"],["1735.82","0.866"],["1735.87","9.406"],["1735.88","0.236"],["1735.89","9.703"],["1735.90","5.576"],["1735.92","18.813"],["1735.93","0.858"],["1735.94","5.006"],["1735.95","0.074"],["1735.96","0.552"],["1735.97","5.111"],["1735.98","23.220"],["1735.99","0.230"],["1736.00","2.489"],["1736.03","1.134"],["1736.05","0.051"],["1736.06","0.014"],["1736.07","0.035"],["1736.10","3.755"],["1736.11","145.507"]],"a":[["1736.12","265.351"],["1736.14","0.028"],["1736.18","0.053"],["1736.21","0.044"],["1736.24","0.660"],["1736.25","3.977"],["1736.27","0.026"],["1736.28","41.260"],["1736.31","22.895"],["1736.33","1.735"],["1736.39","0.098"],["1736.42","36.496"],["1736.52","5.845"],["1736.55","31.365"],["1736.60","5.055"],["1736.61","11.082"],["1736.88","3.633"],["1736.90","57.445"],["1736.96","3.499"],["1737.16","11.330"],["1737.31","9.427"],["1737.51","2.858"],["1737.83","33.086"],["1737.88","34.874"],["1740.55","6.242"],["1742.19","3.099"],["1744.33","2.075"],["1744.34","10.023"],["1744.38","2.137"],["1744.39","0.000"],["1744.81","0.154"],["1762.00","153.236"],["1763.23","15.531"],["2634.56","0.001"],["2634.57","0.001"],["2634.65","0.000"],["2634.66","0.000"]],"st":1}}
{"schema_version":"1.3.0","event_id":"e108ad81-3445-44a3-9c9e-3277c52b0665","event_type":"raw.trade","source":"binance_market_data_recorder","venue":"binance_usdm","market_type":"perpetual_futures","symbol":"BTCUSDT","event_time_ms":1783517069325,"received_time_ms":1783517069323,"trace_id":"d707cbab-a783-416b-a630-d85300b2d11b","trade_id":7881418071,"price":"61853.80","quantity":"0.264","trade_time_ms":1783517069324,"is_buyer_maker":false,"aggressor_side":"buy","raw":{"e":"trade","E":1783517069325,"T":1783517069324,"s":"BTCUSDT","t":7881418071,"p":"61853.80","q":"0.264","X":"MARKET","m":false,"st":1}}
{"schema_version":"1.3.0","event_id":"01173c1d-27dd-4c9c-8bd6-2c537b248736","event_type":"raw.depth_update","source":"binance_market_data_recorder","venue":"binance_usdm","market_type":"perpetual_futures","symbol":"BTCUSDT","event_time_ms":1783517069352,"received_time_ms":1783517069347,"trace_id":"c052d45e-ba6a-4430-b5fa-7bfd99966e30","first_update_id":10999770821275,"final_update_id":10999770834247,"previous_final_update_id":10999770821184,"bids":[{"price":"1000.00","quantity":"207.692"},{"price":"11353.70","quantity":"1.258"},{"price":"11653.70","quantity":"2.544"},{"price":"11753.70","quantity":"1.098"},{"price":"49483.00","quantity":"0.000"},{"price":"55668.30","quantity":"0.002"},{"price":"58759.60","quantity":"0.008"},{"price":"58761.00","quantity":"0.012"},{"price":"59379.50","quantity":"0.001"},{"price":"59806.00","quantity":"0.016"},{"price":"60888.00","quantity":"34.115"},{"price":"61018.70","quantity":"0.490"},{"price":"61235.20","quantity":"0.025"},{"price":"61297.00","quantity":"2.764"},{"price":"61537.60","quantity":"0.348"},{"price":"61544.40","quantity":"0.013"},{"price":"61585.40","quantity":"0.000"},{"price":"61585.50","quantity":"0.008"},{"price":"61723.00","quantity":"0.709"},{"price":"61723.20","quantity":"0.513"},{"price":"61735.90","quantity":"0.000"},{"price":"61794.30","quantity":"0.067"},{"price":"61796.40","quantity":"0.007"},{"price":"61808.10","quantity":"0.000"},{"price":"61808.30","quantity":"1.216"},{"price":"61821.20","quantity":"0.161"},{"price":"61822.00","quantity":"0.001"},{"price":"61835.40","quantity":"0.003"},{"price":"61836.60","quantity":"2.227"},{"price":"61838.20","quantity":"0.481"},{"price":"61838.60","quantity":"0.096"},{"price":"61840.70","quantity":"0.001"},{"price":"61840.80","quantity":"0.011"},{"price":"61841.00","quantity":"0.812"},{"price":"61841.80","quantity":"0.005"},{"price":"61841.90","quantity":"0.484"},{"price":"61842.00","quantity":"0.046"},{"price":"61842.10","quantity":"0.061"},{"price":"61842.30","quantity":"0.000"},{"price":"61842.50","quantity":"0.107"},{"price":"61842.60","quantity":"0.198"},{"price":"61844.00","quantity":"0.033"},{"price":"61844.80","quantity":"2.152"},{"price":"61844.90","quantity":"0.922"},{"price":"61848.40","quantity":"0.002"},{"price":"61850.00","quantity":"1.019"},{"price":"61850.30","quantity":"0.051"},{"price":"61850.50","quantity":"0.006"},{"price":"61852.30","quantity":"0.269"},{"price":"61853.40","quantity":"0.004"},{"price":"61853.50","quantity":"0.001"},{"price":"61853.60","quantity":"0.005"},{"price":"61853.70","quantity":"2.580"}],"asks":[{"price":"61853.80","quantity":"6.908"},{"price":"61854.30","quantity":"2.810"},{"price":"61854.40","quantity":"0.003"},{"price":"61854.90","quantity":"0.016"},{"price":"61855.10","quantity":"0.061"},{"price":"61856.50","quantity":"0.049"},{"price":"61856.60","quantity":"0.235"},{"price":"61856.80","quantity":"0.005"},{"price":"61856.90","quantity":"0.002"},{"price":"61857.20","quantity":"0.000"},{"price":"61857.50","quantity":"0.003"},{"price":"61859.50","quantity":"0.924"},{"price":"61862.90","quantity":"0.002"},{"price":"61883.20","quantity":"0.005"},{"price":"61883.30","quantity":"0.000"},{"price":"61883.70","quantity":"0.164"},{"price":"61893.10","quantity":"0.374"},{"price":"61893.30","quantity":"0.100"},{"price":"61904.40","quantity":"0.027"},{"price":"61910.70","quantity":"0.228"},{"price":"61957.20","quantity":"8.401"},{"price":"61958.10","quantity":"0.000"},{"price":"61985.60","quantity":"0.808"},{"price":"61985.80","quantity":"0.008"},{"price":"62062.00","quantity":"3.032"},{"price":"62472.30","quantity":"0.000"},{"price":"89523.20","quantity":"0.798"}],"raw":{"e":"depthUpdate","E":1783517069352,"T":1783517069350,"s":"BTCUSDT","ps":"BTCUSDT","U":10999770821275,"u":10999770834247,"pu":10999770821184,"b":[["1000.00","207.692"],["11353.70","1.258"],["11653.70","2.544"],["11753.70","1.098"],["49483.00","0.000"],["55668.30","0.002"],["58759.60","0.008"],["58761.00","0.012"],["59379.50","0.001"],["59806.00","0.016"],["60888.00","34.115"],["61018.70","0.490"],["61235.20","0.025"],["61297.00","2.764"],["61537.60","0.348"],["61544.40","0.013"],["61585.40","0.000"],["61585.50","0.008"],["61723.00","0.709"],["61723.20","0.513"],["61735.90","0.000"],["61794.30","0.067"],["61796.40","0.007"],["61808.10","0.000"],["61808.30","1.216"],["61821.20","0.161"],["61822.00","0.001"],["61835.40","0.003"],["61836.60","2.227"],["61838.20","0.481"],["61838.60","0.096"],["61840.70","0.001"],["61840.80","0.011"],["61841.00","0.812"],["61841.80","0.005"],["61841.90","0.484"],["61842.00","0.046"],["61842.10","0.061"],["61842.30","0.000"],["61842.50","0.107"],["61842.60","0.198"],["61844.00","0.033"],["61844.80","2.152"],["61844.90","0.922"],["61848.40","0.002"],["61850.00","1.019"],["61850.30","0.051"],["61850.50","0.006"],["61852.30","0.269"],["61853.40","0.004"],["61853.50","0.001"],["61853.60","0.005"],["61853.70","2.580"]],"a":[["61853.80","6.908"],["61854.30","2.810"],["61854.40","0.003"],["61854.90","0.016"],["61855.10","0.061"],["61856.50","0.049"],["61856.60","0.235"],["61856.80","0.005"],["61856.90","0.002"],["61857.20","0.000"],["61857.50","0.003"],["61859.50","0.924"],["61862.90","0.002"],["61883.20","0.005"],["61883.30","0.000"],["61883.70","0.164"],["61893.10","0.374"],["61893.30","0.100"],["61904.40","0.027"],["61910.70","0.228"],["61957.20","8.401"],["61958.10","0.000"],["61985.60","0.808"],["61985.80","0.008"],["62062.00","3.032"],["62472.30","0.000"],["89523.20","0.798"]],"st":1}}
{"schema_version":"1.3.0","event_id":"fa6015be-b082-4065-b9ae-16bc85404088","event_type":"raw.depth_update","source":"binance_market_data_recorder","venue":"binance_usdm","market_type":"perpetual_futures","symbol":"ETHUSDT","event_time_ms":1783517069422,"received_time_ms":1783517069419,"trace_id":"f48fb1ae-d5d6-4c25-9a5f-be8b0ac7a84d","first_update_id":10999770830681,"final_update_id":10999770844120,"previous_final_update_id":10999770830523,"bids":[{"price":"1211.11","quantity":"0.389"},{"price":"1226.11","quantity":"3.392"},{"price":"1231.11","quantity":"5.856"},{"price":"1562.49","quantity":"0.026"},{"price":"1562.50","quantity":"4.290"},{"price":"1666.60","quantity":"1.078"},{"price":"1693.95","quantity":"0.016"},{"price":"1701.38","quantity":"43.670"},{"price":"1727.42","quantity":"0.617"},{"price":"1730.01","quantity":"4.410"},{"price":"1731.00","quantity":"77.120"},{"price":"1731.25","quantity":"6.640"},{"price":"1732.39","quantity":"9.271"},{"price":"1732.47","quantity":"22.682"},{"price":"1732.70","quantity":"7.567"},{"price":"1732.72","quantity":"21.088"},{"price":"1733.64","quantity":"423.270"},{"price":"1733.68","quantity":"17.339"},{"price":"1734.06","quantity":"54.181"},{"price":"1734.21","quantity":"18.126"},{"price":"1734.61","quantity":"0.834"},{"price":"1734.98","quantity":"69.923"},{"price":"1735.00","quantity":"217.462"},{"price":"1735.06","quantity":"2.219"},{"price":"1735.09","quantity":"2.035"},{"price":"1735.17","quantity":"1.084"},{"price":"1735.20","quantity":"46.708"},{"price":"1735.23","quantity":"4.905"},{"price":"1735.24","quantity":"7.546"},{"price":"1735.29","quantity":"250.268"},{"price":"1735.30","quantity":"29.159"},{"price":"1735.31","quantity":"33.978"},{"price":"1735.37","quantity":"0.595"},{"price":"1735.38","quantity":"67.276"},{"price":"1735.39","quantity":"39.498"},{"price":"1735.46","quantity":"19.608"},{"price":"1735.47","quantity":"15.996"},{"price":"1735.51","quantity":"52.524"},{"price":"1735.53","quantity":"5.781"},{"price":"1735.59","quantity":"7.353"},{"price":"1735.67","quantity":"0.063"},{"price":"1735.70","quantity":"5.798"},{"price":"1735.71","quantity":"0.038"},{"price":"1735.74","quantity":"29.406"},{"price":"1735.75","quantity":"72.244"},{"price":"1735.76","quantity":"14.584"},{"price":"1735.77","quantity":"14.192"},{"price":"1735.78","quantity":"3.944"},{"price":"1735.79","quantity":"5.316"},{"price":"1735.80","quantity":"2.112"},{"price":"1735.81","quantity":"7.056"},{"price":"1735.84","quantity":"0.058"},{"price":"1735.86","quantity":"72.946"},{"price":"1735.87","quantity":"0.739"},{"price":"1735.90","quantity":"6.576"},{"price":"1735.91","quantity":"11.973"},{"price":"1735.92","quantity":"25.386"},{"price":"1735.93","quantity":"9.440"},{"price":"1735.97","quantity":"4.823"},{"price":"1735.98","quantity":"1.036"},{"price":"1735.99","quantity":"0.139"},{"price":"1736.00","quantity":"2.489"},{"price":"1736.02","quantity":"1.789"},{"price":"1736.05","quantity":"0.154"},{"price":"1736.06","quantity":"0.026"},{"price":"1736.07","quantity":"0.047"},{"price":"1736.09","quantity":"1.518"},{"price":"1736.11","quantity":"167.906"}],"asks":[{"price":"1736.12","quantity":"86.317"},{"price":"1736.13","quantity":"8.944"},{"price":"1736.19","quantity":"0.101"},{"price":"1736.20","quantity":"2.820"},{"price":"1736.21","quantity":"0.024"},{"price":"1736.22","quantity":"10.192"},{"price":"1736.28","quantity":"14.775"},{"price":"1736.29","quantity":"1.210"},{"price":"1736.30","quantity":"9.174"},{"price":"1736.32","quantity":"8.783"},{"price":"1736.33","quantity":"2.023"},{"price":"1736.34","quantity":"0.559"},{"price":"1736.40","quantity":"21.369"},{"price":"1736.42","quantity":"8.379"},{"price":"1736.46","quantity":"42.462"},{"price":"1736.47","quantity":"2.139"},{"price":"1736.49","quantity":"2.851"},{"price":"1736.50","quantity":"28.936"},{"price":"1736.57","quantity":"2.094"},{"price":"1736.64","quantity":"76.129"},{"price":"1736.75","quantity":"67.315"},{"price":"1736.77","quantity":"0.161"},{"price":"1736.80","quantity":"43.120"},{"price":"1736.83","quantity":"49.173"},{"price":"1736.87","quantity":"26.251"},{"price":"1736.90","quantity":"40.769"},{"price":"1736.92","quantity":"67.349"},{"price":"1736.98","quantity":"13.096"},{"price":"1737.00","quantity":"83.091"},{"price":"1737.12","quantity":"7.826"},{"price":"1737.23","quantity":"35.967"},{"price":"1737.42","quantity":"3.675"},{"price":"1737.60","quantity":"7.231"},{"price":"1737.68","quantity":"3.610"},{"price":"1737.89","quantity":"7.279"},{"price":"1737.94","quantity":"0.012"},{"price":"1738.03","quantity":"1.667"},{"price":"1738.07","quantity":"440.529"},{"price":"1738.12","quantity":"21.007"},{"price":"1738.13","quantity":"19.864"},{"price":"1738.14","quantity":"16.295"},{"price":"1738.80","quantity":"1.464"},{"price":"1738.88","quantity":"1.079"},{"price":"1738.94","quantity":"7.156"},{"price":"1738.96","quantity":"3.196"},{"price":"1738.98","quantity":"43.748"},{"price":"1739.42","quantity":"20.408"},{"price":"1740.58","quantity":"18.016"},{"price":"1742.47","quantity":"17.246"},{"price":"1744.81","quantity":"0.166"},{"price":"1747.12","quantity":"15.000"},{"price":"1763.03","quantity":"22.927"},{"price":"2634.54","quantity":"0.001"},{"price":"2634.55","quantity":"0.001"},{"price":"2634.63","quantity":"0.009"},{"price":"2634.64","quantity":"0.000"}],"raw":{"e":"depthUpdate","E":1783517069422,"T":1783517069421,"s":"ETHUSDT","ps":"ETHUSDT","U":10999770830681,"u":10999770844120,"pu":10999770830523,"b":[["1211.11","0.389"],["1226.11","3.392"],["1231.11","5.856"],["1562.49","0.026"],["1562.50","4.290"],["1666.60","1.078"],["1693.95","0.016"],["1701.38","43.670"],["1727.42","0.617"],["1730.01","4.410"],["1731.00","77.120"],["1731.25","6.640"],["1732.39","9.271"],["1732.47","22.682"],["1732.70","7.567"],["1732.72","21.088"],["1733.64","423.270"],["1733.68","17.339"],["1734.06","54.181"],["1734.21","18.126"],["1734.61","0.834"],["1734.98","69.923"],["1735.00","217.462"],["1735.06","2.219"],["1735.09","2.035"],["1735.17","1.084"],["1735.20","46.708"],["1735.23","4.905"],["1735.24","7.546"],["1735.29","250.268"],["1735.30","29.159"],["1735.31","33.978"],["1735.37","0.595"],["1735.38","67.276"],["1735.39","39.498"],["1735.46","19.608"],["1735.47","15.996"],["1735.51","52.524"],["1735.53","5.781"],["1735.59","7.353"],["1735.67","0.063"],["1735.70","5.798"],["1735.71","0.038"],["1735.74","29.406"],["1735.75","72.244"],["1735.76","14.584"],["1735.77","14.192"],["1735.78","3.944"],["1735.79","5.316"],["1735.80","2.112"],["1735.81","7.056"],["1735.84","0.058"],["1735.86","72.946"],["1735.87","0.739"],["1735.90","6.576"],["1735.91","11.973"],["1735.92","25.386"],["1735.93","9.440"],["1735.97","4.823"],["1735.98","1.036"],["1735.99","0.139"],["1736.00","2.489"],["1736.02","1.789"],["1736.05","0.154"],["1736.06","0.026"],["1736.07","0.047"],["1736.09","1.518"],["1736.11","167.906"]],"a":[["1736.12","86.317"],["1736.13","8.944"],["1736.19","0.101"],["1736.20","2.820"],["1736.21","0.024"],["1736.22","10.192"],["1736.28","14.775"],["1736.29","1.210"],["1736.30","9.174"],["1736.32","8.783"],["1736.33","2.023"],["1736.34","0.559"],["1736.40","21.369"],["1736.42","8.379"],["1736.46","42.462"],["1736.47","2.139"],["1736.49","2.851"],["1736.50","28.936"],["1736.57","2.094"],["1736.64","76.129"],["1736.75","67.315"],["1736.77","0.161"],["1736.80","43.120"],["1736.83","49.173"],["1736.87","26.251"],["1736.90","40.769"],["1736.92","67.349"],["1736.98","13.096"],["1737.00","83.091"],["1737.12","7.826"],["1737.23","35.967"],["1737.42","3.675"],["1737.60","7.231"],["1737.68","3.610"],["1737.89","7.279"],["1737.94","0.012"],["1738.03","1.667"],["1738.07","440.529"],["1738.12","21.007"],["1738.13","19.864"],["1738.14","16.295"],["1738.80","1.464"],["1738.88","1.079"],["1738.94","7.156"],["1738.96","3.196"],["1738.98","43.748"],["1739.42","20.408"],["1740.58","18.016"],["1742.47","17.246"],["1744.81","0.166"],["1747.12","15.000"],["1763.03","22.927"],["2634.54","0.001"],["2634.55","0.001"],["2634.63","0.009"],["2634.64","0.000"]],"st":1}}
{"schema_version":"1.3.0","event_id":"bb59e607-3cbb-4fa4-a830-3c7ce47ab243","event_type":"raw.trade","source":"binance_market_data_recorder","venue":"binance_usdm","market_type":"perpetual_futures","symbol":"BTCUSDT","event_time_ms":1783517069438,"received_time_ms":1783517069440,"trace_id":"01d5f5ad-ae29-4e09-8fe2-f79bcf6f5409","trade_id":7881418072,"price":"61853.70","quantity":"0.182","trade_time_ms":1783517069437,"is_buyer_maker":true,"aggressor_side":"sell","raw":{"e":"trade","E":1783517069438,"T":1783517069437,"s":"BTCUSDT","t":7881418072,"p":"61853.70","q":"0.182","X":"MARKET","m":true,"st":1}}
{"schema_version":"1.3.0","event_id":"a6b0157b-d2d8-4950-82bb-02a22804639e","event_type":"raw.trade","source":"binance_market_data_recorder","venue":"binance_usdm","market_type":"perpetual_futures","symbol":"BTCUSDT","event_time_ms":1783517069438,"received_time_ms":1783517069440,"trace_id":"f43923a6-da2d-4f63-a6a9-30f32871fad6","trade_id":7881418073,"price":"61853.70","quantity":"0.001","trade_time_ms":1783517069437,"is_buyer_maker":true,"aggressor_side":"sell","raw":{"e":"trade","E":1783517069438,"T":1783517069437,"s":"BTCUSDT","t":7881418073,"p":"61853.70","q":"0.001","X":"MARKET","m":true,"st":1}}
{"schema_version":"1.3.0","event_id":"b1ce1b86-c544-4d5b-b825-c279bdc4eea8","event_type":"raw.trade","source":"binance_market_data_recorder","venue":"binance_usdm","market_type":"perpetual_futures","symbol":"BTCUSDT","event_time_ms":1783517069438,"received_time_ms":1783517069441,"trace_id":"68dac18d-3d61-49c3-b5e4-079d07e78046","trade_id":7881418074,"price":"61853.70","quantity":"0.194","trade_time_ms":1783517069437,"is_buyer_maker":true,"aggressor_side":"sell","raw":{"e":"trade","E":1783517069438,"T":1783517069437,"s":"BTCUSDT","t":7881418074,"p":"61853.70","q":"0.194","X":"MARKET","m":true,"st":1}}
{"schema_version":"1.3.0","event_id":"8e77b403-d98c-4d7b-9e04-17d118bf64a4","event_type":"raw.trade","source":"binance_market_data_recorder","venue":"binance_usdm","market_type":"perpetual_futures","symbol":"BTCUSDT","event_time_ms":1783517069438,"received_time_ms":1783517069441,"trace_id":"5bfe6c09-76d5-4a9b-bad4-13fd5764d37a","trade_id":7881418075,"price":"61853.70","quantity":"0.001","trade_time_ms":1783517069437,"is_buyer_maker":true,"aggressor_side":"sell","raw":{"e":"trade","E":1783517069438,"T":1783517069437,"s":"BTCUSDT","t":7881418075,"p":"61853.70","q":"0.001","X":"MARKET","m":true,"st":1}}
{"schema_version":"1.3.0","event_id":"7800ecca-c193-4e04-802e-c65f45f2e49c","event_type":"raw.trade","source":"binance_market_data_recorder","venue":"binance_usdm","market_type":"perpetual_futures","symbol":"BTCUSDT","event_time_ms":1783517069438,"received_time_ms":1783517069441,"trace_id":"983bd1cf-925d-435d-a968-b400c6ea600b","trade_id":7881418076,"price":"61853.70","quantity":"0.001","trade_time_ms":1783517069437,"is_buyer_maker":true,"aggressor_side":"sell","raw":{"e":"trade","E":1783517069438,"T":1783517069437,"s":"BTCUSDT","t":7881418076,"p":"61853.70","q":"0.001","X":"MARKET","m":true,"st":1}}
{"schema_version":"1.3.0","event_id":"886804bf-e4e4-4404-b521-8ad141f7148b","event_type":"raw.trade","source":"binance_market_data_recorder","venue":"binance_usdm","market_type":"perpetual_futures","symbol":"BTCUSDT","event_time_ms":1783517069438,"received_time_ms":1783517069442,"trace_id":"39f66b7d-a64f-4e1c-8c78-c83671112514","trade_id":7881418077,"price":"61853.70","quantity":"0.011","trade_time_ms":1783517069437,"is_buyer_maker":true,"aggressor_side":"sell","raw":{"e":"trade","E":1783517069438,"T":1783517069437,"s":"BTCUSDT","t":7881418077,"p":"61853.70","q":"0.011","X":"MARKET","m":true,"st":1}}
{"schema_version":"1.3.0","event_id":"0b88c6d3-6c45-43e3-964d-8b2ccdd55ed3","event_type":"raw.trade","source":"binance_market_data_recorder","venue":"binance_usdm","market_type":"perpetual_futures","symbol":"BTCUSDT","event_time_ms":1783517069438,"received_time_ms":1783517069442,"trace_id":"e3e4d305-1aaa-414d-88a9-51171c044cd8","trade_id":7881418078,"price":"61853.70","quantity":"0.017","trade_time_ms":1783517069437,"is_buyer_maker":true,"aggressor_side":"sell","raw":{"e":"trade","E":1783517069438,"T":1783517069437,"s":"BTCUSDT","t":7881418078,"p":"61853.70","q":"0.017","X":"MARKET","m":true,"st":1}}
{"schema_version":"1.3.0","event_id":"57baf2ff-0f88-4d9f-8bf2-49c70d8d8102","event_type":"raw.trade","source":"binance_market_data_recorder","venue":"binance_usdm","market_type":"perpetual_futures","symbol":"BTCUSDT","event_time_ms":1783517069438,"received_time_ms":1783517069443,"trace_id":"6ce6ea56-c452-4fa3-a22d-20c62b142b5e","trade_id":7881418079,"price":"61853.70","quantity":"0.012","trade_time_ms":1783517069437,"is_buyer_maker":true,"aggressor_side":"sell","raw":{"e":"trade","E":1783517069438,"T":1783517069437,"s":"BTCUSDT","t":7881418079,"p":"61853.70","q":"0.012","X":"MARKET","m":true,"st":1}}
{"schema_version":"1.3.0","event_id":"1e1c7338-2c5c-4f32-87a4-383d865f8e13","event_type":"raw.trade","source":"binance_market_data_recorder","venue":"binance_usdm","market_type":"perpetual_futures","symbol":"BTCUSDT","event_time_ms":1783517069438,"received_time_ms":1783517069443,"trace_id":"a1727889-4de9-4ce2-b4cc-b9d32861eb27","trade_id":7881418080,"price":"61853.70","quantity":"0.001","trade_time_ms":1783517069437,"is_buyer_maker":true,"aggressor_side":"sell","raw":{"e":"trade","E":1783517069438,"T":1783517069437,"s":"BTCUSDT","t":7881418080,"p":"61853.70","q":"0.001","X":"MARKET","m":true,"st":1}}
{"schema_version":"1.3.0","event_id":"0d5692ee-39bb-4287-b7b5-ea3e5bbf40eb","event_type":"raw.trade","source":"binance_market_data_recorder","venue":"binance_usdm","market_type":"perpetual_futures","symbol":"BTCUSDT","event_time_ms":1783517069438,"received_time_ms":1783517069444,"trace_id":"ee4e0295-43c9-4881-bd29-19d39fcd15a9","trade_id":7881418081,"price":"61853.70","quantity":"0.003","trade_time_ms":1783517069437,"is_buyer_maker":true,"aggressor_side":"sell","raw":{"e":"trade","E":1783517069438,"T":1783517069437,"s":"BTCUSDT","t":7881418081,"p":"61853.70","q":"0.003","X":"MARKET","m":true,"st":1}}
{"schema_version":"1.3.0","event_id":"9827eb56-877a-44e6-b7be-6ec190d59f77","event_type":"raw.trade","source":"binance_market_data_recorder","venue":"binance_usdm","market_type":"perpetual_futures","symbol":"BTCUSDT","event_time_ms":1783517069438,"received_time_ms":1783517069445,"trace_id":"3c7fa240-dcde-4041-a360-c149e544dbe5","trade_id":7881418082,"price":"61853.70","quantity":"0.056","trade_time_ms":1783517069437,"is_buyer_maker":true,"aggressor_side":"sell","raw":{"e":"trade","E":1783517069438,"T":1783517069437,"s":"BTCUSDT","t":7881418082,"p":"61853.70","q":"0.056","X":"MARKET","m":true,"st":1}}
{"schema_version":"1.3.0","event_id":"e8f40197-19f4-401b-8d19-91e4121744ed","event_type":"raw.depth_update","source":"binance_market_data_recorder","venue":"binance_usdm","market_type":"perpetual_futures","symbol":"BTCUSDT","event_time_ms":1783517069454,"received_time_ms":1783517069453,"trace_id":"f4d81f55-4406-4dc8-b3f8-b087f93f53a5","first_update_id":10999770834593,"final_update_id":10999770850269,"previous_final_update_id":10999770834247,"bids":[{"price":"1000.00","quantity":"207.692"},{"price":"11353.70","quantity":"1.105"},{"price":"11553.70","quantity":"0.048"},{"price":"11653.70","quantity":"2.720"},{"price":"11753.70","quantity":"1.027"},{"price":"55668.30","quantity":"0.002"},{"price":"58761.00","quantity":"0.012"},{"price":"59379.50","quantity":"0.004"},{"price":"60616.70","quantity":"0.035"},{"price":"60896.30","quantity":"0.483"},{"price":"60962.70","quantity":"0.000"},{"price":"61235.20","quantity":"0.025"},{"price":"61259.40","quantity":"0.011"},{"price":"61342.70","quantity":"0.000"},{"price":"61358.90","quantity":"1.225"},{"price":"61541.30","quantity":"0.000"},{"price":"61606.30","quantity":"0.499"},{"price":"61607.30","quantity":"0.158"},{"price":"61608.80","quantity":"0.000"},{"price":"61624.90","quantity":"0.165"},{"price":"61771.60","quantity":"33.563"},{"price":"61786.30","quantity":"0.002"},{"price":"61798.00","quantity":"0.015"},{"price":"61800.20","quantity":"0.331"},{"price":"61806.00","quantity":"0.046"},{"price":"61806.20","quantity":"0.179"},{"price":"61806.30","quantity":"0.018"},{"price":"61808.10","quantity":"0.000"},{"price":"61808.30","quantity":"1.115"},{"price":"61810.30","quantity":"1.606"},{"price":"61811.10","quantity":"0.016"},{"price":"61811.50","quantity":"0.115"},{"price":"61812.60","quantity":"0.000"},{"price":"61814.10","quantity":"0.571"},{"price":"61814.30","quantity":"0.230"},{"price":"61817.40","quantity":"0.004"},{"price":"61820.20","quantity":"0.254"},{"price":"61820.30","quantity":"0.467"},{"price":"61820.50","quantity":"0.340"},{"price":"61821.00","quantity":"1.009"},{"price":"61821.10","quantity":"0.367"},{"price":"61821.20","quantity":"0.101"},{"price":"61822.30","quantity":"0.091"},{"price":"61822.70","quantity":"0.105"},{"price":"61822.90","quantity":"0.092"},{"price":"61823.80","quantity":"0.001"},{"price":"61824.50","quantity":"0.332"},{"price":"61824.60","quantity":"0.005"},{"price":"61824.80","quantity":"0.001"},{"price":"61825.30","quantity":"0.017"},{"price":"61825.80","quantity":"0.008"},{"price":"61826.10","quantity":"1.091"},{"price":"61826.60","quantity":"0.695"},{"price":"61827.40","quantity":"0.564"},{"price":"61827.80","quantity":"0.286"},{"price":"61828.10","quantity":"0.001"},{"price":"61829.00","quantity":"0.610"},{"price":"61829.10","quantity":"0.339"},{"price":"61829.70","quantity":"0.006"},{"price":"61829.80","quantity":"0.004"},{"price":"61829.90","quantity":"0.002"},{"price":"61831.00","quantity":"0.000"},{"price":"61832.10","quantity":"1.033"},{"price":"61832.40","quantity":"0.007"},{"price":"61833.20","quantity":"0.885"},{"price":"61834.40","quantity":"0.179"},{"price":"61835.10","quantity":"1.714"},{"price":"61835.20","quantity":"0.568"},{"price":"61835.30","quantity":"0.355"},{"price":"61835.70","quantity":"0.013"},{"price":"61835.90","quantity":"1.054"},{"price":"61836.00","quantity":"0.064"},{"price":"61836.60","quantity":"1.227"},{"price":"61836.70","quantity":"0.003"},{"price":"61837.10","quantity":"0.002"},{"price":"61837.30","quantity":"0.885"},{"price":"61837.50","quantity":"3.197"},{"price":"61838.00","quantity":"0.566"},{"price":"61838.30","quantity":"0.062"},{"price":"61838.80","quantity":"0.010"},{"price":"61839.50","quantity":"0.124"},{"price":"61840.00","quantity":"0.432"},{"price":"61841.00","quantity":"0.003"},{"price":"61841.30","quantity":"0.573"},{"price":"61841.50","quantity":"0.221"},{"price":"61841.80","quantity":"0.441"},{"price":"61841.90","quantity":"0.383"},{"price":"61842.10","quantity":"0.001"},{"price":"61842.30","quantity":"0.002"},{"price":"61842.40","quantity":"0.293"},{"price":"61842.50","quantity":"0.006"},{"price":"61842.60","quantity":"0.081"},{"price":"61843.10","quantity":"0.002"},{"price":"61843.30","quantity":"0.015"},{"price":"61844.00","quantity":"0.032"},{"price":"61844.10","quantity":"0.000"},{"price":"61844.20","quantity":"1.290"},{"price":"61844.50","quantity":"0.003"},{"price":"61844.90","quantity":"1.119"},{"price":"61845.00","quantity":"0.009"},{"price":"61845.10","quantity":"0.284"},{"price":"61846.20","quantity":"1.305"},{"price":"61846.30","quantity":"0.324"},{"price":"61847.20","quantity":"0.000"},{"price":"61847.60","quantity":"0.006"},{"price":"61847.80","quantity":"0.002"},{"price":"61847.90","quantity":"2.139"},{"price":"61848.00","quantity":"1.138"},{"price":"61848.20","quantity":"0.001"},{"price":"61848.90","quantity":"0.003"},{"price":"61849.30","quantity":"0.248"},{"price":"61849.60","quantity":"0.072"},{"price":"61850.00","quantity":"1.018"},{"price":"61850.20","quantity":"0.124"},{"price":"61850.50","quantity":"0.000"},{"price":"61850.60","quantity":"0.287"},{"price":"61851.20","quantity":"1.527"},{"price":"61851.50","quantity":"0.000"},{"price":"61852.10","quantity":"0.004"},{"price":"61852.30","quantity":"1.209"},{"price":"61852.40","quantity":"1.575"},{"price":"61852.70","quantity":"0.000"},{"price":"61853.40","quantity":"0.004"},{"price":"61853.50","quantity":"0.006"},{"price":"61853.60","quantity":"0.002"},{"price":"61853.70","quantity":"6.391"}],"asks":[{"price":"61853.80","quantity":"2.272"},{"price":"61853.90","quantity":"0.005"},{"price":"61854.00","quantity":"0.001"},{"price":"61854.20","quantity":"0.022"},{"price":"61854.30","quantity":"0.023"},{"price":"61854.40","quantity":"0.127"},{"price":"61855.00","quantity":"1.951"},{"price":"61855.10","quantity":"0.002"},{"price":"61855.30","quantity":"0.002"},{"price":"61855.80","quantity":"0.005"},{"price":"61856.00","quantity":"0.026"},{"price":"61856.10","quantity":"0.005"},{"price":"61856.30","quantity":"0.079"},{"price":"61856.40","quantity":"0.271"},{"price":"61856.50","quantity":"0.000"},{"price":"61856.60","quantity":"0.235"},{"price":"61856.80","quantity":"0.001"},{"price":"61857.00","quantity":"0.714"},{"price":"61857.10","quantity":"0.002"},{"price":"61857.30","quantity":"0.000"},{"price":"61857.40","quantity":"1.005"},{"price":"61857.50","quantity":"0.001"},{"price":"61857.80","quantity":"0.001"},{"price":"61858.90","quantity":"0.053"},{"price":"61859.00","quantity":"0.104"},{"price":"61859.10","quantity":"0.000"},{"price":"61859.20","quantity":"0.501"},{"price":"61859.30","quantity":"0.367"},{"price":"61859.40","quantity":"1.618"},{"price":"61859.50","quantity":"0.019"},{"price":"61859.60","quantity":"0.166"},{"price":"61859.70","quantity":"0.001"},{"price":"61859.80","quantity":"0.187"},{"price":"61859.90","quantity":"0.568"},{"price":"61860.10","quantity":"0.005"},{"price":"61860.20","quantity":"0.347"},{"price":"61860.60","quantity":"0.108"},{"price":"61860.80","quantity":"0.027"},{"price":"61861.00","quantity":"0.408"},{"price":"61861.10","quantity":"0.372"},{"price":"61861.20","quantity":"0.004"},{"price":"61861.40","quantity":"0.165"},{"price":"61862.10","quantity":"0.003"},{"price":"61862.30","quantity":"0.052"},{"price":"61862.40","quantity":"0.038"},{"price":"61862.60","quantity":"0.437"},{"price":"61862.70","quantity":"2.747"},{"price":"61862.90","quantity":"0.001"},{"price":"61863.00","quantity":"0.053"},{"price":"61863.10","quantity":"0.968"},{"price":"61863.40","quantity":"0.030"},{"price":"61863.50","quantity":"0.002"},{"price":"61863.60","quantity":"0.170"},{"price":"61863.80","quantity":"0.280"},{"price":"61864.10","quantity":"0.797"},{"price":"61864.60","quantity":"0.001"},{"price":"61864.70","quantity":"0.003"},{"price":"61865.50","quantity":"0.611"},{"price":"61865.60","quantity":"0.766"},{"price":"61867.60","quantity":"0.345"},{"price":"61868.00","quantity":"0.334"},{"price":"61868.70","quantity":"0.101"},{"price":"61869.50","quantity":"0.083"},{"price":"61869.70","quantity":"0.003"},{"price":"61869.90","quantity":"1.832"},{"price":"61870.00","quantity":"0.532"},{"price":"61871.10","quantity":"0.011"},{"price":"61872.00","quantity":"0.290"},{"price":"61872.80","quantity":"0.008"},{"price":"61873.20","quantity":"0.002"},{"price":"61873.70","quantity":"0.005"},{"price":"61873.80","quantity":"1.292"},{"price":"61874.70","quantity":"0.001"},{"price":"61876.10","quantity":"0.162"},{"price":"61877.30","quantity":"0.229"},{"price":"61877.80","quantity":"0.000"},{"price":"61878.00","quantity":"2.202"},{"price":"61878.20","quantity":"0.062"},{"price":"61878.50","quantity":"0.014"},{"price":"61878.80","quantity":"0.051"},{"price":"61879.70","quantity":"0.152"},{"price":"61880.80","quantity":"0.000"},{"price":"61880.90","quantity":"0.049"},{"price":"61881.30","quantity":"0.681"},{"price":"61881.80","quantity":"0.037"},{"price":"61882.30","quantity":"0.000"},{"price":"61883.00","quantity":"0.149"},{"price":"61883.50","quantity":"0.951"},{"price":"61886.70","quantity":"0.000"},{"price":"61886.80","quantity":"4.243"},{"price":"61887.70","quantity":"0.170"},{"price":"61888.50","quantity":"0.082"},{"price":"61889.20","quantity":"0.023"},{"price":"61890.20","quantity":"0.022"},{"price":"61892.20","quantity":"0.004"},{"price":"61892.50","quantity":"0.080"},{"price":"61893.20","quantity":"0.207"},{"price":"61893.80","quantity":"2.462"},{"price":"61894.00","quantity":"0.001"},{"price":"61894.10","quantity":"0.017"},{"price":"61895.60","quantity":"0.097"},{"price":"61896.60","quantity":"0.000"},{"price":"61897.10","quantity":"0.310"},{"price":"61897.20","quantity":"0.004"},{"price":"61897.40","quantity":"0.000"},{"price":"61897.60","quantity":"0.004"},{"price":"61898.50","quantity":"0.083"},{"price":"61899.10","quantity":"0.137"},{"price":"61904.50","quantity":"0.181"},{"price":"61904.60","quantity":"4.189"},{"price":"61904.80","quantity":"0.386"},{"price":"61905.40","quantity":"0.015"},{"price":"61905.60","quantity":"0.002"},{"price":"61906.10","quantity":"0.084"},{"price":"61906.30","quantity":"0.122"},{"price":"61909.00","quantity":"0.133"},{"price":"61909.20","quantity":"0.277"},{"price":"61909.40","quantity":"0.006"},{"price":"61909.50","quantity":"2.795"},{"price":"61909.90","quantity":"0.217"},{"price":"61910.70","quantity":"0.018"},{"price":"61911.50","quantity":"0.005"},{"price":"61911.70","quantity":"0.001"},{"price":"61913.50","quantity":"5.790"},{"price":"61916.30","quantity":"25.516"},{"price":"61916.40","quantity":"3.235"},{"price":"61917.00","quantity":"0.229"},{"price":"61918.40","quantity":"0.000"},{"price":"61950.50","quantity":"0.264"},{"price":"61952.80","quantity":"0.000"},{"price":"61953.70","quantity":"0.264"},{"price":"62472.30","quantity":"0.000"},{"price":"63089.30","quantity":"0.093"},{"price":"63090.80","quantity":"0.015"}],"raw":{"e":"depthUpdate","E":1783517069454,"T":1783517069453,"s":"BTCUSDT","ps":"BTCUSDT","U":10999770834593,"u":10999770850269,"pu":10999770834247,"b":[["1000.00","207.692"],["11353.70","1.105"],["11553.70","0.048"],["11653.70","2.720"],["11753.70","1.027"],["55668.30","0.002"],["58761.00","0.012"],["59379.50","0.004"],["60616.70","0.035"],["60896.30","0.483"],["60962.70","0.000"],["61235.20","0.025"],["61259.40","0.011"],["61342.70","0.000"],["61358.90","1.225"],["61541.30","0.000"],["61606.30","0.499"],["61607.30","0.158"],["61608.80","0.000"],["61624.90","0.165"],["61771.60","33.563"],["61786.30","0.002"],["61798.00","0.015"],["61800.20","0.331"],["61806.00","0.046"],["61806.20","0.179"],["61806.30","0.018"],["61808.10","0.000"],["61808.30","1.115"],["61810.30","1.606"],["61811.10","0.016"],["61811.50","0.115"],["61812.60","0.000"],["61814.10","0.571"],["61814.30","0.230"],["61817.40","0.004"],["61820.20","0.254"],["61820.30","0.467"],["61820.50","0.340"],["61821.00","1.009"],["61821.10","0.367"],["61821.20","0.101"],["61822.30","0.091"],["61822.70","0.105"],["61822.90","0.092"],["61823.80","0.001"],["61824.50","0.332"],["61824.60","0.005"],["61824.80","0.001"],["61825.30","0.017"],["61825.80","0.008"],["61826.10","1.091"],["61826.60","0.695"],["61827.40","0.564"],["61827.80","0.286"],["61828.10","0.001"],["61829.00","0.610"],["61829.10","0.339"],["61829.70","0.006"],["61829.80","0.004"],["61829.90","0.002"],["61831.00","0.000"],["61832.10","1.033"],["61832.40","0.007"],["61833.20","0.885"],["61834.40","0.179"],["61835.10","1.714"],["61835.20","0.568"],["61835.30","0.355"],["61835.70","0.013"],["61835.90","1.054"],["61836.00","0.064"],["61836.60","1.227"],["61836.70","0.003"],["61837.10","0.002"],["61837.30","0.885"],["61837.50","3.197"],["61838.00","0.566"],["61838.30","0.062"],["61838.80","0.010"],["61839.50","0.124"],["61840.00","0.432"],["61841.00","0.003"],["61841.30","0.573"],["61841.50","0.221"],["61841.80","0.441"],["61841.90","0.383"],["61842.10","0.001"],["61842.30","0.002"],["61842.40","0.293"],["61842.50","0.006"],["61842.60","0.081"],["61843.10","0.002"],["61843.30","0.015"],["61844.00","0.032"],["61844.10","0.000"],["61844.20","1.290"],["61844.50","0.003"],["61844.90","1.119"],["61845.00","0.009"],["61845.10","0.284"],["61846.20","1.305"],["61846.30","0.324"],["61847.20","0.000"],["61847.60","0.006"],["61847.80","0.002"],["61847.90","2.139"],["61848.00","1.138"],["61848.20","0.001"],["61848.90","0.003"],["61849.30","0.248"],["61849.60","0.072"],["61850.00","1.018"],["61850.20","0.124"],["61850.50","0.000"],["61850.60","0.287"],["61851.20","1.527"],["61851.50","0.000"],["61852.10","0.004"],["61852.30","1.209"],["61852.40","1.575"],["61852.70","0.000"],["61853.40","0.004"],["61853.50","0.006"],["61853.60","0.002"],["61853.70","6.391"]],"a":[["61853.80","2.272"],["61853.90","0.005"],["61854.00","0.001"],["61854.20","0.022"],["61854.30","0.023"],["61854.40","0.127"],["61855.00","1.951"],["61855.10","0.002"],["61855.30","0.002"],["61855.80","0.005"],["61856.00","0.026"],["61856.10","0.005"],["61856.30","0.079"],["61856.40","0.271"],["61856.50","0.000"],["61856.60","0.235"],["61856.80","0.001"],["61857.00","0.714"],["61857.10","0.002"],["61857.30","0.000"],["61857.40","1.005"],["61857.50","0.001"],["61857.80","0.001"],["61858.90","0.053"],["61859.00","0.104"],["61859.10","0.000"],["61859.20","0.501"],["61859.30","0.367"],["61859.40","1.618"],["61859.50","0.019"],["61859.60","0.166"],["61859.70","0.001"],["61859.80","0.187"],["61859.90","0.568"],["61860.10","0.005"],["61860.20","0.347"],["61860.60","0.108"],["61860.80","0.027"],["61861.00","0.408"],["61861.10","0.372"],["61861.20","0.004"],["61861.40","0.165"],["61862.10","0.003"],["61862.30","0.052"],["61862.40","0.038"],["61862.60","0.437"],["61862.70","2.747"],["61862.90","0.001"],["61863.00","0.053"],["61863.10","0.968"],["61863.40","0.030"],["61863.50","0.002"],["61863.60","0.170"],["61863.80","0.280"],["61864.10","0.797"],["61864.60","0.001"],["61864.70","0.003"],["61865.50","0.611"],["61865.60","0.766"],["61867.60","0.345"],["61868.00","0.334"],["61868.70","0.101"],["61869.50","0.083"],["61869.70","0.003"],["61869.90","1.832"],["61870.00","0.532"],["61871.10","0.011"],["61872.00","0.290"],["61872.80","0.008"],["61873.20","0.002"],["61873.70","0.005"],["61873.80","1.292"],["61874.70","0.001"],["61876.10","0.162"],["61877.30","0.229"],["61877.80","0.000"],["61878.00","2.202"],["61878.20","0.062"],["61878.50","0.014"],["61878.80","0.051"],["61879.70","0.152"],["61880.80","0.000"],["61880.90","0.049"],["61881.30","0.681"],["61881.80","0.037"],["61882.30","0.000"],["61883.00","0.149"],["61883.50","0.951"],["61886.70","0.000"],["61886.80","4.243"],["61887.70","0.170"],["61888.50","0.082"],["61889.20","0.023"],["61890.20","0.022"],["61892.20","0.004"],["61892.50","0.080"],["61893.20","0.207"],["61893.80","2.462"],["61894.00","0.001"],["61894.10","0.017"],["61895.60","0.097"],["61896.60","0.000"],["61897.10","0.310"],["61897.20","0.004"],["61897.40","0.000"],["61897.60","0.004"],["61898.50","0.083"],["61899.10","0.137"],["61904.50","0.181"],["61904.60","4.189"],["61904.80","0.386"],["61905.40","0.015"],["61905.60","0.002"],["61906.10","0.084"],["61906.30","0.122"],["61909.00","0.133"],["61909.20","0.277"],["61909.40","0.006"],["61909.50","2.795"],["61909.90","0.217"],["61910.70","0.018"],["61911.50","0.005"],["61911.70","0.001"],["61913.50","5.790"],["61916.30","25.516"],["61916.40","3.235"],["61917.00","0.229"],["61918.40","0.000"],["61950.50","0.264"],["61952.80","0.000"],["61953.70","0.264"],["62472.30","0.000"],["63089.30","0.093"],["63090.80","0.015"]],"st":1}}
{"schema_version":"1.3.0","event_id":"76cfbc08-1ef9-47a5-830e-9ecd219907dc","event_type":"raw.trade","source":"binance_market_data_recorder","venue":"binance_usdm","market_type":"perpetual_futures","symbol":"ETHUSDT","event_time_ms":1783517069478,"received_time_ms":1783517069473,"trace_id":"7a6148ff-a70f-4fc9-85f4-f0375ae96db9","trade_id":8429826924,"price":"1736.12","quantity":"0.014","trade_time_ms":1783517069478,"is_buyer_maker":false,"aggressor_side":"buy","raw":{"e":"trade","E":1783517069478,"T":1783517069478,"s":"ETHUSDT","t":8429826924,"p":"1736.12","q":"0.014","X":"MARKET","m":false,"st":1}}
{"schema_version":"1.3.0","event_id":"7457271a-b955-4106-a0e1-2ae2e69d995a","event_type":"raw.trade","source":"binance_market_data_recorder","venue":"binance_usdm","market_type":"perpetual_futures","symbol":"ETHUSDT","event_time_ms":1783517069478,"received_time_ms":1783517069473,"trace_id":"48112cd8-fb5f-462d-9cf9-751285f5fe7c","trade_id":8429826925,"price":"1736.12","quantity":"0.012","trade_time_ms":1783517069478,"is_buyer_maker":false,"aggressor_side":"buy","raw":{"e":"trade","E":1783517069478,"T":1783517069478,"s":"ETHUSDT","t":8429826925,"p":"1736.12","q":"0.012","X":"MARKET","m":false,"st":1}}
{"schema_version":"1.3.0","event_id":"a96b0c53-d99a-40c5-b8aa-9015ce7ee1ec","event_type":"raw.trade","source":"binance_market_data_recorder","venue":"binance_usdm","market_type":"perpetual_futures","symbol":"ETHUSDT","event_time_ms":1783517069478,"received_time_ms":1783517069474,"trace_id":"328522d4-f384-47e5-bba5-26efec283de3","trade_id":8429826926,"price":"1736.12","quantity":"0.089","trade_time_ms":1783517069478,"is_buyer_maker":false,"aggressor_side":"buy","raw":{"e":"trade","E":1783517069478,"T":1783517069478,"s":"ETHUSDT","t":8429826926,"p":"1736.12","q":"0.089","X":"MARKET","m":false,"st":1}}
{"schema_version":"1.3.0","event_id":"e43a0211-48a0-477c-ab7c-8f20e586d1eb","event_type":"raw.depth_update","source":"binance_market_data_recorder","venue":"binance_usdm","market_type":"perpetual_futures","symbol":"ETHUSDT","event_time_ms":1783517069524,"received_time_ms":1783517069519,"trace_id":"cdcdaf7f-b12b-43b2-ae24-9d5d0863e91e","first_update_id":10999770844229,"final_update_id":10999770857138,"previous_final_update_id":10999770844120,"bids":[{"price":"200.00","quantity":"7.594"},{"price":"201.00","quantity":"2.300"},{"price":"1211.11","quantity":"0.133"},{"price":"1226.11","quantity":"3.936"},{"price":"1231.11","quantity":"5.568"},{"price":"1562.49","quantity":"0.026"},{"price":"1562.50","quantity":"4.176"},{"price":"1666.60","quantity":"1.193"},{"price":"1699.08","quantity":"59.375"},{"price":"1701.38","quantity":"43.641"},{"price":"1702.05","quantity":"17.650"},{"price":"1704.85","quantity":"32.496"},{"price":"1714.32","quantity":"0.000"},{"price":"1714.41","quantity":"81.538"},{"price":"1733.17","quantity":"1.452"},{"price":"1733.59","quantity":"22.671"},{"price":"1733.64","quantity":"2.894"},{"price":"1733.70","quantity":"436.976"},{"price":"1734.06","quantity":"54.181"},{"price":"1734.88","quantity":"21.974"},{"price":"1734.98","quantity":"69.905"},{"price":"1735.00","quantity":"217.480"},{"price":"1735.06","quantity":"0.127"},{"price":"1735.07","quantity":"6.117"},{"price":"1735.11","quantity":"45.389"},{"price":"1735.12","quantity":"132.938"},{"price":"1735.19","quantity":"72.207"},{"price":"1735.20","quantity":"47.754"},{"price":"1735.29","quantity":"29.664"},{"price":"1735.32","quantity":"26.988"},{"price":"1735.33","quantity":"237.068"},{"price":"1735.34","quantity":"0.098"},{"price":"1735.46","quantity":"19.608"},{"price":"1735.50","quantity":"239.319"},{"price":"1735.73","quantity":"26.047"},{"price":"1735.77","quantity":"10.996"},{"price":"1735.78","quantity":"1.640"},{"price":"1735.80","quantity":"30.944"},{"price":"1735.81","quantity":"6.958"},{"price":"1735.84","quantity":"0.156"},{"price":"1735.87","quantity":"3.043"},{"price":"1735.99","quantity":"1.291"},{"price":"1736.02","quantity":"1.812"},{"price":"1736.05","quantity":"0.063"},{"price":"1736.08","quantity":"0.821"},{"price":"1736.11","quantity":"168.021"}],"asks":[{"price":"1736.12","quantity":"79.526"},{"price":"1736.15","quantity":"0.024"},{"price":"1736.16","quantity":"1.167"},{"price":"1736.20","quantity":"0.052"},{"price":"1736.23","quantity":"20.052"},{"price":"1736.24","quantity":"0.141"},{"price":"1736.28","quantity":"14.688"},{"price":"1736.31","quantity":"17.453"},{"price":"1736.34","quantity":"0.059"},{"price":"1736.37","quantity":"18.228"},{"price":"1736.39","quantity":"15.775"},{"price":"1736.40","quantity":"12.729"},{"price":"1736.46","quantity":"38.086"},{"price":"1736.47","quantity":"7.668"},{"price":"1736.50","quantity":"0.114"},{"price":"1736.52","quantity":"0.087"},{"price":"1736.54","quantity":"31.690"},{"price":"1736.59","quantity":"7.592"},{"price":"1736.63","quantity":"13.197"},{"price":"1736.90","quantity":"42.436"},{"price":"1764.05","quantity":"100.856"},{"price":"1769.65","quantity":"0.000"},{"price":"1770.07","quantity":"59.806"},{"price":"2634.53","quantity":"0.001"},{"price":"2634.62","quantity":"0.000"}],"raw":{"e":"depthUpdate","E":1783517069524,"T":1783517069523,"s":"ETHUSDT","ps":"ETHUSDT","U":10999770844229,"u":10999770857138,"pu":10999770844120,"b":[["200.00","7.594"],["201.00","2.300"],["1211.11","0.133"],["1226.11","3.936"],["1231.11","5.568"],["1562.49","0.026"],["1562.50","4.176"],["1666.60","1.193"],["1699.08","59.375"],["1701.38","43.641"],["1702.05","17.650"],["1704.85","32.496"],["1714.32","0.000"],["1714.41","81.538"],["1733.17","1.452"],["1733.59","22.671"],["1733.64","2.894"],["1733.70","436.976"],["1734.06","54.181"],["1734.88","21.974"],["1734.98","69.905"],["1735.00","217.480"],["1735.06","0.127"],["1735.07","6.117"],["1735.11","45.389"],["1735.12","132.938"],["1735.19","72.207"],["1735.20","47.754"],["1735.29","29.664"],["1735.32","26.988"],["1735.33","237.068"],["1735.34","0.098"],["1735.46","19.608"],["1735.50","239.319"],["1735.73","26.047"],["1735.77","10.996"],["1735.78","1.640"],["1735.80","30.944"],["1735.81","6.958"],["1735.84","0.156"],["1735.87","3.043"],["1735.99","1.291"],["1736.02","1.812"],["1736.05","0.063"],["1736.08","0.821"],["1736.11","168.021"]],"a":[["1736.12","79.526"],["1736.15","0.024"],["1736.16","1.167"],["1736.20","0.052"],["1736.23","20.052"],["1736.24","0.141"],["1736.28","14.688"],["1736.31","17.453"],["1736.34","0.059"],["1736.37","18.228"],["1736.39","15.775"],["1736.40","12.729"],["1736.46","38.086"],["1736.47","7.668"],["1736.50","0.114"],["1736.52","0.087"],["1736.54","31.690"],["1736.59","7.592"],["1736.63","13.197"],["1736.90","42.436"],["1764.05","100.856"],["1769.65","0.000"],["1770.07","59.806"],["2634.53","0.001"],["2634.62","0.000"]],"st":1}}
{"schema_version":"1.3.0","event_id":"055c302c-1ebc-4aec-bbd6-985c434e7576","event_type":"raw.depth_update","source":"binance_market_data_recorder","venue":"binance_usdm","market_type":"perpetual_futures","symbol":"BTCUSDT","event_time_ms":1783517069558,"received_time_ms":1783517069553,"trace_id":"0c0fe0e2-91a7-4852-9a41-07c7c4cad682","first_update_id":10999770850644,"final_update_id":10999770859633,"previous_final_update_id":10999770850269,"bids":[{"price":"11353.70","quantity":"0.952"},{"price":"11553.70","quantity":"0.176"},{"price":"11653.70","quantity":"2.736"},{"price":"11753.70","quantity":"1.036"},{"price":"55668.30","quantity":"0.002"},{"price":"58761.00","quantity":"0.012"},{"price":"59379.50","quantity":"0.001"},{"price":"61043.60","quantity":"0.000"},{"price":"61151.70","quantity":"0.245"},{"price":"61235.20","quantity":"0.027"},{"price":"61275.90","quantity":"0.245"},{"price":"61313.50","quantity":"0.008"},{"price":"61543.40","quantity":"1.429"},{"price":"61771.60","quantity":"0.001"},{"price":"61784.20","quantity":"0.002"},{"price":"61786.30","quantity":"33.564"},{"price":"61792.90","quantity":"0.017"},{"price":"61799.80","quantity":"1.266"},{"price":"61821.00","quantity":"1.098"},{"price":"61821.10","quantity":"0.456"},{"price":"61823.40","quantity":"0.069"},{"price":"61824.10","quantity":"0.002"},{"price":"61834.00","quantity":"1.382"},{"price":"61834.10","quantity":"2.902"},{"price":"61835.10","quantity":"1.712"},{"price":"61835.40","quantity":"0.001"},{"price":"61835.50","quantity":"0.012"},{"price":"61835.60","quantity":"0.129"},{"price":"61836.90","quantity":"0.081"},{"price":"61837.30","quantity":"0.805"},{"price":"61838.60","quantity":"0.016"},{"price":"61844.70","quantity":"0.002"},{"price":"61844.90","quantity":"1.003"},{"price":"61845.00","quantity":"0.017"},{"price":"61845.10","quantity":"0.123"},{"price":"61846.30","quantity":"0.526"},{"price":"61847.70","quantity":"0.003"},{"price":"61848.00","quantity":"0.726"},{"price":"61850.60","quantity":"0.289"},{"price":"61850.70","quantity":"0.006"},{"price":"61852.10","quantity":"0.000"},{"price":"61852.40","quantity":"1.567"},{"price":"61853.50","quantity":"0.004"},{"price":"61853.60","quantity":"0.004"},{"price":"61853.70","quantity":"6.445"}],"asks":[{"price":"61853.80","quantity":"2.421"},{"price":"61853.90","quantity":"0.006"},{"price":"61854.40","quantity":"0.001"},{"price":"61855.50","quantity":"0.245"},{"price":"61856.00","quantity":"0.026"},{"price":"61856.40","quantity":"0.029"},{"price":"61858.70","quantity":"0.066"},{"price":"61858.90","quantity":"0.623"},{"price":"61859.00","quantity":"0.104"},{"price":"61859.10","quantity":"0.722"},{"price":"61859.20","quantity":"0.069"},{"price":"61859.30","quantity":"0.000"},{"price":"61859.80","quantity":"0.003"},{"price":"61859.90","quantity":"0.002"},{"price":"61860.80","quantity":"0.029"},{"price":"61861.50","quantity":"2.689"},{"price":"61863.80","quantity":"0.200"},{"price":"61868.70","quantity":"0.081"},{"price":"61869.70","quantity":"0.083"},{"price":"61871.00","quantity":"0.020"},{"price":"61913.50","quantity":"2.244"},{"price":"61916.30","quantity":"0.149"},{"price":"61916.40","quantity":"3.237"},{"price":"61918.20","quantity":"0.023"},{"price":"61918.40","quantity":"25.284"},{"price":"61926.40","quantity":"12.227"},{"price":"62472.30","quantity":"0.000"},{"price":"62768.60","quantity":"0.000"},{"price":"89523.20","quantity":"0.804"}],"raw":{"e":"depthUpdate","E":1783517069558,"T":1783517069557,"s":"BTCUSDT","ps":"BTCUSDT","U":10999770850644,"u":10999770859633,"pu":10999770850269,"b":[["11353.70","0.952"],["11553.70","0.176"],["11653.70","2.736"],["11753.70","1.036"],["55668.30","0.002"],["58761.00","0.012"],["59379.50","0.001"],["61043.60","0.000"],["61151.70","0.245"],["61235.20","0.027"],["61275.90","0.245"],["61313.50","0.008"],["61543.40","1.429"],["61771.60","0.001"],["61784.20","0.002"],["61786.30","33.564"],["61792.90","0.017"],["61799.80","1.266"],["61821.00","1.098"],["61821.10","0.456"],["61823.40","0.069"],["61824.10","0.002"],["61834.00","1.382"],["61834.10","2.902"],["61835.10","1.712"],["61835.40","0.001"],["61835.50","0.012"],["61835.60","0.129"],["61836.90","0.081"],["61837.30","0.805"],["61838.60","0.016"],["61844.70","0.002"],["61844.90","1.003"],["61845.00","0.017"],["61845.10","0.123"],["61846.30","0.526"],["61847.70","0.003"],["61848.00","0.726"],["61850.60","0.289"],["61850.70","0.006"],["61852.10","0.000"],["61852.40","1.567"],["61853.50","0.004"],["61853.60","0.004"],["61853.70","6.445"]],"a":[["61853.80","2.421"],["61853.90","0.006"],["61854.40","0.001"],["61855.50","0.245"],["61856.00","0.026"],["61856.40","0.029"],["61858.70","0.066"],["61858.90","0.623"],["61859.00","0.104"],["61859.10","0.722"],["61859.20","0.069"],["61859.30","0.000"],["61859.80","0.003"],["61859.90","0.002"],["61860.80","0.029"],["61861.50","2.689"],["61863.80","0.200"],["61868.70","0.081"],["61869.70","0.083"],["61871.00","0.020"],["61913.50","2.244"],["61916.30","0.149"],["61916.40","3.237"],["61918.20","0.023"],["61918.40","25.284"],["61926.40","12.227"],["62472.30","0.000"],["62768.60","0.000"],["89523.20","0.804"]],"st":1}}
{"schema_version":"1.3.0","event_id":"4ec4637d-9231-49b3-b6bd-feebea58043c","event_type":"raw.trade","source":"binance_market_data_recorder","venue":"binance_usdm","market_type":"perpetual_futures","symbol":"BTCUSDT","event_time_ms":1783517069596,"received_time_ms":1783517069591,"trace_id":"21947909-dd96-4991-890b-da401b9299e7","trade_id":7881418083,"price":"61853.80","quantity":"0.001","trade_time_ms":1783517069596,"is_buyer_maker":false,"aggressor_side":"buy","raw":{"e":"trade","E":1783517069596,"T":1783517069596,"s":"BTCUSDT","t":7881418083,"p":"61853.80","q":"0.001","X":"MARKET","m":false,"st":1}}
{"schema_version":"1.3.0","event_id":"13059224-bded-4749-beb1-d5ab3edf2c07","event_type":"raw.trade","source":"binance_market_data_recorder","venue":"binance_usdm","market_type":"perpetual_futures","symbol":"ETHUSDT","event_time_ms":1783517069600,"received_time_ms":1783517069595,"trace_id":"a1ffc28d-84df-47b4-bce6-92fdb8ae8247","trade_id":8429826927,"price":"1736.12","quantity":"0.186","trade_time_ms":1783517069600,"is_buyer_maker":false,"aggressor_side":"buy","raw":{"e":"trade","E":1783517069600,"T":1783517069600,"s":"ETHUSDT","t":8429826927,"p":"1736.12","q":"0.186","X":"MARKET","m":false,"st":1}}
{"schema_version":"1.3.0","event_id":"c08e4d77-e9e5-438f-8edd-043b183c383f","event_type":"raw.depth_update","source":"binance_market_data_recorder","venue":"binance_usdm","market_type":"perpetual_futures","symbol":"ETHUSDT","event_time_ms":1783517069626,"received_time_ms":1783517069621,"trace_id":"640bdfce-621f-4f5e-84d0-0fba7ff45016","first_update_id":10999770857231,"final_update_id":10999770865301,"previous_final_update_id":10999770857138,"bids":[{"price":"200.00","quantity":"7.594"},{"price":"1211.11","quantity":"0.037"},{"price":"1226.11","quantity":"4.672"},{"price":"1231.11","quantity":"4.928"},{"price":"1562.04","quantity":"0.140"},{"price":"1562.49","quantity":"0.026"},{"price":"1562.50","quantity":"4.176"},{"price":"1666.60","quantity":"1.078"},{"price":"1692.70","quantity":"91.767"},{"price":"1701.39","quantity":"32.216"},{"price":"1707.92","quantity":"24.853"},{"price":"1710.39","quantity":"316.357"},{"price":"1732.19","quantity":"0.100"},{"price":"1733.70","quantity":"16.600"},{"price":"1734.06","quantity":"473.253"},{"price":"1734.15","quantity":"0.490"},{"price":"1735.18","quantity":"0.694"},{"price":"1735.33","quantity":"16.517"},{"price":"1735.53","quantity":"9.093"},{"price":"1735.61","quantity":"8.709"},{"price":"1735.76","quantity":"11.272"},{"price":"1735.99","quantity":"9.939"},{"price":"1736.00","quantity":"5.557"}],"asks":[{"price":"1736.12","quantity":"79.366"},{"price":"1736.20","quantity":"0.072"},{"price":"1736.46","quantity":"42.293"},{"price":"1736.52","quantity":"0.256"},{"price":"1736.63","quantity":"8.870"},{"price":"1736.90","quantity":"31.436"},{"price":"1737.03","quantity":"86.757"},{"price":"1737.12","quantity":"7.826"},{"price":"1737.23","quantity":"32.967"},{"price":"1737.42","quantity":"5.342"},{"price":"1737.51","quantity":"0.218"},{"price":"1738.89","quantity":"56.549"},{"price":"1740.14","quantity":"0.000"},{"price":"1742.16","quantity":"18.982"},{"price":"1742.23","quantity":"9.044"},{"price":"1742.28","quantity":"0.137"},{"price":"1757.09","quantity":"44.357"},{"price":"2634.51","quantity":"0.001"},{"price":"2634.52","quantity":"0.001"},{"price":"2634.60","quantity":"0.000"},{"price":"2634.61","quantity":"0.118"}],"raw":{"e":"depthUpdate","E":1783517069626,"T":1783517069625,"s":"ETHUSDT","ps":"ETHUSDT","U":10999770857231,"u":10999770865301,"pu":10999770857138,"b":[["200.00","7.594"],["1211.11","0.037"],["1226.11","4.672"],["1231.11","4.928"],["1562.04","0.140"],["1562.49","0.026"],["1562.50","4.176"],["1666.60","1.078"],["1692.70","91.767"],["1701.39","32.216"],["1707.92","24.853"],["1710.39","316.357"],["1732.19","0.100"],["1733.70","16.600"],["1734.06","473.253"],["1734.15","0.490"],["1735.18","0.694"],["1735.33","16.517"],["1735.53","9.093"],["1735.61","8.709"],["1735.76","11.272"],["1735.99","9.939"],["1736.00","5.557"]],"a":[["1736.12","79.366"],["1736.20","0.072"],["1736.46","42.293"],["1736.52","0.256"],["1736.63","8.870"],["1736.90","31.436"],["1737.03","86.757"],["1737.12","7.826"],["1737.23","32.967"],["1737.42","5.342"],["1737.51","0.218"],["1738.89","56.549"],["1740.14","0.000"],["1742.16","18.982"],["1742.23","9.044"],["1742.28","0.137"],["1757.09","44.357"],["2634.51","0.001"],["2634.52","0.001"],["2634.60","0.000"],["2634.61","0.118"]],"st":1}}
{"schema_version":"1.3.0","event_id":"786256f8-e98b-4235-9073-15577eba4dd4","event_type":"raw.depth_update","source":"binance_market_data_recorder","venue":"binance_usdm","market_type":"perpetual_futures","symbol":"BTCUSDT","event_time_ms":1783517069660,"received_time_ms":1783517069654,"trace_id":"fa1abb1f-27f6-4bee-8052-15917b29719f","first_update_id":10999770859706,"final_update_id":10999770867877,"previous_final_update_id":10999770859633,"bids":[{"price":"1000.00","quantity":"207.692"},{"price":"11353.70","quantity":"0.816"},{"price":"11553.70","quantity":"0.320"},{"price":"11653.70","quantity":"2.720"},{"price":"11753.70","quantity":"1.044"},{"price":"55668.30","quantity":"0.002"},{"price":"58761.00","quantity":"0.012"},{"price":"59379.50","quantity":"0.004"},{"price":"60794.40","quantity":"0.000"},{"price":"60895.00","quantity":"2.460"},{"price":"60987.70","quantity":"7.651"},{"price":"61076.90","quantity":"3.497"},{"price":"61235.20","quantity":"0.025"},{"price":"61544.40","quantity":"0.013"},{"price":"61747.90","quantity":"0.000"},{"price":"61749.30","quantity":"0.000"},{"price":"61749.40","quantity":"0.014"},{"price":"61749.60","quantity":"0.024"},{"price":"61783.60","quantity":"0.057"},{"price":"61785.10","quantity":"0.015"},{"price":"61789.00","quantity":"6.328"},{"price":"61801.70","quantity":"0.070"},{"price":"61810.30","quantity":"1.591"},{"price":"61814.60","quantity":"0.005"},{"price":"61816.10","quantity":"0.014"},{"price":"61822.50","quantity":"0.761"},{"price":"61823.80","quantity":"0.081"},{"price":"61833.90","quantity":"0.081"},{"price":"61836.90","quantity":"0.001"},{"price":"61843.10","quantity":"0.907"},{"price":"61844.20","quantity":"1.291"},{"price":"61845.00","quantity":"0.009"},{"price":"61845.10","quantity":"0.123"},{"price":"61846.30","quantity":"0.648"},{"price":"61852.40","quantity":"0.670"},{"price":"61853.60","quantity":"0.005"}],"asks":[{"price":"61853.80","quantity":"2.540"},{"price":"61854.80","quantity":"0.001"},{"price":"61854.90","quantity":"0.258"},{"price":"61855.50","quantity":"0.003"},{"price":"61857.00","quantity":"0.713"},{"price":"61858.80","quantity":"0.000"},{"price":"61859.10","quantity":"0.491"},{"price":"61863.10","quantity":"0.000"},{"price":"61863.90","quantity":"1.276"},{"price":"61869.00","quantity":"0.147"},{"price":"61870.50","quantity":"0.178"},{"price":"61892.50","quantity":"0.116"},{"price":"61899.00","quantity":"0.017"},{"price":"61900.50","quantity":"0.030"},{"price":"61926.40","quantity":"12.130"},{"price":"61933.50","quantity":"0.001"},{"price":"61935.00","quantity":"0.014"},{"price":"62027.60","quantity":"0.008"},{"price":"62027.80","quantity":"0.003"},{"price":"62472.30","quantity":"0.000"},{"price":"62778.20","quantity":"0.716"}],"raw":{"e":"depthUpdate","E":1783517069660,"T":1783517069658,"s":"BTCUSDT","ps":"BTCUSDT","U":10999770859706,"u":10999770867877,"pu":10999770859633,"b":[["1000.00","207.692"],["11353.70","0.816"],["11553.70","0.320"],["11653.70","2.720"],["11753.70","1.044"],["55668.30","0.002"],["58761.00","0.012"],["59379.50","0.004"],["60794.40","0.000"],["60895.00","2.460"],["60987.70","7.651"],["61076.90","3.497"],["61235.20","0.025"],["61544.40","0.013"],["61747.90","0.000"],["61749.30","0.000"],["61749.40","0.014"],["61749.60","0.024"],["61783.60","0.057"],["61785.10","0.015"],["61789.00","6.328"],["61801.70","0.070"],["61810.30","1.591"],["61814.60","0.005"],["61816.10","0.014"],["61822.50","0.761"],["61823.80","0.081"],["61833.90","0.081"],["61836.90","0.001"],["61843.10","0.907"],["61844.20","1.291"],["61845.00","0.009"],["61845.10","0.123"],["61846.30","0.648"],["61852.40","0.670"],["61853.60","0.005"]],"a":[["61853.80","2.540"],["61854.80","0.001"],["61854.90","0.258"],["61855.50","0.003"],["61857.00","0.713"],["61858.80","0.000"],["61859.10","0.491"],["61863.10","0.000"],["61863.90","1.276"],["61869.00","0.147"],["61870.50","0.178"],["61892.50","0.116"],["61899.00","0.017"],["61900.50","0.030"],["61926.40","12.130"],["61933.50","0.001"],["61935.00","0.014"],["62027.60","0.008"],["62027.80","0.003"],["62472.30","0.000"],["62778.20","0.716"]],"st":1}}
{"schema_version":"1.3.0","event_id":"10f08033-43f0-44b9-8d38-89babbbb0899","event_type":"raw.depth_update","source":"binance_market_data_recorder","venue":"binance_usdm","market_type":"perpetual_futures","symbol":"ETHUSDT","event_time_ms":1783517069730,"received_time_ms":1783517069724,"trace_id":"b989c978-04ee-4784-99cf-0bd534afed89","first_update_id":10999770865635,"final_update_id":10999770873125,"previous_final_update_id":10999770865301,"bids":[{"price":"1226.11","quantity":"5.504"},{"price":"1231.11","quantity":"4.096"},{"price":"1562.49","quantity":"0.026"},{"price":"1562.50","quantity":"4.176"},{"price":"1687.87","quantity":"0.189"},{"price":"1701.39","quantity":"32.187"},{"price":"1719.12","quantity":"3.115"},{"price":"1732.14","quantity":"42.402"},{"price":"1735.45","quantity":"220.714"},{"price":"1735.50","quantity":"18.754"},{"price":"1735.63","quantity":"0.576"},{"price":"1735.70","quantity":"5.786"},{"price":"1735.73","quantity":"31.813"},{"price":"1735.91","quantity":"11.685"},{"price":"1735.94","quantity":"9.556"},{"price":"1735.98","quantity":"1.324"},{"price":"1736.09","quantity":"1.532"}],"asks":[{"price":"1736.12","quantity":"62.931"},{"price":"1736.18","quantity":"0.065"},{"price":"1736.31","quantity":"17.453"},{"price":"1736.33","quantity":"1.735"},{"price":"1736.37","quantity":"18.516"},{"price":"1736.50","quantity":"0.102"},{"price":"1737.35","quantity":"0.044"},{"price":"1737.54","quantity":"1.118"},{"price":"1737.89","quantity":"33.409"},{"price":"1740.09","quantity":"37.626"},{"price":"1742.31","quantity":"11.636"},{"price":"1742.32","quantity":"0.013"},{"price":"1747.12","quantity":"0.000"},{"price":"1762.77","quantity":"25.808"},{"price":"1768.76","quantity":"155.305"},{"price":"1769.13","quantity":"11.336"},{"price":"2634.50","quantity":"0.001"},{"price":"2634.59","quantity":"0.000"}],"raw":{"e":"depthUpdate","E":1783517069730,"T":1783517069729,"s":"ETHUSDT","ps":"ETHUSDT","U":10999770865635,"u":10999770873125,"pu":10999770865301,"b":[["1226.11","5.504"],["1231.11","4.096"],["1562.49","0.026"],["1562.50","4.176"],["1687.87","0.189"],["1701.39","32.187"],["1719.12","3.115"],["1732.14","42.402"],["1735.45","220.714"],["1735.50","18.754"],["1735.63","0.576"],["1735.70","5.786"],["1735.73","31.813"],["1735.91","11.685"],["1735.94","9.556"],["1735.98","1.324"],["1736.09","1.532"]],"a":[["1736.12","62.931"],["1736.18","0.065"],["1736.31","17.453"],["1736.33","1.735"],["1736.37","18.516"],["1736.50","0.102"],["1737.35","0.044"],["1737.54","1.118"],["1737.89","33.409"],["1740.09","37.626"],["1742.31","11.636"],["1742.32","0.013"],["1747.12","0.000"],["1762.77","25.808"],["1768.76","155.305"],["1769.13","11.336"],["2634.50","0.001"],["2634.59","0.000"]],"st":1}}
{"schema_version":"1.3.0","event_id":"4543e6e1-831e-480c-906c-fe345d17457f","event_type":"raw.depth_update","source":"binance_market_data_recorder","venue":"binance_usdm","market_type":"perpetual_futures","symbol":"BTCUSDT","event_time_ms":1783517069762,"received_time_ms":1783517069759,"trace_id":"2420b4a3-6d6f-4503-a6df-c97a6854dea7","first_update_id":10999770868001,"final_update_id":10999770875462,"previous_final_update_id":10999770867877,"bids":[{"price":"1000.00","quantity":"207.692"},{"price":"11353.70","quantity":"0.663"},{"price":"11553.70","quantity":"0.448"},{"price":"11653.70","quantity":"2.736"},{"price":"11753.70","quantity":"1.053"},{"price":"49483.00","quantity":"0.008"},{"price":"55668.30","quantity":"0.002"},{"price":"58761.00","quantity":"0.012"},{"price":"60717.80","quantity":"0.000"},{"price":"61049.10","quantity":"1.144"},{"price":"61169.90","quantity":"0.491"},{"price":"61235.20","quantity":"0.025"},{"price":"61335.70","quantity":"0.039"},{"price":"61763.50","quantity":"0.001"},{"price":"61823.80","quantity":"0.001"},{"price":"61826.60","quantity":"0.113"},{"price":"61827.50","quantity":"2.750"},{"price":"61827.90","quantity":"0.622"},{"price":"61828.10","quantity":"0.122"},{"price":"61829.10","quantity":"0.218"},{"price":"61832.20","quantity":"0.010"},{"price":"61833.90","quantity":"0.001"},{"price":"61834.40","quantity":"0.171"},{"price":"61838.10","quantity":"0.483"},{"price":"61840.00","quantity":"0.512"},{"price":"61840.30","quantity":"0.123"},{"price":"61840.40","quantity":"0.004"},{"price":"61840.50","quantity":"2.138"},{"price":"61840.60","quantity":"0.566"},{"price":"61840.70","quantity":"0.003"},{"price":"61841.40","quantity":"0.955"},{"price":"61841.60","quantity":"0.053"},{"price":"61843.10","quantity":"0.018"},{"price":"61844.50","quantity":"0.326"},{"price":"61845.00","quantity":"0.332"},{"price":"61845.10","quantity":"0.689"},{"price":"61847.60","quantity":"0.004"},{"price":"61847.80","quantity":"0.004"},{"price":"61852.20","quantity":"0.632"},{"price":"61853.70","quantity":"6.445"}],"asks":[{"price":"61853.80","quantity":"2.429"},{"price":"61857.10","quantity":"0.001"},{"price":"61858.10","quantity":"0.154"},{"price":"61858.30","quantity":"0.014"},{"price":"61858.50","quantity":"0.776"},{"price":"61858.60","quantity":"0.001"},{"price":"61858.70","quantity":"0.001"},{"price":"61858.80","quantity":"0.000"},{"price":"61858.90","quantity":"0.057"},{"price":"61859.10","quantity":"0.000"},{"price":"61859.40","quantity":"0.002"},{"price":"61859.80","quantity":"0.002"},{"price":"61859.90","quantity":"0.002"},{"price":"61860.20","quantity":"2.529"},{"price":"61861.60","quantity":"0.320"},{"price":"61865.60","quantity":"0.184"},{"price":"61866.10","quantity":"0.582"},{"price":"61869.00","quantity":"0.147"},{"price":"61869.40","quantity":"0.128"},{"price":"61870.00","quantity":"0.411"},{"price":"61871.10","quantity":"0.019"},{"price":"61872.80","quantity":"0.000"},{"price":"61926.40","quantity":"12.227"},{"price":"62472.30","quantity":"0.000"},{"price":"63089.30","quantity":"0.090"},{"price":"89523.20","quantity":"0.810"}],"raw":{"e":"depthUpdate","E":1783517069762,"T":1783517069761,"s":"BTCUSDT","ps":"BTCUSDT","U":10999770868001,"u":10999770875462,"pu":10999770867877,"b":[["1000.00","207.692"],["11353.70","0.663"],["11553.70","0.448"],["11653.70","2.736"],["11753.70","1.053"],["49483.00","0.008"],["55668.30","0.002"],["58761.00","0.012"],["60717.80","0.000"],["61049.10","1.144"],["61169.90","0.491"],["61235.20","0.025"],["61335.70","0.039"],["61763.50","0.001"],["61823.80","0.001"],["61826.60","0.113"],["61827.50","2.750"],["61827.90","0.622"],["61828.10","0.122"],["61829.10","0.218"],["61832.20","0.010"],["61833.90","0.001"],["61834.40","0.171"],["61838.10","0.483"],["61840.00","0.512"],["61840.30","0.123"],["61840.40","0.004"],["61840.50","2.138"],["61840.60","0.566"],["61840.70","0.003"],["61841.40","0.955"],["61841.60","0.053"],["61843.10","0.018"],["61844.50","0.326"],["61845.00","0.332"],["61845.10","0.689"],["61847.60","0.004"],["61847.80","0.004"],["61852.20","0.632"],["61853.70","6.445"]],"a":[["61853.80","2.429"],["61857.10","0.001"],["61858.10","0.154"],["61858.30","0.014"],["61858.50","0.776"],["61858.60","0.001"],["61858.70","0.001"],["61858.80","0.000"],["61858.90","0.057"],["61859.10","0.000"],["61859.40","0.002"],["61859.80","0.002"],["61859.90","0.002"],["61860.20","2.529"],["61861.60","0.320"],["61865.60","0.184"],["61866.10","0.582"],["61869.00","0.147"],["61869.40","0.128"],["61870.00","0.411"],["61871.10","0.019"],["61872.80","0.000"],["61926.40","12.227"],["62472.30","0.000"],["63089.30","0.090"],["89523.20","0.810"]],"st":1}}
{"schema_version":"1.3.0","event_id":"c3740863-1ec6-4cad-9dc3-79982e74655a","event_type":"raw.depth_update","source":"binance_market_data_recorder","venue":"binance_usdm","market_type":"perpetual_futures","symbol":"ETHUSDT","event_time_ms":1783517069834,"received_time_ms":1783517069828,"trace_id":"7e70c9e4-79f3-450a-b98a-e1f493d4cfc2","first_update_id":10999770873511,"final_update_id":10999770879690,"previous_final_update_id":10999770873125,"bids":[{"price":"200.00","quantity":"7.594"},{"price":"1226.11","quantity":"6.336"},{"price":"1231.11","quantity":"3.264"},{"price":"1562.49","quantity":"0.026"},{"price":"1562.50","quantity":"4.432"},{"price":"1666.60","quantity":"1.193"},{"price":"1706.13","quantity":"0.000"},{"price":"1710.08","quantity":"112.553"},{"price":"1714.74","quantity":"35.375"},{"price":"1715.12","quantity":"11.644"},{"price":"1729.25","quantity":"1.285"},{"price":"1729.85","quantity":"22.358"},{"price":"1730.67","quantity":"0.000"},{"price":"1734.06","quantity":"54.181"},{"price":"1734.12","quantity":"474.969"},{"price":"1735.11","quantity":"45.389"},{"price":"1735.31","quantity":"254.509"},{"price":"1735.45","quantity":"0.178"},{"price":"1735.55","quantity":"4.604"},{"price":"1735.67","quantity":"0.128"},{"price":"1735.70","quantity":"5.798"},{"price":"1735.71","quantity":"5.804"},{"price":"1735.73","quantity":"27.747"},{"price":"1736.03","quantity":"1.154"}],"asks":[{"price":"1736.12","quantity":"73.552"},{"price":"1736.13","quantity":"8.956"},{"price":"1736.19","quantity":"0.012"},{"price":"1736.23","quantity":"20.141"},{"price":"1736.36","quantity":"22.091"},{"price":"1736.46","quantity":"45.089"},{"price":"1736.50","quantity":"1.814"},{"price":"1736.68","quantity":"4.705"},{"price":"1736.90","quantity":"29.769"},{"price":"1736.91","quantity":"68.135"},{"price":"1736.97","quantity":"4.979"},{"price":"1737.00","quantity":"94.091"},{"price":"1737.02","quantity":"22.435"},{"price":"1737.60","quantity":"4.591"},{"price":"1738.80","quantity":"5.949"},{"price":"1738.94","quantity":"3.960"},{"price":"1741.41","quantity":"10.358"},{"price":"1748.86","quantity":"0.123"},{"price":"1755.22","quantity":"33.090"},{"price":"1768.24","quantity":"38.974"},{"price":"2634.48","quantity":"0.149"},{"price":"2634.49","quantity":"0.001"},{"price":"2634.57","quantity":"0.000"},{"price":"2634.58","quantity":"0.000"}],"raw":{"e":"depthUpdate","E":1783517069834,"T":1783517069833,"s":"ETHUSDT","ps":"ETHUSDT","U":10999770873511,"u":10999770879690,"pu":10999770873125,"b":[["200.00","7.594"],["1226.11","6.336"],["1231.11","3.264"],["1562.49","0.026"],["1562.50","4.432"],["1666.60","1.193"],["1706.13","0.000"],["1710.08","112.553"],["1714.74","35.375"],["1715.12","11.644"],["1729.25","1.285"],["1729.85","22.358"],["1730.67","0.000"],["1734.06","54.181"],["1734.12","474.969"],["1735.11","45.389"],["1735.31","254.509"],["1735.45","0.178"],["1735.55","4.604"],["1735.67","0.128"],["1735.70","5.798"],["1735.71","5.804"],["1735.73","27.747"],["1736.03","1.154"]],"a":[["1736.12","73.552"],["1736.13","8.956"],["1736.19","0.012"],["1736.23","20.141"],["1736.36","22.091"],["1736.46","45.089"],["1736.50","1.814"],["1736.68","4.705"],["1736.90","29.769"],["1736.91","68.135"],["1736.97","4.979"],["1737.00","94.091"],["1737.02","22.435"],["1737.60","4.591"],["1738.80","5.949"],["1738.94","3.960"],["1741.41","10.358"],["1748.86","0.123"],["1755.22","33.090"],["1768.24","38.974"],["2634.48","0.149"],["2634.49","0.001"],["2634.57","0.000"],["2634.58","0.000"]],"st":1}}
{"schema_version":"1.3.0","event_id":"c858634f-cd01-4efa-8fce-1630e8bee290","event_type":"raw.depth_update","source":"binance_market_data_recorder","venue":"binance_usdm","market_type":"perpetual_futures","symbol":"BTCUSDT","event_time_ms":1783517069864,"received_time_ms":1783517069858,"trace_id":"f1f09b41-d097-42e8-ae81-052966fe041d","first_update_id":10999770875480,"final_update_id":10999770881747,"previous_final_update_id":10999770875462,"bids":[{"price":"11353.70","quantity":"0.527"},{"price":"11553.70","quantity":"0.704"},{"price":"11653.70","quantity":"2.496"},{"price":"11753.70","quantity":"1.173"},{"price":"49483.00","quantity":"0.000"},{"price":"55668.30","quantity":"0.002"},{"price":"59379.50","quantity":"0.001"},{"price":"60788.60","quantity":"4.452"},{"price":"61235.20","quantity":"0.025"},{"price":"61260.70","quantity":"1.487"},{"price":"61339.30","quantity":"0.034"},{"price":"61352.40","quantity":"0.338"},{"price":"61537.60","quantity":"0.348"},{"price":"61544.40","quantity":"0.012"},{"price":"61826.10","quantity":"1.051"},{"price":"61833.50","quantity":"0.040"},{"price":"61838.10","quantity":"0.403"},{"price":"61840.00","quantity":"0.592"},{"price":"61840.10","quantity":"0.002"}],"asks":[{"price":"61853.90","quantity":"0.009"},{"price":"61854.60","quantity":"0.005"},{"price":"61858.50","quantity":"0.776"},{"price":"61859.60","quantity":"0.163"},{"price":"61859.80","quantity":"0.128"},{"price":"61859.90","quantity":"1.618"},{"price":"61860.20","quantity":"0.913"},{"price":"61861.70","quantity":"0.000"},{"price":"61862.80","quantity":"0.346"},{"price":"61871.20","quantity":"0.027"},{"price":"61893.00","quantity":"0.373"},{"price":"61926.40","quantity":"12.130"},{"price":"62163.10","quantity":"0.001"},{"price":"62472.30","quantity":"0.002"},{"price":"62781.60","quantity":"0.358"},{"price":"63348.50","quantity":"0.000"}],"raw":{"e":"depthUpdate","E":1783517069864,"T":1783517069863,"s":"BTCUSDT","ps":"BTCUSDT","U":10999770875480,"u":10999770881747,"pu":10999770875462,"b":[["11353.70","0.527"],["11553.70","0.704"],["11653.70","2.496"],["11753.70","1.173"],["49483.00","0.000"],["55668.30","0.002"],["59379.50","0.001"],["60788.60","4.452"],["61235.20","0.025"],["61260.70","1.487"],["61339.30","0.034"],["61352.40","0.338"],["61537.60","0.348"],["61544.40","0.012"],["61826.10","1.051"],["61833.50","0.040"],["61838.10","0.403"],["61840.00","0.592"],["61840.10","0.002"]],"a":[["61853.90","0.009"],["61854.60","0.005"],["61858.50","0.776"],["61859.60","0.163"],["61859.80","0.128"],["61859.90","1.618"],["61860.20","0.913"],["61861.70","0.000"],["61862.80","0.346"],["61871.20","0.027"],["61893.00","0.373"],["61926.40","12.130"],["62163.10","0.001"],["62472.30","0.002"],["62781.60","0.358"],["63348.50","0.000"]],"st":1}}
{"schema_version":"1.3.0","event_id":"48c61ef5-c7f9-49e3-b4f5-bd5d34958147","event_type":"raw.depth_update","source":"binance_market_data_recorder","venue":"binance_usdm","market_type":"perpetual_futures","symbol":"ETHUSDT","event_time_ms":1783517069938,"received_time_ms":1783517069932,"trace_id":"dc1956d0-7132-42ff-84a6-075cdcac8a17","first_update_id":10999770879947,"final_update_id":10999770885423,"previous_final_update_id":10999770879690,"bids":[{"price":"200.00","quantity":"7.594"},{"price":"1221.11","quantity":"0.064"},{"price":"1226.11","quantity":"7.040"},{"price":"1231.11","quantity":"2.496"},{"price":"1562.49","quantity":"0.026"},{"price":"1562.50","quantity":"4.304"},{"price":"1666.60","quantity":"1.078"},{"price":"1701.39","quantity":"32.216"},{"price":"1706.77","quantity":"25.781"},{"price":"1708.50","quantity":"83.080"},{"price":"1730.76","quantity":"17.121"},{"price":"1734.12","quantity":"55.897"},{"price":"1734.18","quantity":"419.084"},{"price":"1735.96","quantity":"0.840"},{"price":"1735.98","quantity":"1.036"}],"asks":[{"price":"1736.60","quantity":"5.151"},{"price":"1736.98","quantity":"13.000"},{"price":"1737.34","quantity":"13.215"},{"price":"1737.68","quantity":"3.610"},{"price":"1737.82","quantity":"42.838"},{"price":"1737.86","quantity":"20.145"},{"price":"1738.12","quantity":"4.331"},{"price":"1738.96","quantity":"0.000"},{"price":"1741.55","quantity":"14.286"},{"price":"1744.60","quantity":"88.497"},{"price":"1768.24","quantity":"50.268"},{"price":"2634.47","quantity":"0.001"},{"price":"2634.56","quantity":"0.000"}],"raw":{"e":"depthUpdate","E":1783517069938,"T":1783517069937,"s":"ETHUSDT","ps":"ETHUSDT","U":10999770879947,"u":10999770885423,"pu":10999770879690,"b":[["200.00","7.594"],["1221.11","0.064"],["1226.11","7.040"],["1231.11","2.496"],["1562.49","0.026"],["1562.50","4.304"],["1666.60","1.078"],["1701.39","32.216"],["1706.77","25.781"],["1708.50","83.080"],["1730.76","17.121"],["1734.12","55.897"],["1734.18","419.084"],["1735.96","0.840"],["1735.98","1.036"]],"a":[["1736.60","5.151"],["1736.98","13.000"],["1737.34","13.215"],["1737.68","3.610"],["1737.82","42.838"],["1737.86","20.145"],["1738.12","4.331"],["1738.96","0.000"],["1741.55","14.286"],["1744.60","88.497"],["1768.24","50.268"],["2634.47","0.001"],["2634.56","0.000"]],"st":1}}
{"schema_version":"1.3.0","event_id":"c6ad5f6a-8d86-4c0c-acb6-3738235abb33","event_type":"raw.trade","source":"binance_market_data_recorder","venue":"binance_usdm","market_type":"perpetual_futures","symbol":"ETHUSDT","event_time_ms":1783517069942,"received_time_ms":1783517069937,"trace_id":"1316fb3e-b580-4115-a760-323395f9265f","trade_id":8429826928,"price":"1736.11","quantity":"0.564","trade_time_ms":1783517069942,"is_buyer_maker":true,"aggressor_side":"sell","raw":{"e":"trade","E":1783517069942,"T":1783517069942,"s":"ETHUSDT","t":8429826928,"p":"1736.11","q":"0.564","X":"MARKET","m":true,"st":1}}
{"schema_version":"1.3.0","event_id":"494f8951-dbf7-4a78-ab6c-54e805e3c1f4","event_type":"raw.depth_update","source":"binance_market_data_recorder","venue":"binance_usdm","market_type":"perpetual_futures","symbol":"BTCUSDT","event_time_ms":1783517069966,"received_time_ms":1783517069963,"trace_id":"137248ca-ba80-4b90-b489-2a99adffe07f","first_update_id":10999770881792,"final_update_id":10999770887268,"previous_final_update_id":10999770881747,"bids":[{"price":"1000.00","quantity":"207.692"},{"price":"11353.70","quantity":"0.374"},{"price":"11553.70","quantity":"0.976"},{"price":"11653.70","quantity":"2.224"},{"price":"11753.70","quantity":"1.326"},{"price":"55668.30","quantity":"0.002"},{"price":"58761.00","quantity":"0.012"},{"price":"59379.50","quantity":"0.004"},{"price":"60616.70","quantity":"0.038"},{"price":"60909.40","quantity":"16.796"},{"price":"61235.20","quantity":"0.025"},{"price":"61266.10","quantity":"1.621"},{"price":"61358.90","quantity":"5.292"},{"price":"61544.40","quantity":"0.013"},{"price":"61812.20","quantity":"1.187"},{"price":"61832.30","quantity":"0.082"},{"price":"61840.00","quantity":"0.512"},{"price":"61845.20","quantity":"0.323"},{"price":"61846.30","quantity":"0.325"}],"asks":[{"price":"61859.80","quantity":"0.325"},{"price":"61860.20","quantity":"0.590"},{"price":"61893.00","quantity":"0.000"},{"price":"61893.30","quantity":"0.680"},{"price":"62163.10","quantity":"0.002"},{"price":"62472.30","quantity":"0.000"},{"price":"62835.20","quantity":"0.000"},{"price":"89523.20","quantity":"0.816"}],"raw":{"e":"depthUpdate","E":1783517069966,"T":1783517069965,"s":"BTCUSDT","ps":"BTCUSDT","U":10999770881792,"u":10999770887268,"pu":10999770881747,"b":[["1000.00","207.692"],["11353.70","0.374"],["11553.70","0.976"],["11653.70","2.224"],["11753.70","1.326"],["55668.30","0.002"],["58761.00","0.012"],["59379.50","0.004"],["60616.70","0.038"],["60909.40","16.796"],["61235.20","0.025"],["61266.10","1.621"],["61358.90","5.292"],["61544.40","0.013"],["61812.20","1.187"],["61832.30","0.082"],["61840.00","0.512"],["61845.20","0.323"],["61846.30","0.325"]],"a":[["61859.80","0.325"],["61860.20","0.590"],["61893.00","0.000"],["61893.30","0.680"],["62163.10","0.002"],["62472.30","0.000"],["62835.20","0.000"],["89523.20","0.816"]],"st":1}}
{"schema_version":"1.3.0","event_id":"1d2a675f-bec3-4ddc-9d71-4d647b3feb23","event_type":"raw.depth_update","source":"binance_market_data_recorder","venue":"binance_usdm","market_type":"perpetual_futures","symbol":"ETHUSDT","event_time_ms":1783517070040,"received_time_ms":1783517070035,"trace_id":"5c3709c2-fb93-4cac-92fb-793015fc168a","first_update_id":10999770885484,"final_update_id":10999770892193,"previous_final_update_id":10999770885423,"bids":[{"price":"1221.11","quantity":"0.320"},{"price":"1226.11","quantity":"7.328"},{"price":"1231.11","quantity":"1.952"},{"price":"1562.49","quantity":"0.026"},{"price":"1562.50","quantity":"4.318"},{"price":"1666.60","quantity":"1.193"},{"price":"1701.39","quantity":"32.187"},{"price":"1704.86","quantity":"32.357"},{"price":"1708.44","quantity":"51.352"},{"price":"1710.34","quantity":"29.258"},{"price":"1716.55","quantity":"58.711"},{"price":"1733.91","quantity":"3.661"},{"price":"1734.99","quantity":"0.122"},{"price":"1735.17","quantity":"0.047"},{"price":"1735.19","quantity":"70.115"},{"price":"1735.20","quantity":"48.803"},{"price":"1735.21","quantity":"34.744"},{"price":"1735.31","quantity":"33.978"},{"price":"1735.41","quantity":"344.695"},{"price":"1735.76","quantity":"11.416"},{"price":"1736.11","quantity":"168.957"}],"asks":[{"price":"1736.12","quantity":"73.564"},{"price":"1736.13","quantity":"9.832"},{"price":"1736.16","quantity":"0.291"},{"price":"1736.19","quantity":"0.101"},{"price":"1736.23","quantity":"20.052"},{"price":"1736.31","quantity":"17.453"},{"price":"1736.47","quantity":"7.812"},{"price":"1736.65","quantity":"17.640"},{"price":"1736.70","quantity":"11.247"},{"price":"1737.12","quantity":"7.826"},{"price":"1737.77","quantity":"17.434"},{"price":"1738.03","quantity":"0.000"},{"price":"1738.97","quantity":"185.116"},{"price":"1747.12","quantity":"15.000"},{"price":"2634.46","quantity":"0.001"},{"price":"2634.55","quantity":"0.000"}],"raw":{"e":"depthUpdate","E":1783517070040,"T":1783517070037,"s":"ETHUSDT","ps":"ETHUSDT","U":10999770885484,"u":10999770892193,"pu":10999770885423,"b":[["1221.11","0.320"],["1226.11","7.328"],["1231.11","1.952"],["1562.49","0.026"],["1562.50","4.318"],["1666.60","1.193"],["1701.39","32.187"],["1704.86","32.357"],["1708.44","51.352"],["1710.34","29.258"],["1716.55","58.711"],["1733.91","3.661"],["1734.99","0.122"],["1735.17","0.047"],["1735.19","70.115"],["1735.20","48.803"],["1735.21","34.744"],["1735.31","33.978"],["1735.41","344.695"],["1735.76","11.416"],["1736.11","168.957"]],"a":[["1736.12","73.564"],["1736.13","9.832"],["1736.16","0.291"],["1736.19","0.101"],["1736.23","20.052"],["1736.31","17.453"],["1736.47","7.812"],["1736.65","17.640"],["1736.70","11.247"],["1737.12","7.826"],["1737.77","17.434"],["1738.03","0.000"],["1738.97","185.116"],["1747.12","15.000"],["2634.46","0.001"],["2634.55","0.000"]],"st":1}}
{"schema_version":"1.3.0","event_id":"7f74313c-a23e-4c28-bcee-d00267ed6f74","event_type":"raw.depth_update","source":"binance_market_data_recorder","venue":"binance_usdm","market_type":"perpetual_futures","symbol":"BTCUSDT","event_time_ms":1783517070068,"received_time_ms":1783517070063,"trace_id":"7dd00f11-dd63-4216-901e-f57021502acf","first_update_id":10999770887370,"final_update_id":10999770894683,"previous_final_update_id":10999770887268,"bids":[{"price":"1000.00","quantity":"207.692"},{"price":"11353.70","quantity":"0.238"},{"price":"11553.70","quantity":"1.248"},{"price":"11653.70","quantity":"1.952"},{"price":"11753.70","quantity":"1.462"},{"price":"55668.30","quantity":"0.002"},{"price":"58761.00","quantity":"0.012"},{"price":"59379.50","quantity":"0.001"},{"price":"60615.20","quantity":"0.000"},{"price":"61173.30","quantity":"0.256"},{"price":"61235.20","quantity":"0.025"},{"price":"61723.20","quantity":"0.513"},{"price":"61811.10","quantity":"0.016"},{"price":"61811.60","quantity":"0.170"},{"price":"61821.10","quantity":"0.561"},{"price":"61832.30","quantity":"0.002"},{"price":"61837.00","quantity":"0.002"},{"price":"61838.20","quantity":"0.609"},{"price":"61842.60","quantity":"0.081"}],"asks":[{"price":"61859.70","quantity":"0.127"},{"price":"61860.00","quantity":"0.595"},{"price":"61861.40","quantity":"0.167"},{"price":"61863.70","quantity":"0.250"},{"price":"61864.90","quantity":"0.054"},{"price":"61866.20","quantity":"0.570"},{"price":"61868.20","quantity":"0.064"},{"price":"61868.60","quantity":"0.004"},{"price":"61872.40","quantity":"0.007"},{"price":"61889.70","quantity":"0.157"},{"price":"61890.20","quantity":"0.022"},{"price":"61909.00","quantity":"0.032"},{"price":"61909.20","quantity":"0.176"},{"price":"61970.90","quantity":"0.007"},{"price":"61985.60","quantity":"0.806"},{"price":"62465.90","quantity":"0.000"},{"price":"62472.30","quantity":"0.000"},{"price":"63036.60","quantity":"0.000"}],"raw":{"e":"depthUpdate","E":1783517070068,"T":1783517070065,"s":"BTCUSDT","ps":"BTCUSDT","U":10999770887370,"u":10999770894683,"pu":10999770887268,"b":[["1000.00","207.692"],["11353.70","0.238"],["11553.70","1.248"],["11653.70","1.952"],["11753.70","1.462"],["55668.30","0.002"],["58761.00","0.012"],["59379.50","0.001"],["60615.20","0.000"],["61173.30","0.256"],["61235.20","0.025"],["61723.20","0.513"],["61811.10","0.016"],["61811.60","0.170"],["61821.10","0.561"],["61832.30","0.002"],["61837.00","0.002"],["61838.20","0.609"],["61842.60","0.081"]],"a":[["61859.70","0.127"],["61860.00","0.595"],["61861.40","0.167"],["61863.70","0.250"],["61864.90","0.054"],["61866.20","0.570"],["61868.20","0.064"],["61868.60","0.004"],["61872.40","0.007"],["61889.70","0.157"],["61890.20","0.022"],["61909.00","0.032"],["61909.20","0.176"],["61970.90","0.007"],["61985.60","0.806"],["62465.90","0.000"],["62472.30","0.000"],["63036.60","0.000"]],"st":1}}
{"schema_version":"1.3.0","event_id":"8ee887d0-f03b-4f80-ae55-ea3385c6fce5","event_type":"raw.trade","source":"binance_market_data_recorder","venue":"binance_usdm","market_type":"perpetual_futures","symbol":"BTCUSDT","event_time_ms":1783517070123,"received_time_ms":1783517070122,"trace_id":"399590dd-107a-4861-a3c7-f70b3c297a2b","trade_id":7881418084,"price":"61853.80","quantity":"0.031","trade_time_ms":1783517070123,"is_buyer_maker":false,"aggressor_side":"buy","raw":{"e":"trade","E":1783517070123,"T":1783517070123,"s":"BTCUSDT","t":7881418084,"p":"61853.80","q":"0.031","X":"MARKET","m":false,"st":1}}
{"schema_version":"1.3.0","event_id":"b63f7c63-3d26-4b8b-828c-4c7fed2baa20","event_type":"raw.trade","source":"binance_market_data_recorder","venue":"binance_usdm","market_type":"perpetual_futures","symbol":"BTCUSDT","event_time_ms":1783517070123,"received_time_ms":1783517070123,"trace_id":"087461a3-7503-4801-acff-9bdbab738ccc","trade_id":7881418085,"price":"61853.80","quantity":"0.001","trade_time_ms":1783517070123,"is_buyer_maker":false,"aggressor_side":"buy","raw":{"e":"trade","E":1783517070123,"T":1783517070123,"s":"BTCUSDT","t":7881418085,"p":"61853.80","q":"0.001","X":"MARKET","m":false,"st":1}}
{"schema_version":"1.3.0","event_id":"821e6ff9-0ec3-491a-84b7-577c079f8ccf","event_type":"raw.trade","source":"binance_market_data_recorder","venue":"binance_usdm","market_type":"perpetual_futures","symbol":"BTCUSDT","event_time_ms":1783517070123,"received_time_ms":1783517070123,"trace_id":"3968810c-5062-4c20-b5b7-9a8dfc0456b3","trade_id":7881418086,"price":"61853.80","quantity":"0.001","trade_time_ms":1783517070123,"is_buyer_maker":false,"aggressor_side":"buy","raw":{"e":"trade","E":1783517070123,"T":1783517070123,"s":"BTCUSDT","t":7881418086,"p":"61853.80","q":"0.001","X":"MARKET","m":false,"st":1}}
{"schema_version":"1.3.0","event_id":"789906b2-5c46-4008-ba25-fde5e231f825","event_type":"raw.trade","source":"binance_market_data_recorder","venue":"binance_usdm","market_type":"perpetual_futures","symbol":"BTCUSDT","event_time_ms":1783517070123,"received_time_ms":1783517070124,"trace_id":"c1a5536b-8cf5-41b1-9691-68e03dc2f05c","trade_id":7881418087,"price":"61853.80","quantity":"0.001","trade_time_ms":1783517070123,"is_buyer_maker":false,"aggressor_side":"buy","raw":{"e":"trade","E":1783517070123,"T":1783517070123,"s":"BTCUSDT","t":7881418087,"p":"61853.80","q":"0.001","X":"MARKET","m":false,"st":1}}
{"schema_version":"1.3.0","event_id":"b531ef94-747d-4e41-9ad4-26f093565bd1","event_type":"raw.trade","source":"binance_market_data_recorder","venue":"binance_usdm","market_type":"perpetual_futures","symbol":"BTCUSDT","event_time_ms":1783517070123,"received_time_ms":1783517070124,"trace_id":"14556354-d82f-4d67-95b9-4f895de11723","trade_id":7881418088,"price":"61853.80","quantity":"0.001","trade_time_ms":1783517070123,"is_buyer_maker":false,"aggressor_side":"buy","raw":{"e":"trade","E":1783517070123,"T":1783517070123,"s":"BTCUSDT","t":7881418088,"p":"61853.80","q":"0.001","X":"MARKET","m":false,"st":1}}
{"schema_version":"1.3.0","event_id":"b0e553dc-19fd-4f7e-b75e-17624285db79","event_type":"raw.trade","source":"binance_market_data_recorder","venue":"binance_usdm","market_type":"perpetual_futures","symbol":"BTCUSDT","event_time_ms":1783517070123,"received_time_ms":1783517070126,"trace_id":"f6cb8258-92a3-4a11-a857-eecb39b76fb5","trade_id":7881418089,"price":"61853.80","quantity":"0.001","trade_time_ms":1783517070123,"is_buyer_maker":false,"aggressor_side":"buy","raw":{"e":"trade","E":1783517070123,"T":1783517070123,"s":"BTCUSDT","t":7881418089,"p":"61853.80","q":"0.001","X":"MARKET","m":false,"st":1}}
{"schema_version":"1.3.0","event_id":"7eb2055f-e85c-47e3-bc6e-a6785455a0b9","event_type":"raw.trade","source":"binance_market_data_recorder","venue":"binance_usdm","market_type":"perpetual_futures","symbol":"BTCUSDT","event_time_ms":1783517070123,"received_time_ms":1783517070131,"trace_id":"01ab0555-e94a-4f54-b01f-3c1a460fb866","trade_id":7881418090,"price":"61853.80","quantity":"0.001","trade_time_ms":1783517070123,"is_buyer_maker":false,"aggressor_side":"buy","raw":{"e":"trade","E":1783517070123,"T":1783517070123,"s":"BTCUSDT","t":7881418090,"p":"61853.80","q":"0.001","X":"MARKET","m":false,"st":1}}
{"schema_version":"1.3.0","event_id":"833ef94e-8dd5-4b5d-9f3a-0c065aec6b84","event_type":"raw.trade","source":"binance_market_data_recorder","venue":"binance_usdm","market_type":"perpetual_futures","symbol":"BTCUSDT","event_time_ms":1783517070123,"received_time_ms":1783517070134,"trace_id":"b86e56b2-2990-457a-ba6c-62f56b4c46fd","trade_id":7881418091,"price":"61853.80","quantity":"0.001","trade_time_ms":1783517070123,"is_buyer_maker":false,"aggressor_side":"buy","raw":{"e":"trade","E":1783517070123,"T":1783517070123,"s":"BTCUSDT","t":7881418091,"p":"61853.80","q":"0.001","X":"MARKET","m":false,"st":1}}
{"schema_version":"1.3.0","event_id":"35ef6dd7-f4bc-4bb4-a3b1-0bc00dec1786","event_type":"raw.trade","source":"binance_market_data_recorder","venue":"binance_usdm","market_type":"perpetual_futures","symbol":"BTCUSDT","event_time_ms":1783517070123,"received_time_ms":1783517070134,"trace_id":"7cff2151-6782-455f-881f-bb7ac630ca34","trade_id":7881418092,"price":"61853.80","quantity":"0.323","trade_time_ms":1783517070123,"is_buyer_maker":false,"aggressor_side":"buy","raw":{"e":"trade","E":1783517070123,"T":1783517070123,"s":"BTCUSDT","t":7881418092,"p":"61853.80","q":"0.323","X":"MARKET","m":false,"st":1}}
{"schema_version":"1.3.0","event_id":"87915b18-5d36-46a6-a1d6-c6306b873b9c","event_type":"raw.trade","source":"binance_market_data_recorder","venue":"binance_usdm","market_type":"perpetual_futures","symbol":"BTCUSDT","event_time_ms":1783517070123,"received_time_ms":1783517070135,"trace_id":"c065ba82-e9fb-412f-9a10-8f1a16727075","trade_id":7881418093,"price":"61853.80","quantity":"0.005","trade_time_ms":1783517070123,"is_buyer_maker":false,"aggressor_side":"buy","raw":{"e":"trade","E":1783517070123,"T":1783517070123,"s":"BTCUSDT","t":7881418093,"p":"61853.80","q":"0.005","X":"MARKET","m":false,"st":1}}
{"schema_version":"1.3.0","event_id":"52df144e-8d59-4e06-b7d7-fe7e2c7316ab","event_type":"raw.trade","source":"binance_market_data_recorder","venue":"binance_usdm","market_type":"perpetual_futures","symbol":"BTCUSDT","event_time_ms":1783517070123,"received_time_ms":1783517070135,"trace_id":"f555db08-c6f6-49a2-a864-74b4496d199e","trade_id":7881418094,"price":"61853.80","quantity":"0.004","trade_time_ms":1783517070123,"is_buyer_maker":false,"aggressor_side":"buy","raw":{"e":"trade","E":1783517070123,"T":1783517070123,"s":"BTCUSDT","t":7881418094,"p":"61853.80","q":"0.004","X":"MARKET","m":false,"st":1}}
{"schema_version":"1.3.0","event_id":"a0056fda-32e9-4641-a3c2-9d97bb4a0781","event_type":"raw.trade","source":"binance_market_data_recorder","venue":"binance_usdm","market_type":"perpetual_futures","symbol":"BTCUSDT","event_time_ms":1783517070123,"received_time_ms":1783517070136,"trace_id":"a74bbabb-1b03-4c7f-a9c8-7608e70d7308","trade_id":7881418095,"price":"61853.80","quantity":"0.043","trade_time_ms":1783517070123,"is_buyer_maker":false,"aggressor_side":"buy","raw":{"e":"trade","E":1783517070123,"T":1783517070123,"s":"BTCUSDT","t":7881418095,"p":"61853.80","q":"0.043","X":"MARKET","m":false,"st":1}}
{"schema_version":"1.3.0","event_id":"f9dd925b-9e04-4825-8300-181452a936f7","event_type":"raw.trade","source":"binance_market_data_recorder","venue":"binance_usdm","market_type":"perpetual_futures","symbol":"BTCUSDT","event_time_ms":1783517070123,"received_time_ms":1783517070136,"trace_id":"cb68e402-2092-427b-a274-88e7042b430a","trade_id":7881418096,"price":"61853.80","quantity":"0.040","trade_time_ms":1783517070123,"is_buyer_maker":false,"aggressor_side":"buy","raw":{"e":"trade","E":1783517070123,"T":1783517070123,"s":"BTCUSDT","t":7881418096,"p":"61853.80","q":"0.040","X":"MARKET","m":false,"st":1}}
{"schema_version":"1.3.0","event_id":"d284c7ea-8d01-435c-87ab-aa8730a702a0","event_type":"raw.trade","source":"binance_market_data_recorder","venue":"binance_usdm","market_type":"perpetual_futures","symbol":"BTCUSDT","event_time_ms":1783517070123,"received_time_ms":1783517070136,"trace_id":"31119e1d-46df-491b-9534-f5733e8751cd","trade_id":7881418097,"price":"61853.80","quantity":"0.001","trade_time_ms":1783517070123,"is_buyer_maker":false,"aggressor_side":"buy","raw":{"e":"trade","E":1783517070123,"T":1783517070123,"s":"BTCUSDT","t":7881418097,"p":"61853.80","q":"0.001","X":"MARKET","m":false,"st":1}}
{"schema_version":"1.3.0","event_id":"949d64cf-837e-4bc1-be93-cf8834530d8a","event_type":"raw.trade","source":"binance_market_data_recorder","venue":"binance_usdm","market_type":"perpetual_futures","symbol":"BTCUSDT","event_time_ms":1783517070123,"received_time_ms":1783517070137,"trace_id":"b29dcb9e-d6d1-41af-be51-1e2b61553fb3","trade_id":7881418098,"price":"61853.80","quantity":"0.008","trade_time_ms":1783517070123,"is_buyer_maker":false,"aggressor_side":"buy","raw":{"e":"trade","E":1783517070123,"T":1783517070123,"s":"BTCUSDT","t":7881418098,"p":"61853.80","q":"0.008","X":"MARKET","m":false,"st":1}}
{"schema_version":"1.3.0","event_id":"ffbd48e1-9f93-4118-babe-1bab3e59de8c","event_type":"raw.trade","source":"binance_market_data_recorder","venue":"binance_usdm","market_type":"perpetual_futures","symbol":"BTCUSDT","event_time_ms":1783517070123,"received_time_ms":1783517070137,"trace_id":"e6c6ccf0-e2aa-4503-8d7d-61f83b349feb","trade_id":7881418099,"price":"61853.80","quantity":"0.020","trade_time_ms":1783517070123,"is_buyer_maker":false,"aggressor_side":"buy","raw":{"e":"trade","E":1783517070123,"T":1783517070123,"s":"BTCUSDT","t":7881418099,"p":"61853.80","q":"0.020","X":"MARKET","m":false,"st":1}}
{"schema_version":"1.3.0","event_id":"6ad5bfba-7a0b-4ac2-8c3a-6f6fe305e0b7","event_type":"raw.trade","source":"binance_market_data_recorder","venue":"binance_usdm","market_type":"perpetual_futures","symbol":"BTCUSDT","event_time_ms":1783517070123,"received_time_ms":1783517070138,"trace_id":"1d363f8e-45f5-425f-bce1-59665335bffd","trade_id":7881418100,"price":"61853.80","quantity":"0.001","trade_time_ms":1783517070123,"is_buyer_maker":false,"aggressor_side":"buy","raw":{"e":"trade","E":1783517070123,"T":1783517070123,"s":"BTCUSDT","t":7881418100,"p":"61853.80","q":"0.001","X":"MARKET","m":false,"st":1}}
{"schema_version":"1.3.0","event_id":"ec75fd01-9260-4359-9df9-b2c509107049","event_type":"raw.trade","source":"binance_market_data_recorder","venue":"binance_usdm","market_type":"perpetual_futures","symbol":"BTCUSDT","event_time_ms":1783517070123,"received_time_ms":1783517070138,"trace_id":"d410c778-4870-4274-97f1-39409518fa1e","trade_id":7881418101,"price":"61853.80","quantity":"0.001","trade_time_ms":1783517070123,"is_buyer_maker":false,"aggressor_side":"buy","raw":{"e":"trade","E":1783517070123,"T":1783517070123,"s":"BTCUSDT","t":7881418101,"p":"61853.80","q":"0.001","X":"MARKET","m":false,"st":1}}
{"schema_version":"1.3.0","event_id":"c72684d9-ecf4-4f10-94b3-886ea3df35b2","event_type":"raw.trade","source":"binance_market_data_recorder","venue":"binance_usdm","market_type":"perpetual_futures","symbol":"BTCUSDT","event_time_ms":1783517070123,"received_time_ms":1783517070138,"trace_id":"93fbf4cb-192e-46fe-8452-241839ba4066","trade_id":7881418102,"price":"61853.80","quantity":"0.003","trade_time_ms":1783517070123,"is_buyer_maker":false,"aggressor_side":"buy","raw":{"e":"trade","E":1783517070123,"T":1783517070123,"s":"BTCUSDT","t":7881418102,"p":"61853.80","q":"0.003","X":"MARKET","m":false,"st":1}}
{"schema_version":"1.3.0","event_id":"bb08290e-57ef-4abc-980d-fcbb41260b85","event_type":"raw.trade","source":"binance_market_data_recorder","venue":"binance_usdm","market_type":"perpetual_futures","symbol":"BTCUSDT","event_time_ms":1783517070123,"received_time_ms":1783517070139,"trace_id":"4a510e6f-0952-4f03-a5c2-c203e27c7577","trade_id":7881418103,"price":"61853.80","quantity":"0.001","trade_time_ms":1783517070123,"is_buyer_maker":false,"aggressor_side":"buy","raw":{"e":"trade","E":1783517070123,"T":1783517070123,"s":"BTCUSDT","t":7881418103,"p":"61853.80","q":"0.001","X":"MARKET","m":false,"st":1}}
{"schema_version":"1.3.0","event_id":"fe7b571b-740b-4254-b68e-d75c0ebbfad5","event_type":"raw.trade","source":"binance_market_data_recorder","venue":"binance_usdm","market_type":"perpetual_futures","symbol":"BTCUSDT","event_time_ms":1783517070123,"received_time_ms":1783517070139,"trace_id":"dcc5405e-29ed-43f1-8460-b7fdb26bcf0e","trade_id":7881418104,"price":"61853.80","quantity":"0.001","trade_time_ms":1783517070123,"is_buyer_maker":false,"aggressor_side":"buy","raw":{"e":"trade","E":1783517070123,"T":1783517070123,"s":"BTCUSDT","t":7881418104,"p":"61853.80","q":"0.001","X":"MARKET","m":false,"st":1}}
{"schema_version":"1.3.0","event_id":"9f3158fa-cdcb-41a1-a6e3-1a006de1aa98","event_type":"raw.trade","source":"binance_market_data_recorder","venue":"binance_usdm","market_type":"perpetual_futures","symbol":"BTCUSDT","event_time_ms":1783517070123,"received_time_ms":1783517070139,"trace_id":"fb49eebb-1b8e-4334-86f9-68bfcc064951","trade_id":7881418105,"price":"61853.80","quantity":"0.014","trade_time_ms":1783517070123,"is_buyer_maker":false,"aggressor_side":"buy","raw":{"e":"trade","E":1783517070123,"T":1783517070123,"s":"BTCUSDT","t":7881418105,"p":"61853.80","q":"0.014","X":"MARKET","m":false,"st":1}}
{"schema_version":"1.3.0","event_id":"cebf21e4-053a-411c-bb61-a0c2433c9bde","event_type":"raw.trade","source":"binance_market_data_recorder","venue":"binance_usdm","market_type":"perpetual_futures","symbol":"BTCUSDT","event_time_ms":1783517070123,"received_time_ms":1783517070140,"trace_id":"db047bc6-3df5-455b-8611-aaedf6e576c8","trade_id":7881418106,"price":"61853.80","quantity":"0.320","trade_time_ms":1783517070123,"is_buyer_maker":false,"aggressor_side":"buy","raw":{"e":"trade","E":1783517070123,"T":1783517070123,"s":"BTCUSDT","t":7881418106,"p":"61853.80","q":"0.320","X":"MARKET","m":false,"st":1}}
{"schema_version":"1.3.0","event_id":"99823787-e6cd-49cd-9795-181573c68e6c","event_type":"raw.trade","source":"binance_market_data_recorder","venue":"binance_usdm","market_type":"perpetual_futures","symbol":"BTCUSDT","event_time_ms":1783517070123,"received_time_ms":1783517070140,"trace_id":"7c7ca05b-fa2d-459d-8973-a821fc087fba","trade_id":7881418107,"price":"61853.80","quantity":"0.001","trade_time_ms":1783517070123,"is_buyer_maker":false,"aggressor_side":"buy","raw":{"e":"trade","E":1783517070123,"T":1783517070123,"s":"BTCUSDT","t":7881418107,"p":"61853.80","q":"0.001","X":"MARKET","m":false,"st":1}}
{"schema_version":"1.3.0","event_id":"b4126587-5c3b-4dab-927e-cdbbc93519ae","event_type":"raw.trade","source":"binance_market_data_recorder","venue":"binance_usdm","market_type":"perpetual_futures","symbol":"BTCUSDT","event_time_ms":1783517070123,"received_time_ms":1783517070140,"trace_id":"b6be2c73-f768-459d-b5bf-e4a1491321c2","trade_id":7881418108,"price":"61853.80","quantity":"0.096","trade_time_ms":1783517070123,"is_buyer_maker":false,"aggressor_side":"buy","raw":{"e":"trade","E":1783517070123,"T":1783517070123,"s":"BTCUSDT","t":7881418108,"p":"61853.80","q":"0.096","X":"MARKET","m":false,"st":1}}
{"schema_version":"1.3.0","event_id":"be9330c5-7167-49bf-bbd4-853029e4cec3","event_type":"raw.trade","source":"binance_market_data_recorder","venue":"binance_usdm","market_type":"perpetual_futures","symbol":"BTCUSDT","event_time_ms":1783517070127,"received_time_ms":1783517070151,"trace_id":"6963e8a1-14ab-4507-85a6-179e2c6ca5f0","trade_id":7881418109,"price":"61853.80","quantity":"0.009","trade_time_ms":1783517070127,"is_buyer_maker":false,"aggressor_side":"buy","raw":{"e":"trade","E":1783517070127,"T":1783517070127,"s":"BTCUSDT","t":7881418109,"p":"61853.80","q":"0.009","X":"MARKET","m":false,"st":1}}
{"schema_version":"1.3.0","event_id":"cd76dc1b-7d6c-491e-91fc-84c80a9528b8","event_type":"raw.trade","source":"binance_market_data_recorder","venue":"binance_usdm","market_type":"perpetual_futures","symbol":"BTCUSDT","event_time_ms":1783517070127,"received_time_ms":1783517070152,"trace_id":"d6cfbf09-116e-4f60-bc2a-95d34fb24168","trade_id":7881418110,"price":"61853.80","quantity":"0.001","trade_time_ms":1783517070127,"is_buyer_maker":false,"aggressor_side":"buy","raw":{"e":"trade","E":1783517070127,"T":1783517070127,"s":"BTCUSDT","t":7881418110,"p":"61853.80","q":"0.001","X":"MARKET","m":false,"st":1}}
{"schema_version":"1.3.0","event_id":"ec02c839-7f45-4bc9-8d84-7c70555a4d20","event_type":"raw.trade","source":"binance_market_data_recorder","venue":"binance_usdm","market_type":"perpetual_futures","symbol":"BTCUSDT","event_time_ms":1783517070127,"received_time_ms":1783517070152,"trace_id":"041dcbe0-8b11-400c-aa5d-62abf3d418b0","trade_id":7881418111,"price":"61853.80","quantity":"0.002","trade_time_ms":1783517070127,"is_buyer_maker":false,"aggressor_side":"buy","raw":{"e":"trade","E":1783517070127,"T":1783517070127,"s":"BTCUSDT","t":7881418111,"p":"61853.80","q":"0.002","X":"MARKET","m":false,"st":1}}
{"schema_version":"1.3.0","event_id":"e1207710-a9ff-4bcb-a48c-a145a2611a40","event_type":"raw.trade","source":"binance_market_data_recorder","venue":"binance_usdm","market_type":"perpetual_futures","symbol":"BTCUSDT","event_time_ms":1783517070127,"received_time_ms":1783517070152,"trace_id":"47d552ed-756b-47b6-8893-498086be28db","trade_id":7881418112,"price":"61853.80","quantity":"0.020","trade_time_ms":1783517070127,"is_buyer_maker":false,"aggressor_side":"buy","raw":{"e":"trade","E":1783517070127,"T":1783517070127,"s":"BTCUSDT","t":7881418112,"p":"61853.80","q":"0.020","X":"MARKET","m":false,"st":1}}
{"schema_version":"1.3.0","event_id":"95a47c4e-d88b-4a62-b425-02c8dcd68620","event_type":"raw.trade","source":"binance_market_data_recorder","venue":"binance_usdm","market_type":"perpetual_futures","symbol":"BTCUSDT","event_time_ms":1783517070127,"received_time_ms":1783517070153,"trace_id":"06d54d47-8199-481a-b5df-38b7ce4808c6","trade_id":7881418113,"price":"61853.80","quantity":"0.001","trade_time_ms":1783517070127,"is_buyer_maker":false,"aggressor_side":"buy","raw":{"e":"trade","E":1783517070127,"T":1783517070127,"s":"BTCUSDT","t":7881418113,"p":"61853.80","q":"0.001","X":"MARKET","m":false,"st":1}}
{"schema_version":"1.3.0","event_id":"8a615f81-dc57-47cd-92ba-8817a4620924","event_type":"raw.trade","source":"binance_market_data_recorder","venue":"binance_usdm","market_type":"perpetual_futures","symbol":"BTCUSDT","event_time_ms":1783517070127,"received_time_ms":1783517070154,"trace_id":"f441b6e8-fb8c-4a63-a494-46f30fbd2545","trade_id":7881418114,"price":"61853.90","quantity":"0.001","trade_time_ms":1783517070127,"is_buyer_maker":false,"aggressor_side":"buy","raw":{"e":"trade","E":1783517070127,"T":1783517070127,"s":"BTCUSDT","t":7881418114,"p":"61853.90","q":"0.001","X":"MARKET","m":false,"st":1}}
{"schema_version":"1.3.0","event_id":"6b321677-b2c5-488c-a6b0-31528bbf5fe3","event_type":"raw.trade","source":"binance_market_data_recorder","venue":"binance_usdm","market_type":"perpetual_futures","symbol":"BTCUSDT","event_time_ms":1783517070127,"received_time_ms":1783517070154,"trace_id":"5da7f192-4d7a-4cb9-a21d-2d6ec7fd86dd","trade_id":7881418115,"price":"61853.90","quantity":"0.001","trade_time_ms":1783517070127,"is_buyer_maker":false,"aggressor_side":"buy","raw":{"e":"trade","E":1783517070127,"T":1783517070127,"s":"BTCUSDT","t":7881418115,"p":"61853.90","q":"0.001","X":"MARKET","m":false,"st":1}}
{"schema_version":"1.3.0","event_id":"5161edfe-460b-4626-8f25-bd19fc81f140","event_type":"raw.trade","source":"binance_market_data_recorder","venue":"binance_usdm","market_type":"perpetual_futures","symbol":"BTCUSDT","event_time_ms":1783517070127,"received_time_ms":1783517070155,"trace_id":"248eddc1-f84d-4eb7-9d3e-8084cd417c84","trade_id":7881418116,"price":"61853.90","quantity":"0.001","trade_time_ms":1783517070127,"is_buyer_maker":false,"aggressor_side":"buy","raw":{"e":"trade","E":1783517070127,"T":1783517070127,"s":"BTCUSDT","t":7881418116,"p":"61853.90","q":"0.001","X":"MARKET","m":false,"st":1}}
{"schema_version":"1.3.0","event_id":"51248b7c-5f02-4c80-a7a1-051cae3600bb","event_type":"raw.trade","source":"binance_market_data_recorder","venue":"binance_usdm","market_type":"perpetual_futures","symbol":"BTCUSDT","event_time_ms":1783517070127,"received_time_ms":1783517070155,"trace_id":"6a53c324-06c5-4400-bf97-5030fa3f6d11","trade_id":7881418117,"price":"61853.90","quantity":"0.003","trade_time_ms":1783517070127,"is_buyer_maker":false,"aggressor_side":"buy","raw":{"e":"trade","E":1783517070127,"T":1783517070127,"s":"BTCUSDT","t":7881418117,"p":"61853.90","q":"0.003","X":"MARKET","m":false,"st":1}}
{"schema_version":"1.3.0","event_id":"aaa2b730-b273-430a-b084-5b97ed4020e8","event_type":"raw.trade","source":"binance_market_data_recorder","venue":"binance_usdm","market_type":"perpetual_futures","symbol":"BTCUSDT","event_time_ms":1783517070128,"received_time_ms":1783517070156,"trace_id":"fed3320d-d490-43a1-beb4-263fb8e7abcc","trade_id":7881418118,"price":"61854.00","quantity":"0.001","trade_time_ms":1783517070127,"is_buyer_maker":false,"aggressor_side":"buy","raw":{"e":"trade","E":1783517070128,"T":1783517070127,"s":"BTCUSDT","t":7881418118,"p":"61854.00","q":"0.001","X":"MARKET","m":false,"st":1}}
{"schema_version":"1.3.0","event_id":"5feaf325-5783-4275-a0d8-6cd94f37be84","event_type":"raw.trade","source":"binance_market_data_recorder","venue":"binance_usdm","market_type":"perpetual_futures","symbol":"BTCUSDT","event_time_ms":1783517070130,"received_time_ms":1783517070194,"trace_id":"ff70b3a2-a136-48f3-903f-3ce30f26a42a","trade_id":7881418119,"price":"61854.20","quantity":"0.013","trade_time_ms":1783517070130,"is_buyer_maker":false,"aggressor_side":"buy","raw":{"e":"trade","E":1783517070130,"T":1783517070130,"s":"BTCUSDT","t":7881418119,"p":"61854.20","q":"0.013","X":"MARKET","m":false,"st":1}}
{"schema_version":"1.3.0","event_id":"b90323e7-246e-467f-8a13-f6f471221789","event_type":"raw.trade","source":"binance_market_data_recorder","venue":"binance_usdm","market_type":"perpetual_futures","symbol":"BTCUSDT","event_time_ms":1783517070130,"received_time_ms":1783517070195,"trace_id":"41db0d33-ea26-4fdd-85c9-fec1aefd27c9","trade_id":7881418120,"price":"61854.20","quantity":"0.009","trade_time_ms":1783517070130,"is_buyer_maker":false,"aggressor_side":"buy","raw":{"e":"trade","E":1783517070130,"T":1783517070130,"s":"BTCUSDT","t":7881418120,"p":"61854.20","q":"0.009","X":"MARKET","m":false,"st":1}}
{"schema_version":"1.3.0","event_id":"b5ae8ab7-da55-42a8-a57e-59cc6169b301","event_type":"raw.trade","source":"binance_market_data_recorder","venue":"binance_usdm","market_type":"perpetual_futures","symbol":"BTCUSDT","event_time_ms":1783517070130,"received_time_ms":1783517070195,"trace_id":"e13885fd-00bd-4c76-ad7a-b8797422e892","trade_id":7881418121,"price":"61854.20","quantity":"0.002","trade_time_ms":1783517070130,"is_buyer_maker":false,"aggressor_side":"buy","raw":{"e":"trade","E":1783517070130,"T":1783517070130,"s":"BTCUSDT","t":7881418121,"p":"61854.20","q":"0.002","X":"MARKET","m":false,"st":1}}
{"schema_version":"1.3.0","event_id":"37ea3425-7745-4624-b905-2b7b358e5531","event_type":"raw.depth_update","source":"binance_market_data_recorder","venue":"binance_usdm","market_type":"perpetual_futures","symbol":"ETHUSDT","event_time_ms":1783517070142,"received_time_ms":1783517070283,"trace_id":"1bbeaf40-54ac-4f36-bd44-39aecba4db17","first_update_id":10999770892579,"final_update_id":10999770904137,"previous_final_update_id":10999770892193,"bids":[{"price":"200.00","quantity":"7.594"},{"price":"1221.11","quantity":"0.832"},{"price":"1226.11","quantity":"7.136"},{"price":"1231.11","quantity":"1.632"},{"price":"1562.49","quantity":"0.026"},{"price":"1562.50","quantity":"4.446"},{"price":"1705.46","quantity":"0.630"},{"price":"1708.35","quantity":"29.229"},{"price":"1715.55","quantity":"1.510"},{"price":"1720.65","quantity":"40.932"},{"price":"1732.41","quantity":"7.697"},{"price":"1733.65","quantity":"9.919"},{"price":"1733.66","quantity":"92.522"},{"price":"1733.72","quantity":"3.365"},{"price":"1733.91","quantity":"0.465"},{"price":"1733.93","quantity":"5.192"},{"price":"1734.06","quantity":"473.253"},{"price":"1734.18","quantity":"0.012"},{"price":"1734.95","quantity":"8.702"},{"price":"1735.11","quantity":"45.389"},{"price":"1735.13","quantity":"3.243"},{"price":"1735.26","quantity":"10.582"},{"price":"1735.41","quantity":"124.169"},{"price":"1735.44","quantity":"248.413"},{"price":"1735.48","quantity":"3.753"},{"price":"1735.51","quantity":"50.796"},{"price":"1735.65","quantity":"20.560"},{"price":"1735.76","quantity":"11.272"},{"price":"1735.86","quantity":"68.396"},{"price":"1735.99","quantity":"1.291"},{"price":"1736.01","quantity":"8.698"},{"price":"1736.08","quantity":"2.549"},{"price":"1736.11","quantity":"168.957"}],"asks":[{"price":"1736.12","quantity":"63.189"},{"price":"1736.13","quantity":"9.913"},{"price":"1736.17","quantity":"0.024"},{"price":"1736.23","quantity":"0.052"},{"price":"1736.25","quantity":"22.810"},{"price":"1736.28","quantity":"14.688"},{"price":"1736.29","quantity":"1.210"},{"price":"1736.31","quantity":"17.366"},{"price":"1736.32","quantity":"0.143"},{"price":"1736.33","quantity":"2.887"},{"price":"1736.37","quantity":"17.261"},{"price":"1736.38","quantity":"10.173"},{"price":"1736.42","quantity":"8.297"},{"price":"1736.47","quantity":"7.668"},{"price":"1736.60","quantity":"5.137"},{"price":"1736.67","quantity":"3.518"},{"price":"1736.74","quantity":"24.750"},{"price":"1736.87","quantity":"26.347"},{"price":"1736.88","quantity":"12.332"},{"price":"1737.03","quantity":"83.757"},{"price":"1737.09","quantity":"38.747"},{"price":"1737.18","quantity":"22.765"},{"price":"1737.24","quantity":"3.141"},{"price":"1737.39","quantity":"3.266"},{"price":"1738.00","quantity":"30.932"},{"price":"1738.07","quantity":"32.889"},{"price":"1738.25","quantity":"411.712"},{"price":"1738.96","quantity":"3.196"},{"price":"1738.98","quantity":"40.552"},{"price":"1743.35","quantity":"18.586"},{"price":"1762.88","quantity":"1304.330"},{"price":"1763.89","quantity":"19.842"},{"price":"2634.44","quantity":"0.001"},{"price":"2634.45","quantity":"0.001"},{"price":"2634.53","quantity":"0.000"},{"price":"2634.54","quantity":"0.000"}],"raw":{"e":"depthUpdate","E":1783517070142,"T":1783517070141,"s":"ETHUSDT","ps":"ETHUSDT","U":10999770892579,"u":10999770904137,"pu":10999770892193,"b":[["200.00","7.594"],["1221.11","0.832"],["1226.11","7.136"],["1231.11","1.632"],["1562.49","0.026"],["1562.50","4.446"],["1705.46","0.630"],["1708.35","29.229"],["1715.55","1.510"],["1720.65","40.932"],["1732.41","7.697"],["1733.65","9.919"],["1733.66","92.522"],["1733.72","3.365"],["1733.91","0.465"],["1733.93","5.192"],["1734.06","473.253"],["1734.18","0.012"],["1734.95","8.702"],["1735.11","45.389"],["1735.13","3.243"],["1735.26","10.582"],["1735.41","124.169"],["1735.44","248.413"],["1735.48","3.753"],["1735.51","50.796"],["1735.65","20.560"],["1735.76","11.272"],["1735.86","68.396"],["1735.99","1.291"],["1736.01","8.698"],["1736.08","2.549"],["1736.11","168.957"]],"a":[["1736.12","63.189"],["1736.13","9.913"],["1736.17","0.024"],["1736.23","0.052"],["1736.25","22.810"],["1736.28","14.688"],["1736.29","1.210"],["1736.31","17.366"],["1736.32","0.143"],["1736.33","2.887"],["1736.37","17.261"],["1736.38","10.173"],["1736.42","8.297"],["1736.47","7.668"],["1736.60","5.137"],["1736.67","3.518"],["1736.74","24.750"],["1736.87","26.347"],["1736.88","12.332"],["1737.03","83.757"],["1737.09","38.747"],["1737.18","22.765"],["1737.24","3.141"],["1737.39","3.266"],["1738.00","30.932"],["1738.07","32.889"],["1738.25","411.712"],["1738.96","3.196"],["1738.98","40.552"],["1743.35","18.586"],["1762.88","1304.330"],["1763.89","19.842"],["2634.44","0.001"],["2634.45","0.001"],["2634.53","0.000"],["2634.54","0.000"]],"st":1}}
{"schema_version":"1.3.0","event_id":"41e7d0c8-6e72-4b5d-97bb-361972f980ec","event_type":"raw.trade","source":"binance_market_data_recorder","venue":"binance_usdm","market_type":"perpetual_futures","symbol":"ETHUSDT","event_time_ms":1783517070154,"received_time_ms":1783517070284,"trace_id":"4925ca7f-9946-4c12-a7ce-1f8cf68cfa8c","trade_id":8429826929,"price":"1736.12","quantity":"0.012","trade_time_ms":1783517070154,"is_buyer_maker":false,"aggressor_side":"buy","raw":{"e":"trade","E":1783517070154,"T":1783517070154,"s":"ETHUSDT","t":8429826929,"p":"1736.12","q":"0.012","X":"MARKET","m":false,"st":1}}
{"schema_version":"1.3.0","event_id":"1486eb2e-c89b-4eae-875d-e9847e12e7b1","event_type":"raw.trade","source":"binance_market_data_recorder","venue":"binance_usdm","market_type":"perpetual_futures","symbol":"ETHUSDT","event_time_ms":1783517070154,"received_time_ms":1783517070284,"trace_id":"537521ae-5c73-46bd-902b-d3ed5da3a7ed","trade_id":8429826930,"price":"1736.12","quantity":"0.012","trade_time_ms":1783517070154,"is_buyer_maker":false,"aggressor_side":"buy","raw":{"e":"trade","E":1783517070154,"T":1783517070154,"s":"ETHUSDT","t":8429826930,"p":"1736.12","q":"0.012","X":"MARKET","m":false,"st":1}}
{"schema_version":"1.3.0","event_id":"36c75077-f0c8-408e-8c1e-167072e52a9f","event_type":"raw.trade","source":"binance_market_data_recorder","venue":"binance_usdm","market_type":"perpetual_futures","symbol":"ETHUSDT","event_time_ms":1783517070154,"received_time_ms":1783517070285,"trace_id":"961d94d9-f132-4562-8120-c586fc22ea6f","trade_id":8429826931,"price":"1736.12","quantity":"0.079","trade_time_ms":1783517070154,"is_buyer_maker":false,"aggressor_side":"buy","raw":{"e":"trade","E":1783517070154,"T":1783517070154,"s":"ETHUSDT","t":8429826931,"p":"1736.12","q":"0.079","X":"MARKET","m":false,"st":1}}
{"schema_version":"1.3.0","event_id":"389adc10-1e6a-4346-96db-a83349e2e25b","event_type":"raw.depth_update","source":"binance_market_data_recorder","venue":"binance_usdm","market_type":"perpetual_futures","symbol":"BTCUSDT","event_time_ms":1783517070170,"received_time_ms":1783517070291,"trace_id":"6b13d940-864b-4963-8426-7d4b9bda234a","first_update_id":10999770894946,"final_update_id":10999770908242,"previous_final_update_id":10999770894683,"bids":[{"price":"11353.70","quantity":"0.085"},{"price":"11553.70","quantity":"1.424"},{"price":"11554.10","quantity":"0.096"},{"price":"11653.70","quantity":"1.680"},{"price":"11753.70","quantity":"1.547"},{"price":"11754.10","quantity":"0.068"},{"price":"55668.30","quantity":"0.000"},{"price":"55668.60","quantity":"0.002"},{"price":"58761.00","quantity":"0.012"},{"price":"60846.40","quantity":"0.001"},{"price":"60848.70","quantity":"0.010"},{"price":"60851.40","quantity":"0.000"},{"price":"60851.60","quantity":"0.020"},{"price":"60854.10","quantity":"0.013"},{"price":"60886.30","quantity":"0.009"},{"price":"60887.90","quantity":"3.457"},{"price":"60925.80","quantity":"0.407"},{"price":"60984.10","quantity":"8.595"},{"price":"61235.20","quantity":"0.025"},{"price":"61235.60","quantity":"0.328"},{"price":"61606.70","quantity":"2.973"},{"price":"61751.00","quantity":"0.201"},{"price":"61763.20","quantity":"33.581"},{"price":"61765.30","quantity":"0.072"},{"price":"61767.50","quantity":"2.323"},{"price":"61770.50","quantity":"0.003"},{"price":"61776.60","quantity":"0.000"},{"price":"61785.00","quantity":"0.001"},{"price":"61786.30","quantity":"0.002"},{"price":"61788.20","quantity":"1.290"},{"price":"61789.00","quantity":"1.492"},{"price":"61789.30","quantity":"0.000"},{"price":"61789.80","quantity":"0.002"},{"price":"61792.60","quantity":"0.000"},{"price":"61794.10","quantity":"0.008"},{"price":"61796.30","quantity":"0.211"},{"price":"61798.90","quantity":"0.000"},{"price":"61799.80","quantity":"1.071"},{"price":"61800.80","quantity":"0.119"},{"price":"61801.70","quantity":"0.000"},{"price":"61802.20","quantity":"0.003"},{"price":"61802.90","quantity":"0.823"},{"price":"61808.90","quantity":"0.108"},{"price":"61809.50","quantity":"0.063"},{"price":"61811.10","quantity":"0.016"},{"price":"61811.50","quantity":"0.115"},{"price":"61811.60","quantity":"0.069"},{"price":"61811.90","quantity":"0.001"},{"price":"61812.60","quantity":"0.033"},{"price":"61813.40","quantity":"0.062"},{"price":"61813.70","quantity":"1.381"},{"price":"61815.00","quantity":"1.415"},{"price":"61815.70","quantity":"0.103"},{"price":"61816.30","quantity":"0.491"},{"price":"61816.70","quantity":"0.055"},{"price":"61816.90","quantity":"0.015"},{"price":"61817.00","quantity":"0.002"},{"price":"61817.30","quantity":"1.771"},{"price":"61817.40","quantity":"0.105"},{"price":"61818.10","quantity":"0.253"},{"price":"61818.30","quantity":"0.000"},{"price":"61818.80","quantity":"0.292"},{"price":"61819.60","quantity":"0.003"},{"price":"61819.70","quantity":"0.000"},{"price":"61821.00","quantity":"1.009"},{"price":"61821.10","quantity":"0.803"},{"price":"61821.60","quantity":"0.004"},{"price":"61821.70","quantity":"1.088"},{"price":"61822.00","quantity":"0.121"},{"price":"61822.30","quantity":"0.002"},{"price":"61822.70","quantity":"0.013"},{"price":"61822.90","quantity":"0.003"},{"price":"61823.00","quantity":"2.166"},{"price":"61823.20","quantity":"0.515"},{"price":"61823.70","quantity":"1.294"},{"price":"61823.80","quantity":"0.150"},{"price":"61824.00","quantity":"0.340"},{"price":"61824.10","quantity":"0.002"},{"price":"61824.30","quantity":"0.197"},{"price":"61824.50","quantity":"0.421"},{"price":"61824.60","quantity":"0.110"},{"price":"61825.00","quantity":"1.335"},{"price":"61825.10","quantity":"0.360"},{"price":"61825.30","quantity":"0.003"},{"price":"61825.90","quantity":"0.093"},{"price":"61826.10","quantity":"1.245"},{"price":"61826.20","quantity":"0.191"},{"price":"61826.50","quantity":"0.958"},{"price":"61827.50","quantity":"2.168"},{"price":"61827.60","quantity":"0.007"},{"price":"61828.10","quantity":"0.008"},{"price":"61828.30","quantity":"0.583"},{"price":"61829.20","quantity":"0.293"},{"price":"61829.40","quantity":"2.288"},{"price":"61830.10","quantity":"0.122"},{"price":"61830.40","quantity":"0.130"},{"price":"61830.50","quantity":"0.000"},{"price":"61830.80","quantity":"0.001"},{"price":"61830.90","quantity":"0.001"},{"price":"61831.20","quantity":"0.060"},{"price":"61831.40","quantity":"0.436"},{"price":"61832.10","quantity":"0.114"},{"price":"61833.40","quantity":"0.007"},{"price":"61833.80","quantity":"0.968"},{"price":"61834.10","quantity":"2.900"},{"price":"61834.30","quantity":"0.704"},{"price":"61834.40","quantity":"0.124"},{"price":"61834.70","quantity":"0.013"},{"price":"61835.20","quantity":"0.002"},{"price":"61835.30","quantity":"0.320"},{"price":"61835.40","quantity":"0.001"},{"price":"61835.60","quantity":"0.139"},{"price":"61835.70","quantity":"0.003"},{"price":"61837.30","quantity":"0.803"},{"price":"61837.40","quantity":"0.811"},{"price":"61837.90","quantity":"1.646"},{"price":"61838.00","quantity":"1.002"},{"price":"61838.20","quantity":"0.325"},{"price":"61838.50","quantity":"0.012"},{"price":"61838.60","quantity":"0.000"},{"price":"61839.50","quantity":"0.128"},{"price":"61840.60","quantity":"0.696"},{"price":"61841.30","quantity":"0.105"},{"price":"61841.40","quantity":"0.951"},{"price":"61841.50","quantity":"0.221"},{"price":"61841.60","quantity":"0.053"},{"price":"61841.70","quantity":"0.518"},{"price":"61841.80","quantity":"0.085"},{"price":"61841.90","quantity":"0.384"},{"price":"61842.00","quantity":"0.069"},{"price":"61842.10","quantity":"0.001"},{"price":"61843.00","quantity":"0.001"},{"price":"61843.10","quantity":"0.010"},{"price":"61843.40","quantity":"0.062"},{"price":"61843.60","quantity":"0.899"},{"price":"61844.60","quantity":"0.037"},{"price":"61845.00","quantity":"0.009"},{"price":"61845.10","quantity":"0.123"},{"price":"61845.20","quantity":"0.323"},{"price":"61845.30","quantity":"0.005"},{"price":"61845.80","quantity":"0.000"},{"price":"61846.20","quantity":"0.101"},{"price":"61846.30","quantity":"0.001"},{"price":"61846.70","quantity":"0.016"},{"price":"61846.80","quantity":"0.564"},{"price":"61847.60","quantity":"0.008"},{"price":"61847.80","quantity":"0.004"},{"price":"61848.80","quantity":"0.002"},{"price":"61848.90","quantity":"0.004"},{"price":"61849.20","quantity":"0.002"},{"price":"61849.90","quantity":"0.004"},{"price":"61850.60","quantity":"0.287"},{"price":"61850.70","quantity":"0.002"},{"price":"61851.20","quantity":"0.001"},{"price":"61851.30","quantity":"0.002"},{"price":"61852.30","quantity":"0.007"},{"price":"61852.40","quantity":"0.000"},{"price":"61852.50","quantity":"0.001"},{"price":"61852.60","quantity":"0.001"},{"price":"61852.90","quantity":"0.006"},{"price":"61853.50","quantity":"0.004"},{"price":"61853.60","quantity":"0.002"},{"price":"61853.70","quantity":"0.418"},{"price":"61853.80","quantity":"1.800"},{"price":"61853.90","quantity":"0.598"},{"price":"61854.00","quantity":"0.005"},{"price":"61854.10","quantity":"23.111"}],"asks":[{"price":"61853.80","quantity":"0.000"},{"price":"61853.90","quantity":"0.000"},{"price":"61854.00","quantity":"0.000"},{"price":"61854.20","quantity":"1.501"},{"price":"61854.30","quantity":"0.025"},{"price":"61854.50","quantity":"0.027"},{"price":"61854.70","quantity":"0.369"},{"price":"61854.90","quantity":"0.016"},{"price":"61855.60","quantity":"0.023"},{"price":"61855.90","quantity":"0.000"},{"price":"61856.10","quantity":"0.000"},{"price":"61856.30","quantity":"0.030"},{"price":"61856.40","quantity":"0.029"},{"price":"61856.50","quantity":"0.000"},{"price":"61856.70","quantity":"0.001"},{"price":"61856.90","quantity":"0.220"},{"price":"61857.30","quantity":"1.001"},{"price":"61857.40","quantity":"0.005"},{"price":"61857.60","quantity":"0.051"},{"price":"61857.70","quantity":"0.249"},{"price":"61857.90","quantity":"0.005"},{"price":"61858.10","quantity":"0.089"},{"price":"61858.40","quantity":"0.001"},{"price":"61858.50","quantity":"0.614"},{"price":"61858.90","quantity":"0.053"},{"price":"61859.20","quantity":"0.010"},{"price":"61859.50","quantity":"0.084"},{"price":"61859.70","quantity":"0.127"},{"price":"61859.90","quantity":"1.616"},{"price":"61860.00","quantity":"0.176"},{"price":"61860.20","quantity":"0.589"},{"price":"61860.30","quantity":"0.306"},{"price":"61860.40","quantity":"0.180"},{"price":"61860.80","quantity":"0.029"},{"price":"61861.00","quantity":"0.412"},{"price":"61861.30","quantity":"0.372"},{"price":"61861.50","quantity":"0.554"},{"price":"61861.80","quantity":"0.161"},{"price":"61862.70","quantity":"2.747"},{"price":"61863.20","quantity":"0.001"},{"price":"61863.90","quantity":"0.308"},{"price":"61864.00","quantity":"2.153"},{"price":"61864.90","quantity":"0.050"},{"price":"61865.20","quantity":"0.016"},{"price":"61865.50","quantity":"0.045"},{"price":"61865.70","quantity":"0.472"},{"price":"61865.80","quantity":"0.968"},{"price":"61866.10","quantity":"0.000"},{"price":"61866.20","quantity":"0.002"},{"price":"61866.50","quantity":"0.570"},{"price":"61866.60","quantity":"3.356"},{"price":"61866.70","quantity":"0.732"},{"price":"61866.80","quantity":"1.292"},{"price":"61866.90","quantity":"0.018"},{"price":"61867.10","quantity":"0.081"},{"price":"61867.40","quantity":"0.061"},{"price":"61867.60","quantity":"0.345"},{"price":"61867.80","quantity":"0.083"},{"price":"61867.90","quantity":"0.584"},{"price":"61868.20","quantity":"0.048"},{"price":"61868.90","quantity":"0.148"},{"price":"61869.40","quantity":"0.007"},{"price":"61870.00","quantity":"0.329"},{"price":"61870.40","quantity":"0.038"},{"price":"61870.60","quantity":"0.242"},{"price":"61870.70","quantity":"2.147"},{"price":"61870.90","quantity":"0.133"},{"price":"61871.00","quantity":"0.020"},{"price":"61871.10","quantity":"0.046"},{"price":"61871.80","quantity":"0.001"},{"price":"61872.10","quantity":"0.019"},{"price":"61872.40","quantity":"0.003"},{"price":"61872.60","quantity":"0.204"},{"price":"61873.20","quantity":"0.004"},{"price":"61873.30","quantity":"0.205"},{"price":"61873.50","quantity":"0.005"},{"price":"61873.60","quantity":"0.043"},{"price":"61873.80","quantity":"1.290"},{"price":"61874.10","quantity":"0.823"},{"price":"61874.90","quantity":"0.122"},{"price":"61875.40","quantity":"0.051"},{"price":"61876.10","quantity":"0.485"},{"price":"61877.40","quantity":"0.063"},{"price":"61877.50","quantity":"0.002"},{"price":"61878.00","quantity":"2.200"},{"price":"61878.20","quantity":"0.046"},{"price":"61878.50","quantity":"0.004"},{"price":"61878.60","quantity":"1.040"},{"price":"61878.70","quantity":"0.032"},{"price":"61878.80","quantity":"0.001"},{"price":"61879.00","quantity":"0.173"},{"price":"61879.50","quantity":"0.412"},{"price":"61879.60","quantity":"0.000"},{"price":"61880.20","quantity":"0.100"},{"price":"61880.50","quantity":"0.004"},{"price":"61881.20","quantity":"0.181"},{"price":"61881.30","quantity":"0.771"},{"price":"61882.50","quantity":"0.000"},{"price":"61882.90","quantity":"1.756"},{"price":"61883.00","quantity":"0.290"},{"price":"61883.50","quantity":"0.937"},{"price":"61885.10","quantity":"0.121"},{"price":"61886.40","quantity":"0.003"},{"price":"61886.60","quantity":"2.136"},{"price":"61887.50","quantity":"0.005"},{"price":"61887.70","quantity":"0.050"},{"price":"61888.10","quantity":"0.170"},{"price":"61888.20","quantity":"0.001"},{"price":"61888.80","quantity":"0.125"},{"price":"61889.10","quantity":"1.024"},{"price":"61889.70","quantity":"0.052"},{"price":"61889.80","quantity":"0.121"},{"price":"61889.90","quantity":"0.000"},{"price":"61890.20","quantity":"0.022"},{"price":"61890.30","quantity":"0.941"},{"price":"61890.40","quantity":"1.471"},{"price":"61891.20","quantity":"0.379"},{"price":"61891.30","quantity":"0.330"},{"price":"61891.90","quantity":"0.042"},{"price":"61893.00","quantity":"0.000"},{"price":"61893.20","quantity":"0.207"},{"price":"61893.40","quantity":"0.099"},{"price":"61893.50","quantity":"0.000"},{"price":"61895.00","quantity":"2.587"},{"price":"61895.30","quantity":"0.929"},{"price":"61895.50","quantity":"0.036"},{"price":"61895.80","quantity":"0.030"},{"price":"61896.10","quantity":"0.061"},{"price":"61897.50","quantity":"0.296"},{"price":"61897.70","quantity":"0.012"},{"price":"61898.30","quantity":"3.274"},{"price":"61900.30","quantity":"0.007"},{"price":"61900.60","quantity":"1.403"},{"price":"61901.50","quantity":"2.205"},{"price":"61902.10","quantity":"0.010"},{"price":"61905.40","quantity":"0.031"},{"price":"61906.10","quantity":"0.069"},{"price":"61907.70","quantity":"0.427"},{"price":"61909.40","quantity":"0.002"},{"price":"61909.90","quantity":"0.376"},{"price":"61915.00","quantity":"2.059"},{"price":"61919.00","quantity":"0.166"},{"price":"61926.40","quantity":"12.130"},{"price":"61930.50","quantity":"2.138"},{"price":"61939.90","quantity":"0.296"},{"price":"62027.80","quantity":"0.000"},{"price":"62027.90","quantity":"0.004"},{"price":"62122.20","quantity":"0.018"},{"price":"62472.30","quantity":"0.338"},{"price":"62472.60","quantity":"0.009"},{"price":"62472.70","quantity":"0.080"},{"price":"62565.30","quantity":"1.898"},{"price":"62565.90","quantity":"10.482"},{"price":"62627.00","quantity":"0.668"},{"price":"62627.80","quantity":"3.160"},{"price":"62818.10","quantity":"0.009"},{"price":"63090.80","quantity":"0.018"},{"price":"63091.20","quantity":"0.008"},{"price":"64947.00","quantity":"0.016"},{"price":"89523.20","quantity":"0.822"}],"raw":{"e":"depthUpdate","E":1783517070170,"T":1783517070169,"s":"BTCUSDT","ps":"BTCUSDT","U":10999770894946,"u":10999770908242,"pu":10999770894683,"b":[["11353.70","0.085"],["11553.70","1.424"],["11554.10","0.096"],["11653.70","1.680"],["11753.70","1.547"],["11754.10","0.068"],["55668.30","0.000"],["55668.60","0.002"],["58761.00","0.012"],["60846.40","0.001"],["60848.70","0.010"],["60851.40","0.000"],["60851.60","0.020"],["60854.10","0.013"],["60886.30","0.009"],["60887.90","3.457"],["60925.80","0.407"],["60984.10","8.595"],["61235.20","0.025"],["61235.60","0.328"],["61606.70","2.973"],["61751.00","0.201"],["61763.20","33.581"],["61765.30","0.072"],["61767.50","2.323"],["61770.50","0.003"],["61776.60","0.000"],["61785.00","0.001"],["61786.30","0.002"],["61788.20","1.290"],["61789.00","1.492"],["61789.30","0.000"],["61789.80","0.002"],["61792.60","0.000"],["61794.10","0.008"],["61796.30","0.211"],["61798.90","0.000"],["61799.80","1.071"],["61800.80","0.119"],["61801.70","0.000"],["61802.20","0.003"],["61802.90","0.823"],["61808.90","0.108"],["61809.50","0.063"],["61811.10","0.016"],["61811.50","0.115"],["61811.60","0.069"],["61811.90","0.001"],["61812.60","0.033"],["61813.40","0.062"],["61813.70","1.381"],["61815.00","1.415"],["61815.70","0.103"],["61816.30","0.491"],["61816.70","0.055"],["61816.90","0.015"],["61817.00","0.002"],["61817.30","1.771"],["61817.40","0.105"],["61818.10","0.253"],["61818.30","0.000"],["61818.80","0.292"],["61819.60","0.003"],["61819.70","0.000"],["61821.00","1.009"],["61821.10","0.803"],["61821.60","0.004"],["61821.70","1.088"],["61822.00","0.121"],["61822.30","0.002"],["61822.70","0.013"],["61822.90","0.003"],["61823.00","2.166"],["61823.20","0.515"],["61823.70","1.294"],["61823.80","0.150"],["61824.00","0.340"],["61824.10","0.002"],["61824.30","0.197"],["61824.50","0.421"],["61824.60","0.110"],["61825.00","1.335"],["61825.10","0.360"],["61825.30","0.003"],["61825.90","0.093"],["61826.10","1.245"],["61826.20","0.191"],["61826.50","0.958"],["61827.50","2.168"],["61827.60","0.007"],["61828.10","0.008"],["61828.30","0.583"],["61829.20","0.293"],["61829.40","2.288"],["61830.10","0.122"],["61830.40","0.130"],["61830.50","0.000"],["61830.80","0.001"],["61830.90","0.001"],["61831.20","0.060"],["61831.40","0.436"],["61832.10","0.114"],["61833.40","0.007"],["61833.80","0.968"],["61834.10","2.900"],["61834.30","0.704"],["61834.40","0.124"],["61834.70","0.013"],["61835.20","0.002"],["61835.30","0.320"],["61835.40","0.001"],["61835.60","0.139"],["61835.70","0.003"],["61837.30","0.803"],["61837.40","0.811"],["61837.90","1.646"],["61838.00","1.002"],["61838.20","0.325"],["61838.50","0.012"],["61838.60","0.000"],["61839.50","0.128"],["61840.60","0.696"],["61841.30","0.105"],["61841.40","0.951"],["61841.50","0.221"],["61841.60","0.053"],["61841.70","0.518"],["61841.80","0.085"],["61841.90","0.384"],["61842.00","0.069"],["61842.10","0.001"],["61843.00","0.001"],["61843.10","0.010"],["61843.40","0.062"],["61843.60","0.899"],["61844.60","0.037"],["61845.00","0.009"],["61845.10","0.123"],["61845.20","0.323"],["61845.30","0.005"],["61845.80","0.000"],["61846.20","0.101"],["61846.30","0.001"],["61846.70","0.016"],["61846.80","0.564"],["61847.60","0.008"],["61847.80","0.004"],["61848.80","0.002"],["61848.90","0.004"],["61849.20","0.002"],["61849.90","0.004"],["61850.60","0.287"],["61850.70","0.002"],["61851.20","0.001"],["61851.30","0.002"],["61852.30","0.007"],["61852.40","0.000"],["61852.50","0.001"],["61852.60","0.001"],["61852.90","0.006"],["61853.50","0.004"],["61853.60","0.002"],["61853.70","0.418"],["61853.80","1.800"],["61853.90","0.598"],["61854.00","0.005"],["61854.10","23.111"]],"a":[["61853.80","0.000"],["61853.90","0.000"],["61854.00","0.000"],["61854.20","1.501"],["61854.30","0.025"],["61854.50","0.027"],["61854.70","0.369"],["61854.90","0.016"],["61855.60","0.023"],["61855.90","0.000"],["61856.10","0.000"],["61856.30","0.030"],["61856.40","0.029"],["61856.50","0.000"],["61856.70","0.001"],["61856.90","0.220"],["61857.30","1.001"],["61857.40","0.005"],["61857.60","0.051"],["61857.70","0.249"],["61857.90","0.005"],["61858.10","0.089"],["61858.40","0.001"],["61858.50","0.614"],["61858.90","0.053"],["61859.20","0.010"],["61859.50","0.084"],["61859.70","0.127"],["61859.90","1.616"],["61860.00","0.176"],["61860.20","0.589"],["61860.30","0.306"],["61860.40","0.180"],["61860.80","0.029"],["61861.00","0.412"],["61861.30","0.372"],["61861.50","0.554"],["61861.80","0.161"],["61862.70","2.747"],["61863.20","0.001"],["61863.90","0.308"],["61864.00","2.153"],["61864.90","0.050"],["61865.20","0.016"],["61865.50","0.045"],["61865.70","0.472"],["61865.80","0.968"],["61866.10","0.000"],["61866.20","0.002"],["61866.50","0.570"],["61866.60","3.356"],["61866.70","0.732"],["61866.80","1.292"],["61866.90","0.018"],["61867.10","0.081"],["61867.40","0.061"],["61867.60","0.345"],["61867.80","0.083"],["61867.90","0.584"],["61868.20","0.048"],["61868.90","0.148"],["61869.40","0.007"],["61870.00","0.329"],["61870.40","0.038"],["61870.60","0.242"],["61870.70","2.147"],["61870.90","0.133"],["61871.00","0.020"],["61871.10","0.046"],["61871.80","0.001"],["61872.10","0.019"],["61872.40","0.003"],["61872.60","0.204"],["61873.20","0.004"],["61873.30","0.205"],["61873.50","0.005"],["61873.60","0.043"],["61873.80","1.290"],["61874.10","0.823"],["61874.90","0.122"],["61875.40","0.051"],["61876.10","0.485"],["61877.40","0.063"],["61877.50","0.002"],["61878.00","2.200"],["61878.20","0.046"],["61878.50","0.004"],["61878.60","1.040"],["61878.70","0.032"],["61878.80","0.001"],["61879.00","0.173"],["61879.50","0.412"],["61879.60","0.000"],["61880.20","0.100"],["61880.50","0.004"],["61881.20","0.181"],["61881.30","0.771"],["61882.50","0.000"],["61882.90","1.756"],["61883.00","0.290"],["61883.50","0.937"],["61885.10","0.121"],["61886.40","0.003"],["61886.60","2.136"],["61887.50","0.005"],["61887.70","0.050"],["61888.10","0.170"],["61888.20","0.001"],["61888.80","0.125"],["61889.10","1.024"],["61889.70","0.052"],["61889.80","0.121"],["61889.90","0.000"],["61890.20","0.022"],["61890.30","0.941"],["61890.40","1.471"],["61891.20","0.379"],["61891.30","0.330"],["61891.90","0.042"],["61893.00","0.000"],["61893.20","0.207"],["61893.40","0.099"],["61893.50","0.000"],["61895.00","2.587"],["61895.30","0.929"],["61895.50","0.036"],["61895.80","0.030"],["61896.10","0.061"],["61897.50","0.296"],["61897.70","0.012"],["61898.30","3.274"],["61900.30","0.007"],["61900.60","1.403"],["61901.50","2.205"],["61902.10","0.010"],["61905.40","0.031"],["61906.10","0.069"],["61907.70","0.427"],["61909.40","0.002"],["61909.90","0.376"],["61915.00","2.059"],["61919.00","0.166"],["61926.40","12.130"],["61930.50","2.138"],["61939.90","0.296"],["62027.80","0.000"],["62027.90","0.004"],["62122.20","0.018"],["62472.30","0.338"],["62472.60","0.009"],["62472.70","0.080"],["62565.30","1.898"],["62565.90","10.482"],["62627.00","0.668"],["62627.80","3.160"],["62818.10","0.009"],["63090.80","0.018"],["63091.20","0.008"],["64947.00","0.016"],["89523.20","0.822"]],"st":1}}
{"schema_version":"1.3.0","event_id":"d5dfe5b7-b244-4102-84d0-b00b549a65be","event_type":"raw.trade","source":"binance_market_data_recorder","venue":"binance_usdm","market_type":"perpetual_futures","symbol":"BTCUSDT","event_time_ms":1783517070203,"received_time_ms":1783517070301,"trace_id":"82d795b8-de51-4665-a028-be0ac37a4d61","trade_id":7881418122,"price":"61854.20","quantity":"0.002","trade_time_ms":1783517070203,"is_buyer_maker":false,"aggressor_side":"buy","raw":{"e":"trade","E":1783517070203,"T":1783517070203,"s":"BTCUSDT","t":7881418122,"p":"61854.20","q":"0.002","X":"MARKET","m":false,"st":1}}
{"schema_version":"1.3.0","event_id":"2dbed377-70c4-4043-8efe-7167784b14fd","event_type":"raw.depth_update","source":"binance_market_data_recorder","venue":"binance_usdm","market_type":"perpetual_futures","symbol":"ETHUSDT","event_time_ms":1783517070244,"received_time_ms":1783517070312,"trace_id":"eed296a9-727f-4b5e-bfa9-6d0c0429b570","first_update_id":10999770904283,"final_update_id":10999770916232,"previous_final_update_id":10999770904137,"bids":[{"price":"200.00","quantity":"7.594"},{"price":"1221.11","quantity":"1.376"},{"price":"1226.11","quantity":"6.848"},{"price":"1231.11","quantity":"1.376"},{"price":"1562.04","quantity":"0.126"},{"price":"1562.49","quantity":"0.026"},{"price":"1562.50","quantity":"4.318"},{"price":"1666.60","quantity":"1.078"},{"price":"1685.32","quantity":"0.106"},{"price":"1696.18","quantity":"15.810"},{"price":"1701.39","quantity":"32.216"},{"price":"1704.86","quantity":"61.641"},{"price":"1708.35","quantity":"29.564"},{"price":"1732.52","quantity":"0.000"},{"price":"1732.53","quantity":"1.871"},{"price":"1733.13","quantity":"40.100"},{"price":"1733.14","quantity":"19.085"},{"price":"1733.66","quantity":"23.837"},{"price":"1733.72","quantity":"0.169"},{"price":"1733.92","quantity":"18.830"},{"price":"1733.93","quantity":"6.942"},{"price":"1734.65","quantity":"13.554"},{"price":"1735.00","quantity":"217.480"},{"price":"1735.09","quantity":"2.635"},{"price":"1735.14","quantity":"9.518"},{"price":"1735.15","quantity":"6.463"},{"price":"1735.26","quantity":"231.048"},{"price":"1735.35","quantity":"18.173"},{"price":"1735.42","quantity":"20.653"},{"price":"1735.44","quantity":"27.914"},{"price":"1735.48","quantity":"0.874"},{"price":"1736.01","quantity":"8.698"},{"price":"1736.09","quantity":"1.532"}],"asks":[{"price":"1736.12","quantity":"73.785"},{"price":"1736.13","quantity":"9.955"},{"price":"1736.17","quantity":"0.036"},{"price":"1736.20","quantity":"0.084"},{"price":"1736.24","quantity":"0.156"},{"price":"1736.25","quantity":"23.962"},{"price":"1736.31","quantity":"17.453"},{"price":"1736.34","quantity":"4.978"},{"price":"1736.81","quantity":"22.200"},{"price":"1737.01","quantity":"74.995"},{"price":"1737.02","quantity":"22.592"},{"price":"1737.03","quantity":"83.938"},{"price":"1737.08","quantity":"16.761"},{"price":"1737.12","quantity":"7.826"},{"price":"1737.16","quantity":"17.090"},{"price":"1737.26","quantity":"6.084"},{"price":"1737.42","quantity":"3.675"},{"price":"1737.51","quantity":"11.738"},{"price":"1738.12","quantity":"5.998"},{"price":"1738.14","quantity":"425.129"},{"price":"1738.17","quantity":"7.677"},{"price":"1738.20","quantity":"0.256"},{"price":"1738.25","quantity":"2.878"},{"price":"1743.22","quantity":"33.087"},{"price":"1747.12","quantity":"0.000"},{"price":"1758.26","quantity":"11.370"},{"price":"1763.20","quantity":"60.263"},{"price":"1763.89","quantity":"20.177"},{"price":"2634.43","quantity":"0.001"},{"price":"2634.52","quantity":"0.000"}],"raw":{"e":"depthUpdate","E":1783517070244,"T":1783517070241,"s":"ETHUSDT","ps":"ETHUSDT","U":10999770904283,"u":10999770916232,"pu":10999770904137,"b":[["200.00","7.594"],["1221.11","1.376"],["1226.11","6.848"],["1231.11","1.376"],["1562.04","0.126"],["1562.49","0.026"],["1562.50","4.318"],["1666.60","1.078"],["1685.32","0.106"],["1696.18","15.810"],["1701.39","32.216"],["1704.86","61.641"],["1708.35","29.564"],["1732.52","0.000"],["1732.53","1.871"],["1733.13","40.100"],["1733.14","19.085"],["1733.66","23.837"],["1733.72","0.169"],["1733.92","18.830"],["1733.93","6.942"],["1734.65","13.554"],["1735.00","217.480"],["1735.09","2.635"],["1735.14","9.518"],["1735.15","6.463"],["1735.26","231.048"],["1735.35","18.173"],["1735.42","20.653"],["1735.44","27.914"],["1735.48","0.874"],["1736.01","8.698"],["1736.09","1.532"]],"a":[["1736.12","73.785"],["1736.13","9.955"],["1736.17","0.036"],["1736.20","0.084"],["1736.24","0.156"],["1736.25","23.962"],["1736.31","17.453"],["1736.34","4.978"],["1736.81","22.200"],["1737.01","74.995"],["1737.02","22.592"],["1737.03","83.938"],["1737.08","16.761"],["1737.12","7.826"],["1737.16","17.090"],["1737.26","6.084"],["1737.42","3.675"],["1737.51","11.738"],["1738.12","5.998"],["1738.14","425.129"],["1738.17","7.677"],["1738.20","0.256"],["1738.25","2.878"],["1743.22","33.087"],["1747.12","0.000"],["1758.26","11.370"],["1763.20","60.263"],["1763.89","20.177"],["2634.43","0.001"],["2634.52","0.000"]],"st":1}}
{"schema_version":"1.3.0","event_id":"95aa5207-e68b-49dc-8daa-b673b3b6e7ab","event_type":"raw.trade","source":"binance_market_data_recorder","venue":"binance_usdm","market_type":"perpetual_futures","symbol":"ETHUSDT","event_time_ms":1783517070250,"received_time_ms":1783517070313,"trace_id":"df475e34-2e8a-4739-9ad4-8fa6c8793838","trade_id":8429826932,"price":"1736.12","quantity":"0.026","trade_time_ms":1783517070250,"is_buyer_maker":false,"aggressor_side":"buy","raw":{"e":"trade","E":1783517070250,"T":1783517070250,"s":"ETHUSDT","t":8429826932,"p":"1736.12","q":"0.026","X":"MARKET","m":false,"st":1}}
{"schema_version":"1.3.0","event_id":"82d19057-b51d-425f-9ada-33ae6118ac5b","event_type":"raw.depth_update","source":"binance_market_data_recorder","venue":"binance_usdm","market_type":"perpetual_futures","symbol":"BTCUSDT","event_time_ms":1783517070272,"received_time_ms":1783517070315,"trace_id":"b6ff28d1-edfe-4876-aff9-3e6bd86f17cb","first_update_id":10999770908337,"final_update_id":10999770918410,"previous_final_update_id":10999770908242,"bids":[{"price":"1000.00","quantity":"207.692"},{"price":"11353.70","quantity":"0.000"},{"price":"11554.10","quantity":"0.368"},{"price":"11653.70","quantity":"1.408"},{"price":"11654.10","quantity":"0.051"},{"price":"11754.10","quantity":"0.102"},{"price":"55668.60","quantity":"0.002"},{"price":"58759.60","quantity":"0.006"},{"price":"58761.30","quantity":"0.000"},{"price":"59379.90","quantity":"0.003"},{"price":"61235.60","quantity":"0.328"},{"price":"61544.40","quantity":"0.003"},{"price":"61740.90","quantity":"0.847"},{"price":"61763.20","quantity":"0.019"},{"price":"61784.20","quantity":"0.002"},{"price":"61785.20","quantity":"0.018"},{"price":"61786.30","quantity":"33.564"},{"price":"61794.20","quantity":"0.024"},{"price":"61802.00","quantity":"0.014"},{"price":"61810.70","quantity":"0.027"},{"price":"61811.80","quantity":"0.995"},{"price":"61811.90","quantity":"0.030"},{"price":"61815.50","quantity":"0.003"},{"price":"61823.40","quantity":"0.069"},{"price":"61823.50","quantity":"0.003"},{"price":"61823.80","quantity":"0.150"},{"price":"61827.40","quantity":"0.568"},{"price":"61836.70","quantity":"0.569"},{"price":"61838.00","quantity":"0.436"},{"price":"61841.80","quantity":"0.005"},{"price":"61844.40","quantity":"0.174"},{"price":"61847.80","quantity":"0.002"},{"price":"61852.60","quantity":"0.002"},{"price":"61853.70","quantity":"0.407"},{"price":"61854.00","quantity":"0.006"},{"price":"61854.10","quantity":"22.835"}],"asks":[{"price":"61854.20","quantity":"2.622"},{"price":"61854.30","quantity":"0.026"},{"price":"61856.00","quantity":"0.003"},{"price":"61856.50","quantity":"0.000"},{"price":"61856.60","quantity":"0.284"},{"price":"61857.20","quantity":"0.242"},{"price":"61857.70","quantity":"0.007"},{"price":"61859.70","quantity":"0.001"},{"price":"61863.90","quantity":"1.692"},{"price":"61864.10","quantity":"0.000"},{"price":"61867.60","quantity":"0.427"},{"price":"61867.80","quantity":"0.003"},{"price":"61869.70","quantity":"0.003"},{"price":"61872.10","quantity":"0.021"},{"price":"61874.10","quantity":"0.821"},{"price":"61874.20","quantity":"0.082"},{"price":"61875.40","quantity":"0.052"},{"price":"61889.40","quantity":"0.123"},{"price":"61890.30","quantity":"0.836"},{"price":"61890.40","quantity":"1.366"},{"price":"61891.30","quantity":"0.202"},{"price":"61893.20","quantity":"0.000"},{"price":"61893.50","quantity":"0.207"},{"price":"61897.40","quantity":"0.004"},{"price":"61918.40","quantity":"0.000"},{"price":"61918.60","quantity":"0.014"},{"price":"61920.50","quantity":"25.284"},{"price":"61931.00","quantity":"0.044"},{"price":"61960.20","quantity":"0.299"},{"price":"61970.20","quantity":"0.970"},{"price":"61972.00","quantity":"2.760"},{"price":"62460.20","quantity":"0.638"},{"price":"62472.70","quantity":"0.080"},{"price":"62565.30","quantity":"0.000"},{"price":"62565.90","quantity":"12.380"},{"price":"62819.70","quantity":"0.013"},{"price":"63060.00","quantity":"1.666"}],"raw":{"e":"depthUpdate","E":1783517070272,"T":1783517070270,"s":"BTCUSDT","ps":"BTCUSDT","U":10999770908337,"u":10999770918410,"pu":10999770908242,"b":[["1000.00","207.692"],["11353.70","0.000"],["11554.10","0.368"],["11653.70","1.408"],["11654.10","0.051"],["11754.10","0.102"],["55668.60","0.002"],["58759.60","0.006"],["58761.30","0.000"],["59379.90","0.003"],["61235.60","0.328"],["61544.40","0.003"],["61740.90","0.847"],["61763.20","0.019"],["61784.20","0.002"],["61785.20","0.018"],["61786.30","33.564"],["61794.20","0.024"],["61802.00","0.014"],["61810.70","0.027"],["61811.80","0.995"],["61811.90","0.030"],["61815.50","0.003"],["61823.40","0.069"],["61823.50","0.003"],["61823.80","0.150"],["61827.40","0.568"],["61836.70","0.569"],["61838.00","0.436"],["61841.80","0.005"],["61844.40","0.174"],["61847.80","0.002"],["61852.60","0.002"],["61853.70","0.407"],["61854.00","0.006"],["61854.10","22.835"]],"a":[["61854.20","2.622"],["61854.30","0.026"],["61856.00","0.003"],["61856.50","0.000"],["61856.60","0.284"],["61857.20","0.242"],["61857.70","0.007"],["61859.70","0.001"],["61863.90","1.692"],["61864.10","0.000"],["61867.60","0.427"],["61867.80","0.003"],["61869.70","0.003"],["61872.10","0.021"],["61874.10","0.821"],["61874.20","0.082"],["61875.40","0.052"],["61889.40","0.123"],["61890.30","0.836"],["61890.40","1.366"],["61891.30","0.202"],["61893.20","0.000"],["61893.50","0.207"],["61897.40","0.004"],["61918.40","0.000"],["61918.60","0.014"],["61920.50","25.284"],["61931.00","0.044"],["61960.20","0.299"],["61970.20","0.970"],["61972.00","2.760"],["62460.20","0.638"],["62472.70","0.080"],["62565.30","0.000"],["62565.90","12.380"],["62819.70","0.013"],["63060.00","1.666"]],"st":1}}
{"schema_version":"1.3.0","event_id":"5e8089ef-5550-46a4-b61b-154801e64c89","event_type":"raw.trade","source":"binance_market_data_recorder","venue":"binance_usdm","market_type":"perpetual_futures","symbol":"ETHUSDT","event_time_ms":1783517070278,"received_time_ms":1783517070317,"trace_id":"a7b3fb2c-e1b9-46d0-ad22-9184015f728a","trade_id":8429826933,"price":"1736.12","quantity":"0.007","trade_time_ms":1783517070278,"is_buyer_maker":false,"aggressor_side":"buy","raw":{"e":"trade","E":1783517070278,"T":1783517070278,"s":"ETHUSDT","t":8429826933,"p":"1736.12","q":"0.007","X":"MARKET","m":false,"st":1}}
{"schema_version":"1.3.0","event_id":"240fe728-90c0-4f3f-ad5f-0de697cb4d41","event_type":"raw.trade","source":"binance_market_data_recorder","venue":"binance_usdm","market_type":"perpetual_futures","symbol":"ETHUSDT","event_time_ms":1783517070279,"received_time_ms":1783517070318,"trace_id":"5e01e539-4a64-48ba-a92c-7b574ee37b9a","trade_id":8429826934,"price":"1736.12","quantity":"0.632","trade_time_ms":1783517070278,"is_buyer_maker":false,"aggressor_side":"buy","raw":{"e":"trade","E":1783517070279,"T":1783517070278,"s":"ETHUSDT","t":8429826934,"p":"1736.12","q":"0.632","X":"MARKET","m":false,"st":1}}
{"schema_version":"1.3.0","event_id":"7f8c1a51-efe3-4e56-b607-0b1b6f8f766b","event_type":"raw.trade","source":"binance_market_data_recorder","venue":"binance_usdm","market_type":"perpetual_futures","symbol":"BTCUSDT","event_time_ms":1783517070344,"received_time_ms":1783517070342,"trace_id":"1e2f2c0c-80fd-4c64-82cd-ae31b1906de4","trade_id":7881418123,"price":"61854.10","quantity":"0.002","trade_time_ms":1783517070344,"is_buyer_maker":true,"aggressor_side":"sell","raw":{"e":"trade","E":1783517070344,"T":1783517070344,"s":"BTCUSDT","t":7881418123,"p":"61854.10","q":"0.002","X":"MARKET","m":true,"st":1}}
{"schema_version":"1.3.0","event_id":"049bdebc-47a6-4904-aa2b-3394a23b7f50","event_type":"raw.depth_update","source":"binance_market_data_recorder","venue":"binance_usdm","market_type":"perpetual_futures","symbol":"ETHUSDT","event_time_ms":1783517070346,"received_time_ms":1783517070345,"trace_id":"9e297c1e-c1eb-4dcd-bdca-0df2daeba8d6","first_update_id":10999770916457,"final_update_id":10999770925181,"previous_final_update_id":10999770916232,"bids":[{"price":"1221.11","quantity":"1.920"},{"price":"1226.11","quantity":"6.592"},{"price":"1231.11","quantity":"1.088"},{"price":"1562.49","quantity":"0.026"},{"price":"1562.50","quantity":"4.332"},{"price":"1666.60","quantity":"1.193"},{"price":"1701.39","quantity":"32.187"},{"price":"1708.33","quantity":"135.823"},{"price":"1712.08","quantity":"107.785"},{"price":"1713.54","quantity":"168.322"},{"price":"1713.82","quantity":"34.592"},{"price":"1714.41","quantity":"90.273"},{"price":"1718.74","quantity":"57.600"},{"price":"1720.77","quantity":"142.207"},{"price":"1727.42","quantity":"0.629"},{"price":"1736.09","quantity":"3.014"}],"asks":[{"price":"1736.12","quantity":"62.509"},{"price":"1736.29","quantity":"1.210"},{"price":"1736.34","quantity":"4.978"},{"price":"1736.81","quantity":"19.320"},{"price":"1737.02","quantity":"21.868"},{"price":"1737.03","quantity":"83.757"},{"price":"1737.06","quantity":"22.110"},{"price":"1737.07","quantity":"0.661"},{"price":"1737.16","quantity":"11.330"},{"price":"1737.51","quantity":"0.218"},{"price":"1744.81","quantity":"0.154"},{"price":"1760.69","quantity":"0.000"},{"price":"1762.17","quantity":"51.578"},{"price":"1764.23","quantity":"0.000"},{"price":"2634.41","quantity":"0.001"},{"price":"2634.42","quantity":"0.001"},{"price":"2634.50","quantity":"0.000"},{"price":"2634.51","quantity":"0.000"}],"raw":{"e":"depthUpdate","E":1783517070346,"T":1783517070345,"s":"ETHUSDT","ps":"ETHUSDT","U":10999770916457,"u":10999770925181,"pu":10999770916232,"b":[["1221.11","1.920"],["1226.11","6.592"],["1231.11","1.088"],["1562.49","0.026"],["1562.50","4.332"],["1666.60","1.193"],["1701.39","32.187"],["1708.33","135.823"],["1712.08","107.785"],["1713.54","168.322"],["1713.82","34.592"],["1714.41","90.273"],["1718.74","57.600"],["1720.77","142.207"],["1727.42","0.629"],["1736.09","3.014"]],"a":[["1736.12","62.509"],["1736.29","1.210"],["1736.34","4.978"],["1736.81","19.320"],["1737.02","21.868"],["1737.03","83.757"],["1737.06","22.110"],["1737.07","0.661"],["1737.16","11.330"],["1737.51","0.218"],["1744.81","0.154"],["1760.69","0.000"],["1762.17","51.578"],["1764.23","0.000"],["2634.41","0.001"],["2634.42","0.001"],["2634.50","0.000"],["2634.51","0.000"]],"st":1}}
{"schema_version":"1.3.0","event_id":"da0a7d54-9550-4daa-bd3a-9d064e4298d1","event_type":"raw.trade","source":"binance_market_data_recorder","venue":"binance_usdm","market_type":"perpetual_futures","symbol":"ETHUSDT","event_time_ms":1783517070350,"received_time_ms":1783517070348,"trace_id":"0d3465c9-010b-4897-8f96-3f5dc9e2c113","trade_id":8429826935,"price":"1736.11","quantity":"0.045","trade_time_ms":1783517070349,"is_buyer_maker":true,"aggressor_side":"sell","raw":{"e":"trade","E":1783517070350,"T":1783517070349,"s":"ETHUSDT","t":8429826935,"p":"1736.11","q":"0.045","X":"MARKET","m":true,"st":1}}
{"schema_version":"1.3.0","event_id":"d6d8aee5-44c2-43cc-bc30-f7fb22c65567","event_type":"raw.depth_update","source":"binance_market_data_recorder","venue":"binance_usdm","market_type":"perpetual_futures","symbol":"BTCUSDT","event_time_ms":1783517070374,"received_time_ms":1783517070368,"trace_id":"39053ca3-dc1e-40ab-9620-b5805da0de6d","first_update_id":10999770918538,"final_update_id":10999770928413,"previous_final_update_id":10999770918410,"bids":[{"price":"1000.00","quantity":"207.692"},{"price":"11554.10","quantity":"0.640"},{"price":"11653.70","quantity":"1.136"},{"price":"11654.10","quantity":"0.204"},{"price":"11753.70","quantity":"1.496"},{"price":"11754.10","quantity":"0.000"},{"price":"55668.60","quantity":"0.002"},{"price":"58761.00","quantity":"0.009"},{"price":"58761.10","quantity":"0.003"},{"price":"58761.30","quantity":"0.000"},{"price":"59379.90","quantity":"0.000"},{"price":"60987.70","quantity":"8.960"},{"price":"61235.60","quantity":"0.328"},{"price":"61520.00","quantity":"3.061"},{"price":"61537.60","quantity":"0.348"},{"price":"61585.50","quantity":"0.000"},{"price":"61585.60","quantity":"0.023"},{"price":"61600.00","quantity":"56.939"},{"price":"61672.30","quantity":"0.000"},{"price":"61680.00","quantity":"0.853"},{"price":"61691.40","quantity":"0.164"},{"price":"61760.00","quantity":"1.062"},{"price":"61815.40","quantity":"0.004"},{"price":"61815.50","quantity":"0.104"},{"price":"61821.90","quantity":"0.413"},{"price":"61823.40","quantity":"0.075"},{"price":"61823.50","quantity":"0.092"},{"price":"61826.80","quantity":"0.586"},{"price":"61828.10","quantity":"0.008"},{"price":"61828.30","quantity":"0.001"},{"price":"61829.20","quantity":"0.352"},{"price":"61830.40","quantity":"0.130"},{"price":"61831.20","quantity":"0.001"},{"price":"61832.50","quantity":"0.970"},{"price":"61833.80","quantity":"0.000"},{"price":"61839.30","quantity":"0.203"},{"price":"61840.00","quantity":"0.396"},{"price":"61840.60","quantity":"0.696"},{"price":"61841.40","quantity":"0.928"},{"price":"61843.00","quantity":"0.001"},{"price":"61843.60","quantity":"0.899"},{"price":"61854.10","quantity":"21.893"}],"asks":[{"price":"61854.20","quantity":"2.383"},{"price":"61854.30","quantity":"0.025"},{"price":"61855.40","quantity":"0.025"},{"price":"61856.20","quantity":"0.050"},{"price":"61856.30","quantity":"0.272"},{"price":"61856.50","quantity":"0.009"},{"price":"61856.60","quantity":"0.235"},{"price":"61856.70","quantity":"0.001"},{"price":"61857.20","quantity":"0.000"},{"price":"61863.50","quantity":"0.002"},{"price":"61863.70","quantity":"0.132"},{"price":"61864.40","quantity":"0.809"},{"price":"61864.50","quantity":"0.968"},{"price":"61865.80","quantity":"0.000"},{"price":"61869.70","quantity":"0.003"},{"price":"61872.80","quantity":"0.128"},{"price":"61889.00","quantity":"0.107"},{"price":"61889.40","quantity":"0.018"},{"price":"61893.10","quantity":"0.001"},{"price":"61893.50","quantity":"0.580"},{"price":"61918.40","quantity":"25.284"},{"price":"61920.00","quantity":"1.314"},{"price":"61920.50","quantity":"0.000"},{"price":"61926.60","quantity":"0.001"},{"price":"62000.00","quantity":"13.165"},{"price":"62080.00","quantity":"0.431"},{"price":"62160.00","quantity":"0.426"},{"price":"62240.00","quantity":"0.421"},{"price":"62472.70","quantity":"0.082"},{"price":"62627.20","quantity":"0.638"},{"price":"62628.00","quantity":"5.534"},{"price":"62654.30","quantity":"0.000"},{"price":"62838.50","quantity":"0.000"},{"price":"63091.20","quantity":"0.011"},{"price":"63732.20","quantity":"0.000"},{"price":"89523.20","quantity":"0.828"}],"raw":{"e":"depthUpdate","E":1783517070374,"T":1783517070373,"s":"BTCUSDT","ps":"BTCUSDT","U":10999770918538,"u":10999770928413,"pu":10999770918410,"b":[["1000.00","207.692"],["11554.10","0.640"],["11653.70","1.136"],["11654.10","0.204"],["11753.70","1.496"],["11754.10","0.000"],["55668.60","0.002"],["58761.00","0.009"],["58761.10","0.003"],["58761.30","0.000"],["59379.90","0.000"],["60987.70","8.960"],["61235.60","0.328"],["61520.00","3.061"],["61537.60","0.348"],["61585.50","0.000"],["61585.60","0.023"],["61600.00","56.939"],["61672.30","0.000"],["61680.00","0.853"],["61691.40","0.164"],["61760.00","1.062"],["61815.40","0.004"],["61815.50","0.104"],["61821.90","0.413"],["61823.40","0.075"],["61823.50","0.092"],["61826.80","0.586"],["61828.10","0.008"],["61828.30","0.001"],["61829.20","0.352"],["61830.40","0.130"],["61831.20","0.001"],["61832.50","0.970"],["61833.80","0.000"],["61839.30","0.203"],["61840.00","0.396"],["61840.60","0.696"],["61841.40","0.928"],["61843.00","0.001"],["61843.60","0.899"],["61854.10","21.893"]],"a":[["61854.20","2.383"],["61854.30","0.025"],["61855.40","0.025"],["61856.20","0.050"],["61856.30","0.272"],["61856.50","0.009"],["61856.60","0.235"],["61856.70","0.001"],["61857.20","0.000"],["61863.50","0.002"],["61863.70","0.132"],["61864.40","0.809"],["61864.50","0.968"],["61865.80","0.000"],["61869.70","0.003"],["61872.80","0.128"],["61889.00","0.107"],["61889.40","0.018"],["61893.10","0.001"],["61893.50","0.580"],["61918.40","25.284"],["61920.00","1.314"],["61920.50","0.000"],["61926.60","0.001"],["62000.00","13.165"],["62080.00","0.431"],["62160.00","0.426"],["62240.00","0.421"],["62472.70","0.082"],["62627.20","0.638"],["62628.00","5.534"],["62654.30","0.000"],["62838.50","0.000"],["63091.20","0.011"],["63732.20","0.000"],["89523.20","0.828"]],"st":1}}
{"schema_version":"1.3.0","event_id":"5ce97604-8a6f-4f49-90e2-cfda03f627e5","event_type":"raw.depth_update","source":"binance_market_data_recorder","venue":"binance_usdm","market_type":"perpetual_futures","symbol":"ETHUSDT","event_time_ms":1783517070448,"received_time_ms":1783517070455,"trace_id":"7875015b-f10d-4f47-9de2-8442c1ea5bd6","first_update_id":10999770925336,"final_update_id":10999770939113,"previous_final_update_id":10999770925181,"bids":[{"price":"200.00","quantity":"7.594"},{"price":"1221.11","quantity":"2.464"},{"price":"1226.11","quantity":"6.304"},{"price":"1231.11","quantity":"0.832"},{"price":"1562.49","quantity":"0.026"},{"price":"1562.50","quantity":"4.332"},{"price":"1666.60","quantity":"1.078"},{"price":"1703.64","quantity":"116.805"},{"price":"1704.86","quantity":"90.925"},{"price":"1710.07","quantity":"66.409"},{"price":"1711.95","quantity":"12.998"},{"price":"1720.50","quantity":"19.075"},{"price":"1727.42","quantity":"0.641"},{"price":"1730.07","quantity":"135.828"},{"price":"1730.08","quantity":"26.320"},{"price":"1730.09","quantity":"4.351"},{"price":"1732.39","quantity":"9.271"},{"price":"1732.41","quantity":"0.192"},{"price":"1733.86","quantity":"0.363"},{"price":"1733.92","quantity":"17.384"},{"price":"1733.93","quantity":"3.746"},{"price":"1733.95","quantity":"5.388"},{"price":"1734.01","quantity":"20.653"},{"price":"1734.06","quantity":"473.253"},{"price":"1735.11","quantity":"45.389"},{"price":"1735.26","quantity":"10.582"},{"price":"1735.37","quantity":"0.613"},{"price":"1735.38","quantity":"67.258"},{"price":"1735.48","quantity":"0.874"},{"price":"1735.51","quantity":"50.796"},{"price":"1735.52","quantity":"80.840"},{"price":"1735.58","quantity":"0.094"},{"price":"1735.61","quantity":"8.709"},{"price":"1735.63","quantity":"0.576"},{"price":"1735.76","quantity":"11.272"},{"price":"1735.80","quantity":"39.344"},{"price":"1735.84","quantity":"0.058"},{"price":"1735.87","quantity":"3.043"},{"price":"1735.88","quantity":"0.334"},{"price":"1736.01","quantity":"0.050"},{"price":"1736.02","quantity":"1.812"},{"price":"1736.04","quantity":"0.044"},{"price":"1736.08","quantity":"0.730"},{"price":"1736.10","quantity":"4.304"},{"price":"1736.11","quantity":"175.590"}],"asks":[{"price":"1736.12","quantity":"12.525"},{"price":"1736.13","quantity":"9.037"},{"price":"1736.15","quantity":"0.012"},{"price":"1736.16","quantity":"0.279"},{"price":"1736.17","quantity":"0.024"},{"price":"1736.19","quantity":"0.888"},{"price":"1736.23","quantity":"0.064"},{"price":"1736.24","quantity":"5.060"},{"price":"1736.25","quantity":"8.585"},{"price":"1736.26","quantity":"13.698"},{"price":"1736.29","quantity":"2.363"},{"price":"1736.31","quantity":"17.366"},{"price":"1736.32","quantity":"0.143"},{"price":"1736.34","quantity":"0.059"},{"price":"1736.35","quantity":"31.165"},{"price":"1736.36","quantity":"17.483"},{"price":"1736.38","quantity":"11.840"},{"price":"1736.42","quantity":"11.753"},{"price":"1736.67","quantity":"0.062"},{"price":"1736.73","quantity":"8.730"},{"price":"1736.80","quantity":"4.218"},{"price":"1736.86","quantity":"39.223"},{"price":"1736.89","quantity":"8.153"},{"price":"1736.90","quantity":"29.781"},{"price":"1736.91","quantity":"68.147"},{"price":"1736.92","quantity":"67.361"},{"price":"1736.95","quantity":"0.446"},{"price":"1736.98","quantity":"5.219"},{"price":"1737.68","quantity":"3.610"},{"price":"1737.82","quantity":"16.708"},{"price":"1738.12","quantity":"4.331"},{"price":"1738.13","quantity":"45.994"},{"price":"1738.98","quantity":"43.748"},{"price":"1744.81","quantity":"0.142"},{"price":"1744.99","quantity":"0.615"},{"price":"1745.04","quantity":"0.106"},{"price":"1748.12","quantity":"6.140"},{"price":"1748.17","quantity":"0.036"},{"price":"1781.24","quantity":"297.349"},{"price":"2634.39","quantity":"0.001"},{"price":"2634.40","quantity":"0.001"},{"price":"2634.48","quantity":"0.148"},{"price":"2634.49","quantity":"0.000"}],"raw":{"e":"depthUpdate","E":1783517070448,"T":1783517070447,"s":"ETHUSDT","ps":"ETHUSDT","U":10999770925336,"u":10999770939113,"pu":10999770925181,"b":[["200.00","7.594"],["1221.11","2.464"],["1226.11","6.304"],["1231.11","0.832"],["1562.49","0.026"],["1562.50","4.332"],["1666.60","1.078"],["1703.64","116.805"],["1704.86","90.925"],["1710.07","66.409"],["1711.95","12.998"],["1720.50","19.075"],["1727.42","0.641"],["1730.07","135.828"],["1730.08","26.320"],["1730.09","4.351"],["1732.39","9.271"],["1732.41","0.192"],["1733.86","0.363"],["1733.92","17.384"],["1733.93","3.746"],["1733.95","5.388"],["1734.01","20.653"],["1734.06","473.253"],["1735.11","45.389"],["1735.26","10.582"],["1735.37","0.613"],["1735.38","67.258"],["1735.48","0.874"],["1735.51","50.796"],["1735.52","80.840"],["1735.58","0.094"],["1735.61","8.709"],["1735.63","0.576"],["1735.76","11.272"],["1735.80","39.344"],["1735.84","0.058"],["1735.87","3.043"],["1735.88","0.334"],["1736.01","0.050"],["1736.02","1.812"],["1736.04","0.044"],["1736.08","0.730"],["1736.10","4.304"],["1736.11","175.590"]],"a":[["1736.12","12.525"],["1736.13","9.037"],["1736.15","0.012"],["1736.16","0.279"],["1736.17","0.024"],["1736.19","0.888"],["1736.23","0.064"],["1736.24","5.060"],["1736.25","8.585"],["1736.26","13.698"],["1736.29","2.363"],["1736.31","17.366"],["1736.32","0.143"],["1736.34","0.059"],["1736.35","31.165"],["1736.36","17.483"],["1736.38","11.840"],["1736.42","11.753"],["1736.67","0.062"],["1736.73","8.730"],["1736.80","4.218"],["1736.86","39.223"],["1736.89","8.153"],["1736.90","29.781"],["1736.91","68.147"],["1736.92","67.361"],["1736.95","0.446"],["1736.98","5.219"],["1737.68","3.610"],["1737.82","16.708"],["1738.12","4.331"],["1738.13","45.994"],["1738.98","43.748"],["1744.81","0.142"],["1744.99","0.615"],["1745.04","0.106"],["1748.12","6.140"],["1748.17","0.036"],["1781.24","297.349"],["2634.39","0.001"],["2634.40","0.001"],["2634.48","0.148"],["2634.49","0.000"]],"st":1}}
{"schema_version":"1.3.0","event_id":"09ecbea6-dc50-440f-a6b7-3cbccc4db91d","event_type":"raw.depth_update","source":"binance_market_data_recorder","venue":"binance_usdm","market_type":"perpetual_futures","symbol":"BTCUSDT","event_time_ms":1783517070476,"received_time_ms":1783517070471,"trace_id":"55fd9cf8-533a-41b6-9ab0-e008f073d7bf","first_update_id":10999770928446,"final_update_id":10999770941612,"previous_final_update_id":10999770928413,"bids":[{"price":"11554.10","quantity":"0.912"},{"price":"11653.70","quantity":"0.864"},{"price":"11654.10","quantity":"0.340"},{"price":"11753.70","quantity":"1.360"},{"price":"55668.60","quantity":"0.002"},{"price":"58761.30","quantity":"0.000"},{"price":"59379.90","quantity":"0.003"},{"price":"60617.10","quantity":"0.003"},{"price":"61235.60","quantity":"0.328"},{"price":"61293.60","quantity":"1.044"},{"price":"61598.60","quantity":"0.000"},{"price":"61601.90","quantity":"0.027"},{"price":"61680.30","quantity":"0.065"},{"price":"61762.00","quantity":"1.554"},{"price":"61762.10","quantity":"0.009"},{"price":"61782.30","quantity":"1.539"},{"price":"61782.40","quantity":"0.029"},{"price":"61802.50","quantity":"0.053"},{"price":"61802.70","quantity":"9.387"},{"price":"61815.50","quantity":"0.104"},{"price":"61823.40","quantity":"0.451"},{"price":"61823.50","quantity":"0.092"},{"price":"61823.80","quantity":"0.255"},{"price":"61828.10","quantity":"0.008"},{"price":"61829.60","quantity":"0.099"},{"price":"61830.40","quantity":"0.050"},{"price":"61831.40","quantity":"0.331"},{"price":"61832.50","quantity":"0.002"},{"price":"61832.80","quantity":"1.311"},{"price":"61833.60","quantity":"0.055"},{"price":"61834.60","quantity":"0.049"},{"price":"61836.80","quantity":"0.081"},{"price":"61836.90","quantity":"0.001"},{"price":"61838.00","quantity":"0.000"},{"price":"61838.90","quantity":"0.505"},{"price":"61840.60","quantity":"0.696"},{"price":"61842.00","quantity":"0.046"},{"price":"61842.50","quantity":"0.030"},{"price":"61843.00","quantity":"0.081"},{"price":"61853.90","quantity":"0.552"},{"price":"61854.10","quantity":"20.956"}],"asks":[{"price":"61854.20","quantity":"2.639"},{"price":"61854.30","quantity":"0.025"},{"price":"61856.00","quantity":"0.004"},{"price":"61856.10","quantity":"0.242"},{"price":"61856.20","quantity":"0.002"},{"price":"61856.30","quantity":"0.030"},{"price":"61856.40","quantity":"0.078"},{"price":"61856.70","quantity":"0.001"},{"price":"61857.30","quantity":"1.000"},{"price":"61859.00","quantity":"0.144"},{"price":"61859.80","quantity":"0.487"},{"price":"61860.20","quantity":"0.648"},{"price":"61862.50","quantity":"0.163"},{"price":"61864.50","quantity":"0.000"},{"price":"61865.50","quantity":"0.005"},{"price":"61865.60","quantity":"1.152"},{"price":"61866.40","quantity":"0.163"},{"price":"61869.70","quantity":"0.003"},{"price":"61869.80","quantity":"0.174"},{"price":"61871.60","quantity":"0.004"},{"price":"61872.80","quantity":"0.128"},{"price":"61873.30","quantity":"0.367"},{"price":"61875.40","quantity":"0.051"},{"price":"61884.50","quantity":"0.005"},{"price":"61888.80","quantity":"0.230"},{"price":"61889.00","quantity":"0.002"},{"price":"61889.40","quantity":"0.018"},{"price":"61897.50","quantity":"0.296"},{"price":"61924.40","quantity":"1.529"},{"price":"61924.50","quantity":"0.000"},{"price":"61926.60","quantity":"0.001"},{"price":"61944.70","quantity":"1.539"},{"price":"61944.90","quantity":"0.001"},{"price":"61965.00","quantity":"1.538"},{"price":"61965.20","quantity":"0.824"},{"price":"62407.10","quantity":"0.480"},{"price":"62472.70","quantity":"0.080"},{"price":"62587.40","quantity":"0.001"}],"raw":{"e":"depthUpdate","E":1783517070476,"T":1783517070473,"s":"BTCUSDT","ps":"BTCUSDT","U":10999770928446,"u":10999770941612,"pu":10999770928413,"b":[["11554.10","0.912"],["11653.70","0.864"],["11654.10","0.340"],["11753.70","1.360"],["55668.60","0.002"],["58761.30","0.000"],["59379.90","0.003"],["60617.10","0.003"],["61235.60","0.328"],["61293.60","1.044"],["61598.60","0.000"],["61601.90","0.027"],["61680.30","0.065"],["61762.00","1.554"],["61762.10","0.009"],["61782.30","1.539"],["61782.40","0.029"],["61802.50","0.053"],["61802.70","9.387"],["61815.50","0.104"],["61823.40","0.451"],["61823.50","0.092"],["61823.80","0.255"],["61828.10","0.008"],["61829.60","0.099"],["61830.40","0.050"],["61831.40","0.331"],["61832.50","0.002"],["61832.80","1.311"],["61833.60","0.055"],["61834.60","0.049"],["61836.80","0.081"],["61836.90","0.001"],["61838.00","0.000"],["61838.90","0.505"],["61840.60","0.696"],["61842.00","0.046"],["61842.50","0.030"],["61843.00","0.081"],["61853.90","0.552"],["61854.10","20.956"]],"a":[["61854.20","2.639"],["61854.30","0.025"],["61856.00","0.004"],["61856.10","0.242"],["61856.20","0.002"],["61856.30","0.030"],["61856.40","0.078"],["61856.70","0.001"],["61857.30","1.000"],["61859.00","0.144"],["61859.80","0.487"],["61860.20","0.648"],["61862.50","0.163"],["61864.50","0.000"],["61865.50","0.005"],["61865.60","1.152"],["61866.40","0.163"],["61869.70","0.003"],["61869.80","0.174"],["61871.60","0.004"],["61872.80","0.128"],["61873.30","0.367"],["61875.40","0.051"],["61884.50","0.005"],["61888.80","0.230"],["61889.00","0.002"],["61889.40","0.018"],["61897.50","0.296"],["61924.40","1.529"],["61924.50","0.000"],["61926.60","0.001"],["61944.70","1.539"],["61944.90","0.001"],["61965.00","1.538"],["61965.20","0.824"],["62407.10","0.480"],["62472.70","0.080"],["62587.40","0.001"]],"st":1}}
{"schema_version":"1.3.0","event_id":"01da4b0a-08b2-4e58-aff9-362ec7e4b4c6","event_type":"raw.trade","source":"binance_market_data_recorder","venue":"binance_usdm","market_type":"perpetual_futures","symbol":"BTCUSDT","event_time_ms":1783517070492,"received_time_ms":1783517070488,"trace_id":"f90ba690-38bb-4321-a35b-85dbc836930c","trade_id":7881418124,"price":"61854.20","quantity":"0.002","trade_time_ms":1783517070492,"is_buyer_maker":false,"aggressor_side":"buy","raw":{"e":"trade","E":1783517070492,"T":1783517070492,"s":"BTCUSDT","t":7881418124,"p":"61854.20","q":"0.002","X":"MARKET","m":false,"st":1}}
{"schema_version":"1.3.0","event_id":"52eaa669-3256-4146-8e93-878f1011aa56","event_type":"raw.depth_update","source":"binance_market_data_recorder","venue":"binance_usdm","market_type":"perpetual_futures","symbol":"ETHUSDT","event_time_ms":1783517070550,"received_time_ms":1783517070546,"trace_id":"2ea17621-3dd4-4a0f-95c6-0c33dd136d9e","first_update_id":10999770939154,"final_update_id":10999770946956,"previous_final_update_id":10999770939113,"bids":[{"price":"200.00","quantity":"7.594"},{"price":"201.00","quantity":"2.300"},{"price":"1221.11","quantity":"3.008"},{"price":"1226.11","quantity":"6.048"},{"price":"1231.11","quantity":"0.544"},{"price":"1562.49","quantity":"0.026"},{"price":"1562.50","quantity":"4.332"},{"price":"1666.60","quantity":"1.193"},{"price":"1701.38","quantity":"43.670"},{"price":"1705.67","quantity":"58.818"},{"price":"1718.29","quantity":"7.604"},{"price":"1719.03","quantity":"203.356"},{"price":"1720.64","quantity":"35.699"},{"price":"1722.51","quantity":"13.932"},{"price":"1731.25","quantity":"14.145"},{"price":"1733.59","quantity":"441.743"},{"price":"1734.06","quantity":"54.181"},{"price":"1735.10","quantity":"233.264"},{"price":"1735.20","quantity":"279.988"},{"price":"1735.23","quantity":"4.905"},{"price":"1735.34","quantity":"0.116"},{"price":"1735.37","quantity":"0.595"},{"price":"1735.38","quantity":"67.258"},{"price":"1735.44","quantity":"27.914"},{"price":"1735.52","quantity":"77.961"},{"price":"1735.82","quantity":"0.964"},{"price":"1735.88","quantity":"0.236"},{"price":"1735.99","quantity":"8.787"},{"price":"1736.02","quantity":"0.084"},{"price":"1736.06","quantity":"0.117"},{"price":"1736.09","quantity":"0.944"},{"price":"1736.11","quantity":"168.922"}],"asks":[{"price":"1736.12","quantity":"87.663"},{"price":"1736.13","quantity":"9.079"},{"price":"1736.14","quantity":"0.904"},{"price":"1736.15","quantity":"0.024"},{"price":"1736.16","quantity":"0.291"},{"price":"1736.18","quantity":"0.178"},{"price":"1736.19","quantity":"0.000"},{"price":"1736.21","quantity":"0.113"},{"price":"1736.23","quantity":"20.064"},{"price":"1736.24","quantity":"2.388"},{"price":"1736.26","quantity":"13.609"},{"price":"1736.28","quantity":"5.261"},{"price":"1736.29","quantity":"1.210"},{"price":"1736.30","quantity":"20.951"},{"price":"1736.31","quantity":"17.471"},{"price":"1736.32","quantity":"18.078"},{"price":"1736.34","quantity":"1.041"},{"price":"1736.35","quantity":"4.537"},{"price":"1736.40","quantity":"21.369"},{"price":"1736.42","quantity":"8.297"},{"price":"1736.57","quantity":"2.108"},{"price":"1736.63","quantity":"12.326"},{"price":"1736.64","quantity":"76.115"},{"price":"1736.72","quantity":"10.939"},{"price":"1736.73","quantity":"15.358"},{"price":"1736.81","quantity":"20.987"},{"price":"1736.89","quantity":"8.141"},{"price":"1736.90","quantity":"31.436"},{"price":"1736.91","quantity":"68.135"},{"price":"1736.92","quantity":"67.349"},{"price":"1737.12","quantity":"7.826"},{"price":"1737.14","quantity":"72.888"},{"price":"1737.39","quantity":"2.576"},{"price":"1738.08","quantity":"410.518"},{"price":"1738.12","quantity":"5.998"},{"price":"1738.14","quantity":"16.295"},{"price":"1738.19","quantity":"16.320"},{"price":"1738.98","quantity":"40.552"},{"price":"1742.47","quantity":"7.517"},{"price":"1747.12","quantity":"15.000"},{"price":"1769.11","quantity":"37.969"},{"price":"1795.47","quantity":"50.157"},{"price":"2634.38","quantity":"0.001"},{"price":"2634.47","quantity":"0.000"}],"raw":{"e":"depthUpdate","E":1783517070550,"T":1783517070549,"s":"ETHUSDT","ps":"ETHUSDT","U":10999770939154,"u":10999770946956,"pu":10999770939113,"b":[["200.00","7.594"],["201.00","2.300"],["1221.11","3.008"],["1226.11","6.048"],["1231.11","0.544"],["1562.49","0.026"],["1562.50","4.332"],["1666.60","1.193"],["1701.38","43.670"],["1705.67","58.818"],["1718.29","7.604"],["1719.03","203.356"],["1720.64","35.699"],["1722.51","13.932"],["1731.25","14.145"],["1733.59","441.743"],["1734.06","54.181"],["1735.10","233.264"],["1735.20","279.988"],["1735.23","4.905"],["1735.34","0.116"],["1735.37","0.595"],["1735.38","67.258"],["1735.44","27.914"],["1735.52","77.961"],["1735.82","0.964"],["1735.88","0.236"],["1735.99","8.787"],["1736.02","0.084"],["1736.06","0.117"],["1736.09","0.944"],["1736.11","168.922"]],"a":[["1736.12","87.663"],["1736.13","9.079"],["1736.14","0.904"],["1736.15","0.024"],["1736.16","0.291"],["1736.18","0.178"],["1736.19","0.000"],["1736.21","0.113"],["1736.23","20.064"],["1736.24","2.388"],["1736.26","13.609"],["1736.28","5.261"],["1736.29","1.210"],["1736.30","20.951"],["1736.31","17.471"],["1736.32","18.078"],["1736.34","1.041"],["1736.35","4.537"],["1736.40","21.369"],["1736.42","8.297"],["1736.57","2.108"],["1736.63","12.326"],["1736.64","76.115"],["1736.72","10.939"],["1736.73","15.358"],["1736.81","20.987"],["1736.89","8.141"],["1736.90","31.436"],["1736.91","68.135"],["1736.92","67.349"],["1737.12","7.826"],["1737.14","72.888"],["1737.39","2.576"],["1738.08","410.518"],["1738.12","5.998"],["1738.14","16.295"],["1738.19","16.320"],["1738.98","40.552"],["1742.47","7.517"],["1747.12","15.000"],["1769.11","37.969"],["1795.47","50.157"],["2634.38","0.001"],["2634.47","0.000"]],"st":1}}
{"schema_version":"1.3.0","event_id":"ebbbad92-8c8d-422e-bb29-e7bfec4eb521","event_type":"raw.depth_update","source":"binance_market_data_recorder","venue":"binance_usdm","market_type":"perpetual_futures","symbol":"BTCUSDT","event_time_ms":1783517070578,"received_time_ms":1783517070575,"trace_id":"7fc5cc4f-ae7f-41ef-9b9b-4bb44857e2c3","first_update_id":10999770941826,"final_update_id":10999770948900,"previous_final_update_id":10999770941612,"bids":[{"price":"1000.00","quantity":"207.692"},{"price":"11554.10","quantity":"1.184"},{"price":"11653.70","quantity":"0.592"},{"price":"11654.10","quantity":"0.493"},{"price":"11753.70","quantity":"1.207"},{"price":"55668.60","quantity":"0.002"},{"price":"58761.30","quantity":"0.000"},{"price":"59379.90","quantity":"0.000"},{"price":"61235.60","quantity":"0.328"},{"price":"61520.00","quantity":"3.079"},{"price":"61544.40","quantity":"0.013"},{"price":"61600.00","quantity":"56.957"},{"price":"61680.00","quantity":"0.871"},{"price":"61760.00","quantity":"1.080"},{"price":"61789.00","quantity":"1.484"},{"price":"61790.70","quantity":"0.038"},{"price":"61828.10","quantity":"0.088"},{"price":"61828.30","quantity":"0.122"},{"price":"61830.10","quantity":"0.001"},{"price":"61830.40","quantity":"0.130"},{"price":"61834.70","quantity":"0.023"},{"price":"61835.60","quantity":"0.129"},{"price":"61836.00","quantity":"0.630"},{"price":"61836.70","quantity":"0.003"},{"price":"61836.80","quantity":"0.001"},{"price":"61838.90","quantity":"0.425"},{"price":"61840.00","quantity":"0.414"},{"price":"61841.70","quantity":"0.518"},{"price":"61842.50","quantity":"0.006"},{"price":"61842.70","quantity":"0.567"},{"price":"61843.00","quantity":"0.001"},{"price":"61843.60","quantity":"0.333"},{"price":"61852.20","quantity":"0.631"},{"price":"61853.70","quantity":"0.405"},{"price":"61854.10","quantity":"19.892"}],"asks":[{"price":"61854.20","quantity":"2.632"},{"price":"61854.30","quantity":"0.026"},{"price":"61854.60","quantity":"0.003"},{"price":"61855.80","quantity":"0.007"},{"price":"61859.70","quantity":"0.001"},{"price":"61860.80","quantity":"0.029"},{"price":"61861.60","quantity":"0.322"},{"price":"61862.70","quantity":"2.745"},{"price":"61863.20","quantity":"0.001"},{"price":"61864.10","quantity":"0.968"},{"price":"61864.30","quantity":"0.002"},{"price":"61865.60","quantity":"0.184"},{"price":"61866.50","quantity":"0.570"},{"price":"61867.40","quantity":"0.691"},{"price":"61887.20","quantity":"0.107"},{"price":"61887.70","quantity":"0.050"},{"price":"61887.80","quantity":"0.286"},{"price":"61888.00","quantity":"0.599"},{"price":"61888.80","quantity":"0.230"},{"price":"61909.40","quantity":"0.266"},{"price":"61909.50","quantity":"2.896"},{"price":"61909.80","quantity":"0.000"},{"price":"61909.90","quantity":"0.376"},{"price":"61918.30","quantity":"0.264"},{"price":"61920.00","quantity":"1.332"},{"price":"61926.60","quantity":"0.098"},{"price":"61950.50","quantity":"0.000"},{"price":"61953.70","quantity":"0.000"},{"price":"62000.00","quantity":"13.183"},{"price":"62080.00","quantity":"0.449"},{"price":"62160.00","quantity":"0.444"},{"price":"62240.00","quantity":"0.439"},{"price":"62407.10","quantity":"0.240"},{"price":"62472.70","quantity":"0.080"},{"price":"62817.00","quantity":"0.794"},{"price":"63069.80","quantity":"0.005"},{"price":"63091.20","quantity":"0.017"},{"price":"63738.00","quantity":"2.758"},{"price":"89523.20","quantity":"0.834"}],"raw":{"e":"depthUpdate","E":1783517070578,"T":1783517070577,"s":"BTCUSDT","ps":"BTCUSDT","U":10999770941826,"u":10999770948900,"pu":10999770941612,"b":[["1000.00","207.692"],["11554.10","1.184"],["11653.70","0.592"],["11654.10","0.493"],["11753.70","1.207"],["55668.60","0.002"],["58761.30","0.000"],["59379.90","0.000"],["61235.60","0.328"],["61520.00","3.079"],["61544.40","0.013"],["61600.00","56.957"],["61680.00","0.871"],["61760.00","1.080"],["61789.00","1.484"],["61790.70","0.038"],["61828.10","0.088"],["61828.30","0.122"],["61830.10","0.001"],["61830.40","0.130"],["61834.70","0.023"],["61835.60","0.129"],["61836.00","0.630"],["61836.70","0.003"],["61836.80","0.001"],["61838.90","0.425"],["61840.00","0.414"],["61841.70","0.518"],["61842.50","0.006"],["61842.70","0.567"],["61843.00","0.001"],["61843.60","0.333"],["61852.20","0.631"],["61853.70","0.405"],["61854.10","19.892"]],"a":[["61854.20","2.632"],["61854.30","0.026"],["61854.60","0.003"],["61855.80","0.007"],["61859.70","0.001"],["61860.80","0.029"],["61861.60","0.322"],["61862.70","2.745"],["61863.20","0.001"],["61864.10","0.968"],["61864.30","0.002"],["61865.60","0.184"],["61866.50","0.570"],["61867.40","0.691"],["61887.20","0.107"],["61887.70","0.050"],["61887.80","0.286"],["61888.00","0.599"],["61888.80","0.230"],["61909.40","0.266"],["61909.50","2.896"],["61909.80","0.000"],["61909.90","0.376"],["61918.30","0.264"],["61920.00","1.332"],["61926.60","0.098"],["61950.50","0.000"],["61953.70","0.000"],["62000.00","13.183"],["62080.00","0.449"],["62160.00","0.444"],["62240.00","0.439"],["62407.10","0.240"],["62472.70","0.080"],["62817.00","0.794"],["63069.80","0.005"],["63091.20","0.017"],["63738.00","2.758"],["89523.20","0.834"]],"st":1}}
{"schema_version":"1.3.0","event_id":"33ae3a58-f240-47e2-8b86-b09ff1985143","event_type":"raw.depth_update","source":"binance_market_data_recorder","venue":"binance_usdm","market_type":"perpetual_futures","symbol":"ETHUSDT","event_time_ms":1783517070652,"received_time_ms":1783517070646,"trace_id":"df7daa5b-e457-4556-a090-2ab37c217d2e","first_update_id":10999770947079,"final_update_id":10999770954256,"previous_final_update_id":10999770946956,"bids":[{"price":"1221.11","quantity":"3.552"},{"price":"1226.11","quantity":"5.760"},{"price":"1231.11","quantity":"0.288"},{"price":"1562.49","quantity":"0.026"},{"price":"1562.50","quantity":"4.204"},{"price":"1701.38","quantity":"43.641"},{"price":"1703.43","quantity":"72.830"},{"price":"1706.60","quantity":"62.366"},{"price":"1709.74","quantity":"0.280"},{"price":"1710.07","quantity":"76.637"},{"price":"1711.80","quantity":"174.117"},{"price":"1717.01","quantity":"27.336"},{"price":"1718.54","quantity":"20.340"},{"price":"1718.75","quantity":"372.741"},{"price":"1728.20","quantity":"0.366"},{"price":"1733.41","quantity":"42.081"},{"price":"1733.42","quantity":"4.369"},{"price":"1733.59","quantity":"22.671"},{"price":"1733.65","quantity":"9.919"},{"price":"1735.10","quantity":"13.075"},{"price":"1735.11","quantity":"45.389"},{"price":"1735.79","quantity":"4.516"},{"price":"1735.84","quantity":"0.858"},{"price":"1735.87","quantity":"3.843"},{"price":"1735.88","quantity":"1.036"},{"price":"1736.05","quantity":"0.083"}],"asks":[{"price":"1736.12","quantity":"87.681"},{"price":"1736.17","quantity":"0.036"},{"price":"1736.18","quantity":"0.190"},{"price":"1736.19","quantity":"0.012"},{"price":"1736.32","quantity":"18.078"},{"price":"1736.34","quantity":"0.041"},{"price":"1736.75","quantity":"67.765"},{"price":"1738.08","quantity":"1.684"},{"price":"1738.12","quantity":"4.331"},{"price":"1738.14","quantity":"16.295"},{"price":"1738.96","quantity":"3.196"},{"price":"1781.26","quantity":"50.466"},{"price":"2634.36","quantity":"0.001"},{"price":"2634.37","quantity":"0.026"},{"price":"2634.45","quantity":"0.000"},{"price":"2634.46","quantity":"0.000"}],"raw":{"e":"depthUpdate","E":1783517070652,"T":1783517070651,"s":"ETHUSDT","ps":"ETHUSDT","U":10999770947079,"u":10999770954256,"pu":10999770946956,"b":[["1221.11","3.552"],["1226.11","5.760"],["1231.11","0.288"],["1562.49","0.026"],["1562.50","4.204"],["1701.38","43.641"],["1703.43","72.830"],["1706.60","62.366"],["1709.74","0.280"],["1710.07","76.637"],["1711.80","174.117"],["1717.01","27.336"],["1718.54","20.340"],["1718.75","372.741"],["1728.20","0.366"],["1733.41","42.081"],["1733.42","4.369"],["1733.59","22.671"],["1733.65","9.919"],["1735.10","13.075"],["1735.11","45.389"],["1735.79","4.516"],["1735.84","0.858"],["1735.87","3.843"],["1735.88","1.036"],["1736.05","0.083"]],"a":[["1736.12","87.681"],["1736.17","0.036"],["1736.18","0.190"],["1736.19","0.012"],["1736.32","18.078"],["1736.34","0.041"],["1736.75","67.765"],["1738.08","1.684"],["1738.12","4.331"],["1738.14","16.295"],["1738.96","3.196"],["1781.26","50.466"],["2634.36","0.001"],["2634.37","0.026"],["2634.45","0.000"],["2634.46","0.000"]],"st":1}}
{"schema_version":"1.3.0","event_id":"1851828a-cf2e-45f3-a371-576d812c1127","event_type":"raw.trade","source":"binance_market_data_recorder","venue":"binance_usdm","market_type":"perpetual_futures","symbol":"BTCUSDT","event_time_ms":1783517070669,"received_time_ms":1783517070664,"trace_id":"988a9938-e722-4b93-892b-0115e314bd16","trade_id":7881418125,"price":"61854.20","quantity":"0.010","trade_time_ms":1783517070669,"is_buyer_maker":false,"aggressor_side":"buy","raw":{"e":"trade","E":1783517070669,"T":1783517070669,"s":"BTCUSDT","t":7881418125,"p":"61854.20","q":"0.010","X":"MARKET","m":false,"st":1}}
{"schema_version":"1.3.0","event_id":"0da2131a-0704-4e14-bf97-0e2d30d11af7","event_type":"raw.depth_update","source":"binance_market_data_recorder","venue":"binance_usdm","market_type":"perpetual_futures","symbol":"BTCUSDT","event_time_ms":1783517070680,"received_time_ms":1783517070675,"trace_id":"b325f0cf-97a4-41a7-914f-ed50d0e86a81","first_update_id":10999770949153,"final_update_id":10999770956690,"previous_final_update_id":10999770948900,"bids":[{"price":"1000.00","quantity":"207.692"},{"price":"11454.10","quantity":"0.080"},{"price":"11554.10","quantity":"1.296"},{"price":"11653.70","quantity":"0.400"},{"price":"11654.10","quantity":"0.629"},{"price":"11753.70","quantity":"1.071"},{"price":"49483.00","quantity":"0.000"},{"price":"55668.60","quantity":"0.002"},{"price":"58761.30","quantity":"0.000"},{"price":"60617.10","quantity":"0.006"},{"price":"60987.70","quantity":"9.238"},{"price":"61235.60","quantity":"0.328"},{"price":"61520.00","quantity":"3.097"},{"price":"61600.00","quantity":"56.975"},{"price":"61680.00","quantity":"0.889"},{"price":"61749.60","quantity":"0.021"},{"price":"61750.30","quantity":"0.826"},{"price":"61760.00","quantity":"1.098"},{"price":"61789.00","quantity":"6.280"},{"price":"61805.60","quantity":"0.386"},{"price":"61828.10","quantity":"0.008"},{"price":"61835.30","quantity":"0.400"},{"price":"61835.90","quantity":"1.056"},{"price":"61836.00","quantity":"0.632"},{"price":"61836.10","quantity":"0.003"},{"price":"61840.00","quantity":"0.432"},{"price":"61841.70","quantity":"0.598"},{"price":"61853.70","quantity":"0.401"},{"price":"61854.10","quantity":"19.893"}],"asks":[{"price":"61854.20","quantity":"2.616"},{"price":"61854.90","quantity":"0.017"},{"price":"61856.20","quantity":"0.001"},{"price":"61864.00","quantity":"2.153"},{"price":"61866.50","quantity":"0.570"},{"price":"61875.20","quantity":"0.318"},{"price":"61878.90","quantity":"0.056"},{"price":"61880.70","quantity":"0.136"},{"price":"61889.20","quantity":"0.083"},{"price":"61893.70","quantity":"0.882"},{"price":"61896.10","quantity":"0.001"},{"price":"61916.40","quantity":"6.620"},{"price":"61920.00","quantity":"1.350"},{"price":"61926.60","quantity":"0.098"},{"price":"62000.00","quantity":"13.201"},{"price":"62027.90","quantity":"0.001"},{"price":"62028.60","quantity":"0.003"},{"price":"62080.00","quantity":"0.467"},{"price":"62160.00","quantity":"0.462"},{"price":"62240.00","quantity":"0.457"},{"price":"62472.70","quantity":"0.080"},{"price":"62627.40","quantity":"0.270"},{"price":"63966.00","quantity":"1.463"}],"raw":{"e":"depthUpdate","E":1783517070680,"T":1783517070679,"s":"BTCUSDT","ps":"BTCUSDT","U":10999770949153,"u":10999770956690,"pu":10999770948900,"b":[["1000.00","207.692"],["11454.10","0.080"],["11554.10","1.296"],["11653.70","0.400"],["11654.10","0.629"],["11753.70","1.071"],["49483.00","0.000"],["55668.60","0.002"],["58761.30","0.000"],["60617.10","0.006"],["60987.70","9.238"],["61235.60","0.328"],["61520.00","3.097"],["61600.00","56.975"],["61680.00","0.889"],["61749.60","0.021"],["61750.30","0.826"],["61760.00","1.098"],["61789.00","6.280"],["61805.60","0.386"],["61828.10","0.008"],["61835.30","0.400"],["61835.90","1.056"],["61836.00","0.632"],["61836.10","0.003"],["61840.00","0.432"],["61841.70","0.598"],["61853.70","0.401"],["61854.10","19.893"]],"a":[["61854.20","2.616"],["61854.90","0.017"],["61856.20","0.001"],["61864.00","2.153"],["61866.50","0.570"],["61875.20","0.318"],["61878.90","0.056"],["61880.70","0.136"],["61889.20","0.083"],["61893.70","0.882"],["61896.10","0.001"],["61916.40","6.620"],["61920.00","1.350"],["61926.60","0.098"],["62000.00","13.201"],["62027.90","0.001"],["62028.60","0.003"],["62080.00","0.467"],["62160.00","0.462"],["62240.00","0.457"],["62472.70","0.080"],["62627.40","0.270"],["63966.00","1.463"]],"st":1}}
{"schema_version":"1.3.0","event_id":"07b63139-9499-4505-996b-ba703e8e693b","event_type":"raw.trade","source":"binance_market_data_recorder","venue":"binance_usdm","market_type":"perpetual_futures","symbol":"BTCUSDT","event_time_ms":1783517070689,"received_time_ms":1783517070685,"trace_id":"83970507-a8a3-4360-b28b-a445a67a0478","trade_id":7881418126,"price":"61854.20","quantity":"0.047","trade_time_ms":1783517070689,"is_buyer_maker":false,"aggressor_side":"buy","raw":{"e":"trade","E":1783517070689,"T":1783517070689,"s":"BTCUSDT","t":7881418126,"p":"61854.20","q":"0.047","X":"MARKET","m":false,"st":1}}
