{"schema_version":"1.3.0","event_id":"4c4d3eb5-d38c-4b7a-82b9-857272d69387","event_type":"raw.trade","source":"binance_market_data_recorder","venue":"binance_usdm","market_type":"perpetual_futures","symbol":"ETHUSDT","event_time_ms":1783517064678,"received_time_ms":1783517064674,"trace_id":"ca41ca65-b58e-4b9d-9614-e2a16d1f96eb","trade_id":8429826586,"price":"1736.17","quantity":"3.240","trade_time_ms":1783517064678,"is_buyer_maker":false,"aggressor_side":"buy","raw":{"e":"trade","E":1783517064678,"T":1783517064678,"s":"ETHUSDT","t":8429826586,"p":"1736.17","q":"3.240","X":"MARKET","m":false,"st":1}}
{"schema_version":"1.3.0","event_id":"4ea023a4-635f-4417-9d49-3a5f3aefa223","event_type":"raw.trade","source":"binance_market_data_recorder","venue":"binance_usdm","market_type":"perpetual_futures","symbol":"ETHUSDT","event_time_ms":1783517064689,"received_time_ms":1783517064841,"trace_id":"f14a6060-7a61-4a2a-847a-b1059cbd7048","trade_id":8429826587,"price":"1736.16","quantity":"11.280","trade_time_ms":1783517064689,"is_buyer_maker":true,"aggressor_side":"sell","raw":{"e":"trade","E":1783517064689,"T":1783517064689,"s":"ETHUSDT","t":8429826587,"p":"1736.16","q":"11.280","X":"MARKET","m":true,"st":1}}
{"schema_version":"1.3.0","event_id":"fbb506b0-d20f-4d58-9c5c-11769a287d8e","event_type":"raw.trade","source":"binance_market_data_recorder","venue":"binance_usdm","market_type":"perpetual_futures","symbol":"ETHUSDT","event_time_ms":1783517064689,"received_time_ms":1783517064841,"trace_id":"4121d615-c021-420d-ad6e-c599bfd3102c","trade_id":8429826588,"price":"1736.16","quantity":"0.800","trade_time_ms":1783517064689,"is_buyer_maker":true,"aggressor_side":"sell","raw":{"e":"trade","E":1783517064689,"T":1783517064689,"s":"ETHUSDT","t":8429826588,"p":"1736.16","q":"0.800","X":"MARKET","m":true,"st":1}}
{"schema_version":"1.3.0","event_id":"7ebff362-2f4a-476d-980a-843d9be72079","event_type":"raw.trade","source":"binance_market_data_recorder","venue":"binance_usdm","market_type":"perpetual_futures","symbol":"ETHUSDT","event_time_ms":1783517064689,"received_time_ms":1783517064841,"trace_id":"054905f9-1936-4096-a652-e1621e4bb232","trade_id":8429826589,"price":"1736.16","quantity":"5.859","trade_time_ms":1783517064689,"is_buyer_maker":true,"aggressor_side":"sell","raw":{"e":"trade","E":1783517064689,"T":1783517064689,"s":"ETHUSDT","t":8429826589,"p":"1736.16","q":"5.859","X":"MARKET","m":true,"st":1}}
{"schema_version":"1.3.0","event_id":"45864779-ceb7-4701-9194-d6987a978f98","event_type":"raw.trade","source":"binance_market_data_recorder","venue":"binance_usdm","market_type":"perpetual_futures","symbol":"ETHUSDT","event_time_ms":1783517064689,"received_time_ms":1783517064842,"trace_id":"29e7677c-ed86-4002-a2b9-587b7658212e","trade_id":8429826590,"price":"1736.16","quantity":"1.081","trade_time_ms":1783517064689,"is_buyer_maker":true,"aggressor_side":"sell","raw":{"e":"trade","E":1783517064689,"T":1783517064689,"s":"ETHUSDT","t":8429826590,"p":"1736.16","q":"1.081","X":"MARKET","m":true,"st":1}}
{"schema_version":"1.3.0","event_id":"1941f85d-41d9-42d0-aaf3-567fc48fdabe","event_type":"raw.depth_update","source":"binance_market_data_recorder","venue":"binance_usdm","market_type":"perpetual_futures","symbol":"ETHUSDT","event_time_ms":1783517064722,"received_time_ms":1783517064847,"trace_id":"1d5244e4-079a-404b-ab15-f332682f0a66","first_update_id":10999770325756,"final_update_id":10999770337339,"previous_final_update_id":10999770325378,"bids":[{"price":"200.00","quantity":"7.594"},{"price":"1221.16","quantity":"3.936"},{"price":"1226.12","quantity":"2.304"},{"price":"1226.16","quantity":"3.232"},{"price":"1231.12","quantity":"0.096"},{"price":"1562.20","quantity":"2.061"},{"price":"1562.54","quantity":"0.212"},{"price":"1562.55","quantity":"3.315"},{"price":"1664.00","quantity":"1634.980"},{"price":"1666.70","quantity":"0.825"},{"price":"1684.56","quantity":"127.483"},{"price":"1700.40","quantity":"29.731"},{"price":"1701.44","quantity":"50.079"},{"price":"1710.10","quantity":"46.767"},{"price":"1718.79","quantity":"59.185"},{"price":"1730.07","quantity":"135.828"},{"price":"1730.08","quantity":"26.320"},{"price":"1730.09","quantity":"4.351"},{"price":"1732.11","quantity":"4.445"},{"price":"1733.50","quantity":"15.160"},{"price":"1733.94","quantity":"427.279"},{"price":"1733.95","quantity":"5.388"},{"price":"1734.00","quantity":"215.521"},{"price":"1734.05","quantity":"13.575"},{"price":"1734.18","quantity":"0.012"},{"price":"1734.22","quantity":"17.048"},{"price":"1734.54","quantity":"13.457"},{"price":"1735.16","quantity":"3.810"},{"price":"1735.74","quantity":"247.263"},{"price":"1735.80","quantity":"0.118"},{"price":"1735.83","quantity":"47.595"},{"price":"1735.85","quantity":"7.428"},{"price":"1735.94","quantity":"35.092"},{"price":"1735.97","quantity":"7.513"},{"price":"1736.09","quantity":"13.444"},{"price":"1736.11","quantity":"1.178"},{"price":"1736.12","quantity":"24.913"},{"price":"1736.14","quantity":"71.818"},{"price":"1736.16","quantity":"439.072"}],"asks":[{"price":"1736.17","quantity":"16.536"},{"price":"1736.21","quantity":"3.121"},{"price":"1736.36","quantity":"1.740"},{"price":"1736.43","quantity":"10.243"},{"price":"1736.76","quantity":"43.509"},{"price":"1736.85","quantity":"0.458"},{"price":"1736.94","quantity":"19.186"},{"price":"1737.00","quantity":"97.908"},{"price":"1737.09","quantity":"24.470"},{"price":"1737.11","quantity":"23.216"},{"price":"1737.26","quantity":"2.255"},{"price":"1737.29","quantity":"1.832"},{"price":"1737.44","quantity":"49.160"},{"price":"1737.46","quantity":"8.656"},{"price":"1737.61","quantity":"10.732"},{"price":"1737.63","quantity":"0.093"},{"price":"1737.73","quantity":"4.121"},{"price":"1737.78","quantity":"3.890"},{"price":"1738.08","quantity":"411.967"},{"price":"1738.78","quantity":"3.752"},{"price":"1738.89","quantity":"56.491"},{"price":"1738.98","quantity":"43.816"},{"price":"1740.25","quantity":"4.091"},{"price":"1750.81","quantity":"0.003"},{"price":"2635.25","quantity":"0.004"},{"price":"2635.26","quantity":"0.001"},{"price":"2635.34","quantity":"0.000"},{"price":"2635.35","quantity":"0.150"}],"raw":{"e":"depthUpdate","E":1783517064722,"T":1783517064721,"s":"ETHUSDT","ps":"ETHUSDT","U":10999770325756,"u":10999770337339,"pu":10999770325378,"b":[["200.00","7.594"],["1221.16","3.936"],["1226.12","2.304"],["1226.16","3.232"],["1231.12","0.096"],["1562.20","2.061"],["1562.54","0.212"],["1562.55","3.315"],["1664.00","1634.980"],["1666.70","0.825"],["1684.56","127.483"],["1700.40","29.731"],["1701.44","50.079"],["1710.10","46.767"],["1718.79","59.185"],["1730.07","135.828"],["1730.08","26.320"],["1730.09","4.351"],["1732.11","4.445"],["1733.50","15.160"],["1733.94","427.279"],["1733.95","5.388"],["1734.00","215.521"],["1734.05","13.575"],["1734.18","0.012"],["1734.22","17.048"],["1734.54","13.457"],["1735.16","3.810"],["1735.74","247.263"],["1735.80","0.118"],["1735.83","47.595"],["1735.85","7.428"],["1735.94","35.092"],["1735.97","7.513"],["1736.09","13.444"],["1736.11","1.178"],["1736.12","24.913"],["1736.14","71.818"],["1736.16","439.072"]],"a":[["1736.17","16.536"],["1736.21","3.121"],["1736.36","1.740"],["1736.43","10.243"],["1736.76","43.509"],["1736.85","0.458"],["1736.94","19.186"],["1737.00","97.908"],["1737.09","24.470"],["1737.11","23.216"],["1737.26","2.255"],["1737.29","1.832"],["1737.44","49.160"],["1737.46","8.656"],["1737.61","10.732"],["1737.63","0.093"],["1737.73","4.121"],["1737.78","3.890"],["1738.08","411.967"],["1738.78","3.752"],["1738.89","56.491"],["1738.98","43.816"],["1740.25","4.091"],["1750.81","0.003"],["2635.25","0.004"],["2635.26","0.001"],["2635.34","0.000"],["2635.35","0.150"]],"st":1}}
{"schema_version":"1.3.0","event_id":"8d832cfb-057b-491c-92bb-e34a92e7c156","event_type":"raw.trade","source":"binance_market_data_recorder","venue":"binance_usdm","market_type":"perpetual_futures","symbol":"ETHUSDT","event_time_ms":1783517064736,"received_time_ms":1783517064852,"trace_id":"4237c661-6959-4354-966d-955a266f3c03","trade_id":8429826591,"price":"1736.17","quantity":"0.069","trade_time_ms":1783517064736,"is_buyer_maker":false,"aggressor_side":"buy","raw":{"e":"trade","E":1783517064736,"T":1783517064736,"s":"ETHUSDT","t":8429826591,"p":"1736.17","q":"0.069","X":"MARKET","m":false,"st":1}}
{"schema_version":"1.3.0","event_id":"26966e9b-c1ff-45dd-a256-40b22cea11a5","event_type":"raw.depth_update","source":"binance_market_data_recorder","venue":"binance_usdm","market_type":"perpetual_futures","symbol":"BTCUSDT","event_time_ms":1783517064762,"received_time_ms":1783517064855,"trace_id":"53c202f8-fae2-4e90-954d-01cfdb46e839","first_update_id":10999770331228,"final_update_id":10999770341720,"previous_final_update_id":10999770330898,"bids":[{"price":"11452.20","quantity":"0.192"},{"price":"11552.20","quantity":"2.720"},{"price":"11652.20","quantity":"1.036"},{"price":"11752.20","quantity":"0.952"},{"price":"55666.90","quantity":"0.003"},{"price":"58759.50","quantity":"0.000"},{"price":"59378.10","quantity":"0.003"},{"price":"60788.30","quantity":"1.306"},{"price":"60831.60","quantity":"1.166"},{"price":"60844.70","quantity":"4.436"},{"price":"60862.60","quantity":"3.446"},{"price":"60893.50","quantity":"3.449"},{"price":"60937.40","quantity":"13.601"},{"price":"60996.20","quantity":"0.001"},{"price":"61092.00","quantity":"9.171"},{"price":"61233.70","quantity":"0.000"},{"price":"61266.60","quantity":"2.383"},{"price":"61286.90","quantity":"0.014"},{"price":"61294.30","quantity":"1.191"},{"price":"61542.90","quantity":"0.011"},{"price":"61811.60","quantity":"0.069"},{"price":"61815.40","quantity":"0.105"},{"price":"61815.50","quantity":"0.104"},{"price":"61820.50","quantity":"0.656"},{"price":"61821.00","quantity":"0.793"},{"price":"61823.50","quantity":"0.092"},{"price":"61823.80","quantity":"0.203"},{"price":"61823.90","quantity":"0.105"},{"price":"61824.10","quantity":"0.110"},{"price":"61825.10","quantity":"0.263"},{"price":"61830.40","quantity":"0.050"},{"price":"61833.90","quantity":"0.001"},{"price":"61836.50","quantity":"0.087"},{"price":"61837.90","quantity":"0.325"},{"price":"61838.00","quantity":"0.000"},{"price":"61841.80","quantity":"0.085"},{"price":"61842.00","quantity":"0.572"},{"price":"61844.20","quantity":"1.202"},{"price":"61845.00","quantity":"0.348"},{"price":"61845.10","quantity":"0.003"}],"asks":[{"price":"61853.60","quantity":"0.001"},{"price":"61868.80","quantity":"0.040"},{"price":"61872.50","quantity":"0.080"},{"price":"61896.50","quantity":"0.016"},{"price":"61925.80","quantity":"0.275"},{"price":"62172.80","quantity":"0.161"},{"price":"62470.80","quantity":"0.018"},{"price":"62576.10","quantity":"4.277"},{"price":"63089.30","quantity":"0.135"},{"price":"68037.50","quantity":"0.000"}],"raw":{"e":"depthUpdate","E":1783517064762,"T":1783517064761,"s":"BTCUSDT","ps":"BTCUSDT","U":10999770331228,"u":10999770341720,"pu":10999770330898,"b":[["11452.20","0.192"],["11552.20","2.720"],["11652.20","1.036"],["11752.20","0.952"],["55666.90","0.003"],["58759.50","0.000"],["59378.10","0.003"],["60788.30","1.306"],["60831.60","1.166"],["60844.70","4.436"],["60862.60","3.446"],["60893.50","3.449"],["60937.40","13.601"],["60996.20","0.001"],["61092.00","9.171"],["61233.70","0.000"],["61266.60","2.383"],["61286.90","0.014"],["61294.30","1.191"],["61542.90","0.011"],["61811.60","0.069"],["61815.40","0.105"],["61815.50","0.104"],["61820.50","0.656"],["61821.00","0.793"],["61823.50","0.092"],["61823.80","0.203"],["61823.90","0.105"],["61824.10","0.110"],["61825.10","0.263"],["61830.40","0.050"],["61833.90","0.001"],["61836.50","0.087"],["61837.90","0.325"],["61838.00","0.000"],["61841.80","0.085"],["61842.00","0.572"],["61844.20","1.202"],["61845.00","0.348"],["61845.10","0.003"]],"a":[["61853.60","0.001"],["61868.80","0.040"],["61872.50","0.080"],["61896.50","0.016"],["61925.80","0.275"],["62172.80","0.161"],["62470.80","0.018"],["62576.10","4.277"],["63089.30","0.135"],["68037.50","0.000"]],"st":1}}
{"schema_version":"1.3.0","event_id":"a3e6087c-25f9-4e60-82cc-45590e277408","event_type":"raw.trade","source":"binance_market_data_recorder","venue":"binance_usdm","market_type":"perpetual_futures","symbol":"BTCUSDT","event_time_ms":1783517064801,"received_time_ms":1783517064859,"trace_id":"d3d6271b-abf6-43ad-999a-b38b803ebee5","trade_id":7881417996,"price":"61852.30","quantity":"0.007","trade_time_ms":1783517064801,"is_buyer_maker":false,"aggressor_side":"buy","raw":{"e":"trade","E":1783517064801,"T":1783517064801,"s":"BTCUSDT","t":7881417996,"p":"61852.30","q":"0.007","X":"MARKET","m":false,"st":1}}
{"schema_version":"1.3.0","event_id":"fd3cefd6-8101-47c5-84d7-189d64d1deed","event_type":"raw.depth_update","source":"binance_market_data_recorder","venue":"binance_usdm","market_type":"perpetual_futures","symbol":"ETHUSDT","event_time_ms":1783517064824,"received_time_ms":1783517064862,"trace_id":"a5a31175-43a5-447d-87f6-2850843fe749","first_update_id":10999770337415,"final_update_id":10999770346741,"previous_final_update_id":10999770337339,"bids":[{"price":"200.00","quantity":"7.594"},{"price":"1221.16","quantity":"4.640"},{"price":"1226.12","quantity":"1.952"},{"price":"1226.13","quantity":"1.032"},{"price":"1226.16","quantity":"3.008"},{"price":"1231.12","quantity":"0.000"},{"price":"1562.20","quantity":"2.047"},{"price":"1562.54","quantity":"0.212"},{"price":"1562.55","quantity":"3.315"},{"price":"1666.70","quantity":"0.940"},{"price":"1701.44","quantity":"50.050"},{"price":"1708.89","quantity":"45.438"},{"price":"1710.82","quantity":"0.062"},{"price":"1732.11","quantity":"1.445"},{"price":"1732.50","quantity":"88.354"},{"price":"1732.69","quantity":"172.912"},{"price":"1733.04","quantity":"3.838"},{"price":"1733.12","quantity":"124.290"},{"price":"1733.13","quantity":"30.189"},{"price":"1733.50","quantity":"18.160"},{"price":"1733.94","quantity":"1.165"},{"price":"1733.95","quantity":"430.056"},{"price":"1734.00","quantity":"214.075"},{"price":"1734.01","quantity":"23.213"},{"price":"1734.03","quantity":"170.423"},{"price":"1734.05","quantity":"15.021"},{"price":"1734.18","quantity":"0.012"},{"price":"1734.23","quantity":"60.276"},{"price":"1735.01","quantity":"54.012"},{"price":"1735.09","quantity":"17.366"},{"price":"1735.45","quantity":"4.024"},{"price":"1735.48","quantity":"11.851"},{"price":"1735.60","quantity":"0.172"},{"price":"1735.74","quantity":"27.064"},{"price":"1735.82","quantity":"0.122"},{"price":"1735.83","quantity":"16.585"},{"price":"1735.85","quantity":"7.446"},{"price":"1735.86","quantity":"231.832"},{"price":"1735.90","quantity":"70.314"},{"price":"1735.91","quantity":"55.166"},{"price":"1736.16","quantity":"431.935"}],"asks":[{"price":"1736.17","quantity":"16.467"},{"price":"1736.21","quantity":"3.122"},{"price":"1737.00","quantity":"98.260"},{"price":"1737.12","quantity":"15.689"},{"price":"1737.15","quantity":"2.125"},{"price":"1737.26","quantity":"4.988"},{"price":"1737.49","quantity":"37.659"},{"price":"1737.69","quantity":"27.641"},{"price":"1737.73","quantity":"1.481"},{"price":"1738.11","quantity":"0.039"},{"price":"1738.13","quantity":"19.864"},{"price":"1738.47","quantity":"91.217"},{"price":"1738.80","quantity":"7.999"},{"price":"1738.97","quantity":"185.102"},{"price":"1739.70","quantity":"9.432"},{"price":"1740.24","quantity":"50.385"},{"price":"1740.97","quantity":"29.654"},{"price":"1743.21","quantity":"13.846"},{"price":"1743.22","quantity":"32.514"},{"price":"1744.38","quantity":"3.339"},{"price":"1747.12","quantity":"37.204"},{"price":"1747.76","quantity":"9.171"},{"price":"1751.20","quantity":"5.890"},{"price":"1756.61","quantity":"196.948"},{"price":"1787.39","quantity":"50.312"},{"price":"2635.23","quantity":"0.001"},{"price":"2635.24","quantity":"0.001"},{"price":"2635.32","quantity":"0.000"},{"price":"2635.33","quantity":"0.000"}],"raw":{"e":"depthUpdate","E":1783517064824,"T":1783517064823,"s":"ETHUSDT","ps":"ETHUSDT","U":10999770337415,"u":10999770346741,"pu":10999770337339,"b":[["200.00","7.594"],["1221.16","4.640"],["1226.12","1.952"],["1226.13","1.032"],["1226.16","3.008"],["1231.12","0.000"],["1562.20","2.047"],["1562.54","0.212"],["1562.55","3.315"],["1666.70","0.940"],["1701.44","50.050"],["1708.89","45.438"],["1710.82","0.062"],["1732.11","1.445"],["1732.50","88.354"],["1732.69","172.912"],["1733.04","3.838"],["1733.12","124.290"],["1733.13","30.189"],["1733.50","18.160"],["1733.94","1.165"],["1733.95","430.056"],["1734.00","214.075"],["1734.01","23.213"],["1734.03","170.423"],["1734.05","15.021"],["1734.18","0.012"],["1734.23","60.276"],["1735.01","54.012"],["1735.09","17.366"],["1735.45","4.024"],["1735.48","11.851"],["1735.60","0.172"],["1735.74","27.064"],["1735.82","0.122"],["1735.83","16.585"],["1735.85","7.446"],["1735.86","231.832"],["1735.90","70.314"],["1735.91","55.166"],["1736.16","431.935"]],"a":[["1736.17","16.467"],["1736.21","3.122"],["1737.00","98.260"],["1737.12","15.689"],["1737.15","2.125"],["1737.26","4.988"],["1737.49","37.659"],["1737.69","27.641"],["1737.73","1.481"],["1738.11","0.039"],["1738.13","19.864"],["1738.47","91.217"],["1738.80","7.999"],["1738.97","185.102"],["1739.70","9.432"],["1740.24","50.385"],["1740.97","29.654"],["1743.21","13.846"],["1743.22","32.514"],["1744.38","3.339"],["1747.12","37.204"],["1747.76","9.171"],["1751.20","5.890"],["1756.61","196.948"],["1787.39","50.312"],["2635.23","0.001"],["2635.24","0.001"],["2635.32","0.000"],["2635.33","0.000"]],"st":1}}
{"schema_version":"1.3.0","event_id":"83e1b8ec-3091-4839-89f7-bb92803436ee","event_type":"raw.depth_update","source":"binance_market_data_recorder","venue":"binance_usdm","market_type":"perpetual_futures","symbol":"BTCUSDT","event_time_ms":1783517064864,"received_time_ms":1783517064866,"trace_id":"002415dd-e138-428d-b59f-ea581923a6a0","first_update_id":10999770341905,"final_update_id":10999770349305,"previous_final_update_id":10999770341720,"bids":[{"price":"1000.00","quantity":"207.692"},{"price":"11452.20","quantity":"0.320"},{"price":"11552.20","quantity":"2.736"},{"price":"11652.20","quantity":"1.028"},{"price":"11752.20","quantity":"0.816"},{"price":"55666.90","quantity":"0.003"},{"price":"56500.00","quantity":"24.888"},{"price":"58759.50","quantity":"0.000"},{"price":"59378.10","quantity":"0.000"},{"price":"60806.90","quantity":"0.586"},{"price":"60813.70","quantity":"3.037"},{"price":"60862.60","quantity":"4.595"},{"price":"60937.40","quantity":"12.454"},{"price":"60955.30","quantity":"6.882"},{"price":"61122.90","quantity":"1.964"},{"price":"61233.70","quantity":"0.000"},{"price":"61270.30","quantity":"0.031"},{"price":"61295.50","quantity":"1.638"},{"price":"61542.90","quantity":"0.011"},{"price":"61700.30","quantity":"0.528"},{"price":"61721.80","quantity":"0.272"},{"price":"61747.80","quantity":"0.000"},{"price":"61747.90","quantity":"0.017"},{"price":"61763.70","quantity":"0.008"},{"price":"61808.30","quantity":"1.119"},{"price":"61814.50","quantity":"0.003"},{"price":"61815.40","quantity":"0.004"},{"price":"61815.50","quantity":"0.003"},{"price":"61826.10","quantity":"0.003"},{"price":"61827.10","quantity":"0.583"},{"price":"61827.90","quantity":"0.004"},{"price":"61828.10","quantity":"0.001"},{"price":"61830.40","quantity":"0.050"},{"price":"61836.50","quantity":"0.007"},{"price":"61841.80","quantity":"0.085"},{"price":"61842.20","quantity":"0.141"},{"price":"61848.10","quantity":"0.080"}],"asks":[{"price":"61852.30","quantity":"2.290"},{"price":"61853.30","quantity":"0.007"},{"price":"61925.80","quantity":"0.275"},{"price":"61986.80","quantity":"0.707"},{"price":"61987.10","quantity":"0.000"},{"price":"62008.30","quantity":"1.289"},{"price":"62009.50","quantity":"0.000"},{"price":"62026.00","quantity":"0.000"},{"price":"62026.20","quantity":"0.003"},{"price":"62147.50","quantity":"0.018"},{"price":"62170.90","quantity":"0.052"},{"price":"62470.80","quantity":"0.018"},{"price":"62588.30","quantity":"0.958"},{"price":"62594.50","quantity":"5.181"},{"price":"62792.00","quantity":"0.000"},{"price":"89523.20","quantity":"0.666"}],"raw":{"e":"depthUpdate","E":1783517064864,"T":1783517064863,"s":"BTCUSDT","ps":"BTCUSDT","U":10999770341905,"u":10999770349305,"pu":10999770341720,"b":[["1000.00","207.692"],["11452.20","0.320"],["11552.20","2.736"],["11652.20","1.028"],["11752.20","0.816"],["55666.90","0.003"],["56500.00","24.888"],["58759.50","0.000"],["59378.10","0.000"],["60806.90","0.586"],["60813.70","3.037"],["60862.60","4.595"],["60937.40","12.454"],["60955.30","6.882"],["61122.90","1.964"],["61233.70","0.000"],["61270.30","0.031"],["61295.50","1.638"],["61542.90","0.011"],["61700.30","0.528"],["61721.80","0.272"],["61747.80","0.000"],["61747.90","0.017"],["61763.70","0.008"],["61808.30","1.119"],["61814.50","0.003"],["61815.40","0.004"],["61815.50","0.003"],["61826.10","0.003"],["61827.10","0.583"],["61827.90","0.004"],["61828.10","0.001"],["61830.40","0.050"],["61836.50","0.007"],["61841.80","0.085"],["61842.20","0.141"],["61848.10","0.080"]],"a":[["61852.30","2.290"],["61853.30","0.007"],["61925.80","0.275"],["61986.80","0.707"],["61987.10","0.000"],["62008.30","1.289"],["62009.50","0.000"],["62026.00","0.000"],["62026.20","0.003"],["62147.50","0.018"],["62170.90","0.052"],["62470.80","0.018"],["62588.30","0.958"],["62594.50","5.181"],["62792.00","0.000"],["89523.20","0.666"]],"st":1}}
{"schema_version":"1.3.0","event_id":"e23863d9-820c-4fb7-8ac2-f7a8f51c92e8","event_type":"raw.depth_update","source":"binance_market_data_recorder","venue":"binance_usdm","market_type":"perpetual_futures","symbol":"ETHUSDT","event_time_ms":1783517064926,"received_time_ms":1783517065028,"trace_id":"d901460f-0f16-40e7-930f-8513e9428c19","first_update_id":10999770346768,"final_update_id":10999770354008,"previous_final_update_id":10999770346741,"bids":[{"price":"1221.16","quantity":"5.472"},{"price":"1226.12","quantity":"1.376"},{"price":"1226.16","quantity":"2.752"},{"price":"1562.54","quantity":"0.212"},{"price":"1562.55","quantity":"3.187"},{"price":"1684.94","quantity":"80.159"},{"price":"1705.75","quantity":"58.547"},{"price":"1710.29","quantity":"90.674"},{"price":"1714.42","quantity":"34.373"},{"price":"1715.00","quantity":"1024.454"},{"price":"1730.81","quantity":"19.773"},{"price":"1735.48","quantity":"8.972"},{"price":"1735.68","quantity":"18.139"},{"price":"1736.02","quantity":"2.398"},{"price":"1736.16","quantity":"439.095"}],"asks":[{"price":"1736.36","quantity":"1.740"},{"price":"1736.74","quantity":"0.062"},{"price":"1737.17","quantity":"1.620"},{"price":"1741.65","quantity":"15.319"},{"price":"1741.67","quantity":"0.013"},{"price":"1763.25","quantity":"111.485"},{"price":"1763.30","quantity":"63.431"},{"price":"1763.43","quantity":"0.026"},{"price":"1766.35","quantity":"18.079"},{"price":"1767.02","quantity":"98.467"},{"price":"2635.22","quantity":"0.001"},{"price":"2635.31","quantity":"0.000"}],"raw":{"e":"depthUpdate","E":1783517064926,"T":1783517064925,"s":"ETHUSDT","ps":"ETHUSDT","U":10999770346768,"u":10999770354008,"pu":10999770346741,"b":[["1221.16","5.472"],["1226.12","1.376"],["1226.16","2.752"],["1562.54","0.212"],["1562.55","3.187"],["1684.94","80.159"],["1705.75","58.547"],["1710.29","90.674"],["1714.42","34.373"],["1715.00","1024.454"],["1730.81","19.773"],["1735.48","8.972"],["1735.68","18.139"],["1736.02","2.398"],["1736.16","439.095"]],"a":[["1736.36","1.740"],["1736.74","0.062"],["1737.17","1.620"],["1741.65","15.319"],["1741.67","0.013"],["1763.25","111.485"],["1763.30","63.431"],["1763.43","0.026"],["1766.35","18.079"],["1767.02","98.467"],["2635.22","0.001"],["2635.31","0.000"]],"st":1}}
{"schema_version":"1.3.0","event_id":"7643747b-c13c-463c-bb87-6a5e39d61832","event_type":"raw.depth_update","source":"binance_market_data_recorder","venue":"binance_usdm","market_type":"perpetual_futures","symbol":"BTCUSDT","event_time_ms":1783517064966,"received_time_ms":1783517065045,"trace_id":"59f8b9a9-96d1-4315-be15-34cac6bc4202","first_update_id":10999770349344,"final_update_id":10999770358284,"previous_final_update_id":10999770349305,"bids":[{"price":"1000.00","quantity":"207.692"},{"price":"11452.20","quantity":"0.464"},{"price":"11552.20","quantity":"2.720"},{"price":"11652.20","quantity":"1.053"},{"price":"11752.20","quantity":"0.663"},{"price":"55666.90","quantity":"0.003"},{"price":"60992.50","quantity":"0.982"},{"price":"61150.80","quantity":"0.245"},{"price":"61163.20","quantity":"0.245"},{"price":"61233.70","quantity":"0.002"},{"price":"61274.50","quantity":"0.245"},{"price":"61295.50","quantity":"1.882"},{"price":"61759.40","quantity":"0.000"},{"price":"61760.30","quantity":"0.214"},{"price":"61762.90","quantity":"1.941"},{"price":"61767.50","quantity":"0.281"},{"price":"61821.70","quantity":"1.088"},{"price":"61822.50","quantity":"0.761"},{"price":"61823.50","quantity":"0.092"},{"price":"61828.10","quantity":"0.081"},{"price":"61842.00","quantity":"0.006"},{"price":"61842.20","quantity":"0.061"},{"price":"61845.10","quantity":"0.569"},{"price":"61852.20","quantity":"16.123"}],"asks":[{"price":"61852.30","quantity":"1.000"},{"price":"61852.40","quantity":"0.002"},{"price":"61854.90","quantity":"0.148"},{"price":"61856.30","quantity":"0.032"},{"price":"61856.40","quantity":"0.791"},{"price":"61856.90","quantity":"1.617"},{"price":"61857.40","quantity":"1.274"},{"price":"61858.30","quantity":"0.383"},{"price":"61861.00","quantity":"0.047"},{"price":"61865.20","quantity":"0.015"},{"price":"61868.90","quantity":"0.112"},{"price":"61869.10","quantity":"0.004"},{"price":"61871.30","quantity":"0.151"},{"price":"61872.80","quantity":"0.000"},{"price":"61873.60","quantity":"0.035"},{"price":"61878.10","quantity":"0.000"},{"price":"61878.30","quantity":"0.040"},{"price":"61880.70","quantity":"0.236"},{"price":"61887.90","quantity":"0.484"},{"price":"61888.00","quantity":"0.599"},{"price":"61888.80","quantity":"0.057"},{"price":"61925.80","quantity":"0.275"},{"price":"61984.80","quantity":"0.000"},{"price":"62022.50","quantity":"0.162"},{"price":"62056.10","quantity":"0.002"},{"price":"62417.50","quantity":"3.182"},{"price":"62470.80","quantity":"0.000"},{"price":"62594.50","quantity":"5.452"}],"raw":{"e":"depthUpdate","E":1783517064966,"T":1783517064965,"s":"BTCUSDT","ps":"BTCUSDT","U":10999770349344,"u":10999770358284,"pu":10999770349305,"b":[["1000.00","207.692"],["11452.20","0.464"],["11552.20","2.720"],["11652.20","1.053"],["11752.20","0.663"],["55666.90","0.003"],["60992.50","0.982"],["61150.80","0.245"],["61163.20","0.245"],["61233.70","0.002"],["61274.50","0.245"],["61295.50","1.882"],["61759.40","0.000"],["61760.30","0.214"],["61762.90","1.941"],["61767.50","0.281"],["61821.70","1.088"],["61822.50","0.761"],["61823.50","0.092"],["61828.10","0.081"],["61842.00","0.006"],["61842.20","0.061"],["61845.10","0.569"],["61852.20","16.123"]],"a":[["61852.30","1.000"],["61852.40","0.002"],["61854.90","0.148"],["61856.30","0.032"],["61856.40","0.791"],["61856.90","1.617"],["61857.40","1.274"],["61858.30","0.383"],["61861.00","0.047"],["61865.20","0.015"],["61868.90","0.112"],["61869.10","0.004"],["61871.30","0.151"],["61872.80","0.000"],["61873.60","0.035"],["61878.10","0.000"],["61878.30","0.040"],["61880.70","0.236"],["61887.90","0.484"],["61888.00","0.599"],["61888.80","0.057"],["61925.80","0.275"],["61984.80","0.000"],["62022.50","0.162"],["62056.10","0.002"],["62417.50","3.182"],["62470.80","0.000"],["62594.50","5.452"]],"st":1}}
{"schema_version":"1.3.0","event_id":"578aeb54-fded-4617-8896-59b5c3ba019f","event_type":"raw.trade","source":"binance_market_data_recorder","venue":"binance_usdm","market_type":"perpetual_futures","symbol":"ETHUSDT","event_time_ms":1783517064994,"received_time_ms":1783517065046,"trace_id":"04c9de50-8e41-4bd1-871b-bfb1033ce77c","trade_id":8429826592,"price":"1736.17","quantity":"0.012","trade_time_ms":1783517064994,"is_buyer_maker":false,"aggressor_side":"buy","raw":{"e":"trade","E":1783517064994,"T":1783517064994,"s":"ETHUSDT","t":8429826592,"p":"1736.17","q":"0.012","X":"MARKET","m":false,"st":1}}
{"schema_version":"1.3.0","event_id":"ae0b4846-9c42-4904-9332-eefa124255ee","event_type":"raw.depth_update","source":"binance_market_data_recorder","venue":"binance_usdm","market_type":"perpetual_futures","symbol":"ETHUSDT","event_time_ms":1783517065028,"received_time_ms":1783517065050,"trace_id":"e70d106f-a5e7-48a6-b01c-3815a638e423","first_update_id":10999770354074,"final_update_id":10999770364171,"previous_final_update_id":10999770354008,"bids":[{"price":"200.00","quantity":"7.594"},{"price":"1221.16","quantity":"6.272"},{"price":"1226.12","quantity":"0.864"},{"price":"1226.16","quantity":"2.464"},{"price":"1562.54","quantity":"0.212"},{"price":"1562.55","quantity":"3.201"},{"price":"1666.70","quantity":"0.825"},{"price":"1684.56","quantity":"100.806"},{"price":"1700.57","quantity":"61.745"},{"price":"1701.44","quantity":"50.079"},{"price":"1706.13","quantity":"40.974"},{"price":"1729.79","quantity":"27.356"},{"price":"1729.95","quantity":"17.689"},{"price":"1730.81","quantity":"19.847"},{"price":"1733.95","quantity":"3.942"},{"price":"1734.01","quantity":"21.767"},{"price":"1734.03","quantity":"111.557"},{"price":"1734.18","quantity":"426.126"},{"price":"1735.16","quantity":"3.810"},{"price":"1735.24","quantity":"1.449"},{"price":"1735.25","quantity":"1.011"},{"price":"1735.26","quantity":"0.123"},{"price":"1735.65","quantity":"19.245"},{"price":"1735.68","quantity":"235.752"},{"price":"1735.73","quantity":"34.593"},{"price":"1735.74","quantity":"58.687"},{"price":"1735.75","quantity":"73.010"},{"price":"1735.86","quantity":"11.574"},{"price":"1735.91","quantity":"18.473"},{"price":"1736.04","quantity":"8.424"},{"price":"1736.16","quantity":"431.883"}],"asks":[{"price":"1736.17","quantity":"27.281"},{"price":"1736.19","quantity":"2.607"},{"price":"1736.27","quantity":"0.059"},{"price":"1736.28","quantity":"1.083"},{"price":"1736.33","quantity":"1.752"},{"price":"1736.37","quantity":"21.093"},{"price":"1736.57","quantity":"12.657"},{"price":"1736.60","quantity":"3.462"},{"price":"1736.61","quantity":"6.517"},{"price":"1736.66","quantity":"67.370"},{"price":"1736.80","quantity":"8.903"},{"price":"1736.82","quantity":"19.064"},{"price":"1736.93","quantity":"33.071"},{"price":"1736.94","quantity":"19.174"},{"price":"1737.06","quantity":"26.658"},{"price":"1737.07","quantity":"7.497"},{"price":"1737.09","quantity":"35.632"},{"price":"1737.12","quantity":"13.995"},{"price":"1737.21","quantity":"3.524"},{"price":"1737.22","quantity":"3.552"},{"price":"1737.65","quantity":"4.106"},{"price":"1737.82","quantity":"16.693"},{"price":"1737.89","quantity":"33.500"},{"price":"1738.96","quantity":"3.196"},{"price":"1738.98","quantity":"40.620"},{"price":"1741.65","quantity":"15.319"},{"price":"1742.27","quantity":"3.761"},{"price":"1742.50","quantity":"9.733"},{"price":"1753.49","quantity":"0.413"},{"price":"1755.00","quantity":"590.178"},{"price":"1760.00","quantity":"903.543"},{"price":"1763.25","quantity":"91.834"},{"price":"2635.20","quantity":"0.016"},{"price":"2635.21","quantity":"0.001"},{"price":"2635.29","quantity":"0.000"},{"price":"2635.30","quantity":"0.016"}],"raw":{"e":"depthUpdate","E":1783517065028,"T":1783517065025,"s":"ETHUSDT","ps":"ETHUSDT","U":10999770354074,"u":10999770364171,"pu":10999770354008,"b":[["200.00","7.594"],["1221.16","6.272"],["1226.12","0.864"],["1226.16","2.464"],["1562.54","0.212"],["1562.55","3.201"],["1666.70","0.825"],["1684.56","100.806"],["1700.57","61.745"],["1701.44","50.079"],["1706.13","40.974"],["1729.79","27.356"],["1729.95","17.689"],["1730.81","19.847"],["1733.95","3.942"],["1734.01","21.767"],["1734.03","111.557"],["1734.18","426.126"],["1735.16","3.810"],["1735.24","1.449"],["1735.25","1.011"],["1735.26","0.123"],["1735.65","19.245"],["1735.68","235.752"],["1735.73","34.593"],["1735.74","58.687"],["1735.75","73.010"],["1735.86","11.574"],["1735.91","18.473"],["1736.04","8.424"],["1736.16","431.883"]],"a":[["1736.17","27.281"],["1736.19","2.607"],["1736.27","0.059"],["1736.28","1.083"],["1736.33","1.752"],["1736.37","21.093"],["1736.57","12.657"],["1736.60","3.462"],["1736.61","6.517"],["1736.66","67.370"],["1736.80","8.903"],["1736.82","19.064"],["1736.93","33.071"],["1736.94","19.174"],["1737.06","26.658"],["1737.07","7.497"],["1737.09","35.632"],["1737.12","13.995"],["1737.21","3.524"],["1737.22","3.552"],["1737.65","4.106"],["1737.82","16.693"],["1737.89","33.500"],["1738.96","3.196"],["1738.98","40.620"],["1741.65","15.319"],["1742.27","3.761"],["1742.50","9.733"],["1753.49","0.413"],["1755.00","590.178"],["1760.00","903.543"],["1763.25","91.834"],["2635.20","0.016"],["2635.21","0.001"],["2635.29","0.000"],["2635.30","0.016"]],"st":1}}
{"schema_version":"1.3.0","event_id":"4ea2e64e-2bd0-47fe-91e3-83bf91395017","event_type":"raw.depth_update","source":"binance_market_data_recorder","venue":"binance_usdm","market_type":"perpetual_futures","symbol":"BTCUSDT","event_time_ms":1783517065068,"received_time_ms":1783517065062,"trace_id":"68f15238-759a-404a-87f9-06d7d94ac8b4","first_update_id":10999770358435,"final_update_id":10999770367988,"previous_final_update_id":10999770358284,"bids":[{"price":"11452.20","quantity":"0.720"},{"price":"11552.20","quantity":"2.480"},{"price":"11652.20","quantity":"1.173"},{"price":"11752.20","quantity":"0.527"},{"price":"55666.90","quantity":"0.003"},{"price":"58759.50","quantity":"0.020"},{"price":"59378.10","quantity":"0.003"},{"price":"60615.20","quantity":"0.057"},{"price":"60875.60","quantity":"5.333"},{"price":"60937.40","quantity":"11.307"},{"price":"61079.00","quantity":"0.974"},{"price":"61122.90","quantity":"0.984"},{"price":"61140.90","quantity":"3.920"},{"price":"61163.20","quantity":"0.000"},{"price":"61233.70","quantity":"0.000"},{"price":"61315.50","quantity":"0.018"},{"price":"61745.70","quantity":"5.883"},{"price":"61746.10","quantity":"0.007"},{"price":"61748.60","quantity":"0.927"},{"price":"61787.20","quantity":"0.051"},{"price":"61787.50","quantity":"0.030"},{"price":"61808.30","quantity":"1.115"},{"price":"61814.50","quantity":"0.007"},{"price":"61828.10","quantity":"0.001"},{"price":"61830.40","quantity":"0.050"},{"price":"61833.10","quantity":"0.407"},{"price":"61835.70","quantity":"0.569"},{"price":"61836.70","quantity":"0.006"},{"price":"61837.60","quantity":"1.240"},{"price":"61841.10","quantity":"0.405"},{"price":"61841.80","quantity":"0.990"},{"price":"61842.20","quantity":"0.141"},{"price":"61845.00","quantity":"0.009"},{"price":"61845.10","quantity":"0.003"},{"price":"61848.10","quantity":"0.000"},{"price":"61850.80","quantity":"0.000"},{"price":"61852.20","quantity":"16.124"}],"asks":[{"price":"61852.30","quantity":"2.293"},{"price":"61852.40","quantity":"0.003"},{"price":"61853.20","quantity":"0.002"},{"price":"61854.90","quantity":"0.022"},{"price":"61856.30","quantity":"1.648"},{"price":"61856.40","quantity":"1.791"},{"price":"61856.90","quantity":"0.001"},{"price":"61857.40","quantity":"0.274"},{"price":"61857.60","quantity":"0.633"},{"price":"61858.50","quantity":"0.540"},{"price":"61859.60","quantity":"0.453"},{"price":"61859.70","quantity":"2.138"},{"price":"61860.40","quantity":"1.785"},{"price":"61862.50","quantity":"0.001"},{"price":"61863.20","quantity":"1.423"},{"price":"61863.40","quantity":"0.033"},{"price":"61864.20","quantity":"0.011"},{"price":"61864.70","quantity":"3.064"},{"price":"61864.90","quantity":"0.054"},{"price":"61866.80","quantity":"3.442"},{"price":"61870.90","quantity":"0.149"},{"price":"61878.10","quantity":"0.002"},{"price":"61887.20","quantity":"0.107"},{"price":"61887.70","quantity":"0.050"},{"price":"61887.80","quantity":"0.286"},{"price":"61887.90","quantity":"0.379"},{"price":"61888.00","quantity":"0.494"},{"price":"61888.80","quantity":"0.055"},{"price":"61893.40","quantity":"0.243"},{"price":"61909.30","quantity":"0.131"},{"price":"61909.50","quantity":"2.715"},{"price":"61909.80","quantity":"0.000"},{"price":"61909.90","quantity":"0.113"},{"price":"61923.30","quantity":"0.096"},{"price":"61923.70","quantity":"0.000"},{"price":"61994.00","quantity":"4.043"},{"price":"61994.80","quantity":"0.831"},{"price":"62470.80","quantity":"0.000"},{"price":"89523.20","quantity":"0.672"}],"raw":{"e":"depthUpdate","E":1783517065068,"T":1783517065066,"s":"BTCUSDT","ps":"BTCUSDT","U":10999770358435,"u":10999770367988,"pu":10999770358284,"b":[["11452.20","0.720"],["11552.20","2.480"],["11652.20","1.173"],["11752.20","0.527"],["55666.90","0.003"],["58759.50","0.020"],["59378.10","0.003"],["60615.20","0.057"],["60875.60","5.333"],["60937.40","11.307"],["61079.00","0.974"],["61122.90","0.984"],["61140.90","3.920"],["61163.20","0.000"],["61233.70","0.000"],["61315.50","0.018"],["61745.70","5.883"],["61746.10","0.007"],["61748.60","0.927"],["61787.20","0.051"],["61787.50","0.030"],["61808.30","1.115"],["61814.50","0.007"],["61828.10","0.001"],["61830.40","0.050"],["61833.10","0.407"],["61835.70","0.569"],["61836.70","0.006"],["61837.60","1.240"],["61841.10","0.405"],["61841.80","0.990"],["61842.20","0.141"],["61845.00","0.009"],["61845.10","0.003"],["61848.10","0.000"],["61850.80","0.000"],["61852.20","16.124"]],"a":[["61852.30","2.293"],["61852.40","0.003"],["61853.20","0.002"],["61854.90","0.022"],["61856.30","1.648"],["61856.40","1.791"],["61856.90","0.001"],["61857.40","0.274"],["61857.60","0.633"],["61858.50","0.540"],["61859.60","0.453"],["61859.70","2.138"],["61860.40","1.785"],["61862.50","0.001"],["61863.20","1.423"],["61863.40","0.033"],["61864.20","0.011"],["61864.70","3.064"],["61864.90","0.054"],["61866.80","3.442"],["61870.90","0.149"],["61878.10","0.002"],["61887.20","0.107"],["61887.70","0.050"],["61887.80","0.286"],["61887.90","0.379"],["61888.00","0.494"],["61888.80","0.055"],["61893.40","0.243"],["61909.30","0.131"],["61909.50","2.715"],["61909.80","0.000"],["61909.90","0.113"],["61923.30","0.096"],["61923.70","0.000"],["61994.00","4.043"],["61994.80","0.831"],["62470.80","0.000"],["89523.20","0.672"]],"st":1}}
{"schema_version":"1.3.0","event_id":"f82a38be-284e-40a3-9846-8138f9c27211","event_type":"raw.depth_update","source":"binance_market_data_recorder","venue":"binance_usdm","market_type":"perpetual_futures","symbol":"ETHUSDT","event_time_ms":1783517065130,"received_time_ms":1783517065124,"trace_id":"f1b411fa-bc10-491e-9436-348b5fa6baab","first_update_id":10999770364652,"final_update_id":10999770372895,"previous_final_update_id":10999770364171,"bids":[{"price":"200.00","quantity":"7.594"},{"price":"1216.16","quantity":"0.032"},{"price":"1221.16","quantity":"7.040"},{"price":"1226.12","quantity":"0.320"},{"price":"1226.16","quantity":"2.208"},{"price":"1562.54","quantity":"0.212"},{"price":"1562.55","quantity":"3.329"},{"price":"1666.70","quantity":"0.940"},{"price":"1701.44","quantity":"50.050"},{"price":"1704.74","quantity":"0.416"},{"price":"1718.06","quantity":"17.342"},{"price":"1727.47","quantity":"0.012"},{"price":"1734.06","quantity":"55.627"},{"price":"1735.47","quantity":"229.898"},{"price":"1735.68","quantity":"15.278"},{"price":"1735.74","quantity":"27.064"},{"price":"1735.75","quantity":"70.131"},{"price":"1735.81","quantity":"9.313"},{"price":"1735.96","quantity":"6.464"},{"price":"1736.08","quantity":"2.058"},{"price":"1736.09","quantity":"13.432"},{"price":"1736.12","quantity":"25.113"},{"price":"1736.13","quantity":"7.553"},{"price":"1736.16","quantity":"416.626"}],"asks":[{"price":"1736.17","quantity":"36.439"},{"price":"1736.51","quantity":"19.904"},{"price":"1736.52","quantity":"26.302"},{"price":"1736.57","quantity":"10.963"},{"price":"1736.60","quantity":"1.768"},{"price":"1736.65","quantity":"29.063"},{"price":"1737.15","quantity":"0.431"},{"price":"1737.17","quantity":"1.620"},{"price":"1737.34","quantity":"14.909"},{"price":"1738.06","quantity":"81.219"},{"price":"1738.08","quantity":"410.300"},{"price":"1739.30","quantity":"5.271"},{"price":"1739.80","quantity":"5.290"},{"price":"1744.86","quantity":"40.385"},{"price":"1747.12","quantity":"52.204"},{"price":"1761.73","quantity":"0.078"},{"price":"2635.19","quantity":"0.001"},{"price":"2635.28","quantity":"0.000"}],"raw":{"e":"depthUpdate","E":1783517065130,"T":1783517065129,"s":"ETHUSDT","ps":"ETHUSDT","U":10999770364652,"u":10999770372895,"pu":10999770364171,"b":[["200.00","7.594"],["1216.16","0.032"],["1221.16","7.040"],["1226.12","0.320"],["1226.16","2.208"],["1562.54","0.212"],["1562.55","3.329"],["1666.70","0.940"],["1701.44","50.050"],["1704.74","0.416"],["1718.06","17.342"],["1727.47","0.012"],["1734.06","55.627"],["1735.47","229.898"],["1735.68","15.278"],["1735.74","27.064"],["1735.75","70.131"],["1735.81","9.313"],["1735.96","6.464"],["1736.08","2.058"],["1736.09","13.432"],["1736.12","25.113"],["1736.13","7.553"],["1736.16","416.626"]],"a":[["1736.17","36.439"],["1736.51","19.904"],["1736.52","26.302"],["1736.57","10.963"],["1736.60","1.768"],["1736.65","29.063"],["1737.15","0.431"],["1737.17","1.620"],["1737.34","14.909"],["1738.06","81.219"],["1738.08","410.300"],["1739.30","5.271"],["1739.80","5.290"],["1744.86","40.385"],["1747.12","52.204"],["1761.73","0.078"],["2635.19","0.001"],["2635.28","0.000"]],"st":1}}
{"schema_version":"1.3.0","event_id":"03741e8d-5618-4f5d-80c8-d578adc27652","event_type":"raw.depth_update","source":"binance_market_data_recorder","venue":"binance_usdm","market_type":"perpetual_futures","symbol":"BTCUSDT","event_time_ms":1783517065170,"received_time_ms":1783517065167,"trace_id":"6213d4d4-b047-48a6-9589-310c36c594e2","first_update_id":10999770368096,"final_update_id":10999770379048,"previous_final_update_id":10999770367988,"bids":[{"price":"1000.00","quantity":"207.692"},{"price":"11452.20","quantity":"0.992"},{"price":"11552.20","quantity":"2.208"},{"price":"11652.20","quantity":"1.326"},{"price":"11752.20","quantity":"0.374"},{"price":"55666.90","quantity":"0.003"},{"price":"59378.10","quantity":"0.000"},{"price":"60831.60","quantity":"2.315"},{"price":"60955.30","quantity":"8.029"},{"price":"61233.70","quantity":"0.000"},{"price":"61292.00","quantity":"1.165"},{"price":"61320.00","quantity":"2.053"},{"price":"61542.90","quantity":"0.011"},{"price":"61783.30","quantity":"0.002"},{"price":"61805.00","quantity":"2.114"},{"price":"61807.10","quantity":"0.122"},{"price":"61811.80","quantity":"0.929"},{"price":"61815.40","quantity":"0.105"},{"price":"61815.70","quantity":"0.002"},{"price":"61820.40","quantity":"0.631"},{"price":"61823.40","quantity":"0.181"},{"price":"61823.50","quantity":"0.197"},{"price":"61826.10","quantity":"0.585"},{"price":"61827.10","quantity":"0.001"},{"price":"61827.60","quantity":"0.062"},{"price":"61828.10","quantity":"0.081"},{"price":"61831.60","quantity":"0.968"},{"price":"61832.30","quantity":"0.002"},{"price":"61833.10","quantity":"0.327"},{"price":"61842.20","quantity":"0.061"}],"asks":[{"price":"61853.00","quantity":"0.045"},{"price":"61853.70","quantity":"0.026"},{"price":"61854.10","quantity":"0.126"},{"price":"61856.20","quantity":"0.066"},{"price":"61857.50","quantity":"0.324"},{"price":"61857.80","quantity":"1.156"},{"price":"61859.20","quantity":"0.010"},{"price":"61859.60","quantity":"0.130"},{"price":"61859.80","quantity":"1.210"},{"price":"61860.50","quantity":"0.972"},{"price":"61860.60","quantity":"0.002"},{"price":"61863.00","quantity":"0.053"},{"price":"61863.20","quantity":"0.455"},{"price":"61863.90","quantity":"0.309"},{"price":"61864.10","quantity":"2.329"},{"price":"61864.60","quantity":"0.567"},{"price":"61865.60","quantity":"0.005"},{"price":"61866.80","quantity":"3.427"},{"price":"61883.30","quantity":"0.000"},{"price":"61886.70","quantity":"0.105"},{"price":"61887.20","quantity":"0.107"},{"price":"61898.70","quantity":"0.256"},{"price":"61900.00","quantity":"1.358"},{"price":"61909.40","quantity":"0.371"},{"price":"61909.90","quantity":"0.214"},{"price":"61919.60","quantity":"1.648"},{"price":"61919.70","quantity":"0.000"},{"price":"61925.80","quantity":"0.372"},{"price":"62062.00","quantity":"3.033"},{"price":"62168.00","quantity":"0.004"},{"price":"62470.80","quantity":"0.000"},{"price":"62699.70","quantity":"0.560"},{"price":"62738.60","quantity":"0.000"},{"price":"62801.70","quantity":"0.278"}],"raw":{"e":"depthUpdate","E":1783517065170,"T":1783517065169,"s":"BTCUSDT","ps":"BTCUSDT","U":10999770368096,"u":10999770379048,"pu":10999770367988,"b":[["1000.00","207.692"],["11452.20","0.992"],["11552.20","2.208"],["11652.20","1.326"],["11752.20","0.374"],["55666.90","0.003"],["59378.10","0.000"],["60831.60","2.315"],["60955.30","8.029"],["61233.70","0.000"],["61292.00","1.165"],["61320.00","2.053"],["61542.90","0.011"],["61783.30","0.002"],["61805.00","2.114"],["61807.10","0.122"],["61811.80","0.929"],["61815.40","0.105"],["61815.70","0.002"],["61820.40","0.631"],["61823.40","0.181"],["61823.50","0.197"],["61826.10","0.585"],["61827.10","0.001"],["61827.60","0.062"],["61828.10","0.081"],["61831.60","0.968"],["61832.30","0.002"],["61833.10","0.327"],["61842.20","0.061"]],"a":[["61853.00","0.045"],["61853.70","0.026"],["61854.10","0.126"],["61856.20","0.066"],["61857.50","0.324"],["61857.80","1.156"],["61859.20","0.010"],["61859.60","0.130"],["61859.80","1.210"],["61860.50","0.972"],["61860.60","0.002"],["61863.00","0.053"],["61863.20","0.455"],["61863.90","0.309"],["61864.10","2.329"],["61864.60","0.567"],["61865.60","0.005"],["61866.80","3.427"],["61883.30","0.000"],["61886.70","0.105"],["61887.20","0.107"],["61898.70","0.256"],["61900.00","1.358"],["61909.40","0.371"],["61909.90","0.214"],["61919.60","1.648"],["61919.70","0.000"],["61925.80","0.372"],["62062.00","3.033"],["62168.00","0.004"],["62470.80","0.000"],["62699.70","0.560"],["62738.60","0.000"],["62801.70","0.278"]],"st":1}}
{"schema_version":"1.3.0","event_id":"58d09d85-34b5-4952-8349-d19982237899","event_type":"raw.trade","source":"binance_market_data_recorder","venue":"binance_usdm","market_type":"perpetual_futures","symbol":"BTCUSDT","event_time_ms":1783517065193,"received_time_ms":1783517065188,"trace_id":"12c369f1-077f-4990-9eec-fb1b94c810af","trade_id":7881417997,"price":"61852.30","quantity":"0.001","trade_time_ms":1783517065193,"is_buyer_maker":false,"aggressor_side":"buy","raw":{"e":"trade","E":1783517065193,"T":1783517065193,"s":"BTCUSDT","t":7881417997,"p":"61852.30","q":"0.001","X":"MARKET","m":false,"st":1}}
{"schema_version":"1.3.0","event_id":"517288d0-8395-472b-a645-3368da08b22d","event_type":"raw.trade","source":"binance_market_data_recorder","venue":"binance_usdm","market_type":"perpetual_futures","symbol":"BTCUSDT","event_time_ms":1783517065202,"received_time_ms":1783517065197,"trace_id":"dd14037f-0a6d-4b60-8970-59e5409b78c7","trade_id":7881417998,"price":"61852.30","quantity":"0.001","trade_time_ms":1783517065202,"is_buyer_maker":false,"aggressor_side":"buy","raw":{"e":"trade","E":1783517065202,"T":1783517065202,"s":"BTCUSDT","t":7881417998,"p":"61852.30","q":"0.001","X":"MARKET","m":false,"st":1}}
{"schema_version":"1.3.0","event_id":"f4b22f00-ba22-47a6-ac96-d29c40ef209a","event_type":"raw.depth_update","source":"binance_market_data_recorder","venue":"binance_usdm","market_type":"perpetual_futures","symbol":"ETHUSDT","event_time_ms":1783517065232,"received_time_ms":1783517065226,"trace_id":"7d07e169-9a91-4cfd-91d8-e7ce32748ced","first_update_id":10999770372925,"final_update_id":10999770388529,"previous_final_update_id":10999770372895,"bids":[{"price":"1216.16","quantity":"0.288"},{"price":"1221.16","quantity":"7.328"},{"price":"1226.12","quantity":"0.064"},{"price":"1226.16","quantity":"1.920"},{"price":"1562.54","quantity":"0.212"},{"price":"1562.55","quantity":"3.201"},{"price":"1666.70","quantity":"0.825"},{"price":"1701.44","quantity":"50.079"},{"price":"1706.06","quantity":"30.519"},{"price":"1733.67","quantity":"0.332"},{"price":"1733.95","quantity":"430.056"},{"price":"1734.01","quantity":"21.767"},{"price":"1734.05","quantity":"11.825"},{"price":"1734.06","quantity":"54.181"},{"price":"1734.16","quantity":"5.208"},{"price":"1734.18","quantity":"0.012"},{"price":"1734.36","quantity":"13.419"},{"price":"1735.47","quantity":"9.416"},{"price":"1735.59","quantity":"223.745"},{"price":"1735.60","quantity":"0.172"},{"price":"1736.00","quantity":"1.734"},{"price":"1736.03","quantity":"6.354"},{"price":"1736.08","quantity":"2.046"},{"price":"1736.16","quantity":"401.507"}],"asks":[{"price":"1736.17","quantity":"27.293"},{"price":"1736.18","quantity":"0.024"},{"price":"1736.27","quantity":"0.059"},{"price":"1736.36","quantity":"1.740"},{"price":"1736.62","quantity":"5.860"},{"price":"1736.66","quantity":"67.539"},{"price":"1736.83","quantity":"36.581"},{"price":"1736.96","quantity":"188.134"},{"price":"1736.97","quantity":"7.320"},{"price":"1737.27","quantity":"19.154"},{"price":"1737.82","quantity":"33.369"},{"price":"1738.80","quantity":"4.943"},{"price":"1738.86","quantity":"19.557"},{"price":"1751.13","quantity":"0.689"},{"price":"1753.54","quantity":"122.436"},{"price":"1762.04","quantity":"17.022"},{"price":"1763.89","quantity":"20.177"},{"price":"2635.17","quantity":"0.032"},{"price":"2635.18","quantity":"0.040"},{"price":"2635.26","quantity":"0.000"},{"price":"2635.27","quantity":"0.000"}],"raw":{"e":"depthUpdate","E":1783517065232,"T":1783517065229,"s":"ETHUSDT","ps":"ETHUSDT","U":10999770372925,"u":10999770388529,"pu":10999770372895,"b":[["1216.16","0.288"],["1221.16","7.328"],["1226.12","0.064"],["1226.16","1.920"],["1562.54","0.212"],["1562.55","3.201"],["1666.70","0.825"],["1701.44","50.079"],["1706.06","30.519"],["1733.67","0.332"],["1733.95","430.056"],["1734.01","21.767"],["1734.05","11.825"],["1734.06","54.181"],["1734.16","5.208"],["1734.18","0.012"],["1734.36","13.419"],["1735.47","9.416"],["1735.59","223.745"],["1735.60","0.172"],["1736.00","1.734"],["1736.03","6.354"],["1736.08","2.046"],["1736.16","401.507"]],"a":[["1736.17","27.293"],["1736.18","0.024"],["1736.27","0.059"],["1736.36","1.740"],["1736.62","5.860"],["1736.66","67.539"],["1736.83","36.581"],["1736.96","188.134"],["1736.97","7.320"],["1737.27","19.154"],["1737.82","33.369"],["1738.80","4.943"],["1738.86","19.557"],["1751.13","0.689"],["1753.54","122.436"],["1762.04","17.022"],["1763.89","20.177"],["2635.17","0.032"],["2635.18","0.040"],["2635.26","0.000"],["2635.27","0.000"]],"st":1}}
{"schema_version":"1.3.0","event_id":"38e37283-101a-45b4-8269-efd3e71fb878","event_type":"raw.trade","source":"binance_market_data_recorder","venue":"binance_usdm","market_type":"perpetual_futures","symbol":"BTCUSDT","event_time_ms":1783517065262,"received_time_ms":1783517065257,"trace_id":"dfbf2f75-030f-4a02-9689-c11a1a787711","trade_id":7881417999,"price":"61852.20","quantity":"0.125","trade_time_ms":1783517065261,"is_buyer_maker":true,"aggressor_side":"sell","raw":{"e":"trade","E":1783517065262,"T":1783517065261,"s":"BTCUSDT","t":7881417999,"p":"61852.20","q":"0.125","X":"MARKET","m":true,"st":1}}
{"schema_version":"1.3.0","event_id":"7cc88822-e775-40eb-ab5d-f2fe96b05229","event_type":"raw.depth_update","source":"binance_market_data_recorder","venue":"binance_usdm","market_type":"perpetual_futures","symbol":"BTCUSDT","event_time_ms":1783517065272,"received_time_ms":1783517065267,"trace_id":"2c2946af-afba-4c0f-9d43-89cd59fb2ce4","first_update_id":10999770379429,"final_update_id":10999770393602,"previous_final_update_id":10999770379048,"bids":[{"price":"1000.00","quantity":"207.692"},{"price":"11452.20","quantity":"1.264"},{"price":"11552.20","quantity":"1.936"},{"price":"11652.20","quantity":"1.462"},{"price":"11752.20","quantity":"0.238"},{"price":"55666.90","quantity":"0.003"},{"price":"58745.80","quantity":"0.033"},{"price":"59378.10","quantity":"0.003"},{"price":"60615.20","quantity":"0.054"},{"price":"61171.80","quantity":"0.737"},{"price":"61233.70","quantity":"0.000"},{"price":"61440.00","quantity":"0.318"},{"price":"61520.00","quantity":"2.901"},{"price":"61600.00","quantity":"56.779"},{"price":"61680.00","quantity":"0.693"},{"price":"61752.40","quantity":"0.012"},{"price":"61754.80","quantity":"1.367"},{"price":"61760.00","quantity":"0.902"},{"price":"61763.70","quantity":"0.000"},{"price":"61828.10","quantity":"0.001"},{"price":"61830.20","quantity":"1.377"},{"price":"61830.40","quantity":"0.130"},{"price":"61831.60","quantity":"0.000"},{"price":"61832.30","quantity":"0.970"},{"price":"61833.80","quantity":"0.000"},{"price":"61839.80","quantity":"0.944"},{"price":"61841.80","quantity":"0.005"},{"price":"61842.00","quantity":"0.911"},{"price":"61842.30","quantity":"0.140"},{"price":"61844.20","quantity":"0.000"},{"price":"61845.00","quantity":"0.009"},{"price":"61845.10","quantity":"0.003"},{"price":"61845.20","quantity":"0.000"},{"price":"61852.20","quantity":"15.999"}],"asks":[{"price":"61852.30","quantity":"2.341"},{"price":"61852.40","quantity":"0.003"},{"price":"61853.40","quantity":"0.006"},{"price":"61854.10","quantity":"0.000"},{"price":"61854.90","quantity":"0.017"},{"price":"61856.20","quantity":"0.171"},{"price":"61857.00","quantity":"0.841"},{"price":"61860.50","quantity":"1.094"},{"price":"61864.10","quantity":"1.361"},{"price":"61864.60","quantity":"0.001"},{"price":"61864.80","quantity":"1.311"},{"price":"61865.60","quantity":"0.571"},{"price":"61909.50","quantity":"2.614"},{"price":"61920.00","quantity":"1.154"},{"price":"61925.80","quantity":"0.275"},{"price":"61950.60","quantity":"1.628"},{"price":"61950.70","quantity":"0.001"},{"price":"62000.00","quantity":"13.005"},{"price":"62080.00","quantity":"0.271"},{"price":"62147.50","quantity":"0.000"},{"price":"62160.00","quantity":"0.266"},{"price":"62240.00","quantity":"0.261"},{"price":"62470.80","quantity":"0.000"},{"price":"62627.50","quantity":"0.335"},{"price":"89523.20","quantity":"0.678"}],"raw":{"e":"depthUpdate","E":1783517065272,"T":1783517065269,"s":"BTCUSDT","ps":"BTCUSDT","U":10999770379429,"u":10999770393602,"pu":10999770379048,"b":[["1000.00","207.692"],["11452.20","1.264"],["11552.20","1.936"],["11652.20","1.462"],["11752.20","0.238"],["55666.90","0.003"],["58745.80","0.033"],["59378.10","0.003"],["60615.20","0.054"],["61171.80","0.737"],["61233.70","0.000"],["61440.00","0.318"],["61520.00","2.901"],["61600.00","56.779"],["61680.00","0.693"],["61752.40","0.012"],["61754.80","1.367"],["61760.00","0.902"],["61763.70","0.000"],["61828.10","0.001"],["61830.20","1.377"],["61830.40","0.130"],["61831.60","0.000"],["61832.30","0.970"],["61833.80","0.000"],["61839.80","0.944"],["61841.80","0.005"],["61842.00","0.911"],["61842.30","0.140"],["61844.20","0.000"],["61845.00","0.009"],["61845.10","0.003"],["61845.20","0.000"],["61852.20","15.999"]],"a":[["61852.30","2.341"],["61852.40","0.003"],["61853.40","0.006"],["61854.10","0.000"],["61854.90","0.017"],["61856.20","0.171"],["61857.00","0.841"],["61860.50","1.094"],["61864.10","1.361"],["61864.60","0.001"],["61864.80","1.311"],["61865.60","0.571"],["61909.50","2.614"],["61920.00","1.154"],["61925.80","0.275"],["61950.60","1.628"],["61950.70","0.001"],["62000.00","13.005"],["62080.00","0.271"],["62147.50","0.000"],["62160.00","0.266"],["62240.00","0.261"],["62470.80","0.000"],["62627.50","0.335"],["89523.20","0.678"]],"st":1}}
{"schema_version":"1.3.0","event_id":"773795eb-199f-45cd-b6c7-07bc96cab9d8","event_type":"raw.trade","source":"binance_market_data_recorder","venue":"binance_usdm","market_type":"perpetual_futures","symbol":"ETHUSDT","event_time_ms":1783517065318,"received_time_ms":1783517065313,"trace_id":"f2c22302-e2e8-44f6-adf0-cb0c416c9379","trade_id":8429826593,"price":"1736.17","quantity":"0.141","trade_time_ms":1783517065317,"is_buyer_maker":false,"aggressor_side":"buy","raw":{"e":"trade","E":1783517065318,"T":1783517065317,"s":"ETHUSDT","t":8429826593,"p":"1736.17","q":"0.141","X":"MARKET","m":false,"st":1}}
{"schema_version":"1.3.0","event_id":"3bb0deca-bf15-4442-a400-48f2c3839c21","event_type":"raw.depth_update","source":"binance_market_data_recorder","venue":"binance_usdm","market_type":"perpetual_futures","symbol":"ETHUSDT","event_time_ms":1783517065334,"received_time_ms":1783517065328,"trace_id":"c5a09865-a1a6-42fa-af84-3063ac671fa3","first_update_id":10999770388940,"final_update_id":10999770399935,"previous_final_update_id":10999770388529,"bids":[{"price":"200.00","quantity":"7.594"},{"price":"1216.16","quantity":"0.800"},{"price":"1221.16","quantity":"7.136"},{"price":"1226.12","quantity":"0.000"},{"price":"1226.16","quantity":"1.664"},{"price":"1562.54","quantity":"0.212"},{"price":"1562.55","quantity":"3.215"},{"price":"1684.94","quantity":"106.830"},{"price":"1701.44","quantity":"50.050"},{"price":"1703.52","quantity":"31.977"},{"price":"1704.91","quantity":"36.369"},{"price":"1708.27","quantity":"0.076"},{"price":"1714.71","quantity":"61.653"},{"price":"1718.79","quantity":"76.615"},{"price":"1727.47","quantity":"0.000"},{"price":"1733.95","quantity":"3.942"},{"price":"1733.96","quantity":"4.848"},{"price":"1734.05","quantity":"13.271"},{"price":"1734.18","quantity":"426.126"},{"price":"1735.16","quantity":"3.810"},{"price":"1735.40","quantity":"8.527"}],"asks":[{"price":"1736.17","quantity":"27.152"},{"price":"1736.52","quantity":"24.635"},{"price":"1736.79","quantity":"0.108"},{"price":"1736.88","quantity":"3.670"},{"price":"1736.91","quantity":"53.794"},{"price":"1737.07","quantity":"9.464"},{"price":"1737.08","quantity":"9.700"},{"price":"1737.12","quantity":"15.689"},{"price":"1737.21","quantity":"0.850"},{"price":"1737.22","quantity":"2.641"},{"price":"1737.34","quantity":"13.215"},{"price":"1737.83","quantity":"104.229"},{"price":"1738.06","quantity":"79.525"},{"price":"1744.86","quantity":"40.397"},{"price":"2635.16","quantity":"0.001"},{"price":"2635.25","quantity":"0.003"}],"raw":{"e":"depthUpdate","E":1783517065334,"T":1783517065333,"s":"ETHUSDT","ps":"ETHUSDT","U":10999770388940,"u":10999770399935,"pu":10999770388529,"b":[["200.00","7.594"],["1216.16","0.800"],["1221.16","7.136"],["1226.12","0.000"],["1226.16","1.664"],["1562.54","0.212"],["1562.55","3.215"],["1684.94","106.830"],["1701.44","50.050"],["1703.52","31.977"],["1704.91","36.369"],["1708.27","0.076"],["1714.71","61.653"],["1718.79","76.615"],["1727.47","0.000"],["1733.95","3.942"],["1733.96","4.848"],["1734.05","13.271"],["1734.18","426.126"],["1735.16","3.810"],["1735.40","8.527"]],"a":[["1736.17","27.152"],["1736.52","24.635"],["1736.79","0.108"],["1736.88","3.670"],["1736.91","53.794"],["1737.07","9.464"],["1737.08","9.700"],["1737.12","15.689"],["1737.21","0.850"],["1737.22","2.641"],["1737.34","13.215"],["1737.83","104.229"],["1738.06","79.525"],["1744.86","40.397"],["2635.16","0.001"],["2635.25","0.003"]],"st":1}}
{"schema_version":"1.3.0","event_id":"98782152-b43c-4c4c-9bb1-0437309c4066","event_type":"raw.depth_update","source":"binance_market_data_recorder","venue":"binance_usdm","market_type":"perpetual_futures","symbol":"BTCUSDT","event_time_ms":1783517065374,"received_time_ms":1783517065368,"trace_id":"4834e274-3b6f-432c-a579-c739b8207351","first_update_id":10999770393939,"final_update_id":10999770404109,"previous_final_update_id":10999770393602,"bids":[{"price":"11452.20","quantity":"1.536"},{"price":"11552.20","quantity":"1.664"},{"price":"11652.20","quantity":"1.615"},{"price":"11752.20","quantity":"0.085"},{"price":"55666.90","quantity":"0.003"},{"price":"60893.50","quantity":"4.597"},{"price":"60955.30","quantity":"9.176"},{"price":"61042.50","quantity":"1.475"},{"price":"61140.90","quantity":"4.900"},{"price":"61171.80","quantity":"0.982"},{"price":"61233.70","quantity":"0.000"},{"price":"61271.40","quantity":"0.407"},{"price":"61520.00","quantity":"2.919"},{"price":"61600.00","quantity":"56.797"},{"price":"61680.00","quantity":"0.711"},{"price":"61721.80","quantity":"0.273"},{"price":"61760.00","quantity":"0.920"},{"price":"61783.30","quantity":"8.002"},{"price":"61792.90","quantity":"0.017"},{"price":"61805.00","quantity":"6.614"},{"price":"61815.10","quantity":"0.004"},{"price":"61820.40","quantity":"1.425"},{"price":"61823.40","quantity":"0.286"},{"price":"61823.80","quantity":"0.211"},{"price":"61823.90","quantity":"0.000"},{"price":"61824.10","quantity":"0.005"},{"price":"61828.10","quantity":"0.081"},{"price":"61829.60","quantity":"0.039"},{"price":"61830.20","quantity":"1.297"},{"price":"61830.40","quantity":"0.050"},{"price":"61840.00","quantity":"0.076"},{"price":"61841.80","quantity":"0.085"},{"price":"61842.30","quantity":"0.060"},{"price":"61849.80","quantity":"0.002"},{"price":"61852.20","quantity":"15.998"}],"asks":[{"price":"61852.30","quantity":"2.342"},{"price":"61856.20","quantity":"0.172"},{"price":"61862.90","quantity":"0.969"},{"price":"61863.90","quantity":"0.875"},{"price":"61864.80","quantity":"0.343"},{"price":"61865.60","quantity":"0.005"},{"price":"61882.10","quantity":"0.008"},{"price":"61882.90","quantity":"0.826"},{"price":"61898.40","quantity":"5.704"},{"price":"61909.90","quantity":"0.113"},{"price":"61920.00","quantity":"1.172"},{"price":"61920.10","quantity":"8.000"},{"price":"61925.80","quantity":"0.372"},{"price":"61986.60","quantity":"0.735"},{"price":"61986.80","quantity":"0.001"},{"price":"62000.00","quantity":"13.023"},{"price":"62080.00","quantity":"0.289"},{"price":"62160.00","quantity":"0.284"},{"price":"62239.10","quantity":"0.073"},{"price":"62240.00","quantity":"0.279"},{"price":"62470.80","quantity":"0.000"},{"price":"62625.50","quantity":"0.398"},{"price":"62687.30","quantity":"0.477"},{"price":"62911.80","quantity":"0.000"},{"price":"62974.80","quantity":"0.000"}],"raw":{"e":"depthUpdate","E":1783517065374,"T":1783517065373,"s":"BTCUSDT","ps":"BTCUSDT","U":10999770393939,"u":10999770404109,"pu":10999770393602,"b":[["11452.20","1.536"],["11552.20","1.664"],["11652.20","1.615"],["11752.20","0.085"],["55666.90","0.003"],["60893.50","4.597"],["60955.30","9.176"],["61042.50","1.475"],["61140.90","4.900"],["61171.80","0.982"],["61233.70","0.000"],["61271.40","0.407"],["61520.00","2.919"],["61600.00","56.797"],["61680.00","0.711"],["61721.80","0.273"],["61760.00","0.920"],["61783.30","8.002"],["61792.90","0.017"],["61805.00","6.614"],["61815.10","0.004"],["61820.40","1.425"],["61823.40","0.286"],["61823.80","0.211"],["61823.90","0.000"],["61824.10","0.005"],["61828.10","0.081"],["61829.60","0.039"],["61830.20","1.297"],["61830.40","0.050"],["61840.00","0.076"],["61841.80","0.085"],["61842.30","0.060"],["61849.80","0.002"],["61852.20","15.998"]],"a":[["61852.30","2.342"],["61856.20","0.172"],["61862.90","0.969"],["61863.90","0.875"],["61864.80","0.343"],["61865.60","0.005"],["61882.10","0.008"],["61882.90","0.826"],["61898.40","5.704"],["61909.90","0.113"],["61920.00","1.172"],["61920.10","8.000"],["61925.80","0.372"],["61986.60","0.735"],["61986.80","0.001"],["62000.00","13.023"],["62080.00","0.289"],["62160.00","0.284"],["62239.10","0.073"],["62240.00","0.279"],["62470.80","0.000"],["62625.50","0.398"],["62687.30","0.477"],["62911.80","0.000"],["62974.80","0.000"]],"st":1}}
{"schema_version":"1.3.0","event_id":"33d731c9-3f9c-4cb1-808d-c20b82ad5cf6","event_type":"raw.depth_update","source":"binance_market_data_recorder","venue":"binance_usdm","market_type":"perpetual_futures","symbol":"ETHUSDT","event_time_ms":1783517065438,"received_time_ms":1783517065433,"trace_id":"e3e67fc7-ea30-4b2c-8975-6340fa0e2e42","first_update_id":10999770400361,"final_update_id":10999770410770,"previous_final_update_id":10999770399935,"bids":[{"price":"200.00","quantity":"7.594"},{"price":"1216.16","quantity":"1.344"},{"price":"1221.16","quantity":"6.880"},{"price":"1226.16","quantity":"1.376"},{"price":"1562.54","quantity":"0.212"},{"price":"1562.55","quantity":"3.471"},{"price":"1666.70","quantity":"0.940"},{"price":"1704.71","quantity":"29.292"},{"price":"1705.75","quantity":"58.547"},{"price":"1720.39","quantity":"1.651"},{"price":"1730.81","quantity":"19.847"},{"price":"1735.59","quantity":"3.201"},{"price":"1736.13","quantity":"7.826"},{"price":"1736.16","quantity":"401.292"}],"asks":[{"price":"1736.17","quantity":"36.784"},{"price":"1736.20","quantity":"0.076"},{"price":"1736.36","quantity":"1.740"},{"price":"1736.43","quantity":"10.243"},{"price":"1736.52","quantity":"26.302"},{"price":"1736.77","quantity":"83.694"},{"price":"1737.17","quantity":"1.620"},{"price":"1737.71","quantity":"1.975"},{"price":"1739.30","quantity":"3.887"},{"price":"1739.80","quantity":"6.674"},{"price":"1741.64","quantity":"38.004"},{"price":"1741.65","quantity":"0.632"},{"price":"1743.34","quantity":"104.627"},{"price":"1747.12","quantity":"37.204"},{"price":"1757.87","quantity":"16.497"},{"price":"1771.33","quantity":"2.822"},{"price":"1868.58","quantity":"0.101"},{"price":"2635.14","quantity":"0.014"},{"price":"2635.15","quantity":"0.001"},{"price":"2635.23","quantity":"0.000"},{"price":"2635.24","quantity":"0.000"}],"raw":{"e":"depthUpdate","E":1783517065438,"T":1783517065437,"s":"ETHUSDT","ps":"ETHUSDT","U":10999770400361,"u":10999770410770,"pu":10999770399935,"b":[["200.00","7.594"],["1216.16","1.344"],["1221.16","6.880"],["1226.16","1.376"],["1562.54","0.212"],["1562.55","3.471"],["1666.70","0.940"],["1704.71","29.292"],["1705.75","58.547"],["1720.39","1.651"],["1730.81","19.847"],["1735.59","3.201"],["1736.13","7.826"],["1736.16","401.292"]],"a":[["1736.17","36.784"],["1736.20","0.076"],["1736.36","1.740"],["1736.43","10.243"],["1736.52","26.302"],["1736.77","83.694"],["1737.17","1.620"],["1737.71","1.975"],["1739.30","3.887"],["1739.80","6.674"],["1741.64","38.004"],["1741.65","0.632"],["1743.34","104.627"],["1747.12","37.204"],["1757.87","16.497"],["1771.33","2.822"],["1868.58","0.101"],["2635.14","0.014"],["2635.15","0.001"],["2635.23","0.000"],["2635.24","0.000"]],"st":1}}
{"schema_version":"1.3.0","event_id":"f723ab1e-2d59-41e0-ac79-de1b1417b5e4","event_type":"raw.depth_update","source":"binance_market_data_recorder","venue":"binance_usdm","market_type":"perpetual_futures","symbol":"BTCUSDT","event_time_ms":1783517065476,"received_time_ms":1783517065471,"trace_id":"0181a97b-e504-46b3-a994-02733b6f64d7","first_update_id":10999770404391,"final_update_id":10999770413869,"previous_final_update_id":10999770404109,"bids":[{"price":"1000.00","quantity":"207.692"},{"price":"11452.20","quantity":"1.808"},{"price":"11552.20","quantity":"1.443"},{"price":"11652.20","quantity":"1.649"},{"price":"11752.20","quantity":"0.000"},{"price":"49482.00","quantity":"0.000"},{"price":"55666.90","quantity":"0.003"},{"price":"58759.70","quantity":"0.000"},{"price":"59378.10","quantity":"0.000"},{"price":"60875.60","quantity":"4.185"},{"price":"60893.50","quantity":"5.745"},{"price":"60937.40","quantity":"10.160"},{"price":"60955.30","quantity":"10.323"},{"price":"61233.70","quantity":"0.000"},{"price":"61260.00","quantity":"0.488"},{"price":"61520.00","quantity":"3.097"},{"price":"61542.90","quantity":"0.011"},{"price":"61600.00","quantity":"56.975"},{"price":"61680.00","quantity":"0.889"},{"price":"61752.40","quantity":"11.012"},{"price":"61754.80","quantity":"2.749"},{"price":"61760.00","quantity":"1.098"},{"price":"61815.30","quantity":"1.274"},{"price":"61823.30","quantity":"2.230"},{"price":"61823.80","quantity":"0.166"},{"price":"61832.00","quantity":"0.429"},{"price":"61834.00","quantity":"4.610"},{"price":"61834.10","quantity":"2.900"},{"price":"61834.20","quantity":"0.163"},{"price":"61840.00","quantity":"0.254"},{"price":"61844.00","quantity":"0.000"},{"price":"61844.90","quantity":"0.163"},{"price":"61849.30","quantity":"0.000"},{"price":"61850.30","quantity":"0.004"},{"price":"61852.20","quantity":"15.998"}],"asks":[{"price":"61852.30","quantity":"2.341"},{"price":"61854.90","quantity":"1.219"},{"price":"61856.20","quantity":"1.374"},{"price":"61857.20","quantity":"0.324"},{"price":"61857.50","quantity":"0.890"},{"price":"61857.60","quantity":"0.067"},{"price":"61858.90","quantity":"0.051"},{"price":"61859.60","quantity":"0.130"},{"price":"61862.90","quantity":"0.001"},{"price":"61863.80","quantity":"0.969"},{"price":"61863.90","quantity":"0.309"},{"price":"61864.60","quantity":"0.001"},{"price":"61865.60","quantity":"0.571"},{"price":"61881.90","quantity":"0.533"},{"price":"61883.40","quantity":"0.395"},{"price":"61891.90","quantity":"0.028"},{"price":"61893.50","quantity":"0.373"},{"price":"61895.60","quantity":"0.408"},{"price":"61908.00","quantity":"0.003"},{"price":"61920.00","quantity":"1.350"},{"price":"61925.80","quantity":"0.372"},{"price":"61951.00","quantity":"11.000"},{"price":"62000.00","quantity":"13.201"},{"price":"62080.00","quantity":"0.467"},{"price":"62160.00","quantity":"0.462"},{"price":"62186.30","quantity":"0.161"},{"price":"62240.00","quantity":"0.457"},{"price":"62470.80","quantity":"0.000"},{"price":"62885.30","quantity":"2.460"},{"price":"63398.60","quantity":"0.079"},{"price":"89523.20","quantity":"0.684"}],"raw":{"e":"depthUpdate","E":1783517065476,"T":1783517065474,"s":"BTCUSDT","ps":"BTCUSDT","U":10999770404391,"u":10999770413869,"pu":10999770404109,"b":[["1000.00","207.692"],["11452.20","1.808"],["11552.20","1.443"],["11652.20","1.649"],["11752.20","0.000"],["49482.00","0.000"],["55666.90","0.003"],["58759.70","0.000"],["59378.10","0.000"],["60875.60","4.185"],["60893.50","5.745"],["60937.40","10.160"],["60955.30","10.323"],["61233.70","0.000"],["61260.00","0.488"],["61520.00","3.097"],["61542.90","0.011"],["61600.00","56.975"],["61680.00","0.889"],["61752.40","11.012"],["61754.80","2.749"],["61760.00","1.098"],["61815.30","1.274"],["61823.30","2.230"],["61823.80","0.166"],["61832.00","0.429"],["61834.00","4.610"],["61834.10","2.900"],["61834.20","0.163"],["61840.00","0.254"],["61844.00","0.000"],["61844.90","0.163"],["61849.30","0.000"],["61850.30","0.004"],["61852.20","15.998"]],"a":[["61852.30","2.341"],["61854.90","1.219"],["61856.20","1.374"],["61857.20","0.324"],["61857.50","0.890"],["61857.60","0.067"],["61858.90","0.051"],["61859.60","0.130"],["61862.90","0.001"],["61863.80","0.969"],["61863.90","0.309"],["61864.60","0.001"],["61865.60","0.571"],["61881.90","0.533"],["61883.40","0.395"],["61891.90","0.028"],["61893.50","0.373"],["61895.60","0.408"],["61908.00","0.003"],["61920.00","1.350"],["61925.80","0.372"],["61951.00","11.000"],["62000.00","13.201"],["62080.00","0.467"],["62160.00","0.462"],["62186.30","0.161"],["62240.00","0.457"],["62470.80","0.000"],["62885.30","2.460"],["63398.60","0.079"],["89523.20","0.684"]],"st":1}}
{"schema_version":"1.3.0","event_id":"7131e629-3436-49ca-8aee-d0fb70a3c593","event_type":"raw.trade","source":"binance_market_data_recorder","venue":"binance_usdm","market_type":"perpetual_futures","symbol":"ETHUSDT","event_time_ms":1783517065492,"received_time_ms":1783517065487,"trace_id":"6bfc8be1-b75e-4413-9330-1d68aee919d3","trade_id":8429826594,"price":"1736.17","quantity":"0.015","trade_time_ms":1783517065492,"is_buyer_maker":false,"aggressor_side":"buy","raw":{"e":"trade","E":1783517065492,"T":1783517065492,"s":"ETHUSDT","t":8429826594,"p":"1736.17","q":"0.015","X":"MARKET","m":false,"st":1}}
{"schema_version":"1.3.0","event_id":"f85c5f90-e955-4d88-9fe5-7460ff7b05c7","event_type":"raw.depth_update","source":"binance_market_data_recorder","venue":"binance_usdm","market_type":"perpetual_futures","symbol":"ETHUSDT","event_time_ms":1783517065540,"received_time_ms":1783517065534,"trace_id":"8aee23a2-f850-43c0-825b-ece5d034ed41","first_update_id":10999770410790,"final_update_id":10999770420271,"previous_final_update_id":10999770410770,"bids":[{"price":"201.00","quantity":"2.300"},{"price":"1216.16","quantity":"1.888"},{"price":"1221.16","quantity":"6.592"},{"price":"1226.16","quantity":"1.120"},{"price":"1562.54","quantity":"0.212"},{"price":"1562.55","quantity":"3.485"},{"price":"1666.70","quantity":"0.825"},{"price":"1701.44","quantity":"50.079"},{"price":"1713.71","quantity":"8.747"},{"price":"1732.52","quantity":"0.000"},{"price":"1733.04","quantity":"11.343"},{"price":"1733.95","quantity":"3.942"},{"price":"1734.05","quantity":"11.825"},{"price":"1734.12","quantity":"455.725"},{"price":"1734.13","quantity":"4.338"},{"price":"1734.18","quantity":"0.012"},{"price":"1734.27","quantity":"0.670"},{"price":"1735.12","quantity":"28.273"},{"price":"1735.16","quantity":"3.810"},{"price":"1735.28","quantity":"3.648"},{"price":"1735.29","quantity":"29.748"},{"price":"1735.40","quantity":"229.132"},{"price":"1735.43","quantity":"42.789"},{"price":"1735.49","quantity":"3.990"},{"price":"1735.68","quantity":"15.278"},{"price":"1735.79","quantity":"7.374"},{"price":"1735.82","quantity":"5.888"},{"price":"1735.85","quantity":"7.277"},{"price":"1735.86","quantity":"5.808"},{"price":"1735.91","quantity":"47.304"},{"price":"1735.94","quantity":"6.262"},{"price":"1736.01","quantity":"79.891"},{"price":"1736.06","quantity":"0.314"},{"price":"1736.08","quantity":"10.694"},{"price":"1736.10","quantity":"3.735"},{"price":"1736.11","quantity":"0.890"},{"price":"1736.12","quantity":"15.679"},{"price":"1736.16","quantity":"395.278"}],"asks":[{"price":"1736.17","quantity":"27.149"},{"price":"1736.32","quantity":"17.978"},{"price":"1736.33","quantity":"21.752"},{"price":"1736.36","quantity":"6.348"},{"price":"1736.38","quantity":"9.808"},{"price":"1736.39","quantity":"20.070"},{"price":"1736.41","quantity":"0.080"},{"price":"1736.46","quantity":"19.812"},{"price":"1736.47","quantity":"14.886"},{"price":"1736.49","quantity":"6.160"},{"price":"1736.51","quantity":"15.240"},{"price":"1736.52","quantity":"25.802"},{"price":"1736.54","quantity":"16.957"},{"price":"1736.55","quantity":"90.978"},{"price":"1736.61","quantity":"35.336"},{"price":"1736.68","quantity":"4.506"},{"price":"1736.77","quantity":"84.161"},{"price":"1736.86","quantity":"5.826"},{"price":"1736.90","quantity":"39.121"},{"price":"1736.92","quantity":"69.043"},{"price":"1737.07","quantity":"7.497"},{"price":"1737.08","quantity":"9.142"},{"price":"1737.09","quantity":"37.599"},{"price":"1737.10","quantity":"6.799"},{"price":"1737.12","quantity":"13.995"},{"price":"1737.34","quantity":"14.909"},{"price":"1737.56","quantity":"33.338"},{"price":"1737.65","quantity":"1.466"},{"price":"1738.96","quantity":"3.196"},{"price":"1742.44","quantity":"8.041"},{"price":"1742.47","quantity":"9.741"},{"price":"1742.48","quantity":"40.122"},{"price":"1744.75","quantity":"1.894"},{"price":"1744.83","quantity":"0.012"},{"price":"1744.99","quantity":"7.836"},{"price":"1751.52","quantity":"5.716"},{"price":"1778.71","quantity":"76.174"},{"price":"2635.13","quantity":"0.001"},{"price":"2635.22","quantity":"0.000"}],"raw":{"e":"depthUpdate","E":1783517065540,"T":1783517065538,"s":"ETHUSDT","ps":"ETHUSDT","U":10999770410790,"u":10999770420271,"pu":10999770410770,"b":[["201.00","2.300"],["1216.16","1.888"],["1221.16","6.592"],["1226.16","1.120"],["1562.54","0.212"],["1562.55","3.485"],["1666.70","0.825"],["1701.44","50.079"],["1713.71","8.747"],["1732.52","0.000"],["1733.04","11.343"],["1733.95","3.942"],["1734.05","11.825"],["1734.12","455.725"],["1734.13","4.338"],["1734.18","0.012"],["1734.27","0.670"],["1735.12","28.273"],["1735.16","3.810"],["1735.28","3.648"],["1735.29","29.748"],["1735.40","229.132"],["1735.43","42.789"],["1735.49","3.990"],["1735.68","15.278"],["1735.79","7.374"],["1735.82","5.888"],["1735.85","7.277"],["1735.86","5.808"],["1735.91","47.304"],["1735.94","6.262"],["1736.01","79.891"],["1736.06","0.314"],["1736.08","10.694"],["1736.10","3.735"],["1736.11","0.890"],["1736.12","15.679"],["1736.16","395.278"]],"a":[["1736.17","27.149"],["1736.32","17.978"],["1736.33","21.752"],["1736.36","6.348"],["1736.38","9.808"],["1736.39","20.070"],["1736.41","0.080"],["1736.46","19.812"],["1736.47","14.886"],["1736.49","6.160"],["1736.51","15.240"],["1736.52","25.802"],["1736.54","16.957"],["1736.55","90.978"],["1736.61","35.336"],["1736.68","4.506"],["1736.77","84.161"],["1736.86","5.826"],["1736.90","39.121"],["1736.92","69.043"],["1737.07","7.497"],["1737.08","9.142"],["1737.09","37.599"],["1737.10","6.799"],["1737.12","13.995"],["1737.34","14.909"],["1737.56","33.338"],["1737.65","1.466"],["1738.96","3.196"],["1742.44","8.041"],["1742.47","9.741"],["1742.48","40.122"],["1744.75","1.894"],["1744.83","0.012"],["1744.99","7.836"],["1751.52","5.716"],["1778.71","76.174"],["2635.13","0.001"],["2635.22","0.000"]],"st":1}}
{"schema_version":"1.3.0","event_id":"4723fe33-968d-4890-89ff-6984ff2cf305","event_type":"raw.depth_update","source":"binance_market_data_recorder","venue":"binance_usdm","market_type":"perpetual_futures","symbol":"BTCUSDT","event_time_ms":1783517065578,"received_time_ms":1783517065575,"trace_id":"cb5b8c8e-9968-4452-bf1c-879f35a32705","first_update_id":10999770414027,"final_update_id":10999770423251,"previous_final_update_id":10999770413869,"bids":[{"price":"1000.00","quantity":"207.692"},{"price":"11452.20","quantity":"2.080"},{"price":"11552.20","quantity":"1.324"},{"price":"11652.20","quantity":"1.496"},{"price":"55666.90","quantity":"0.003"},{"price":"58759.60","quantity":"0.006"},{"price":"58759.70","quantity":"0.003"},{"price":"59378.10","quantity":"0.003"},{"price":"60937.40","quantity":"9.013"},{"price":"61122.90","quantity":"0.003"},{"price":"61233.70","quantity":"0.000"},{"price":"61288.70","quantity":"1.145"},{"price":"61289.90","quantity":"1.796"},{"price":"61762.90","quantity":"1.877"},{"price":"61813.40","quantity":"0.101"},{"price":"61822.00","quantity":"0.001"},{"price":"61822.30","quantity":"0.013"},{"price":"61828.10","quantity":"0.001"},{"price":"61830.40","quantity":"0.130"},{"price":"61832.00","quantity":"0.349"},{"price":"61841.20","quantity":"0.569"},{"price":"61841.80","quantity":"0.005"},{"price":"61841.90","quantity":"0.506"},{"price":"61842.00","quantity":"0.345"},{"price":"61843.70","quantity":"0.326"},{"price":"61844.40","quantity":"0.000"}],"asks":[{"price":"61854.70","quantity":"0.001"},{"price":"61854.80","quantity":"0.000"},{"price":"61856.20","quantity":"1.269"},{"price":"61856.40","quantity":"2.033"},{"price":"61856.80","quantity":"0.001"},{"price":"61858.00","quantity":"0.765"},{"price":"61858.10","quantity":"0.008"},{"price":"61859.80","quantity":"1.208"},{"price":"61862.90","quantity":"0.000"},{"price":"61879.30","quantity":"1.589"},{"price":"61886.50","quantity":"0.027"},{"price":"61886.70","quantity":"0.000"},{"price":"61887.20","quantity":"0.002"},{"price":"61893.40","quantity":"0.036"},{"price":"61893.50","quantity":"0.207"},{"price":"61895.90","quantity":"0.015"},{"price":"61898.20","quantity":"0.265"},{"price":"61908.70","quantity":"0.117"},{"price":"61909.00","quantity":"0.133"},{"price":"61909.20","quantity":"0.176"},{"price":"61909.40","quantity":"0.006"},{"price":"61911.00","quantity":"0.000"},{"price":"61925.80","quantity":"0.275"},{"price":"62161.60","quantity":"0.001"},{"price":"62470.80","quantity":"0.000"},{"price":"62660.00","quantity":"0.811"},{"price":"62903.80","quantity":"3.492"},{"price":"62978.00","quantity":"0.707"}],"raw":{"e":"depthUpdate","E":1783517065578,"T":1783517065577,"s":"BTCUSDT","ps":"BTCUSDT","U":10999770414027,"u":10999770423251,"pu":10999770413869,"b":[["1000.00","207.692"],["11452.20","2.080"],["11552.20","1.324"],["11652.20","1.496"],["55666.90","0.003"],["58759.60","0.006"],["58759.70","0.003"],["59378.10","0.003"],["60937.40","9.013"],["61122.90","0.003"],["61233.70","0.000"],["61288.70","1.145"],["61289.90","1.796"],["61762.90","1.877"],["61813.40","0.101"],["61822.00","0.001"],["61822.30","0.013"],["61828.10","0.001"],["61830.40","0.130"],["61832.00","0.349"],["61841.20","0.569"],["61841.80","0.005"],["61841.90","0.506"],["61842.00","0.345"],["61843.70","0.326"],["61844.40","0.000"]],"a":[["61854.70","0.001"],["61854.80","0.000"],["61856.20","1.269"],["61856.40","2.033"],["61856.80","0.001"],["61858.00","0.765"],["61858.10","0.008"],["61859.80","1.208"],["61862.90","0.000"],["61879.30","1.589"],["61886.50","0.027"],["61886.70","0.000"],["61887.20","0.002"],["61893.40","0.036"],["61893.50","0.207"],["61895.90","0.015"],["61898.20","0.265"],["61908.70","0.117"],["61909.00","0.133"],["61909.20","0.176"],["61909.40","0.006"],["61911.00","0.000"],["61925.80","0.275"],["62161.60","0.001"],["62470.80","0.000"],["62660.00","0.811"],["62903.80","3.492"],["62978.00","0.707"]],"st":1}}
{"schema_version":"1.3.0","event_id":"b74a57e5-3204-46cf-9b61-dd190e3d0c98","event_type":"raw.trade","source":"binance_market_data_recorder","venue":"binance_usdm","market_type":"perpetual_futures","symbol":"ETHUSDT","event_time_ms":1783517065635,"received_time_ms":1783517065629,"trace_id":"89bc1efb-5dd0-4b65-b8b0-640d7b7598e8","trade_id":8429826595,"price":"1736.16","quantity":"0.026","trade_time_ms":1783517065635,"is_buyer_maker":true,"aggressor_side":"sell","raw":{"e":"trade","E":1783517065635,"T":1783517065635,"s":"ETHUSDT","t":8429826595,"p":"1736.16","q":"0.026","X":"MARKET","m":true,"st":1}}
{"schema_version":"1.3.0","event_id":"6b5652a0-bf3f-44e9-a243-3bd23ec14260","event_type":"raw.depth_update","source":"binance_market_data_recorder","venue":"binance_usdm","market_type":"perpetual_futures","symbol":"ETHUSDT","event_time_ms":1783517065642,"received_time_ms":1783517065636,"trace_id":"a2b10920-7278-4b4b-9877-a5702ef710f9","first_update_id":10999770420568,"final_update_id":10999770427587,"previous_final_update_id":10999770420271,"bids":[{"price":"200.00","quantity":"7.594"},{"price":"1216.16","quantity":"2.432"},{"price":"1221.16","quantity":"6.336"},{"price":"1226.16","quantity":"0.832"},{"price":"1562.54","quantity":"0.212"},{"price":"1562.55","quantity":"3.357"},{"price":"1666.70","quantity":"0.940"},{"price":"1694.46","quantity":"0.000"},{"price":"1701.44","quantity":"50.050"},{"price":"1704.39","quantity":"29.299"},{"price":"1710.87","quantity":"6.265"},{"price":"1713.59","quantity":"11.684"},{"price":"1721.02","quantity":"325.128"},{"price":"1721.25","quantity":"11.630"},{"price":"1723.45","quantity":"154.330"},{"price":"1730.39","quantity":"2.936"},{"price":"1734.12","quantity":"26.918"},{"price":"1734.16","quantity":"2.012"},{"price":"1734.18","quantity":"428.819"},{"price":"1735.17","quantity":"1.204"},{"price":"1735.18","quantity":"69.991"},{"price":"1735.25","quantity":"0.840"},{"price":"1735.26","quantity":"0.038"},{"price":"1735.70","quantity":"0.037"},{"price":"1736.16","quantity":"395.210"}],"asks":[{"price":"1736.36","quantity":"6.348"},{"price":"1736.60","quantity":"1.768"},{"price":"1736.62","quantity":"0.100"},{"price":"1737.06","quantity":"28.625"},{"price":"1737.07","quantity":"8.055"},{"price":"1737.09","quantity":"35.632"},{"price":"1737.10","quantity":"6.241"},{"price":"1737.17","quantity":"1.620"},{"price":"1738.05","quantity":"16.399"},{"price":"1739.30","quantity":"5.271"},{"price":"1739.80","quantity":"5.290"},{"price":"1743.34","quantity":"104.684"},{"price":"1747.12","quantity":"52.204"},{"price":"1750.53","quantity":"34.574"},{"price":"1788.26","quantity":"0.120"},{"price":"2635.12","quantity":"0.001"},{"price":"2635.21","quantity":"0.000"}],"raw":{"e":"depthUpdate","E":1783517065642,"T":1783517065641,"s":"ETHUSDT","ps":"ETHUSDT","U":10999770420568,"u":10999770427587,"pu":10999770420271,"b":[["200.00","7.594"],["1216.16","2.432"],["1221.16","6.336"],["1226.16","0.832"],["1562.54","0.212"],["1562.55","3.357"],["1666.70","0.940"],["1694.46","0.000"],["1701.44","50.050"],["1704.39","29.299"],["1710.87","6.265"],["1713.59","11.684"],["1721.02","325.128"],["1721.25","11.630"],["1723.45","154.330"],["1730.39","2.936"],["1734.12","26.918"],["1734.16","2.012"],["1734.18","428.819"],["1735.17","1.204"],["1735.18","69.991"],["1735.25","0.840"],["1735.26","0.038"],["1735.70","0.037"],["1736.16","395.210"]],"a":[["1736.36","6.348"],["1736.60","1.768"],["1736.62","0.100"],["1737.06","28.625"],["1737.07","8.055"],["1737.09","35.632"],["1737.10","6.241"],["1737.17","1.620"],["1738.05","16.399"],["1739.30","5.271"],["1739.80","5.290"],["1743.34","104.684"],["1747.12","52.204"],["1750.53","34.574"],["1788.26","0.120"],["2635.12","0.001"],["2635.21","0.000"]],"st":1}}
{"schema_version":"1.3.0","event_id":"cced8c27-e2d0-4fc5-a77d-a31c22aa668b","event_type":"raw.depth_update","source":"binance_market_data_recorder","venue":"binance_usdm","market_type":"perpetual_futures","symbol":"BTCUSDT","event_time_ms":1783517065680,"received_time_ms":1783517065674,"trace_id":"f6736f92-00a3-4c9b-8d0a-69b7893d4421","first_update_id":10999770423365,"final_update_id":10999770430032,"previous_final_update_id":10999770423251,"bids":[{"price":"11452.20","quantity":"2.352"},{"price":"11552.20","quantity":"1.188"},{"price":"11652.20","quantity":"1.360"},{"price":"49481.80","quantity":"0.000"},{"price":"55666.90","quantity":"0.003"},{"price":"59378.10","quantity":"0.000"},{"price":"61048.10","quantity":"1.473"},{"price":"61079.00","quantity":"1.097"},{"price":"61233.70","quantity":"0.000"},{"price":"61295.50","quantity":"2.126"},{"price":"61542.90","quantity":"0.012"},{"price":"61721.80","quantity":"0.000"},{"price":"61759.10","quantity":"0.000"},{"price":"61785.90","quantity":"2.043"},{"price":"61812.20","quantity":"1.251"},{"price":"61826.10","quantity":"0.003"},{"price":"61828.10","quantity":"0.583"},{"price":"61835.70","quantity":"0.003"},{"price":"61837.40","quantity":"1.377"},{"price":"61838.60","quantity":"0.387"},{"price":"61841.50","quantity":"0.302"},{"price":"61849.40","quantity":"0.001"}],"asks":[{"price":"61852.30","quantity":"2.342"},{"price":"61853.10","quantity":"0.001"},{"price":"61863.80","quantity":"0.001"},{"price":"61864.60","quantity":"0.969"},{"price":"61869.70","quantity":"0.005"},{"price":"61893.50","quantity":"0.580"},{"price":"61908.00","quantity":"0.158"},{"price":"61909.40","quantity":"0.107"},{"price":"61919.90","quantity":"3.755"},{"price":"61925.80","quantity":"0.275"},{"price":"61986.60","quantity":"0.000"},{"price":"62470.80","quantity":"0.000"},{"price":"62676.70","quantity":"0.401"},{"price":"62999.10","quantity":"0.793"},{"price":"63089.30","quantity":"0.138"},{"price":"89523.20","quantity":"0.690"}],"raw":{"e":"depthUpdate","E":1783517065680,"T":1783517065677,"s":"BTCUSDT","ps":"BTCUSDT","U":10999770423365,"u":10999770430032,"pu":10999770423251,"b":[["11452.20","2.352"],["11552.20","1.188"],["11652.20","1.360"],["49481.80","0.000"],["55666.90","0.003"],["59378.10","0.000"],["61048.10","1.473"],["61079.00","1.097"],["61233.70","0.000"],["61295.50","2.126"],["61542.90","0.012"],["61721.80","0.000"],["61759.10","0.000"],["61785.90","2.043"],["61812.20","1.251"],["61826.10","0.003"],["61828.10","0.583"],["61835.70","0.003"],["61837.40","1.377"],["61838.60","0.387"],["61841.50","0.302"],["61849.40","0.001"]],"a":[["61852.30","2.342"],["61853.10","0.001"],["61863.80","0.001"],["61864.60","0.969"],["61869.70","0.005"],["61893.50","0.580"],["61908.00","0.158"],["61909.40","0.107"],["61919.90","3.755"],["61925.80","0.275"],["61986.60","0.000"],["62470.80","0.000"],["62676.70","0.401"],["62999.10","0.793"],["63089.30","0.138"],["89523.20","0.690"]],"st":1}}
{"schema_version":"1.3.0","event_id":"e37fdbf1-20ce-44a3-bd38-85eb19dd31e3","event_type":"raw.depth_update","source":"binance_market_data_recorder","venue":"binance_usdm","market_type":"perpetual_futures","symbol":"ETHUSDT","event_time_ms":1783517065744,"received_time_ms":1783517065738,"trace_id":"1db006d4-efca-4a6c-aa31-e63ab29413ff","first_update_id":10999770427609,"final_update_id":10999770434258,"previous_final_update_id":10999770427587,"bids":[{"price":"200.00","quantity":"7.594"},{"price":"1216.16","quantity":"2.976"},{"price":"1221.16","quantity":"6.048"},{"price":"1226.16","quantity":"0.576"},{"price":"1562.54","quantity":"0.212"},{"price":"1562.55","quantity":"3.371"},{"price":"1666.70","quantity":"0.825"},{"price":"1690.56","quantity":"29.536"},{"price":"1701.43","quantity":"0.171"},{"price":"1703.17","quantity":"12.469"},{"price":"1733.94","quantity":"1.165"},{"price":"1734.05","quantity":"11.825"},{"price":"1734.06","quantity":"482.988"},{"price":"1734.07","quantity":"5.976"},{"price":"1734.18","quantity":"0.012"},{"price":"1735.27","quantity":"2.573"},{"price":"1735.40","quantity":"8.527"},{"price":"1735.43","quantity":"3.857"},{"price":"1735.49","quantity":"42.921"},{"price":"1735.56","quantity":"242.973"},{"price":"1735.68","quantity":"25.278"},{"price":"1736.16","quantity":"395.867"}],"asks":[{"price":"1736.88","quantity":"5.364"},{"price":"1736.98","quantity":"6.419"},{"price":"1737.02","quantity":"30.065"},{"price":"1737.34","quantity":"13.215"},{"price":"1737.82","quantity":"33.384"},{"price":"1751.07","quantity":"24.925"},{"price":"1779.19","quantity":"0.036"},{"price":"2635.10","quantity":"0.001"},{"price":"2635.11","quantity":"0.001"},{"price":"2635.19","quantity":"0.000"},{"price":"2635.20","quantity":"0.015"}],"raw":{"e":"depthUpdate","E":1783517065744,"T":1783517065743,"s":"ETHUSDT","ps":"ETHUSDT","U":10999770427609,"u":10999770434258,"pu":10999770427587,"b":[["200.00","7.594"],["1216.16","2.976"],["1221.16","6.048"],["1226.16","0.576"],["1562.54","0.212"],["1562.55","3.371"],["1666.70","0.825"],["1690.56","29.536"],["1701.43","0.171"],["1703.17","12.469"],["1733.94","1.165"],["1734.05","11.825"],["1734.06","482.988"],["1734.07","5.976"],["1734.18","0.012"],["1735.27","2.573"],["1735.40","8.527"],["1735.43","3.857"],["1735.49","42.921"],["1735.56","242.973"],["1735.68","25.278"],["1736.16","395.867"]],"a":[["1736.88","5.364"],["1736.98","6.419"],["1737.02","30.065"],["1737.34","13.215"],["1737.82","33.384"],["1751.07","24.925"],["1779.19","0.036"],["2635.10","0.001"],["2635.11","0.001"],["2635.19","0.000"],["2635.20","0.015"]],"st":1}}
{"schema_version":"1.3.0","event_id":"7e49a288-f20e-4636-9472-bde1775fe340","event_type":"raw.depth_update","source":"binance_market_data_recorder","venue":"binance_usdm","market_type":"perpetual_futures","symbol":"BTCUSDT","event_time_ms":1783517065782,"received_time_ms":1783517065776,"trace_id":"3d7a844a-1752-47c0-ba98-7845d8cf3d83","first_update_id":10999770430314,"final_update_id":10999770437447,"previous_final_update_id":10999770430032,"bids":[{"price":"1000.00","quantity":"207.692"},{"price":"11452.20","quantity":"2.624"},{"price":"11552.20","quantity":"1.069"},{"price":"11652.20","quantity":"1.207"},{"price":"55666.90","quantity":"0.003"},{"price":"59378.10","quantity":"0.003"},{"price":"60893.50","quantity":"6.893"},{"price":"60955.30","quantity":"11.470"},{"price":"61140.90","quantity":"5.880"},{"price":"61233.70","quantity":"0.000"},{"price":"61542.90","quantity":"0.011"},{"price":"61721.80","quantity":"0.278"},{"price":"61813.40","quantity":"0.000"},{"price":"61813.70","quantity":"1.482"},{"price":"61813.80","quantity":"0.115"},{"price":"61815.40","quantity":"0.004"},{"price":"61820.50","quantity":"0.220"},{"price":"61821.00","quantity":"0.357"},{"price":"61827.10","quantity":"0.583"},{"price":"61828.10","quantity":"0.001"},{"price":"61832.50","quantity":"0.084"},{"price":"61835.70","quantity":"0.569"},{"price":"61837.40","quantity":"0.811"},{"price":"61837.90","quantity":"0.761"},{"price":"61843.80","quantity":"0.032"},{"price":"61849.10","quantity":"0.003"}],"asks":[{"price":"61852.30","quantity":"1.370"},{"price":"61852.40","quantity":"0.002"},{"price":"61854.10","quantity":"0.000"},{"price":"61857.20","quantity":"0.000"},{"price":"61857.70","quantity":"0.572"},{"price":"61858.10","quantity":"0.007"},{"price":"61859.80","quantity":"0.007"},{"price":"61909.40","quantity":"0.107"},{"price":"61925.80","quantity":"0.372"},{"price":"61986.50","quantity":"0.736"},{"price":"62161.60","quantity":"0.002"},{"price":"62470.80","quantity":"0.000"},{"price":"62654.50","quantity":"1.276"}],"raw":{"e":"depthUpdate","E":1783517065782,"T":1783517065781,"s":"BTCUSDT","ps":"BTCUSDT","U":10999770430314,"u":10999770437447,"pu":10999770430032,"b":[["1000.00","207.692"],["11452.20","2.624"],["11552.20","1.069"],["11652.20","1.207"],["55666.90","0.003"],["59378.10","0.003"],["60893.50","6.893"],["60955.30","11.470"],["61140.90","5.880"],["61233.70","0.000"],["61542.90","0.011"],["61721.80","0.278"],["61813.40","0.000"],["61813.70","1.482"],["61813.80","0.115"],["61815.40","0.004"],["61820.50","0.220"],["61821.00","0.357"],["61827.10","0.583"],["61828.10","0.001"],["61832.50","0.084"],["61835.70","0.569"],["61837.40","0.811"],["61837.90","0.761"],["61843.80","0.032"],["61849.10","0.003"]],"a":[["61852.30","1.370"],["61852.40","0.002"],["61854.10","0.000"],["61857.20","0.000"],["61857.70","0.572"],["61858.10","0.007"],["61859.80","0.007"],["61909.40","0.107"],["61925.80","0.372"],["61986.50","0.736"],["62161.60","0.002"],["62470.80","0.000"],["62654.50","1.276"]],"st":1}}
{"schema_version":"1.3.0","event_id":"4262c9ef-5da0-423f-b100-954aee0db21d","event_type":"raw.trade","source":"binance_market_data_recorder","venue":"binance_usdm","market_type":"perpetual_futures","symbol":"BTCUSDT","event_time_ms":1783517065803,"received_time_ms":1783517065800,"trace_id":"741e21ca-f191-4466-b992-e6a33b663952","trade_id":7881418000,"price":"61852.30","quantity":"0.004","trade_time_ms":1783517065803,"is_buyer_maker":false,"aggressor_side":"buy","raw":{"e":"trade","E":1783517065803,"T":1783517065803,"s":"BTCUSDT","t":7881418000,"p":"61852.30","q":"0.004","X":"MARKET","m":false,"st":1}}
{"schema_version":"1.3.0","event_id":"8c85a5ce-3645-4359-b748-254a020fbda6","event_type":"raw.trade","source":"binance_market_data_recorder","venue":"binance_usdm","market_type":"perpetual_futures","symbol":"BTCUSDT","event_time_ms":1783517065837,"received_time_ms":1783517065832,"trace_id":"0764ac2d-d189-4516-b153-ae568369786c","trade_id":7881418001,"price":"61852.30","quantity":"0.018","trade_time_ms":1783517065837,"is_buyer_maker":false,"aggressor_side":"buy","raw":{"e":"trade","E":1783517065837,"T":1783517065837,"s":"BTCUSDT","t":7881418001,"p":"61852.30","q":"0.018","X":"MARKET","m":false,"st":1}}
{"schema_version":"1.3.0","event_id":"7323f46d-19ce-47b6-8bab-2d5e06ab87fa","event_type":"raw.trade","source":"binance_market_data_recorder","venue":"binance_usdm","market_type":"perpetual_futures","symbol":"BTCUSDT","event_time_ms":1783517065837,"received_time_ms":1783517065833,"trace_id":"8fc8927c-37ea-4f10-8e82-6e3929ee7fae","trade_id":7881418002,"price":"61852.30","quantity":"0.001","trade_time_ms":1783517065837,"is_buyer_maker":false,"aggressor_side":"buy","raw":{"e":"trade","E":1783517065837,"T":1783517065837,"s":"BTCUSDT","t":7881418002,"p":"61852.30","q":"0.001","X":"MARKET","m":false,"st":1}}
{"schema_version":"1.3.0","event_id":"b04f8233-8271-4b52-9801-781919794c07","event_type":"raw.trade","source":"binance_market_data_recorder","venue":"binance_usdm","market_type":"perpetual_futures","symbol":"BTCUSDT","event_time_ms":1783517065837,"received_time_ms":1783517065834,"trace_id":"d16ec9aa-29cc-4269-80ec-a8df95cc2f30","trade_id":7881418003,"price":"61852.30","quantity":"0.001","trade_time_ms":1783517065837,"is_buyer_maker":false,"aggressor_side":"buy","raw":{"e":"trade","E":1783517065837,"T":1783517065837,"s":"BTCUSDT","t":7881418003,"p":"61852.30","q":"0.001","X":"MARKET","m":false,"st":1}}
{"schema_version":"1.3.0","event_id":"9ac13512-7d57-4e3a-8313-a4772de5dbed","event_type":"raw.trade","source":"binance_market_data_recorder","venue":"binance_usdm","market_type":"perpetual_futures","symbol":"BTCUSDT","event_time_ms":1783517065837,"received_time_ms":1783517065835,"trace_id":"43770b82-22da-450c-842f-adca0ee148c6","trade_id":7881418004,"price":"61852.30","quantity":"0.001","trade_time_ms":1783517065837,"is_buyer_maker":false,"aggressor_side":"buy","raw":{"e":"trade","E":1783517065837,"T":1783517065837,"s":"BTCUSDT","t":7881418004,"p":"61852.30","q":"0.001","X":"MARKET","m":false,"st":1}}
{"schema_version":"1.3.0","event_id":"54e7b284-3a8e-4906-b138-001916c82b05","event_type":"raw.trade","source":"binance_market_data_recorder","venue":"binance_usdm","market_type":"perpetual_futures","symbol":"BTCUSDT","event_time_ms":1783517065837,"received_time_ms":1783517065835,"trace_id":"96b46bd9-8364-42a6-b14f-c47eac9bbfd1","trade_id":7881418005,"price":"61852.30","quantity":"0.279","trade_time_ms":1783517065837,"is_buyer_maker":false,"aggressor_side":"buy","raw":{"e":"trade","E":1783517065837,"T":1783517065837,"s":"BTCUSDT","t":7881418005,"p":"61852.30","q":"0.279","X":"MARKET","m":false,"st":1}}
{"schema_version":"1.3.0","event_id":"5c602dbe-6796-4dcc-bc0d-0f4850156c2e","event_type":"raw.depth_update","source":"binance_market_data_recorder","venue":"binance_usdm","market_type":"perpetual_futures","symbol":"ETHUSDT","event_time_ms":1783517065846,"received_time_ms":1783517065847,"trace_id":"4b5babf3-71cd-40f4-bc68-e03b52db2eca","first_update_id":10999770434508,"final_update_id":10999770443421,"previous_final_update_id":10999770434258,"bids":[{"price":"1216.16","quantity":"3.520"},{"price":"1221.16","quantity":"5.792"},{"price":"1226.16","quantity":"0.288"},{"price":"1562.54","quantity":"0.212"},{"price":"1562.55","quantity":"3.499"},{"price":"1701.43","quantity":"0.142"},{"price":"1705.75","quantity":"58.547"},{"price":"1710.17","quantity":"22.211"},{"price":"1721.40","quantity":"23.803"},{"price":"1724.99","quantity":"0.588"},{"price":"1725.03","quantity":"0.345"},{"price":"1732.77","quantity":"76.302"},{"price":"1733.95","quantity":"432.749"},{"price":"1734.06","quantity":"54.181"},{"price":"1734.18","quantity":"0.012"},{"price":"1734.19","quantity":"5.021"},{"price":"1734.75","quantity":"67.153"},{"price":"1735.16","quantity":"3.810"},{"price":"1735.56","quantity":"22.341"},{"price":"1735.60","quantity":"1.872"},{"price":"1735.67","quantity":"229.813"},{"price":"1735.78","quantity":"4.416"},{"price":"1736.10","quantity":"12.375"},{"price":"1736.16","quantity":"408.372"}],"asks":[{"price":"1736.20","quantity":"0.088"},{"price":"1736.36","quantity":"6.348"},{"price":"1736.39","quantity":"0.095"},{"price":"1736.55","quantity":"89.278"},{"price":"1736.73","quantity":"8.318"},{"price":"1736.83","quantity":"36.593"},{"price":"1736.88","quantity":"3.670"},{"price":"1737.12","quantity":"15.689"},{"price":"1738.46","quantity":"33.701"},{"price":"1739.98","quantity":"40.338"},{"price":"1750.93","quantity":"113.568"},{"price":"1776.10","quantity":"28.114"},{"price":"2635.09","quantity":"0.001"},{"price":"2635.18","quantity":"0.039"}],"raw":{"e":"depthUpdate","E":1783517065846,"T":1783517065845,"s":"ETHUSDT","ps":"ETHUSDT","U":10999770434508,"u":10999770443421,"pu":10999770434258,"b":[["1216.16","3.520"],["1221.16","5.792"],["1226.16","0.288"],["1562.54","0.212"],["1562.55","3.499"],["1701.43","0.142"],["1705.75","58.547"],["1710.17","22.211"],["1721.40","23.803"],["1724.99","0.588"],["1725.03","0.345"],["1732.77","76.302"],["1733.95","432.749"],["1734.06","54.181"],["1734.18","0.012"],["1734.19","5.021"],["1734.75","67.153"],["1735.16","3.810"],["1735.56","22.341"],["1735.60","1.872"],["1735.67","229.813"],["1735.78","4.416"],["1736.10","12.375"],["1736.16","408.372"]],"a":[["1736.20","0.088"],["1736.36","6.348"],["1736.39","0.095"],["1736.55","89.278"],["1736.73","8.318"],["1736.83","36.593"],["1736.88","3.670"],["1737.12","15.689"],["1738.46","33.701"],["1739.98","40.338"],["1750.93","113.568"],["1776.10","28.114"],["2635.09","0.001"],["2635.18","0.039"]],"st":1}}
{"schema_version":"1.3.0","event_id":"7d41a002-e45d-4dab-835a-cf215beb9ff1","event_type":"raw.depth_update","source":"binance_market_data_recorder","venue":"binance_usdm","market_type":"perpetual_futures","symbol":"BTCUSDT","event_time_ms":1783517065884,"received_time_ms":1783517065878,"trace_id":"f8bcc467-7f3d-4bb9-b056-9645171dded5","first_update_id":10999770437656,"final_update_id":10999770446885,"previous_final_update_id":10999770437447,"bids":[{"price":"1000.00","quantity":"207.692"},{"price":"11352.20","quantity":"0.080"},{"price":"11452.20","quantity":"2.736"},{"price":"11552.20","quantity":"1.013"},{"price":"11652.20","quantity":"1.071"},{"price":"55666.90","quantity":"0.003"},{"price":"60615.20","quantity":"0.045"},{"price":"60955.30","quantity":"12.617"},{"price":"61039.60","quantity":"0.000"},{"price":"61233.70","quantity":"0.000"},{"price":"61300.00","quantity":"78.955"},{"price":"61747.90","quantity":"0.014"},{"price":"61748.00","quantity":"0.157"},{"price":"61765.40","quantity":"0.028"},{"price":"61768.50","quantity":"0.008"},{"price":"61808.30","quantity":"1.119"},{"price":"61813.40","quantity":"0.000"},{"price":"61813.70","quantity":"1.381"},{"price":"61813.80","quantity":"0.014"},{"price":"61813.90","quantity":"0.104"},{"price":"61814.20","quantity":"0.277"},{"price":"61814.50","quantity":"0.003"},{"price":"61815.10","quantity":"0.105"},{"price":"61821.00","quantity":"0.793"},{"price":"61822.30","quantity":"0.007"},{"price":"61823.10","quantity":"0.006"},{"price":"61823.50","quantity":"0.092"},{"price":"61828.40","quantity":"0.016"},{"price":"61832.50","quantity":"0.004"},{"price":"61834.00","quantity":"3.610"},{"price":"61839.80","quantity":"1.048"},{"price":"61841.20","quantity":"0.003"},{"price":"61841.50","quantity":"0.221"},{"price":"61841.70","quantity":"0.021"},{"price":"61842.00","quantity":"0.022"},{"price":"61843.80","quantity":"1.234"},{"price":"61843.90","quantity":"0.889"},{"price":"61846.40","quantity":"0.121"},{"price":"61849.10","quantity":"2.138"},{"price":"61850.30","quantity":"0.053"},{"price":"61851.00","quantity":"0.001"},{"price":"61852.20","quantity":"15.997"}],"asks":[{"price":"61852.30","quantity":"2.037"},{"price":"61852.40","quantity":"0.003"},{"price":"61852.90","quantity":"0.001"},{"price":"61853.30","quantity":"0.507"},{"price":"61853.40","quantity":"0.001"},{"price":"61854.10","quantity":"0.000"},{"price":"61855.00","quantity":"1.956"},{"price":"61855.90","quantity":"0.242"},{"price":"61856.40","quantity":"1.791"},{"price":"61857.10","quantity":"0.002"},{"price":"61857.20","quantity":"0.000"},{"price":"61857.50","quantity":"0.001"},{"price":"61857.60","quantity":"0.051"},{"price":"61858.00","quantity":"0.763"},{"price":"61858.80","quantity":"0.002"},{"price":"61860.40","quantity":"0.496"},{"price":"61860.50","quantity":"0.972"},{"price":"61862.20","quantity":"1.032"},{"price":"61893.40","quantity":"0.243"},{"price":"61925.80","quantity":"0.275"},{"price":"62026.20","quantity":"0.000"},{"price":"62026.30","quantity":"0.003"},{"price":"62142.70","quantity":"0.018"},{"price":"62354.60","quantity":"0.002"},{"price":"62470.80","quantity":"0.002"},{"price":"62569.90","quantity":"3.832"},{"price":"62673.90","quantity":"0.000"},{"price":"62678.10","quantity":"0.279"},{"price":"63089.30","quantity":"0.138"},{"price":"89523.20","quantity":"0.696"}],"raw":{"e":"depthUpdate","E":1783517065884,"T":1783517065883,"s":"BTCUSDT","ps":"BTCUSDT","U":10999770437656,"u":10999770446885,"pu":10999770437447,"b":[["1000.00","207.692"],["11352.20","0.080"],["11452.20","2.736"],["11552.20","1.013"],["11652.20","1.071"],["55666.90","0.003"],["60615.20","0.045"],["60955.30","12.617"],["61039.60","0.000"],["61233.70","0.000"],["61300.00","78.955"],["61747.90","0.014"],["61748.00","0.157"],["61765.40","0.028"],["61768.50","0.008"],["61808.30","1.119"],["61813.40","0.000"],["61813.70","1.381"],["61813.80","0.014"],["61813.90","0.104"],["61814.20","0.277"],["61814.50","0.003"],["61815.10","0.105"],["61821.00","0.793"],["61822.30","0.007"],["61823.10","0.006"],["61823.50","0.092"],["61828.40","0.016"],["61832.50","0.004"],["61834.00","3.610"],["61839.80","1.048"],["61841.20","0.003"],["61841.50","0.221"],["61841.70","0.021"],["61842.00","0.022"],["61843.80","1.234"],["61843.90","0.889"],["61846.40","0.121"],["61849.10","2.138"],["61850.30","0.053"],["61851.00","0.001"],["61852.20","15.997"]],"a":[["61852.30","2.037"],["61852.40","0.003"],["61852.90","0.001"],["61853.30","0.507"],["61853.40","0.001"],["61854.10","0.000"],["61855.00","1.956"],["61855.90","0.242"],["61856.40","1.791"],["61857.10","0.002"],["61857.20","0.000"],["61857.50","0.001"],["61857.60","0.051"],["61858.00","0.763"],["61858.80","0.002"],["61860.40","0.496"],["61860.50","0.972"],["61862.20","1.032"],["61893.40","0.243"],["61925.80","0.275"],["62026.20","0.000"],["62026.30","0.003"],["62142.70","0.018"],["62354.60","0.002"],["62470.80","0.002"],["62569.90","3.832"],["62673.90","0.000"],["62678.10","0.279"],["63089.30","0.138"],["89523.20","0.696"]],"st":1}}
{"schema_version":"1.3.0","event_id":"480e4864-08e9-44ab-812a-22cc7e0885eb","event_type":"raw.trade","source":"binance_market_data_recorder","venue":"binance_usdm","market_type":"perpetual_futures","symbol":"ETHUSDT","event_time_ms":1783517065916,"received_time_ms":1783517065911,"trace_id":"d5f9286e-9f5d-41ec-aa43-1001e848e35c","trade_id":8429826596,"price":"1736.16","quantity":"0.014","trade_time_ms":1783517065916,"is_buyer_maker":true,"aggressor_side":"sell","raw":{"e":"trade","E":1783517065916,"T":1783517065916,"s":"ETHUSDT","t":8429826596,"p":"1736.16","q":"0.014","X":"MARKET","m":true,"st":1}}
{"schema_version":"1.3.0","event_id":"8f51305e-2ca5-4af6-a7e8-b974cc6e2a7b","event_type":"raw.depth_update","source":"binance_market_data_recorder","venue":"binance_usdm","market_type":"perpetual_futures","symbol":"ETHUSDT","event_time_ms":1783517065948,"received_time_ms":1783517065944,"trace_id":"ac6231b1-5537-4351-83c2-810eaff105c7","first_update_id":10999770443566,"final_update_id":10999770452298,"previous_final_update_id":10999770443421,"bids":[{"price":"200.00","quantity":"7.594"},{"price":"1216.16","quantity":"4.064"},{"price":"1221.16","quantity":"5.504"},{"price":"1226.16","quantity":"0.032"},{"price":"1562.54","quantity":"0.212"},{"price":"1562.55","quantity":"3.257"},{"price":"1666.70","quantity":"0.940"},{"price":"1684.56","quantity":"74.123"},{"price":"1701.43","quantity":"0.171"},{"price":"1703.17","quantity":"27.125"},{"price":"1705.72","quantity":"29.335"},{"price":"1708.32","quantity":"39.350"},{"price":"1709.53","quantity":"27.624"},{"price":"1710.12","quantity":"34.229"},{"price":"1727.25","quantity":"0.226"},{"price":"1727.29","quantity":"0.318"},{"price":"1733.04","quantity":"3.838"},{"price":"1733.95","quantity":"3.942"},{"price":"1734.07","quantity":"13.481"},{"price":"1734.13","quantity":"431.699"},{"price":"1735.17","quantity":"1.064"},{"price":"1735.18","quantity":"69.921"},{"price":"1735.25","quantity":"0.980"},{"price":"1735.26","quantity":"0.108"},{"price":"1735.64","quantity":"224.933"},{"price":"1735.67","quantity":"9.174"},{"price":"1735.79","quantity":"7.374"},{"price":"1736.08","quantity":"2.046"},{"price":"1736.13","quantity":"16.473"},{"price":"1736.16","quantity":"395.253"}],"asks":[{"price":"1736.21","quantity":"3.134"},{"price":"1736.28","quantity":"1.069"},{"price":"1736.41","quantity":"10.483"},{"price":"1736.81","quantity":"19.090"},{"price":"1737.17","quantity":"1.620"},{"price":"1737.39","quantity":"16.747"},{"price":"1737.42","quantity":"3.693"},{"price":"1737.56","quantity":"30.698"},{"price":"1737.65","quantity":"4.106"},{"price":"1738.97","quantity":"185.102"},{"price":"1740.00","quantity":"55.806"},{"price":"1747.12","quantity":"37.204"},{"price":"1762.52","quantity":"2.833"},{"price":"2635.08","quantity":"0.001"},{"price":"2635.17","quantity":"0.031"}],"raw":{"e":"depthUpdate","E":1783517065948,"T":1783517065945,"s":"ETHUSDT","ps":"ETHUSDT","U":10999770443566,"u":10999770452298,"pu":10999770443421,"b":[["200.00","7.594"],["1216.16","4.064"],["1221.16","5.504"],["1226.16","0.032"],["1562.54","0.212"],["1562.55","3.257"],["1666.70","0.940"],["1684.56","74.123"],["1701.43","0.171"],["1703.17","27.125"],["1705.72","29.335"],["1708.32","39.350"],["1709.53","27.624"],["1710.12","34.229"],["1727.25","0.226"],["1727.29","0.318"],["1733.04","3.838"],["1733.95","3.942"],["1734.07","13.481"],["1734.13","431.699"],["1735.17","1.064"],["1735.18","69.921"],["1735.25","0.980"],["1735.26","0.108"],["1735.64","224.933"],["1735.67","9.174"],["1735.79","7.374"],["1736.08","2.046"],["1736.13","16.473"],["1736.16","395.253"]],"a":[["1736.21","3.134"],["1736.28","1.069"],["1736.41","10.483"],["1736.81","19.090"],["1737.17","1.620"],["1737.39","16.747"],["1737.42","3.693"],["1737.56","30.698"],["1737.65","4.106"],["1738.97","185.102"],["1740.00","55.806"],["1747.12","37.204"],["1762.52","2.833"],["2635.08","0.001"],["2635.17","0.031"]],"st":1}}
{"schema_version":"1.3.0","event_id":"5bfca7a1-d615-4fbb-951f-980cd7c7e85e","event_type":"raw.depth_update","source":"binance_market_data_recorder","venue":"binance_usdm","market_type":"perpetual_futures","symbol":"BTCUSDT","event_time_ms":1783517065986,"received_time_ms":1783517065980,"trace_id":"33362c70-c4d0-4f9b-8584-027f5124e689","first_update_id":10999770446900,"final_update_id":10999770455075,"previous_final_update_id":10999770446885,"bids":[{"price":"11352.20","quantity":"0.224"},{"price":"11452.20","quantity":"2.720"},{"price":"11552.20","quantity":"1.038"},{"price":"11652.20","quantity":"0.918"},{"price":"49482.00","quantity":"0.000"},{"price":"55666.90","quantity":"0.001"},{"price":"59378.10","quantity":"0.000"},{"price":"61159.80","quantity":"0.000"},{"price":"61233.60","quantity":"6.986"},{"price":"61233.70","quantity":"0.000"},{"price":"61808.30","quantity":"1.115"},{"price":"61813.90","quantity":"0.003"},{"price":"61814.30","quantity":"0.331"},{"price":"61814.50","quantity":"0.007"},{"price":"61823.40","quantity":"0.181"},{"price":"61828.40","quantity":"0.000"},{"price":"61836.00","quantity":"0.144"},{"price":"61841.70","quantity":"0.910"},{"price":"61843.90","quantity":"0.000"},{"price":"61846.40","quantity":"0.041"},{"price":"61852.20","quantity":"15.998"}],"asks":[{"price":"61863.90","quantity":"0.309"},{"price":"61864.60","quantity":"1.535"},{"price":"61865.60","quantity":"0.005"},{"price":"61875.10","quantity":"2.120"},{"price":"61877.00","quantity":"0.166"},{"price":"61925.80","quantity":"0.372"},{"price":"62470.80","quantity":"0.000"},{"price":"62569.90","quantity":"2.874"},{"price":"62656.40","quantity":"2.711"}],"raw":{"e":"depthUpdate","E":1783517065986,"T":1783517065985,"s":"BTCUSDT","ps":"BTCUSDT","U":10999770446900,"u":10999770455075,"pu":10999770446885,"b":[["11352.20","0.224"],["11452.20","2.720"],["11552.20","1.038"],["11652.20","0.918"],["49482.00","0.000"],["55666.90","0.001"],["59378.10","0.000"],["61159.80","0.000"],["61233.60","6.986"],["61233.70","0.000"],["61808.30","1.115"],["61813.90","0.003"],["61814.30","0.331"],["61814.50","0.007"],["61823.40","0.181"],["61828.40","0.000"],["61836.00","0.144"],["61841.70","0.910"],["61843.90","0.000"],["61846.40","0.041"],["61852.20","15.998"]],"a":[["61863.90","0.309"],["61864.60","1.535"],["61865.60","0.005"],["61875.10","2.120"],["61877.00","0.166"],["61925.80","0.372"],["62470.80","0.000"],["62569.90","2.874"],["62656.40","2.711"]],"st":1}}
{"schema_version":"1.3.0","event_id":"f575bd9b-2d8c-4633-9ddd-4a3bcd7b883c","event_type":"raw.depth_update","source":"binance_market_data_recorder","venue":"binance_usdm","market_type":"perpetual_futures","symbol":"ETHUSDT","event_time_ms":1783517066050,"received_time_ms":1783517066045,"trace_id":"f773e33c-b0c7-4d90-8923-61d8c486cb91","first_update_id":10999770452523,"final_update_id":10999770460396,"previous_final_update_id":10999770452298,"bids":[{"price":"200.00","quantity":"7.594"},{"price":"1216.16","quantity":"4.864"},{"price":"1221.16","quantity":"4.736"},{"price":"1226.16","quantity":"0.000"},{"price":"1562.54","quantity":"0.212"},{"price":"1562.55","quantity":"3.257"},{"price":"1666.70","quantity":"0.825"},{"price":"1701.43","quantity":"0.142"},{"price":"1703.02","quantity":"29.485"},{"price":"1732.26","quantity":"20.837"},{"price":"1732.27","quantity":"35.499"},{"price":"1733.81","quantity":"25.379"},{"price":"1733.85","quantity":"55.264"},{"price":"1733.95","quantity":"432.749"},{"price":"1734.05","quantity":"13.271"},{"price":"1734.13","quantity":"2.892"},{"price":"1734.18","quantity":"0.012"},{"price":"1735.16","quantity":"3.810"},{"price":"1735.25","quantity":"0.929"},{"price":"1735.81","quantity":"9.457"},{"price":"1736.12","quantity":"11.547"},{"price":"1736.16","quantity":"399.427"}],"asks":[{"price":"1736.36","quantity":"6.348"},{"price":"1736.52","quantity":"24.279"},{"price":"1736.69","quantity":"9.640"},{"price":"1736.73","quantity":"8.836"},{"price":"1737.12","quantity":"13.995"},{"price":"1737.34","quantity":"14.909"},{"price":"1737.69","quantity":"27.123"},{"price":"1737.73","quantity":"1.999"},{"price":"1738.84","quantity":"2.936"},{"price":"1738.88","quantity":"1.122"},{"price":"1738.96","quantity":"0.000"},{"price":"1739.64","quantity":"7.141"},{"price":"1739.65","quantity":"0.055"},{"price":"1739.92","quantity":"31.490"},{"price":"1740.51","quantity":"32.875"},{"price":"1740.52","quantity":"0.024"},{"price":"1741.37","quantity":"12.199"},{"price":"1741.38","quantity":"0.673"},{"price":"1742.24","quantity":"22.246"},{"price":"1742.25","quantity":"16.413"},{"price":"1743.11","quantity":"2.304"},{"price":"1743.12","quantity":"33.605"},{"price":"1751.46","quantity":"24.520"},{"price":"2635.06","quantity":"0.012"},{"price":"2635.07","quantity":"0.001"},{"price":"2635.15","quantity":"0.000"},{"price":"2635.16","quantity":"0.000"}],"raw":{"e":"depthUpdate","E":1783517066050,"T":1783517066049,"s":"ETHUSDT","ps":"ETHUSDT","U":10999770452523,"u":10999770460396,"pu":10999770452298,"b":[["200.00","7.594"],["1216.16","4.864"],["1221.16","4.736"],["1226.16","0.000"],["1562.54","0.212"],["1562.55","3.257"],["1666.70","0.825"],["1701.43","0.142"],["1703.02","29.485"],["1732.26","20.837"],["1732.27","35.499"],["1733.81","25.379"],["1733.85","55.264"],["1733.95","432.749"],["1734.05","13.271"],["1734.13","2.892"],["1734.18","0.012"],["1735.16","3.810"],["1735.25","0.929"],["1735.81","9.457"],["1736.12","11.547"],["1736.16","399.427"]],"a":[["1736.36","6.348"],["1736.52","24.279"],["1736.69","9.640"],["1736.73","8.836"],["1737.12","13.995"],["1737.34","14.909"],["1737.69","27.123"],["1737.73","1.999"],["1738.84","2.936"],["1738.88","1.122"],["1738.96","0.000"],["1739.64","7.141"],["1739.65","0.055"],["1739.92","31.490"],["1740.51","32.875"],["1740.52","0.024"],["1741.37","12.199"],["1741.38","0.673"],["1742.24","22.246"],["1742.25","16.413"],["1743.11","2.304"],["1743.12","33.605"],["1751.46","24.520"],["2635.06","0.012"],["2635.07","0.001"],["2635.15","0.000"],["2635.16","0.000"]],"st":1}}
{"schema_version":"1.3.0","event_id":"99228e02-7db5-4ab0-90b1-5967839185e6","event_type":"raw.depth_update","source":"binance_market_data_recorder","venue":"binance_usdm","market_type":"perpetual_futures","symbol":"BTCUSDT","event_time_ms":1783517066088,"received_time_ms":1783517066084,"trace_id":"dd6c446e-f444-4800-a30c-da1e13703a7f","first_update_id":10999770455079,"final_update_id":10999770464378,"previous_final_update_id":10999770455075,"bids":[{"price":"1000.00","quantity":"207.692"},{"price":"11352.20","quantity":"0.352"},{"price":"11452.20","quantity":"2.736"},{"price":"11552.20","quantity":"1.030"},{"price":"11652.20","quantity":"0.782"},{"price":"55666.90","quantity":"0.003"},{"price":"58759.60","quantity":"0.009"},{"price":"59378.10","quantity":"0.003"},{"price":"61048.10","quantity":"2.618"},{"price":"61079.00","quantity":"1.341"},{"price":"61092.00","quantity":"7.209"},{"price":"61169.90","quantity":"0.736"},{"price":"61233.70","quantity":"0.000"},{"price":"61542.90","quantity":"0.001"},{"price":"61815.30","quantity":"1.173"},{"price":"61831.20","quantity":"0.081"},{"price":"61834.00","quantity":"3.414"},{"price":"61836.00","quantity":"0.064"},{"price":"61841.10","quantity":"0.405"},{"price":"61841.70","quantity":"0.344"},{"price":"61843.90","quantity":"0.566"}],"asks":[{"price":"61852.30","quantity":"2.038"},{"price":"61852.70","quantity":"0.007"},{"price":"61855.50","quantity":"0.245"},{"price":"61855.90","quantity":"0.000"},{"price":"61856.30","quantity":"0.032"},{"price":"61856.40","quantity":"1.069"},{"price":"61858.50","quantity":"0.540"},{"price":"61859.50","quantity":"0.005"},{"price":"61862.10","quantity":"1.617"},{"price":"61863.40","quantity":"0.033"},{"price":"61864.70","quantity":"3.064"},{"price":"61866.80","quantity":"3.443"},{"price":"61870.10","quantity":"0.361"},{"price":"61870.90","quantity":"0.149"},{"price":"61875.10","quantity":"2.118"},{"price":"61876.30","quantity":"0.401"},{"price":"61880.20","quantity":"0.170"},{"price":"61883.20","quantity":"0.005"},{"price":"61925.80","quantity":"0.275"},{"price":"62353.60","quantity":"0.320"},{"price":"62402.80","quantity":"2.719"},{"price":"62452.30","quantity":"1.020"},{"price":"62470.80","quantity":"0.049"},{"price":"62588.30","quantity":"1.916"},{"price":"89523.20","quantity":"0.702"}],"raw":{"e":"depthUpdate","E":1783517066088,"T":1783517066087,"s":"BTCUSDT","ps":"BTCUSDT","U":10999770455079,"u":10999770464378,"pu":10999770455075,"b":[["1000.00","207.692"],["11352.20","0.352"],["11452.20","2.736"],["11552.20","1.030"],["11652.20","0.782"],["55666.90","0.003"],["58759.60","0.009"],["59378.10","0.003"],["61048.10","2.618"],["61079.00","1.341"],["61092.00","7.209"],["61169.90","0.736"],["61233.70","0.000"],["61542.90","0.001"],["61815.30","1.173"],["61831.20","0.081"],["61834.00","3.414"],["61836.00","0.064"],["61841.10","0.405"],["61841.70","0.344"],["61843.90","0.566"]],"a":[["61852.30","2.038"],["61852.70","0.007"],["61855.50","0.245"],["61855.90","0.000"],["61856.30","0.032"],["61856.40","1.069"],["61858.50","0.540"],["61859.50","0.005"],["61862.10","1.617"],["61863.40","0.033"],["61864.70","3.064"],["61866.80","3.443"],["61870.10","0.361"],["61870.90","0.149"],["61875.10","2.118"],["61876.30","0.401"],["61880.20","0.170"],["61883.20","0.005"],["61925.80","0.275"],["62353.60","0.320"],["62402.80","2.719"],["62452.30","1.020"],["62470.80","0.049"],["62588.30","1.916"],["89523.20","0.702"]],"st":1}}
{"schema_version":"1.3.0","event_id":"2a315e58-c690-44a6-84fc-74237346aaff","event_type":"raw.trade","source":"binance_market_data_recorder","venue":"binance_usdm","market_type":"perpetual_futures","symbol":"BTCUSDT","event_time_ms":1783517066145,"received_time_ms":1783517066142,"trace_id":"9390569e-324f-4a37-9e73-c7baf54824a5","trade_id":7881418006,"price":"61852.30","quantity":"0.001","trade_time_ms":1783517066145,"is_buyer_maker":false,"aggressor_side":"buy","raw":{"e":"trade","E":1783517066145,"T":1783517066145,"s":"BTCUSDT","t":7881418006,"p":"61852.30","q":"0.001","X":"MARKET","m":false,"st":1}}
{"schema_version":"1.3.0","event_id":"4d8fd6d2-25f5-4917-a9fa-663817e53537","event_type":"raw.trade","source":"binance_market_data_recorder","venue":"binance_usdm","market_type":"perpetual_futures","symbol":"BTCUSDT","event_time_ms":1783517066145,"received_time_ms":1783517066143,"trace_id":"31fa11a4-21d7-4f55-98ee-99c5b1586dbd","trade_id":7881418007,"price":"61852.30","quantity":"0.007","trade_time_ms":1783517066145,"is_buyer_maker":false,"aggressor_side":"buy","raw":{"e":"trade","E":1783517066145,"T":1783517066145,"s":"BTCUSDT","t":7881418007,"p":"61852.30","q":"0.007","X":"MARKET","m":false,"st":1}}
{"schema_version":"1.3.0","event_id":"08cf514d-b838-4479-8a73-428e2e996ee6","event_type":"raw.depth_update","source":"binance_market_data_recorder","venue":"binance_usdm","market_type":"perpetual_futures","symbol":"ETHUSDT","event_time_ms":1783517066152,"received_time_ms":1783517066167,"trace_id":"093d427f-cc36-4dec-a7d4-405f3610775e","first_update_id":10999770460510,"final_update_id":10999770472217,"previous_final_update_id":10999770460396,"bids":[{"price":"1216.16","quantity":"5.664"},{"price":"1221.16","quantity":"3.936"},{"price":"1562.54","quantity":"0.212"},{"price":"1562.55","quantity":"3.385"},{"price":"1666.70","quantity":"0.940"},{"price":"1685.35","quantity":"0.033"},{"price":"1701.43","quantity":"0.171"},{"price":"1703.82","quantity":"173.374"},{"price":"1705.02","quantity":"134.763"},{"price":"1733.95","quantity":"3.942"},{"price":"1734.13","quantity":"2.892"},{"price":"1734.18","quantity":"428.819"},{"price":"1735.55","quantity":"3.080"},{"price":"1735.60","quantity":"0.172"},{"price":"1735.77","quantity":"13.310"},{"price":"1735.78","quantity":"6.116"},{"price":"1735.81","quantity":"9.313"},{"price":"1736.00","quantity":"1.754"},{"price":"1736.12","quantity":"11.106"},{"price":"1736.16","quantity":"399.859"}],"asks":[{"price":"1736.17","quantity":"27.296"},{"price":"1736.43","quantity":"10.243"},{"price":"1736.52","quantity":"25.802"},{"price":"1736.55","quantity":"90.978"},{"price":"1736.61","quantity":"6.517"},{"price":"1736.64","quantity":"46.656"},{"price":"1736.73","quantity":"7.136"},{"price":"1737.17","quantity":"1.620"},{"price":"1738.00","quantity":"14.422"},{"price":"1738.86","quantity":"2.881"},{"price":"1744.86","quantity":"40.385"},{"price":"1767.72","quantity":"107.354"},{"price":"2635.05","quantity":"0.001"},{"price":"2635.14","quantity":"0.013"}],"raw":{"e":"depthUpdate","E":1783517066152,"T":1783517066151,"s":"ETHUSDT","ps":"ETHUSDT","U":10999770460510,"u":10999770472217,"pu":10999770460396,"b":[["1216.16","5.664"],["1221.16","3.936"],["1562.54","0.212"],["1562.55","3.385"],["1666.70","0.940"],["1685.35","0.033"],["1701.43","0.171"],["1703.82","173.374"],["1705.02","134.763"],["1733.95","3.942"],["1734.13","2.892"],["1734.18","428.819"],["1735.55","3.080"],["1735.60","0.172"],["1735.77","13.310"],["1735.78","6.116"],["1735.81","9.313"],["1736.00","1.754"],["1736.12","11.106"],["1736.16","399.859"]],"a":[["1736.17","27.296"],["1736.43","10.243"],["1736.52","25.802"],["1736.55","90.978"],["1736.61","6.517"],["1736.64","46.656"],["1736.73","7.136"],["1737.17","1.620"],["1738.00","14.422"],["1738.86","2.881"],["1744.86","40.385"],["1767.72","107.354"],["2635.05","0.001"],["2635.14","0.013"]],"st":1}}
{"schema_version":"1.3.0","event_id":"c149eeee-62d9-4625-8666-7ec45f5571f7","event_type":"raw.trade","source":"binance_market_data_recorder","venue":"binance_usdm","market_type":"perpetual_futures","symbol":"ETHUSDT","event_time_ms":1783517066159,"received_time_ms":1783517066180,"trace_id":"6e74019f-4620-4809-9a3f-8d65afbed589","trade_id":8429826597,"price":"1736.16","quantity":"0.014","trade_time_ms":1783517066159,"is_buyer_maker":true,"aggressor_side":"sell","raw":{"e":"trade","E":1783517066159,"T":1783517066159,"s":"ETHUSDT","t":8429826597,"p":"1736.16","q":"0.014","X":"MARKET","m":true,"st":1}}
{"schema_version":"1.3.0","event_id":"4da63551-4630-4a38-aefd-ecad550cd3f0","event_type":"raw.trade","source":"binance_market_data_recorder","venue":"binance_usdm","market_type":"perpetual_futures","symbol":"ETHUSDT","event_time_ms":1783517066164,"received_time_ms":1783517066188,"trace_id":"36348a8e-5fc9-4cc0-a567-543bfec4d905","trade_id":8429826598,"price":"1736.17","quantity":"14.675","trade_time_ms":1783517066164,"is_buyer_maker":false,"aggressor_side":"buy","raw":{"e":"trade","E":1783517066164,"T":1783517066164,"s":"ETHUSDT","t":8429826598,"p":"1736.17","q":"14.675","X":"MARKET","m":false,"st":1}}
{"schema_version":"1.3.0","event_id":"32108097-db9a-49fb-9c16-d68bebbe047e","event_type":"raw.trade","source":"binance_market_data_recorder","venue":"binance_usdm","market_type":"perpetual_futures","symbol":"ETHUSDT","event_time_ms":1783517066164,"received_time_ms":1783517066189,"trace_id":"2ecb75bc-d9ba-436f-a2e0-d2d7ce37ffb9","trade_id":8429826599,"price":"1736.17","quantity":"0.022","trade_time_ms":1783517066164,"is_buyer_maker":false,"aggressor_side":"buy","raw":{"e":"trade","E":1783517066164,"T":1783517066164,"s":"ETHUSDT","t":8429826599,"p":"1736.17","q":"0.022","X":"MARKET","m":false,"st":1}}
{"schema_version":"1.3.0","event_id":"6882d92c-2019-478f-95fc-0081e4d3ac1c","event_type":"raw.trade","source":"binance_market_data_recorder","venue":"binance_usdm","market_type":"perpetual_futures","symbol":"ETHUSDT","event_time_ms":1783517066164,"received_time_ms":1783517066189,"trace_id":"56f92c08-1989-453d-b2ec-1eb74b38f5b4","trade_id":8429826600,"price":"1736.17","quantity":"0.012","trade_time_ms":1783517066164,"is_buyer_maker":false,"aggressor_side":"buy","raw":{"e":"trade","E":1783517066164,"T":1783517066164,"s":"ETHUSDT","t":8429826600,"p":"1736.17","q":"0.012","X":"MARKET","m":false,"st":1}}
{"schema_version":"1.3.0","event_id":"ea92274e-f755-4a13-b743-bc8af40c55bd","event_type":"raw.trade","source":"binance_market_data_recorder","venue":"binance_usdm","market_type":"perpetual_futures","symbol":"ETHUSDT","event_time_ms":1783517066164,"received_time_ms":1783517066190,"trace_id":"f9b356d5-902d-4d3f-802b-e609b728867d","trade_id":8429826601,"price":"1736.17","quantity":"0.012","trade_time_ms":1783517066164,"is_buyer_maker":false,"aggressor_side":"buy","raw":{"e":"trade","E":1783517066164,"T":1783517066164,"s":"ETHUSDT","t":8429826601,"p":"1736.17","q":"0.012","X":"MARKET","m":false,"st":1}}
{"schema_version":"1.3.0","event_id":"f06b2f30-64b5-4de1-aa85-125817a920c6","event_type":"raw.trade","source":"binance_market_data_recorder","venue":"binance_usdm","market_type":"perpetual_futures","symbol":"ETHUSDT","event_time_ms":1783517066164,"received_time_ms":1783517066190,"trace_id":"bf52c124-ac53-4270-920d-79ffaaa4fff4","trade_id":8429826602,"price":"1736.17","quantity":"1.509","trade_time_ms":1783517066164,"is_buyer_maker":false,"aggressor_side":"buy","raw":{"e":"trade","E":1783517066164,"T":1783517066164,"s":"ETHUSDT","t":8429826602,"p":"1736.17","q":"1.509","X":"MARKET","m":false,"st":1}}
{"schema_version":"1.3.0","event_id":"b4bb257c-786b-430d-a8c2-3c548f12cfec","event_type":"raw.trade","source":"binance_market_data_recorder","venue":"binance_usdm","market_type":"perpetual_futures","symbol":"ETHUSDT","event_time_ms":1783517066164,"received_time_ms":1783517066191,"trace_id":"e00b6e1f-5c0d-412d-ace4-d5cb1451ff76","trade_id":8429826603,"price":"1736.17","quantity":"0.014","trade_time_ms":1783517066164,"is_buyer_maker":false,"aggressor_side":"buy","raw":{"e":"trade","E":1783517066164,"T":1783517066164,"s":"ETHUSDT","t":8429826603,"p":"1736.17","q":"0.014","X":"MARKET","m":false,"st":1}}
{"schema_version":"1.3.0","event_id":"98fffb11-28e6-4dfa-916b-3cf4720b159c","event_type":"raw.trade","source":"binance_market_data_recorder","venue":"binance_usdm","market_type":"perpetual_futures","symbol":"ETHUSDT","event_time_ms":1783517066164,"received_time_ms":1783517066191,"trace_id":"7aa514d1-8d8e-45d9-80cb-904673a43852","trade_id":8429826604,"price":"1736.17","quantity":"0.013","trade_time_ms":1783517066164,"is_buyer_maker":false,"aggressor_side":"buy","raw":{"e":"trade","E":1783517066164,"T":1783517066164,"s":"ETHUSDT","t":8429826604,"p":"1736.17","q":"0.013","X":"MARKET","m":false,"st":1}}
{"schema_version":"1.3.0","event_id":"97f6e05c-53e4-4eeb-9c91-5055f71ff632","event_type":"raw.trade","source":"binance_market_data_recorder","venue":"binance_usdm","market_type":"perpetual_futures","symbol":"ETHUSDT","event_time_ms":1783517066164,"received_time_ms":1783517066192,"trace_id":"c5ea3ef5-feb5-42f7-ae8c-0b88af6b2a04","trade_id":8429826605,"price":"1736.17","quantity":"1.429","trade_time_ms":1783517066164,"is_buyer_maker":false,"aggressor_side":"buy","raw":{"e":"trade","E":1783517066164,"T":1783517066164,"s":"ETHUSDT","t":8429826605,"p":"1736.17","q":"1.429","X":"MARKET","m":false,"st":1}}
{"schema_version":"1.3.0","event_id":"66e852d5-3966-4c23-8cad-cb2e38911e59","event_type":"raw.trade","source":"binance_market_data_recorder","venue":"binance_usdm","market_type":"perpetual_futures","symbol":"ETHUSDT","event_time_ms":1783517066164,"received_time_ms":1783517066193,"trace_id":"8ba2eb56-2ee3-435e-9803-36a8e05cd05f","trade_id":8429826606,"price":"1736.17","quantity":"1.572","trade_time_ms":1783517066164,"is_buyer_maker":false,"aggressor_side":"buy","raw":{"e":"trade","E":1783517066164,"T":1783517066164,"s":"ETHUSDT","t":8429826606,"p":"1736.17","q":"1.572","X":"MARKET","m":false,"st":1}}
{"schema_version":"1.3.0","event_id":"149040c2-f14b-4b1f-b3cb-b8f4b6a85f2a","event_type":"raw.trade","source":"binance_market_data_recorder","venue":"binance_usdm","market_type":"perpetual_futures","symbol":"ETHUSDT","event_time_ms":1783517066164,"received_time_ms":1783517066195,"trace_id":"7ae6f2f4-642c-4b98-9bfd-4a9de3ab1d12","trade_id":8429826607,"price":"1736.17","quantity":"7.813","trade_time_ms":1783517066164,"is_buyer_maker":false,"aggressor_side":"buy","raw":{"e":"trade","E":1783517066164,"T":1783517066164,"s":"ETHUSDT","t":8429826607,"p":"1736.17","q":"7.813","X":"MARKET","m":false,"st":1}}
{"schema_version":"1.3.0","event_id":"e274fa83-c107-40c2-8c2a-b2443e1633bd","event_type":"raw.trade","source":"binance_market_data_recorder","venue":"binance_usdm","market_type":"perpetual_futures","symbol":"ETHUSDT","event_time_ms":1783517066164,"received_time_ms":1783517066195,"trace_id":"69e7c9cd-1dee-48d6-b0f7-2aa41edbabe4","trade_id":8429826608,"price":"1736.17","quantity":"0.012","trade_time_ms":1783517066164,"is_buyer_maker":false,"aggressor_side":"buy","raw":{"e":"trade","E":1783517066164,"T":1783517066164,"s":"ETHUSDT","t":8429826608,"p":"1736.17","q":"0.012","X":"MARKET","m":false,"st":1}}
{"schema_version":"1.3.0","event_id":"62d7f113-0c81-4ab9-ab9f-1750f2ca8b82","event_type":"raw.trade","source":"binance_market_data_recorder","venue":"binance_usdm","market_type":"perpetual_futures","symbol":"ETHUSDT","event_time_ms":1783517066164,"received_time_ms":1783517066196,"trace_id":"ac7f9378-1fb7-4b39-98c2-eea85cd6a621","trade_id":8429826609,"price":"1736.17","quantity":"0.012","trade_time_ms":1783517066164,"is_buyer_maker":false,"aggressor_side":"buy","raw":{"e":"trade","E":1783517066164,"T":1783517066164,"s":"ETHUSDT","t":8429826609,"p":"1736.17","q":"0.012","X":"MARKET","m":false,"st":1}}
{"schema_version":"1.3.0","event_id":"7704c23b-9948-4398-b81d-cd49cda2565f","event_type":"raw.trade","source":"binance_market_data_recorder","venue":"binance_usdm","market_type":"perpetual_futures","symbol":"ETHUSDT","event_time_ms":1783517066164,"received_time_ms":1783517066196,"trace_id":"606c60d9-75e2-485a-a30b-26cdc1086ef9","trade_id":8429826610,"price":"1736.17","quantity":"0.018","trade_time_ms":1783517066164,"is_buyer_maker":false,"aggressor_side":"buy","raw":{"e":"trade","E":1783517066164,"T":1783517066164,"s":"ETHUSDT","t":8429826610,"p":"1736.17","q":"0.018","X":"MARKET","m":false,"st":1}}
{"schema_version":"1.3.0","event_id":"2228b6d0-38a1-46fa-8205-c994fe888032","event_type":"raw.trade","source":"binance_market_data_recorder","venue":"binance_usdm","market_type":"perpetual_futures","symbol":"ETHUSDT","event_time_ms":1783517066164,"received_time_ms":1783517066197,"trace_id":"e37c2e28-e67d-45ce-aae8-e2bf6bfa53c0","trade_id":8429826611,"price":"1736.17","quantity":"0.012","trade_time_ms":1783517066164,"is_buyer_maker":false,"aggressor_side":"buy","raw":{"e":"trade","E":1783517066164,"T":1783517066164,"s":"ETHUSDT","t":8429826611,"p":"1736.17","q":"0.012","X":"MARKET","m":false,"st":1}}
{"schema_version":"1.3.0","event_id":"2154e2df-16f6-4c48-b55e-a9c2fcce135e","event_type":"raw.trade","source":"binance_market_data_recorder","venue":"binance_usdm","market_type":"perpetual_futures","symbol":"ETHUSDT","event_time_ms":1783517066164,"received_time_ms":1783517066198,"trace_id":"f90bfe3b-e3ca-4a12-aa3c-c273cb4777c0","trade_id":8429826612,"price":"1736.17","quantity":"0.012","trade_time_ms":1783517066164,"is_buyer_maker":false,"aggressor_side":"buy","raw":{"e":"trade","E":1783517066164,"T":1783517066164,"s":"ETHUSDT","t":8429826612,"p":"1736.17","q":"0.012","X":"MARKET","m":false,"st":1}}
{"schema_version":"1.3.0","event_id":"b1b1ee5f-d47c-4053-8788-8271b2bb9eff","event_type":"raw.trade","source":"binance_market_data_recorder","venue":"binance_usdm","market_type":"perpetual_futures","symbol":"ETHUSDT","event_time_ms":1783517066164,"received_time_ms":1783517066198,"trace_id":"c4b64d64-68b3-4324-9e64-068d012cc2b8","trade_id":8429826613,"price":"1736.17","quantity":"0.147","trade_time_ms":1783517066164,"is_buyer_maker":false,"aggressor_side":"buy","raw":{"e":"trade","E":1783517066164,"T":1783517066164,"s":"ETHUSDT","t":8429826613,"p":"1736.17","q":"0.147","X":"MARKET","m":false,"st":1}}
{"schema_version":"1.3.0","event_id":"7931fe69-b11d-4e74-b7e2-a9f6597e04f3","event_type":"raw.trade","source":"binance_market_data_recorder","venue":"binance_usdm","market_type":"perpetual_futures","symbol":"ETHUSDT","event_time_ms":1783517066164,"received_time_ms":1783517066199,"trace_id":"1052ad19-4619-40d0-9374-e4343a25666f","trade_id":8429826614,"price":"1736.18","quantity":"0.012","trade_time_ms":1783517066164,"is_buyer_maker":false,"aggressor_side":"buy","raw":{"e":"trade","E":1783517066164,"T":1783517066164,"s":"ETHUSDT","t":8429826614,"p":"1736.18","q":"0.012","X":"MARKET","m":false,"st":1}}
{"schema_version":"1.3.0","event_id":"b066c8f4-28b7-4702-9a1a-1875fca04797","event_type":"raw.trade","source":"binance_market_data_recorder","venue":"binance_usdm","market_type":"perpetual_futures","symbol":"ETHUSDT","event_time_ms":1783517066164,"received_time_ms":1783517066200,"trace_id":"3df9bf04-be86-406e-b5bb-ba2dc8b46d44","trade_id":8429826615,"price":"1736.19","quantity":"0.335","trade_time_ms":1783517066164,"is_buyer_maker":false,"aggressor_side":"buy","raw":{"e":"trade","E":1783517066164,"T":1783517066164,"s":"ETHUSDT","t":8429826615,"p":"1736.19","q":"0.335","X":"MARKET","m":false,"st":1}}
{"schema_version":"1.3.0","event_id":"ea1a3203-dd41-46a3-91e6-c7375250ad41","event_type":"raw.trade","source":"binance_market_data_recorder","venue":"binance_usdm","market_type":"perpetual_futures","symbol":"ETHUSDT","event_time_ms":1783517066164,"received_time_ms":1783517066200,"trace_id":"6db4a636-841e-4902-9d40-ee6d6bf9744a","trade_id":8429826616,"price":"1736.19","quantity":"0.288","trade_time_ms":1783517066164,"is_buyer_maker":false,"aggressor_side":"buy","raw":{"e":"trade","E":1783517066164,"T":1783517066164,"s":"ETHUSDT","t":8429826616,"p":"1736.19","q":"0.288","X":"MARKET","m":false,"st":1}}
{"schema_version":"1.3.0","event_id":"a3e381dc-c3d9-45d2-92ea-f3f59c8a3268","event_type":"raw.trade","source":"binance_market_data_recorder","venue":"binance_usdm","market_type":"perpetual_futures","symbol":"ETHUSDT","event_time_ms":1783517066164,"received_time_ms":1783517066201,"trace_id":"c55bf6b0-dccf-4a8a-9e8c-19273e944a54","trade_id":8429826617,"price":"1736.19","quantity":"1.970","trade_time_ms":1783517066164,"is_buyer_maker":false,"aggressor_side":"buy","raw":{"e":"trade","E":1783517066164,"T":1783517066164,"s":"ETHUSDT","t":8429826617,"p":"1736.19","q":"1.970","X":"MARKET","m":false,"st":1}}
{"schema_version":"1.3.0","event_id":"3de4b0a1-87fc-4f0b-a714-748dde3089cb","event_type":"raw.trade","source":"binance_market_data_recorder","venue":"binance_usdm","market_type":"perpetual_futures","symbol":"ETHUSDT","event_time_ms":1783517066164,"received_time_ms":1783517066201,"trace_id":"d2027d65-128f-43a8-b54c-a03d83eba046","trade_id":8429826618,"price":"1736.19","quantity":"0.014","trade_time_ms":1783517066164,"is_buyer_maker":false,"aggressor_side":"buy","raw":{"e":"trade","E":1783517066164,"T":1783517066164,"s":"ETHUSDT","t":8429826618,"p":"1736.19","q":"0.014","X":"MARKET","m":false,"st":1}}
{"schema_version":"1.3.0","event_id":"98e4fa20-af9d-4618-a025-9c10d535b03a","event_type":"raw.trade","source":"binance_market_data_recorder","venue":"binance_usdm","market_type":"perpetual_futures","symbol":"ETHUSDT","event_time_ms":1783517066164,"received_time_ms":1783517066202,"trace_id":"efe0b3ab-d151-4822-ba66-39cb7d824667","trade_id":8429826619,"price":"1736.20","quantity":"0.013","trade_time_ms":1783517066164,"is_buyer_maker":false,"aggressor_side":"buy","raw":{"e":"trade","E":1783517066164,"T":1783517066164,"s":"ETHUSDT","t":8429826619,"p":"1736.20","q":"0.013","X":"MARKET","m":false,"st":1}}
{"schema_version":"1.3.0","event_id":"f1d522e2-c126-4d85-86ff-fd4ada175c54","event_type":"raw.trade","source":"binance_market_data_recorder","venue":"binance_usdm","market_type":"perpetual_futures","symbol":"ETHUSDT","event_time_ms":1783517066164,"received_time_ms":1783517066202,"trace_id":"89675a6f-d1b6-4efb-8785-f1dca03d22ff","trade_id":8429826620,"price":"1736.20","quantity":"0.012","trade_time_ms":1783517066164,"is_buyer_maker":false,"aggressor_side":"buy","raw":{"e":"trade","E":1783517066164,"T":1783517066164,"s":"ETHUSDT","t":8429826620,"p":"1736.20","q":"0.012","X":"MARKET","m":false,"st":1}}
{"schema_version":"1.3.0","event_id":"629f5deb-cb21-45a2-a709-ec4653857663","event_type":"raw.trade","source":"binance_market_data_recorder","venue":"binance_usdm","market_type":"perpetual_futures","symbol":"ETHUSDT","event_time_ms":1783517066164,"received_time_ms":1783517066203,"trace_id":"78e1655d-db33-4c34-b7d9-34bc84903877","trade_id":8429826621,"price":"1736.20","quantity":"0.022","trade_time_ms":1783517066164,"is_buyer_maker":false,"aggressor_side":"buy","raw":{"e":"trade","E":1783517066164,"T":1783517066164,"s":"ETHUSDT","t":8429826621,"p":"1736.20","q":"0.022","X":"MARKET","m":false,"st":1}}
{"schema_version":"1.3.0","event_id":"2741b6be-d0d9-4554-b025-f42a68eaa5e1","event_type":"raw.trade","source":"binance_market_data_recorder","venue":"binance_usdm","market_type":"perpetual_futures","symbol":"ETHUSDT","event_time_ms":1783517066164,"received_time_ms":1783517066203,"trace_id":"87466b6f-c9eb-4c9b-8ba5-acb56c75ba3e","trade_id":8429826622,"price":"1736.20","quantity":"0.017","trade_time_ms":1783517066164,"is_buyer_maker":false,"aggressor_side":"buy","raw":{"e":"trade","E":1783517066164,"T":1783517066164,"s":"ETHUSDT","t":8429826622,"p":"1736.20","q":"0.017","X":"MARKET","m":false,"st":1}}
{"schema_version":"1.3.0","event_id":"4b7253c2-cf3a-47d7-a939-94b5d83dcc4f","event_type":"raw.trade","source":"binance_market_data_recorder","venue":"binance_usdm","market_type":"perpetual_futures","symbol":"ETHUSDT","event_time_ms":1783517066164,"received_time_ms":1783517066204,"trace_id":"cd244ea5-d7c5-4457-85e5-0e8e4ed33df4","trade_id":8429826623,"price":"1736.21","quantity":"3.084","trade_time_ms":1783517066164,"is_buyer_maker":false,"aggressor_side":"buy","raw":{"e":"trade","E":1783517066164,"T":1783517066164,"s":"ETHUSDT","t":8429826623,"p":"1736.21","q":"3.084","X":"MARKET","m":false,"st":1}}
{"schema_version":"1.3.0","event_id":"15b4c4c6-6dc8-4ba1-b958-ccb668061dd5","event_type":"raw.trade","source":"binance_market_data_recorder","venue":"binance_usdm","market_type":"perpetual_futures","symbol":"ETHUSDT","event_time_ms":1783517066164,"received_time_ms":1783517066205,"trace_id":"8b3c5407-0a50-48ae-81c4-d8c723351814","trade_id":8429826624,"price":"1736.21","quantity":"0.012","trade_time_ms":1783517066164,"is_buyer_maker":false,"aggressor_side":"buy","raw":{"e":"trade","E":1783517066164,"T":1783517066164,"s":"ETHUSDT","t":8429826624,"p":"1736.21","q":"0.012","X":"MARKET","m":false,"st":1}}
{"schema_version":"1.3.0","event_id":"533de125-ffb5-46c8-bed9-afd66a6f7df0","event_type":"raw.trade","source":"binance_market_data_recorder","venue":"binance_usdm","market_type":"perpetual_futures","symbol":"ETHUSDT","event_time_ms":1783517066164,"received_time_ms":1783517066206,"trace_id":"d0821fbf-a60c-4a37-9e2c-0ddd171509f8","trade_id":8429826625,"price":"1736.21","quantity":"0.014","trade_time_ms":1783517066164,"is_buyer_maker":false,"aggressor_side":"buy","raw":{"e":"trade","E":1783517066164,"T":1783517066164,"s":"ETHUSDT","t":8429826625,"p":"1736.21","q":"0.014","X":"MARKET","m":false,"st":1}}
{"schema_version":"1.3.0","event_id":"7f1d1775-074f-46cc-9320-ddd4a36acaef","event_type":"raw.trade","source":"binance_market_data_recorder","venue":"binance_usdm","market_type":"perpetual_futures","symbol":"ETHUSDT","event_time_ms":1783517066164,"received_time_ms":1783517066206,"trace_id":"e0b863bd-6c67-46ef-beb5-8710e4f536b8","trade_id":8429826626,"price":"1736.21","quantity":"0.001","trade_time_ms":1783517066164,"is_buyer_maker":false,"aggressor_side":"buy","raw":{"e":"trade","E":1783517066164,"T":1783517066164,"s":"ETHUSDT","t":8429826626,"p":"1736.21","q":"0.001","X":"MARKET","m":false,"st":1}}
{"schema_version":"1.3.0","event_id":"a2357bf3-6fdb-4c2c-8c71-c5b6dd188bb4","event_type":"raw.trade","source":"binance_market_data_recorder","venue":"binance_usdm","market_type":"perpetual_futures","symbol":"ETHUSDT","event_time_ms":1783517066164,"received_time_ms":1783517066207,"trace_id":"b2a4bf7a-2bf0-44c5-91d0-f96b8ff8f00d","trade_id":8429826627,"price":"1736.21","quantity":"0.001","trade_time_ms":1783517066164,"is_buyer_maker":false,"aggressor_side":"buy","raw":{"e":"trade","E":1783517066164,"T":1783517066164,"s":"ETHUSDT","t":8429826627,"p":"1736.21","q":"0.001","X":"MARKET","m":false,"st":1}}
{"schema_version":"1.3.0","event_id":"891a4340-4ce1-4092-8035-801a7aabf8a7","event_type":"raw.trade","source":"binance_market_data_recorder","venue":"binance_usdm","market_type":"perpetual_futures","symbol":"ETHUSDT","event_time_ms":1783517066164,"received_time_ms":1783517066207,"trace_id":"696da064-f75e-41eb-be5f-638390089f8b","trade_id":8429826628,"price":"1736.21","quantity":"0.001","trade_time_ms":1783517066164,"is_buyer_maker":false,"aggressor_side":"buy","raw":{"e":"trade","E":1783517066164,"T":1783517066164,"s":"ETHUSDT","t":8429826628,"p":"1736.21","q":"0.001","X":"MARKET","m":false,"st":1}}
{"schema_version":"1.3.0","event_id":"9abd3d26-06e5-4aac-9c31-ad2559c5a05e","event_type":"raw.trade","source":"binance_market_data_recorder","venue":"binance_usdm","market_type":"perpetual_futures","symbol":"ETHUSDT","event_time_ms":1783517066164,"received_time_ms":1783517066208,"trace_id":"1b171b5f-7fef-412f-9b92-10ea278ecbc6","trade_id":8429826629,"price":"1736.21","quantity":"0.001","trade_time_ms":1783517066164,"is_buyer_maker":false,"aggressor_side":"buy","raw":{"e":"trade","E":1783517066164,"T":1783517066164,"s":"ETHUSDT","t":8429826629,"p":"1736.21","q":"0.001","X":"MARKET","m":false,"st":1}}
{"schema_version":"1.3.0","event_id":"72fa8cfa-e559-4823-b9b4-95b48265f2a2","event_type":"raw.trade","source":"binance_market_data_recorder","venue":"binance_usdm","market_type":"perpetual_futures","symbol":"ETHUSDT","event_time_ms":1783517066164,"received_time_ms":1783517066209,"trace_id":"7c791118-8e7d-477b-b5f8-15dc6f231408","trade_id":8429826630,"price":"1736.21","quantity":"0.001","trade_time_ms":1783517066164,"is_buyer_maker":false,"aggressor_side":"buy","raw":{"e":"trade","E":1783517066164,"T":1783517066164,"s":"ETHUSDT","t":8429826630,"p":"1736.21","q":"0.001","X":"MARKET","m":false,"st":1}}
{"schema_version":"1.3.0","event_id":"04a47c56-aa15-498f-831b-ed2277eccd5e","event_type":"raw.trade","source":"binance_market_data_recorder","venue":"binance_usdm","market_type":"perpetual_futures","symbol":"ETHUSDT","event_time_ms":1783517066164,"received_time_ms":1783517066209,"trace_id":"92c0f8d7-76de-4179-aaba-347c6f2ccfcb","trade_id":8429826631,"price":"1736.21","quantity":"0.001","trade_time_ms":1783517066164,"is_buyer_maker":false,"aggressor_side":"buy","raw":{"e":"trade","E":1783517066164,"T":1783517066164,"s":"ETHUSDT","t":8429826631,"p":"1736.21","q":"0.001","X":"MARKET","m":false,"st":1}}
{"schema_version":"1.3.0","event_id":"db093aa8-0778-4178-87fa-2b9ff3c27b0b","event_type":"raw.trade","source":"binance_market_data_recorder","venue":"binance_usdm","market_type":"perpetual_futures","symbol":"ETHUSDT","event_time_ms":1783517066164,"received_time_ms":1783517066211,"trace_id":"1eae8e25-3640-46a1-838b-6fd74fd63a02","trade_id":8429826632,"price":"1736.21","quantity":"0.001","trade_time_ms":1783517066164,"is_buyer_maker":false,"aggressor_side":"buy","raw":{"e":"trade","E":1783517066164,"T":1783517066164,"s":"ETHUSDT","t":8429826632,"p":"1736.21","q":"0.001","X":"MARKET","m":false,"st":1}}
{"schema_version":"1.3.0","event_id":"4fe6da6d-5d07-4bf5-a049-50748ccf075d","event_type":"raw.trade","source":"binance_market_data_recorder","venue":"binance_usdm","market_type":"perpetual_futures","symbol":"ETHUSDT","event_time_ms":1783517066164,"received_time_ms":1783517066211,"trace_id":"105514af-d677-4988-b098-0fbc95176531","trade_id":8429826633,"price":"1736.21","quantity":"0.001","trade_time_ms":1783517066164,"is_buyer_maker":false,"aggressor_side":"buy","raw":{"e":"trade","E":1783517066164,"T":1783517066164,"s":"ETHUSDT","t":8429826633,"p":"1736.21","q":"0.001","X":"MARKET","m":false,"st":1}}
{"schema_version":"1.3.0","event_id":"10603a63-292c-4e63-804a-210d5ad82049","event_type":"raw.trade","source":"binance_market_data_recorder","venue":"binance_usdm","market_type":"perpetual_futures","symbol":"ETHUSDT","event_time_ms":1783517066164,"received_time_ms":1783517066212,"trace_id":"90399b92-f534-4fd7-9934-ee65b8831836","trade_id":8429826634,"price":"1736.21","quantity":"0.001","trade_time_ms":1783517066164,"is_buyer_maker":false,"aggressor_side":"buy","raw":{"e":"trade","E":1783517066164,"T":1783517066164,"s":"ETHUSDT","t":8429826634,"p":"1736.21","q":"0.001","X":"MARKET","m":false,"st":1}}
{"schema_version":"1.3.0","event_id":"5e2963e0-73af-4999-a71a-d9f704df2e83","event_type":"raw.trade","source":"binance_market_data_recorder","venue":"binance_usdm","market_type":"perpetual_futures","symbol":"ETHUSDT","event_time_ms":1783517066164,"received_time_ms":1783517066212,"trace_id":"0e34f089-052f-4599-85db-de111b6e35d9","trade_id":8429826635,"price":"1736.21","quantity":"0.001","trade_time_ms":1783517066164,"is_buyer_maker":false,"aggressor_side":"buy","raw":{"e":"trade","E":1783517066164,"T":1783517066164,"s":"ETHUSDT","t":8429826635,"p":"1736.21","q":"0.001","X":"MARKET","m":false,"st":1}}
{"schema_version":"1.3.0","event_id":"0979b1a1-dccd-40d3-ae95-164a425ca619","event_type":"raw.trade","source":"binance_market_data_recorder","venue":"binance_usdm","market_type":"perpetual_futures","symbol":"ETHUSDT","event_time_ms":1783517066164,"received_time_ms":1783517066213,"trace_id":"446f8408-7896-481b-8e37-3f4a61cc70c6","trade_id":8429826636,"price":"1736.21","quantity":"0.001","trade_time_ms":1783517066164,"is_buyer_maker":false,"aggressor_side":"buy","raw":{"e":"trade","E":1783517066164,"T":1783517066164,"s":"ETHUSDT","t":8429826636,"p":"1736.21","q":"0.001","X":"MARKET","m":false,"st":1}}
{"schema_version":"1.3.0","event_id":"7922f4ad-6a57-4ae4-93d7-a5c10cf58117","event_type":"raw.trade","source":"binance_market_data_recorder","venue":"binance_usdm","market_type":"perpetual_futures","symbol":"ETHUSDT","event_time_ms":1783517066164,"received_time_ms":1783517066214,"trace_id":"19b92338-5d28-4863-a212-e5fc831dfbbc","trade_id":8429826637,"price":"1736.21","quantity":"0.001","trade_time_ms":1783517066164,"is_buyer_maker":false,"aggressor_side":"buy","raw":{"e":"trade","E":1783517066164,"T":1783517066164,"s":"ETHUSDT","t":8429826637,"p":"1736.21","q":"0.001","X":"MARKET","m":false,"st":1}}
{"schema_version":"1.3.0","event_id":"1c8bee25-2688-452b-ac8c-ca40bf0e04a2","event_type":"raw.trade","source":"binance_market_data_recorder","venue":"binance_usdm","market_type":"perpetual_futures","symbol":"ETHUSDT","event_time_ms":1783517066167,"received_time_ms":1783517066254,"trace_id":"c61287a1-afcf-4aae-8e0e-5f928fc78e35","trade_id":8429826638,"price":"1736.22","quantity":"0.012","trade_time_ms":1783517066167,"is_buyer_maker":false,"aggressor_side":"buy","raw":{"e":"trade","E":1783517066167,"T":1783517066167,"s":"ETHUSDT","t":8429826638,"p":"1736.22","q":"0.012","X":"MARKET","m":false,"st":1}}
{"schema_version":"1.3.0","event_id":"733bbf49-a17d-4080-b106-8938f3c03841","event_type":"raw.trade","source":"binance_market_data_recorder","venue":"binance_usdm","market_type":"perpetual_futures","symbol":"ETHUSDT","event_time_ms":1783517066167,"received_time_ms":1783517066256,"trace_id":"832a80ae-6d4e-4bf3-bc1a-a724e60f1dc0","trade_id":8429826639,"price":"1736.22","quantity":"0.012","trade_time_ms":1783517066167,"is_buyer_maker":false,"aggressor_side":"buy","raw":{"e":"trade","E":1783517066167,"T":1783517066167,"s":"ETHUSDT","t":8429826639,"p":"1736.22","q":"0.012","X":"MARKET","m":false,"st":1}}
{"schema_version":"1.3.0","event_id":"930282d1-85c7-4a27-93ba-0dec918c9300","event_type":"raw.trade","source":"binance_market_data_recorder","venue":"binance_usdm","market_type":"perpetual_futures","symbol":"ETHUSDT","event_time_ms":1783517066167,"received_time_ms":1783517066257,"trace_id":"eedbeec2-3b22-452f-a149-08d60045ceb8","trade_id":8429826640,"price":"1736.22","quantity":"0.001","trade_time_ms":1783517066167,"is_buyer_maker":false,"aggressor_side":"buy","raw":{"e":"trade","E":1783517066167,"T":1783517066167,"s":"ETHUSDT","t":8429826640,"p":"1736.22","q":"0.001","X":"MARKET","m":false,"st":1}}
{"schema_version":"1.3.0","event_id":"d8b21a3c-8d2a-4693-8913-89e762b623fa","event_type":"raw.trade","source":"binance_market_data_recorder","venue":"binance_usdm","market_type":"perpetual_futures","symbol":"ETHUSDT","event_time_ms":1783517066167,"received_time_ms":1783517066258,"trace_id":"30f313bb-4daa-48d6-a38b-24b57ced8270","trade_id":8429826641,"price":"1736.22","quantity":"20.421","trade_time_ms":1783517066167,"is_buyer_maker":false,"aggressor_side":"buy","raw":{"e":"trade","E":1783517066167,"T":1783517066167,"s":"ETHUSDT","t":8429826641,"p":"1736.22","q":"20.421","X":"MARKET","m":false,"st":1}}
{"schema_version":"1.3.0","event_id":"64a5063d-c85a-481b-91d8-f95298cff126","event_type":"raw.trade","source":"binance_market_data_recorder","venue":"binance_usdm","market_type":"perpetual_futures","symbol":"ETHUSDT","event_time_ms":1783517066167,"received_time_ms":1783517066259,"trace_id":"8b5c738c-3fda-477a-9e10-bc2f94c8addf","trade_id":8429826642,"price":"1736.22","quantity":"0.164","trade_time_ms":1783517066167,"is_buyer_maker":false,"aggressor_side":"buy","raw":{"e":"trade","E":1783517066167,"T":1783517066167,"s":"ETHUSDT","t":8429826642,"p":"1736.22","q":"0.164","X":"MARKET","m":false,"st":1}}
{"schema_version":"1.3.0","event_id":"9641aed5-1a54-4f8c-a9b2-7fd5a8ef9ec8","event_type":"raw.trade","source":"binance_market_data_recorder","venue":"binance_usdm","market_type":"perpetual_futures","symbol":"ETHUSDT","event_time_ms":1783517066169,"received_time_ms":1783517066355,"trace_id":"c9092084-d35d-4240-a6f6-e8b6713376fd","trade_id":8429826643,"price":"1736.23","quantity":"0.014","trade_time_ms":1783517066169,"is_buyer_maker":false,"aggressor_side":"buy","raw":{"e":"trade","E":1783517066169,"T":1783517066169,"s":"ETHUSDT","t":8429826643,"p":"1736.23","q":"0.014","X":"MARKET","m":false,"st":1}}
{"schema_version":"1.3.0","event_id":"7d0a51a5-6567-4df8-b4ed-17029d4122f9","event_type":"raw.trade","source":"binance_market_data_recorder","venue":"binance_usdm","market_type":"perpetual_futures","symbol":"ETHUSDT","event_time_ms":1783517066169,"received_time_ms":1783517066355,"trace_id":"bc580cb7-7d98-4a6b-b4ac-a864eb7b775a","trade_id":8429826644,"price":"1736.24","quantity":"0.012","trade_time_ms":1783517066169,"is_buyer_maker":false,"aggressor_side":"buy","raw":{"e":"trade","E":1783517066169,"T":1783517066169,"s":"ETHUSDT","t":8429826644,"p":"1736.24","q":"0.012","X":"MARKET","m":false,"st":1}}
{"schema_version":"1.3.0","event_id":"dba715f8-8921-4b5d-945f-8d879e340a58","event_type":"raw.trade","source":"binance_market_data_recorder","venue":"binance_usdm","market_type":"perpetual_futures","symbol":"ETHUSDT","event_time_ms":1783517066169,"received_time_ms":1783517066356,"trace_id":"8f065fed-54bc-4efb-9daf-544591ae9c78","trade_id":8429826645,"price":"1736.24","quantity":"0.012","trade_time_ms":1783517066169,"is_buyer_maker":false,"aggressor_side":"buy","raw":{"e":"trade","E":1783517066169,"T":1783517066169,"s":"ETHUSDT","t":8429826645,"p":"1736.24","q":"0.012","X":"MARKET","m":false,"st":1}}
{"schema_version":"1.3.0","event_id":"5dfe3382-f4ce-4dff-9de5-98769ebca2df","event_type":"raw.trade","source":"binance_market_data_recorder","venue":"binance_usdm","market_type":"perpetual_futures","symbol":"ETHUSDT","event_time_ms":1783517066169,"received_time_ms":1783517066356,"trace_id":"bb5ff388-a593-4426-9e19-2d55d215d787","trade_id":8429826646,"price":"1736.24","quantity":"0.012","trade_time_ms":1783517066169,"is_buyer_maker":false,"aggressor_side":"buy","raw":{"e":"trade","E":1783517066169,"T":1783517066169,"s":"ETHUSDT","t":8429826646,"p":"1736.24","q":"0.012","X":"MARKET","m":false,"st":1}}
{"schema_version":"1.3.0","event_id":"5cbaff0e-b125-46d5-88ae-3ae8d31f6dca","event_type":"raw.trade","source":"binance_market_data_recorder","venue":"binance_usdm","market_type":"perpetual_futures","symbol":"ETHUSDT","event_time_ms":1783517066169,"received_time_ms":1783517066357,"trace_id":"a8c406ab-cb9e-4907-9bd4-e07d8e37e9e3","trade_id":8429826647,"price":"1736.24","quantity":"0.001","trade_time_ms":1783517066169,"is_buyer_maker":false,"aggressor_side":"buy","raw":{"e":"trade","E":1783517066169,"T":1783517066169,"s":"ETHUSDT","t":8429826647,"p":"1736.24","q":"0.001","X":"MARKET","m":false,"st":1}}
{"schema_version":"1.3.0","event_id":"5e0e2b85-db1f-44da-9e08-e07f41c8d57d","event_type":"raw.trade","source":"binance_market_data_recorder","venue":"binance_usdm","market_type":"perpetual_futures","symbol":"ETHUSDT","event_time_ms":1783517066169,"received_time_ms":1783517066357,"trace_id":"2d2bce09-94d3-4594-b4f4-a62a64f993a6","trade_id":8429826648,"price":"1736.25","quantity":"0.014","trade_time_ms":1783517066169,"is_buyer_maker":false,"aggressor_side":"buy","raw":{"e":"trade","E":1783517066169,"T":1783517066169,"s":"ETHUSDT","t":8429826648,"p":"1736.25","q":"0.014","X":"MARKET","m":false,"st":1}}
{"schema_version":"1.3.0","event_id":"8722b395-2f1c-4c80-8460-34ebada63ce2","event_type":"raw.trade","source":"binance_market_data_recorder","venue":"binance_usdm","market_type":"perpetual_futures","symbol":"ETHUSDT","event_time_ms":1783517066169,"received_time_ms":1783517066357,"trace_id":"863e6d8e-04fe-49f6-8809-ee0cf3335a33","trade_id":8429826649,"price":"1736.25","quantity":"0.013","trade_time_ms":1783517066169,"is_buyer_maker":false,"aggressor_side":"buy","raw":{"e":"trade","E":1783517066169,"T":1783517066169,"s":"ETHUSDT","t":8429826649,"p":"1736.25","q":"0.013","X":"MARKET","m":false,"st":1}}
{"schema_version":"1.3.0","event_id":"48b1304a-7f18-4907-819a-e8dd950fbea6","event_type":"raw.trade","source":"binance_market_data_recorder","venue":"binance_usdm","market_type":"perpetual_futures","symbol":"ETHUSDT","event_time_ms":1783517066169,"received_time_ms":1783517066358,"trace_id":"b071c7d6-9787-4ace-96c5-e769d9481bd6","trade_id":8429826650,"price":"1736.25","quantity":"0.013","trade_time_ms":1783517066169,"is_buyer_maker":false,"aggressor_side":"buy","raw":{"e":"trade","E":1783517066169,"T":1783517066169,"s":"ETHUSDT","t":8429826650,"p":"1736.25","q":"0.013","X":"MARKET","m":false,"st":1}}
{"schema_version":"1.3.0","event_id":"8983a5da-2dcc-41c4-b3d8-b43ee114f4d4","event_type":"raw.trade","source":"binance_market_data_recorder","venue":"binance_usdm","market_type":"perpetual_futures","symbol":"ETHUSDT","event_time_ms":1783517066169,"received_time_ms":1783517066358,"trace_id":"da442abb-1837-43e3-bcb8-8ce059bdce33","trade_id":8429826651,"price":"1736.25","quantity":"0.012","trade_time_ms":1783517066169,"is_buyer_maker":false,"aggressor_side":"buy","raw":{"e":"trade","E":1783517066169,"T":1783517066169,"s":"ETHUSDT","t":8429826651,"p":"1736.25","q":"0.012","X":"MARKET","m":false,"st":1}}
{"schema_version":"1.3.0","event_id":"2efd1a55-5020-4be4-be26-77d5feca15d6","event_type":"raw.trade","source":"binance_market_data_recorder","venue":"binance_usdm","market_type":"perpetual_futures","symbol":"ETHUSDT","event_time_ms":1783517066169,"received_time_ms":1783517066358,"trace_id":"02c91eb5-4cc3-4d3c-8edb-9ed33850728b","trade_id":8429826652,"price":"1736.25","quantity":"0.068","trade_time_ms":1783517066169,"is_buyer_maker":false,"aggressor_side":"buy","raw":{"e":"trade","E":1783517066169,"T":1783517066169,"s":"ETHUSDT","t":8429826652,"p":"1736.25","q":"0.068","X":"MARKET","m":false,"st":1}}
{"schema_version":"1.3.0","event_id":"60b836de-a590-4743-b27e-da8cfc24f34d","event_type":"raw.trade","source":"binance_market_data_recorder","venue":"binance_usdm","market_type":"perpetual_futures","symbol":"ETHUSDT","event_time_ms":1783517066169,"received_time_ms":1783517066359,"trace_id":"d9fc3a5f-0b99-48c2-b2bb-5a419cfcd7e7","trade_id":8429826653,"price":"1736.26","quantity":"0.012","trade_time_ms":1783517066169,"is_buyer_maker":false,"aggressor_side":"buy","raw":{"e":"trade","E":1783517066169,"T":1783517066169,"s":"ETHUSDT","t":8429826653,"p":"1736.26","q":"0.012","X":"MARKET","m":false,"st":1}}
{"schema_version":"1.3.0","event_id":"ff66e16f-727c-4c59-8c7b-057c065bf7a4","event_type":"raw.trade","source":"binance_market_data_recorder","venue":"binance_usdm","market_type":"perpetual_futures","symbol":"ETHUSDT","event_time_ms":1783517066169,"received_time_ms":1783517066359,"trace_id":"be589000-b1d9-4ff2-9b46-c0920aaa4af6","trade_id":8429826654,"price":"1736.27","quantity":"0.012","trade_time_ms":1783517066169,"is_buyer_maker":false,"aggressor_side":"buy","raw":{"e":"trade","E":1783517066169,"T":1783517066169,"s":"ETHUSDT","t":8429826654,"p":"1736.27","q":"0.012","X":"MARKET","m":false,"st":1}}
{"schema_version":"1.3.0","event_id":"0805818f-a707-4c90-be94-82bbeeec1531","event_type":"raw.trade","source":"binance_market_data_recorder","venue":"binance_usdm","market_type":"perpetual_futures","symbol":"ETHUSDT","event_time_ms":1783517066169,"received_time_ms":1783517066360,"trace_id":"cf4baf29-52f6-4bcb-87d0-0c665390ecbb","trade_id":8429826655,"price":"1736.27","quantity":"0.022","trade_time_ms":1783517066169,"is_buyer_maker":false,"aggressor_side":"buy","raw":{"e":"trade","E":1783517066169,"T":1783517066169,"s":"ETHUSDT","t":8429826655,"p":"1736.27","q":"0.022","X":"MARKET","m":false,"st":1}}
{"schema_version":"1.3.0","event_id":"b858b03c-615a-4c0f-8328-ac886598d135","event_type":"raw.trade","source":"binance_market_data_recorder","venue":"binance_usdm","market_type":"perpetual_futures","symbol":"ETHUSDT","event_time_ms":1783517066169,"received_time_ms":1783517066360,"trace_id":"935c1783-b900-44eb-9973-ef010dac637d","trade_id":8429826656,"price":"1736.27","quantity":"0.013","trade_time_ms":1783517066169,"is_buyer_maker":false,"aggressor_side":"buy","raw":{"e":"trade","E":1783517066169,"T":1783517066169,"s":"ETHUSDT","t":8429826656,"p":"1736.27","q":"0.013","X":"MARKET","m":false,"st":1}}
{"schema_version":"1.3.0","event_id":"bd540f7e-ee7d-494d-a4cb-6d6a7187f7a5","event_type":"raw.trade","source":"binance_market_data_recorder","venue":"binance_usdm","market_type":"perpetual_futures","symbol":"BTCUSDT","event_time_ms":1783517066174,"received_time_ms":1783517066424,"trace_id":"164b7f4c-9d28-4ea9-8b71-f1efb7912cc6","trade_id":7881418008,"price":"61852.30","quantity":"0.006","trade_time_ms":1783517066174,"is_buyer_maker":false,"aggressor_side":"buy","raw":{"e":"trade","E":1783517066174,"T":1783517066174,"s":"BTCUSDT","t":7881418008,"p":"61852.30","q":"0.006","X":"MARKET","m":false,"st":1}}
{"schema_version":"1.3.0","event_id":"85ed4e9e-92a0-4e52-85bc-b24a79a23ec8","event_type":"raw.trade","source":"binance_market_data_recorder","venue":"binance_usdm","market_type":"perpetual_futures","symbol":"BTCUSDT","event_time_ms":1783517066174,"received_time_ms":1783517066424,"trace_id":"1d18c352-849b-404b-813e-28989c705eb2","trade_id":7881418009,"price":"61852.30","quantity":"0.002","trade_time_ms":1783517066174,"is_buyer_maker":false,"aggressor_side":"buy","raw":{"e":"trade","E":1783517066174,"T":1783517066174,"s":"BTCUSDT","t":7881418009,"p":"61852.30","q":"0.002","X":"MARKET","m":false,"st":1}}
{"schema_version":"1.3.0","event_id":"1d5c2d6d-6650-4746-bf8a-9930a7cf6ea1","event_type":"raw.trade","source":"binance_market_data_recorder","venue":"binance_usdm","market_type":"perpetual_futures","symbol":"BTCUSDT","event_time_ms":1783517066174,"received_time_ms":1783517066426,"trace_id":"99b67496-bce0-4e90-b03d-27f9a546d180","trade_id":7881418010,"price":"61852.30","quantity":"0.024","trade_time_ms":1783517066174,"is_buyer_maker":false,"aggressor_side":"buy","raw":{"e":"trade","E":1783517066174,"T":1783517066174,"s":"BTCUSDT","t":7881418010,"p":"61852.30","q":"0.024","X":"MARKET","m":false,"st":1}}
{"schema_version":"1.3.0","event_id":"c5299844-fa8d-4bdd-83ab-55cfa45477fd","event_type":"raw.trade","source":"binance_market_data_recorder","venue":"binance_usdm","market_type":"perpetual_futures","symbol":"BTCUSDT","event_time_ms":1783517066174,"received_time_ms":1783517066426,"trace_id":"0dae5d46-7ec5-44ab-b576-f8b7abe84e93","trade_id":7881418011,"price":"61852.30","quantity":"0.003","trade_time_ms":1783517066174,"is_buyer_maker":false,"aggressor_side":"buy","raw":{"e":"trade","E":1783517066174,"T":1783517066174,"s":"BTCUSDT","t":7881418011,"p":"61852.30","q":"0.003","X":"MARKET","m":false,"st":1}}
{"schema_version":"1.3.0","event_id":"ca9a9e24-ad7f-4678-9b49-2be963fa5d67","event_type":"raw.trade","source":"binance_market_data_recorder","venue":"binance_usdm","market_type":"perpetual_futures","symbol":"BTCUSDT","event_time_ms":1783517066174,"received_time_ms":1783517066426,"trace_id":"5ba22759-d0da-4eeb-8d66-c56fb34ee014","trade_id":7881418012,"price":"61852.30","quantity":"0.001","trade_time_ms":1783517066174,"is_buyer_maker":false,"aggressor_side":"buy","raw":{"e":"trade","E":1783517066174,"T":1783517066174,"s":"BTCUSDT","t":7881418012,"p":"61852.30","q":"0.001","X":"MARKET","m":false,"st":1}}
{"schema_version":"1.3.0","event_id":"fca830c4-04f6-489c-9140-8507868cf94e","event_type":"raw.trade","source":"binance_market_data_recorder","venue":"binance_usdm","market_type":"perpetual_futures","symbol":"BTCUSDT","event_time_ms":1783517066174,"received_time_ms":1783517066427,"trace_id":"c90396e2-c323-43f6-b64f-e5fd559fe22d","trade_id":7881418013,"price":"61852.30","quantity":"0.044","trade_time_ms":1783517066174,"is_buyer_maker":false,"aggressor_side":"buy","raw":{"e":"trade","E":1783517066174,"T":1783517066174,"s":"BTCUSDT","t":7881418013,"p":"61852.30","q":"0.044","X":"MARKET","m":false,"st":1}}
{"schema_version":"1.3.0","event_id":"edd52fe3-2479-4eaf-91b0-7a991204e1f4","event_type":"raw.trade","source":"binance_market_data_recorder","venue":"binance_usdm","market_type":"perpetual_futures","symbol":"BTCUSDT","event_time_ms":1783517066174,"received_time_ms":1783517066427,"trace_id":"0dfebef8-1fdf-45bc-a36e-3369141e007a","trade_id":7881418014,"price":"61852.30","quantity":"0.153","trade_time_ms":1783517066174,"is_buyer_maker":false,"aggressor_side":"buy","raw":{"e":"trade","E":1783517066174,"T":1783517066174,"s":"BTCUSDT","t":7881418014,"p":"61852.30","q":"0.153","X":"MARKET","m":false,"st":1}}
{"schema_version":"1.3.0","event_id":"1e5b6374-7d5e-407e-ade6-0e8e9c4810bc","event_type":"raw.trade","source":"binance_market_data_recorder","venue":"binance_usdm","market_type":"perpetual_futures","symbol":"BTCUSDT","event_time_ms":1783517066174,"received_time_ms":1783517066429,"trace_id":"f859f7de-75e9-4c86-93ca-a76a86f7ce0d","trade_id":7881418015,"price":"61852.30","quantity":"0.001","trade_time_ms":1783517066174,"is_buyer_maker":false,"aggressor_side":"buy","raw":{"e":"trade","E":1783517066174,"T":1783517066174,"s":"BTCUSDT","t":7881418015,"p":"61852.30","q":"0.001","X":"MARKET","m":false,"st":1}}
{"schema_version":"1.3.0","event_id":"84df87c5-4ecb-4e8f-ba6d-bf823db1f0cb","event_type":"raw.trade","source":"binance_market_data_recorder","venue":"binance_usdm","market_type":"perpetual_futures","symbol":"BTCUSDT","event_time_ms":1783517066174,"received_time_ms":1783517066429,"trace_id":"364157a8-38da-4e0f-b3e3-7e5946d8300d","trade_id":7881418016,"price":"61852.30","quantity":"0.001","trade_time_ms":1783517066174,"is_buyer_maker":false,"aggressor_side":"buy","raw":{"e":"trade","E":1783517066174,"T":1783517066174,"s":"BTCUSDT","t":7881418016,"p":"61852.30","q":"0.001","X":"MARKET","m":false,"st":1}}
{"schema_version":"1.3.0","event_id":"d51e4e44-6178-4326-b7e2-78882cc3bbbd","event_type":"raw.trade","source":"binance_market_data_recorder","venue":"binance_usdm","market_type":"perpetual_futures","symbol":"BTCUSDT","event_time_ms":1783517066174,"received_time_ms":1783517066430,"trace_id":"cf26b4eb-cbd5-4e48-85de-e93da031db26","trade_id":7881418017,"price":"61852.40","quantity":"0.001","trade_time_ms":1783517066174,"is_buyer_maker":false,"aggressor_side":"buy","raw":{"e":"trade","E":1783517066174,"T":1783517066174,"s":"BTCUSDT","t":7881418017,"p":"61852.40","q":"0.001","X":"MARKET","m":false,"st":1}}
{"schema_version":"1.3.0","event_id":"84f840b4-d653-4d4e-bb2a-9377ec305ce8","event_type":"raw.trade","source":"binance_market_data_recorder","venue":"binance_usdm","market_type":"perpetual_futures","symbol":"BTCUSDT","event_time_ms":1783517066174,"received_time_ms":1783517066430,"trace_id":"37b618ec-c571-4993-beac-5cc0a6ab17ee","trade_id":7881418018,"price":"61852.40","quantity":"0.001","trade_time_ms":1783517066174,"is_buyer_maker":false,"aggressor_side":"buy","raw":{"e":"trade","E":1783517066174,"T":1783517066174,"s":"BTCUSDT","t":7881418018,"p":"61852.40","q":"0.001","X":"MARKET","m":false,"st":1}}
{"schema_version":"1.3.0","event_id":"4fe52152-e8b9-4179-ac2c-8d6dec9ca55e","event_type":"raw.trade","source":"binance_market_data_recorder","venue":"binance_usdm","market_type":"perpetual_futures","symbol":"BTCUSDT","event_time_ms":1783517066174,"received_time_ms":1783517066431,"trace_id":"eedad65b-02aa-447c-8f10-4257e7e87a53","trade_id":7881418019,"price":"61852.50","quantity":"0.001","trade_time_ms":1783517066174,"is_buyer_maker":false,"aggressor_side":"buy","raw":{"e":"trade","E":1783517066174,"T":1783517066174,"s":"BTCUSDT","t":7881418019,"p":"61852.50","q":"0.001","X":"MARKET","m":false,"st":1}}
{"schema_version":"1.3.0","event_id":"5f5a87f1-906d-4852-b114-c4a5e6f24c64","event_type":"raw.trade","source":"binance_market_data_recorder","venue":"binance_usdm","market_type":"perpetual_futures","symbol":"BTCUSDT","event_time_ms":1783517066174,"received_time_ms":1783517066431,"trace_id":"0d4e7ce5-ab07-44ab-aa5e-85d7948b17af","trade_id":7881418020,"price":"61852.70","quantity":"0.001","trade_time_ms":1783517066174,"is_buyer_maker":false,"aggressor_side":"buy","raw":{"e":"trade","E":1783517066174,"T":1783517066174,"s":"BTCUSDT","t":7881418020,"p":"61852.70","q":"0.001","X":"MARKET","m":false,"st":1}}
{"schema_version":"1.3.0","event_id":"8469bffc-e226-4b68-ac0c-d45ea37f7e81","event_type":"raw.trade","source":"binance_market_data_recorder","venue":"binance_usdm","market_type":"perpetual_futures","symbol":"BTCUSDT","event_time_ms":1783517066174,"received_time_ms":1783517066431,"trace_id":"bdc29d72-77c0-4e57-9b18-c79483dd9391","trade_id":7881418021,"price":"61852.70","quantity":"0.001","trade_time_ms":1783517066174,"is_buyer_maker":false,"aggressor_side":"buy","raw":{"e":"trade","E":1783517066174,"T":1783517066174,"s":"BTCUSDT","t":7881418021,"p":"61852.70","q":"0.001","X":"MARKET","m":false,"st":1}}
{"schema_version":"1.3.0","event_id":"dbdba3b6-8e29-4695-83f8-bcf099f0918a","event_type":"raw.trade","source":"binance_market_data_recorder","venue":"binance_usdm","market_type":"perpetual_futures","symbol":"BTCUSDT","event_time_ms":1783517066174,"received_time_ms":1783517066432,"trace_id":"fadd63cc-fb2e-43c7-a608-98c8eb0ed463","trade_id":7881418022,"price":"61852.70","quantity":"0.001","trade_time_ms":1783517066174,"is_buyer_maker":false,"aggressor_side":"buy","raw":{"e":"trade","E":1783517066174,"T":1783517066174,"s":"BTCUSDT","t":7881418022,"p":"61852.70","q":"0.001","X":"MARKET","m":false,"st":1}}
{"schema_version":"1.3.0","event_id":"b549c71c-c7b5-4544-8bfa-f03fe62606da","event_type":"raw.trade","source":"binance_market_data_recorder","venue":"binance_usdm","market_type":"perpetual_futures","symbol":"BTCUSDT","event_time_ms":1783517066174,"received_time_ms":1783517066433,"trace_id":"3e81ea1d-1eab-417f-8a25-9bc2394f4795","trade_id":7881418023,"price":"61852.70","quantity":"0.001","trade_time_ms":1783517066174,"is_buyer_maker":false,"aggressor_side":"buy","raw":{"e":"trade","E":1783517066174,"T":1783517066174,"s":"BTCUSDT","t":7881418023,"p":"61852.70","q":"0.001","X":"MARKET","m":false,"st":1}}
{"schema_version":"1.3.0","event_id":"53f00f10-ad54-4ea6-a019-5678419d5554","event_type":"raw.trade","source":"binance_market_data_recorder","venue":"binance_usdm","market_type":"perpetual_futures","symbol":"BTCUSDT","event_time_ms":1783517066174,"received_time_ms":1783517066433,"trace_id":"df8b0176-c04c-4102-b3f6-768708137a12","trade_id":7881418024,"price":"61852.70","quantity":"0.002","trade_time_ms":1783517066174,"is_buyer_maker":false,"aggressor_side":"buy","raw":{"e":"trade","E":1783517066174,"T":1783517066174,"s":"BTCUSDT","t":7881418024,"p":"61852.70","q":"0.002","X":"MARKET","m":false,"st":1}}
{"schema_version":"1.3.0","event_id":"1edb3e11-1dd4-43bb-94a0-ac7e85e82140","event_type":"raw.trade","source":"binance_market_data_recorder","venue":"binance_usdm","market_type":"perpetual_futures","symbol":"BTCUSDT","event_time_ms":1783517066174,"received_time_ms":1783517066434,"trace_id":"8320b578-46ac-4d36-b45b-8a91accfaee4","trade_id":7881418025,"price":"61852.80","quantity":"0.001","trade_time_ms":1783517066174,"is_buyer_maker":false,"aggressor_side":"buy","raw":{"e":"trade","E":1783517066174,"T":1783517066174,"s":"BTCUSDT","t":7881418025,"p":"61852.80","q":"0.001","X":"MARKET","m":false,"st":1}}
{"schema_version":"1.3.0","event_id":"06410b5b-4f48-4805-a929-dc23a52593d7","event_type":"raw.trade","source":"binance_market_data_recorder","venue":"binance_usdm","market_type":"perpetual_futures","symbol":"BTCUSDT","event_time_ms":1783517066174,"received_time_ms":1783517066434,"trace_id":"347a2c55-66b1-46a7-8d84-d3209986c736","trade_id":7881418026,"price":"61852.80","quantity":"0.001","trade_time_ms":1783517066174,"is_buyer_maker":false,"aggressor_side":"buy","raw":{"e":"trade","E":1783517066174,"T":1783517066174,"s":"BTCUSDT","t":7881418026,"p":"61852.80","q":"0.001","X":"MARKET","m":false,"st":1}}
{"schema_version":"1.3.0","event_id":"5dfa0aad-b67e-44de-bbff-274c77048526","event_type":"raw.trade","source":"binance_market_data_recorder","venue":"binance_usdm","market_type":"perpetual_futures","symbol":"BTCUSDT","event_time_ms":1783517066175,"received_time_ms":1783517066435,"trace_id":"bd623864-e5ae-486c-9a4c-5d38668d61f3","trade_id":7881418027,"price":"61853.00","quantity":"0.004","trade_time_ms":1783517066174,"is_buyer_maker":false,"aggressor_side":"buy","raw":{"e":"trade","E":1783517066175,"T":1783517066174,"s":"BTCUSDT","t":7881418027,"p":"61853.00","q":"0.004","X":"MARKET","m":false,"st":1}}
{"schema_version":"1.3.0","event_id":"d7342f45-4774-4655-9814-be7de947d8b2","event_type":"raw.trade","source":"binance_market_data_recorder","venue":"binance_usdm","market_type":"perpetual_futures","symbol":"BTCUSDT","event_time_ms":1783517066175,"received_time_ms":1783517066435,"trace_id":"6c8f623f-b3bd-40c8-b0ea-d1604e675359","trade_id":7881418028,"price":"61853.00","quantity":"0.004","trade_time_ms":1783517066174,"is_buyer_maker":false,"aggressor_side":"buy","raw":{"e":"trade","E":1783517066175,"T":1783517066174,"s":"BTCUSDT","t":7881418028,"p":"61853.00","q":"0.004","X":"MARKET","m":false,"st":1}}
{"schema_version":"1.3.0","event_id":"3e9270db-600c-41c7-af52-0e0855aaf1f9","event_type":"raw.trade","source":"binance_market_data_recorder","venue":"binance_usdm","market_type":"perpetual_futures","symbol":"BTCUSDT","event_time_ms":1783517066175,"received_time_ms":1783517066438,"trace_id":"871d9804-26e9-4ed4-a7b4-adcda81c2143","trade_id":7881418029,"price":"61853.00","quantity":"0.004","trade_time_ms":1783517066174,"is_buyer_maker":false,"aggressor_side":"buy","raw":{"e":"trade","E":1783517066175,"T":1783517066174,"s":"BTCUSDT","t":7881418029,"p":"61853.00","q":"0.004","X":"MARKET","m":false,"st":1}}
{"schema_version":"1.3.0","event_id":"a3e302ca-6e36-4498-ba33-3591dcaa8a17","event_type":"raw.trade","source":"binance_market_data_recorder","venue":"binance_usdm","market_type":"perpetual_futures","symbol":"BTCUSDT","event_time_ms":1783517066175,"received_time_ms":1783517066438,"trace_id":"ac7a5d71-b543-4b49-b51d-9d65e0a3be1e","trade_id":7881418030,"price":"61853.00","quantity":"0.004","trade_time_ms":1783517066174,"is_buyer_maker":false,"aggressor_side":"buy","raw":{"e":"trade","E":1783517066175,"T":1783517066174,"s":"BTCUSDT","t":7881418030,"p":"61853.00","q":"0.004","X":"MARKET","m":false,"st":1}}
{"schema_version":"1.3.0","event_id":"a1dfbc21-c895-4e07-a275-7fb408519230","event_type":"raw.trade","source":"binance_market_data_recorder","venue":"binance_usdm","market_type":"perpetual_futures","symbol":"BTCUSDT","event_time_ms":1783517066175,"received_time_ms":1783517066439,"trace_id":"4ee9b67f-8aee-4fda-a6d7-40c9b0bc5911","trade_id":7881418031,"price":"61853.00","quantity":"0.004","trade_time_ms":1783517066174,"is_buyer_maker":false,"aggressor_side":"buy","raw":{"e":"trade","E":1783517066175,"T":1783517066174,"s":"BTCUSDT","t":7881418031,"p":"61853.00","q":"0.004","X":"MARKET","m":false,"st":1}}
{"schema_version":"1.3.0","event_id":"0899e9e1-c4f2-458b-bc4f-8edb646fcc59","event_type":"raw.trade","source":"binance_market_data_recorder","venue":"binance_usdm","market_type":"perpetual_futures","symbol":"BTCUSDT","event_time_ms":1783517066175,"received_time_ms":1783517066439,"trace_id":"0c32541c-eb81-4a61-910a-a55c3ea8d2fd","trade_id":7881418032,"price":"61853.00","quantity":"0.001","trade_time_ms":1783517066174,"is_buyer_maker":false,"aggressor_side":"buy","raw":{"e":"trade","E":1783517066175,"T":1783517066174,"s":"BTCUSDT","t":7881418032,"p":"61853.00","q":"0.001","X":"MARKET","m":false,"st":1}}
{"schema_version":"1.3.0","event_id":"216615d2-4e71-48a9-8471-3431bc0416a5","event_type":"raw.trade","source":"binance_market_data_recorder","venue":"binance_usdm","market_type":"perpetual_futures","symbol":"BTCUSDT","event_time_ms":1783517066175,"received_time_ms":1783517066439,"trace_id":"726579fb-db68-4860-b1e3-708a59dd9641","trade_id":7881418033,"price":"61853.00","quantity":"0.010","trade_time_ms":1783517066174,"is_buyer_maker":false,"aggressor_side":"buy","raw":{"e":"trade","E":1783517066175,"T":1783517066174,"s":"BTCUSDT","t":7881418033,"p":"61853.00","q":"0.010","X":"MARKET","m":false,"st":1}}
{"schema_version":"1.3.0","event_id":"df76b8f2-8fed-4c6e-9d63-4e756caac17b","event_type":"raw.trade","source":"binance_market_data_recorder","venue":"binance_usdm","market_type":"perpetual_futures","symbol":"BTCUSDT","event_time_ms":1783517066175,"received_time_ms":1783517066440,"trace_id":"084bc73f-a86b-48f5-9233-8482400ef711","trade_id":7881418034,"price":"61853.00","quantity":"0.014","trade_time_ms":1783517066174,"is_buyer_maker":false,"aggressor_side":"buy","raw":{"e":"trade","E":1783517066175,"T":1783517066174,"s":"BTCUSDT","t":7881418034,"p":"61853.00","q":"0.014","X":"MARKET","m":false,"st":1}}
{"schema_version":"1.3.0","event_id":"bf6faec3-3f23-4433-baaa-11abc8723e9b","event_type":"raw.trade","source":"binance_market_data_recorder","venue":"binance_usdm","market_type":"perpetual_futures","symbol":"BTCUSDT","event_time_ms":1783517066175,"received_time_ms":1783517066440,"trace_id":"0905c1be-2b64-4178-9004-2b878109e43b","trade_id":7881418035,"price":"61853.20","quantity":"0.001","trade_time_ms":1783517066174,"is_buyer_maker":false,"aggressor_side":"buy","raw":{"e":"trade","E":1783517066175,"T":1783517066174,"s":"BTCUSDT","t":7881418035,"p":"61853.20","q":"0.001","X":"MARKET","m":false,"st":1}}
{"schema_version":"1.3.0","event_id":"4cf3b25b-70fc-473d-9be8-a00db60ec526","event_type":"raw.trade","source":"binance_market_data_recorder","venue":"binance_usdm","market_type":"perpetual_futures","symbol":"BTCUSDT","event_time_ms":1783517066175,"received_time_ms":1783517066441,"trace_id":"b33216d7-591c-4ece-87df-474dd3a06449","trade_id":7881418036,"price":"61853.30","quantity":"0.002","trade_time_ms":1783517066174,"is_buyer_maker":false,"aggressor_side":"buy","raw":{"e":"trade","E":1783517066175,"T":1783517066174,"s":"BTCUSDT","t":7881418036,"p":"61853.30","q":"0.002","X":"MARKET","m":false,"st":1}}
{"schema_version":"1.3.0","event_id":"583de0fc-45bf-4cf0-83d4-29111c0e31b6","event_type":"raw.trade","source":"binance_market_data_recorder","venue":"binance_usdm","market_type":"perpetual_futures","symbol":"BTCUSDT","event_time_ms":1783517066175,"received_time_ms":1783517066442,"trace_id":"c7672d39-0a8a-4531-93d7-b9ff4788a8e2","trade_id":7881418037,"price":"61853.30","quantity":"0.002","trade_time_ms":1783517066174,"is_buyer_maker":false,"aggressor_side":"buy","raw":{"e":"trade","E":1783517066175,"T":1783517066174,"s":"BTCUSDT","t":7881418037,"p":"61853.30","q":"0.002","X":"MARKET","m":false,"st":1}}
{"schema_version":"1.3.0","event_id":"a2163965-d96c-47f5-a9d6-ed09d8601e00","event_type":"raw.trade","source":"binance_market_data_recorder","venue":"binance_usdm","market_type":"perpetual_futures","symbol":"BTCUSDT","event_time_ms":1783517066175,"received_time_ms":1783517066444,"trace_id":"d5f0f2bc-27fb-4b43-a87f-2a49e05d7ac7","trade_id":7881418038,"price":"61853.30","quantity":"0.002","trade_time_ms":1783517066174,"is_buyer_maker":false,"aggressor_side":"buy","raw":{"e":"trade","E":1783517066175,"T":1783517066174,"s":"BTCUSDT","t":7881418038,"p":"61853.30","q":"0.002","X":"MARKET","m":false,"st":1}}
{"schema_version":"1.3.0","event_id":"9a369d73-7ede-4a9f-a492-e0aecfd835b5","event_type":"raw.trade","source":"binance_market_data_recorder","venue":"binance_usdm","market_type":"perpetual_futures","symbol":"BTCUSDT","event_time_ms":1783517066175,"received_time_ms":1783517066444,"trace_id":"1b082811-e9a3-4063-bc2c-26ef5cfbead9","trade_id":7881418039,"price":"61853.30","quantity":"0.053","trade_time_ms":1783517066174,"is_buyer_maker":false,"aggressor_side":"buy","raw":{"e":"trade","E":1783517066175,"T":1783517066174,"s":"BTCUSDT","t":7881418039,"p":"61853.30","q":"0.053","X":"MARKET","m":false,"st":1}}
{"schema_version":"1.3.0","event_id":"24bef0ea-e009-4d3b-9740-bb3428567a56","event_type":"raw.trade","source":"binance_market_data_recorder","venue":"binance_usdm","market_type":"perpetual_futures","symbol":"BTCUSDT","event_time_ms":1783517066182,"received_time_ms":1783517066583,"trace_id":"3efd1ac7-66b1-4247-8f6f-57ebf9a433dc","trade_id":7881418040,"price":"61853.30","quantity":"0.001","trade_time_ms":1783517066181,"is_buyer_maker":false,"aggressor_side":"buy","raw":{"e":"trade","E":1783517066182,"T":1783517066181,"s":"BTCUSDT","t":7881418040,"p":"61853.30","q":"0.001","X":"MARKET","m":false,"st":1}}
{"schema_version":"1.3.0","event_id":"08a819cf-d168-4ec1-997e-03627e094fd5","event_type":"raw.trade","source":"binance_market_data_recorder","venue":"binance_usdm","market_type":"perpetual_futures","symbol":"BTCUSDT","event_time_ms":1783517066182,"received_time_ms":1783517066584,"trace_id":"d713a470-7700-4a2e-a55f-91d64f023943","trade_id":7881418041,"price":"61853.30","quantity":"0.001","trade_time_ms":1783517066181,"is_buyer_maker":false,"aggressor_side":"buy","raw":{"e":"trade","E":1783517066182,"T":1783517066181,"s":"BTCUSDT","t":7881418041,"p":"61853.30","q":"0.001","X":"MARKET","m":false,"st":1}}
{"schema_version":"1.3.0","event_id":"9bbff346-ff0e-4741-9303-4103cf2bce0e","event_type":"raw.trade","source":"binance_market_data_recorder","venue":"binance_usdm","market_type":"perpetual_futures","symbol":"BTCUSDT","event_time_ms":1783517066182,"received_time_ms":1783517066584,"trace_id":"434bfed4-a8a7-468e-9eca-f43319256540","trade_id":7881418042,"price":"61853.40","quantity":"0.001","trade_time_ms":1783517066181,"is_buyer_maker":false,"aggressor_side":"buy","raw":{"e":"trade","E":1783517066182,"T":1783517066181,"s":"BTCUSDT","t":7881418042,"p":"61853.40","q":"0.001","X":"MARKET","m":false,"st":1}}
{"schema_version":"1.3.0","event_id":"5cad3b46-9096-49b1-b0e4-5526c948042c","event_type":"raw.trade","source":"binance_market_data_recorder","venue":"binance_usdm","market_type":"perpetual_futures","symbol":"BTCUSDT","event_time_ms":1783517066182,"received_time_ms":1783517066585,"trace_id":"ebbaf517-d7e5-46c0-821e-91a4c3ecc1a9","trade_id":7881418043,"price":"61853.40","quantity":"0.001","trade_time_ms":1783517066181,"is_buyer_maker":false,"aggressor_side":"buy","raw":{"e":"trade","E":1783517066182,"T":1783517066181,"s":"BTCUSDT","t":7881418043,"p":"61853.40","q":"0.001","X":"MARKET","m":false,"st":1}}
{"schema_version":"1.3.0","event_id":"91f4eb79-a7da-4c79-9f6c-e9657398a3e9","event_type":"raw.trade","source":"binance_market_data_recorder","venue":"binance_usdm","market_type":"perpetual_futures","symbol":"BTCUSDT","event_time_ms":1783517066182,"received_time_ms":1783517066585,"trace_id":"95c572bf-528d-4463-a913-a8c8bc64a6ef","trade_id":7881418044,"price":"61853.70","quantity":"0.013","trade_time_ms":1783517066181,"is_buyer_maker":false,"aggressor_side":"buy","raw":{"e":"trade","E":1783517066182,"T":1783517066181,"s":"BTCUSDT","t":7881418044,"p":"61853.70","q":"0.013","X":"MARKET","m":false,"st":1}}
{"schema_version":"1.3.0","event_id":"1ebc8cc0-e44b-404d-9f2c-be36aafc5027","event_type":"raw.trade","source":"binance_market_data_recorder","venue":"binance_usdm","market_type":"perpetual_futures","symbol":"BTCUSDT","event_time_ms":1783517066182,"received_time_ms":1783517066585,"trace_id":"c3470071-e9e2-4262-9377-b3232b948640","trade_id":7881418045,"price":"61853.70","quantity":"0.004","trade_time_ms":1783517066181,"is_buyer_maker":false,"aggressor_side":"buy","raw":{"e":"trade","E":1783517066182,"T":1783517066181,"s":"BTCUSDT","t":7881418045,"p":"61853.70","q":"0.004","X":"MARKET","m":false,"st":1}}
