{"schema_version":"1.3.0","event_id":"bbd1e055-c77f-4a42-a055-67fbf5ef9d0f","event_type":"raw.depth_update","source":"binance_market_data_recorder","venue":"binance_usdm","market_type":"perpetual_futures","symbol":"BTCUSDT","event_time_ms":1783517066292,"received_time_ms":1783517066984,"trace_id":"d7da7eb6-0726-4f3c-8afd-5077be362e40","first_update_id":10999770489995,"final_update_id":10999770524747,"previous_final_update_id":10999770489945,"bids":[{"price":"11353.70","quantity":"0.288"},{"price":"11452.20","quantity":"2.416"},{"price":"11553.70","quantity":"0.153"},{"price":"11652.20","quantity":"0.493"},{"price":"49483.00","quantity":"0.000"},{"price":"55668.30","quantity":"0.002"},{"price":"58745.80","quantity":"0.031"},{"price":"59379.50","quantity":"0.004"},{"price":"60616.70","quantity":"0.011"},{"price":"60781.60","quantity":"0.822"},{"price":"60948.40","quantity":"3.580"},{"price":"61076.90","quantity":"3.774"},{"price":"61171.80","quantity":"1.227"},{"price":"61177.70","quantity":"0.001"},{"price":"61235.20","quantity":"0.025"},{"price":"61397.00","quantity":"0.052"},{"price":"61440.00","quantity":"0.140"},{"price":"61520.00","quantity":"2.919"},{"price":"61593.90","quantity":"0.276"},{"price":"61600.00","quantity":"56.797"},{"price":"61677.90","quantity":"0.005"},{"price":"61679.40","quantity":"0.588"},{"price":"61680.00","quantity":"0.711"},{"price":"61750.50","quantity":"0.047"},{"price":"61758.90","quantity":"0.019"},{"price":"61759.80","quantity":"0.000"},{"price":"61760.00","quantity":"0.920"},{"price":"61760.50","quantity":"0.009"},{"price":"61763.20","quantity":"0.019"},{"price":"61764.00","quantity":"1.363"},{"price":"61770.00","quantity":"1.664"},{"price":"61773.80","quantity":"0.033"},{"price":"61777.30","quantity":"0.000"},{"price":"61785.80","quantity":"0.000"},{"price":"61786.00","quantity":"0.212"},{"price":"61786.30","quantity":"0.002"},{"price":"61786.40","quantity":"2.413"},{"price":"61786.50","quantity":"0.022"},{"price":"61788.40","quantity":"34.215"},{"price":"61789.00","quantity":"6.412"},{"price":"61790.00","quantity":"0.203"},{"price":"61790.50","quantity":"1.114"},{"price":"61792.40","quantity":"0.162"},{"price":"61792.70","quantity":"0.070"},{"price":"61794.30","quantity":"0.028"},{"price":"61796.30","quantity":"0.001"},{"price":"61796.60","quantity":"0.801"},{"price":"61797.40","quantity":"0.163"},{"price":"61797.50","quantity":"0.003"},{"price":"61797.70","quantity":"0.843"},{"price":"61797.90","quantity":"1.431"},{"price":"61798.00","quantity":"0.015"},{"price":"61798.60","quantity":"0.026"},{"price":"61800.90","quantity":"0.025"},{"price":"61803.90","quantity":"0.198"},{"price":"61804.60","quantity":"0.049"},{"price":"61806.00","quantity":"0.043"},{"price":"61806.30","quantity":"0.021"},{"price":"61807.60","quantity":"1.444"},{"price":"61808.00","quantity":"0.056"},{"price":"61808.10","quantity":"0.000"},{"price":"61808.50","quantity":"0.000"},{"price":"61808.80","quantity":"0.351"},{"price":"61808.90","quantity":"0.111"},{"price":"61809.30","quantity":"0.182"},{"price":"61810.30","quantity":"1.007"},{"price":"61812.50","quantity":"0.933"},{"price":"61813.60","quantity":"0.103"},{"price":"61814.20","quantity":"0.296"},{"price":"61814.30","quantity":"0.232"},{"price":"61814.40","quantity":"0.110"},{"price":"61814.50","quantity":"0.007"},{"price":"61815.70","quantity":"0.002"},{"price":"61815.90","quantity":"0.002"},{"price":"61816.30","quantity":"0.390"},{"price":"61816.40","quantity":"0.868"},{"price":"61816.50","quantity":"0.081"},{"price":"61817.00","quantity":"0.018"},{"price":"61817.30","quantity":"1.771"},{"price":"61818.20","quantity":"0.000"},{"price":"61818.40","quantity":"0.004"},{"price":"61819.10","quantity":"0.120"},{"price":"61819.40","quantity":"0.100"},{"price":"61820.00","quantity":"50.542"},{"price":"61820.10","quantity":"10.663"},{"price":"61820.30","quantity":"0.556"},{"price":"61820.40","quantity":"1.415"},{"price":"61820.50","quantity":"0.309"},{"price":"61820.90","quantity":"1.779"},{"price":"61821.00","quantity":"0.737"},{"price":"61821.20","quantity":"0.065"},{"price":"61821.30","quantity":"0.096"},{"price":"61821.50","quantity":"0.324"},{"price":"61822.10","quantity":"0.001"},{"price":"61822.30","quantity":"0.002"},{"price":"61822.70","quantity":"0.016"},{"price":"61823.20","quantity":"0.355"},{"price":"61823.40","quantity":"0.002"},{"price":"61823.80","quantity":"0.017"},{"price":"61824.20","quantity":"0.002"},{"price":"61824.30","quantity":"0.092"},{"price":"61824.70","quantity":"0.001"},{"price":"61824.80","quantity":"0.009"},{"price":"61825.00","quantity":"3.092"},{"price":"61825.10","quantity":"0.255"},{"price":"61825.30","quantity":"0.017"},{"price":"61825.50","quantity":"0.008"},{"price":"61825.70","quantity":"0.004"},{"price":"61825.90","quantity":"1.319"},{"price":"61826.40","quantity":"0.881"},{"price":"61826.70","quantity":"0.011"},{"price":"61826.90","quantity":"0.003"},{"price":"61827.10","quantity":"0.006"},{"price":"61827.50","quantity":"2.686"},{"price":"61827.60","quantity":"0.002"},{"price":"61828.10","quantity":"0.081"},{"price":"61828.30","quantity":"0.001"},{"price":"61828.50","quantity":"0.016"},{"price":"61828.70","quantity":"0.129"},{"price":"61828.90","quantity":"1.011"},{"price":"61829.00","quantity":"0.098"},{"price":"61829.50","quantity":"0.879"},{"price":"61829.90","quantity":"0.005"},{"price":"61830.00","quantity":"0.004"},{"price":"61830.30","quantity":"0.007"},{"price":"61830.40","quantity":"0.419"},{"price":"61830.50","quantity":"0.001"},{"price":"61831.20","quantity":"0.001"},{"price":"61831.70","quantity":"0.247"},{"price":"61831.90","quantity":"0.001"},{"price":"61832.30","quantity":"0.002"},{"price":"61832.50","quantity":"0.004"},{"price":"61832.90","quantity":"0.021"},{"price":"61833.10","quantity":"0.325"},{"price":"61833.30","quantity":"0.000"},{"price":"61833.70","quantity":"0.001"},{"price":"61834.00","quantity":"2.414"},{"price":"61834.20","quantity":"0.163"},{"price":"61834.60","quantity":"0.049"},{"price":"61834.90","quantity":"0.001"},{"price":"61835.00","quantity":"2.035"},{"price":"61835.20","quantity":"1.640"},{"price":"61835.40","quantity":"0.001"},{"price":"61835.50","quantity":"0.014"},{"price":"61835.60","quantity":"0.129"},{"price":"61835.70","quantity":"1.070"},{"price":"61836.20","quantity":"0.012"},{"price":"61836.50","quantity":"0.023"},{"price":"61836.60","quantity":"2.227"},{"price":"61836.70","quantity":"0.006"},{"price":"61836.90","quantity":"0.001"},{"price":"61837.40","quantity":"0.811"},{"price":"61837.50","quantity":"2.197"},{"price":"61837.60","quantity":"1.240"},{"price":"61837.80","quantity":"2.139"},{"price":"61837.90","quantity":"1.483"},{"price":"61838.00","quantity":"1.202"},{"price":"61838.10","quantity":"0.483"},{"price":"61838.60","quantity":"0.018"},{"price":"61838.70","quantity":"1.329"},{"price":"61839.10","quantity":"0.080"},{"price":"61839.20","quantity":"0.003"},{"price":"61839.30","quantity":"0.001"},{"price":"61840.00","quantity":"0.500"},{"price":"61840.60","quantity":"0.564"},{"price":"61840.70","quantity":"1.393"},{"price":"61840.80","quantity":"0.241"},{"price":"61840.90","quantity":"0.284"},{"price":"61841.00","quantity":"0.190"},{"price":"61841.20","quantity":"0.152"},{"price":"61841.30","quantity":"0.703"},{"price":"61841.40","quantity":"0.027"},{"price":"61841.60","quantity":"0.053"},{"price":"61841.70","quantity":"1.223"},{"price":"61841.90","quantity":"0.402"},{"price":"61842.00","quantity":"0.046"},{"price":"61842.40","quantity":"0.413"},{"price":"61842.60","quantity":"0.081"},{"price":"61842.80","quantity":"0.180"},{"price":"61842.90","quantity":"0.000"},{"price":"61843.00","quantity":"0.033"},{"price":"61843.10","quantity":"0.052"},{"price":"61843.20","quantity":"0.008"},{"price":"61843.60","quantity":"0.002"},{"price":"61843.70","quantity":"0.003"},{"price":"61843.90","quantity":"0.000"},{"price":"61844.00","quantity":"0.000"},{"price":"61844.10","quantity":"1.202"},{"price":"61844.20","quantity":"0.131"},{"price":"61844.30","quantity":"0.002"},{"price":"61844.40","quantity":"0.020"},{"price":"61844.70","quantity":"1.202"},{"price":"61844.80","quantity":"0.139"},{"price":"61844.90","quantity":"0.001"},{"price":"61845.00","quantity":"0.007"},{"price":"61845.10","quantity":"0.001"},{"price":"61845.30","quantity":"0.005"},{"price":"61845.60","quantity":"0.002"},{"price":"61846.20","quantity":"1.253"},{"price":"61846.40","quantity":"0.001"},{"price":"61846.50","quantity":"0.006"},{"price":"61846.80","quantity":"0.000"},{"price":"61846.90","quantity":"0.146"},{"price":"61847.00","quantity":"0.002"},{"price":"61847.40","quantity":"0.002"},{"price":"61847.80","quantity":"0.002"},{"price":"61848.20","quantity":"0.000"},{"price":"61848.40","quantity":"0.008"},{"price":"61848.70","quantity":"0.064"},{"price":"61849.10","quantity":"0.003"},{"price":"61849.20","quantity":"0.000"},{"price":"61850.00","quantity":"0.032"},{"price":"61850.10","quantity":"0.049"},{"price":"61850.20","quantity":"0.002"},{"price":"61850.30","quantity":"0.004"},{"price":"61850.50","quantity":"0.000"},{"price":"61850.60","quantity":"0.043"},{"price":"61850.70","quantity":"0.002"},{"price":"61851.30","quantity":"0.001"},{"price":"61851.50","quantity":"0.004"},{"price":"61851.60","quantity":"0.070"},{"price":"61852.00","quantity":"1.000"},{"price":"61852.10","quantity":"0.000"},{"price":"61852.20","quantity":"0.871"},{"price":"61852.30","quantity":"0.000"},{"price":"61852.80","quantity":"0.000"},{"price":"61853.20","quantity":"0.000"},{"price":"61853.30","quantity":"0.000"},{"price":"61853.40","quantity":"0.002"},{"price":"61853.50","quantity":"0.000"},{"price":"61853.60","quantity":"0.002"},{"price":"61853.70","quantity":"2.240"}],"asks":[{"price":"61853.80","quantity":"8.406"},{"price":"61853.90","quantity":"0.008"},{"price":"61854.00","quantity":"0.266"},{"price":"61854.40","quantity":"0.001"},{"price":"61854.50","quantity":"0.060"},{"price":"61854.60","quantity":"0.053"},{"price":"61854.80","quantity":"1.881"},{"price":"61854.90","quantity":"2.366"},{"price":"61855.00","quantity":"1.951"},{"price":"61855.50","quantity":"0.003"},{"price":"61855.80","quantity":"0.005"},{"price":"61856.50","quantity":"0.049"},{"price":"61856.70","quantity":"0.915"},{"price":"61856.80","quantity":"1.070"},{"price":"61856.90","quantity":"0.006"},{"price":"61857.00","quantity":"0.841"},{"price":"61857.10","quantity":"0.325"},{"price":"61857.20","quantity":"2.135"},{"price":"61857.30","quantity":"1.402"},{"price":"61857.40","quantity":"1.273"},{"price":"61857.70","quantity":"0.113"},{"price":"61857.80","quantity":"1.022"},{"price":"61857.90","quantity":"0.498"},{"price":"61858.20","quantity":"0.558"},{"price":"61858.40","quantity":"0.002"},{"price":"61858.70","quantity":"0.157"},{"price":"61858.90","quantity":"0.101"},{"price":"61859.20","quantity":"0.069"},{"price":"61859.40","quantity":"0.182"},{"price":"61859.50","quantity":"0.017"},{"price":"61859.60","quantity":"0.133"},{"price":"61859.70","quantity":"0.567"},{"price":"61859.80","quantity":"1.042"},{"price":"61859.90","quantity":"0.199"},{"price":"61860.00","quantity":"0.335"},{"price":"61860.20","quantity":"1.293"},{"price":"61860.30","quantity":"0.018"},{"price":"61860.40","quantity":"0.016"},{"price":"61860.50","quantity":"2.086"},{"price":"61860.60","quantity":"0.124"},{"price":"61860.70","quantity":"0.126"},{"price":"61860.80","quantity":"0.023"},{"price":"61861.00","quantity":"0.047"},{"price":"61861.10","quantity":"0.047"},{"price":"61861.20","quantity":"0.328"},{"price":"61861.30","quantity":"1.247"},{"price":"61861.70","quantity":"0.163"},{"price":"61861.80","quantity":"0.968"},{"price":"61862.00","quantity":"0.163"},{"price":"61862.10","quantity":"0.265"},{"price":"61862.20","quantity":"0.127"},{"price":"61862.30","quantity":"0.002"},{"price":"61862.40","quantity":"0.373"},{"price":"61862.50","quantity":"0.001"},{"price":"61862.60","quantity":"0.007"},{"price":"61862.80","quantity":"0.343"},{"price":"61863.30","quantity":"0.003"},{"price":"61863.40","quantity":"0.596"},{"price":"61863.50","quantity":"0.082"},{"price":"61863.60","quantity":"0.170"},{"price":"61863.80","quantity":"0.003"},{"price":"61863.90","quantity":"0.471"},{"price":"61864.10","quantity":"1.763"},{"price":"61864.50","quantity":"0.000"},{"price":"61864.60","quantity":"0.066"},{"price":"61864.70","quantity":"3.063"},{"price":"61865.00","quantity":"0.003"},{"price":"61865.20","quantity":"0.027"},{"price":"61865.40","quantity":"0.000"},{"price":"61865.60","quantity":"0.004"},{"price":"61866.00","quantity":"0.014"},{"price":"61866.20","quantity":"0.566"},{"price":"61866.40","quantity":"0.122"},{"price":"61866.60","quantity":"0.203"},{"price":"61867.10","quantity":"0.000"},{"price":"61868.40","quantity":"0.025"},{"price":"61868.90","quantity":"0.122"},{"price":"61869.10","quantity":"0.004"},{"price":"61869.40","quantity":"0.007"},{"price":"61870.00","quantity":"0.412"},{"price":"61870.10","quantity":"0.235"},{"price":"61871.30","quantity":"0.111"},{"price":"61871.60","quantity":"0.003"},{"price":"61872.10","quantity":"0.011"},{"price":"61872.90","quantity":"0.394"},{"price":"61873.20","quantity":"0.016"},{"price":"61873.30","quantity":"0.011"},{"price":"61873.60","quantity":"0.033"},{"price":"61873.70","quantity":"0.007"},{"price":"61873.80","quantity":"1.290"},{"price":"61874.70","quantity":"0.011"},{"price":"61874.90","quantity":"0.159"},{"price":"61875.10","quantity":"2.218"},{"price":"61875.20","quantity":"0.283"},{"price":"61875.70","quantity":"3.718"},{"price":"61877.80","quantity":"0.016"},{"price":"61878.10","quantity":"0.002"},{"price":"61878.60","quantity":"1.024"},{"price":"61878.90","quantity":"0.002"},{"price":"61879.20","quantity":"0.055"},{"price":"61879.60","quantity":"0.000"},{"price":"61879.70","quantity":"0.105"},{"price":"61880.20","quantity":"0.121"},{"price":"61880.80","quantity":"0.008"},{"price":"61881.00","quantity":"0.572"},{"price":"61881.10","quantity":"0.002"},{"price":"61881.30","quantity":"0.975"},{"price":"61881.40","quantity":"0.249"},{"price":"61881.50","quantity":"0.014"},{"price":"61881.70","quantity":"0.000"},{"price":"61882.20","quantity":"0.799"},{"price":"61882.30","quantity":"0.008"},{"price":"61882.40","quantity":"0.000"},{"price":"61882.60","quantity":"0.016"},{"price":"61885.90","quantity":"0.013"},{"price":"61886.30","quantity":"0.002"},{"price":"61886.70","quantity":"0.010"},{"price":"61886.80","quantity":"0.735"},{"price":"61886.90","quantity":"0.000"},{"price":"61887.40","quantity":"0.013"},{"price":"61888.20","quantity":"0.123"},{"price":"61888.30","quantity":"0.078"},{"price":"61888.90","quantity":"0.952"},{"price":"61889.00","quantity":"0.002"},{"price":"61889.40","quantity":"0.018"},{"price":"61889.80","quantity":"0.121"},{"price":"61889.90","quantity":"0.003"},{"price":"61891.50","quantity":"0.004"},{"price":"61892.90","quantity":"0.009"},{"price":"61894.10","quantity":"0.020"},{"price":"61895.20","quantity":"0.015"},{"price":"61895.30","quantity":"0.002"},{"price":"61895.70","quantity":"0.090"},{"price":"61895.80","quantity":"0.158"},{"price":"61895.90","quantity":"0.000"},{"price":"61896.40","quantity":"1.052"},{"price":"61896.50","quantity":"0.002"},{"price":"61897.30","quantity":"0.001"},{"price":"61897.50","quantity":"0.012"},{"price":"61897.60","quantity":"0.007"},{"price":"61902.80","quantity":"0.097"},{"price":"61903.30","quantity":"0.469"},{"price":"61904.80","quantity":"0.386"},{"price":"61905.60","quantity":"0.004"},{"price":"61907.70","quantity":"0.513"},{"price":"61909.00","quantity":"0.032"},{"price":"61909.40","quantity":"0.006"},{"price":"61909.50","quantity":"2.640"},{"price":"61909.90","quantity":"0.116"},{"price":"61910.10","quantity":"0.036"},{"price":"61910.40","quantity":"1.157"},{"price":"61910.60","quantity":"0.019"},{"price":"61911.70","quantity":"0.004"},{"price":"61913.50","quantity":"2.244"},{"price":"61914.40","quantity":"0.363"},{"price":"61915.10","quantity":"0.121"},{"price":"61916.00","quantity":"0.003"},{"price":"61916.30","quantity":"0.149"},{"price":"61916.40","quantity":"6.531"},{"price":"61918.30","quantity":"0.000"},{"price":"61918.40","quantity":"25.201"},{"price":"61920.00","quantity":"1.172"},{"price":"61920.30","quantity":"0.000"},{"price":"61921.50","quantity":"0.000"},{"price":"61921.80","quantity":"0.029"},{"price":"61922.30","quantity":"0.218"},{"price":"61926.60","quantity":"0.001"},{"price":"61928.70","quantity":"0.026"},{"price":"61946.30","quantity":"2.154"},{"price":"61950.90","quantity":"0.833"},{"price":"61953.70","quantity":"0.000"},{"price":"62000.00","quantity":"13.023"},{"price":"62080.00","quantity":"0.289"},{"price":"62136.50","quantity":"0.149"},{"price":"62138.30","quantity":"0.017"},{"price":"62160.00","quantity":"0.284"},{"price":"62240.00","quantity":"0.279"},{"price":"62470.80","quantity":"0.022"},{"price":"62472.30","quantity":"0.002"},{"price":"62564.00","quantity":"0.002"},{"price":"62564.20","quantity":"0.000"},{"price":"62565.10","quantity":"2.374"},{"price":"62565.30","quantity":"13.286"},{"price":"62589.30","quantity":"0.958"},{"price":"62625.90","quantity":"4.426"},{"price":"62626.10","quantity":"0.000"},{"price":"62627.00","quantity":"3.160"},{"price":"62627.20","quantity":"6.168"},{"price":"63090.80","quantity":"0.003"},{"price":"89523.20","quantity":"0.708"}],"raw":{"e":"depthUpdate","E":1783517066292,"T":1783517066291,"s":"BTCUSDT","ps":"BTCUSDT","U":10999770489995,"u":10999770524747,"pu":10999770489945,"b":[["11353.70","0.288"],["11452.20","2.416"],["11553.70","0.153"],["11652.20","0.493"],["49483.00","0.000"],["55668.30","0.002"],["58745.80","0.031"],["59379.50","0.004"],["60616.70","0.011"],["60781.60","0.822"],["60948.40","3.580"],["61076.90","3.774"],["61171.80","1.227"],["61177.70","0.001"],["61235.20","0.025"],["61397.00","0.052"],["61440.00","0.140"],["61520.00","2.919"],["61593.90","0.276"],["61600.00","56.797"],["61677.90","0.005"],["61679.40","0.588"],["61680.00","0.711"],["61750.50","0.047"],["61758.90","0.019"],["61759.80","0.000"],["61760.00","0.920"],["61760.50","0.009"],["61763.20","0.019"],["61764.00","1.363"],["61770.00","1.664"],["61773.80","0.033"],["61777.30","0.000"],["61785.80","0.000"],["61786.00","0.212"],["61786.30","0.002"],["61786.40","2.413"],["61786.50","0.022"],["61788.40","34.215"],["61789.00","6.412"],["61790.00","0.203"],["61790.50","1.114"],["61792.40","0.162"],["61792.70","0.070"],["61794.30","0.028"],["61796.30","0.001"],["61796.60","0.801"],["61797.40","0.163"],["61797.50","0.003"],["61797.70","0.843"],["61797.90","1.431"],["61798.00","0.015"],["61798.60","0.026"],["61800.90","0.025"],["61803.90","0.198"],["61804.60","0.049"],["61806.00","0.043"],["61806.30","0.021"],["61807.60","1.444"],["61808.00","0.056"],["61808.10","0.000"],["61808.50","0.000"],["61808.80","0.351"],["61808.90","0.111"],["61809.30","0.182"],["61810.30","1.007"],["61812.50","0.933"],["61813.60","0.103"],["61814.20","0.296"],["61814.30","0.232"],["61814.40","0.110"],["61814.50","0.007"],["61815.70","0.002"],["61815.90","0.002"],["61816.30","0.390"],["61816.40","0.868"],["61816.50","0.081"],["61817.00","0.018"],["61817.30","1.771"],["61818.20","0.000"],["61818.40","0.004"],["61819.10","0.120"],["61819.40","0.100"],["61820.00","50.542"],["61820.10","10.663"],["61820.30","0.556"],["61820.40","1.415"],["61820.50","0.309"],["61820.90","1.779"],["61821.00","0.737"],["61821.20","0.065"],["61821.30","0.096"],["61821.50","0.324"],["61822.10","0.001"],["61822.30","0.002"],["61822.70","0.016"],["61823.20","0.355"],["61823.40","0.002"],["61823.80","0.017"],["61824.20","0.002"],["61824.30","0.092"],["61824.70","0.001"],["61824.80","0.009"],["61825.00","3.092"],["61825.10","0.255"],["61825.30","0.017"],["61825.50","0.008"],["61825.70","0.004"],["61825.90","1.319"],["61826.40","0.881"],["61826.70","0.011"],["61826.90","0.003"],["61827.10","0.006"],["61827.50","2.686"],["61827.60","0.002"],["61828.10","0.081"],["61828.30","0.001"],["61828.50","0.016"],["61828.70","0.129"],["61828.90","1.011"],["61829.00","0.098"],["61829.50","0.879"],["61829.90","0.005"],["61830.00","0.004"],["61830.30","0.007"],["61830.40","0.419"],["61830.50","0.001"],["61831.20","0.001"],["61831.70","0.247"],["61831.90","0.001"],["61832.30","0.002"],["61832.50","0.004"],["61832.90","0.021"],["61833.10","0.325"],["61833.30","0.000"],["61833.70","0.001"],["61834.00","2.414"],["61834.20","0.163"],["61834.60","0.049"],["61834.90","0.001"],["61835.00","2.035"],["61835.20","1.640"],["61835.40","0.001"],["61835.50","0.014"],["61835.60","0.129"],["61835.70","1.070"],["61836.20","0.012"],["61836.50","0.023"],["61836.60","2.227"],["61836.70","0.006"],["61836.90","0.001"],["61837.40","0.811"],["61837.50","2.197"],["61837.60","1.240"],["61837.80","2.139"],["61837.90","1.483"],["61838.00","1.202"],["61838.10","0.483"],["61838.60","0.018"],["61838.70","1.329"],["61839.10","0.080"],["61839.20","0.003"],["61839.30","0.001"],["61840.00","0.500"],["61840.60","0.564"],["61840.70","1.393"],["61840.80","0.241"],["61840.90","0.284"],["61841.00","0.190"],["61841.20","0.152"],["61841.30","0.703"],["61841.40","0.027"],["61841.60","0.053"],["61841.70","1.223"],["61841.90","0.402"],["61842.00","0.046"],["61842.40","0.413"],["61842.60","0.081"],["61842.80","0.180"],["61842.90","0.000"],["61843.00","0.033"],["61843.10","0.052"],["61843.20","0.008"],["61843.60","0.002"],["61843.70","0.003"],["61843.90","0.000"],["61844.00","0.000"],["61844.10","1.202"],["61844.20","0.131"],["61844.30","0.002"],["61844.40","0.020"],["61844.70","1.202"],["61844.80","0.139"],["61844.90","0.001"],["61845.00","0.007"],["61845.10","0.001"],["61845.30","0.005"],["61845.60","0.002"],["61846.20","1.253"],["61846.40","0.001"],["61846.50","0.006"],["61846.80","0.000"],["61846.90","0.146"],["61847.00","0.002"],["61847.40","0.002"],["61847.80","0.002"],["61848.20","0.000"],["61848.40","0.008"],["61848.70","0.064"],["61849.10","0.003"],["61849.20","0.000"],["61850.00","0.032"],["61850.10","0.049"],["61850.20","0.002"],["61850.30","0.004"],["61850.50","0.000"],["61850.60","0.043"],["61850.70","0.002"],["61851.30","0.001"],["61851.50","0.004"],["61851.60","0.070"],["61852.00","1.000"],["61852.10","0.000"],["61852.20","0.871"],["61852.30","0.000"],["61852.80","0.000"],["61853.20","0.000"],["61853.30","0.000"],["61853.40","0.002"],["61853.50","0.000"],["61853.60","0.002"],["61853.70","2.240"]],"a":[["61853.80","8.406"],["61853.90","0.008"],["61854.00","0.266"],["61854.40","0.001"],["61854.50","0.060"],["61854.60","0.053"],["61854.80","1.881"],["61854.90","2.366"],["61855.00","1.951"],["61855.50","0.003"],["61855.80","0.005"],["61856.50","0.049"],["61856.70","0.915"],["61856.80","1.070"],["61856.90","0.006"],["61857.00","0.841"],["61857.10","0.325"],["61857.20","2.135"],["61857.30","1.402"],["61857.40","1.273"],["61857.70","0.113"],["61857.80","1.022"],["61857.90","0.498"],["61858.20","0.558"],["61858.40","0.002"],["61858.70","0.157"],["61858.90","0.101"],["61859.20","0.069"],["61859.40","0.182"],["61859.50","0.017"],["61859.60","0.133"],["61859.70","0.567"],["61859.80","1.042"],["61859.90","0.199"],["61860.00","0.335"],["61860.20","1.293"],["61860.30","0.018"],["61860.40","0.016"],["61860.50","2.086"],["61860.60","0.124"],["61860.70","0.126"],["61860.80","0.023"],["61861.00","0.047"],["61861.10","0.047"],["61861.20","0.328"],["61861.30","1.247"],["61861.70","0.163"],["61861.80","0.968"],["61862.00","0.163"],["61862.10","0.265"],["61862.20","0.127"],["61862.30","0.002"],["61862.40","0.373"],["61862.50","0.001"],["61862.60","0.007"],["61862.80","0.343"],["61863.30","0.003"],["61863.40","0.596"],["61863.50","0.082"],["61863.60","0.170"],["61863.80","0.003"],["61863.90","0.471"],["61864.10","1.763"],["61864.50","0.000"],["61864.60","0.066"],["61864.70","3.063"],["61865.00","0.003"],["61865.20","0.027"],["61865.40","0.000"],["61865.60","0.004"],["61866.00","0.014"],["61866.20","0.566"],["61866.40","0.122"],["61866.60","0.203"],["61867.10","0.000"],["61868.40","0.025"],["61868.90","0.122"],["61869.10","0.004"],["61869.40","0.007"],["61870.00","0.412"],["61870.10","0.235"],["61871.30","0.111"],["61871.60","0.003"],["61872.10","0.011"],["61872.90","0.394"],["61873.20","0.016"],["61873.30","0.011"],["61873.60","0.033"],["61873.70","0.007"],["61873.80","1.290"],["61874.70","0.011"],["61874.90","0.159"],["61875.10","2.218"],["61875.20","0.283"],["61875.70","3.718"],["61877.80","0.016"],["61878.10","0.002"],["61878.60","1.024"],["61878.90","0.002"],["61879.20","0.055"],["61879.60","0.000"],["61879.70","0.105"],["61880.20","0.121"],["61880.80","0.008"],["61881.00","0.572"],["61881.10","0.002"],["61881.30","0.975"],["61881.40","0.249"],["61881.50","0.014"],["61881.70","0.000"],["61882.20","0.799"],["61882.30","0.008"],["61882.40","0.000"],["61882.60","0.016"],["61885.90","0.013"],["61886.30","0.002"],["61886.70","0.010"],["61886.80","0.735"],["61886.90","0.000"],["61887.40","0.013"],["61888.20","0.123"],["61888.30","0.078"],["61888.90","0.952"],["61889.00","0.002"],["61889.40","0.018"],["61889.80","0.121"],["61889.90","0.003"],["61891.50","0.004"],["61892.90","0.009"],["61894.10","0.020"],["61895.20","0.015"],["61895.30","0.002"],["61895.70","0.090"],["61895.80","0.158"],["61895.90","0.000"],["61896.40","1.052"],["61896.50","0.002"],["61897.30","0.001"],["61897.50","0.012"],["61897.60","0.007"],["61902.80","0.097"],["61903.30","0.469"],["61904.80","0.386"],["61905.60","0.004"],["61907.70","0.513"],["61909.00","0.032"],["61909.40","0.006"],["61909.50","2.640"],["61909.90","0.116"],["61910.10","0.036"],["61910.40","1.157"],["61910.60","0.019"],["61911.70","0.004"],["61913.50","2.244"],["61914.40","0.363"],["61915.10","0.121"],["61916.00","0.003"],["61916.30","0.149"],["61916.40","6.531"],["61918.30","0.000"],["61918.40","25.201"],["61920.00","1.172"],["61920.30","0.000"],["61921.50","0.000"],["61921.80","0.029"],["61922.30","0.218"],["61926.60","0.001"],["61928.70","0.026"],["61946.30","2.154"],["61950.90","0.833"],["61953.70","0.000"],["62000.00","13.023"],["62080.00","0.289"],["62136.50","0.149"],["62138.30","0.017"],["62160.00","0.284"],["62240.00","0.279"],["62470.80","0.022"],["62472.30","0.002"],["62564.00","0.002"],["62564.20","0.000"],["62565.10","2.374"],["62565.30","13.286"],["62589.30","0.958"],["62625.90","4.426"],["62626.10","0.000"],["62627.00","3.160"],["62627.20","6.168"],["63090.80","0.003"],["89523.20","0.708"]],"st":1}}
{"schema_version":"1.3.0","event_id":"6ab1e47e-caaa-4902-84d0-e900bc64a550","event_type":"raw.trade","source":"binance_market_data_recorder","venue":"binance_usdm","market_type":"perpetual_futures","symbol":"BTCUSDT","event_time_ms":1783517066315,"received_time_ms":1783517067014,"trace_id":"f3515b39-01fe-43b3-a4c1-10a6da7d43fe","trade_id":7881418048,"price":"61853.80","quantity":"0.078","trade_time_ms":1783517066315,"is_buyer_maker":false,"aggressor_side":"buy","raw":{"e":"trade","E":1783517066315,"T":1783517066315,"s":"BTCUSDT","t":7881418048,"p":"61853.80","q":"0.078","X":"MARKET","m":false,"st":1}}
{"schema_version":"1.3.0","event_id":"2ffd43df-3d6a-4ee5-b57a-d3dde30d11a9","event_type":"raw.trade","source":"binance_market_data_recorder","venue":"binance_usdm","market_type":"perpetual_futures","symbol":"ETHUSDT","event_time_ms":1783517066320,"received_time_ms":1783517067024,"trace_id":"2e83cc8f-4ddc-4346-9c25-79456cd9d7f3","trade_id":8429826838,"price":"1736.13","quantity":"0.012","trade_time_ms":1783517066320,"is_buyer_maker":true,"aggressor_side":"sell","raw":{"e":"trade","E":1783517066320,"T":1783517066320,"s":"ETHUSDT","t":8429826838,"p":"1736.13","q":"0.012","X":"MARKET","m":true,"st":1}}
{"schema_version":"1.3.0","event_id":"6e8b57c0-7282-4d7b-8064-7b12d49c7e75","event_type":"raw.trade","source":"binance_market_data_recorder","venue":"binance_usdm","market_type":"perpetual_futures","symbol":"ETHUSDT","event_time_ms":1783517066320,"received_time_ms":1783517067025,"trace_id":"8deebfb0-0f10-4d10-9001-6e85abb47d8b","trade_id":8429826839,"price":"1736.13","quantity":"0.012","trade_time_ms":1783517066320,"is_buyer_maker":true,"aggressor_side":"sell","raw":{"e":"trade","E":1783517066320,"T":1783517066320,"s":"ETHUSDT","t":8429826839,"p":"1736.13","q":"0.012","X":"MARKET","m":true,"st":1}}
{"schema_version":"1.3.0","event_id":"ffd44360-22fa-4a85-a9e1-32b336ed167d","event_type":"raw.trade","source":"binance_market_data_recorder","venue":"binance_usdm","market_type":"perpetual_futures","symbol":"ETHUSDT","event_time_ms":1783517066320,"received_time_ms":1783517067025,"trace_id":"15a07037-cdaf-4c3e-8471-fa1aeb590a55","trade_id":8429826840,"price":"1736.13","quantity":"0.012","trade_time_ms":1783517066320,"is_buyer_maker":true,"aggressor_side":"sell","raw":{"e":"trade","E":1783517066320,"T":1783517066320,"s":"ETHUSDT","t":8429826840,"p":"1736.13","q":"0.012","X":"MARKET","m":true,"st":1}}
{"schema_version":"1.3.0","event_id":"5e926011-10ad-4c1d-8a7f-c12bf3c7c878","event_type":"raw.trade","source":"binance_market_data_recorder","venue":"binance_usdm","market_type":"perpetual_futures","symbol":"ETHUSDT","event_time_ms":1783517066320,"received_time_ms":1783517067026,"trace_id":"19203db5-3dba-43d1-9359-cc9366ecc12c","trade_id":8429826841,"price":"1736.13","quantity":"0.526","trade_time_ms":1783517066320,"is_buyer_maker":true,"aggressor_side":"sell","raw":{"e":"trade","E":1783517066320,"T":1783517066320,"s":"ETHUSDT","t":8429826841,"p":"1736.13","q":"0.526","X":"MARKET","m":true,"st":1}}
{"schema_version":"1.3.0","event_id":"8430c5db-137d-4cea-92da-21e0cc616d2d","event_type":"raw.trade","source":"binance_market_data_recorder","venue":"binance_usdm","market_type":"perpetual_futures","symbol":"ETHUSDT","event_time_ms":1783517066320,"received_time_ms":1783517067026,"trace_id":"f85739c8-b186-4113-8990-979e8e10cb5e","trade_id":8429826842,"price":"1736.13","quantity":"0.012","trade_time_ms":1783517066320,"is_buyer_maker":true,"aggressor_side":"sell","raw":{"e":"trade","E":1783517066320,"T":1783517066320,"s":"ETHUSDT","t":8429826842,"p":"1736.13","q":"0.012","X":"MARKET","m":true,"st":1}}
{"schema_version":"1.3.0","event_id":"1565d06c-01e8-4aa3-af14-2bc57bec9e5b","event_type":"raw.trade","source":"binance_market_data_recorder","venue":"binance_usdm","market_type":"perpetual_futures","symbol":"ETHUSDT","event_time_ms":1783517066320,"received_time_ms":1783517067027,"trace_id":"7e943829-098c-43d3-b28c-12a9820f9c34","trade_id":8429826843,"price":"1736.13","quantity":"0.012","trade_time_ms":1783517066320,"is_buyer_maker":true,"aggressor_side":"sell","raw":{"e":"trade","E":1783517066320,"T":1783517066320,"s":"ETHUSDT","t":8429826843,"p":"1736.13","q":"0.012","X":"MARKET","m":true,"st":1}}
{"schema_version":"1.3.0","event_id":"eb23e26f-3a17-4fa5-9479-3925260005dd","event_type":"raw.trade","source":"binance_market_data_recorder","venue":"binance_usdm","market_type":"perpetual_futures","symbol":"ETHUSDT","event_time_ms":1783517066320,"received_time_ms":1783517067027,"trace_id":"5915b534-2520-4f58-b35a-ace62005606c","trade_id":8429826844,"price":"1736.13","quantity":"0.012","trade_time_ms":1783517066320,"is_buyer_maker":true,"aggressor_side":"sell","raw":{"e":"trade","E":1783517066320,"T":1783517066320,"s":"ETHUSDT","t":8429826844,"p":"1736.13","q":"0.012","X":"MARKET","m":true,"st":1}}
{"schema_version":"1.3.0","event_id":"2593a3a9-76ce-46bf-9a3b-0ad54b42f7ac","event_type":"raw.trade","source":"binance_market_data_recorder","venue":"binance_usdm","market_type":"perpetual_futures","symbol":"ETHUSDT","event_time_ms":1783517066320,"received_time_ms":1783517067028,"trace_id":"65f257b6-bc32-449d-8327-1a4a8f3d320a","trade_id":8429826845,"price":"1736.13","quantity":"0.012","trade_time_ms":1783517066320,"is_buyer_maker":true,"aggressor_side":"sell","raw":{"e":"trade","E":1783517066320,"T":1783517066320,"s":"ETHUSDT","t":8429826845,"p":"1736.13","q":"0.012","X":"MARKET","m":true,"st":1}}
{"schema_version":"1.3.0","event_id":"bea0c1ec-30ac-426c-a294-03e7e057713c","event_type":"raw.trade","source":"binance_market_data_recorder","venue":"binance_usdm","market_type":"perpetual_futures","symbol":"ETHUSDT","event_time_ms":1783517066320,"received_time_ms":1783517067028,"trace_id":"d43bf81a-cb6a-46ac-bfd3-ecba31a397b2","trade_id":8429826846,"price":"1736.13","quantity":"0.012","trade_time_ms":1783517066320,"is_buyer_maker":true,"aggressor_side":"sell","raw":{"e":"trade","E":1783517066320,"T":1783517066320,"s":"ETHUSDT","t":8429826846,"p":"1736.13","q":"0.012","X":"MARKET","m":true,"st":1}}
{"schema_version":"1.3.0","event_id":"68329b7c-bcb5-4a14-9bd6-1ea6e059690a","event_type":"raw.trade","source":"binance_market_data_recorder","venue":"binance_usdm","market_type":"perpetual_futures","symbol":"ETHUSDT","event_time_ms":1783517066320,"received_time_ms":1783517067029,"trace_id":"c2e6acab-9d6f-4a63-8f5f-2c2288955db4","trade_id":8429826847,"price":"1736.13","quantity":"0.012","trade_time_ms":1783517066320,"is_buyer_maker":true,"aggressor_side":"sell","raw":{"e":"trade","E":1783517066320,"T":1783517066320,"s":"ETHUSDT","t":8429826847,"p":"1736.13","q":"0.012","X":"MARKET","m":true,"st":1}}
{"schema_version":"1.3.0","event_id":"59d2d6c9-c9dd-432b-9f06-93dec0e11373","event_type":"raw.depth_update","source":"binance_market_data_recorder","venue":"binance_usdm","market_type":"perpetual_futures","symbol":"ETHUSDT","event_time_ms":1783517066356,"received_time_ms":1783517067147,"trace_id":"15dc595a-b504-4476-b056-b95f6b6887fb","first_update_id":10999770515262,"final_update_id":10999770540664,"previous_final_update_id":10999770515220,"bids":[{"price":"200.00","quantity":"7.594"},{"price":"1211.12","quantity":"0.289"},{"price":"1216.12","quantity":"0.160"},{"price":"1216.13","quantity":"0.640"},{"price":"1216.27","quantity":"0.532"},{"price":"1221.16","quantity":"2.400"},{"price":"1562.50","quantity":"1.060"},{"price":"1562.51","quantity":"5.880"},{"price":"1562.52","quantity":"0.000"},{"price":"1667.58","quantity":"0.060"},{"price":"1693.39","quantity":"0.000"},{"price":"1700.44","quantity":"29.399"},{"price":"1704.88","quantity":"40.317"},{"price":"1710.75","quantity":"43.994"},{"price":"1724.90","quantity":"43.360"},{"price":"1725.72","quantity":"60.118"},{"price":"1726.10","quantity":"2.608"},{"price":"1726.83","quantity":"46.883"},{"price":"1727.44","quantity":"0.024"},{"price":"1729.13","quantity":"0.028"},{"price":"1729.35","quantity":"0.310"},{"price":"1729.57","quantity":"0.000"},{"price":"1730.01","quantity":"21.644"},{"price":"1730.23","quantity":"33.557"},{"price":"1730.26","quantity":"5.916"},{"price":"1731.24","quantity":"223.992"},{"price":"1731.26","quantity":"4.677"},{"price":"1731.33","quantity":"19.266"},{"price":"1731.40","quantity":"7.047"},{"price":"1731.41","quantity":"43.977"},{"price":"1731.51","quantity":"1.976"},{"price":"1731.84","quantity":"0.118"},{"price":"1731.91","quantity":"16.420"},{"price":"1731.94","quantity":"0.042"},{"price":"1731.96","quantity":"108.350"},{"price":"1732.05","quantity":"51.899"},{"price":"1732.10","quantity":"10.440"},{"price":"1732.28","quantity":"16.371"},{"price":"1732.29","quantity":"0.493"},{"price":"1732.30","quantity":"172.874"},{"price":"1732.31","quantity":"6.708"},{"price":"1732.32","quantity":"135.425"},{"price":"1732.50","quantity":"54.587"},{"price":"1732.53","quantity":"1.871"},{"price":"1732.63","quantity":"0.876"},{"price":"1732.72","quantity":"22.451"},{"price":"1732.95","quantity":"24.467"},{"price":"1733.13","quantity":"30.371"},{"price":"1733.23","quantity":"17.236"},{"price":"1733.27","quantity":"0.012"},{"price":"1733.28","quantity":"67.245"},{"price":"1733.29","quantity":"24.558"},{"price":"1733.30","quantity":"24.381"},{"price":"1733.32","quantity":"4.367"},{"price":"1733.34","quantity":"0.000"},{"price":"1733.36","quantity":"20.130"},{"price":"1733.39","quantity":"22.071"},{"price":"1733.42","quantity":"5.753"},{"price":"1733.44","quantity":"10.089"},{"price":"1733.53","quantity":"429.699"},{"price":"1733.54","quantity":"83.739"},{"price":"1733.63","quantity":"51.010"},{"price":"1733.70","quantity":"16.600"},{"price":"1733.71","quantity":"85.123"},{"price":"1733.74","quantity":"15.812"},{"price":"1733.82","quantity":"2.575"},{"price":"1733.83","quantity":"0.562"},{"price":"1733.85","quantity":"65.288"},{"price":"1733.86","quantity":"2.091"},{"price":"1733.94","quantity":"29.283"},{"price":"1733.98","quantity":"0.245"},{"price":"1734.01","quantity":"17.457"},{"price":"1734.04","quantity":"125.012"},{"price":"1734.18","quantity":"0.012"},{"price":"1734.19","quantity":"5.021"},{"price":"1734.21","quantity":"19.027"},{"price":"1734.22","quantity":"17.049"},{"price":"1734.24","quantity":"1.874"},{"price":"1734.25","quantity":"0.059"},{"price":"1734.26","quantity":"0.703"},{"price":"1734.27","quantity":"0.449"},{"price":"1734.30","quantity":"21.202"},{"price":"1734.32","quantity":"231.107"},{"price":"1734.33","quantity":"19.958"},{"price":"1734.35","quantity":"8.782"},{"price":"1734.36","quantity":"43.618"},{"price":"1734.37","quantity":"0.150"},{"price":"1734.42","quantity":"3.047"},{"price":"1734.43","quantity":"1.184"},{"price":"1734.45","quantity":"0.056"},{"price":"1734.46","quantity":"51.458"},{"price":"1734.47","quantity":"4.441"},{"price":"1734.48","quantity":"18.044"},{"price":"1734.49","quantity":"53.052"},{"price":"1734.50","quantity":"9.332"},{"price":"1734.51","quantity":"12.717"},{"price":"1734.52","quantity":"1.949"},{"price":"1734.53","quantity":"255.759"},{"price":"1734.54","quantity":"17.767"},{"price":"1734.55","quantity":"0.955"},{"price":"1734.57","quantity":"29.333"},{"price":"1734.59","quantity":"1.211"},{"price":"1734.62","quantity":"119.388"},{"price":"1734.63","quantity":"19.810"},{"price":"1734.65","quantity":"13.647"},{"price":"1734.66","quantity":"1.206"},{"price":"1734.68","quantity":"8.509"},{"price":"1734.70","quantity":"0.870"},{"price":"1734.73","quantity":"97.067"},{"price":"1734.75","quantity":"68.153"},{"price":"1734.77","quantity":"84.150"},{"price":"1734.79","quantity":"8.220"},{"price":"1734.81","quantity":"19.072"},{"price":"1734.82","quantity":"18.237"},{"price":"1734.83","quantity":"8.889"},{"price":"1734.84","quantity":"272.072"},{"price":"1734.86","quantity":"38.717"},{"price":"1734.87","quantity":"19.856"},{"price":"1734.88","quantity":"59.458"},{"price":"1734.89","quantity":"0.168"},{"price":"1734.90","quantity":"19.409"},{"price":"1734.92","quantity":"58.981"},{"price":"1734.93","quantity":"63.524"},{"price":"1734.94","quantity":"12.464"},{"price":"1734.99","quantity":"0.689"},{"price":"1735.00","quantity":"217.843"},{"price":"1735.01","quantity":"44.586"},{"price":"1735.02","quantity":"50.511"},{"price":"1735.03","quantity":"0.065"},{"price":"1735.04","quantity":"2.899"},{"price":"1735.05","quantity":"1.232"},{"price":"1735.06","quantity":"0.927"},{"price":"1735.08","quantity":"6.025"},{"price":"1735.09","quantity":"1.235"},{"price":"1735.11","quantity":"44.136"},{"price":"1735.13","quantity":"1.559"},{"price":"1735.15","quantity":"47.601"},{"price":"1735.16","quantity":"3.909"},{"price":"1735.19","quantity":"70.115"},{"price":"1735.20","quantity":"45.938"},{"price":"1735.21","quantity":"34.467"},{"price":"1735.22","quantity":"16.287"},{"price":"1735.23","quantity":"5.796"},{"price":"1735.24","quantity":"8.926"},{"price":"1735.25","quantity":"0.769"},{"price":"1735.26","quantity":"0.038"},{"price":"1735.27","quantity":"70.102"},{"price":"1735.28","quantity":"4.962"},{"price":"1735.32","quantity":"26.988"},{"price":"1735.33","quantity":"16.311"},{"price":"1735.37","quantity":"0.752"},{"price":"1735.38","quantity":"65.064"},{"price":"1735.39","quantity":"0.541"},{"price":"1735.41","quantity":"124.157"},{"price":"1735.42","quantity":"20.611"},{"price":"1735.43","quantity":"4.041"},{"price":"1735.44","quantity":"27.461"},{"price":"1735.45","quantity":"0.166"},{"price":"1735.47","quantity":"17.509"},{"price":"1735.48","quantity":"0.874"},{"price":"1735.49","quantity":"7.056"},{"price":"1735.50","quantity":"18.754"},{"price":"1735.51","quantity":"58.185"},{"price":"1735.52","quantity":"77.458"},{"price":"1735.53","quantity":"5.205"},{"price":"1735.54","quantity":"5.779"},{"price":"1735.55","quantity":"4.511"},{"price":"1735.56","quantity":"28.286"},{"price":"1735.57","quantity":"1.802"},{"price":"1735.58","quantity":"0.766"},{"price":"1735.59","quantity":"4.353"},{"price":"1735.60","quantity":"33.449"},{"price":"1735.61","quantity":"8.709"},{"price":"1735.63","quantity":"0.576"},{"price":"1735.64","quantity":"76.667"},{"price":"1735.65","quantity":"20.560"},{"price":"1735.66","quantity":"0.157"},{"price":"1735.67","quantity":"1.451"},{"price":"1735.69","quantity":"4.767"},{"price":"1735.70","quantity":"0.037"},{"price":"1735.72","quantity":"89.558"},{"price":"1735.73","quantity":"26.847"},{"price":"1735.74","quantity":"27.864"},{"price":"1735.75","quantity":"86.033"},{"price":"1735.76","quantity":"5.511"},{"price":"1735.77","quantity":"22.995"},{"price":"1735.78","quantity":"21.175"},{"price":"1735.79","quantity":"1.795"},{"price":"1735.80","quantity":"0.242"},{"price":"1735.81","quantity":"5.186"},{"price":"1735.82","quantity":"14.191"},{"price":"1735.83","quantity":"28.903"},{"price":"1735.84","quantity":"5.090"},{"price":"1735.85","quantity":"6.839"},{"price":"1735.86","quantity":"1.148"},{"price":"1735.87","quantity":"0.220"},{"price":"1735.88","quantity":"22.221"},{"price":"1735.89","quantity":"1.159"},{"price":"1735.90","quantity":"3.012"},{"price":"1735.91","quantity":"12.427"},{"price":"1735.92","quantity":"9.714"},{"price":"1735.93","quantity":"0.197"},{"price":"1735.94","quantity":"3.711"},{"price":"1735.95","quantity":"0.074"},{"price":"1735.96","quantity":"2.280"},{"price":"1735.98","quantity":"3.677"},{"price":"1735.99","quantity":"0.052"},{"price":"1736.00","quantity":"1.084"},{"price":"1736.01","quantity":"0.038"},{"price":"1736.02","quantity":"0.049"},{"price":"1736.03","quantity":"0.050"},{"price":"1736.04","quantity":"0.012"},{"price":"1736.05","quantity":"0.051"},{"price":"1736.06","quantity":"0.014"},{"price":"1736.07","quantity":"0.048"},{"price":"1736.08","quantity":"0.709"},{"price":"1736.09","quantity":"0.669"},{"price":"1736.10","quantity":"3.722"},{"price":"1736.11","quantity":"0.029"},{"price":"1736.12","quantity":"75.293"},{"price":"1736.13","quantity":"0.000"}],"asks":[{"price":"1736.13","quantity":"347.586"},{"price":"1736.14","quantity":"0.040"},{"price":"1736.15","quantity":"0.000"},{"price":"1736.16","quantity":"0.538"},{"price":"1736.17","quantity":"0.024"},{"price":"1736.18","quantity":"0.036"},{"price":"1736.19","quantity":"0.300"},{"price":"1736.20","quantity":"2.807"},{"price":"1736.21","quantity":"1.740"},{"price":"1736.22","quantity":"20.724"},{"price":"1736.23","quantity":"3.275"},{"price":"1736.24","quantity":"29.245"},{"price":"1736.25","quantity":"2.800"},{"price":"1736.27","quantity":"11.637"},{"price":"1736.28","quantity":"44.020"},{"price":"1736.29","quantity":"1.164"},{"price":"1736.30","quantity":"11.736"},{"price":"1736.31","quantity":"89.094"},{"price":"1736.32","quantity":"0.176"},{"price":"1736.33","quantity":"0.012"},{"price":"1736.34","quantity":"28.865"},{"price":"1736.35","quantity":"4.525"},{"price":"1736.36","quantity":"0.548"},{"price":"1736.37","quantity":"9.021"},{"price":"1736.38","quantity":"0.256"},{"price":"1736.39","quantity":"0.098"},{"price":"1736.40","quantity":"18.642"},{"price":"1736.41","quantity":"9.520"},{"price":"1736.42","quantity":"3.358"},{"price":"1736.43","quantity":"29.927"},{"price":"1736.44","quantity":"9.485"},{"price":"1736.45","quantity":"74.946"},{"price":"1736.46","quantity":"43.794"},{"price":"1736.47","quantity":"13.186"},{"price":"1736.48","quantity":"7.730"},{"price":"1736.49","quantity":"3.215"},{"price":"1736.50","quantity":"0.090"},{"price":"1736.52","quantity":"0.087"},{"price":"1736.53","quantity":"1.419"},{"price":"1736.54","quantity":"2.869"},{"price":"1736.55","quantity":"31.365"},{"price":"1736.58","quantity":"1.665"},{"price":"1736.59","quantity":"8.864"},{"price":"1736.60","quantity":"5.067"},{"price":"1736.62","quantity":"1.645"},{"price":"1736.63","quantity":"6.912"},{"price":"1736.64","quantity":"76.115"},{"price":"1736.65","quantity":"23.605"},{"price":"1736.66","quantity":"3.202"},{"price":"1736.67","quantity":"42.423"},{"price":"1736.68","quantity":"4.735"},{"price":"1736.69","quantity":"7.376"},{"price":"1736.70","quantity":"11.534"},{"price":"1736.71","quantity":"1.647"},{"price":"1736.72","quantity":"9.617"},{"price":"1736.73","quantity":"6.985"},{"price":"1736.74","quantity":"41.426"},{"price":"1736.75","quantity":"97.173"},{"price":"1736.76","quantity":"18.794"},{"price":"1736.79","quantity":"23.148"},{"price":"1736.80","quantity":"4.218"},{"price":"1736.81","quantity":"19.320"},{"price":"1736.82","quantity":"57.462"},{"price":"1736.83","quantity":"33.747"},{"price":"1736.84","quantity":"5.057"},{"price":"1736.86","quantity":"46.430"},{"price":"1736.87","quantity":"25.010"},{"price":"1736.88","quantity":"3.731"},{"price":"1736.89","quantity":"8.553"},{"price":"1736.90","quantity":"29.164"},{"price":"1736.91","quantity":"30.664"},{"price":"1736.92","quantity":"78.863"},{"price":"1736.93","quantity":"16.374"},{"price":"1736.94","quantity":"19.401"},{"price":"1736.95","quantity":"0.434"},{"price":"1736.96","quantity":"3.499"},{"price":"1736.97","quantity":"2.963"},{"price":"1736.98","quantity":"13.096"},{"price":"1736.99","quantity":"24.442"},{"price":"1737.00","quantity":"57.866"},{"price":"1737.02","quantity":"23.872"},{"price":"1737.03","quantity":"85.611"},{"price":"1737.04","quantity":"99.212"},{"price":"1737.06","quantity":"23.938"},{"price":"1737.07","quantity":"7.358"},{"price":"1737.08","quantity":"9.141"},{"price":"1737.09","quantity":"43.267"},{"price":"1737.12","quantity":"5.651"},{"price":"1737.13","quantity":"4.987"},{"price":"1737.16","quantity":"9.170"},{"price":"1737.17","quantity":"1.620"},{"price":"1737.18","quantity":"23.455"},{"price":"1737.19","quantity":"6.167"},{"price":"1737.20","quantity":"26.327"},{"price":"1737.22","quantity":"1.835"},{"price":"1737.23","quantity":"32.967"},{"price":"1737.24","quantity":"0.141"},{"price":"1737.25","quantity":"72.370"},{"price":"1737.26","quantity":"5.190"},{"price":"1737.27","quantity":"20.256"},{"price":"1737.30","quantity":"0.435"},{"price":"1737.33","quantity":"19.563"},{"price":"1737.35","quantity":"38.543"},{"price":"1737.36","quantity":"70.002"},{"price":"1737.38","quantity":"90.231"},{"price":"1737.40","quantity":"32.884"},{"price":"1737.44","quantity":"46.784"},{"price":"1737.45","quantity":"34.233"},{"price":"1737.50","quantity":"67.937"},{"price":"1737.51","quantity":"0.218"},{"price":"1737.53","quantity":"0.012"},{"price":"1737.55","quantity":"51.056"},{"price":"1737.56","quantity":"89.012"},{"price":"1737.57","quantity":"134.845"},{"price":"1737.58","quantity":"22.806"},{"price":"1737.59","quantity":"3.831"},{"price":"1737.62","quantity":"68.808"},{"price":"1737.68","quantity":"0.970"},{"price":"1737.72","quantity":"40.016"},{"price":"1737.74","quantity":"83.465"},{"price":"1737.75","quantity":"15.839"},{"price":"1737.76","quantity":"14.004"},{"price":"1737.77","quantity":"4.618"},{"price":"1737.78","quantity":"4.822"},{"price":"1737.81","quantity":"31.808"},{"price":"1737.83","quantity":"34.780"},{"price":"1737.84","quantity":"73.782"},{"price":"1737.87","quantity":"19.322"},{"price":"1737.89","quantity":"7.279"},{"price":"1737.95","quantity":"89.115"},{"price":"1738.00","quantity":"30.118"},{"price":"1738.01","quantity":"37.396"},{"price":"1738.04","quantity":"0.239"},{"price":"1738.05","quantity":"16.400"},{"price":"1738.09","quantity":"0.252"},{"price":"1738.16","quantity":"67.260"},{"price":"1738.33","quantity":"0.053"},{"price":"1738.34","quantity":"18.144"},{"price":"1738.39","quantity":"18.268"},{"price":"1738.45","quantity":"1.836"},{"price":"1738.46","quantity":"35.681"},{"price":"1738.53","quantity":"20.776"},{"price":"1738.54","quantity":"95.558"},{"price":"1738.56","quantity":"4.240"},{"price":"1738.57","quantity":"36.248"},{"price":"1738.65","quantity":"22.477"},{"price":"1738.68","quantity":"0.108"},{"price":"1738.70","quantity":"0.197"},{"price":"1738.71","quantity":"35.150"},{"price":"1738.72","quantity":"54.567"},{"price":"1738.74","quantity":"0.752"},{"price":"1738.78","quantity":"1.109"},{"price":"1738.79","quantity":"83.666"},{"price":"1738.80","quantity":"4.943"},{"price":"1738.82","quantity":"5.011"},{"price":"1738.85","quantity":"3.921"},{"price":"1738.86","quantity":"2.881"},{"price":"1739.09","quantity":"0.856"},{"price":"1739.30","quantity":"3.887"},{"price":"1739.38","quantity":"10.084"},{"price":"1739.41","quantity":"6.891"},{"price":"1739.42","quantity":"17.925"},{"price":"1739.62","quantity":"23.603"},{"price":"1739.64","quantity":"93.540"},{"price":"1739.70","quantity":"34.145"},{"price":"1739.76","quantity":"177.848"},{"price":"1739.94","quantity":"2.045"},{"price":"1739.98","quantity":"12.540"},{"price":"1740.06","quantity":"14.476"},{"price":"1740.08","quantity":"0.000"},{"price":"1740.09","quantity":"32.626"},{"price":"1740.23","quantity":"176.638"},{"price":"1740.24","quantity":"50.385"},{"price":"1740.30","quantity":"19.737"},{"price":"1740.60","quantity":"58.931"},{"price":"1740.62","quantity":"1.235"},{"price":"1740.69","quantity":"189.824"},{"price":"1740.78","quantity":"14.288"},{"price":"1740.80","quantity":"0.222"},{"price":"1741.14","quantity":"95.834"},{"price":"1742.44","quantity":"5.839"},{"price":"1744.86","quantity":"40.373"},{"price":"1753.53","quantity":"0.293"},{"price":"1767.53","quantity":"73.466"},{"price":"1835.77","quantity":"0.103"},{"price":"1835.78","quantity":"0.039"},{"price":"1836.13","quantity":"0.035"},{"price":"1836.14","quantity":"0.189"},{"price":"2480.19","quantity":"0.036"},{"price":"2635.01","quantity":"0.001"},{"price":"2635.02","quantity":"0.001"},{"price":"2635.10","quantity":"0.000"},{"price":"2635.11","quantity":"0.000"},{"price":"3472.27","quantity":"0.009"}],"raw":{"e":"depthUpdate","E":1783517066356,"T":1783517066355,"s":"ETHUSDT","ps":"ETHUSDT","U":10999770515262,"u":10999770540664,"pu":10999770515220,"b":[["200.00","7.594"],["1211.12","0.289"],["1216.12","0.160"],["1216.13","0.640"],["1216.27","0.532"],["1221.16","2.400"],["1562.50","1.060"],["1562.51","5.880"],["1562.52","0.000"],["1667.58","0.060"],["1693.39","0.000"],["1700.44","29.399"],["1704.88","40.317"],["1710.75","43.994"],["1724.90","43.360"],["1725.72","60.118"],["1726.10","2.608"],["1726.83","46.883"],["1727.44","0.024"],["1729.13","0.028"],["1729.35","0.310"],["1729.57","0.000"],["1730.01","21.644"],["1730.23","33.557"],["1730.26","5.916"],["1731.24","223.992"],["1731.26","4.677"],["1731.33","19.266"],["1731.40","7.047"],["1731.41","43.977"],["1731.51","1.976"],["1731.84","0.118"],["1731.91","16.420"],["1731.94","0.042"],["1731.96","108.350"],["1732.05","51.899"],["1732.10","10.440"],["1732.28","16.371"],["1732.29","0.493"],["1732.30","172.874"],["1732.31","6.708"],["1732.32","135.425"],["1732.50","54.587"],["1732.53","1.871"],["1732.63","0.876"],["1732.72","22.451"],["1732.95","24.467"],["1733.13","30.371"],["1733.23","17.236"],["1733.27","0.012"],["1733.28","67.245"],["1733.29","24.558"],["1733.30","24.381"],["1733.32","4.367"],["1733.34","0.000"],["1733.36","20.130"],["1733.39","22.071"],["1733.42","5.753"],["1733.44","10.089"],["1733.53","429.699"],["1733.54","83.739"],["1733.63","51.010"],["1733.70","16.600"],["1733.71","85.123"],["1733.74","15.812"],["1733.82","2.575"],["1733.83","0.562"],["1733.85","65.288"],["1733.86","2.091"],["1733.94","29.283"],["1733.98","0.245"],["1734.01","17.457"],["1734.04","125.012"],["1734.18","0.012"],["1734.19","5.021"],["1734.21","19.027"],["1734.22","17.049"],["1734.24","1.874"],["1734.25","0.059"],["1734.26","0.703"],["1734.27","0.449"],["1734.30","21.202"],["1734.32","231.107"],["1734.33","19.958"],["1734.35","8.782"],["1734.36","43.618"],["1734.37","0.150"],["1734.42","3.047"],["1734.43","1.184"],["1734.45","0.056"],["1734.46","51.458"],["1734.47","4.441"],["1734.48","18.044"],["1734.49","53.052"],["1734.50","9.332"],["1734.51","12.717"],["1734.52","1.949"],["1734.53","255.759"],["1734.54","17.767"],["1734.55","0.955"],["1734.57","29.333"],["1734.59","1.211"],["1734.62","119.388"],["1734.63","19.810"],["1734.65","13.647"],["1734.66","1.206"],["1734.68","8.509"],["1734.70","0.870"],["1734.73","97.067"],["1734.75","68.153"],["1734.77","84.150"],["1734.79","8.220"],["1734.81","19.072"],["1734.82","18.237"],["1734.83","8.889"],["1734.84","272.072"],["1734.86","38.717"],["1734.87","19.856"],["1734.88","59.458"],["1734.89","0.168"],["1734.90","19.409"],["1734.92","58.981"],["1734.93","63.524"],["1734.94","12.464"],["1734.99","0.689"],["1735.00","217.843"],["1735.01","44.586"],["1735.02","50.511"],["1735.03","0.065"],["1735.04","2.899"],["1735.05","1.232"],["1735.06","0.927"],["1735.08","6.025"],["1735.09","1.235"],["1735.11","44.136"],["1735.13","1.559"],["1735.15","47.601"],["1735.16","3.909"],["1735.19","70.115"],["1735.20","45.938"],["1735.21","34.467"],["1735.22","16.287"],["1735.23","5.796"],["1735.24","8.926"],["1735.25","0.769"],["1735.26","0.038"],["1735.27","70.102"],["1735.28","4.962"],["1735.32","26.988"],["1735.33","16.311"],["1735.37","0.752"],["1735.38","65.064"],["1735.39","0.541"],["1735.41","124.157"],["1735.42","20.611"],["1735.43","4.041"],["1735.44","27.461"],["1735.45","0.166"],["1735.47","17.509"],["1735.48","0.874"],["1735.49","7.056"],["1735.50","18.754"],["1735.51","58.185"],["1735.52","77.458"],["1735.53","5.205"],["1735.54","5.779"],["1735.55","4.511"],["1735.56","28.286"],["1735.57","1.802"],["1735.58","0.766"],["1735.59","4.353"],["1735.60","33.449"],["1735.61","8.709"],["1735.63","0.576"],["1735.64","76.667"],["1735.65","20.560"],["1735.66","0.157"],["1735.67","1.451"],["1735.69","4.767"],["1735.70","0.037"],["1735.72","89.558"],["1735.73","26.847"],["1735.74","27.864"],["1735.75","86.033"],["1735.76","5.511"],["1735.77","22.995"],["1735.78","21.175"],["1735.79","1.795"],["1735.80","0.242"],["1735.81","5.186"],["1735.82","14.191"],["1735.83","28.903"],["1735.84","5.090"],["1735.85","6.839"],["1735.86","1.148"],["1735.87","0.220"],["1735.88","22.221"],["1735.89","1.159"],["1735.90","3.012"],["1735.91","12.427"],["1735.92","9.714"],["1735.93","0.197"],["1735.94","3.711"],["1735.95","0.074"],["1735.96","2.280"],["1735.98","3.677"],["1735.99","0.052"],["1736.00","1.084"],["1736.01","0.038"],["1736.02","0.049"],["1736.03","0.050"],["1736.04","0.012"],["1736.05","0.051"],["1736.06","0.014"],["1736.07","0.048"],["1736.08","0.709"],["1736.09","0.669"],["1736.10","3.722"],["1736.11","0.029"],["1736.12","75.293"],["1736.13","0.000"]],"a":[["1736.13","347.586"],["1736.14","0.040"],["1736.15","0.000"],["1736.16","0.538"],["1736.17","0.024"],["1736.18","0.036"],["1736.19","0.300"],["1736.20","2.807"],["1736.21","1.740"],["1736.22","20.724"],["1736.23","3.275"],["1736.24","29.245"],["1736.25","2.800"],["1736.27","11.637"],["1736.28","44.020"],["1736.29","1.164"],["1736.30","11.736"],["1736.31","89.094"],["1736.32","0.176"],["1736.33","0.012"],["1736.34","28.865"],["1736.35","4.525"],["1736.36","0.548"],["1736.37","9.021"],["1736.38","0.256"],["1736.39","0.098"],["1736.40","18.642"],["1736.41","9.520"],["1736.42","3.358"],["1736.43","29.927"],["1736.44","9.485"],["1736.45","74.946"],["1736.46","43.794"],["1736.47","13.186"],["1736.48","7.730"],["1736.49","3.215"],["1736.50","0.090"],["1736.52","0.087"],["1736.53","1.419"],["1736.54","2.869"],["1736.55","31.365"],["1736.58","1.665"],["1736.59","8.864"],["1736.60","5.067"],["1736.62","1.645"],["1736.63","6.912"],["1736.64","76.115"],["1736.65","23.605"],["1736.66","3.202"],["1736.67","42.423"],["1736.68","4.735"],["1736.69","7.376"],["1736.70","11.534"],["1736.71","1.647"],["1736.72","9.617"],["1736.73","6.985"],["1736.74","41.426"],["1736.75","97.173"],["1736.76","18.794"],["1736.79","23.148"],["1736.80","4.218"],["1736.81","19.320"],["1736.82","57.462"],["1736.83","33.747"],["1736.84","5.057"],["1736.86","46.430"],["1736.87","25.010"],["1736.88","3.731"],["1736.89","8.553"],["1736.90","29.164"],["1736.91","30.664"],["1736.92","78.863"],["1736.93","16.374"],["1736.94","19.401"],["1736.95","0.434"],["1736.96","3.499"],["1736.97","2.963"],["1736.98","13.096"],["1736.99","24.442"],["1737.00","57.866"],["1737.02","23.872"],["1737.03","85.611"],["1737.04","99.212"],["1737.06","23.938"],["1737.07","7.358"],["1737.08","9.141"],["1737.09","43.267"],["1737.12","5.651"],["1737.13","4.987"],["1737.16","9.170"],["1737.17","1.620"],["1737.18","23.455"],["1737.19","6.167"],["1737.20","26.327"],["1737.22","1.835"],["1737.23","32.967"],["1737.24","0.141"],["1737.25","72.370"],["1737.26","5.190"],["1737.27","20.256"],["1737.30","0.435"],["1737.33","19.563"],["1737.35","38.543"],["1737.36","70.002"],["1737.38","90.231"],["1737.40","32.884"],["1737.44","46.784"],["1737.45","34.233"],["1737.50","67.937"],["1737.51","0.218"],["1737.53","0.012"],["1737.55","51.056"],["1737.56","89.012"],["1737.57","134.845"],["1737.58","22.806"],["1737.59","3.831"],["1737.62","68.808"],["1737.68","0.970"],["1737.72","40.016"],["1737.74","83.465"],["1737.75","15.839"],["1737.76","14.004"],["1737.77","4.618"],["1737.78","4.822"],["1737.81","31.808"],["1737.83","34.780"],["1737.84","73.782"],["1737.87","19.322"],["1737.89","7.279"],["1737.95","89.115"],["1738.00","30.118"],["1738.01","37.396"],["1738.04","0.239"],["1738.05","16.400"],["1738.09","0.252"],["1738.16","67.260"],["1738.33","0.053"],["1738.34","18.144"],["1738.39","18.268"],["1738.45","1.836"],["1738.46","35.681"],["1738.53","20.776"],["1738.54","95.558"],["1738.56","4.240"],["1738.57","36.248"],["1738.65","22.477"],["1738.68","0.108"],["1738.70","0.197"],["1738.71","35.150"],["1738.72","54.567"],["1738.74","0.752"],["1738.78","1.109"],["1738.79","83.666"],["1738.80","4.943"],["1738.82","5.011"],["1738.85","3.921"],["1738.86","2.881"],["1739.09","0.856"],["1739.30","3.887"],["1739.38","10.084"],["1739.41","6.891"],["1739.42","17.925"],["1739.62","23.603"],["1739.64","93.540"],["1739.70","34.145"],["1739.76","177.848"],["1739.94","2.045"],["1739.98","12.540"],["1740.06","14.476"],["1740.08","0.000"],["1740.09","32.626"],["1740.23","176.638"],["1740.24","50.385"],["1740.30","19.737"],["1740.60","58.931"],["1740.62","1.235"],["1740.69","189.824"],["1740.78","14.288"],["1740.80","0.222"],["1741.14","95.834"],["1742.44","5.839"],["1744.86","40.373"],["1753.53","0.293"],["1767.53","73.466"],["1835.77","0.103"],["1835.78","0.039"],["1836.13","0.035"],["1836.14","0.189"],["2480.19","0.036"],["2635.01","0.001"],["2635.02","0.001"],["2635.10","0.000"],["2635.11","0.000"],["3472.27","0.009"]],"st":1}}
{"schema_version":"1.3.0","event_id":"13e7dcc0-e11e-4bae-b79b-3143ebe37819","event_type":"raw.depth_update","source":"binance_market_data_recorder","venue":"binance_usdm","market_type":"perpetual_futures","symbol":"BTCUSDT","event_time_ms":1783517066394,"received_time_ms":1783517067156,"trace_id":"d616c977-5bd4-4929-9493-ed4cd6c9d1f8","first_update_id":10999770524885,"final_update_id":10999770545000,"previous_final_update_id":10999770524747,"bids":[{"price":"1000.00","quantity":"207.692"},{"price":"11353.70","quantity":"0.560"},{"price":"11452.20","quantity":"2.144"},{"price":"11553.70","quantity":"0.306"},{"price":"11652.20","quantity":"0.340"},{"price":"49482.00","quantity":"0.000"},{"price":"55668.30","quantity":"0.002"},{"price":"58759.50","quantity":"0.000"},{"price":"58761.00","quantity":"0.000"},{"price":"60931.00","quantity":"4.693"},{"price":"60955.30","quantity":"13.764"},{"price":"61110.00","quantity":"4.977"},{"price":"61171.80","quantity":"1.472"},{"price":"61235.20","quantity":"0.025"},{"price":"61293.60","quantity":"1.776"},{"price":"61537.60","quantity":"0.348"},{"price":"61542.90","quantity":"0.011"},{"price":"61584.10","quantity":"0.000"},{"price":"61584.20","quantity":"0.084"},{"price":"61598.60","quantity":"0.873"},{"price":"61606.30","quantity":"0.621"},{"price":"61769.50","quantity":"34.249"},{"price":"61770.00","quantity":"6.631"},{"price":"61771.60","quantity":"0.001"},{"price":"61788.10","quantity":"0.809"},{"price":"61788.40","quantity":"0.002"},{"price":"61789.00","quantity":"1.484"},{"price":"61792.70","quantity":"0.000"},{"price":"61799.60","quantity":"0.000"},{"price":"61804.60","quantity":"0.000"},{"price":"61807.60","quantity":"1.442"},{"price":"61807.90","quantity":"0.070"},{"price":"61808.00","quantity":"4.445"},{"price":"61808.90","quantity":"0.110"},{"price":"61809.50","quantity":"0.061"},{"price":"61810.30","quantity":"1.591"},{"price":"61813.30","quantity":"2.195"},{"price":"61817.30","quantity":"1.861"},{"price":"61817.40","quantity":"0.014"},{"price":"61820.00","quantity":"50.544"},{"price":"61820.90","quantity":"1.744"},{"price":"61821.20","quantity":"0.064"},{"price":"61821.30","quantity":"0.060"},{"price":"61823.20","quantity":"0.357"},{"price":"61823.40","quantity":"0.009"},{"price":"61823.50","quantity":"0.124"},{"price":"61823.80","quantity":"0.599"},{"price":"61825.00","quantity":"3.094"},{"price":"61825.90","quantity":"0.009"},{"price":"61826.10","quantity":"1.417"},{"price":"61826.20","quantity":"0.161"},{"price":"61827.50","quantity":"2.168"},{"price":"61827.80","quantity":"0.321"},{"price":"61828.10","quantity":"0.001"},{"price":"61828.40","quantity":"0.000"},{"price":"61829.30","quantity":"0.048"},{"price":"61829.40","quantity":"1.829"},{"price":"61829.80","quantity":"0.016"},{"price":"61830.00","quantity":"0.006"},{"price":"61830.30","quantity":"0.162"},{"price":"61830.40","quantity":"0.499"},{"price":"61830.50","quantity":"0.989"},{"price":"61831.00","quantity":"0.010"},{"price":"61831.60","quantity":"0.002"},{"price":"61832.90","quantity":"0.001"},{"price":"61833.00","quantity":"1.034"},{"price":"61833.30","quantity":"0.566"},{"price":"61833.60","quantity":"0.056"},{"price":"61833.70","quantity":"2.548"},{"price":"61834.20","quantity":"0.001"},{"price":"61834.80","quantity":"0.019"},{"price":"61835.00","quantity":"2.037"},{"price":"61835.20","quantity":"0.438"},{"price":"61835.40","quantity":"0.003"},{"price":"61835.50","quantity":"0.014"},{"price":"61835.60","quantity":"0.131"},{"price":"61835.70","quantity":"0.003"},{"price":"61836.50","quantity":"1.023"},{"price":"61836.60","quantity":"1.227"},{"price":"61836.80","quantity":"0.001"},{"price":"61837.80","quantity":"2.219"},{"price":"61837.90","quantity":"1.645"},{"price":"61838.10","quantity":"0.403"},{"price":"61838.20","quantity":"0.325"},{"price":"61838.30","quantity":"0.003"},{"price":"61838.80","quantity":"0.009"},{"price":"61839.10","quantity":"0.000"},{"price":"61839.50","quantity":"0.126"},{"price":"61840.00","quantity":"0.502"},{"price":"61840.30","quantity":"0.446"},{"price":"61840.60","quantity":"0.564"},{"price":"61841.00","quantity":"0.191"},{"price":"61841.30","quantity":"0.819"},{"price":"61841.40","quantity":"1.281"},{"price":"61841.50","quantity":"0.221"},{"price":"61841.80","quantity":"0.106"},{"price":"61841.90","quantity":"0.403"},{"price":"61842.00","quantity":"0.470"},{"price":"61842.10","quantity":"0.243"},{"price":"61842.40","quantity":"0.736"},{"price":"61842.70","quantity":"0.213"},{"price":"61842.80","quantity":"0.281"},{"price":"61842.90","quantity":"0.037"},{"price":"61843.80","quantity":"0.234"},{"price":"61844.20","quantity":"0.001"},{"price":"61844.40","quantity":"0.176"},{"price":"61844.50","quantity":"0.784"},{"price":"61844.70","quantity":"1.204"},{"price":"61844.80","quantity":"0.599"},{"price":"61845.00","quantity":"0.009"},{"price":"61845.10","quantity":"0.123"},{"price":"61846.20","quantity":"1.255"},{"price":"61846.30","quantity":"0.131"},{"price":"61847.50","quantity":"0.002"},{"price":"61847.70","quantity":"1.203"},{"price":"61847.80","quantity":"0.491"},{"price":"61848.70","quantity":"0.000"},{"price":"61848.80","quantity":"0.289"},{"price":"61849.10","quantity":"0.197"},{"price":"61849.60","quantity":"0.076"},{"price":"61850.00","quantity":"0.034"},{"price":"61850.10","quantity":"0.049"},{"price":"61850.20","quantity":"0.002"},{"price":"61851.20","quantity":"0.001"},{"price":"61851.50","quantity":"0.000"},{"price":"61852.20","quantity":"0.867"},{"price":"61853.50","quantity":"0.002"},{"price":"61853.60","quantity":"0.002"},{"price":"61853.70","quantity":"2.876"}],"asks":[{"price":"61853.80","quantity":"7.969"},{"price":"61854.30","quantity":"0.027"},{"price":"61854.60","quantity":"0.004"},{"price":"61854.70","quantity":"0.001"},{"price":"61854.80","quantity":"1.617"},{"price":"61856.70","quantity":"0.917"},{"price":"61857.30","quantity":"0.200"},{"price":"61857.80","quantity":"1.023"},{"price":"61859.50","quantity":"0.017"},{"price":"61859.80","quantity":"0.002"},{"price":"61860.30","quantity":"0.018"},{"price":"61860.50","quantity":"0.971"},{"price":"61861.00","quantity":"0.047"},{"price":"61861.30","quantity":"0.045"},{"price":"61861.60","quantity":"0.001"},{"price":"61861.70","quantity":"0.162"},{"price":"61861.80","quantity":"0.968"},{"price":"61862.10","quantity":"0.001"},{"price":"61862.50","quantity":"0.002"},{"price":"61862.60","quantity":"0.573"},{"price":"61862.70","quantity":"3.327"},{"price":"61863.00","quantity":"0.133"},{"price":"61863.40","quantity":"0.030"},{"price":"61863.90","quantity":"0.470"},{"price":"61864.10","quantity":"1.181"},{"price":"61866.90","quantity":"0.022"},{"price":"61872.80","quantity":"0.000"},{"price":"61872.90","quantity":"0.394"},{"price":"61873.40","quantity":"2.986"},{"price":"61873.80","quantity":"1.292"},{"price":"61874.20","quantity":"0.000"},{"price":"61874.90","quantity":"0.157"},{"price":"61875.10","quantity":"2.267"},{"price":"61876.90","quantity":"0.661"},{"price":"61879.70","quantity":"0.048"},{"price":"61881.10","quantity":"0.122"},{"price":"61881.40","quantity":"0.249"},{"price":"61882.20","quantity":"0.750"},{"price":"61883.90","quantity":"0.950"},{"price":"61888.20","quantity":"0.073"},{"price":"61888.30","quantity":"0.008"},{"price":"61892.50","quantity":"0.116"},{"price":"61893.40","quantity":"0.570"},{"price":"61894.00","quantity":"0.016"},{"price":"61895.00","quantity":"2.587"},{"price":"61895.20","quantity":"0.013"},{"price":"61895.30","quantity":"0.000"},{"price":"61897.40","quantity":"0.000"},{"price":"61897.80","quantity":"0.011"},{"price":"61899.10","quantity":"5.031"},{"price":"61902.60","quantity":"0.001"},{"price":"61902.80","quantity":"0.082"},{"price":"61905.00","quantity":"0.000"},{"price":"61907.60","quantity":"0.101"},{"price":"61907.90","quantity":"0.317"},{"price":"61908.70","quantity":"0.016"},{"price":"61909.00","quantity":"0.032"},{"price":"61914.40","quantity":"0.153"},{"price":"61920.80","quantity":"4.703"},{"price":"61926.40","quantity":"12.130"},{"price":"62137.80","quantity":"0.001"},{"price":"62211.60","quantity":"0.000"},{"price":"62213.10","quantity":"0.008"},{"price":"62471.30","quantity":"0.000"},{"price":"62472.30","quantity":"0.000"},{"price":"62472.90","quantity":"0.008"},{"price":"62662.70","quantity":"0.809"},{"price":"63000.00","quantity":"46.663"},{"price":"63090.80","quantity":"0.006"}],"raw":{"e":"depthUpdate","E":1783517066394,"T":1783517066393,"s":"BTCUSDT","ps":"BTCUSDT","U":10999770524885,"u":10999770545000,"pu":10999770524747,"b":[["1000.00","207.692"],["11353.70","0.560"],["11452.20","2.144"],["11553.70","0.306"],["11652.20","0.340"],["49482.00","0.000"],["55668.30","0.002"],["58759.50","0.000"],["58761.00","0.000"],["60931.00","4.693"],["60955.30","13.764"],["61110.00","4.977"],["61171.80","1.472"],["61235.20","0.025"],["61293.60","1.776"],["61537.60","0.348"],["61542.90","0.011"],["61584.10","0.000"],["61584.20","0.084"],["61598.60","0.873"],["61606.30","0.621"],["61769.50","34.249"],["61770.00","6.631"],["61771.60","0.001"],["61788.10","0.809"],["61788.40","0.002"],["61789.00","1.484"],["61792.70","0.000"],["61799.60","0.000"],["61804.60","0.000"],["61807.60","1.442"],["61807.90","0.070"],["61808.00","4.445"],["61808.90","0.110"],["61809.50","0.061"],["61810.30","1.591"],["61813.30","2.195"],["61817.30","1.861"],["61817.40","0.014"],["61820.00","50.544"],["61820.90","1.744"],["61821.20","0.064"],["61821.30","0.060"],["61823.20","0.357"],["61823.40","0.009"],["61823.50","0.124"],["61823.80","0.599"],["61825.00","3.094"],["61825.90","0.009"],["61826.10","1.417"],["61826.20","0.161"],["61827.50","2.168"],["61827.80","0.321"],["61828.10","0.001"],["61828.40","0.000"],["61829.30","0.048"],["61829.40","1.829"],["61829.80","0.016"],["61830.00","0.006"],["61830.30","0.162"],["61830.40","0.499"],["61830.50","0.989"],["61831.00","0.010"],["61831.60","0.002"],["61832.90","0.001"],["61833.00","1.034"],["61833.30","0.566"],["61833.60","0.056"],["61833.70","2.548"],["61834.20","0.001"],["61834.80","0.019"],["61835.00","2.037"],["61835.20","0.438"],["61835.40","0.003"],["61835.50","0.014"],["61835.60","0.131"],["61835.70","0.003"],["61836.50","1.023"],["61836.60","1.227"],["61836.80","0.001"],["61837.80","2.219"],["61837.90","1.645"],["61838.10","0.403"],["61838.20","0.325"],["61838.30","0.003"],["61838.80","0.009"],["61839.10","0.000"],["61839.50","0.126"],["61840.00","0.502"],["61840.30","0.446"],["61840.60","0.564"],["61841.00","0.191"],["61841.30","0.819"],["61841.40","1.281"],["61841.50","0.221"],["61841.80","0.106"],["61841.90","0.403"],["61842.00","0.470"],["61842.10","0.243"],["61842.40","0.736"],["61842.70","0.213"],["61842.80","0.281"],["61842.90","0.037"],["61843.80","0.234"],["61844.20","0.001"],["61844.40","0.176"],["61844.50","0.784"],["61844.70","1.204"],["61844.80","0.599"],["61845.00","0.009"],["61845.10","0.123"],["61846.20","1.255"],["61846.30","0.131"],["61847.50","0.002"],["61847.70","1.203"],["61847.80","0.491"],["61848.70","0.000"],["61848.80","0.289"],["61849.10","0.197"],["61849.60","0.076"],["61850.00","0.034"],["61850.10","0.049"],["61850.20","0.002"],["61851.20","0.001"],["61851.50","0.000"],["61852.20","0.867"],["61853.50","0.002"],["61853.60","0.002"],["61853.70","2.876"]],"a":[["61853.80","7.969"],["61854.30","0.027"],["61854.60","0.004"],["61854.70","0.001"],["61854.80","1.617"],["61856.70","0.917"],["61857.30","0.200"],["61857.80","1.023"],["61859.50","0.017"],["61859.80","0.002"],["61860.30","0.018"],["61860.50","0.971"],["61861.00","0.047"],["61861.30","0.045"],["61861.60","0.001"],["61861.70","0.162"],["61861.80","0.968"],["61862.10","0.001"],["61862.50","0.002"],["61862.60","0.573"],["61862.70","3.327"],["61863.00","0.133"],["61863.40","0.030"],["61863.90","0.470"],["61864.10","1.181"],["61866.90","0.022"],["61872.80","0.000"],["61872.90","0.394"],["61873.40","2.986"],["61873.80","1.292"],["61874.20","0.000"],["61874.90","0.157"],["61875.10","2.267"],["61876.90","0.661"],["61879.70","0.048"],["61881.10","0.122"],["61881.40","0.249"],["61882.20","0.750"],["61883.90","0.950"],["61888.20","0.073"],["61888.30","0.008"],["61892.50","0.116"],["61893.40","0.570"],["61894.00","0.016"],["61895.00","2.587"],["61895.20","0.013"],["61895.30","0.000"],["61897.40","0.000"],["61897.80","0.011"],["61899.10","5.031"],["61902.60","0.001"],["61902.80","0.082"],["61905.00","0.000"],["61907.60","0.101"],["61907.90","0.317"],["61908.70","0.016"],["61909.00","0.032"],["61914.40","0.153"],["61920.80","4.703"],["61926.40","12.130"],["62137.80","0.001"],["62211.60","0.000"],["62213.10","0.008"],["62471.30","0.000"],["62472.30","0.000"],["62472.90","0.008"],["62662.70","0.809"],["63000.00","46.663"],["63090.80","0.006"]],"st":1}}
{"schema_version":"1.3.0","event_id":"3783bcc1-9e07-4354-8af7-244cc6a65af2","event_type":"raw.trade","source":"binance_market_data_recorder","venue":"binance_usdm","market_type":"perpetual_futures","symbol":"BTCUSDT","event_time_ms":1783517066438,"received_time_ms":1783517067169,"trace_id":"664c837b-aed1-4e3b-bd2d-3a6fb742d751","trade_id":7881418049,"price":"61853.80","quantity":"0.009","trade_time_ms":1783517066438,"is_buyer_maker":false,"aggressor_side":"buy","raw":{"e":"trade","E":1783517066438,"T":1783517066438,"s":"BTCUSDT","t":7881418049,"p":"61853.80","q":"0.009","X":"MARKET","m":false,"st":1}}
{"schema_version":"1.3.0","event_id":"980dcaa6-38df-448d-91a0-dcc8ef203491","event_type":"raw.depth_update","source":"binance_market_data_recorder","venue":"binance_usdm","market_type":"perpetual_futures","symbol":"ETHUSDT","event_time_ms":1783517066458,"received_time_ms":1783517067172,"trace_id":"398b574a-a448-46db-bfc4-d9ecbeceea5c","first_update_id":10999770540675,"final_update_id":10999770552351,"previous_final_update_id":10999770540664,"bids":[{"price":"1211.12","quantity":"0.577"},{"price":"1216.12","quantity":"0.704"},{"price":"1216.16","quantity":"5.632"},{"price":"1216.22","quantity":"0.000"},{"price":"1216.23","quantity":"0.000"},{"price":"1216.27","quantity":"0.468"},{"price":"1221.16","quantity":"1.856"},{"price":"1562.50","quantity":"1.060"},{"price":"1562.51","quantity":"6.520"},{"price":"1666.60","quantity":"1.193"},{"price":"1701.40","quantity":"0.402"},{"price":"1702.49","quantity":"34.934"},{"price":"1702.64","quantity":"0.030"},{"price":"1703.17","quantity":"27.177"},{"price":"1708.84","quantity":"0.033"},{"price":"1711.63","quantity":"46.492"},{"price":"1721.37","quantity":"87.996"},{"price":"1729.11","quantity":"34.452"},{"price":"1729.29","quantity":"0.031"},{"price":"1731.16","quantity":"5.197"},{"price":"1731.24","quantity":"224.004"},{"price":"1733.05","quantity":"2.031"},{"price":"1733.53","quantity":"0.892"},{"price":"1733.54","quantity":"0.099"},{"price":"1733.65","quantity":"9.919"},{"price":"1733.66","quantity":"23.837"},{"price":"1733.71","quantity":"84.523"},{"price":"1733.74","quantity":"16.412"},{"price":"1733.82","quantity":"2.575"},{"price":"1733.85","quantity":"128.008"},{"price":"1733.89","quantity":"429.572"},{"price":"1734.24","quantity":"1.474"},{"price":"1734.32","quantity":"11.558"},{"price":"1734.33","quantity":"19.867"},{"price":"1734.36","quantity":"13.419"},{"price":"1734.37","quantity":"0.950"},{"price":"1734.38","quantity":"11.389"},{"price":"1734.39","quantity":"240.097"},{"price":"1734.40","quantity":"4.555"},{"price":"1734.42","quantity":"2.247"},{"price":"1734.43","quantity":"0.384"},{"price":"1734.45","quantity":"0.038"},{"price":"1734.46","quantity":"51.590"},{"price":"1734.49","quantity":"53.070"},{"price":"1734.51","quantity":"232.678"},{"price":"1734.53","quantity":"35.877"},{"price":"1734.56","quantity":"3.962"},{"price":"1734.57","quantity":"29.351"},{"price":"1734.58","quantity":"0.519"},{"price":"1734.61","quantity":"0.240"},{"price":"1734.65","quantity":"13.554"},{"price":"1734.70","quantity":"0.670"},{"price":"1734.82","quantity":"18.237"},{"price":"1734.83","quantity":"6.689"},{"price":"1734.84","quantity":"272.072"},{"price":"1734.87","quantity":"19.838"},{"price":"1734.88","quantity":"59.476"},{"price":"1735.01","quantity":"19.586"},{"price":"1735.10","quantity":"14.768"},{"price":"1735.12","quantity":"95.482"},{"price":"1735.15","quantity":"5.663"},{"price":"1735.16","quantity":"4.509"},{"price":"1735.17","quantity":"3.284"},{"price":"1735.22","quantity":"16.399"},{"price":"1735.25","quantity":"39.105"},{"price":"1735.31","quantity":"33.996"},{"price":"1735.35","quantity":"20.776"},{"price":"1735.37","quantity":"0.583"},{"price":"1735.43","quantity":"4.210"},{"price":"1735.46","quantity":"21.324"},{"price":"1735.51","quantity":"58.285"},{"price":"1735.59","quantity":"4.365"},{"price":"1735.60","quantity":"4.613"},{"price":"1735.61","quantity":"17.408"},{"price":"1735.63","quantity":"29.411"},{"price":"1735.65","quantity":"20.560"},{"price":"1735.66","quantity":"0.157"},{"price":"1735.73","quantity":"27.647"},{"price":"1735.74","quantity":"28.064"},{"price":"1735.76","quantity":"2.001"},{"price":"1735.77","quantity":"23.595"},{"price":"1735.78","quantity":"21.763"},{"price":"1735.79","quantity":"7.539"},{"price":"1735.81","quantity":"5.646"},{"price":"1735.83","quantity":"20.204"},{"price":"1735.84","quantity":"4.090"},{"price":"1735.85","quantity":"6.839"},{"price":"1735.88","quantity":"0.036"},{"price":"1735.89","quantity":"23.252"},{"price":"1735.91","quantity":"15.361"},{"price":"1735.92","quantity":"9.819"},{"price":"1735.93","quantity":"0.176"},{"price":"1735.94","quantity":"3.729"},{"price":"1735.98","quantity":"3.764"},{"price":"1736.00","quantity":"1.096"},{"price":"1736.01","quantity":"0.050"},{"price":"1736.05","quantity":"0.063"},{"price":"1736.06","quantity":"0.026"},{"price":"1736.08","quantity":"0.723"},{"price":"1736.10","quantity":"3.736"},{"price":"1736.12","quantity":"21.443"}],"asks":[{"price":"1736.13","quantity":"343.338"},{"price":"1736.14","quantity":"0.106"},{"price":"1736.16","quantity":"0.038"},{"price":"1736.20","quantity":"3.328"},{"price":"1736.22","quantity":"20.736"},{"price":"1736.23","quantity":"3.287"},{"price":"1736.25","quantity":"2.813"},{"price":"1736.26","quantity":"0.426"},{"price":"1736.28","quantity":"30.808"},{"price":"1736.30","quantity":"16.224"},{"price":"1736.31","quantity":"17.372"},{"price":"1736.32","quantity":"0.162"},{"price":"1736.33","quantity":"0.012"},{"price":"1736.34","quantity":"29.034"},{"price":"1736.35","quantity":"4.525"},{"price":"1736.42","quantity":"3.658"},{"price":"1736.43","quantity":"27.285"},{"price":"1736.44","quantity":"11.299"},{"price":"1736.45","quantity":"77.026"},{"price":"1736.46","quantity":"46.108"},{"price":"1736.47","quantity":"13.186"},{"price":"1736.48","quantity":"9.902"},{"price":"1736.59","quantity":"4.554"},{"price":"1736.63","quantity":"11.774"},{"price":"1736.74","quantity":"41.892"},{"price":"1736.87","quantity":"24.551"},{"price":"1737.05","quantity":"0.879"},{"price":"1737.09","quantity":"41.647"},{"price":"1737.13","quantity":"5.002"},{"price":"1737.14","quantity":"70.031"},{"price":"1737.17","quantity":"1.605"},{"price":"1737.20","quantity":"29.782"},{"price":"1737.25","quantity":"71.600"},{"price":"1737.34","quantity":"14.909"},{"price":"1737.36","quantity":"68.335"},{"price":"1737.37","quantity":"41.800"},{"price":"1737.43","quantity":"11.221"},{"price":"1737.73","quantity":"1.987"},{"price":"1737.74","quantity":"76.585"},{"price":"1737.79","quantity":"5.635"},{"price":"1737.81","quantity":"33.968"},{"price":"1738.17","quantity":"67.911"},{"price":"1738.26","quantity":"408.982"},{"price":"1738.43","quantity":"2.232"},{"price":"1738.45","quantity":"0.142"},{"price":"1738.46","quantity":"33.701"},{"price":"1738.50","quantity":"0.298"},{"price":"1738.53","quantity":"58.124"},{"price":"1738.54","quantity":"13.091"},{"price":"1738.55","quantity":"0.274"},{"price":"1738.62","quantity":"16.391"},{"price":"1738.64","quantity":"7.862"},{"price":"1739.42","quantity":"19.309"},{"price":"1739.94","quantity":"0.661"},{"price":"1742.45","quantity":"9.579"},{"price":"1743.49","quantity":"9.908"},{"price":"1745.03","quantity":"0.000"},{"price":"1745.15","quantity":"0.358"},{"price":"1747.10","quantity":"5.676"},{"price":"1747.11","quantity":"37.224"},{"price":"1747.12","quantity":"0.000"},{"price":"1748.16","quantity":"2.528"},{"price":"1748.28","quantity":"0.283"},{"price":"1748.42","quantity":"37.216"},{"price":"1748.43","quantity":"0.658"},{"price":"1763.19","quantity":"35.926"},{"price":"2635.00","quantity":"0.194"},{"price":"2635.09","quantity":"0.000"}],"raw":{"e":"depthUpdate","E":1783517066458,"T":1783517066457,"s":"ETHUSDT","ps":"ETHUSDT","U":10999770540675,"u":10999770552351,"pu":10999770540664,"b":[["1211.12","0.577"],["1216.12","0.704"],["1216.16","5.632"],["1216.22","0.000"],["1216.23","0.000"],["1216.27","0.468"],["1221.16","1.856"],["1562.50","1.060"],["1562.51","6.520"],["1666.60","1.193"],["1701.40","0.402"],["1702.49","34.934"],["1702.64","0.030"],["1703.17","27.177"],["1708.84","0.033"],["1711.63","46.492"],["1721.37","87.996"],["1729.11","34.452"],["1729.29","0.031"],["1731.16","5.197"],["1731.24","224.004"],["1733.05","2.031"],["1733.53","0.892"],["1733.54","0.099"],["1733.65","9.919"],["1733.66","23.837"],["1733.71","84.523"],["1733.74","16.412"],["1733.82","2.575"],["1733.85","128.008"],["1733.89","429.572"],["1734.24","1.474"],["1734.32","11.558"],["1734.33","19.867"],["1734.36","13.419"],["1734.37","0.950"],["1734.38","11.389"],["1734.39","240.097"],["1734.40","4.555"],["1734.42","2.247"],["1734.43","0.384"],["1734.45","0.038"],["1734.46","51.590"],["1734.49","53.070"],["1734.51","232.678"],["1734.53","35.877"],["1734.56","3.962"],["1734.57","29.351"],["1734.58","0.519"],["1734.61","0.240"],["1734.65","13.554"],["1734.70","0.670"],["1734.82","18.237"],["1734.83","6.689"],["1734.84","272.072"],["1734.87","19.838"],["1734.88","59.476"],["1735.01","19.586"],["1735.10","14.768"],["1735.12","95.482"],["1735.15","5.663"],["1735.16","4.509"],["1735.17","3.284"],["1735.22","16.399"],["1735.25","39.105"],["1735.31","33.996"],["1735.35","20.776"],["1735.37","0.583"],["1735.43","4.210"],["1735.46","21.324"],["1735.51","58.285"],["1735.59","4.365"],["1735.60","4.613"],["1735.61","17.408"],["1735.63","29.411"],["1735.65","20.560"],["1735.66","0.157"],["1735.73","27.647"],["1735.74","28.064"],["1735.76","2.001"],["1735.77","23.595"],["1735.78","21.763"],["1735.79","7.539"],["1735.81","5.646"],["1735.83","20.204"],["1735.84","4.090"],["1735.85","6.839"],["1735.88","0.036"],["1735.89","23.252"],["1735.91","15.361"],["1735.92","9.819"],["1735.93","0.176"],["1735.94","3.729"],["1735.98","3.764"],["1736.00","1.096"],["1736.01","0.050"],["1736.05","0.063"],["1736.06","0.026"],["1736.08","0.723"],["1736.10","3.736"],["1736.12","21.443"]],"a":[["1736.13","343.338"],["1736.14","0.106"],["1736.16","0.038"],["1736.20","3.328"],["1736.22","20.736"],["1736.23","3.287"],["1736.25","2.813"],["1736.26","0.426"],["1736.28","30.808"],["1736.30","16.224"],["1736.31","17.372"],["1736.32","0.162"],["1736.33","0.012"],["1736.34","29.034"],["1736.35","4.525"],["1736.42","3.658"],["1736.43","27.285"],["1736.44","11.299"],["1736.45","77.026"],["1736.46","46.108"],["1736.47","13.186"],["1736.48","9.902"],["1736.59","4.554"],["1736.63","11.774"],["1736.74","41.892"],["1736.87","24.551"],["1737.05","0.879"],["1737.09","41.647"],["1737.13","5.002"],["1737.14","70.031"],["1737.17","1.605"],["1737.20","29.782"],["1737.25","71.600"],["1737.34","14.909"],["1737.36","68.335"],["1737.37","41.800"],["1737.43","11.221"],["1737.73","1.987"],["1737.74","76.585"],["1737.79","5.635"],["1737.81","33.968"],["1738.17","67.911"],["1738.26","408.982"],["1738.43","2.232"],["1738.45","0.142"],["1738.46","33.701"],["1738.50","0.298"],["1738.53","58.124"],["1738.54","13.091"],["1738.55","0.274"],["1738.62","16.391"],["1738.64","7.862"],["1739.42","19.309"],["1739.94","0.661"],["1742.45","9.579"],["1743.49","9.908"],["1745.03","0.000"],["1745.15","0.358"],["1747.10","5.676"],["1747.11","37.224"],["1747.12","0.000"],["1748.16","2.528"],["1748.28","0.283"],["1748.42","37.216"],["1748.43","0.658"],["1763.19","35.926"],["2635.00","0.194"],["2635.09","0.000"]],"st":1}}
{"schema_version":"1.3.0","event_id":"d15df2f4-52c6-463e-9ab6-cfab71b5d915","event_type":"raw.depth_update","source":"binance_market_data_recorder","venue":"binance_usdm","market_type":"perpetual_futures","symbol":"BTCUSDT","event_time_ms":1783517066496,"received_time_ms":1783517067176,"trace_id":"d383be5c-6422-4e79-8131-e1953c9bc88d","first_update_id":10999770545134,"final_update_id":10999770557223,"previous_final_update_id":10999770545000,"bids":[{"price":"1000.00","quantity":"207.692"},{"price":"11353.70","quantity":"0.832"},{"price":"11452.20","quantity":"1.872"},{"price":"11553.70","quantity":"0.442"},{"price":"11652.20","quantity":"0.204"},{"price":"55668.30","quantity":"0.002"},{"price":"58761.00","quantity":"0.000"},{"price":"59379.50","quantity":"0.001"},{"price":"60765.50","quantity":"0.822"},{"price":"61107.80","quantity":"5.918"},{"price":"61235.20","quantity":"0.025"},{"price":"61397.70","quantity":"0.264"},{"price":"61520.00","quantity":"3.097"},{"price":"61600.00","quantity":"56.975"},{"price":"61680.00","quantity":"0.889"},{"price":"61740.90","quantity":"0.747"},{"price":"61760.00","quantity":"1.098"},{"price":"61762.10","quantity":"1.547"},{"price":"61762.30","quantity":"0.023"},{"price":"61769.50","quantity":"0.092"},{"price":"61770.00","quantity":"1.664"},{"price":"61782.40","quantity":"1.567"},{"price":"61782.60","quantity":"0.003"},{"price":"61784.20","quantity":"34.159"},{"price":"61785.90","quantity":"7.014"},{"price":"61786.00","quantity":"0.002"},{"price":"61792.90","quantity":"0.227"},{"price":"61796.10","quantity":"0.661"},{"price":"61802.70","quantity":"9.395"},{"price":"61802.90","quantity":"0.856"},{"price":"61807.90","quantity":"0.000"},{"price":"61810.10","quantity":"0.003"},{"price":"61813.30","quantity":"2.146"},{"price":"61814.80","quantity":"0.074"},{"price":"61820.20","quantity":"0.183"},{"price":"61822.50","quantity":"0.061"},{"price":"61831.60","quantity":"0.042"},{"price":"61833.50","quantity":"0.000"},{"price":"61833.60","quantity":"0.055"},{"price":"61834.00","quantity":"1.414"},{"price":"61837.40","quantity":"0.812"},{"price":"61837.60","quantity":"1.244"},{"price":"61837.90","quantity":"1.483"},{"price":"61838.30","quantity":"0.003"},{"price":"61838.80","quantity":"0.171"},{"price":"61840.00","quantity":"0.680"},{"price":"61841.30","quantity":"0.975"},{"price":"61842.50","quantity":"0.588"},{"price":"61844.80","quantity":"0.017"},{"price":"61844.90","quantity":"0.001"},{"price":"61846.30","quantity":"0.333"},{"price":"61847.70","quantity":"1.205"},{"price":"61849.10","quantity":"0.003"},{"price":"61849.20","quantity":"1.204"},{"price":"61849.30","quantity":"0.374"},{"price":"61850.10","quantity":"0.000"},{"price":"61850.20","quantity":"0.051"},{"price":"61852.20","quantity":"0.846"},{"price":"61853.60","quantity":"0.001"},{"price":"61853.70","quantity":"1.607"}],"asks":[{"price":"61853.80","quantity":"7.965"},{"price":"61854.40","quantity":"0.002"},{"price":"61854.50","quantity":"0.001"},{"price":"61855.10","quantity":"0.061"},{"price":"61856.10","quantity":"0.000"},{"price":"61856.60","quantity":"0.164"},{"price":"61862.50","quantity":"0.001"},{"price":"61862.60","quantity":"0.007"},{"price":"61863.90","quantity":"1.036"},{"price":"61865.70","quantity":"0.474"},{"price":"61872.00","quantity":"0.340"},{"price":"61879.20","quantity":"0.005"},{"price":"61882.20","quantity":"0.751"},{"price":"61890.90","quantity":"0.246"},{"price":"61898.20","quantity":"0.638"},{"price":"61920.00","quantity":"1.350"},{"price":"61924.50","quantity":"1.529"},{"price":"61924.70","quantity":"0.000"},{"price":"61926.30","quantity":"0.722"},{"price":"61926.40","quantity":"12.227"},{"price":"61944.90","quantity":"1.538"},{"price":"61945.00","quantity":"0.003"},{"price":"61965.20","quantity":"2.360"},{"price":"61965.40","quantity":"0.000"},{"price":"62000.00","quantity":"13.201"},{"price":"62080.00","quantity":"0.467"},{"price":"62136.50","quantity":"0.108"},{"price":"62160.00","quantity":"0.462"},{"price":"62240.00","quantity":"0.457"},{"price":"62450.00","quantity":"3.927"},{"price":"62472.30","quantity":"0.000"},{"price":"62530.80","quantity":"0.720"},{"price":"62565.10","quantity":"0.476"},{"price":"62565.70","quantity":"1.898"},{"price":"63090.80","quantity":"0.009"},{"price":"89523.20","quantity":"0.714"}],"raw":{"e":"depthUpdate","E":1783517066496,"T":1783517066494,"s":"BTCUSDT","ps":"BTCUSDT","U":10999770545134,"u":10999770557223,"pu":10999770545000,"b":[["1000.00","207.692"],["11353.70","0.832"],["11452.20","1.872"],["11553.70","0.442"],["11652.20","0.204"],["55668.30","0.002"],["58761.00","0.000"],["59379.50","0.001"],["60765.50","0.822"],["61107.80","5.918"],["61235.20","0.025"],["61397.70","0.264"],["61520.00","3.097"],["61600.00","56.975"],["61680.00","0.889"],["61740.90","0.747"],["61760.00","1.098"],["61762.10","1.547"],["61762.30","0.023"],["61769.50","0.092"],["61770.00","1.664"],["61782.40","1.567"],["61782.60","0.003"],["61784.20","34.159"],["61785.90","7.014"],["61786.00","0.002"],["61792.90","0.227"],["61796.10","0.661"],["61802.70","9.395"],["61802.90","0.856"],["61807.90","0.000"],["61810.10","0.003"],["61813.30","2.146"],["61814.80","0.074"],["61820.20","0.183"],["61822.50","0.061"],["61831.60","0.042"],["61833.50","0.000"],["61833.60","0.055"],["61834.00","1.414"],["61837.40","0.812"],["61837.60","1.244"],["61837.90","1.483"],["61838.30","0.003"],["61838.80","0.171"],["61840.00","0.680"],["61841.30","0.975"],["61842.50","0.588"],["61844.80","0.017"],["61844.90","0.001"],["61846.30","0.333"],["61847.70","1.205"],["61849.10","0.003"],["61849.20","1.204"],["61849.30","0.374"],["61850.10","0.000"],["61850.20","0.051"],["61852.20","0.846"],["61853.60","0.001"],["61853.70","1.607"]],"a":[["61853.80","7.965"],["61854.40","0.002"],["61854.50","0.001"],["61855.10","0.061"],["61856.10","0.000"],["61856.60","0.164"],["61862.50","0.001"],["61862.60","0.007"],["61863.90","1.036"],["61865.70","0.474"],["61872.00","0.340"],["61879.20","0.005"],["61882.20","0.751"],["61890.90","0.246"],["61898.20","0.638"],["61920.00","1.350"],["61924.50","1.529"],["61924.70","0.000"],["61926.30","0.722"],["61926.40","12.227"],["61944.90","1.538"],["61945.00","0.003"],["61965.20","2.360"],["61965.40","0.000"],["62000.00","13.201"],["62080.00","0.467"],["62136.50","0.108"],["62160.00","0.462"],["62240.00","0.457"],["62450.00","3.927"],["62472.30","0.000"],["62530.80","0.720"],["62565.10","0.476"],["62565.70","1.898"],["63090.80","0.009"],["89523.20","0.714"]],"st":1}}
{"schema_version":"1.3.0","event_id":"e26188d8-3fc0-4650-b694-f0f090bb8dfb","event_type":"raw.depth_update","source":"binance_market_data_recorder","venue":"binance_usdm","market_type":"perpetual_futures","symbol":"ETHUSDT","event_time_ms":1783517066560,"received_time_ms":1783517067190,"trace_id":"33359fa0-ae72-4809-9445-87f28f915f8d","first_update_id":10999770552523,"final_update_id":10999770563387,"previous_final_update_id":10999770552351,"bids":[{"price":"200.00","quantity":"7.594"},{"price":"201.00","quantity":"2.300"},{"price":"1211.12","quantity":"1.121"},{"price":"1216.12","quantity":"0.960"},{"price":"1216.16","quantity":"5.280"},{"price":"1216.27","quantity":"0.276"},{"price":"1221.16","quantity":"1.600"},{"price":"1562.50","quantity":"1.060"},{"price":"1562.51","quantity":"7.032"},{"price":"1666.60","quantity":"1.078"},{"price":"1693.59","quantity":"187.007"},{"price":"1701.40","quantity":"0.373"},{"price":"1725.00","quantity":"1296.499"},{"price":"1725.03","quantity":"0.058"},{"price":"1727.26","quantity":"0.804"},{"price":"1727.29","quantity":"0.031"},{"price":"1732.60","quantity":"0.448"},{"price":"1733.05","quantity":"1.431"},{"price":"1733.43","quantity":"0.377"},{"price":"1733.52","quantity":"35.883"},{"price":"1733.61","quantity":"17.538"},{"price":"1733.71","quantity":"84.523"},{"price":"1733.72","quantity":"0.169"},{"price":"1733.73","quantity":"43.339"},{"price":"1733.74","quantity":"15.812"},{"price":"1733.85","quantity":"65.288"},{"price":"1733.89","quantity":"429.572"},{"price":"1733.94","quantity":"90.517"},{"price":"1734.24","quantity":"1.565"},{"price":"1734.37","quantity":"0.150"},{"price":"1734.38","quantity":"10.789"},{"price":"1734.39","quantity":"19.545"},{"price":"1734.40","quantity":"3.064"},{"price":"1734.41","quantity":"80.333"},{"price":"1734.42","quantity":"0.847"},{"price":"1734.46","quantity":"25.640"},{"price":"1734.51","quantity":"12.717"},{"price":"1734.55","quantity":"0.155"},{"price":"1734.56","quantity":"4.362"},{"price":"1734.57","quantity":"52.200"},{"price":"1734.59","quantity":"0.411"},{"price":"1734.61","quantity":"220.204"},{"price":"1734.63","quantity":"50.178"},{"price":"1734.81","quantity":"18.272"},{"price":"1734.86","quantity":"39.120"},{"price":"1735.03","quantity":"0.237"},{"price":"1735.04","quantity":"2.099"},{"price":"1735.05","quantity":"0.432"},{"price":"1735.06","quantity":"0.127"},{"price":"1735.07","quantity":"5.145"},{"price":"1735.08","quantity":"5.225"},{"price":"1735.09","quantity":"0.635"},{"price":"1735.10","quantity":"12.368"},{"price":"1735.11","quantity":"43.336"},{"price":"1735.12","quantity":"94.697"},{"price":"1735.13","quantity":"1.544"},{"price":"1735.16","quantity":"3.909"},{"price":"1735.23","quantity":"4.996"},{"price":"1735.24","quantity":"7.526"},{"price":"1735.27","quantity":"68.102"},{"price":"1735.46","quantity":"21.336"},{"price":"1735.57","quantity":"1.884"},{"price":"1735.67","quantity":"0.051"},{"price":"1735.72","quantity":"88.758"},{"price":"1735.73","quantity":"26.047"},{"price":"1735.74","quantity":"28.064"},{"price":"1735.75","quantity":"85.233"},{"price":"1735.76","quantity":"1.201"},{"price":"1735.77","quantity":"22.995"},{"price":"1735.78","quantity":"21.163"},{"price":"1735.83","quantity":"28.853"},{"price":"1735.89","quantity":"23.170"},{"price":"1736.02","quantity":"0.061"},{"price":"1736.03","quantity":"0.062"},{"price":"1736.04","quantity":"0.024"},{"price":"1736.11","quantity":"0.735"},{"price":"1736.12","quantity":"21.608"}],"asks":[{"price":"1736.13","quantity":"333.235"},{"price":"1736.24","quantity":"29.257"},{"price":"1736.25","quantity":"2.825"},{"price":"1736.26","quantity":"0.438"},{"price":"1736.27","quantity":"11.649"},{"price":"1736.29","quantity":"1.186"},{"price":"1736.34","quantity":"28.865"},{"price":"1736.41","quantity":"0.080"},{"price":"1736.42","quantity":"0.538"},{"price":"1736.43","quantity":"25.065"},{"price":"1736.44","quantity":"7.259"},{"price":"1736.45","quantity":"72.966"},{"price":"1736.46","quantity":"46.108"},{"price":"1736.48","quantity":"5.662"},{"price":"1736.55","quantity":"31.534"},{"price":"1736.56","quantity":"9.082"},{"price":"1736.59","quantity":"1.834"},{"price":"1736.63","quantity":"10.154"},{"price":"1736.64","quantity":"76.197"},{"price":"1737.03","quantity":"85.783"},{"price":"1737.05","quantity":"0.797"},{"price":"1737.06","quantity":"21.378"},{"price":"1737.07","quantity":"0.478"},{"price":"1737.08","quantity":"3.801"},{"price":"1737.09","quantity":"36.527"},{"price":"1737.10","quantity":"6.051"},{"price":"1737.11","quantity":"16.916"},{"price":"1737.12","quantity":"1.611"},{"price":"1737.13","quantity":"0.842"},{"price":"1737.14","quantity":"67.871"},{"price":"1737.36","quantity":"69.335"},{"price":"1737.38","quantity":"87.911"},{"price":"1737.56","quantity":"88.012"},{"price":"1737.74","quantity":"71.305"},{"price":"1737.76","quantity":"8.664"},{"price":"1737.77","quantity":"0.758"},{"price":"1737.78","quantity":"3.022"},{"price":"1737.79","quantity":"0.015"},{"price":"1737.80","quantity":"1.344"},{"price":"1737.81","quantity":"29.728"},{"price":"1737.99","quantity":"0.425"},{"price":"1738.30","quantity":"24.606"},{"price":"1738.43","quantity":"0.012"},{"price":"1738.44","quantity":"1.090"},{"price":"1738.47","quantity":"91.217"},{"price":"1738.53","quantity":"46.293"},{"price":"1738.58","quantity":"87.179"},{"price":"1738.61","quantity":"0.290"},{"price":"1738.62","quantity":"16.391"},{"price":"1739.30","quantity":"5.271"},{"price":"1739.42","quantity":"17.925"},{"price":"1739.74","quantity":"0.448"},{"price":"1742.04","quantity":"30.634"},{"price":"1742.52","quantity":"6.764"},{"price":"1758.85","quantity":"30.476"},{"price":"2634.98","quantity":"0.001"},{"price":"2634.99","quantity":"0.001"},{"price":"2635.07","quantity":"0.000"},{"price":"2635.08","quantity":"0.000"}],"raw":{"e":"depthUpdate","E":1783517066560,"T":1783517066559,"s":"ETHUSDT","ps":"ETHUSDT","U":10999770552523,"u":10999770563387,"pu":10999770552351,"b":[["200.00","7.594"],["201.00","2.300"],["1211.12","1.121"],["1216.12","0.960"],["1216.16","5.280"],["1216.27","0.276"],["1221.16","1.600"],["1562.50","1.060"],["1562.51","7.032"],["1666.60","1.078"],["1693.59","187.007"],["1701.40","0.373"],["1725.00","1296.499"],["1725.03","0.058"],["1727.26","0.804"],["1727.29","0.031"],["1732.60","0.448"],["1733.05","1.431"],["1733.43","0.377"],["1733.52","35.883"],["1733.61","17.538"],["1733.71","84.523"],["1733.72","0.169"],["1733.73","43.339"],["1733.74","15.812"],["1733.85","65.288"],["1733.89","429.572"],["1733.94","90.517"],["1734.24","1.565"],["1734.37","0.150"],["1734.38","10.789"],["1734.39","19.545"],["1734.40","3.064"],["1734.41","80.333"],["1734.42","0.847"],["1734.46","25.640"],["1734.51","12.717"],["1734.55","0.155"],["1734.56","4.362"],["1734.57","52.200"],["1734.59","0.411"],["1734.61","220.204"],["1734.63","50.178"],["1734.81","18.272"],["1734.86","39.120"],["1735.03","0.237"],["1735.04","2.099"],["1735.05","0.432"],["1735.06","0.127"],["1735.07","5.145"],["1735.08","5.225"],["1735.09","0.635"],["1735.10","12.368"],["1735.11","43.336"],["1735.12","94.697"],["1735.13","1.544"],["1735.16","3.909"],["1735.23","4.996"],["1735.24","7.526"],["1735.27","68.102"],["1735.46","21.336"],["1735.57","1.884"],["1735.67","0.051"],["1735.72","88.758"],["1735.73","26.047"],["1735.74","28.064"],["1735.75","85.233"],["1735.76","1.201"],["1735.77","22.995"],["1735.78","21.163"],["1735.83","28.853"],["1735.89","23.170"],["1736.02","0.061"],["1736.03","0.062"],["1736.04","0.024"],["1736.11","0.735"],["1736.12","21.608"]],"a":[["1736.13","333.235"],["1736.24","29.257"],["1736.25","2.825"],["1736.26","0.438"],["1736.27","11.649"],["1736.29","1.186"],["1736.34","28.865"],["1736.41","0.080"],["1736.42","0.538"],["1736.43","25.065"],["1736.44","7.259"],["1736.45","72.966"],["1736.46","46.108"],["1736.48","5.662"],["1736.55","31.534"],["1736.56","9.082"],["1736.59","1.834"],["1736.63","10.154"],["1736.64","76.197"],["1737.03","85.783"],["1737.05","0.797"],["1737.06","21.378"],["1737.07","0.478"],["1737.08","3.801"],["1737.09","36.527"],["1737.10","6.051"],["1737.11","16.916"],["1737.12","1.611"],["1737.13","0.842"],["1737.14","67.871"],["1737.36","69.335"],["1737.38","87.911"],["1737.56","88.012"],["1737.74","71.305"],["1737.76","8.664"],["1737.77","0.758"],["1737.78","3.022"],["1737.79","0.015"],["1737.80","1.344"],["1737.81","29.728"],["1737.99","0.425"],["1738.30","24.606"],["1738.43","0.012"],["1738.44","1.090"],["1738.47","91.217"],["1738.53","46.293"],["1738.58","87.179"],["1738.61","0.290"],["1738.62","16.391"],["1739.30","5.271"],["1739.42","17.925"],["1739.74","0.448"],["1742.04","30.634"],["1742.52","6.764"],["1758.85","30.476"],["2634.98","0.001"],["2634.99","0.001"],["2635.07","0.000"],["2635.08","0.000"]],"st":1}}
{"schema_version":"1.3.0","event_id":"f963601d-5a04-4f30-9572-f62eeb05e3d8","event_type":"raw.trade","source":"binance_market_data_recorder","venue":"binance_usdm","market_type":"perpetual_futures","symbol":"ETHUSDT","event_time_ms":1783517066564,"received_time_ms":1783517067192,"trace_id":"18147433-9aeb-4ac0-87f9-7d1ccd8da03b","trade_id":8429826849,"price":"1736.12","quantity":"0.060","trade_time_ms":1783517066564,"is_buyer_maker":true,"aggressor_side":"sell","raw":{"e":"trade","E":1783517066564,"T":1783517066564,"s":"ETHUSDT","t":8429826849,"p":"1736.12","q":"0.060","X":"MARKET","m":true,"st":1}}
{"schema_version":"1.3.0","event_id":"8d31d601-1afc-4e22-aa39-73c9902de437","event_type":"raw.trade","source":"binance_market_data_recorder","venue":"binance_usdm","market_type":"perpetual_futures","symbol":"ETHUSDT","event_time_ms":1783517066564,"received_time_ms":1783517067193,"trace_id":"b7872315-7a37-4482-83e5-e781e9e91e86","trade_id":8429826850,"price":"1736.12","quantity":"0.345","trade_time_ms":1783517066564,"is_buyer_maker":true,"aggressor_side":"sell","raw":{"e":"trade","E":1783517066564,"T":1783517066564,"s":"ETHUSDT","t":8429826850,"p":"1736.12","q":"0.345","X":"MARKET","m":true,"st":1}}
{"schema_version":"1.3.0","event_id":"ca0ab5ee-8524-4e92-a993-b8d7f0221bec","event_type":"raw.depth_update","source":"binance_market_data_recorder","venue":"binance_usdm","market_type":"perpetual_futures","symbol":"BTCUSDT","event_time_ms":1783517066598,"received_time_ms":1783517067206,"trace_id":"ea907a22-c7fa-4d9e-ad16-e0c053fed3a8","first_update_id":10999770557565,"final_update_id":10999770567076,"previous_final_update_id":10999770557223,"bids":[{"price":"11353.70","quantity":"1.104"},{"price":"11452.20","quantity":"1.600"},{"price":"11553.70","quantity":"0.595"},{"price":"11652.20","quantity":"0.051"},{"price":"55668.30","quantity":"0.002"},{"price":"58623.90","quantity":"0.002"},{"price":"58761.00","quantity":"0.000"},{"price":"59379.50","quantity":"0.004"},{"price":"61110.00","quantity":"5.794"},{"price":"61222.70","quantity":"0.000"},{"price":"61235.20","quantity":"0.025"},{"price":"61283.40","quantity":"0.000"},{"price":"61360.00","quantity":"2.308"},{"price":"61671.50","quantity":"0.002"},{"price":"61775.80","quantity":"36.292"},{"price":"61776.80","quantity":"7.528"},{"price":"61784.00","quantity":"1.582"},{"price":"61784.20","quantity":"0.002"},{"price":"61784.60","quantity":"0.002"},{"price":"61784.80","quantity":"0.000"},{"price":"61785.10","quantity":"0.001"},{"price":"61785.40","quantity":"0.000"},{"price":"61785.60","quantity":"0.009"},{"price":"61785.90","quantity":"0.223"},{"price":"61786.30","quantity":"0.002"},{"price":"61789.00","quantity":"1.484"},{"price":"61791.80","quantity":"0.045"},{"price":"61803.90","quantity":"0.166"},{"price":"61804.20","quantity":"2.864"},{"price":"61804.50","quantity":"0.087"},{"price":"61804.80","quantity":"0.003"},{"price":"61805.00","quantity":"6.582"},{"price":"61805.30","quantity":"1.345"},{"price":"61814.20","quantity":"0.176"},{"price":"61818.80","quantity":"0.276"},{"price":"61818.90","quantity":"0.000"},{"price":"61819.00","quantity":"0.974"},{"price":"61819.10","quantity":"0.000"},{"price":"61819.40","quantity":"0.040"},{"price":"61819.50","quantity":"0.002"},{"price":"61820.00","quantity":"50.424"},{"price":"61821.10","quantity":"0.247"},{"price":"61821.50","quantity":"0.274"},{"price":"61821.70","quantity":"1.208"},{"price":"61823.30","quantity":"2.021"},{"price":"61825.00","quantity":"3.174"},{"price":"61826.60","quantity":"0.113"},{"price":"61828.90","quantity":"1.061"},{"price":"61830.40","quantity":"0.419"},{"price":"61832.70","quantity":"0.009"},{"price":"61833.30","quantity":"0.000"},{"price":"61835.20","quantity":"1.004"},{"price":"61840.60","quantity":"0.566"},{"price":"61840.80","quantity":"0.160"},{"price":"61842.10","quantity":"0.003"},{"price":"61842.20","quantity":"0.001"},{"price":"61842.30","quantity":"0.000"},{"price":"61842.40","quantity":"0.616"},{"price":"61842.70","quantity":"0.001"},{"price":"61842.80","quantity":"0.101"},{"price":"61843.00","quantity":"0.001"},{"price":"61843.30","quantity":"0.013"},{"price":"61843.50","quantity":"0.002"},{"price":"61843.80","quantity":"0.262"},{"price":"61844.00","quantity":"0.032"},{"price":"61844.40","quantity":"0.236"},{"price":"61847.20","quantity":"0.007"},{"price":"61847.80","quantity":"0.491"},{"price":"61847.90","quantity":"0.004"},{"price":"61850.00","quantity":"0.358"},{"price":"61850.60","quantity":"0.000"},{"price":"61851.80","quantity":"0.049"},{"price":"61852.20","quantity":"0.823"},{"price":"61853.20","quantity":"0.003"},{"price":"61853.40","quantity":"0.004"},{"price":"61853.60","quantity":"0.002"},{"price":"61853.70","quantity":"1.627"}],"asks":[{"price":"61853.90","quantity":"0.006"},{"price":"61856.60","quantity":"0.001"},{"price":"61856.70","quantity":"0.012"},{"price":"61857.00","quantity":"0.713"},{"price":"61857.30","quantity":"0.002"},{"price":"61857.40","quantity":"1.005"},{"price":"61857.70","quantity":"0.007"},{"price":"61857.80","quantity":"0.578"},{"price":"61857.90","quantity":"0.162"},{"price":"61858.00","quantity":"0.011"},{"price":"61858.20","quantity":"0.128"},{"price":"61858.30","quantity":"0.011"},{"price":"61858.50","quantity":"0.004"},{"price":"61858.60","quantity":"0.001"},{"price":"61858.70","quantity":"0.001"},{"price":"61859.60","quantity":"0.563"},{"price":"61860.30","quantity":"0.216"},{"price":"61860.60","quantity":"0.230"},{"price":"61861.00","quantity":"0.185"},{"price":"61861.80","quantity":"0.000"},{"price":"61862.30","quantity":"0.907"},{"price":"61862.50","quantity":"0.969"},{"price":"61862.70","quantity":"2.745"},{"price":"61864.00","quantity":"2.735"},{"price":"61865.80","quantity":"0.000"},{"price":"61876.00","quantity":"0.125"},{"price":"61876.40","quantity":"0.944"},{"price":"61876.70","quantity":"0.048"},{"price":"61877.00","quantity":"0.050"},{"price":"61877.30","quantity":"0.229"},{"price":"61877.40","quantity":"0.003"},{"price":"61878.50","quantity":"0.624"},{"price":"61880.00","quantity":"0.119"},{"price":"61880.60","quantity":"0.210"},{"price":"61880.70","quantity":"0.074"},{"price":"61881.20","quantity":"0.122"},{"price":"61881.30","quantity":"0.681"},{"price":"61881.60","quantity":"0.003"},{"price":"61881.80","quantity":"0.027"},{"price":"61881.90","quantity":"0.035"},{"price":"61883.20","quantity":"0.007"},{"price":"61883.30","quantity":"0.002"},{"price":"61883.60","quantity":"0.308"},{"price":"61883.70","quantity":"0.004"},{"price":"61884.30","quantity":"0.139"},{"price":"61884.40","quantity":"0.005"},{"price":"61888.80","quantity":"0.115"},{"price":"61893.30","quantity":"0.307"},{"price":"61893.50","quantity":"0.388"},{"price":"61895.40","quantity":"0.096"},{"price":"61895.70","quantity":"0.030"},{"price":"61895.80","quantity":"0.030"},{"price":"61896.10","quantity":"0.001"},{"price":"61896.40","quantity":"0.946"},{"price":"61896.80","quantity":"0.449"},{"price":"61908.30","quantity":"0.127"},{"price":"61909.00","quantity":"0.133"},{"price":"61913.50","quantity":"5.754"},{"price":"61915.70","quantity":"0.294"},{"price":"61916.30","quantity":"25.272"},{"price":"61916.40","quantity":"3.237"},{"price":"61918.40","quantity":"0.000"},{"price":"62061.80","quantity":"0.824"},{"price":"62086.80","quantity":"0.359"},{"price":"62086.90","quantity":"1.121"},{"price":"62087.50","quantity":"0.000"},{"price":"62472.30","quantity":"0.000"},{"price":"62569.90","quantity":"1.916"},{"price":"62596.00","quantity":"0.971"},{"price":"62657.90","quantity":"0.319"},{"price":"62732.60","quantity":"0.005"}],"raw":{"e":"depthUpdate","E":1783517066598,"T":1783517066597,"s":"BTCUSDT","ps":"BTCUSDT","U":10999770557565,"u":10999770567076,"pu":10999770557223,"b":[["11353.70","1.104"],["11452.20","1.600"],["11553.70","0.595"],["11652.20","0.051"],["55668.30","0.002"],["58623.90","0.002"],["58761.00","0.000"],["59379.50","0.004"],["61110.00","5.794"],["61222.70","0.000"],["61235.20","0.025"],["61283.40","0.000"],["61360.00","2.308"],["61671.50","0.002"],["61775.80","36.292"],["61776.80","7.528"],["61784.00","1.582"],["61784.20","0.002"],["61784.60","0.002"],["61784.80","0.000"],["61785.10","0.001"],["61785.40","0.000"],["61785.60","0.009"],["61785.90","0.223"],["61786.30","0.002"],["61789.00","1.484"],["61791.80","0.045"],["61803.90","0.166"],["61804.20","2.864"],["61804.50","0.087"],["61804.80","0.003"],["61805.00","6.582"],["61805.30","1.345"],["61814.20","0.176"],["61818.80","0.276"],["61818.90","0.000"],["61819.00","0.974"],["61819.10","0.000"],["61819.40","0.040"],["61819.50","0.002"],["61820.00","50.424"],["61821.10","0.247"],["61821.50","0.274"],["61821.70","1.208"],["61823.30","2.021"],["61825.00","3.174"],["61826.60","0.113"],["61828.90","1.061"],["61830.40","0.419"],["61832.70","0.009"],["61833.30","0.000"],["61835.20","1.004"],["61840.60","0.566"],["61840.80","0.160"],["61842.10","0.003"],["61842.20","0.001"],["61842.30","0.000"],["61842.40","0.616"],["61842.70","0.001"],["61842.80","0.101"],["61843.00","0.001"],["61843.30","0.013"],["61843.50","0.002"],["61843.80","0.262"],["61844.00","0.032"],["61844.40","0.236"],["61847.20","0.007"],["61847.80","0.491"],["61847.90","0.004"],["61850.00","0.358"],["61850.60","0.000"],["61851.80","0.049"],["61852.20","0.823"],["61853.20","0.003"],["61853.40","0.004"],["61853.60","0.002"],["61853.70","1.627"]],"a":[["61853.90","0.006"],["61856.60","0.001"],["61856.70","0.012"],["61857.00","0.713"],["61857.30","0.002"],["61857.40","1.005"],["61857.70","0.007"],["61857.80","0.578"],["61857.90","0.162"],["61858.00","0.011"],["61858.20","0.128"],["61858.30","0.011"],["61858.50","0.004"],["61858.60","0.001"],["61858.70","0.001"],["61859.60","0.563"],["61860.30","0.216"],["61860.60","0.230"],["61861.00","0.185"],["61861.80","0.000"],["61862.30","0.907"],["61862.50","0.969"],["61862.70","2.745"],["61864.00","2.735"],["61865.80","0.000"],["61876.00","0.125"],["61876.40","0.944"],["61876.70","0.048"],["61877.00","0.050"],["61877.30","0.229"],["61877.40","0.003"],["61878.50","0.624"],["61880.00","0.119"],["61880.60","0.210"],["61880.70","0.074"],["61881.20","0.122"],["61881.30","0.681"],["61881.60","0.003"],["61881.80","0.027"],["61881.90","0.035"],["61883.20","0.007"],["61883.30","0.002"],["61883.60","0.308"],["61883.70","0.004"],["61884.30","0.139"],["61884.40","0.005"],["61888.80","0.115"],["61893.30","0.307"],["61893.50","0.388"],["61895.40","0.096"],["61895.70","0.030"],["61895.80","0.030"],["61896.10","0.001"],["61896.40","0.946"],["61896.80","0.449"],["61908.30","0.127"],["61909.00","0.133"],["61913.50","5.754"],["61915.70","0.294"],["61916.30","25.272"],["61916.40","3.237"],["61918.40","0.000"],["62061.80","0.824"],["62086.80","0.359"],["62086.90","1.121"],["62087.50","0.000"],["62472.30","0.000"],["62569.90","1.916"],["62596.00","0.971"],["62657.90","0.319"],["62732.60","0.005"]],"st":1}}
{"schema_version":"1.3.0","event_id":"da6aa1bc-03d7-474a-a04c-5bc8ffaa9546","event_type":"raw.depth_update","source":"binance_market_data_recorder","venue":"binance_usdm","market_type":"perpetual_futures","symbol":"ETHUSDT","event_time_ms":1783517066662,"received_time_ms":1783517067228,"trace_id":"fa2d1382-fc4f-45f6-91c4-22b2ce4bb084","first_update_id":10999770563541,"final_update_id":10999770572595,"previous_final_update_id":10999770563387,"bids":[{"price":"200.00","quantity":"7.594"},{"price":"1211.12","quantity":"1.665"},{"price":"1216.12","quantity":"1.248"},{"price":"1216.16","quantity":"4.736"},{"price":"1221.16","quantity":"1.312"},{"price":"1562.50","quantity":"1.060"},{"price":"1562.51","quantity":"7.686"},{"price":"1666.02","quantity":"29.999"},{"price":"1666.60","quantity":"1.193"},{"price":"1701.39","quantity":"32.216"},{"price":"1709.51","quantity":"39.542"},{"price":"1710.22","quantity":"31.807"},{"price":"1729.82","quantity":"0.000"},{"price":"1730.01","quantity":"4.410"},{"price":"1730.23","quantity":"16.323"},{"price":"1730.44","quantity":"4.322"},{"price":"1731.25","quantity":"14.145"},{"price":"1731.51","quantity":"1.964"},{"price":"1731.98","quantity":"173.156"},{"price":"1732.52","quantity":"0.000"},{"price":"1732.53","quantity":"19.105"},{"price":"1732.75","quantity":"145.605"},{"price":"1733.53","quantity":"0.892"},{"price":"1733.65","quantity":"429.945"},{"price":"1733.66","quantity":"82.631"},{"price":"1733.70","quantity":"16.350"},{"price":"1733.85","quantity":"88.400"},{"price":"1733.89","quantity":"0.765"},{"price":"1733.94","quantity":"29.283"},{"price":"1734.40","quantity":"3.664"},{"price":"1734.44","quantity":"55.636"},{"price":"1734.45","quantity":"1.951"},{"price":"1734.46","quantity":"26.596"},{"price":"1734.52","quantity":"0.039"},{"price":"1734.53","quantity":"34.922"},{"price":"1734.56","quantity":"3.962"},{"price":"1734.57","quantity":"29.333"},{"price":"1734.58","quantity":"25.519"},{"price":"1734.61","quantity":"0.258"},{"price":"1734.63","quantity":"19.810"},{"price":"1734.84","quantity":"272.072"},{"price":"1734.85","quantity":"1.504"},{"price":"1734.88","quantity":"59.458"},{"price":"1734.90","quantity":"19.427"},{"price":"1734.93","quantity":"71.602"},{"price":"1734.96","quantity":"5.239"},{"price":"1735.02","quantity":"53.535"},{"price":"1735.06","quantity":"0.127"},{"price":"1735.09","quantity":"0.435"},{"price":"1735.10","quantity":"12.275"},{"price":"1735.11","quantity":"43.336"},{"price":"1735.13","quantity":"1.544"},{"price":"1735.22","quantity":"236.367"},{"price":"1735.27","quantity":"68.101"},{"price":"1735.28","quantity":"4.962"},{"price":"1735.31","quantity":"34.596"},{"price":"1735.33","quantity":"16.517"},{"price":"1735.38","quantity":"285.061"},{"price":"1735.42","quantity":"20.623"},{"price":"1735.43","quantity":"4.053"},{"price":"1735.44","quantity":"67.218"},{"price":"1735.45","quantity":"0.178"},{"price":"1735.46","quantity":"19.608"},{"price":"1735.47","quantity":"16.709"},{"price":"1735.49","quantity":"5.329"},{"price":"1735.54","quantity":"0.012"},{"price":"1735.55","quantity":"4.604"},{"price":"1735.56","quantity":"28.455"},{"price":"1735.57","quantity":"1.802"},{"price":"1735.58","quantity":"0.094"},{"price":"1735.59","quantity":"4.353"},{"price":"1735.63","quantity":"0.576"},{"price":"1735.65","quantity":"20.560"},{"price":"1735.66","quantity":"5.924"},{"price":"1735.68","quantity":"15.170"},{"price":"1735.69","quantity":"24.767"},{"price":"1735.70","quantity":"28.871"},{"price":"1735.72","quantity":"89.558"},{"price":"1735.74","quantity":"28.664"},{"price":"1735.75","quantity":"70.644"},{"price":"1735.76","quantity":"9.144"},{"price":"1735.77","quantity":"23.795"},{"price":"1735.78","quantity":"19.300"},{"price":"1735.79","quantity":"16.959"},{"price":"1735.80","quantity":"0.130"},{"price":"1735.81","quantity":"5.358"},{"price":"1735.82","quantity":"14.215"},{"price":"1735.83","quantity":"21.004"},{"price":"1735.84","quantity":"0.058"},{"price":"1735.85","quantity":"2.933"},{"price":"1735.86","quantity":"68.508"},{"price":"1735.87","quantity":"24.344"},{"price":"1735.89","quantity":"0.986"},{"price":"1735.90","quantity":"4.012"},{"price":"1735.91","quantity":"10.233"},{"price":"1735.92","quantity":"33.465"},{"price":"1735.93","quantity":"5.088"},{"price":"1735.94","quantity":"3.929"},{"price":"1735.95","quantity":"1.226"},{"price":"1735.96","quantity":"2.280"},{"price":"1735.98","quantity":"23.325"},{"price":"1735.99","quantity":"6.258"},{"price":"1736.00","quantity":"0.113"},{"price":"1736.02","quantity":"1.789"},{"price":"1736.05","quantity":"0.154"},{"price":"1736.08","quantity":"0.735"},{"price":"1736.12","quantity":"131.311"}],"asks":[{"price":"1736.13","quantity":"60.825"},{"price":"1736.14","quantity":"0.082"},{"price":"1736.17","quantity":"0.036"},{"price":"1736.19","quantity":"0.843"},{"price":"1736.20","quantity":"2.917"},{"price":"1736.21","quantity":"0.012"},{"price":"1736.22","quantity":"15.476"},{"price":"1736.23","quantity":"0.052"},{"price":"1736.24","quantity":"0.098"},{"price":"1736.25","quantity":"2.825"},{"price":"1736.27","quantity":"1.754"},{"price":"1736.28","quantity":"49.092"},{"price":"1736.29","quantity":"1.198"},{"price":"1736.30","quantity":"7.929"},{"price":"1736.31","quantity":"17.384"},{"price":"1736.33","quantity":"0.012"},{"price":"1736.34","quantity":"0.041"},{"price":"1736.37","quantity":"7.821"},{"price":"1736.38","quantity":"17.501"},{"price":"1736.39","quantity":"4.248"},{"price":"1736.40","quantity":"21.362"},{"price":"1736.41","quantity":"18.185"},{"price":"1736.42","quantity":"29.361"},{"price":"1736.43","quantity":"27.625"},{"price":"1736.44","quantity":"7.245"},{"price":"1736.45","quantity":"77.106"},{"price":"1736.46","quantity":"41.550"},{"price":"1736.47","quantity":"19.642"},{"price":"1736.48","quantity":"6.182"},{"price":"1736.49","quantity":"3.015"},{"price":"1736.50","quantity":"0.102"},{"price":"1736.52","quantity":"5.845"},{"price":"1736.56","quantity":"9.082"},{"price":"1736.60","quantity":"5.055"},{"price":"1736.62","quantity":"2.245"},{"price":"1736.63","quantity":"8.821"},{"price":"1736.66","quantity":"3.216"},{"price":"1736.67","quantity":"3.518"},{"price":"1736.73","quantity":"45.889"},{"price":"1736.74","quantity":"43.559"},{"price":"1736.75","quantity":"95.506"},{"price":"1736.83","quantity":"37.658"},{"price":"1736.86","quantity":"0.328"},{"price":"1736.88","quantity":"5.425"},{"price":"1736.89","quantity":"8.153"},{"price":"1736.96","quantity":"12.198"},{"price":"1737.00","quantity":"72.152"},{"price":"1737.02","quantity":"25.898"},{"price":"1737.03","quantity":"84.344"},{"price":"1737.04","quantity":"98.625"},{"price":"1737.05","quantity":"46.894"},{"price":"1737.08","quantity":"6.521"},{"price":"1737.09","quantity":"28.385"},{"price":"1737.10","quantity":"8.611"},{"price":"1737.12","quantity":"3.771"},{"price":"1737.13","quantity":"2.822"},{"price":"1737.15","quantity":"2.934"},{"price":"1737.26","quantity":"6.857"},{"price":"1737.32","quantity":"1.295"},{"price":"1737.34","quantity":"13.215"},{"price":"1737.35","quantity":"27.841"},{"price":"1737.52","quantity":"2.666"},{"price":"1737.54","quantity":"27.248"},{"price":"1737.78","quantity":"1.355"},{"price":"1737.80","quantity":"3.324"},{"price":"1737.87","quantity":"7.926"},{"price":"1737.95","quantity":"90.782"},{"price":"1738.04","quantity":"0.239"},{"price":"1738.20","quantity":"408.215"},{"price":"1738.26","quantity":"1.023"},{"price":"1738.34","quantity":"10.639"},{"price":"1738.53","quantity":"29.337"},{"price":"1738.54","quantity":"9.895"},{"price":"1738.56","quantity":"1.044"},{"price":"1738.57","quantity":"33.052"},{"price":"1738.71","quantity":"38.346"},{"price":"1738.72","quantity":"56.323"},{"price":"1738.78","quantity":"7.305"},{"price":"1738.80","quantity":"6.458"},{"price":"1738.86","quantity":"6.077"},{"price":"1738.89","quantity":"59.745"},{"price":"1739.38","quantity":"7.600"},{"price":"1739.41","quantity":"4.407"},{"price":"1739.42","quantity":"27.654"},{"price":"1739.43","quantity":"70.670"},{"price":"1740.16","quantity":"26.711"},{"price":"1740.58","quantity":"8.287"},{"price":"1740.84","quantity":"0.172"},{"price":"1741.03","quantity":"1.152"},{"price":"1743.50","quantity":"10.964"},{"price":"1757.12","quantity":"54.225"},{"price":"1771.38","quantity":"0.013"},{"price":"1909.74","quantity":"0.012"},{"price":"2634.97","quantity":"0.001"},{"price":"2635.06","quantity":"0.011"}],"raw":{"e":"depthUpdate","E":1783517066662,"T":1783517066661,"s":"ETHUSDT","ps":"ETHUSDT","U":10999770563541,"u":10999770572595,"pu":10999770563387,"b":[["200.00","7.594"],["1211.12","1.665"],["1216.12","1.248"],["1216.16","4.736"],["1221.16","1.312"],["1562.50","1.060"],["1562.51","7.686"],["1666.02","29.999"],["1666.60","1.193"],["1701.39","32.216"],["1709.51","39.542"],["1710.22","31.807"],["1729.82","0.000"],["1730.01","4.410"],["1730.23","16.323"],["1730.44","4.322"],["1731.25","14.145"],["1731.51","1.964"],["1731.98","173.156"],["1732.52","0.000"],["1732.53","19.105"],["1732.75","145.605"],["1733.53","0.892"],["1733.65","429.945"],["1733.66","82.631"],["1733.70","16.350"],["1733.85","88.400"],["1733.89","0.765"],["1733.94","29.283"],["1734.40","3.664"],["1734.44","55.636"],["1734.45","1.951"],["1734.46","26.596"],["1734.52","0.039"],["1734.53","34.922"],["1734.56","3.962"],["1734.57","29.333"],["1734.58","25.519"],["1734.61","0.258"],["1734.63","19.810"],["1734.84","272.072"],["1734.85","1.504"],["1734.88","59.458"],["1734.90","19.427"],["1734.93","71.602"],["1734.96","5.239"],["1735.02","53.535"],["1735.06","0.127"],["1735.09","0.435"],["1735.10","12.275"],["1735.11","43.336"],["1735.13","1.544"],["1735.22","236.367"],["1735.27","68.101"],["1735.28","4.962"],["1735.31","34.596"],["1735.33","16.517"],["1735.38","285.061"],["1735.42","20.623"],["1735.43","4.053"],["1735.44","67.218"],["1735.45","0.178"],["1735.46","19.608"],["1735.47","16.709"],["1735.49","5.329"],["1735.54","0.012"],["1735.55","4.604"],["1735.56","28.455"],["1735.57","1.802"],["1735.58","0.094"],["1735.59","4.353"],["1735.63","0.576"],["1735.65","20.560"],["1735.66","5.924"],["1735.68","15.170"],["1735.69","24.767"],["1735.70","28.871"],["1735.72","89.558"],["1735.74","28.664"],["1735.75","70.644"],["1735.76","9.144"],["1735.77","23.795"],["1735.78","19.300"],["1735.79","16.959"],["1735.80","0.130"],["1735.81","5.358"],["1735.82","14.215"],["1735.83","21.004"],["1735.84","0.058"],["1735.85","2.933"],["1735.86","68.508"],["1735.87","24.344"],["1735.89","0.986"],["1735.90","4.012"],["1735.91","10.233"],["1735.92","33.465"],["1735.93","5.088"],["1735.94","3.929"],["1735.95","1.226"],["1735.96","2.280"],["1735.98","23.325"],["1735.99","6.258"],["1736.00","0.113"],["1736.02","1.789"],["1736.05","0.154"],["1736.08","0.735"],["1736.12","131.311"]],"a":[["1736.13","60.825"],["1736.14","0.082"],["1736.17","0.036"],["1736.19","0.843"],["1736.20","2.917"],["1736.21","0.012"],["1736.22","15.476"],["1736.23","0.052"],["1736.24","0.098"],["1736.25","2.825"],["1736.27","1.754"],["1736.28","49.092"],["1736.29","1.198"],["1736.30","7.929"],["1736.31","17.384"],["1736.33","0.012"],["1736.34","0.041"],["1736.37","7.821"],["1736.38","17.501"],["1736.39","4.248"],["1736.40","21.362"],["1736.41","18.185"],["1736.42","29.361"],["1736.43","27.625"],["1736.44","7.245"],["1736.45","77.106"],["1736.46","41.550"],["1736.47","19.642"],["1736.48","6.182"],["1736.49","3.015"],["1736.50","0.102"],["1736.52","5.845"],["1736.56","9.082"],["1736.60","5.055"],["1736.62","2.245"],["1736.63","8.821"],["1736.66","3.216"],["1736.67","3.518"],["1736.73","45.889"],["1736.74","43.559"],["1736.75","95.506"],["1736.83","37.658"],["1736.86","0.328"],["1736.88","5.425"],["1736.89","8.153"],["1736.96","12.198"],["1737.00","72.152"],["1737.02","25.898"],["1737.03","84.344"],["1737.04","98.625"],["1737.05","46.894"],["1737.08","6.521"],["1737.09","28.385"],["1737.10","8.611"],["1737.12","3.771"],["1737.13","2.822"],["1737.15","2.934"],["1737.26","6.857"],["1737.32","1.295"],["1737.34","13.215"],["1737.35","27.841"],["1737.52","2.666"],["1737.54","27.248"],["1737.78","1.355"],["1737.80","3.324"],["1737.87","7.926"],["1737.95","90.782"],["1738.04","0.239"],["1738.20","408.215"],["1738.26","1.023"],["1738.34","10.639"],["1738.53","29.337"],["1738.54","9.895"],["1738.56","1.044"],["1738.57","33.052"],["1738.71","38.346"],["1738.72","56.323"],["1738.78","7.305"],["1738.80","6.458"],["1738.86","6.077"],["1738.89","59.745"],["1739.38","7.600"],["1739.41","4.407"],["1739.42","27.654"],["1739.43","70.670"],["1740.16","26.711"],["1740.58","8.287"],["1740.84","0.172"],["1741.03","1.152"],["1743.50","10.964"],["1757.12","54.225"],["1771.38","0.013"],["1909.74","0.012"],["2634.97","0.001"],["2635.06","0.011"]],"st":1}}
{"schema_version":"1.3.0","event_id":"512e7d22-b365-459a-931c-76075612b869","event_type":"raw.depth_update","source":"binance_market_data_recorder","venue":"binance_usdm","market_type":"perpetual_futures","symbol":"BTCUSDT","event_time_ms":1783517066700,"received_time_ms":1783517067232,"trace_id":"fef374cd-f235-49eb-a508-e692726b4925","first_update_id":10999770567250,"final_update_id":10999770574901,"previous_final_update_id":10999770567076,"bids":[{"price":"1000.00","quantity":"207.692"},{"price":"11353.70","quantity":"1.376"},{"price":"11452.20","quantity":"1.328"},{"price":"11453.70","quantity":"0.085"},{"price":"11553.70","quantity":"0.561"},{"price":"11652.20","quantity":"0.000"},{"price":"49483.00","quantity":"0.000"},{"price":"55668.30","quantity":"0.002"},{"price":"59379.50","quantity":"0.001"},{"price":"60615.20","quantity":"0.033"},{"price":"60955.30","quantity":"14.911"},{"price":"61024.10","quantity":"0.821"},{"price":"61235.20","quantity":"0.025"},{"price":"61295.50","quantity":"2.370"},{"price":"61542.90","quantity":"0.000"},{"price":"61543.90","quantity":"0.011"},{"price":"61775.80","quantity":"2.135"},{"price":"61776.80","quantity":"2.746"},{"price":"61786.30","quantity":"34.159"},{"price":"61789.00","quantity":"6.403"},{"price":"61805.60","quantity":"0.331"},{"price":"61809.30","quantity":"0.053"},{"price":"61820.20","quantity":"0.134"},{"price":"61821.00","quantity":"0.735"},{"price":"61823.20","quantity":"0.359"},{"price":"61823.50","quantity":"0.003"},{"price":"61823.80","quantity":"0.017"},{"price":"61826.60","quantity":"0.695"},{"price":"61826.90","quantity":"0.124"},{"price":"61827.40","quantity":"0.613"},{"price":"61828.90","quantity":"1.384"},{"price":"61830.50","quantity":"0.021"},{"price":"61831.30","quantity":"3.103"},{"price":"61832.10","quantity":"0.067"},{"price":"61832.80","quantity":"0.343"},{"price":"61835.10","quantity":"1.874"},{"price":"61837.30","quantity":"0.805"},{"price":"61838.60","quantity":"0.016"},{"price":"61840.70","quantity":"1.292"},{"price":"61840.90","quantity":"0.286"},{"price":"61841.30","quantity":"1.056"},{"price":"61841.60","quantity":"0.055"},{"price":"61842.50","quantity":"0.689"},{"price":"61843.90","quantity":"0.120"},{"price":"61844.40","quantity":"0.328"},{"price":"61846.30","quantity":"0.203"},{"price":"61847.50","quantity":"0.131"},{"price":"61847.60","quantity":"0.006"},{"price":"61847.90","quantity":"0.134"},{"price":"61852.20","quantity":"0.636"},{"price":"61853.60","quantity":"0.003"},{"price":"61853.70","quantity":"2.135"}],"asks":[{"price":"61853.80","quantity":"7.964"},{"price":"61854.40","quantity":"0.003"},{"price":"61856.90","quantity":"0.002"},{"price":"61857.30","quantity":"0.003"},{"price":"61858.40","quantity":"0.001"},{"price":"61860.30","quantity":"0.322"},{"price":"61860.40","quantity":"0.178"},{"price":"61860.90","quantity":"0.312"},{"price":"61862.40","quantity":"0.374"},{"price":"61862.50","quantity":"0.001"},{"price":"61863.30","quantity":"0.002"},{"price":"61863.60","quantity":"0.493"},{"price":"61863.80","quantity":"0.971"},{"price":"61863.90","quantity":"0.470"},{"price":"61864.00","quantity":"2.719"},{"price":"61864.60","quantity":"0.066"},{"price":"61865.60","quantity":"0.586"},{"price":"61865.70","quantity":"0.472"},{"price":"61866.40","quantity":"0.001"},{"price":"61866.60","quantity":"0.203"},{"price":"61866.90","quantity":"0.103"},{"price":"61867.20","quantity":"0.054"},{"price":"61867.80","quantity":"0.205"},{"price":"61868.40","quantity":"0.017"},{"price":"61869.70","quantity":"0.011"},{"price":"61873.10","quantity":"0.165"},{"price":"61876.90","quantity":"0.602"},{"price":"61879.00","quantity":"0.069"},{"price":"61879.30","quantity":"1.912"},{"price":"61879.70","quantity":"0.154"},{"price":"61881.10","quantity":"0.002"},{"price":"61883.70","quantity":"0.166"},{"price":"61884.20","quantity":"0.315"},{"price":"61887.90","quantity":"0.499"},{"price":"61897.10","quantity":"0.306"},{"price":"61907.90","quantity":"0.107"},{"price":"61908.00","quantity":"0.003"},{"price":"61908.20","quantity":"0.665"},{"price":"61908.70","quantity":"0.016"},{"price":"61909.00","quantity":"0.032"},{"price":"61913.50","quantity":"2.244"},{"price":"61914.10","quantity":"0.261"},{"price":"61916.30","quantity":"25.272"},{"price":"61916.40","quantity":"6.520"},{"price":"61918.40","quantity":"0.000"},{"price":"62472.30","quantity":"0.000"},{"price":"89523.20","quantity":"0.720"}],"raw":{"e":"depthUpdate","E":1783517066700,"T":1783517066697,"s":"BTCUSDT","ps":"BTCUSDT","U":10999770567250,"u":10999770574901,"pu":10999770567076,"b":[["1000.00","207.692"],["11353.70","1.376"],["11452.20","1.328"],["11453.70","0.085"],["11553.70","0.561"],["11652.20","0.000"],["49483.00","0.000"],["55668.30","0.002"],["59379.50","0.001"],["60615.20","0.033"],["60955.30","14.911"],["61024.10","0.821"],["61235.20","0.025"],["61295.50","2.370"],["61542.90","0.000"],["61543.90","0.011"],["61775.80","2.135"],["61776.80","2.746"],["61786.30","34.159"],["61789.00","6.403"],["61805.60","0.331"],["61809.30","0.053"],["61820.20","0.134"],["61821.00","0.735"],["61823.20","0.359"],["61823.50","0.003"],["61823.80","0.017"],["61826.60","0.695"],["61826.90","0.124"],["61827.40","0.613"],["61828.90","1.384"],["61830.50","0.021"],["61831.30","3.103"],["61832.10","0.067"],["61832.80","0.343"],["61835.10","1.874"],["61837.30","0.805"],["61838.60","0.016"],["61840.70","1.292"],["61840.90","0.286"],["61841.30","1.056"],["61841.60","0.055"],["61842.50","0.689"],["61843.90","0.120"],["61844.40","0.328"],["61846.30","0.203"],["61847.50","0.131"],["61847.60","0.006"],["61847.90","0.134"],["61852.20","0.636"],["61853.60","0.003"],["61853.70","2.135"]],"a":[["61853.80","7.964"],["61854.40","0.003"],["61856.90","0.002"],["61857.30","0.003"],["61858.40","0.001"],["61860.30","0.322"],["61860.40","0.178"],["61860.90","0.312"],["61862.40","0.374"],["61862.50","0.001"],["61863.30","0.002"],["61863.60","0.493"],["61863.80","0.971"],["61863.90","0.470"],["61864.00","2.719"],["61864.60","0.066"],["61865.60","0.586"],["61865.70","0.472"],["61866.40","0.001"],["61866.60","0.203"],["61866.90","0.103"],["61867.20","0.054"],["61867.80","0.205"],["61868.40","0.017"],["61869.70","0.011"],["61873.10","0.165"],["61876.90","0.602"],["61879.00","0.069"],["61879.30","1.912"],["61879.70","0.154"],["61881.10","0.002"],["61883.70","0.166"],["61884.20","0.315"],["61887.90","0.499"],["61897.10","0.306"],["61907.90","0.107"],["61908.00","0.003"],["61908.20","0.665"],["61908.70","0.016"],["61909.00","0.032"],["61913.50","2.244"],["61914.10","0.261"],["61916.30","25.272"],["61916.40","6.520"],["61918.40","0.000"],["62472.30","0.000"],["89523.20","0.720"]],"st":1}}
{"schema_version":"1.3.0","event_id":"68703edc-2693-4862-8db1-80dbb15074ac","event_type":"raw.trade","source":"binance_market_data_recorder","venue":"binance_usdm","market_type":"perpetual_futures","symbol":"ETHUSDT","event_time_ms":1783517066718,"received_time_ms":1783517067236,"trace_id":"4c55e29e-cc7b-4e29-957d-2a5d6ee3b8f5","trade_id":8429826851,"price":"1736.13","quantity":"0.575","trade_time_ms":1783517066718,"is_buyer_maker":false,"aggressor_side":"buy","raw":{"e":"trade","E":1783517066718,"T":1783517066718,"s":"ETHUSDT","t":8429826851,"p":"1736.13","q":"0.575","X":"MARKET","m":false,"st":1}}
{"schema_version":"1.3.0","event_id":"d6dc2cca-f399-4de0-b993-b29a95b4e640","event_type":"raw.trade","source":"binance_market_data_recorder","venue":"binance_usdm","market_type":"perpetual_futures","symbol":"ETHUSDT","event_time_ms":1783517066745,"received_time_ms":1783517067240,"trace_id":"11b28ec8-c80e-4a86-83ce-d6cf8bcc101e","trade_id":8429826852,"price":"1736.13","quantity":"2.872","trade_time_ms":1783517066745,"is_buyer_maker":false,"aggressor_side":"buy","raw":{"e":"trade","E":1783517066745,"T":1783517066745,"s":"ETHUSDT","t":8429826852,"p":"1736.13","q":"2.872","X":"MARKET","m":false,"st":1}}
{"schema_version":"1.3.0","event_id":"730bd1c2-abe6-4945-9243-828d940e222a","event_type":"raw.depth_update","source":"binance_market_data_recorder","venue":"binance_usdm","market_type":"perpetual_futures","symbol":"ETHUSDT","event_time_ms":1783517066764,"received_time_ms":1783517067240,"trace_id":"47415f74-47d0-497c-94f3-3911c6a56fa3","first_update_id":10999770572661,"final_update_id":10999770579204,"previous_final_update_id":10999770572595,"bids":[{"price":"1211.12","quantity":"2.209"},{"price":"1216.12","quantity":"1.504"},{"price":"1216.16","quantity":"4.192"},{"price":"1221.16","quantity":"1.056"},{"price":"1562.50","quantity":"1.060"},{"price":"1562.51","quantity":"8.340"},{"price":"1699.00","quantity":"152.240"},{"price":"1701.39","quantity":"32.187"},{"price":"1710.25","quantity":"126.003"},{"price":"1732.52","quantity":"9.729"},{"price":"1733.65","quantity":"9.919"},{"price":"1733.66","quantity":"23.837"},{"price":"1733.70","quantity":"16.600"},{"price":"1733.71","quantity":"84.523"},{"price":"1733.76","quantity":"35.199"},{"price":"1733.91","quantity":"0.465"},{"price":"1733.95","quantity":"3.942"},{"price":"1734.18","quantity":"420.038"},{"price":"1734.21","quantity":"79.237"},{"price":"1734.43","quantity":"0.984"},{"price":"1734.45","quantity":"0.638"},{"price":"1734.46","quantity":"25.640"},{"price":"1734.99","quantity":"220.634"},{"price":"1735.00","quantity":"228.843"},{"price":"1735.02","quantity":"94.800"},{"price":"1735.10","quantity":"232.216"},{"price":"1735.11","quantity":"74.437"},{"price":"1735.15","quantity":"6.463"},{"price":"1735.20","quantity":"45.938"},{"price":"1735.21","quantity":"36.379"},{"price":"1735.22","quantity":"17.355"},{"price":"1735.25","quantity":"39.125"},{"price":"1735.27","quantity":"68.102"},{"price":"1735.38","quantity":"65.076"},{"price":"1735.39","quantity":"0.553"},{"price":"1735.40","quantity":"3.830"},{"price":"1735.41","quantity":"124.169"},{"price":"1735.44","quantity":"27.473"},{"price":"1735.47","quantity":"16.709"},{"price":"1735.60","quantity":"4.695"},{"price":"1735.72","quantity":"89.558"},{"price":"1735.76","quantity":"9.944"},{"price":"1735.78","quantity":"1.373"},{"price":"1735.79","quantity":"8.630"},{"price":"1735.80","quantity":"0.730"},{"price":"1735.81","quantity":"6.958"},{"price":"1735.82","quantity":"0.866"},{"price":"1735.93","quantity":"5.111"},{"price":"1735.95","quantity":"9.874"},{"price":"1735.99","quantity":"9.910"},{"price":"1736.12","quantity":"131.384"}],"asks":[{"price":"1736.13","quantity":"65.737"},{"price":"1736.18","quantity":"0.041"},{"price":"1736.22","quantity":"9.992"},{"price":"1736.26","quantity":"7.529"},{"price":"1736.27","quantity":"21.846"},{"price":"1736.28","quantity":"48.804"},{"price":"1736.31","quantity":"17.672"},{"price":"1736.32","quantity":"0.174"},{"price":"1736.35","quantity":"4.537"},{"price":"1736.36","quantity":"0.560"},{"price":"1736.41","quantity":"27.625"},{"price":"1736.42","quantity":"5.878"},{"price":"1736.44","quantity":"6.677"},{"price":"1736.45","quantity":"105.759"},{"price":"1736.48","quantity":"8.262"},{"price":"1736.60","quantity":"9.365"},{"price":"1736.62","quantity":"2.196"},{"price":"1736.72","quantity":"9.786"},{"price":"1736.76","quantity":"20.522"},{"price":"1736.82","quantity":"20.001"},{"price":"1736.85","quantity":"0.619"},{"price":"1736.91","quantity":"68.123"},{"price":"1737.01","quantity":"75.007"},{"price":"1737.02","quantity":"23.872"},{"price":"1737.03","quantity":"83.757"},{"price":"1737.08","quantity":"15.961"},{"price":"1737.10","quantity":"13.951"},{"price":"1737.11","quantity":"17.097"},{"price":"1737.12","quantity":"7.811"},{"price":"1737.15","quantity":"5.014"},{"price":"1737.16","quantity":"11.200"},{"price":"1737.17","quantity":"2.194"},{"price":"1737.20","quantity":"26.327"},{"price":"1737.21","quantity":"3.477"},{"price":"1737.29","quantity":"2.293"},{"price":"1737.43","quantity":"8.581"},{"price":"1737.46","quantity":"9.147"},{"price":"1737.63","quantity":"0.314"},{"price":"1737.78","quantity":"3.575"},{"price":"1737.80","quantity":"5.124"},{"price":"1738.78","quantity":"4.305"},{"price":"1738.82","quantity":"8.207"},{"price":"1738.86","quantity":"2.881"},{"price":"1738.89","quantity":"56.549"},{"price":"1740.17","quantity":"46.948"},{"price":"1740.21","quantity":"8.357"},{"price":"1741.69","quantity":"4.136"},{"price":"1742.38","quantity":"4.136"},{"price":"1747.12","quantity":"15.000"},{"price":"1760.59","quantity":"58.998"},{"price":"1767.53","quantity":"101.712"},{"price":"1775.37","quantity":"0.015"},{"price":"1909.74","quantity":"0.000"},{"price":"2634.95","quantity":"0.001"},{"price":"2634.96","quantity":"0.001"},{"price":"2635.04","quantity":"0.000"},{"price":"2635.05","quantity":"0.000"}],"raw":{"e":"depthUpdate","E":1783517066764,"T":1783517066763,"s":"ETHUSDT","ps":"ETHUSDT","U":10999770572661,"u":10999770579204,"pu":10999770572595,"b":[["1211.12","2.209"],["1216.12","1.504"],["1216.16","4.192"],["1221.16","1.056"],["1562.50","1.060"],["1562.51","8.340"],["1699.00","152.240"],["1701.39","32.187"],["1710.25","126.003"],["1732.52","9.729"],["1733.65","9.919"],["1733.66","23.837"],["1733.70","16.600"],["1733.71","84.523"],["1733.76","35.199"],["1733.91","0.465"],["1733.95","3.942"],["1734.18","420.038"],["1734.21","79.237"],["1734.43","0.984"],["1734.45","0.638"],["1734.46","25.640"],["1734.99","220.634"],["1735.00","228.843"],["1735.02","94.800"],["1735.10","232.216"],["1735.11","74.437"],["1735.15","6.463"],["1735.20","45.938"],["1735.21","36.379"],["1735.22","17.355"],["1735.25","39.125"],["1735.27","68.102"],["1735.38","65.076"],["1735.39","0.553"],["1735.40","3.830"],["1735.41","124.169"],["1735.44","27.473"],["1735.47","16.709"],["1735.60","4.695"],["1735.72","89.558"],["1735.76","9.944"],["1735.78","1.373"],["1735.79","8.630"],["1735.80","0.730"],["1735.81","6.958"],["1735.82","0.866"],["1735.93","5.111"],["1735.95","9.874"],["1735.99","9.910"],["1736.12","131.384"]],"a":[["1736.13","65.737"],["1736.18","0.041"],["1736.22","9.992"],["1736.26","7.529"],["1736.27","21.846"],["1736.28","48.804"],["1736.31","17.672"],["1736.32","0.174"],["1736.35","4.537"],["1736.36","0.560"],["1736.41","27.625"],["1736.42","5.878"],["1736.44","6.677"],["1736.45","105.759"],["1736.48","8.262"],["1736.60","9.365"],["1736.62","2.196"],["1736.72","9.786"],["1736.76","20.522"],["1736.82","20.001"],["1736.85","0.619"],["1736.91","68.123"],["1737.01","75.007"],["1737.02","23.872"],["1737.03","83.757"],["1737.08","15.961"],["1737.10","13.951"],["1737.11","17.097"],["1737.12","7.811"],["1737.15","5.014"],["1737.16","11.200"],["1737.17","2.194"],["1737.20","26.327"],["1737.21","3.477"],["1737.29","2.293"],["1737.43","8.581"],["1737.46","9.147"],["1737.63","0.314"],["1737.78","3.575"],["1737.80","5.124"],["1738.78","4.305"],["1738.82","8.207"],["1738.86","2.881"],["1738.89","56.549"],["1740.17","46.948"],["1740.21","8.357"],["1741.69","4.136"],["1742.38","4.136"],["1747.12","15.000"],["1760.59","58.998"],["1767.53","101.712"],["1775.37","0.015"],["1909.74","0.000"],["2634.95","0.001"],["2634.96","0.001"],["2635.04","0.000"],["2635.05","0.000"]],"st":1}}
{"schema_version":"1.3.0","event_id":"6594df29-0dd8-4fb1-b920-f76e40f41f28","event_type":"raw.depth_update","source":"binance_market_data_recorder","venue":"binance_usdm","market_type":"perpetual_futures","symbol":"BTCUSDT","event_time_ms":1783517066802,"received_time_ms":1783517067242,"trace_id":"ca46a3cd-9fff-4a9f-8bc5-1a7ec3936fb9","first_update_id":10999770575010,"final_update_id":10999770581814,"previous_final_update_id":10999770574901,"bids":[{"price":"1000.00","quantity":"207.692"},{"price":"11353.70","quantity":"1.648"},{"price":"11452.20","quantity":"1.056"},{"price":"11453.70","quantity":"0.238"},{"price":"11553.70","quantity":"0.408"},{"price":"55668.30","quantity":"0.002"},{"price":"58760.50","quantity":"0.003"},{"price":"59379.50","quantity":"0.004"},{"price":"60781.60","quantity":"0.000"},{"price":"61235.20","quantity":"0.025"},{"price":"61301.70","quantity":"2.794"},{"price":"61399.90","quantity":"2.071"},{"price":"61544.40","quantity":"0.003"},{"price":"61593.50","quantity":"0.001"},{"price":"61593.90","quantity":"0.144"},{"price":"61756.70","quantity":"0.000"},{"price":"61762.80","quantity":"2.425"},{"price":"61770.10","quantity":"0.002"},{"price":"61775.80","quantity":"2.135"},{"price":"61776.80","quantity":"2.746"},{"price":"61786.30","quantity":"34.159"},{"price":"61789.00","quantity":"6.403"},{"price":"61805.00","quantity":"6.614"},{"price":"61806.10","quantity":"0.039"},{"price":"61818.00","quantity":"3.658"},{"price":"61825.50","quantity":"0.590"},{"price":"61826.60","quantity":"0.113"},{"price":"61833.00","quantity":"0.034"},{"price":"61834.40","quantity":"0.688"},{"price":"61835.20","quantity":"0.438"},{"price":"61840.10","quantity":"0.002"},{"price":"61841.00","quantity":"0.899"},{"price":"61841.30","quantity":"0.975"},{"price":"61843.20","quantity":"0.188"},{"price":"61843.50","quantity":"0.062"},{"price":"61843.80","quantity":"0.414"},{"price":"61844.90","quantity":"0.033"},{"price":"61850.30","quantity":"0.002"},{"price":"61852.20","quantity":"0.638"},{"price":"61853.70","quantity":"1.816"}],"asks":[{"price":"61853.80","quantity":"7.969"},{"price":"61856.70","quantity":"0.917"},{"price":"61857.80","quantity":"1.058"},{"price":"61859.60","quantity":"0.726"},{"price":"61860.10","quantity":"2.140"},{"price":"61860.40","quantity":"0.987"},{"price":"61860.90","quantity":"0.684"},{"price":"61861.00","quantity":"0.271"},{"price":"61861.30","quantity":"0.225"},{"price":"61861.50","quantity":"0.206"},{"price":"61861.60","quantity":"0.319"},{"price":"61862.00","quantity":"1.131"},{"price":"61862.30","quantity":"0.002"},{"price":"61862.40","quantity":"0.373"},{"price":"61863.80","quantity":"0.003"},{"price":"61871.20","quantity":"0.027"},{"price":"61879.00","quantity":"0.232"},{"price":"61880.30","quantity":"1.079"},{"price":"61880.40","quantity":"0.371"},{"price":"61882.20","quantity":"1.076"},{"price":"61884.20","quantity":"0.495"},{"price":"61884.60","quantity":"0.183"},{"price":"61884.80","quantity":"0.254"},{"price":"61884.90","quantity":"0.332"},{"price":"61904.80","quantity":"0.487"},{"price":"61905.20","quantity":"0.121"},{"price":"61907.60","quantity":"0.000"},{"price":"61907.70","quantity":"0.412"},{"price":"61908.20","quantity":"0.564"},{"price":"61913.50","quantity":"2.244"},{"price":"61916.30","quantity":"0.149"},{"price":"61916.40","quantity":"6.520"},{"price":"61918.40","quantity":"25.123"},{"price":"61971.50","quantity":"0.860"},{"price":"61976.20","quantity":"2.427"},{"price":"62161.60","quantity":"0.001"},{"price":"62163.10","quantity":"0.002"},{"price":"62472.30","quantity":"0.000"},{"price":"62532.70","quantity":"4.299"},{"price":"62623.20","quantity":"2.662"},{"price":"62693.80","quantity":"0.000"},{"price":"63089.30","quantity":"0.135"}],"raw":{"e":"depthUpdate","E":1783517066802,"T":1783517066801,"s":"BTCUSDT","ps":"BTCUSDT","U":10999770575010,"u":10999770581814,"pu":10999770574901,"b":[["1000.00","207.692"],["11353.70","1.648"],["11452.20","1.056"],["11453.70","0.238"],["11553.70","0.408"],["55668.30","0.002"],["58760.50","0.003"],["59379.50","0.004"],["60781.60","0.000"],["61235.20","0.025"],["61301.70","2.794"],["61399.90","2.071"],["61544.40","0.003"],["61593.50","0.001"],["61593.90","0.144"],["61756.70","0.000"],["61762.80","2.425"],["61770.10","0.002"],["61775.80","2.135"],["61776.80","2.746"],["61786.30","34.159"],["61789.00","6.403"],["61805.00","6.614"],["61806.10","0.039"],["61818.00","3.658"],["61825.50","0.590"],["61826.60","0.113"],["61833.00","0.034"],["61834.40","0.688"],["61835.20","0.438"],["61840.10","0.002"],["61841.00","0.899"],["61841.30","0.975"],["61843.20","0.188"],["61843.50","0.062"],["61843.80","0.414"],["61844.90","0.033"],["61850.30","0.002"],["61852.20","0.638"],["61853.70","1.816"]],"a":[["61853.80","7.969"],["61856.70","0.917"],["61857.80","1.058"],["61859.60","0.726"],["61860.10","2.140"],["61860.40","0.987"],["61860.90","0.684"],["61861.00","0.271"],["61861.30","0.225"],["61861.50","0.206"],["61861.60","0.319"],["61862.00","1.131"],["61862.30","0.002"],["61862.40","0.373"],["61863.80","0.003"],["61871.20","0.027"],["61879.00","0.232"],["61880.30","1.079"],["61880.40","0.371"],["61882.20","1.076"],["61884.20","0.495"],["61884.60","0.183"],["61884.80","0.254"],["61884.90","0.332"],["61904.80","0.487"],["61905.20","0.121"],["61907.60","0.000"],["61907.70","0.412"],["61908.20","0.564"],["61913.50","2.244"],["61916.30","0.149"],["61916.40","6.520"],["61918.40","25.123"],["61971.50","0.860"],["61976.20","2.427"],["62161.60","0.001"],["62163.10","0.002"],["62472.30","0.000"],["62532.70","4.299"],["62623.20","2.662"],["62693.80","0.000"],["63089.30","0.135"]],"st":1}}
{"schema_version":"1.3.0","event_id":"4f5e5b7c-83eb-41ab-a0dc-a5949fdbfaa4","event_type":"raw.depth_update","source":"binance_market_data_recorder","venue":"binance_usdm","market_type":"perpetual_futures","symbol":"ETHUSDT","event_time_ms":1783517066866,"received_time_ms":1783517067250,"trace_id":"3d60eb80-d2ef-4f82-aea9-f56f2157b9c4","first_update_id":10999770579253,"final_update_id":10999770586155,"previous_final_update_id":10999770579204,"bids":[{"price":"200.00","quantity":"7.594"},{"price":"1211.12","quantity":"2.753"},{"price":"1216.12","quantity":"1.792"},{"price":"1216.16","quantity":"3.648"},{"price":"1221.16","quantity":"0.768"},{"price":"1562.50","quantity":"1.060"},{"price":"1562.51","quantity":"8.852"},{"price":"1666.60","quantity":"1.078"},{"price":"1730.22","quantity":"65.350"},{"price":"1730.56","quantity":"1.729"},{"price":"1734.01","quantity":"20.653"},{"price":"1734.04","quantity":"126.458"},{"price":"1734.42","quantity":"1.447"},{"price":"1734.44","quantity":"56.236"},{"price":"1734.89","quantity":"220.103"},{"price":"1734.99","quantity":"0.689"},{"price":"1735.02","quantity":"53.535"},{"price":"1735.10","quantity":"12.293"},{"price":"1735.11","quantity":"43.336"},{"price":"1735.12","quantity":"94.679"},{"price":"1735.36","quantity":"3.786"},{"price":"1735.37","quantity":"0.595"},{"price":"1735.42","quantity":"20.653"},{"price":"1735.62","quantity":"12.166"},{"price":"1735.75","quantity":"71.444"},{"price":"1735.77","quantity":"15.801"},{"price":"1735.78","quantity":"2.173"},{"price":"1735.80","quantity":"1.330"},{"price":"1735.87","quantity":"3.043"},{"price":"1735.88","quantity":"0.036"},{"price":"1735.90","quantity":"11.661"},{"price":"1735.95","quantity":"1.226"},{"price":"1735.98","quantity":"23.307"},{"price":"1735.99","quantity":"8.758"},{"price":"1736.12","quantity":"122.467"}],"asks":[{"price":"1736.13","quantity":"119.956"},{"price":"1736.23","quantity":"20.052"},{"price":"1736.24","quantity":"0.617"},{"price":"1736.25","quantity":"10.094"},{"price":"1736.26","quantity":"0.438"},{"price":"1736.27","quantity":"14.992"},{"price":"1736.28","quantity":"28.804"},{"price":"1736.30","quantity":"9.657"},{"price":"1736.33","quantity":"0.042"},{"price":"1736.39","quantity":"7.189"},{"price":"1736.44","quantity":"8.297"},{"price":"1736.45","quantity":"107.857"},{"price":"1736.46","quantity":"43.092"},{"price":"1736.48","quantity":"10.452"},{"price":"1736.57","quantity":"2.108"},{"price":"1736.63","quantity":"10.521"},{"price":"1736.66","quantity":"3.202"},{"price":"1736.68","quantity":"4.705"},{"price":"1736.88","quantity":"3.731"},{"price":"1737.11","quantity":"20.411"},{"price":"1737.13","quantity":"4.902"},{"price":"1737.14","quantity":"69.431"},{"price":"1737.16","quantity":"13.360"},{"price":"1737.21","quantity":"0.022"},{"price":"1737.22","quantity":"5.290"},{"price":"1737.79","quantity":"1.635"},{"price":"1737.81","quantity":"31.288"},{"price":"1737.95","quantity":"89.115"},{"price":"1738.20","quantity":"0.256"},{"price":"1738.25","quantity":"410.177"},{"price":"1738.82","quantity":"5.011"},{"price":"1738.86","quantity":"2.881"},{"price":"1740.16","quantity":"16.982"},{"price":"1749.67","quantity":"0.038"},{"price":"1762.98","quantity":"689.407"},{"price":"2634.93","quantity":"0.001"},{"price":"2634.94","quantity":"0.082"},{"price":"2635.02","quantity":"0.000"},{"price":"2635.03","quantity":"0.000"}],"raw":{"e":"depthUpdate","E":1783517066866,"T":1783517066865,"s":"ETHUSDT","ps":"ETHUSDT","U":10999770579253,"u":10999770586155,"pu":10999770579204,"b":[["200.00","7.594"],["1211.12","2.753"],["1216.12","1.792"],["1216.16","3.648"],["1221.16","0.768"],["1562.50","1.060"],["1562.51","8.852"],["1666.60","1.078"],["1730.22","65.350"],["1730.56","1.729"],["1734.01","20.653"],["1734.04","126.458"],["1734.42","1.447"],["1734.44","56.236"],["1734.89","220.103"],["1734.99","0.689"],["1735.02","53.535"],["1735.10","12.293"],["1735.11","43.336"],["1735.12","94.679"],["1735.36","3.786"],["1735.37","0.595"],["1735.42","20.653"],["1735.62","12.166"],["1735.75","71.444"],["1735.77","15.801"],["1735.78","2.173"],["1735.80","1.330"],["1735.87","3.043"],["1735.88","0.036"],["1735.90","11.661"],["1735.95","1.226"],["1735.98","23.307"],["1735.99","8.758"],["1736.12","122.467"]],"a":[["1736.13","119.956"],["1736.23","20.052"],["1736.24","0.617"],["1736.25","10.094"],["1736.26","0.438"],["1736.27","14.992"],["1736.28","28.804"],["1736.30","9.657"],["1736.33","0.042"],["1736.39","7.189"],["1736.44","8.297"],["1736.45","107.857"],["1736.46","43.092"],["1736.48","10.452"],["1736.57","2.108"],["1736.63","10.521"],["1736.66","3.202"],["1736.68","4.705"],["1736.88","3.731"],["1737.11","20.411"],["1737.13","4.902"],["1737.14","69.431"],["1737.16","13.360"],["1737.21","0.022"],["1737.22","5.290"],["1737.79","1.635"],["1737.81","31.288"],["1737.95","89.115"],["1738.20","0.256"],["1738.25","410.177"],["1738.82","5.011"],["1738.86","2.881"],["1740.16","16.982"],["1749.67","0.038"],["1762.98","689.407"],["2634.93","0.001"],["2634.94","0.082"],["2635.02","0.000"],["2635.03","0.000"]],"st":1}}
{"schema_version":"1.3.0","event_id":"de0fd7b7-d771-4479-b348-8c8a4c2bb65e","event_type":"raw.depth_update","source":"binance_market_data_recorder","venue":"binance_usdm","market_type":"perpetual_futures","symbol":"BTCUSDT","event_time_ms":1783517066904,"received_time_ms":1783517067255,"trace_id":"4dc35c5b-7907-4e99-914b-b4217c8cb22f","first_update_id":10999770581980,"final_update_id":10999770588150,"previous_final_update_id":10999770581814,"bids":[{"price":"11353.70","quantity":"1.920"},{"price":"11452.20","quantity":"0.784"},{"price":"11453.70","quantity":"0.374"},{"price":"11553.70","quantity":"0.272"},{"price":"55668.30","quantity":"0.002"},{"price":"60886.60","quantity":"0.001"},{"price":"61041.90","quantity":"1.145"},{"price":"61235.20","quantity":"0.025"},{"price":"61295.50","quantity":"2.614"},{"price":"61320.00","quantity":"2.068"},{"price":"61537.60","quantity":"0.348"},{"price":"61611.00","quantity":"1.986"},{"price":"61771.60","quantity":"34.158"},{"price":"61773.60","quantity":"8.059"},{"price":"61785.90","quantity":"0.255"},{"price":"61786.30","quantity":"0.002"},{"price":"61789.00","quantity":"1.484"},{"price":"61795.30","quantity":"4.734"},{"price":"61795.40","quantity":"0.003"},{"price":"61805.90","quantity":"0.034"},{"price":"61825.00","quantity":"1.748"},{"price":"61825.80","quantity":"0.121"},{"price":"61826.90","quantity":"0.003"},{"price":"61831.30","quantity":"3.105"},{"price":"61832.50","quantity":"0.002"},{"price":"61841.90","quantity":"0.503"},{"price":"61842.00","quantity":"0.377"},{"price":"61842.10","quantity":"0.001"},{"price":"61842.50","quantity":"0.681"},{"price":"61842.60","quantity":"0.081"},{"price":"61842.80","quantity":"0.000"},{"price":"61842.90","quantity":"0.036"},{"price":"61843.20","quantity":"0.248"},{"price":"61843.50","quantity":"0.122"},{"price":"61843.70","quantity":"0.004"},{"price":"61843.80","quantity":"0.474"},{"price":"61844.60","quantity":"0.033"},{"price":"61844.80","quantity":"0.017"},{"price":"61844.90","quantity":"0.033"},{"price":"61849.40","quantity":"0.001"},{"price":"61853.70","quantity":"2.485"}],"asks":[{"price":"61853.80","quantity":"7.968"},{"price":"61854.70","quantity":"0.163"},{"price":"61857.90","quantity":"0.000"},{"price":"61860.00","quantity":"0.463"},{"price":"61860.50","quantity":"1.317"},{"price":"61861.00","quantity":"0.451"},{"price":"61861.30","quantity":"0.417"},{"price":"61861.50","quantity":"0.386"},{"price":"61862.00","quantity":"0.163"},{"price":"61862.50","quantity":"0.002"},{"price":"61862.60","quantity":"0.007"},{"price":"61862.90","quantity":"0.968"},{"price":"61866.60","quantity":"0.203"},{"price":"61866.90","quantity":"0.022"},{"price":"61872.90","quantity":"0.394"},{"price":"61873.10","quantity":"0.003"},{"price":"61879.30","quantity":"1.589"},{"price":"61879.40","quantity":"0.469"},{"price":"61880.30","quantity":"1.196"},{"price":"61884.60","quantity":"0.375"},{"price":"61884.80","quantity":"0.434"},{"price":"61893.20","quantity":"0.207"},{"price":"61893.30","quantity":"0.680"},{"price":"61893.40","quantity":"0.363"},{"price":"61893.50","quantity":"0.015"},{"price":"61897.10","quantity":"0.307"},{"price":"61899.40","quantity":"2.403"},{"price":"61970.20","quantity":"0.635"},{"price":"62472.30","quantity":"0.000"},{"price":"62589.90","quantity":"0.961"},{"price":"62725.90","quantity":"0.637"},{"price":"89523.20","quantity":"0.726"}],"raw":{"e":"depthUpdate","E":1783517066904,"T":1783517066901,"s":"BTCUSDT","ps":"BTCUSDT","U":10999770581980,"u":10999770588150,"pu":10999770581814,"b":[["11353.70","1.920"],["11452.20","0.784"],["11453.70","0.374"],["11553.70","0.272"],["55668.30","0.002"],["60886.60","0.001"],["61041.90","1.145"],["61235.20","0.025"],["61295.50","2.614"],["61320.00","2.068"],["61537.60","0.348"],["61611.00","1.986"],["61771.60","34.158"],["61773.60","8.059"],["61785.90","0.255"],["61786.30","0.002"],["61789.00","1.484"],["61795.30","4.734"],["61795.40","0.003"],["61805.90","0.034"],["61825.00","1.748"],["61825.80","0.121"],["61826.90","0.003"],["61831.30","3.105"],["61832.50","0.002"],["61841.90","0.503"],["61842.00","0.377"],["61842.10","0.001"],["61842.50","0.681"],["61842.60","0.081"],["61842.80","0.000"],["61842.90","0.036"],["61843.20","0.248"],["61843.50","0.122"],["61843.70","0.004"],["61843.80","0.474"],["61844.60","0.033"],["61844.80","0.017"],["61844.90","0.033"],["61849.40","0.001"],["61853.70","2.485"]],"a":[["61853.80","7.968"],["61854.70","0.163"],["61857.90","0.000"],["61860.00","0.463"],["61860.50","1.317"],["61861.00","0.451"],["61861.30","0.417"],["61861.50","0.386"],["61862.00","0.163"],["61862.50","0.002"],["61862.60","0.007"],["61862.90","0.968"],["61866.60","0.203"],["61866.90","0.022"],["61872.90","0.394"],["61873.10","0.003"],["61879.30","1.589"],["61879.40","0.469"],["61880.30","1.196"],["61884.60","0.375"],["61884.80","0.434"],["61893.20","0.207"],["61893.30","0.680"],["61893.40","0.363"],["61893.50","0.015"],["61897.10","0.307"],["61899.40","2.403"],["61970.20","0.635"],["62472.30","0.000"],["62589.90","0.961"],["62725.90","0.637"],["89523.20","0.726"]],"st":1}}
{"schema_version":"1.3.0","event_id":"9cea3ae5-6502-4ce7-805a-fef4703cedd3","event_type":"raw.depth_update","source":"binance_market_data_recorder","venue":"binance_usdm","market_type":"perpetual_futures","symbol":"ETHUSDT","event_time_ms":1783517066968,"received_time_ms":1783517067264,"trace_id":"2c579f6f-b32f-4b98-af86-8fc7ab9e7638","first_update_id":10999770586157,"final_update_id":10999770592650,"previous_final_update_id":10999770586155,"bids":[{"price":"1211.12","quantity":"3.297"},{"price":"1216.12","quantity":"2.048"},{"price":"1216.16","quantity":"3.104"},{"price":"1221.16","quantity":"0.512"},{"price":"1562.50","quantity":"1.060"},{"price":"1562.51","quantity":"8.852"},{"price":"1666.60","quantity":"1.193"},{"price":"1700.62","quantity":"29.596"},{"price":"1701.40","quantity":"0.373"},{"price":"1713.47","quantity":"0.826"},{"price":"1714.57","quantity":"1.044"},{"price":"1730.01","quantity":"11.915"},{"price":"1732.53","quantity":"11.600"},{"price":"1733.73","quantity":"43.939"},{"price":"1734.04","quantity":"125.012"},{"price":"1734.18","quantity":"0.012"},{"price":"1734.21","quantity":"19.027"},{"price":"1734.61","quantity":"220.129"},{"price":"1734.73","quantity":"97.067"},{"price":"1734.87","quantity":"19.856"},{"price":"1734.88","quantity":"59.458"},{"price":"1734.89","quantity":"0.168"},{"price":"1734.90","quantity":"19.409"},{"price":"1735.03","quantity":"0.065"},{"price":"1735.10","quantity":"12.275"},{"price":"1735.11","quantity":"41.730"},{"price":"1735.12","quantity":"94.697"},{"price":"1735.21","quantity":"36.551"},{"price":"1735.23","quantity":"4.905"},{"price":"1735.47","quantity":"17.509"},{"price":"1735.64","quantity":"76.667"},{"price":"1735.65","quantity":"20.572"},{"price":"1735.66","quantity":"5.936"},{"price":"1735.68","quantity":"15.158"},{"price":"1735.69","quantity":"4.767"},{"price":"1735.72","quantity":"88.758"},{"price":"1735.76","quantity":"15.145"},{"price":"1735.77","quantity":"16.601"},{"price":"1735.78","quantity":"4.419"},{"price":"1735.79","quantity":"4.320"},{"price":"1735.80","quantity":"2.242"},{"price":"1735.82","quantity":"0.842"},{"price":"1735.86","quantity":"68.396"},{"price":"1735.88","quantity":"0.324"},{"price":"1735.90","quantity":"3.012"},{"price":"1735.91","quantity":"9.945"},{"price":"1735.93","quantity":"0.801"},{"price":"1735.99","quantity":"8.849"},{"price":"1736.05","quantity":"0.063"},{"price":"1736.12","quantity":"33.710"}],"asks":[{"price":"1736.13","quantity":"122.857"},{"price":"1736.15","quantity":"0.831"},{"price":"1736.16","quantity":"0.127"},{"price":"1736.19","quantity":"0.012"},{"price":"1736.20","quantity":"2.828"},{"price":"1736.21","quantity":"18.116"},{"price":"1736.22","quantity":"20.013"},{"price":"1736.23","quantity":"21.780"},{"price":"1736.25","quantity":"3.977"},{"price":"1736.33","quantity":"14.352"},{"price":"1736.36","quantity":"1.560"},{"price":"1736.37","quantity":"9.262"},{"price":"1736.39","quantity":"8.630"},{"price":"1736.44","quantity":"12.298"},{"price":"1736.46","quantity":"47.812"},{"price":"1736.48","quantity":"12.772"},{"price":"1736.49","quantity":"3.029"},{"price":"1736.57","quantity":"2.094"},{"price":"1736.63","quantity":"11.962"},{"price":"1736.64","quantity":"76.246"},{"price":"1736.72","quantity":"11.227"},{"price":"1736.85","quantity":"1.360"},{"price":"1736.86","quantity":"0.310"},{"price":"1736.90","quantity":"40.182"},{"price":"1737.11","quantity":"22.971"},{"price":"1737.13","quantity":"7.142"},{"price":"1737.14","quantity":"71.911"},{"price":"1737.35","quantity":"26.174"},{"price":"1737.39","quantity":"71.709"},{"price":"1737.43","quantity":"11.221"},{"price":"1737.52","quantity":"0.026"},{"price":"1738.58","quantity":"83.983"},{"price":"1738.72","quantity":"57.763"},{"price":"1738.74","quantity":"0.752"},{"price":"1738.78","quantity":"4.109"},{"price":"1738.88","quantity":"10.808"},{"price":"1739.41","quantity":"21.363"},{"price":"1739.42","quantity":"25.430"},{"price":"1740.16","quantity":"0.026"},{"price":"1740.21","quantity":"5.357"},{"price":"1740.58","quantity":"0.782"},{"price":"1741.75","quantity":"2.539"},{"price":"1747.12","quantity":"0.000"},{"price":"1757.13","quantity":"33.242"},{"price":"2634.92","quantity":"0.020"},{"price":"2635.01","quantity":"0.000"}],"raw":{"e":"depthUpdate","E":1783517066968,"T":1783517066967,"s":"ETHUSDT","ps":"ETHUSDT","U":10999770586157,"u":10999770592650,"pu":10999770586155,"b":[["1211.12","3.297"],["1216.12","2.048"],["1216.16","3.104"],["1221.16","0.512"],["1562.50","1.060"],["1562.51","8.852"],["1666.60","1.193"],["1700.62","29.596"],["1701.40","0.373"],["1713.47","0.826"],["1714.57","1.044"],["1730.01","11.915"],["1732.53","11.600"],["1733.73","43.939"],["1734.04","125.012"],["1734.18","0.012"],["1734.21","19.027"],["1734.61","220.129"],["1734.73","97.067"],["1734.87","19.856"],["1734.88","59.458"],["1734.89","0.168"],["1734.90","19.409"],["1735.03","0.065"],["1735.10","12.275"],["1735.11","41.730"],["1735.12","94.697"],["1735.21","36.551"],["1735.23","4.905"],["1735.47","17.509"],["1735.64","76.667"],["1735.65","20.572"],["1735.66","5.936"],["1735.68","15.158"],["1735.69","4.767"],["1735.72","88.758"],["1735.76","15.145"],["1735.77","16.601"],["1735.78","4.419"],["1735.79","4.320"],["1735.80","2.242"],["1735.82","0.842"],["1735.86","68.396"],["1735.88","0.324"],["1735.90","3.012"],["1735.91","9.945"],["1735.93","0.801"],["1735.99","8.849"],["1736.05","0.063"],["1736.12","33.710"]],"a":[["1736.13","122.857"],["1736.15","0.831"],["1736.16","0.127"],["1736.19","0.012"],["1736.20","2.828"],["1736.21","18.116"],["1736.22","20.013"],["1736.23","21.780"],["1736.25","3.977"],["1736.33","14.352"],["1736.36","1.560"],["1736.37","9.262"],["1736.39","8.630"],["1736.44","12.298"],["1736.46","47.812"],["1736.48","12.772"],["1736.49","3.029"],["1736.57","2.094"],["1736.63","11.962"],["1736.64","76.246"],["1736.72","11.227"],["1736.85","1.360"],["1736.86","0.310"],["1736.90","40.182"],["1737.11","22.971"],["1737.13","7.142"],["1737.14","71.911"],["1737.35","26.174"],["1737.39","71.709"],["1737.43","11.221"],["1737.52","0.026"],["1738.58","83.983"],["1738.72","57.763"],["1738.74","0.752"],["1738.78","4.109"],["1738.88","10.808"],["1739.41","21.363"],["1739.42","25.430"],["1740.16","0.026"],["1740.21","5.357"],["1740.58","0.782"],["1741.75","2.539"],["1747.12","0.000"],["1757.13","33.242"],["2634.92","0.020"],["2635.01","0.000"]],"st":1}}
{"schema_version":"1.3.0","event_id":"ea79dac1-d700-4bfe-bb31-02cbbc2aebdb","event_type":"raw.depth_update","source":"binance_market_data_recorder","venue":"binance_usdm","market_type":"perpetual_futures","symbol":"BTCUSDT","event_time_ms":1783517067006,"received_time_ms":1783517067270,"trace_id":"4cc170a4-c1e3-4fda-908b-a6a876298b8e","first_update_id":10999770588364,"final_update_id":10999770597811,"previous_final_update_id":10999770588150,"bids":[{"price":"1000.00","quantity":"207.692"},{"price":"11353.70","quantity":"2.192"},{"price":"11452.20","quantity":"0.512"},{"price":"11453.70","quantity":"0.527"},{"price":"11553.70","quantity":"0.119"},{"price":"55668.30","quantity":"0.002"},{"price":"59379.50","quantity":"0.001"},{"price":"60763.30","quantity":"0.822"},{"price":"61233.60","quantity":"6.985"},{"price":"61235.20","quantity":"0.025"},{"price":"61543.90","quantity":"0.001"},{"price":"61544.40","quantity":"0.013"},{"price":"61721.80","quantity":"0.000"},{"price":"61722.50","quantity":"2.363"},{"price":"61771.60","quantity":"0.001"},{"price":"61773.60","quantity":"3.357"},{"price":"61786.20","quantity":"0.032"},{"price":"61786.30","quantity":"34.159"},{"price":"61786.70","quantity":"0.089"},{"price":"61789.00","quantity":"6.403"},{"price":"61820.50","quantity":"0.369"},{"price":"61821.10","quantity":"0.307"},{"price":"61821.20","quantity":"0.101"},{"price":"61830.40","quantity":"0.050"},{"price":"61831.70","quantity":"0.227"},{"price":"61841.70","quantity":"1.592"},{"price":"61841.80","quantity":"0.005"},{"price":"61841.90","quantity":"0.484"},{"price":"61842.00","quantity":"0.369"},{"price":"61842.90","quantity":"0.000"},{"price":"61843.10","quantity":"0.053"},{"price":"61843.20","quantity":"0.308"},{"price":"61843.40","quantity":"0.066"},{"price":"61843.70","quantity":"0.003"},{"price":"61844.80","quantity":"0.025"},{"price":"61852.20","quantity":"0.630"},{"price":"61853.70","quantity":"2.486"}],"asks":[{"price":"61853.80","quantity":"8.050"},{"price":"61854.70","quantity":"0.532"},{"price":"61856.40","quantity":"0.029"},{"price":"61860.00","quantity":"0.467"},{"price":"61861.00","quantity":"0.408"},{"price":"61861.40","quantity":"0.165"},{"price":"61861.50","quantity":"0.554"},{"price":"61861.80","quantity":"0.095"},{"price":"61862.40","quantity":"0.004"},{"price":"61866.20","quantity":"0.570"},{"price":"61868.30","quantity":"0.024"},{"price":"61870.10","quantity":"0.140"},{"price":"61870.60","quantity":"0.103"},{"price":"61872.40","quantity":"0.007"},{"price":"61878.70","quantity":"0.093"},{"price":"61880.20","quantity":"0.051"},{"price":"61883.00","quantity":"0.141"},{"price":"61884.70","quantity":"0.440"},{"price":"61884.80","quantity":"0.602"},{"price":"61888.10","quantity":"0.050"},{"price":"61898.40","quantity":"5.869"},{"price":"61899.10","quantity":"5.137"},{"price":"61904.70","quantity":"0.104"},{"price":"61910.00","quantity":"23.581"},{"price":"61985.90","quantity":"0.695"},{"price":"61986.50","quantity":"0.001"},{"price":"62470.80","quantity":"0.000"},{"price":"62472.30","quantity":"0.000"},{"price":"62627.00","quantity":"3.558"},{"price":"62694.70","quantity":"0.796"}],"raw":{"e":"depthUpdate","E":1783517067006,"T":1783517067005,"s":"BTCUSDT","ps":"BTCUSDT","U":10999770588364,"u":10999770597811,"pu":10999770588150,"b":[["1000.00","207.692"],["11353.70","2.192"],["11452.20","0.512"],["11453.70","0.527"],["11553.70","0.119"],["55668.30","0.002"],["59379.50","0.001"],["60763.30","0.822"],["61233.60","6.985"],["61235.20","0.025"],["61543.90","0.001"],["61544.40","0.013"],["61721.80","0.000"],["61722.50","2.363"],["61771.60","0.001"],["61773.60","3.357"],["61786.20","0.032"],["61786.30","34.159"],["61786.70","0.089"],["61789.00","6.403"],["61820.50","0.369"],["61821.10","0.307"],["61821.20","0.101"],["61830.40","0.050"],["61831.70","0.227"],["61841.70","1.592"],["61841.80","0.005"],["61841.90","0.484"],["61842.00","0.369"],["61842.90","0.000"],["61843.10","0.053"],["61843.20","0.308"],["61843.40","0.066"],["61843.70","0.003"],["61844.80","0.025"],["61852.20","0.630"],["61853.70","2.486"]],"a":[["61853.80","8.050"],["61854.70","0.532"],["61856.40","0.029"],["61860.00","0.467"],["61861.00","0.408"],["61861.40","0.165"],["61861.50","0.554"],["61861.80","0.095"],["61862.40","0.004"],["61866.20","0.570"],["61868.30","0.024"],["61870.10","0.140"],["61870.60","0.103"],["61872.40","0.007"],["61878.70","0.093"],["61880.20","0.051"],["61883.00","0.141"],["61884.70","0.440"],["61884.80","0.602"],["61888.10","0.050"],["61898.40","5.869"],["61899.10","5.137"],["61904.70","0.104"],["61910.00","23.581"],["61985.90","0.695"],["61986.50","0.001"],["62470.80","0.000"],["62472.30","0.000"],["62627.00","3.558"],["62694.70","0.796"]],"st":1}}
{"schema_version":"1.3.0","event_id":"66ef18bf-23bf-4725-a578-91e4b3f5ec9e","event_type":"raw.depth_update","source":"binance_market_data_recorder","venue":"binance_usdm","market_type":"perpetual_futures","symbol":"ETHUSDT","event_time_ms":1783517067070,"received_time_ms":1783517067272,"trace_id":"b33e889b-de22-4eaa-86eb-52c0f4d04b41","first_update_id":10999770592694,"final_update_id":10999770604649,"previous_final_update_id":10999770592650,"bids":[{"price":"1211.12","quantity":"3.841"},{"price":"1216.12","quantity":"2.336"},{"price":"1216.16","quantity":"2.560"},{"price":"1221.16","quantity":"0.224"},{"price":"1562.50","quantity":"1.060"},{"price":"1562.51","quantity":"8.852"},{"price":"1666.60","quantity":"1.078"},{"price":"1733.76","quantity":"35.799"},{"price":"1733.77","quantity":"17.792"},{"price":"1734.01","quantity":"17.457"},{"price":"1734.06","quantity":"474.207"},{"price":"1734.12","quantity":"113.048"},{"price":"1734.50","quantity":"229.164"},{"price":"1734.57","quantity":"51.615"},{"price":"1734.61","quantity":"0.258"},{"price":"1734.63","quantity":"19.810"},{"price":"1734.87","quantity":"19.838"},{"price":"1734.88","quantity":"59.476"},{"price":"1735.00","quantity":"217.843"},{"price":"1735.07","quantity":"5.945"},{"price":"1735.09","quantity":"1.235"},{"price":"1735.10","quantity":"23.275"},{"price":"1735.11","quantity":"44.574"},{"price":"1735.16","quantity":"4.709"},{"price":"1735.43","quantity":"4.065"},{"price":"1735.62","quantity":"17.933"},{"price":"1735.66","quantity":"0.169"},{"price":"1735.75","quantity":"71.556"},{"price":"1735.77","quantity":"18.047"},{"price":"1735.78","quantity":"1.640"},{"price":"1735.80","quantity":"2.130"},{"price":"1735.86","quantity":"77.045"},{"price":"1735.87","quantity":"1.139"},{"price":"1735.89","quantity":"5.536"},{"price":"1735.93","quantity":"22.985"},{"price":"1735.94","quantity":"7.074"},{"price":"1735.95","quantity":"3.530"},{"price":"1735.96","quantity":"2.280"},{"price":"1735.98","quantity":"1.123"},{"price":"1735.99","quantity":"8.758"},{"price":"1736.02","quantity":"0.061"},{"price":"1736.12","quantity":"21.486"}],"asks":[{"price":"1736.13","quantity":"123.840"},{"price":"1736.15","quantity":"0.012"},{"price":"1736.16","quantity":"0.038"},{"price":"1736.20","quantity":"3.980"},{"price":"1736.25","quantity":"4.477"},{"price":"1736.28","quantity":"31.446"},{"price":"1736.30","quantity":"13.533"},{"price":"1736.36","quantity":"0.560"},{"price":"1736.37","quantity":"7.821"},{"price":"1736.39","quantity":"33.529"},{"price":"1736.44","quantity":"10.857"},{"price":"1736.45","quantity":"79.035"},{"price":"1736.47","quantity":"15.266"},{"price":"1736.48","quantity":"12.772"},{"price":"1736.53","quantity":"3.113"},{"price":"1736.56","quantity":"10.776"},{"price":"1736.63","quantity":"10.521"},{"price":"1736.72","quantity":"9.786"},{"price":"1736.91","quantity":"69.817"},{"price":"1737.11","quantity":"21.277"},{"price":"1737.71","quantity":"0.042"},{"price":"1737.83","quantity":"33.086"},{"price":"1737.87","quantity":"9.593"},{"price":"1738.20","quantity":"407.555"},{"price":"1738.25","quantity":"2.878"},{"price":"1738.62","quantity":"13.195"},{"price":"1739.61","quantity":"23.070"},{"price":"1739.64","quantity":"91.236"},{"price":"1740.48","quantity":"19.360"},{"price":"1740.51","quantity":"30.571"},{"price":"1741.34","quantity":"18.784"},{"price":"1741.37","quantity":"9.895"},{"price":"1742.21","quantity":"52.963"},{"price":"1742.24","quantity":"19.942"},{"price":"1743.08","quantity":"7.051"},{"price":"1743.11","quantity":"0.000"},{"price":"2236.18","quantity":"0.000"},{"price":"2634.91","quantity":"0.001"},{"price":"2635.00","quantity":"0.193"}],"raw":{"e":"depthUpdate","E":1783517067070,"T":1783517067069,"s":"ETHUSDT","ps":"ETHUSDT","U":10999770592694,"u":10999770604649,"pu":10999770592650,"b":[["1211.12","3.841"],["1216.12","2.336"],["1216.16","2.560"],["1221.16","0.224"],["1562.50","1.060"],["1562.51","8.852"],["1666.60","1.078"],["1733.76","35.799"],["1733.77","17.792"],["1734.01","17.457"],["1734.06","474.207"],["1734.12","113.048"],["1734.50","229.164"],["1734.57","51.615"],["1734.61","0.258"],["1734.63","19.810"],["1734.87","19.838"],["1734.88","59.476"],["1735.00","217.843"],["1735.07","5.945"],["1735.09","1.235"],["1735.10","23.275"],["1735.11","44.574"],["1735.16","4.709"],["1735.43","4.065"],["1735.62","17.933"],["1735.66","0.169"],["1735.75","71.556"],["1735.77","18.047"],["1735.78","1.640"],["1735.80","2.130"],["1735.86","77.045"],["1735.87","1.139"],["1735.89","5.536"],["1735.93","22.985"],["1735.94","7.074"],["1735.95","3.530"],["1735.96","2.280"],["1735.98","1.123"],["1735.99","8.758"],["1736.02","0.061"],["1736.12","21.486"]],"a":[["1736.13","123.840"],["1736.15","0.012"],["1736.16","0.038"],["1736.20","3.980"],["1736.25","4.477"],["1736.28","31.446"],["1736.30","13.533"],["1736.36","0.560"],["1736.37","7.821"],["1736.39","33.529"],["1736.44","10.857"],["1736.45","79.035"],["1736.47","15.266"],["1736.48","12.772"],["1736.53","3.113"],["1736.56","10.776"],["1736.63","10.521"],["1736.72","9.786"],["1736.91","69.817"],["1737.11","21.277"],["1737.71","0.042"],["1737.83","33.086"],["1737.87","9.593"],["1738.20","407.555"],["1738.25","2.878"],["1738.62","13.195"],["1739.61","23.070"],["1739.64","91.236"],["1740.48","19.360"],["1740.51","30.571"],["1741.34","18.784"],["1741.37","9.895"],["1742.21","52.963"],["1742.24","19.942"],["1743.08","7.051"],["1743.11","0.000"],["2236.18","0.000"],["2634.91","0.001"],["2635.00","0.193"]],"st":1}}
{"schema_version":"1.3.0","event_id":"733c7fa3-7c0a-4ca7-87d5-f307d325b76b","event_type":"raw.depth_update","source":"binance_market_data_recorder","venue":"binance_usdm","market_type":"perpetual_futures","symbol":"BTCUSDT","event_time_ms":1783517067108,"received_time_ms":1783517067273,"trace_id":"0718a334-2307-44fb-be24-46358db2d5c4","first_update_id":10999770597875,"final_update_id":10999770608672,"previous_final_update_id":10999770597811,"bids":[{"price":"1000.00","quantity":"207.692"},{"price":"11353.70","quantity":"2.240"},{"price":"11452.20","quantity":"0.352"},{"price":"11453.70","quantity":"0.663"},{"price":"11552.20","quantity":"1.037"},{"price":"11553.70","quantity":"0.000"},{"price":"11753.70","quantity":"0.112"},{"price":"55668.30","quantity":"0.002"},{"price":"58468.40","quantity":"0.002"},{"price":"59379.50","quantity":"0.004"},{"price":"60895.00","quantity":"1.312"},{"price":"61022.20","quantity":"0.501"},{"price":"61134.30","quantity":"0.000"},{"price":"61235.20","quantity":"0.025"},{"price":"61287.00","quantity":"0.000"},{"price":"61750.50","quantity":"0.000"},{"price":"61785.60","quantity":"0.041"},{"price":"61809.00","quantity":"0.164"},{"price":"61816.10","quantity":"0.047"},{"price":"61819.50","quantity":"0.702"},{"price":"61820.60","quantity":"0.140"},{"price":"61821.10","quantity":"0.367"},{"price":"61824.40","quantity":"0.061"},{"price":"61832.10","quantity":"0.065"},{"price":"61837.00","quantity":"1.002"},{"price":"61840.80","quantity":"0.100"},{"price":"61841.20","quantity":"0.092"},{"price":"61841.80","quantity":"0.065"},{"price":"61842.60","quantity":"0.081"},{"price":"61852.30","quantity":"0.002"},{"price":"61852.80","quantity":"0.002"}],"asks":[{"price":"61853.80","quantity":"8.059"},{"price":"61854.50","quantity":"0.028"},{"price":"61858.20","quantity":"0.130"},{"price":"61860.00","quantity":"0.463"},{"price":"61864.90","quantity":"0.054"},{"price":"61866.20","quantity":"0.566"},{"price":"61868.30","quantity":"0.009"},{"price":"61872.40","quantity":"0.003"},{"price":"61899.70","quantity":"0.089"},{"price":"61904.50","quantity":"0.282"},{"price":"61904.60","quantity":"4.290"},{"price":"61904.70","quantity":"0.003"},{"price":"61904.80","quantity":"0.386"},{"price":"62472.30","quantity":"0.002"},{"price":"62899.10","quantity":"0.480"},{"price":"89523.20","quantity":"0.732"}],"raw":{"e":"depthUpdate","E":1783517067108,"T":1783517067107,"s":"BTCUSDT","ps":"BTCUSDT","U":10999770597875,"u":10999770608672,"pu":10999770597811,"b":[["1000.00","207.692"],["11353.70","2.240"],["11452.20","0.352"],["11453.70","0.663"],["11552.20","1.037"],["11553.70","0.000"],["11753.70","0.112"],["55668.30","0.002"],["58468.40","0.002"],["59379.50","0.004"],["60895.00","1.312"],["61022.20","0.501"],["61134.30","0.000"],["61235.20","0.025"],["61287.00","0.000"],["61750.50","0.000"],["61785.60","0.041"],["61809.00","0.164"],["61816.10","0.047"],["61819.50","0.702"],["61820.60","0.140"],["61821.10","0.367"],["61824.40","0.061"],["61832.10","0.065"],["61837.00","1.002"],["61840.80","0.100"],["61841.20","0.092"],["61841.80","0.065"],["61842.60","0.081"],["61852.30","0.002"],["61852.80","0.002"]],"a":[["61853.80","8.059"],["61854.50","0.028"],["61858.20","0.130"],["61860.00","0.463"],["61864.90","0.054"],["61866.20","0.566"],["61868.30","0.009"],["61872.40","0.003"],["61899.70","0.089"],["61904.50","0.282"],["61904.60","4.290"],["61904.70","0.003"],["61904.80","0.386"],["62472.30","0.002"],["62899.10","0.480"],["89523.20","0.732"]],"st":1}}
{"schema_version":"1.3.0","event_id":"160339e0-dbf3-45b5-98e7-742fc404ad75","event_type":"raw.trade","source":"binance_market_data_recorder","venue":"binance_usdm","market_type":"perpetual_futures","symbol":"ETHUSDT","event_time_ms":1783517067124,"received_time_ms":1783517067275,"trace_id":"e6377dd8-3a5d-4ae9-b0c6-05b3008820d2","trade_id":8429826853,"price":"1736.13","quantity":"0.012","trade_time_ms":1783517067123,"is_buyer_maker":false,"aggressor_side":"buy","raw":{"e":"trade","E":1783517067124,"T":1783517067123,"s":"ETHUSDT","t":8429826853,"p":"1736.13","q":"0.012","X":"MARKET","m":false,"st":1}}
{"schema_version":"1.3.0","event_id":"49cbdb0b-afb9-492f-960f-c002965ae937","event_type":"raw.depth_update","source":"binance_market_data_recorder","venue":"binance_usdm","market_type":"perpetual_futures","symbol":"ETHUSDT","event_time_ms":1783517067172,"received_time_ms":1783517067276,"trace_id":"57e70dad-ee7b-4e8a-807c-b6b2a0ae6b8f","first_update_id":10999770604871,"final_update_id":10999770612942,"previous_final_update_id":10999770604649,"bids":[{"price":"200.00","quantity":"7.594"},{"price":"1211.12","quantity":"4.417"},{"price":"1216.12","quantity":"2.560"},{"price":"1216.16","quantity":"2.016"},{"price":"1216.27","quantity":"0.244"},{"price":"1221.16","quantity":"0.000"},{"price":"1562.50","quantity":"1.060"},{"price":"1562.51","quantity":"8.738"},{"price":"1666.60","quantity":"1.193"},{"price":"1701.40","quantity":"0.402"},{"price":"1708.13","quantity":"52.333"},{"price":"1708.36","quantity":"1.189"},{"price":"1713.52","quantity":"27.295"},{"price":"1713.56","quantity":"81.234"},{"price":"1727.47","quantity":"0.000"},{"price":"1729.72","quantity":"0.082"},{"price":"1732.63","quantity":"3.761"},{"price":"1733.74","quantity":"16.412"},{"price":"1733.77","quantity":"18.392"},{"price":"1734.06","quantity":"54.181"},{"price":"1734.12","quantity":"55.897"},{"price":"1734.21","quantity":"26.784"},{"price":"1734.51","quantity":"13.293"},{"price":"1735.02","quantity":"55.437"},{"price":"1735.03","quantity":"1.016"},{"price":"1735.08","quantity":"6.025"},{"price":"1735.12","quantity":"95.497"},{"price":"1735.13","quantity":"3.178"},{"price":"1735.14","quantity":"9.518"},{"price":"1735.21","quantity":"34.639"},{"price":"1735.22","quantity":"16.399"},{"price":"1735.44","quantity":"27.761"},{"price":"1735.60","quantity":"4.613"},{"price":"1735.77","quantity":"16.601"},{"price":"1736.12","quantity":"21.543"}],"asks":[{"price":"1736.13","quantity":"123.828"},{"price":"1736.28","quantity":"31.469"},{"price":"1736.32","quantity":"0.174"},{"price":"1736.35","quantity":"4.594"},{"price":"1736.36","quantity":"5.168"},{"price":"1736.39","quantity":"28.921"},{"price":"1736.40","quantity":"21.374"},{"price":"1736.44","quantity":"9.416"},{"price":"1736.53","quantity":"1.419"},{"price":"1736.56","quantity":"9.082"},{"price":"1736.62","quantity":"0.755"},{"price":"1736.74","quantity":"41.892"},{"price":"1736.88","quantity":"3.731"},{"price":"1736.91","quantity":"68.123"},{"price":"1737.02","quantity":"25.859"},{"price":"1737.03","quantity":"84.325"},{"price":"1737.11","quantity":"22.971"},{"price":"1737.14","quantity":"72.198"},{"price":"1737.16","quantity":"11.330"},{"price":"1737.17","quantity":"1.605"},{"price":"1737.60","quantity":"6.285"},{"price":"1737.83","quantity":"34.780"},{"price":"1738.08","quantity":"1.684"},{"price":"1738.71","quantity":"38.346"},{"price":"1739.96","quantity":"19.275"},{"price":"1748.32","quantity":"2.989"},{"price":"1762.17","quantity":"38.828"},{"price":"1763.65","quantity":"0.000"},{"price":"1770.03","quantity":"29.906"},{"price":"2634.89","quantity":"0.001"},{"price":"2634.90","quantity":"0.001"},{"price":"2634.98","quantity":"0.000"},{"price":"2634.99","quantity":"0.000"}],"raw":{"e":"depthUpdate","E":1783517067172,"T":1783517067171,"s":"ETHUSDT","ps":"ETHUSDT","U":10999770604871,"u":10999770612942,"pu":10999770604649,"b":[["200.00","7.594"],["1211.12","4.417"],["1216.12","2.560"],["1216.16","2.016"],["1216.27","0.244"],["1221.16","0.000"],["1562.50","1.060"],["1562.51","8.738"],["1666.60","1.193"],["1701.40","0.402"],["1708.13","52.333"],["1708.36","1.189"],["1713.52","27.295"],["1713.56","81.234"],["1727.47","0.000"],["1729.72","0.082"],["1732.63","3.761"],["1733.74","16.412"],["1733.77","18.392"],["1734.06","54.181"],["1734.12","55.897"],["1734.21","26.784"],["1734.51","13.293"],["1735.02","55.437"],["1735.03","1.016"],["1735.08","6.025"],["1735.12","95.497"],["1735.13","3.178"],["1735.14","9.518"],["1735.21","34.639"],["1735.22","16.399"],["1735.44","27.761"],["1735.60","4.613"],["1735.77","16.601"],["1736.12","21.543"]],"a":[["1736.13","123.828"],["1736.28","31.469"],["1736.32","0.174"],["1736.35","4.594"],["1736.36","5.168"],["1736.39","28.921"],["1736.40","21.374"],["1736.44","9.416"],["1736.53","1.419"],["1736.56","9.082"],["1736.62","0.755"],["1736.74","41.892"],["1736.88","3.731"],["1736.91","68.123"],["1737.02","25.859"],["1737.03","84.325"],["1737.11","22.971"],["1737.14","72.198"],["1737.16","11.330"],["1737.17","1.605"],["1737.60","6.285"],["1737.83","34.780"],["1738.08","1.684"],["1738.71","38.346"],["1739.96","19.275"],["1748.32","2.989"],["1762.17","38.828"],["1763.65","0.000"],["1770.03","29.906"],["2634.89","0.001"],["2634.90","0.001"],["2634.98","0.000"],["2634.99","0.000"]],"st":1}}
{"schema_version":"1.3.0","event_id":"95bfc403-d073-42cd-8c92-b2bd77f9429a","event_type":"raw.depth_update","source":"binance_market_data_recorder","venue":"binance_usdm","market_type":"perpetual_futures","symbol":"BTCUSDT","event_time_ms":1783517067210,"received_time_ms":1783517067280,"trace_id":"966b9629-d3c7-4571-a487-2cda91d399c8","first_update_id":10999770608744,"final_update_id":10999770615846,"previous_final_update_id":10999770608672,"bids":[{"price":"11353.70","quantity":"2.224"},{"price":"11452.20","quantity":"0.224"},{"price":"11453.70","quantity":"0.816"},{"price":"11552.20","quantity":"0.884"},{"price":"11753.70","quantity":"0.256"},{"price":"55668.30","quantity":"0.002"},{"price":"58761.00","quantity":"0.003"},{"price":"59379.50","quantity":"0.001"},{"price":"61235.20","quantity":"0.025"},{"price":"61295.50","quantity":"3.755"},{"price":"61544.40","quantity":"0.003"},{"price":"61757.60","quantity":"0.049"},{"price":"61786.50","quantity":"0.054"},{"price":"61799.90","quantity":"0.018"},{"price":"61816.10","quantity":"0.000"},{"price":"61819.90","quantity":"0.181"},{"price":"61820.20","quantity":"0.194"},{"price":"61820.50","quantity":"0.429"},{"price":"61821.10","quantity":"0.427"},{"price":"61835.10","quantity":"1.712"},{"price":"61835.20","quantity":"0.002"},{"price":"61844.40","quantity":"0.172"},{"price":"61853.40","quantity":"0.006"},{"price":"61853.70","quantity":"2.486"}],"asks":[{"price":"61853.80","quantity":"8.450"},{"price":"61870.60","quantity":"0.100"},{"price":"61871.90","quantity":"0.364"},{"price":"61893.50","quantity":"0.388"},{"price":"61897.10","quantity":"0.309"},{"price":"61898.20","quantity":"0.265"},{"price":"61898.70","quantity":"0.226"},{"price":"62472.30","quantity":"0.000"},{"price":"62675.30","quantity":"0.000"},{"price":"62722.30","quantity":"0.000"},{"price":"63823.00","quantity":"0.600"}],"raw":{"e":"depthUpdate","E":1783517067210,"T":1783517067209,"s":"BTCUSDT","ps":"BTCUSDT","U":10999770608744,"u":10999770615846,"pu":10999770608672,"b":[["11353.70","2.224"],["11452.20","0.224"],["11453.70","0.816"],["11552.20","0.884"],["11753.70","0.256"],["55668.30","0.002"],["58761.00","0.003"],["59379.50","0.001"],["61235.20","0.025"],["61295.50","3.755"],["61544.40","0.003"],["61757.60","0.049"],["61786.50","0.054"],["61799.90","0.018"],["61816.10","0.000"],["61819.90","0.181"],["61820.20","0.194"],["61820.50","0.429"],["61821.10","0.427"],["61835.10","1.712"],["61835.20","0.002"],["61844.40","0.172"],["61853.40","0.006"],["61853.70","2.486"]],"a":[["61853.80","8.450"],["61870.60","0.100"],["61871.90","0.364"],["61893.50","0.388"],["61897.10","0.309"],["61898.20","0.265"],["61898.70","0.226"],["62472.30","0.000"],["62675.30","0.000"],["62722.30","0.000"],["63823.00","0.600"]],"st":1}}
{"schema_version":"1.3.0","event_id":"d9b48f02-879c-44d8-8b48-90dc555414ce","event_type":"raw.trade","source":"binance_market_data_recorder","venue":"binance_usdm","market_type":"perpetual_futures","symbol":"BTCUSDT","event_time_ms":1783517067221,"received_time_ms":1783517067281,"trace_id":"b23101cc-89bf-458a-b747-8ee979efa174","trade_id":7881418050,"price":"61853.70","quantity":"0.001","trade_time_ms":1783517067221,"is_buyer_maker":true,"aggressor_side":"sell","raw":{"e":"trade","E":1783517067221,"T":1783517067221,"s":"BTCUSDT","t":7881418050,"p":"61853.70","q":"0.001","X":"MARKET","m":true,"st":1}}
{"schema_version":"1.3.0","event_id":"2df152ff-45f6-4881-a9f2-aaab9e7f8c95","event_type":"raw.depth_update","source":"binance_market_data_recorder","venue":"binance_usdm","market_type":"perpetual_futures","symbol":"ETHUSDT","event_time_ms":1783517067274,"received_time_ms":1783517067295,"trace_id":"3f91cedf-487d-46af-b38d-848ee3c4674e","first_update_id":10999770612990,"final_update_id":10999770622458,"previous_final_update_id":10999770612942,"bids":[{"price":"1211.12","quantity":"5.249"},{"price":"1216.16","quantity":"1.344"},{"price":"1216.27","quantity":"0.084"},{"price":"1562.50","quantity":"1.060"},{"price":"1562.51","quantity":"8.738"},{"price":"1698.07","quantity":"0.145"},{"price":"1701.40","quantity":"0.373"},{"price":"1729.70","quantity":"2790.824"},{"price":"1734.06","quantity":"474.207"},{"price":"1734.12","quantity":"111.586"},{"price":"1734.24","quantity":"1.474"},{"price":"1734.28","quantity":"22.858"},{"price":"1734.29","quantity":"8.642"},{"price":"1734.38","quantity":"13.652"},{"price":"1734.40","quantity":"223.405"},{"price":"1734.41","quantity":"80.333"},{"price":"1734.50","quantity":"9.332"},{"price":"1734.57","quantity":"29.351"},{"price":"1734.61","quantity":"0.240"},{"price":"1734.66","quantity":"1.206"},{"price":"1735.01","quantity":"19.586"},{"price":"1735.08","quantity":"6.825"},{"price":"1735.11","quantity":"45.374"},{"price":"1735.25","quantity":"39.105"},{"price":"1735.35","quantity":"20.776"},{"price":"1735.69","quantity":"4.849"},{"price":"1735.70","quantity":"28.978"},{"price":"1735.74","quantity":"29.064"},{"price":"1735.75","quantity":"71.444"},{"price":"1735.76","quantity":"11.833"},{"price":"1735.77","quantity":"16.201"},{"price":"1735.86","quantity":"68.396"},{"price":"1735.87","quantity":"1.139"},{"price":"1735.90","quantity":"25.196"},{"price":"1735.93","quantity":"4.113"},{"price":"1735.94","quantity":"3.390"},{"price":"1735.95","quantity":"3.824"},{"price":"1735.96","quantity":"0.552"},{"price":"1735.97","quantity":"3.095"},{"price":"1735.99","quantity":"6.258"},{"price":"1736.11","quantity":"0.749"},{"price":"1736.12","quantity":"7.951"}],"asks":[{"price":"1736.13","quantity":"132.837"},{"price":"1736.16","quantity":"0.255"},{"price":"1736.18","quantity":"1.769"},{"price":"1736.22","quantity":"24.022"},{"price":"1736.29","quantity":"1.210"},{"price":"1736.36","quantity":"5.168"},{"price":"1736.37","quantity":"7.833"},{"price":"1736.76","quantity":"18.794"},{"price":"1736.81","quantity":"19.320"},{"price":"1736.88","quantity":"3.621"},{"price":"1736.90","quantity":"40.757"},{"price":"1737.00","quantity":"71.577"},{"price":"1737.11","quantity":"21.277"},{"price":"1737.13","quantity":"7.142"},{"price":"1737.16","quantity":"11.330"},{"price":"1737.26","quantity":"5.190"},{"price":"1737.37","quantity":"40.106"},{"price":"1737.50","quantity":"67.957"},{"price":"1737.51","quantity":"11.738"},{"price":"1737.60","quantity":"4.591"},{"price":"1737.69","quantity":"28.817"},{"price":"1738.07","quantity":"34.583"},{"price":"1738.15","quantity":"24.452"},{"price":"1738.37","quantity":"88.051"},{"price":"1738.41","quantity":"5.890"},{"price":"1738.56","quantity":"1.996"},{"price":"1744.82","quantity":"0.066"},{"price":"1747.12","quantity":"15.000"},{"price":"1749.44","quantity":"0.057"},{"price":"1763.90","quantity":"15.787"},{"price":"1770.18","quantity":"56.565"},{"price":"1776.06","quantity":"11.248"},{"price":"2634.88","quantity":"0.001"},{"price":"2634.97","quantity":"0.000"}],"raw":{"e":"depthUpdate","E":1783517067274,"T":1783517067273,"s":"ETHUSDT","ps":"ETHUSDT","U":10999770612990,"u":10999770622458,"pu":10999770612942,"b":[["1211.12","5.249"],["1216.16","1.344"],["1216.27","0.084"],["1562.50","1.060"],["1562.51","8.738"],["1698.07","0.145"],["1701.40","0.373"],["1729.70","2790.824"],["1734.06","474.207"],["1734.12","111.586"],["1734.24","1.474"],["1734.28","22.858"],["1734.29","8.642"],["1734.38","13.652"],["1734.40","223.405"],["1734.41","80.333"],["1734.50","9.332"],["1734.57","29.351"],["1734.61","0.240"],["1734.66","1.206"],["1735.01","19.586"],["1735.08","6.825"],["1735.11","45.374"],["1735.25","39.105"],["1735.35","20.776"],["1735.69","4.849"],["1735.70","28.978"],["1735.74","29.064"],["1735.75","71.444"],["1735.76","11.833"],["1735.77","16.201"],["1735.86","68.396"],["1735.87","1.139"],["1735.90","25.196"],["1735.93","4.113"],["1735.94","3.390"],["1735.95","3.824"],["1735.96","0.552"],["1735.97","3.095"],["1735.99","6.258"],["1736.11","0.749"],["1736.12","7.951"]],"a":[["1736.13","132.837"],["1736.16","0.255"],["1736.18","1.769"],["1736.22","24.022"],["1736.29","1.210"],["1736.36","5.168"],["1736.37","7.833"],["1736.76","18.794"],["1736.81","19.320"],["1736.88","3.621"],["1736.90","40.757"],["1737.00","71.577"],["1737.11","21.277"],["1737.13","7.142"],["1737.16","11.330"],["1737.26","5.190"],["1737.37","40.106"],["1737.50","67.957"],["1737.51","11.738"],["1737.60","4.591"],["1737.69","28.817"],["1738.07","34.583"],["1738.15","24.452"],["1738.37","88.051"],["1738.41","5.890"],["1738.56","1.996"],["1744.82","0.066"],["1747.12","15.000"],["1749.44","0.057"],["1763.90","15.787"],["1770.18","56.565"],["1776.06","11.248"],["2634.88","0.001"],["2634.97","0.000"]],"st":1}}
{"schema_version":"1.3.0","event_id":"6f9e981f-5f0f-488b-bd8d-bd05fbbe09d3","event_type":"raw.depth_update","source":"binance_market_data_recorder","venue":"binance_usdm","market_type":"perpetual_futures","symbol":"BTCUSDT","event_time_ms":1783517067312,"received_time_ms":1783517067309,"trace_id":"fdaa6e7e-6e34-41d8-9530-d286e5f8dd2f","first_update_id":10999770615874,"final_update_id":10999770625502,"previous_final_update_id":10999770615846,"bids":[{"price":"1000.00","quantity":"207.692"},{"price":"11353.70","quantity":"2.240"},{"price":"11452.20","quantity":"0.080"},{"price":"11453.70","quantity":"0.952"},{"price":"11552.20","quantity":"0.748"},{"price":"11753.70","quantity":"0.384"},{"price":"55668.30","quantity":"0.002"},{"price":"58759.60","quantity":"0.011"},{"price":"58761.00","quantity":"0.006"},{"price":"60616.70","quantity":"0.014"},{"price":"61013.90","quantity":"0.825"},{"price":"61055.20","quantity":"0.002"},{"price":"61235.20","quantity":"0.025"},{"price":"61544.40","quantity":"0.013"},{"price":"61584.20","quantity":"0.076"},{"price":"61585.40","quantity":"0.008"},{"price":"61722.50","quantity":"2.143"},{"price":"61722.70","quantity":"0.830"},{"price":"61748.10","quantity":"0.006"},{"price":"61748.90","quantity":"0.284"},{"price":"61775.20","quantity":"0.055"},{"price":"61819.90","quantity":"0.241"},{"price":"61820.10","quantity":"10.723"},{"price":"61820.20","quantity":"0.254"},{"price":"61822.80","quantity":"0.400"},{"price":"61823.80","quantity":"0.009"},{"price":"61824.40","quantity":"0.121"},{"price":"61828.50","quantity":"0.003"},{"price":"61833.40","quantity":"0.008"},{"price":"61834.00","quantity":"1.402"},{"price":"61838.00","quantity":"0.000"},{"price":"61838.70","quantity":"0.127"},{"price":"61842.00","quantity":"0.470"},{"price":"61842.10","quantity":"0.102"},{"price":"61842.50","quantity":"0.682"},{"price":"61842.60","quantity":"0.089"},{"price":"61843.10","quantity":"0.052"},{"price":"61844.80","quantity":"0.017"},{"price":"61848.80","quantity":"0.002"},{"price":"61850.20","quantity":"0.002"},{"price":"61853.70","quantity":"2.473"}],"asks":[{"price":"61853.80","quantity":"8.448"},{"price":"61856.20","quantity":"0.001"},{"price":"61856.90","quantity":"0.289"},{"price":"61985.80","quantity":"0.744"},{"price":"61985.90","quantity":"0.000"},{"price":"62026.40","quantity":"0.791"},{"price":"62027.20","quantity":"0.003"},{"price":"62136.00","quantity":"0.034"},{"price":"62451.50","quantity":"0.000"},{"price":"62472.30","quantity":"0.000"},{"price":"89523.20","quantity":"0.738"}],"raw":{"e":"depthUpdate","E":1783517067312,"T":1783517067310,"s":"BTCUSDT","ps":"BTCUSDT","U":10999770615874,"u":10999770625502,"pu":10999770615846,"b":[["1000.00","207.692"],["11353.70","2.240"],["11452.20","0.080"],["11453.70","0.952"],["11552.20","0.748"],["11753.70","0.384"],["55668.30","0.002"],["58759.60","0.011"],["58761.00","0.006"],["60616.70","0.014"],["61013.90","0.825"],["61055.20","0.002"],["61235.20","0.025"],["61544.40","0.013"],["61584.20","0.076"],["61585.40","0.008"],["61722.50","2.143"],["61722.70","0.830"],["61748.10","0.006"],["61748.90","0.284"],["61775.20","0.055"],["61819.90","0.241"],["61820.10","10.723"],["61820.20","0.254"],["61822.80","0.400"],["61823.80","0.009"],["61824.40","0.121"],["61828.50","0.003"],["61833.40","0.008"],["61834.00","1.402"],["61838.00","0.000"],["61838.70","0.127"],["61842.00","0.470"],["61842.10","0.102"],["61842.50","0.682"],["61842.60","0.089"],["61843.10","0.052"],["61844.80","0.017"],["61848.80","0.002"],["61850.20","0.002"],["61853.70","2.473"]],"a":[["61853.80","8.448"],["61856.20","0.001"],["61856.90","0.289"],["61985.80","0.744"],["61985.90","0.000"],["62026.40","0.791"],["62027.20","0.003"],["62136.00","0.034"],["62451.50","0.000"],["62472.30","0.000"],["89523.20","0.738"]],"st":1}}
{"schema_version":"1.3.0","event_id":"12208af8-3e15-4fd5-8c65-b74770e6919e","event_type":"raw.trade","source":"binance_market_data_recorder","venue":"binance_usdm","market_type":"perpetual_futures","symbol":"BTCUSDT","event_time_ms":1783517067365,"received_time_ms":1783517067361,"trace_id":"615a03c7-5a57-4380-8830-b548dddde065","trade_id":7881418051,"price":"61853.70","quantity":"0.003","trade_time_ms":1783517067365,"is_buyer_maker":true,"aggressor_side":"sell","raw":{"e":"trade","E":1783517067365,"T":1783517067365,"s":"BTCUSDT","t":7881418051,"p":"61853.70","q":"0.003","X":"MARKET","m":true,"st":1}}
{"schema_version":"1.3.0","event_id":"df13f258-6728-4383-b281-2616fbc89fde","event_type":"raw.trade","source":"binance_market_data_recorder","venue":"binance_usdm","market_type":"perpetual_futures","symbol":"ETHUSDT","event_time_ms":1783517067366,"received_time_ms":1783517067362,"trace_id":"1190b1a0-fb31-48c5-8e32-ffbe8e387137","trade_id":8429826854,"price":"1736.12","quantity":"0.655","trade_time_ms":1783517067366,"is_buyer_maker":true,"aggressor_side":"sell","raw":{"e":"trade","E":1783517067366,"T":1783517067366,"s":"ETHUSDT","t":8429826854,"p":"1736.12","q":"0.655","X":"MARKET","m":true,"st":1}}
{"schema_version":"1.3.0","event_id":"16ef6b79-40a3-4e7e-871d-10d939db243f","event_type":"raw.trade","source":"binance_market_data_recorder","venue":"binance_usdm","market_type":"perpetual_futures","symbol":"ETHUSDT","event_time_ms":1783517067366,"received_time_ms":1783517067363,"trace_id":"e4012507-e523-4454-91ce-82f86b9f9330","trade_id":8429826855,"price":"1736.12","quantity":"0.338","trade_time_ms":1783517067366,"is_buyer_maker":true,"aggressor_side":"sell","raw":{"e":"trade","E":1783517067366,"T":1783517067366,"s":"ETHUSDT","t":8429826855,"p":"1736.12","q":"0.338","X":"MARKET","m":true,"st":1}}
{"schema_version":"1.3.0","event_id":"b7b2bae4-a4cb-4247-acb4-81c83bc678cb","event_type":"raw.depth_update","source":"binance_market_data_recorder","venue":"binance_usdm","market_type":"perpetual_futures","symbol":"ETHUSDT","event_time_ms":1783517067376,"received_time_ms":1783517067371,"trace_id":"a1abb571-cc09-43bc-ac61-17b1141101a2","first_update_id":10999770622549,"final_update_id":10999770631686,"previous_final_update_id":10999770622458,"bids":[{"price":"1211.12","quantity":"6.049"},{"price":"1216.16","quantity":"0.544"},{"price":"1562.50","quantity":"1.060"},{"price":"1562.51","quantity":"8.880"},{"price":"1666.60","quantity":"1.078"},{"price":"1701.40","quantity":"0.402"},{"price":"1714.43","quantity":"8.763"},{"price":"1720.48","quantity":"0.064"},{"price":"1727.44","quantity":"0.012"},{"price":"1734.06","quantity":"54.181"},{"price":"1734.12","quantity":"55.897"},{"price":"1734.18","quantity":"0.012"},{"price":"1734.21","quantity":"79.952"},{"price":"1734.24","quantity":"1.474"},{"price":"1734.29","quantity":"8.551"},{"price":"1734.30","quantity":"21.202"},{"price":"1734.35","quantity":"8.764"},{"price":"1734.36","quantity":"2.988"},{"price":"1734.37","quantity":"0.168"},{"price":"1734.38","quantity":"56.188"},{"price":"1734.39","quantity":"19.527"},{"price":"1734.40","quantity":"3.664"},{"price":"1734.41","quantity":"80.351"},{"price":"1734.46","quantity":"25.640"},{"price":"1734.63","quantity":"239.299"},{"price":"1734.75","quantity":"287.604"},{"price":"1734.84","quantity":"272.872"},{"price":"1735.00","quantity":"216.833"},{"price":"1735.02","quantity":"53.535"},{"price":"1735.09","quantity":"2.035"},{"price":"1735.10","quantity":"24.075"},{"price":"1735.12","quantity":"96.297"},{"price":"1735.18","quantity":"2.293"},{"price":"1735.25","quantity":"0.169"},{"price":"1735.27","quantity":"69.112"},{"price":"1735.32","quantity":"65.935"},{"price":"1735.33","quantity":"16.529"},{"price":"1735.34","quantity":"0.110"},{"price":"1735.35","quantity":"20.788"},{"price":"1735.58","quantity":"5.861"},{"price":"1735.61","quantity":"8.709"},{"price":"1735.62","quantity":"32.166"},{"price":"1735.65","quantity":"20.679"},{"price":"1735.66","quantity":"29.004"},{"price":"1735.68","quantity":"15.094"},{"price":"1735.70","quantity":"0.037"},{"price":"1735.76","quantity":"11.257"},{"price":"1735.77","quantity":"17.647"},{"price":"1735.79","quantity":"3.983"},{"price":"1735.81","quantity":"7.246"},{"price":"1735.84","quantity":"0.058"},{"price":"1735.88","quantity":"0.036"},{"price":"1735.89","quantity":"14.235"},{"price":"1735.90","quantity":"3.103"},{"price":"1735.92","quantity":"24.825"},{"price":"1735.93","quantity":"3.974"},{"price":"1735.94","quantity":"0.103"},{"price":"1735.95","quantity":"2.378"},{"price":"1735.99","quantity":"26.090"},{"price":"1736.04","quantity":"0.012"},{"price":"1736.05","quantity":"0.051"},{"price":"1736.06","quantity":"0.014"},{"price":"1736.07","quantity":"0.036"},{"price":"1736.08","quantity":"0.723"},{"price":"1736.09","quantity":"0.930"},{"price":"1736.10","quantity":"3.724"},{"price":"1736.12","quantity":"61.868"}],"asks":[{"price":"1736.13","quantity":"153.647"},{"price":"1736.17","quantity":"2.816"},{"price":"1736.18","quantity":"18.616"},{"price":"1736.21","quantity":"18.136"},{"price":"1736.23","quantity":"22.568"},{"price":"1736.25","quantity":"3.977"},{"price":"1736.26","quantity":"0.482"},{"price":"1736.27","quantity":"0.026"},{"price":"1736.31","quantity":"22.913"},{"price":"1736.32","quantity":"0.130"},{"price":"1736.33","quantity":"0.012"},{"price":"1736.36","quantity":"5.168"},{"price":"1736.37","quantity":"7.833"},{"price":"1736.41","quantity":"9.520"},{"price":"1736.44","quantity":"9.416"},{"price":"1736.45","quantity":"73.507"},{"price":"1736.63","quantity":"10.521"},{"price":"1736.64","quantity":"76.197"},{"price":"1736.72","quantity":"9.786"},{"price":"1736.73","quantity":"45.967"},{"price":"1736.74","quantity":"25.216"},{"price":"1736.91","quantity":"84.799"},{"price":"1737.00","quantity":"73.244"},{"price":"1737.17","quantity":"1.527"},{"price":"1737.26","quantity":"5.190"},{"price":"1737.50","quantity":"67.937"},{"price":"1737.51","quantity":"0.218"},{"price":"1737.89","quantity":"17.008"},{"price":"1738.15","quantity":"31.957"},{"price":"1738.66","quantity":"7.002"},{"price":"1738.70","quantity":"3.393"},{"price":"1738.71","quantity":"35.150"},{"price":"1738.72","quantity":"54.567"},{"price":"1738.88","quantity":"8.584"},{"price":"1739.41","quantity":"13.858"},{"price":"1739.42","quantity":"17.925"},{"price":"1744.82","quantity":"0.078"},{"price":"1781.13","quantity":"5.002"},{"price":"2634.86","quantity":"0.001"},{"price":"2634.87","quantity":"0.001"},{"price":"2634.95","quantity":"0.000"},{"price":"2634.96","quantity":"0.000"}],"raw":{"e":"depthUpdate","E":1783517067376,"T":1783517067375,"s":"ETHUSDT","ps":"ETHUSDT","U":10999770622549,"u":10999770631686,"pu":10999770622458,"b":[["1211.12","6.049"],["1216.16","0.544"],["1562.50","1.060"],["1562.51","8.880"],["1666.60","1.078"],["1701.40","0.402"],["1714.43","8.763"],["1720.48","0.064"],["1727.44","0.012"],["1734.06","54.181"],["1734.12","55.897"],["1734.18","0.012"],["1734.21","79.952"],["1734.24","1.474"],["1734.29","8.551"],["1734.30","21.202"],["1734.35","8.764"],["1734.36","2.988"],["1734.37","0.168"],["1734.38","56.188"],["1734.39","19.527"],["1734.40","3.664"],["1734.41","80.351"],["1734.46","25.640"],["1734.63","239.299"],["1734.75","287.604"],["1734.84","272.872"],["1735.00","216.833"],["1735.02","53.535"],["1735.09","2.035"],["1735.10","24.075"],["1735.12","96.297"],["1735.18","2.293"],["1735.25","0.169"],["1735.27","69.112"],["1735.32","65.935"],["1735.33","16.529"],["1735.34","0.110"],["1735.35","20.788"],["1735.58","5.861"],["1735.61","8.709"],["1735.62","32.166"],["1735.65","20.679"],["1735.66","29.004"],["1735.68","15.094"],["1735.70","0.037"],["1735.76","11.257"],["1735.77","17.647"],["1735.79","3.983"],["1735.81","7.246"],["1735.84","0.058"],["1735.88","0.036"],["1735.89","14.235"],["1735.90","3.103"],["1735.92","24.825"],["1735.93","3.974"],["1735.94","0.103"],["1735.95","2.378"],["1735.99","26.090"],["1736.04","0.012"],["1736.05","0.051"],["1736.06","0.014"],["1736.07","0.036"],["1736.08","0.723"],["1736.09","0.930"],["1736.10","3.724"],["1736.12","61.868"]],"a":[["1736.13","153.647"],["1736.17","2.816"],["1736.18","18.616"],["1736.21","18.136"],["1736.23","22.568"],["1736.25","3.977"],["1736.26","0.482"],["1736.27","0.026"],["1736.31","22.913"],["1736.32","0.130"],["1736.33","0.012"],["1736.36","5.168"],["1736.37","7.833"],["1736.41","9.520"],["1736.44","9.416"],["1736.45","73.507"],["1736.63","10.521"],["1736.64","76.197"],["1736.72","9.786"],["1736.73","45.967"],["1736.74","25.216"],["1736.91","84.799"],["1737.00","73.244"],["1737.17","1.527"],["1737.26","5.190"],["1737.50","67.937"],["1737.51","0.218"],["1737.89","17.008"],["1738.15","31.957"],["1738.66","7.002"],["1738.70","3.393"],["1738.71","35.150"],["1738.72","54.567"],["1738.88","8.584"],["1739.41","13.858"],["1739.42","17.925"],["1744.82","0.078"],["1781.13","5.002"],["2634.86","0.001"],["2634.87","0.001"],["2634.95","0.000"],["2634.96","0.000"]],"st":1}}
