{"schema_version":"1.3.0","event_id":"77747559-5aab-4377-8bde-9e594f70a0d1","event_type":"raw.depth_update","source":"binance_market_data_recorder","venue":"binance_usdm","market_type":"perpetual_futures","symbol":"ETHUSDT","event_time_ms":1783517072086,"received_time_ms":1783517072081,"trace_id":"913e1bf8-e0d0-44d4-ae4f-e64522731a4c","first_update_id":10999771046659,"final_update_id":10999771053035,"previous_final_update_id":10999771046361,"bids":[{"price":"1216.11","quantity":"5.152"},{"price":"1221.11","quantity":"4.448"},{"price":"1562.49","quantity":"0.026"},{"price":"1562.50","quantity":"4.488"},{"price":"1650.00","quantity":"1681.405"},{"price":"1703.59","quantity":"1.014"},{"price":"1714.49","quantity":"0.013"},{"price":"1715.28","quantity":"50.658"},{"price":"1732.29","quantity":"37.899"},{"price":"1735.09","quantity":"1.235"},{"price":"1735.29","quantity":"30.264"},{"price":"1735.43","quantity":"0.479"},{"price":"1735.76","quantity":"12.941"}],"asks":[{"price":"1736.28","quantity":"0.097"},{"price":"1736.47","quantity":"7.668"},{"price":"1737.11","quantity":"21.277"},{"price":"1737.14","quantity":"72.286"},{"price":"1737.36","quantity":"68.335"},{"price":"1737.68","quantity":"3.610"},{"price":"1737.70","quantity":"35.872"},{"price":"1737.86","quantity":"3.560"},{"price":"1737.87","quantity":"33.965"},{"price":"1738.07","quantity":"34.583"},{"price":"1738.41","quantity":"5.890"},{"price":"1738.98","quantity":"43.748"},{"price":"1739.87","quantity":"31.057"},{"price":"1756.95","quantity":"151.748"},{"price":"1762.16","quantity":"113.553"},{"price":"2634.15","quantity":"0.001"},{"price":"2634.16","quantity":"0.001"},{"price":"2634.24","quantity":"0.000"},{"price":"2634.25","quantity":"1.093"}],"raw":{"e":"depthUpdate","E":1783517072086,"T":1783517072085,"s":"ETHUSDT","ps":"ETHUSDT","U":10999771046659,"u":10999771053035,"pu":10999771046361,"b":[["1216.11","5.152"],["1221.11","4.448"],["1562.49","0.026"],["1562.50","4.488"],["1650.00","1681.405"],["1703.59","1.014"],["1714.49","0.013"],["1715.28","50.658"],["1732.29","37.899"],["1735.09","1.235"],["1735.29","30.264"],["1735.43","0.479"],["1735.76","12.941"]],"a":[["1736.28","0.097"],["1736.47","7.668"],["1737.11","21.277"],["1737.14","72.286"],["1737.36","68.335"],["1737.68","3.610"],["1737.70","35.872"],["1737.86","3.560"],["1737.87","33.965"],["1738.07","34.583"],["1738.41","5.890"],["1738.98","43.748"],["1739.87","31.057"],["1756.95","151.748"],["1762.16","113.553"],["2634.15","0.001"],["2634.16","0.001"],["2634.24","0.000"],["2634.25","1.093"]],"st":1}}
{"schema_version":"1.3.0","event_id":"83c88646-e292-4769-8711-e60e9ec990f1","event_type":"raw.depth_update","source":"binance_market_data_recorder","venue":"binance_usdm","market_type":"perpetual_futures","symbol":"ETHUSDT","event_time_ms":1783517072188,"received_time_ms":1783517072186,"trace_id":"d9fb9857-7972-4759-9f1e-6cf27dd27084","first_update_id":10999771053162,"final_update_id":10999771062004,"previous_final_update_id":10999771053035,"bids":[{"price":"1216.11","quantity":"5.952"},{"price":"1221.11","quantity":"3.648"},{"price":"1562.49","quantity":"0.026"},{"price":"1562.50","quantity":"4.616"},{"price":"1666.60","quantity":"1.193"},{"price":"1701.38","quantity":"43.670"},{"price":"1718.74","quantity":"75.034"},{"price":"1730.07","quantity":"135.808"},{"price":"1730.08","quantity":"26.300"},{"price":"1730.09","quantity":"4.331"},{"price":"1731.25","quantity":"6.640"},{"price":"1733.71","quantity":"513.558"},{"price":"1733.72","quantity":"1.615"},{"price":"1734.18","quantity":"0.012"},{"price":"1734.21","quantity":"18.126"},{"price":"1735.02","quantity":"50.511"},{"price":"1735.07","quantity":"6.135"},{"price":"1735.08","quantity":"6.998"},{"price":"1735.11","quantity":"38.668"},{"price":"1735.19","quantity":"73.049"},{"price":"1735.20","quantity":"58.005"},{"price":"1735.22","quantity":"18.067"},{"price":"1735.26","quantity":"1.073"},{"price":"1735.28","quantity":"3.762"},{"price":"1735.30","quantity":"29.159"},{"price":"1735.36","quantity":"3.786"},{"price":"1735.37","quantity":"0.509"},{"price":"1735.38","quantity":"65.076"},{"price":"1735.40","quantity":"6.030"},{"price":"1735.43","quantity":"39.412"},{"price":"1735.53","quantity":"15.021"},{"price":"1735.54","quantity":"0.027"},{"price":"1735.55","quantity":"4.604"},{"price":"1735.57","quantity":"2.146"},{"price":"1735.62","quantity":"230.329"},{"price":"1735.63","quantity":"0.576"},{"price":"1735.68","quantity":"15.685"},{"price":"1735.73","quantity":"27.747"},{"price":"1735.78","quantity":"1.984"},{"price":"1735.87","quantity":"3.843"},{"price":"1735.89","quantity":"10.219"},{"price":"1735.99","quantity":"1.290"},{"price":"1736.01","quantity":"2.535"},{"price":"1736.02","quantity":"0.082"},{"price":"1736.03","quantity":"2.882"},{"price":"1736.05","quantity":"0.083"},{"price":"1736.07","quantity":"0.047"},{"price":"1736.10","quantity":"5.939"},{"price":"1736.11","quantity":"195.116"}],"asks":[{"price":"1736.12","quantity":"8.221"},{"price":"1736.13","quantity":"9.037"},{"price":"1736.17","quantity":"0.024"},{"price":"1736.20","quantity":"0.064"},{"price":"1736.21","quantity":"0.036"},{"price":"1736.24","quantity":"0.097"},{"price":"1736.25","quantity":"7.741"},{"price":"1736.27","quantity":"0.127"},{"price":"1736.29","quantity":"15.343"},{"price":"1736.30","quantity":"9.174"},{"price":"1736.31","quantity":"17.384"},{"price":"1736.35","quantity":"24.537"},{"price":"1736.36","quantity":"17.468"},{"price":"1736.39","quantity":"0.113"},{"price":"1736.40","quantity":"27.083"},{"price":"1736.42","quantity":"27.038"},{"price":"1736.43","quantity":"4.320"},{"price":"1736.45","quantity":"6.259"},{"price":"1736.46","quantity":"52.981"},{"price":"1736.50","quantity":"1.814"},{"price":"1736.53","quantity":"68.753"},{"price":"1736.56","quantity":"10.282"},{"price":"1736.59","quantity":"7.603"},{"price":"1736.68","quantity":"4.705"},{"price":"1736.73","quantity":"2.157"},{"price":"1736.74","quantity":"29.060"},{"price":"1736.89","quantity":"8.153"},{"price":"1736.90","quantity":"29.781"},{"price":"1737.04","quantity":"29.765"},{"price":"1737.12","quantity":"7.826"},{"price":"1737.17","quantity":"4.527"},{"price":"1737.23","quantity":"36.422"},{"price":"1737.27","quantity":"20.256"},{"price":"1737.37","quantity":"29.259"},{"price":"1737.42","quantity":"3.675"},{"price":"1737.48","quantity":"0.173"},{"price":"1737.58","quantity":"22.806"},{"price":"1737.77","quantity":"18.434"},{"price":"1737.86","quantity":"20.236"},{"price":"1738.00","quantity":"30.932"},{"price":"1738.03","quantity":"0.000"},{"price":"1738.08","quantity":"1.684"},{"price":"1738.14","quantity":"423.328"},{"price":"1739.12","quantity":"1.417"},{"price":"1747.12","quantity":"15.000"},{"price":"1762.32","quantity":"69.002"},{"price":"2634.13","quantity":"0.001"},{"price":"2634.14","quantity":"0.001"},{"price":"2634.22","quantity":"0.001"},{"price":"2634.23","quantity":"0.000"}],"raw":{"e":"depthUpdate","E":1783517072188,"T":1783517072187,"s":"ETHUSDT","ps":"ETHUSDT","U":10999771053162,"u":10999771062004,"pu":10999771053035,"b":[["1216.11","5.952"],["1221.11","3.648"],["1562.49","0.026"],["1562.50","4.616"],["1666.60","1.193"],["1701.38","43.670"],["1718.74","75.034"],["1730.07","135.808"],["1730.08","26.300"],["1730.09","4.331"],["1731.25","6.640"],["1733.71","513.558"],["1733.72","1.615"],["1734.18","0.012"],["1734.21","18.126"],["1735.02","50.511"],["1735.07","6.135"],["1735.08","6.998"],["1735.11","38.668"],["1735.19","73.049"],["1735.20","58.005"],["1735.22","18.067"],["1735.26","1.073"],["1735.28","3.762"],["1735.30","29.159"],["1735.36","3.786"],["1735.37","0.509"],["1735.38","65.076"],["1735.40","6.030"],["1735.43","39.412"],["1735.53","15.021"],["1735.54","0.027"],["1735.55","4.604"],["1735.57","2.146"],["1735.62","230.329"],["1735.63","0.576"],["1735.68","15.685"],["1735.73","27.747"],["1735.78","1.984"],["1735.87","3.843"],["1735.89","10.219"],["1735.99","1.290"],["1736.01","2.535"],["1736.02","0.082"],["1736.03","2.882"],["1736.05","0.083"],["1736.07","0.047"],["1736.10","5.939"],["1736.11","195.116"]],"a":[["1736.12","8.221"],["1736.13","9.037"],["1736.17","0.024"],["1736.20","0.064"],["1736.21","0.036"],["1736.24","0.097"],["1736.25","7.741"],["1736.27","0.127"],["1736.29","15.343"],["1736.30","9.174"],["1736.31","17.384"],["1736.35","24.537"],["1736.36","17.468"],["1736.39","0.113"],["1736.40","27.083"],["1736.42","27.038"],["1736.43","4.320"],["1736.45","6.259"],["1736.46","52.981"],["1736.50","1.814"],["1736.53","68.753"],["1736.56","10.282"],["1736.59","7.603"],["1736.68","4.705"],["1736.73","2.157"],["1736.74","29.060"],["1736.89","8.153"],["1736.90","29.781"],["1737.04","29.765"],["1737.12","7.826"],["1737.17","4.527"],["1737.23","36.422"],["1737.27","20.256"],["1737.37","29.259"],["1737.42","3.675"],["1737.48","0.173"],["1737.58","22.806"],["1737.77","18.434"],["1737.86","20.236"],["1738.00","30.932"],["1738.03","0.000"],["1738.08","1.684"],["1738.14","423.328"],["1739.12","1.417"],["1747.12","15.000"],["1762.32","69.002"],["2634.13","0.001"],["2634.14","0.001"],["2634.22","0.001"],["2634.23","0.000"]],"st":1}}
{"schema_version":"1.3.0","event_id":"fec2e281-2929-49b4-90b1-0723898dd5a2","event_type":"raw.depth_update","source":"binance_market_data_recorder","venue":"binance_usdm","market_type":"perpetual_futures","symbol":"ETHUSDT","event_time_ms":1783517072290,"received_time_ms":1783517072285,"trace_id":"9b7b5acc-aaff-4151-ad84-cf7dd131a0b8","first_update_id":10999771062127,"final_update_id":10999771072662,"previous_final_update_id":10999771062004,"bids":[{"price":"200.00","quantity":"7.594"},{"price":"1216.11","quantity":"6.784"},{"price":"1221.11","quantity":"2.816"},{"price":"1562.49","quantity":"0.026"},{"price":"1562.50","quantity":"4.488"},{"price":"1666.60","quantity":"1.078"},{"price":"1701.38","quantity":"43.641"},{"price":"1702.26","quantity":"40.754"},{"price":"1733.71","quantity":"84.523"},{"price":"1733.72","quantity":"0.169"},{"price":"1733.89","quantity":"3.961"},{"price":"1733.91","quantity":"0.465"},{"price":"1734.18","quantity":"429.047"},{"price":"1734.21","quantity":"18.217"},{"price":"1734.22","quantity":"17.049"},{"price":"1734.24","quantity":"12.994"},{"price":"1734.58","quantity":"0.519"},{"price":"1734.93","quantity":"68.243"},{"price":"1735.11","quantity":"38.668"},{"price":"1735.53","quantity":"13.293"},{"price":"1735.62","quantity":"230.347"},{"price":"1735.63","quantity":"0.558"},{"price":"1735.65","quantity":"48.664"},{"price":"1735.69","quantity":"4.692"},{"price":"1735.74","quantity":"16.742"},{"price":"1735.86","quantity":"69.078"},{"price":"1735.93","quantity":"34.314"},{"price":"1736.00","quantity":"9.971"},{"price":"1736.01","quantity":"1.202"},{"price":"1736.06","quantity":"0.046"},{"price":"1736.07","quantity":"0.047"},{"price":"1736.11","quantity":"195.762"}],"asks":[{"price":"1736.17","quantity":"0.012"},{"price":"1736.18","quantity":"0.178"},{"price":"1736.19","quantity":"0.000"},{"price":"1736.25","quantity":"7.741"},{"price":"1736.28","quantity":"0.112"},{"price":"1736.39","quantity":"0.113"},{"price":"1736.49","quantity":"3.202"},{"price":"1736.52","quantity":"9.982"},{"price":"1736.53","quantity":"68.771"},{"price":"1736.54","quantity":"2.869"},{"price":"1736.56","quantity":"10.370"},{"price":"1736.58","quantity":"30.485"},{"price":"1736.59","quantity":"1.757"},{"price":"1736.65","quantity":"15.352"},{"price":"1736.67","quantity":"5.820"},{"price":"1736.74","quantity":"29.060"},{"price":"1736.80","quantity":"4.218"},{"price":"1736.83","quantity":"37.658"},{"price":"1736.86","quantity":"40.423"},{"price":"1736.89","quantity":"19.667"},{"price":"1736.91","quantity":"30.688"},{"price":"1736.92","quantity":"67.361"},{"price":"1736.93","quantity":"16.398"},{"price":"1736.94","quantity":"19.272"},{"price":"1737.00","quantity":"120.034"},{"price":"1737.06","quantity":"32.891"},{"price":"1737.08","quantity":"15.961"},{"price":"1737.09","quantity":"28.385"},{"price":"1737.19","quantity":"6.680"},{"price":"1737.33","quantity":"21.257"},{"price":"1737.36","quantity":"70.029"},{"price":"1737.70","quantity":"34.178"},{"price":"1737.77","quantity":"1.758"},{"price":"1738.12","quantity":"5.998"},{"price":"1738.41","quantity":"4.196"},{"price":"1738.80","quantity":"7.787"},{"price":"1738.81","quantity":"25.729"},{"price":"1740.57","quantity":"16.352"},{"price":"1758.86","quantity":"11.406"},{"price":"1775.90","quantity":"28.133"},{"price":"2634.12","quantity":"0.001"},{"price":"2634.21","quantity":"0.000"}],"raw":{"e":"depthUpdate","E":1783517072290,"T":1783517072289,"s":"ETHUSDT","ps":"ETHUSDT","U":10999771062127,"u":10999771072662,"pu":10999771062004,"b":[["200.00","7.594"],["1216.11","6.784"],["1221.11","2.816"],["1562.49","0.026"],["1562.50","4.488"],["1666.60","1.078"],["1701.38","43.641"],["1702.26","40.754"],["1733.71","84.523"],["1733.72","0.169"],["1733.89","3.961"],["1733.91","0.465"],["1734.18","429.047"],["1734.21","18.217"],["1734.22","17.049"],["1734.24","12.994"],["1734.58","0.519"],["1734.93","68.243"],["1735.11","38.668"],["1735.53","13.293"],["1735.62","230.347"],["1735.63","0.558"],["1735.65","48.664"],["1735.69","4.692"],["1735.74","16.742"],["1735.86","69.078"],["1735.93","34.314"],["1736.00","9.971"],["1736.01","1.202"],["1736.06","0.046"],["1736.07","0.047"],["1736.11","195.762"]],"a":[["1736.17","0.012"],["1736.18","0.178"],["1736.19","0.000"],["1736.25","7.741"],["1736.28","0.112"],["1736.39","0.113"],["1736.49","3.202"],["1736.52","9.982"],["1736.53","68.771"],["1736.54","2.869"],["1736.56","10.370"],["1736.58","30.485"],["1736.59","1.757"],["1736.65","15.352"],["1736.67","5.820"],["1736.74","29.060"],["1736.80","4.218"],["1736.83","37.658"],["1736.86","40.423"],["1736.89","19.667"],["1736.91","30.688"],["1736.92","67.361"],["1736.93","16.398"],["1736.94","19.272"],["1737.00","120.034"],["1737.06","32.891"],["1737.08","15.961"],["1737.09","28.385"],["1737.19","6.680"],["1737.33","21.257"],["1737.36","70.029"],["1737.70","34.178"],["1737.77","1.758"],["1738.12","5.998"],["1738.41","4.196"],["1738.80","7.787"],["1738.81","25.729"],["1740.57","16.352"],["1758.86","11.406"],["1775.90","28.133"],["2634.12","0.001"],["2634.21","0.000"]],"st":1}}
{"schema_version":"1.3.0","event_id":"8d689e3b-7e08-4dad-8ddd-1880be791bc7","event_type":"raw.depth_update","source":"binance_market_data_recorder","venue":"binance_usdm","market_type":"perpetual_futures","symbol":"ETHUSDT","event_time_ms":1783517072394,"received_time_ms":1783517072389,"trace_id":"b6e487c1-cc87-4f1d-9720-64af5b7d3e2e","first_update_id":10999771072996,"final_update_id":10999771083102,"previous_final_update_id":10999771072662,"bids":[{"price":"1211.11","quantity":"0.229"},{"price":"1216.11","quantity":"7.232"},{"price":"1221.11","quantity":"2.176"},{"price":"1562.49","quantity":"0.026"},{"price":"1562.50","quantity":"4.488"},{"price":"1666.60","quantity":"1.193"},{"price":"1705.75","quantity":"58.547"},{"price":"1715.00","quantity":"1036.099"},{"price":"1732.41","quantity":"7.697"},{"price":"1733.89","quantity":"2.211"},{"price":"1733.91","quantity":"3.661"},{"price":"1734.18","quantity":"0.012"},{"price":"1734.24","quantity":"442.029"},{"price":"1735.53","quantity":"15.021"},{"price":"1735.62","quantity":"10.484"},{"price":"1735.65","quantity":"0.115"},{"price":"1735.72","quantity":"2.321"},{"price":"1735.74","quantity":"16.742"},{"price":"1735.76","quantity":"12.941"},{"price":"1735.93","quantity":"5.510"},{"price":"1736.00","quantity":"6.368"},{"price":"1736.11","quantity":"224.575"}],"asks":[{"price":"1736.21","quantity":"0.024"},{"price":"1736.25","quantity":"2.834"},{"price":"1736.32","quantity":"18.248"},{"price":"1736.39","quantity":"3.569"},{"price":"1736.40","quantity":"36.737"},{"price":"1736.41","quantity":"76.738"},{"price":"1736.42","quantity":"23.582"},{"price":"1737.14","quantity":"95.333"},{"price":"1737.32","quantity":"24.340"},{"price":"1737.42","quantity":"3.675"},{"price":"1737.49","quantity":"82.051"},{"price":"1737.60","quantity":"7.231"},{"price":"1737.66","quantity":"46.235"},{"price":"1737.68","quantity":"0.970"},{"price":"1737.84","quantity":"119.858"},{"price":"1738.08","quantity":"1.684"},{"price":"1738.12","quantity":"4.331"},{"price":"1738.14","quantity":"16.295"},{"price":"1738.19","quantity":"423.353"},{"price":"1738.25","quantity":"2.878"},{"price":"1738.27","quantity":"61.220"},{"price":"1738.96","quantity":"3.196"},{"price":"1738.98","quantity":"40.552"},{"price":"1744.81","quantity":"0.154"},{"price":"1757.82","quantity":"8.127"},{"price":"1762.17","quantity":"64.331"},{"price":"2634.10","quantity":"0.001"},{"price":"2634.11","quantity":"0.001"},{"price":"2634.19","quantity":"0.000"},{"price":"2634.20","quantity":"0.041"}],"raw":{"e":"depthUpdate","E":1783517072394,"T":1783517072393,"s":"ETHUSDT","ps":"ETHUSDT","U":10999771072996,"u":10999771083102,"pu":10999771072662,"b":[["1211.11","0.229"],["1216.11","7.232"],["1221.11","2.176"],["1562.49","0.026"],["1562.50","4.488"],["1666.60","1.193"],["1705.75","58.547"],["1715.00","1036.099"],["1732.41","7.697"],["1733.89","2.211"],["1733.91","3.661"],["1734.18","0.012"],["1734.24","442.029"],["1735.53","15.021"],["1735.62","10.484"],["1735.65","0.115"],["1735.72","2.321"],["1735.74","16.742"],["1735.76","12.941"],["1735.93","5.510"],["1736.00","6.368"],["1736.11","224.575"]],"a":[["1736.21","0.024"],["1736.25","2.834"],["1736.32","18.248"],["1736.39","3.569"],["1736.40","36.737"],["1736.41","76.738"],["1736.42","23.582"],["1737.14","95.333"],["1737.32","24.340"],["1737.42","3.675"],["1737.49","82.051"],["1737.60","7.231"],["1737.66","46.235"],["1737.68","0.970"],["1737.84","119.858"],["1738.08","1.684"],["1738.12","4.331"],["1738.14","16.295"],["1738.19","423.353"],["1738.25","2.878"],["1738.27","61.220"],["1738.96","3.196"],["1738.98","40.552"],["1744.81","0.154"],["1757.82","8.127"],["1762.17","64.331"],["2634.10","0.001"],["2634.11","0.001"],["2634.19","0.000"],["2634.20","0.041"]],"st":1}}
{"schema_version":"1.3.0","event_id":"a64f7367-0758-4935-acc7-3449a776890d","event_type":"raw.depth_update","source":"binance_market_data_recorder","venue":"binance_usdm","market_type":"perpetual_futures","symbol":"ETHUSDT","event_time_ms":1783517072496,"received_time_ms":1783517072491,"trace_id":"f0bd809b-3534-490e-b36b-8067d7516aa8","first_update_id":10999771083252,"final_update_id":10999771096640,"previous_final_update_id":10999771083102,"bids":[{"price":"200.00","quantity":"7.594"},{"price":"201.00","quantity":"2.400"},{"price":"1211.11","quantity":"0.613"},{"price":"1216.11","quantity":"7.264"},{"price":"1221.11","quantity":"1.760"},{"price":"1562.49","quantity":"0.026"},{"price":"1562.50","quantity":"4.616"},{"price":"1666.60","quantity":"1.078"},{"price":"1675.13","quantity":"0.113"},{"price":"1689.17","quantity":"0.367"},{"price":"1701.38","quantity":"43.670"},{"price":"1727.42","quantity":"0.629"},{"price":"1733.74","quantity":"15.812"},{"price":"1733.76","quantity":"35.199"},{"price":"1733.77","quantity":"17.192"},{"price":"1733.88","quantity":"473.751"},{"price":"1734.21","quantity":"18.217"},{"price":"1734.24","quantity":"1.474"},{"price":"1734.25","quantity":"0.059"},{"price":"1734.40","quantity":"3.064"},{"price":"1734.42","quantity":"0.258"},{"price":"1734.43","quantity":"0.384"},{"price":"1734.44","quantity":"55.636"},{"price":"1734.45","quantity":"0.038"},{"price":"1734.84","quantity":"268.616"},{"price":"1734.94","quantity":"37.464"},{"price":"1735.00","quantity":"217.768"},{"price":"1735.07","quantity":"5.335"},{"price":"1735.08","quantity":"5.398"},{"price":"1735.09","quantity":"0.435"},{"price":"1735.10","quantity":"12.275"},{"price":"1735.11","quantity":"37.068"},{"price":"1735.12","quantity":"131.338"},{"price":"1735.13","quantity":"1.643"},{"price":"1735.14","quantity":"8.718"},{"price":"1735.15","quantity":"5.663"},{"price":"1735.16","quantity":"7.364"},{"price":"1735.17","quantity":"0.047"},{"price":"1735.19","quantity":"72.249"},{"price":"1735.29","quantity":"30.264"},{"price":"1735.37","quantity":"3.316"},{"price":"1735.44","quantity":"247.648"},{"price":"1735.46","quantity":"19.608"},{"price":"1735.56","quantity":"27.627"},{"price":"1735.58","quantity":"2.973"},{"price":"1735.60","quantity":"225.134"},{"price":"1735.62","quantity":"10.484"},{"price":"1735.67","quantity":"0.318"},{"price":"1735.75","quantity":"70.662"},{"price":"1735.76","quantity":"11.341"},{"price":"1735.77","quantity":"8.796"},{"price":"1735.78","quantity":"0.384"},{"price":"1735.79","quantity":"3.116"},{"price":"1735.80","quantity":"8.512"},{"price":"1735.81","quantity":"5.358"},{"price":"1735.82","quantity":"29.878"},{"price":"1735.83","quantity":"20.204"},{"price":"1735.84","quantity":"0.058"},{"price":"1735.86","quantity":"68.478"},{"price":"1735.87","quantity":"3.043"},{"price":"1735.88","quantity":"1.036"},{"price":"1735.91","quantity":"11.685"},{"price":"1735.99","quantity":"3.565"},{"price":"1736.01","quantity":"0.050"},{"price":"1736.02","quantity":"0.082"},{"price":"1736.03","quantity":"1.810"},{"price":"1736.10","quantity":"4.825"},{"price":"1736.11","quantity":"224.690"}],"asks":[{"price":"1736.12","quantity":"8.203"},{"price":"1736.17","quantity":"0.024"},{"price":"1736.18","quantity":"0.190"},{"price":"1736.23","quantity":"0.162"},{"price":"1736.24","quantity":"7.896"},{"price":"1736.27","quantity":"14.643"},{"price":"1736.29","quantity":"7.562"},{"price":"1736.30","quantity":"9.261"},{"price":"1736.31","quantity":"17.384"},{"price":"1736.34","quantity":"6.669"},{"price":"1736.35","quantity":"24.537"},{"price":"1736.38","quantity":"1.756"},{"price":"1736.39","quantity":"12.209"},{"price":"1736.40","quantity":"24.363"},{"price":"1736.41","quantity":"0.068"},{"price":"1736.42","quantity":"1.738"},{"price":"1736.43","quantity":"1.760"},{"price":"1736.44","quantity":"1.196"},{"price":"1736.45","quantity":"0.039"},{"price":"1736.46","quantity":"49.261"},{"price":"1736.47","quantity":"5.588"},{"price":"1736.48","quantity":"1.781"},{"price":"1736.52","quantity":"11.223"},{"price":"1736.56","quantity":"10.282"},{"price":"1736.73","quantity":"3.824"},{"price":"1737.00","quantity":"120.052"},{"price":"1737.01","quantity":"75.709"},{"price":"1737.08","quantity":"3.801"},{"price":"1737.10","quantity":"6.051"},{"price":"1737.11","quantity":"17.097"},{"price":"1737.12","quantity":"1.626"},{"price":"1737.13","quantity":"0.827"},{"price":"1737.14","quantity":"95.547"},{"price":"1737.15","quantity":"4.337"},{"price":"1737.16","quantity":"9.170"},{"price":"1737.39","quantity":"0.256"},{"price":"1737.59","quantity":"28.831"},{"price":"1737.66","quantity":"46.253"},{"price":"1737.67","quantity":"1.318"},{"price":"1737.68","quantity":"3.610"},{"price":"1737.78","quantity":"1.355"},{"price":"1737.79","quantity":"0.015"},{"price":"1737.80","quantity":"1.344"},{"price":"1737.81","quantity":"29.728"},{"price":"1738.07","quantity":"32.889"},{"price":"1738.12","quantity":"5.998"},{"price":"1739.12","quantity":"1.405"},{"price":"1744.81","quantity":"0.142"},{"price":"1745.37","quantity":"5.076"},{"price":"1747.12","quantity":"0.000"},{"price":"2634.09","quantity":"0.001"},{"price":"2634.18","quantity":"0.000"}],"raw":{"e":"depthUpdate","E":1783517072496,"T":1783517072494,"s":"ETHUSDT","ps":"ETHUSDT","U":10999771083252,"u":10999771096640,"pu":10999771083102,"b":[["200.00","7.594"],["201.00","2.400"],["1211.11","0.613"],["1216.11","7.264"],["1221.11","1.760"],["1562.49","0.026"],["1562.50","4.616"],["1666.60","1.078"],["1675.13","0.113"],["1689.17","0.367"],["1701.38","43.670"],["1727.42","0.629"],["1733.74","15.812"],["1733.76","35.199"],["1733.77","17.192"],["1733.88","473.751"],["1734.21","18.217"],["1734.24","1.474"],["1734.25","0.059"],["1734.40","3.064"],["1734.42","0.258"],["1734.43","0.384"],["1734.44","55.636"],["1734.45","0.038"],["1734.84","268.616"],["1734.94","37.464"],["1735.00","217.768"],["1735.07","5.335"],["1735.08","5.398"],["1735.09","0.435"],["1735.10","12.275"],["1735.11","37.068"],["1735.12","131.338"],["1735.13","1.643"],["1735.14","8.718"],["1735.15","5.663"],["1735.16","7.364"],["1735.17","0.047"],["1735.19","72.249"],["1735.29","30.264"],["1735.37","3.316"],["1735.44","247.648"],["1735.46","19.608"],["1735.56","27.627"],["1735.58","2.973"],["1735.60","225.134"],["1735.62","10.484"],["1735.67","0.318"],["1735.75","70.662"],["1735.76","11.341"],["1735.77","8.796"],["1735.78","0.384"],["1735.79","3.116"],["1735.80","8.512"],["1735.81","5.358"],["1735.82","29.878"],["1735.83","20.204"],["1735.84","0.058"],["1735.86","68.478"],["1735.87","3.043"],["1735.88","1.036"],["1735.91","11.685"],["1735.99","3.565"],["1736.01","0.050"],["1736.02","0.082"],["1736.03","1.810"],["1736.10","4.825"],["1736.11","224.690"]],"a":[["1736.12","8.203"],["1736.17","0.024"],["1736.18","0.190"],["1736.23","0.162"],["1736.24","7.896"],["1736.27","14.643"],["1736.29","7.562"],["1736.30","9.261"],["1736.31","17.384"],["1736.34","6.669"],["1736.35","24.537"],["1736.38","1.756"],["1736.39","12.209"],["1736.40","24.363"],["1736.41","0.068"],["1736.42","1.738"],["1736.43","1.760"],["1736.44","1.196"],["1736.45","0.039"],["1736.46","49.261"],["1736.47","5.588"],["1736.48","1.781"],["1736.52","11.223"],["1736.56","10.282"],["1736.73","3.824"],["1737.00","120.052"],["1737.01","75.709"],["1737.08","3.801"],["1737.10","6.051"],["1737.11","17.097"],["1737.12","1.626"],["1737.13","0.827"],["1737.14","95.547"],["1737.15","4.337"],["1737.16","9.170"],["1737.39","0.256"],["1737.59","28.831"],["1737.66","46.253"],["1737.67","1.318"],["1737.68","3.610"],["1737.78","1.355"],["1737.79","0.015"],["1737.80","1.344"],["1737.81","29.728"],["1738.07","32.889"],["1738.12","5.998"],["1739.12","1.405"],["1744.81","0.142"],["1745.37","5.076"],["1747.12","0.000"],["2634.09","0.001"],["2634.18","0.000"]],"st":1}}
{"schema_version":"1.3.0","event_id":"f7beb300-cc60-4ad3-8bfe-fd6d4a2ccf11","event_type":"raw.depth_update","source":"binance_market_data_recorder","venue":"binance_usdm","market_type":"perpetual_futures","symbol":"ETHUSDT","event_time_ms":1783517072598,"received_time_ms":1783517072593,"trace_id":"12570beb-4bef-4a0a-bad4-24740164fa87","first_update_id":10999771096728,"final_update_id":10999771105537,"previous_final_update_id":10999771096640,"bids":[{"price":"200.00","quantity":"7.594"},{"price":"201.00","quantity":"2.300"},{"price":"1211.11","quantity":"1.157"},{"price":"1216.11","quantity":"7.008"},{"price":"1221.11","quantity":"1.472"},{"price":"1562.04","quantity":"0.084"},{"price":"1562.49","quantity":"0.026"},{"price":"1562.50","quantity":"4.488"},{"price":"1689.57","quantity":"0.000"},{"price":"1701.38","quantity":"43.641"},{"price":"1718.00","quantity":"708.059"},{"price":"1727.42","quantity":"0.641"},{"price":"1730.26","quantity":"3.433"},{"price":"1732.54","quantity":"5.858"},{"price":"1732.80","quantity":"14.396"},{"price":"1733.14","quantity":"14.766"},{"price":"1734.50","quantity":"10.532"},{"price":"1734.52","quantity":"0.639"},{"price":"1735.11","quantity":"37.068"},{"price":"1735.19","quantity":"70.115"},{"price":"1735.20","quantity":"57.300"},{"price":"1735.21","quantity":"33.878"},{"price":"1735.36","quantity":"3.786"},{"price":"1735.43","quantity":"39.411"},{"price":"1735.53","quantity":"13.293"},{"price":"1735.55","quantity":"8.923"},{"price":"1735.58","quantity":"0.094"},{"price":"1735.60","quantity":"5.431"},{"price":"1735.62","quantity":"10.466"},{"price":"1735.65","quantity":"1.843"},{"price":"1735.76","quantity":"13.824"},{"price":"1735.84","quantity":"0.858"},{"price":"1735.85","quantity":"5.133"},{"price":"1735.86","quantity":"69.078"},{"price":"1735.87","quantity":"4.443"},{"price":"1735.88","quantity":"1.836"},{"price":"1735.89","quantity":"14.538"},{"price":"1735.94","quantity":"21.363"},{"price":"1736.04","quantity":"8.692"},{"price":"1736.11","quantity":"224.676"}],"asks":[{"price":"1736.12","quantity":"8.233"},{"price":"1736.13","quantity":"9.025"},{"price":"1736.17","quantity":"0.012"},{"price":"1736.18","quantity":"0.178"},{"price":"1736.24","quantity":"2.977"},{"price":"1736.25","quantity":"7.753"},{"price":"1736.26","quantity":"13.209"},{"price":"1736.30","quantity":"9.273"},{"price":"1736.32","quantity":"18.248"},{"price":"1736.36","quantity":"17.968"},{"price":"1736.38","quantity":"8.812"},{"price":"1736.39","quantity":"8.753"},{"price":"1736.40","quantity":"10.297"},{"price":"1736.45","quantity":"6.055"},{"price":"1736.46","quantity":"50.881"},{"price":"1736.47","quantity":"9.728"},{"price":"1736.48","quantity":"4.021"},{"price":"1736.49","quantity":"7.242"},{"price":"1736.50","quantity":"4.134"},{"price":"1736.51","quantity":"31.886"},{"price":"1736.58","quantity":"1.665"},{"price":"1736.77","quantity":"0.161"},{"price":"1736.80","quantity":"4.218"},{"price":"1736.86","quantity":"40.423"},{"price":"1737.13","quantity":"3.387"},{"price":"1737.14","quantity":"99.147"},{"price":"1737.15","quantity":"6.497"},{"price":"1737.16","quantity":"12.970"},{"price":"1737.17","quantity":"7.007"},{"price":"1737.42","quantity":"5.995"},{"price":"1737.57","quantity":"44.195"},{"price":"1737.77","quantity":"0.758"},{"price":"1737.81","quantity":"31.348"},{"price":"1737.82","quantity":"44.818"},{"price":"1737.84","quantity":"121.418"},{"price":"1740.57","quantity":"16.364"},{"price":"1740.65","quantity":"16.331"},{"price":"1773.47","quantity":"56.833"},{"price":"1780.06","quantity":"0.108"},{"price":"2634.07","quantity":"0.022"},{"price":"2634.08","quantity":"0.001"},{"price":"2634.16","quantity":"0.000"},{"price":"2634.17","quantity":"0.000"}],"raw":{"e":"depthUpdate","E":1783517072598,"T":1783517072597,"s":"ETHUSDT","ps":"ETHUSDT","U":10999771096728,"u":10999771105537,"pu":10999771096640,"b":[["200.00","7.594"],["201.00","2.300"],["1211.11","1.157"],["1216.11","7.008"],["1221.11","1.472"],["1562.04","0.084"],["1562.49","0.026"],["1562.50","4.488"],["1689.57","0.000"],["1701.38","43.641"],["1718.00","708.059"],["1727.42","0.641"],["1730.26","3.433"],["1732.54","5.858"],["1732.80","14.396"],["1733.14","14.766"],["1734.50","10.532"],["1734.52","0.639"],["1735.11","37.068"],["1735.19","70.115"],["1735.20","57.300"],["1735.21","33.878"],["1735.36","3.786"],["1735.43","39.411"],["1735.53","13.293"],["1735.55","8.923"],["1735.58","0.094"],["1735.60","5.431"],["1735.62","10.466"],["1735.65","1.843"],["1735.76","13.824"],["1735.84","0.858"],["1735.85","5.133"],["1735.86","69.078"],["1735.87","4.443"],["1735.88","1.836"],["1735.89","14.538"],["1735.94","21.363"],["1736.04","8.692"],["1736.11","224.676"]],"a":[["1736.12","8.233"],["1736.13","9.025"],["1736.17","0.012"],["1736.18","0.178"],["1736.24","2.977"],["1736.25","7.753"],["1736.26","13.209"],["1736.30","9.273"],["1736.32","18.248"],["1736.36","17.968"],["1736.38","8.812"],["1736.39","8.753"],["1736.40","10.297"],["1736.45","6.055"],["1736.46","50.881"],["1736.47","9.728"],["1736.48","4.021"],["1736.49","7.242"],["1736.50","4.134"],["1736.51","31.886"],["1736.58","1.665"],["1736.77","0.161"],["1736.80","4.218"],["1736.86","40.423"],["1737.13","3.387"],["1737.14","99.147"],["1737.15","6.497"],["1737.16","12.970"],["1737.17","7.007"],["1737.42","5.995"],["1737.57","44.195"],["1737.77","0.758"],["1737.81","31.348"],["1737.82","44.818"],["1737.84","121.418"],["1740.57","16.364"],["1740.65","16.331"],["1773.47","56.833"],["1780.06","0.108"],["2634.07","0.022"],["2634.08","0.001"],["2634.16","0.000"],["2634.17","0.000"]],"st":1}}
{"schema_version":"1.3.0","event_id":"0a289e75-a36b-42fa-ad49-68209404175e","event_type":"raw.depth_update","source":"binance_market_data_recorder","venue":"binance_usdm","market_type":"perpetual_futures","symbol":"ETHUSDT","event_time_ms":1783517072702,"received_time_ms":1783517072697,"trace_id":"ea34df1f-7e64-4145-b2e5-944cf6bca177","first_update_id":10999771105811,"final_update_id":10999771114592,"previous_final_update_id":10999771105537,"bids":[{"price":"1211.11","quantity":"1.733"},{"price":"1216.11","quantity":"6.688"},{"price":"1221.11","quantity":"1.216"},{"price":"1562.49","quantity":"0.026"},{"price":"1562.50","quantity":"4.246"},{"price":"1666.60","quantity":"1.193"},{"price":"1685.12","quantity":"38.552"},{"price":"1701.39","quantity":"32.216"},{"price":"1703.99","quantity":"135.122"},{"price":"1706.77","quantity":"43.331"},{"price":"1707.76","quantity":"29.302"},{"price":"1714.20","quantity":"0.371"},{"price":"1730.68","quantity":"16.369"},{"price":"1730.76","quantity":"17.040"},{"price":"1731.62","quantity":"0.680"},{"price":"1733.88","quantity":"44.716"},{"price":"1734.16","quantity":"52.012"},{"price":"1734.18","quantity":"429.047"},{"price":"1734.51","quantity":"13.893"},{"price":"1735.19","quantity":"70.477"},{"price":"1735.20","quantity":"57.119"},{"price":"1735.21","quantity":"33.697"},{"price":"1735.45","quantity":"2.971"},{"price":"1735.51","quantity":"51.664"},{"price":"1735.55","quantity":"10.623"},{"price":"1735.57","quantity":"1.802"},{"price":"1735.67","quantity":"0.383"},{"price":"1735.68","quantity":"15.169"},{"price":"1735.69","quantity":"4.680"},{"price":"1735.73","quantity":"26.047"},{"price":"1735.78","quantity":"0.040"},{"price":"1735.84","quantity":"1.658"},{"price":"1735.87","quantity":"5.043"},{"price":"1735.88","quantity":"2.636"},{"price":"1735.89","quantity":"14.022"},{"price":"1735.91","quantity":"12.485"},{"price":"1735.99","quantity":"3.221"},{"price":"1736.01","quantity":"1.202"},{"price":"1736.02","quantity":"0.106"},{"price":"1736.04","quantity":"0.044"},{"price":"1736.05","quantity":"0.083"},{"price":"1736.07","quantity":"0.047"},{"price":"1736.09","quantity":"2.672"},{"price":"1736.10","quantity":"5.311"},{"price":"1736.11","quantity":"224.664"}],"asks":[{"price":"1736.12","quantity":"7.800"},{"price":"1736.23","quantity":"0.076"},{"price":"1736.24","quantity":"0.097"},{"price":"1736.25","quantity":"2.834"},{"price":"1736.27","quantity":"14.729"},{"price":"1736.29","quantity":"5.895"},{"price":"1736.30","quantity":"9.186"},{"price":"1736.43","quantity":"8.080"},{"price":"1736.47","quantity":"11.528"},{"price":"1736.49","quantity":"7.073"},{"price":"1736.50","quantity":"2.434"},{"price":"1736.51","quantity":"33.966"},{"price":"1736.55","quantity":"31.534"},{"price":"1736.68","quantity":"6.405"},{"price":"1736.81","quantity":"20.987"},{"price":"1737.10","quantity":"8.771"},{"price":"1737.11","quantity":"20.697"},{"price":"1737.12","quantity":"1.626"},{"price":"1737.14","quantity":"97.453"},{"price":"1737.15","quantity":"8.297"},{"price":"1737.18","quantity":"24.845"},{"price":"1737.82","quantity":"46.618"},{"price":"1738.04","quantity":"1.933"},{"price":"1738.35","quantity":"50.047"},{"price":"1741.41","quantity":"10.358"},{"price":"1741.48","quantity":"17.965"},{"price":"1747.12","quantity":"15.000"},{"price":"1758.71","quantity":"70.727"},{"price":"1767.79","quantity":"33.763"},{"price":"1803.83","quantity":"44.297"},{"price":"2634.06","quantity":"0.012"},{"price":"2634.15","quantity":"0.000"}],"raw":{"e":"depthUpdate","E":1783517072702,"T":1783517072701,"s":"ETHUSDT","ps":"ETHUSDT","U":10999771105811,"u":10999771114592,"pu":10999771105537,"b":[["1211.11","1.733"],["1216.11","6.688"],["1221.11","1.216"],["1562.49","0.026"],["1562.50","4.246"],["1666.60","1.193"],["1685.12","38.552"],["1701.39","32.216"],["1703.99","135.122"],["1706.77","43.331"],["1707.76","29.302"],["1714.20","0.371"],["1730.68","16.369"],["1730.76","17.040"],["1731.62","0.680"],["1733.88","44.716"],["1734.16","52.012"],["1734.18","429.047"],["1734.51","13.893"],["1735.19","70.477"],["1735.20","57.119"],["1735.21","33.697"],["1735.45","2.971"],["1735.51","51.664"],["1735.55","10.623"],["1735.57","1.802"],["1735.67","0.383"],["1735.68","15.169"],["1735.69","4.680"],["1735.73","26.047"],["1735.78","0.040"],["1735.84","1.658"],["1735.87","5.043"],["1735.88","2.636"],["1735.89","14.022"],["1735.91","12.485"],["1735.99","3.221"],["1736.01","1.202"],["1736.02","0.106"],["1736.04","0.044"],["1736.05","0.083"],["1736.07","0.047"],["1736.09","2.672"],["1736.10","5.311"],["1736.11","224.664"]],"a":[["1736.12","7.800"],["1736.23","0.076"],["1736.24","0.097"],["1736.25","2.834"],["1736.27","14.729"],["1736.29","5.895"],["1736.30","9.186"],["1736.43","8.080"],["1736.47","11.528"],["1736.49","7.073"],["1736.50","2.434"],["1736.51","33.966"],["1736.55","31.534"],["1736.68","6.405"],["1736.81","20.987"],["1737.10","8.771"],["1737.11","20.697"],["1737.12","1.626"],["1737.14","97.453"],["1737.15","8.297"],["1737.18","24.845"],["1737.82","46.618"],["1738.04","1.933"],["1738.35","50.047"],["1741.41","10.358"],["1741.48","17.965"],["1747.12","15.000"],["1758.71","70.727"],["1767.79","33.763"],["1803.83","44.297"],["2634.06","0.012"],["2634.15","0.000"]],"st":1}}
{"schema_version":"1.3.0","event_id":"efc86d05-b3a2-423a-9f1c-095119e60ad6","event_type":"raw.depth_update","source":"binance_market_data_recorder","venue":"binance_usdm","market_type":"perpetual_futures","symbol":"ETHUSDT","event_time_ms":1783517072804,"received_time_ms":1783517072799,"trace_id":"5835831c-a63d-4c1d-bb81-7c76ade69212","first_update_id":10999771114755,"final_update_id":10999771123773,"previous_final_update_id":10999771114592,"bids":[{"price":"200.00","quantity":"7.594"},{"price":"1211.11","quantity":"2.245"},{"price":"1216.11","quantity":"6.464"},{"price":"1221.11","quantity":"0.928"},{"price":"1562.49","quantity":"0.026"},{"price":"1562.50","quantity":"4.246"},{"price":"1666.60","quantity":"1.078"},{"price":"1684.21","quantity":"132.339"},{"price":"1688.61","quantity":"61.593"},{"price":"1701.39","quantity":"32.187"},{"price":"1722.22","quantity":"4.449"},{"price":"1733.64","quantity":"2.894"},{"price":"1733.66","quantity":"23.837"},{"price":"1733.67","quantity":"5.201"},{"price":"1733.77","quantity":"20.388"},{"price":"1733.82","quantity":"3.175"},{"price":"1733.89","quantity":"0.765"},{"price":"1733.91","quantity":"0.465"},{"price":"1734.06","quantity":"54.181"},{"price":"1734.12","quantity":"486.842"},{"price":"1734.18","quantity":"0.012"},{"price":"1734.60","quantity":"0.909"},{"price":"1735.11","quantity":"37.068"},{"price":"1735.44","quantity":"27.914"},{"price":"1735.45","quantity":"0.092"},{"price":"1735.70","quantity":"5.786"},{"price":"1735.72","quantity":"2.321"},{"price":"1735.87","quantity":"5.843"},{"price":"1735.91","quantity":"13.285"},{"price":"1735.95","quantity":"0.674"},{"price":"1735.96","quantity":"1.352"},{"price":"1735.97","quantity":"6.775"},{"price":"1735.98","quantity":"1.836"},{"price":"1736.11","quantity":"231.262"}],"asks":[{"price":"1736.25","quantity":"7.753"},{"price":"1736.32","quantity":"18.248"},{"price":"1736.36","quantity":"17.468"},{"price":"1736.38","quantity":"21.392"},{"price":"1736.41","quantity":"3.524"},{"price":"1736.42","quantity":"68.968"},{"price":"1736.43","quantity":"13.920"},{"price":"1736.45","quantity":"7.939"},{"price":"1736.47","quantity":"13.768"},{"price":"1736.50","quantity":"4.502"},{"price":"1736.51","quantity":"5.145"},{"price":"1736.54","quantity":"31.690"},{"price":"1736.98","quantity":"5.188"},{"price":"1737.09","quantity":"35.477"},{"price":"1737.11","quantity":"26.537"},{"price":"1737.13","quantity":"8.727"},{"price":"1737.14","quantity":"99.693"},{"price":"1737.18","quantity":"26.925"},{"price":"1737.68","quantity":"0.970"},{"price":"1737.80","quantity":"3.564"},{"price":"1737.82","quantity":"20.488"},{"price":"1738.44","quantity":"1.071"},{"price":"1738.91","quantity":"3.541"},{"price":"1738.96","quantity":"0.000"},{"price":"1739.62","quantity":"12.625"},{"price":"1739.64","quantity":"4.837"},{"price":"1740.00","quantity":"141.706"},{"price":"1758.95","quantity":"63.883"},{"price":"1772.75","quantity":"0.012"},{"price":"2634.04","quantity":"0.001"},{"price":"2634.05","quantity":"0.001"},{"price":"2634.13","quantity":"0.000"},{"price":"2634.14","quantity":"0.000"}],"raw":{"e":"depthUpdate","E":1783517072804,"T":1783517072802,"s":"ETHUSDT","ps":"ETHUSDT","U":10999771114755,"u":10999771123773,"pu":10999771114592,"b":[["200.00","7.594"],["1211.11","2.245"],["1216.11","6.464"],["1221.11","0.928"],["1562.49","0.026"],["1562.50","4.246"],["1666.60","1.078"],["1684.21","132.339"],["1688.61","61.593"],["1701.39","32.187"],["1722.22","4.449"],["1733.64","2.894"],["1733.66","23.837"],["1733.67","5.201"],["1733.77","20.388"],["1733.82","3.175"],["1733.89","0.765"],["1733.91","0.465"],["1734.06","54.181"],["1734.12","486.842"],["1734.18","0.012"],["1734.60","0.909"],["1735.11","37.068"],["1735.44","27.914"],["1735.45","0.092"],["1735.70","5.786"],["1735.72","2.321"],["1735.87","5.843"],["1735.91","13.285"],["1735.95","0.674"],["1735.96","1.352"],["1735.97","6.775"],["1735.98","1.836"],["1736.11","231.262"]],"a":[["1736.25","7.753"],["1736.32","18.248"],["1736.36","17.468"],["1736.38","21.392"],["1736.41","3.524"],["1736.42","68.968"],["1736.43","13.920"],["1736.45","7.939"],["1736.47","13.768"],["1736.50","4.502"],["1736.51","5.145"],["1736.54","31.690"],["1736.98","5.188"],["1737.09","35.477"],["1737.11","26.537"],["1737.13","8.727"],["1737.14","99.693"],["1737.18","26.925"],["1737.68","0.970"],["1737.80","3.564"],["1737.82","20.488"],["1738.44","1.071"],["1738.91","3.541"],["1738.96","0.000"],["1739.62","12.625"],["1739.64","4.837"],["1740.00","141.706"],["1758.95","63.883"],["1772.75","0.012"],["2634.04","0.001"],["2634.05","0.001"],["2634.13","0.000"],["2634.14","0.000"]],"st":1}}
{"schema_version":"1.3.0","event_id":"24348dd8-d96f-4360-ab22-97589f9f4161","event_type":"raw.depth_update","source":"binance_market_data_recorder","venue":"binance_usdm","market_type":"perpetual_futures","symbol":"ETHUSDT","event_time_ms":1783517072906,"received_time_ms":1783517072901,"trace_id":"9cf5b577-0c3b-4684-8f4f-a05e23701c67","first_update_id":10999771123989,"final_update_id":10999771131603,"previous_final_update_id":10999771123773,"bids":[{"price":"200.00","quantity":"7.594"},{"price":"1211.11","quantity":"2.821"},{"price":"1216.11","quantity":"6.144"},{"price":"1221.11","quantity":"0.672"},{"price":"1562.49","quantity":"0.026"},{"price":"1562.50","quantity":"4.374"},{"price":"1666.60","quantity":"1.193"},{"price":"1701.46","quantity":"2.329"},{"price":"1705.75","quantity":"58.547"},{"price":"1719.03","quantity":"0.031"},{"price":"1722.22","quantity":"4.413"},{"price":"1730.07","quantity":"135.828"},{"price":"1730.08","quantity":"26.320"},{"price":"1730.09","quantity":"4.351"},{"price":"1733.77","quantity":"17.192"},{"price":"1733.78","quantity":"2.612"},{"price":"1733.82","quantity":"6.371"},{"price":"1733.83","quantity":"2.890"},{"price":"1733.84","quantity":"14.407"},{"price":"1734.12","quantity":"55.897"},{"price":"1734.18","quantity":"430.957"},{"price":"1734.63","quantity":"19.778"},{"price":"1735.17","quantity":"0.847"},{"price":"1735.20","quantity":"57.919"},{"price":"1735.44","quantity":"40.443"},{"price":"1735.55","quantity":"11.406"},{"price":"1735.56","quantity":"30.506"},{"price":"1735.63","quantity":"0.558"},{"price":"1735.70","quantity":"5.798"},{"price":"1735.73","quantity":"27.747"},{"price":"1735.76","quantity":"11.341"},{"price":"1735.90","quantity":"3.066"},{"price":"1735.93","quantity":"6.310"},{"price":"1736.06","quantity":"8.694"},{"price":"1736.10","quantity":"6.478"},{"price":"1736.11","quantity":"224.746"}],"asks":[{"price":"1736.27","quantity":"14.741"},{"price":"1736.29","quantity":"7.562"},{"price":"1736.41","quantity":"3.506"},{"price":"1736.42","quantity":"68.986"},{"price":"1736.46","quantity":"46.505"},{"price":"1736.48","quantity":"6.101"},{"price":"1736.50","quantity":"6.214"},{"price":"1736.51","quantity":"7.305"},{"price":"1736.63","quantity":"13.246"},{"price":"1736.68","quantity":"4.705"},{"price":"1736.73","quantity":"2.157"},{"price":"1737.16","quantity":"15.050"},{"price":"1737.18","quantity":"29.085"},{"price":"1737.60","quantity":"7.231"},{"price":"1737.64","quantity":"27.062"},{"price":"1737.80","quantity":"29.694"},{"price":"1738.12","quantity":"4.331"},{"price":"1738.17","quantity":"67.773"},{"price":"1738.89","quantity":"59.745"},{"price":"1738.90","quantity":"170.825"},{"price":"1738.91","quantity":"0.345"},{"price":"1768.24","quantity":"38.968"},{"price":"1771.03","quantity":"19.805"},{"price":"2634.03","quantity":"0.001"},{"price":"2634.12","quantity":"0.000"}],"raw":{"e":"depthUpdate","E":1783517072906,"T":1783517072905,"s":"ETHUSDT","ps":"ETHUSDT","U":10999771123989,"u":10999771131603,"pu":10999771123773,"b":[["200.00","7.594"],["1211.11","2.821"],["1216.11","6.144"],["1221.11","0.672"],["1562.49","0.026"],["1562.50","4.374"],["1666.60","1.193"],["1701.46","2.329"],["1705.75","58.547"],["1719.03","0.031"],["1722.22","4.413"],["1730.07","135.828"],["1730.08","26.320"],["1730.09","4.351"],["1733.77","17.192"],["1733.78","2.612"],["1733.82","6.371"],["1733.83","2.890"],["1733.84","14.407"],["1734.12","55.897"],["1734.18","430.957"],["1734.63","19.778"],["1735.17","0.847"],["1735.20","57.919"],["1735.44","40.443"],["1735.55","11.406"],["1735.56","30.506"],["1735.63","0.558"],["1735.70","5.798"],["1735.73","27.747"],["1735.76","11.341"],["1735.90","3.066"],["1735.93","6.310"],["1736.06","8.694"],["1736.10","6.478"],["1736.11","224.746"]],"a":[["1736.27","14.741"],["1736.29","7.562"],["1736.41","3.506"],["1736.42","68.986"],["1736.46","46.505"],["1736.48","6.101"],["1736.50","6.214"],["1736.51","7.305"],["1736.63","13.246"],["1736.68","4.705"],["1736.73","2.157"],["1737.16","15.050"],["1737.18","29.085"],["1737.60","7.231"],["1737.64","27.062"],["1737.80","29.694"],["1738.12","4.331"],["1738.17","67.773"],["1738.89","59.745"],["1738.90","170.825"],["1738.91","0.345"],["1768.24","38.968"],["1771.03","19.805"],["2634.03","0.001"],["2634.12","0.000"]],"st":1}}
{"schema_version":"1.3.0","event_id":"89186d3d-ea28-44cc-a76f-88c1af111a33","event_type":"raw.depth_update","source":"binance_market_data_recorder","venue":"binance_usdm","market_type":"perpetual_futures","symbol":"ETHUSDT","event_time_ms":1783517073008,"received_time_ms":1783517073003,"trace_id":"1d95690e-c985-4f3e-b55b-7eb2dc588383","first_update_id":10999771131733,"final_update_id":10999771141088,"previous_final_update_id":10999771131603,"bids":[{"price":"1211.11","quantity":"3.333"},{"price":"1216.11","quantity":"5.920"},{"price":"1221.11","quantity":"0.384"},{"price":"1562.04","quantity":"0.070"},{"price":"1562.49","quantity":"0.000"},{"price":"1562.50","quantity":"4.246"},{"price":"1666.60","quantity":"1.078"},{"price":"1672.58","quantity":"16.120"},{"price":"1684.89","quantity":"79.813"},{"price":"1701.39","quantity":"32.216"},{"price":"1702.87","quantity":"0.427"},{"price":"1703.12","quantity":"34.520"},{"price":"1712.95","quantity":"10.992"},{"price":"1714.41","quantity":"99.009"},{"price":"1716.56","quantity":"0.000"},{"price":"1718.30","quantity":"10.737"},{"price":"1720.03","quantity":"0.057"},{"price":"1721.76","quantity":"24.968"},{"price":"1723.49","quantity":"0.067"},{"price":"1725.23","quantity":"0.734"},{"price":"1726.96","quantity":"0.805"},{"price":"1728.69","quantity":"1.959"},{"price":"1730.42","quantity":"33.071"},{"price":"1732.08","quantity":"3.026"},{"price":"1732.15","quantity":"5.990"},{"price":"1732.87","quantity":"0.804"},{"price":"1732.95","quantity":"17.102"},{"price":"1733.50","quantity":"10.855"},{"price":"1733.71","quantity":"515.468"},{"price":"1733.74","quantity":"15.812"},{"price":"1733.76","quantity":"95.790"},{"price":"1733.78","quantity":"1.166"},{"price":"1733.82","quantity":"3.175"},{"price":"1733.84","quantity":"15.007"},{"price":"1733.91","quantity":"1.911"},{"price":"1734.18","quantity":"0.012"},{"price":"1734.92","quantity":"63.246"},{"price":"1735.18","quantity":"1.494"},{"price":"1735.19","quantity":"70.915"},{"price":"1735.20","quantity":"58.112"},{"price":"1735.21","quantity":"34.684"},{"price":"1735.55","quantity":"4.604"},{"price":"1735.56","quantity":"27.627"},{"price":"1735.59","quantity":"224.000"},{"price":"1735.62","quantity":"13.345"},{"price":"1735.65","quantity":"0.115"},{"price":"1735.67","quantity":"0.371"},{"price":"1735.71","quantity":"219.690"},{"price":"1735.74","quantity":"47.389"},{"price":"1735.76","quantity":"15.564"},{"price":"1735.98","quantity":"69.066"},{"price":"1736.00","quantity":"17.102"},{"price":"1736.01","quantity":"0.050"},{"price":"1736.11","quantity":"222.746"}],"asks":[{"price":"1736.23","quantity":"0.162"},{"price":"1736.24","quantity":"6.168"},{"price":"1736.25","quantity":"2.834"},{"price":"1736.27","quantity":"14.655"},{"price":"1736.32","quantity":"18.248"},{"price":"1736.81","quantity":"19.320"},{"price":"1737.01","quantity":"74.977"},{"price":"1737.02","quantity":"21.902"},{"price":"1737.03","quantity":"83.599"},{"price":"1737.12","quantity":"1.626"},{"price":"1737.87","quantity":"7.835"},{"price":"1738.12","quantity":"5.998"},{"price":"1738.17","quantity":"7.677"},{"price":"1738.19","quantity":"16.320"},{"price":"1738.20","quantity":"402.776"},{"price":"1738.32","quantity":"1.077"},{"price":"1738.91","quantity":"3.541"},{"price":"1747.12","quantity":"0.000"},{"price":"1758.70","quantity":"32.719"},{"price":"1769.95","quantity":"45.274"},{"price":"2634.02","quantity":"0.001"},{"price":"2634.11","quantity":"0.000"}],"raw":{"e":"depthUpdate","E":1783517073008,"T":1783517073007,"s":"ETHUSDT","ps":"ETHUSDT","U":10999771131733,"u":10999771141088,"pu":10999771131603,"b":[["1211.11","3.333"],["1216.11","5.920"],["1221.11","0.384"],["1562.04","0.070"],["1562.49","0.000"],["1562.50","4.246"],["1666.60","1.078"],["1672.58","16.120"],["1684.89","79.813"],["1701.39","32.216"],["1702.87","0.427"],["1703.12","34.520"],["1712.95","10.992"],["1714.41","99.009"],["1716.56","0.000"],["1718.30","10.737"],["1720.03","0.057"],["1721.76","24.968"],["1723.49","0.067"],["1725.23","0.734"],["1726.96","0.805"],["1728.69","1.959"],["1730.42","33.071"],["1732.08","3.026"],["1732.15","5.990"],["1732.87","0.804"],["1732.95","17.102"],["1733.50","10.855"],["1733.71","515.468"],["1733.74","15.812"],["1733.76","95.790"],["1733.78","1.166"],["1733.82","3.175"],["1733.84","15.007"],["1733.91","1.911"],["1734.18","0.012"],["1734.92","63.246"],["1735.18","1.494"],["1735.19","70.915"],["1735.20","58.112"],["1735.21","34.684"],["1735.55","4.604"],["1735.56","27.627"],["1735.59","224.000"],["1735.62","13.345"],["1735.65","0.115"],["1735.67","0.371"],["1735.71","219.690"],["1735.74","47.389"],["1735.76","15.564"],["1735.98","69.066"],["1736.00","17.102"],["1736.01","0.050"],["1736.11","222.746"]],"a":[["1736.23","0.162"],["1736.24","6.168"],["1736.25","2.834"],["1736.27","14.655"],["1736.32","18.248"],["1736.81","19.320"],["1737.01","74.977"],["1737.02","21.902"],["1737.03","83.599"],["1737.12","1.626"],["1737.87","7.835"],["1738.12","5.998"],["1738.17","7.677"],["1738.19","16.320"],["1738.20","402.776"],["1738.32","1.077"],["1738.91","3.541"],["1747.12","0.000"],["1758.70","32.719"],["1769.95","45.274"],["2634.02","0.001"],["2634.11","0.000"]],"st":1}}
{"schema_version":"1.3.0","event_id":"f81aeaaa-e68e-40a0-8a94-99957308de40","event_type":"raw.depth_update","source":"binance_market_data_recorder","venue":"binance_usdm","market_type":"perpetual_futures","symbol":"ETHUSDT","event_time_ms":1783517073110,"received_time_ms":1783517073106,"trace_id":"e21886c1-aa75-4cde-b541-292c00b00296","first_update_id":10999771141093,"final_update_id":10999771151119,"previous_final_update_id":10999771141088,"bids":[{"price":"200.00","quantity":"7.594"},{"price":"1211.11","quantity":"3.909"},{"price":"1216.11","quantity":"5.600"},{"price":"1221.11","quantity":"0.128"},{"price":"1562.49","quantity":"0.026"},{"price":"1562.50","quantity":"4.246"},{"price":"1693.00","quantity":"178.479"},{"price":"1701.39","quantity":"32.187"},{"price":"1702.16","quantity":"21.163"},{"price":"1733.86","quantity":"3.559"},{"price":"1733.92","quantity":"17.984"},{"price":"1735.11","quantity":"37.068"},{"price":"1735.17","quantity":"1.647"},{"price":"1735.21","quantity":"35.484"},{"price":"1735.24","quantity":"8.346"},{"price":"1735.62","quantity":"10.466"},{"price":"1735.72","quantity":"5.200"},{"price":"1735.76","quantity":"15.564"},{"price":"1735.94","quantity":"21.345"},{"price":"1735.98","quantity":"69.084"},{"price":"1736.02","quantity":"4.425"}],"asks":[{"price":"1736.32","quantity":"18.260"},{"price":"1736.47","quantity":"13.768"},{"price":"1736.64","quantity":"76.316"},{"price":"1737.20","quantity":"26.499"},{"price":"1737.86","quantity":"3.469"},{"price":"1737.87","quantity":"7.926"},{"price":"2634.00","quantity":"0.559"},{"price":"2634.01","quantity":"0.021"},{"price":"2634.09","quantity":"0.000"},{"price":"2634.10","quantity":"0.000"}],"raw":{"e":"depthUpdate","E":1783517073110,"T":1783517073109,"s":"ETHUSDT","ps":"ETHUSDT","U":10999771141093,"u":10999771151119,"pu":10999771141088,"b":[["200.00","7.594"],["1211.11","3.909"],["1216.11","5.600"],["1221.11","0.128"],["1562.49","0.026"],["1562.50","4.246"],["1693.00","178.479"],["1701.39","32.187"],["1702.16","21.163"],["1733.86","3.559"],["1733.92","17.984"],["1735.11","37.068"],["1735.17","1.647"],["1735.21","35.484"],["1735.24","8.346"],["1735.62","10.466"],["1735.72","5.200"],["1735.76","15.564"],["1735.94","21.345"],["1735.98","69.084"],["1736.02","4.425"]],"a":[["1736.32","18.260"],["1736.47","13.768"],["1736.64","76.316"],["1737.20","26.499"],["1737.86","3.469"],["1737.87","7.926"],["2634.00","0.559"],["2634.01","0.021"],["2634.09","0.000"],["2634.10","0.000"]],"st":1}}
{"schema_version":"1.3.0","event_id":"c46dc574-c63b-4809-88be-b15a852a1e67","event_type":"raw.depth_update","source":"binance_market_data_recorder","venue":"binance_usdm","market_type":"perpetual_futures","symbol":"ETHUSDT","event_time_ms":1783517073212,"received_time_ms":1783517073207,"trace_id":"b477b803-e4b2-4a22-8493-8063e01dd4b9","first_update_id":10999771151308,"final_update_id":10999771158951,"previous_final_update_id":10999771151119,"bids":[{"price":"200.00","quantity":"7.594"},{"price":"1211.11","quantity":"4.581"},{"price":"1216.11","quantity":"5.056"},{"price":"1221.11","quantity":"0.000"},{"price":"1562.49","quantity":"0.026"},{"price":"1562.50","quantity":"4.630"},{"price":"1666.60","quantity":"1.193"},{"price":"1697.92","quantity":"0.269"},{"price":"1708.13","quantity":"32.048"},{"price":"1708.67","quantity":"60.777"},{"price":"1713.09","quantity":"0.775"},{"price":"1732.18","quantity":"235.775"},{"price":"1735.20","quantity":"58.912"},{"price":"1735.23","quantity":"5.705"},{"price":"1735.26","quantity":"1.873"},{"price":"1735.28","quantity":"4.562"},{"price":"1735.29","quantity":"31.064"},{"price":"1735.30","quantity":"29.959"},{"price":"1735.59","quantity":"4.353"},{"price":"1735.71","quantity":"0.038"},{"price":"1735.74","quantity":"16.742"},{"price":"1735.75","quantity":"290.303"},{"price":"1735.83","quantity":"52.110"},{"price":"1736.11","quantity":"222.789"}],"asks":[{"price":"1736.12","quantity":"7.813"},{"price":"1736.24","quantity":"1.249"},{"price":"1736.29","quantity":"7.562"},{"price":"1736.32","quantity":"18.260"},{"price":"1736.38","quantity":"20.892"},{"price":"1736.41","quantity":"4.006"},{"price":"1736.46","quantity":"46.505"},{"price":"1736.54","quantity":"2.869"},{"price":"1736.59","quantity":"30.577"},{"price":"1736.63","quantity":"13.246"},{"price":"1738.12","quantity":"22.674"},{"price":"1738.81","quantity":"9.053"},{"price":"1738.94","quantity":"7.156"},{"price":"1768.27","quantity":"92.984"},{"price":"1771.94","quantity":"0.052"},{"price":"2633.99","quantity":"0.001"},{"price":"2634.08","quantity":"0.000"}],"raw":{"e":"depthUpdate","E":1783517073212,"T":1783517073209,"s":"ETHUSDT","ps":"ETHUSDT","U":10999771151308,"u":10999771158951,"pu":10999771151119,"b":[["200.00","7.594"],["1211.11","4.581"],["1216.11","5.056"],["1221.11","0.000"],["1562.49","0.026"],["1562.50","4.630"],["1666.60","1.193"],["1697.92","0.269"],["1708.13","32.048"],["1708.67","60.777"],["1713.09","0.775"],["1732.18","235.775"],["1735.20","58.912"],["1735.23","5.705"],["1735.26","1.873"],["1735.28","4.562"],["1735.29","31.064"],["1735.30","29.959"],["1735.59","4.353"],["1735.71","0.038"],["1735.74","16.742"],["1735.75","290.303"],["1735.83","52.110"],["1736.11","222.789"]],"a":[["1736.12","7.813"],["1736.24","1.249"],["1736.29","7.562"],["1736.32","18.260"],["1736.38","20.892"],["1736.41","4.006"],["1736.46","46.505"],["1736.54","2.869"],["1736.59","30.577"],["1736.63","13.246"],["1738.12","22.674"],["1738.81","9.053"],["1738.94","7.156"],["1768.27","92.984"],["1771.94","0.052"],["2633.99","0.001"],["2634.08","0.000"]],"st":1}}
{"schema_version":"1.3.0","event_id":"a78548f0-54bd-4124-98e1-962ad28b130e","event_type":"raw.depth_update","source":"binance_market_data_recorder","venue":"binance_usdm","market_type":"perpetual_futures","symbol":"ETHUSDT","event_time_ms":1783517073314,"received_time_ms":1783517073309,"trace_id":"fb952691-549d-4527-96d4-3e82dd823345","first_update_id":10999771159181,"final_update_id":10999771167278,"previous_final_update_id":10999771158951,"bids":[{"price":"1211.11","quantity":"5.413"},{"price":"1216.11","quantity":"4.224"},{"price":"1562.49","quantity":"0.026"},{"price":"1562.50","quantity":"4.502"},{"price":"1666.60","quantity":"1.078"},{"price":"1701.38","quantity":"43.670"},{"price":"1701.61","quantity":"28.888"},{"price":"1734.64","quantity":"0.556"},{"price":"1734.73","quantity":"96.598"},{"price":"1734.98","quantity":"69.905"},{"price":"1735.23","quantity":"6.505"},{"price":"1735.33","quantity":"16.517"},{"price":"1735.42","quantity":"20.653"},{"price":"1735.52","quantity":"297.572"},{"price":"1735.53","quantity":"15.021"},{"price":"1735.54","quantity":"2.906"},{"price":"1735.58","quantity":"0.094"},{"price":"1735.72","quantity":"2.321"},{"price":"1735.75","quantity":"70.662"},{"price":"1735.76","quantity":"13.836"},{"price":"1735.83","quantity":"21.905"},{"price":"1736.04","quantity":"8.692"},{"price":"1736.06","quantity":"0.046"},{"price":"1736.09","quantity":"0.944"},{"price":"1736.10","quantity":"6.692"},{"price":"1736.11","quantity":"222.829"}],"asks":[{"price":"1736.12","quantity":"8.132"},{"price":"1736.15","quantity":"0.012"},{"price":"1736.16","quantity":"0.279"},{"price":"1736.25","quantity":"7.753"},{"price":"1736.31","quantity":"17.471"},{"price":"1736.61","quantity":"11.096"},{"price":"1736.69","quantity":"7.376"},{"price":"1736.80","quantity":"4.218"},{"price":"1736.81","quantity":"20.957"},{"price":"1737.12","quantity":"1.626"},{"price":"1737.15","quantity":"8.297"},{"price":"1737.32","quantity":"1.295"},{"price":"1737.34","quantity":"29.891"},{"price":"1737.49","quantity":"82.051"},{"price":"1737.50","quantity":"137.065"},{"price":"1737.51","quantity":"2.858"},{"price":"1737.60","quantity":"4.591"},{"price":"1737.66","quantity":"0.172"},{"price":"1737.67","quantity":"70.439"},{"price":"1737.82","quantity":"46.618"},{"price":"1737.84","quantity":"75.433"},{"price":"1737.85","quantity":"92.432"},{"price":"1737.87","quantity":"7.835"},{"price":"1737.94","quantity":"1.679"},{"price":"1738.12","quantity":"21.007"},{"price":"1738.91","quantity":"0.345"},{"price":"1738.94","quantity":"3.960"},{"price":"1747.12","quantity":"15.000"},{"price":"1781.70","quantity":"0.000"},{"price":"2633.97","quantity":"50.001"},{"price":"2633.98","quantity":"0.001"},{"price":"2634.06","quantity":"0.011"},{"price":"2634.07","quantity":"0.021"}],"raw":{"e":"depthUpdate","E":1783517073314,"T":1783517073313,"s":"ETHUSDT","ps":"ETHUSDT","U":10999771159181,"u":10999771167278,"pu":10999771158951,"b":[["1211.11","5.413"],["1216.11","4.224"],["1562.49","0.026"],["1562.50","4.502"],["1666.60","1.078"],["1701.38","43.670"],["1701.61","28.888"],["1734.64","0.556"],["1734.73","96.598"],["1734.98","69.905"],["1735.23","6.505"],["1735.33","16.517"],["1735.42","20.653"],["1735.52","297.572"],["1735.53","15.021"],["1735.54","2.906"],["1735.58","0.094"],["1735.72","2.321"],["1735.75","70.662"],["1735.76","13.836"],["1735.83","21.905"],["1736.04","8.692"],["1736.06","0.046"],["1736.09","0.944"],["1736.10","6.692"],["1736.11","222.829"]],"a":[["1736.12","8.132"],["1736.15","0.012"],["1736.16","0.279"],["1736.25","7.753"],["1736.31","17.471"],["1736.61","11.096"],["1736.69","7.376"],["1736.80","4.218"],["1736.81","20.957"],["1737.12","1.626"],["1737.15","8.297"],["1737.32","1.295"],["1737.34","29.891"],["1737.49","82.051"],["1737.50","137.065"],["1737.51","2.858"],["1737.60","4.591"],["1737.66","0.172"],["1737.67","70.439"],["1737.82","46.618"],["1737.84","75.433"],["1737.85","92.432"],["1737.87","7.835"],["1737.94","1.679"],["1738.12","21.007"],["1738.91","0.345"],["1738.94","3.960"],["1747.12","15.000"],["1781.70","0.000"],["2633.97","50.001"],["2633.98","0.001"],["2634.06","0.011"],["2634.07","0.021"]],"st":1}}
{"schema_version":"1.3.0","event_id":"e7fab44a-85f6-4adc-90d5-8e3251e4fd97","event_type":"raw.depth_update","source":"binance_market_data_recorder","venue":"binance_usdm","market_type":"perpetual_futures","symbol":"ETHUSDT","event_time_ms":1783517073416,"received_time_ms":1783517073411,"trace_id":"d1d97975-2aef-4fc2-9be8-d9684fb468d1","first_update_id":10999771167435,"final_update_id":10999771174470,"previous_final_update_id":10999771167278,"bids":[{"price":"200.00","quantity":"7.594"},{"price":"1211.11","quantity":"6.213"},{"price":"1216.11","quantity":"3.424"},{"price":"1562.49","quantity":"0.026"},{"price":"1562.50","quantity":"4.502"},{"price":"1666.60","quantity":"1.193"},{"price":"1701.38","quantity":"43.641"},{"price":"1705.75","quantity":"58.547"},{"price":"1712.96","quantity":"10.302"},{"price":"1732.08","quantity":"0.026"},{"price":"1733.50","quantity":"13.855"},{"price":"1733.76","quantity":"97.236"},{"price":"1733.91","quantity":"0.465"},{"price":"1735.11","quantity":"37.068"},{"price":"1735.38","quantity":"284.658"},{"price":"1735.39","quantity":"39.498"},{"price":"1735.41","quantity":"124.151"},{"price":"1735.42","quantity":"20.671"},{"price":"1735.43","quantity":"0.479"},{"price":"1735.46","quantity":"22.487"},{"price":"1735.52","quantity":"77.961"},{"price":"1735.54","quantity":"0.027"},{"price":"1735.90","quantity":"2.066"},{"price":"1736.03","quantity":"10.458"},{"price":"1736.04","quantity":"0.044"},{"price":"1736.10","quantity":"6.692"},{"price":"1736.11","quantity":"222.842"}],"asks":[{"price":"1736.12","quantity":"37.194"},{"price":"1736.15","quantity":"0.024"},{"price":"1736.16","quantity":"0.291"},{"price":"1736.25","quantity":"2.834"},{"price":"1736.29","quantity":"23.868"},{"price":"1736.30","quantity":"29.186"},{"price":"1736.32","quantity":"18.260"},{"price":"1736.34","quantity":"6.669"},{"price":"1736.35","quantity":"4.537"},{"price":"1736.46","quantity":"50.881"},{"price":"1736.52","quantity":"12.917"},{"price":"1736.55","quantity":"33.228"},{"price":"1736.63","quantity":"8.870"},{"price":"1736.73","quantity":"3.824"},{"price":"1736.81","quantity":"19.290"},{"price":"1736.90","quantity":"31.475"},{"price":"1737.33","quantity":"19.563"},{"price":"1737.66","quantity":"0.154"},{"price":"1737.67","quantity":"70.457"},{"price":"1737.83","quantity":"33.086"},{"price":"1737.94","quantity":"0.012"},{"price":"1738.04","quantity":"0.239"},{"price":"1738.89","quantity":"59.745"},{"price":"1767.37","quantity":"43.288"},{"price":"1768.95","quantity":"37.547"},{"price":"1774.50","quantity":"3.357"},{"price":"2633.96","quantity":"0.001"},{"price":"2634.05","quantity":"0.000"}],"raw":{"e":"depthUpdate","E":1783517073416,"T":1783517073413,"s":"ETHUSDT","ps":"ETHUSDT","U":10999771167435,"u":10999771174470,"pu":10999771167278,"b":[["200.00","7.594"],["1211.11","6.213"],["1216.11","3.424"],["1562.49","0.026"],["1562.50","4.502"],["1666.60","1.193"],["1701.38","43.641"],["1705.75","58.547"],["1712.96","10.302"],["1732.08","0.026"],["1733.50","13.855"],["1733.76","97.236"],["1733.91","0.465"],["1735.11","37.068"],["1735.38","284.658"],["1735.39","39.498"],["1735.41","124.151"],["1735.42","20.671"],["1735.43","0.479"],["1735.46","22.487"],["1735.52","77.961"],["1735.54","0.027"],["1735.90","2.066"],["1736.03","10.458"],["1736.04","0.044"],["1736.10","6.692"],["1736.11","222.842"]],"a":[["1736.12","37.194"],["1736.15","0.024"],["1736.16","0.291"],["1736.25","2.834"],["1736.29","23.868"],["1736.30","29.186"],["1736.32","18.260"],["1736.34","6.669"],["1736.35","4.537"],["1736.46","50.881"],["1736.52","12.917"],["1736.55","33.228"],["1736.63","8.870"],["1736.73","3.824"],["1736.81","19.290"],["1736.90","31.475"],["1737.33","19.563"],["1737.66","0.154"],["1737.67","70.457"],["1737.83","33.086"],["1737.94","0.012"],["1738.04","0.239"],["1738.89","59.745"],["1767.37","43.288"],["1768.95","37.547"],["1774.50","3.357"],["2633.96","0.001"],["2634.05","0.000"]],"st":1}}
{"schema_version":"1.3.0","event_id":"9e9a1aec-df2c-456c-a5d3-c03b2addc211","event_type":"raw.depth_update","source":"binance_market_data_recorder","venue":"binance_usdm","market_type":"perpetual_futures","symbol":"ETHUSDT","event_time_ms":1783517073518,"received_time_ms":1783517073515,"trace_id":"1ac475bd-abec-4158-b41b-b7cd8488f1a5","first_update_id":10999771174653,"final_update_id":10999771182253,"previous_final_update_id":10999771174470,"bids":[{"price":"200.00","quantity":"7.594"},{"price":"201.00","quantity":"2.300"},{"price":"1211.11","quantity":"7.045"},{"price":"1216.11","quantity":"2.592"},{"price":"1562.49","quantity":"0.026"},{"price":"1562.50","quantity":"4.644"},{"price":"1670.03","quantity":"0.126"},{"price":"1701.38","quantity":"43.670"},{"price":"1714.41","quantity":"103.377"},{"price":"1727.42","quantity":"0.629"},{"price":"1730.58","quantity":"17.016"},{"price":"1731.87","quantity":"193.861"},{"price":"1733.48","quantity":"18.806"},{"price":"1733.61","quantity":"17.239"},{"price":"1733.71","quantity":"84.523"},{"price":"1733.76","quantity":"35.199"},{"price":"1733.86","quantity":"0.363"},{"price":"1733.95","quantity":"5.906"},{"price":"1733.96","quantity":"7.802"},{"price":"1733.98","quantity":"0.544"},{"price":"1734.18","quantity":"430.957"},{"price":"1734.40","quantity":"0.064"},{"price":"1734.50","quantity":"13.532"},{"price":"1735.19","quantity":"71.283"},{"price":"1735.20","quantity":"58.722"},{"price":"1735.21","quantity":"35.297"},{"price":"1735.41","quantity":"124.169"},{"price":"1735.42","quantity":"20.653"},{"price":"1735.46","quantity":"19.608"},{"price":"1735.52","quantity":"77.961"},{"price":"1735.56","quantity":"28.098"},{"price":"1736.11","quantity":"235.976"}],"asks":[{"price":"1736.12","quantity":"22.888"},{"price":"1736.17","quantity":"0.024"},{"price":"1736.18","quantity":"0.190"},{"price":"1736.19","quantity":"0.012"},{"price":"1736.24","quantity":"2.977"},{"price":"1736.26","quantity":"18.128"},{"price":"1736.28","quantity":"0.124"},{"price":"1736.30","quantity":"9.186"},{"price":"1736.33","quantity":"22.887"},{"price":"1736.52","quantity":"11.223"},{"price":"1736.55","quantity":"31.534"},{"price":"1736.89","quantity":"19.655"},{"price":"1736.90","quantity":"29.769"},{"price":"1736.91","quantity":"30.676"},{"price":"1736.92","quantity":"67.349"},{"price":"1736.93","quantity":"16.386"},{"price":"1736.94","quantity":"19.260"},{"price":"1737.01","quantity":"74.994"},{"price":"1737.02","quantity":"21.899"},{"price":"1737.03","quantity":"83.585"},{"price":"1737.12","quantity":"1.626"},{"price":"1737.17","quantity":"8.701"},{"price":"1737.34","quantity":"31.558"},{"price":"1737.54","quantity":"2.812"},{"price":"1737.89","quantity":"8.973"},{"price":"1743.34","quantity":"104.627"},{"price":"1743.92","quantity":"3.152"},{"price":"1744.02","quantity":"1.072"},{"price":"1744.81","quantity":"0.154"},{"price":"1747.12","quantity":"0.000"},{"price":"1757.13","quantity":"25.354"},{"price":"1767.62","quantity":"29.980"},{"price":"1772.46","quantity":"28.203"},{"price":"2633.95","quantity":"0.043"},{"price":"2634.04","quantity":"0.000"}],"raw":{"e":"depthUpdate","E":1783517073518,"T":1783517073517,"s":"ETHUSDT","ps":"ETHUSDT","U":10999771174653,"u":10999771182253,"pu":10999771174470,"b":[["200.00","7.594"],["201.00","2.300"],["1211.11","7.045"],["1216.11","2.592"],["1562.49","0.026"],["1562.50","4.644"],["1670.03","0.126"],["1701.38","43.670"],["1714.41","103.377"],["1727.42","0.629"],["1730.58","17.016"],["1731.87","193.861"],["1733.48","18.806"],["1733.61","17.239"],["1733.71","84.523"],["1733.76","35.199"],["1733.86","0.363"],["1733.95","5.906"],["1733.96","7.802"],["1733.98","0.544"],["1734.18","430.957"],["1734.40","0.064"],["1734.50","13.532"],["1735.19","71.283"],["1735.20","58.722"],["1735.21","35.297"],["1735.41","124.169"],["1735.42","20.653"],["1735.46","19.608"],["1735.52","77.961"],["1735.56","28.098"],["1736.11","235.976"]],"a":[["1736.12","22.888"],["1736.17","0.024"],["1736.18","0.190"],["1736.19","0.012"],["1736.24","2.977"],["1736.26","18.128"],["1736.28","0.124"],["1736.30","9.186"],["1736.33","22.887"],["1736.52","11.223"],["1736.55","31.534"],["1736.89","19.655"],["1736.90","29.769"],["1736.91","30.676"],["1736.92","67.349"],["1736.93","16.386"],["1736.94","19.260"],["1737.01","74.994"],["1737.02","21.899"],["1737.03","83.585"],["1737.12","1.626"],["1737.17","8.701"],["1737.34","31.558"],["1737.54","2.812"],["1737.89","8.973"],["1743.34","104.627"],["1743.92","3.152"],["1744.02","1.072"],["1744.81","0.154"],["1747.12","0.000"],["1757.13","25.354"],["1767.62","29.980"],["1772.46","28.203"],["2633.95","0.043"],["2634.04","0.000"]],"st":1}}
{"schema_version":"1.3.0","event_id":"bb84d27a-11e2-4806-8b57-dc8240a38d2b","event_type":"raw.depth_update","source":"binance_market_data_recorder","venue":"binance_usdm","market_type":"perpetual_futures","symbol":"ETHUSDT","event_time_ms":1783517073620,"received_time_ms":1783517073616,"trace_id":"fe4d3d63-c199-40bf-9951-8210c07b2055","first_update_id":10999771182318,"final_update_id":10999771191265,"previous_final_update_id":10999771182253,"bids":[{"price":"1211.11","quantity":"7.333"},{"price":"1216.11","quantity":"2.048"},{"price":"1231.11","quantity":"0.256"},{"price":"1562.49","quantity":"0.026"},{"price":"1562.50","quantity":"4.516"},{"price":"1650.00","quantity":"1681.223"},{"price":"1666.60","quantity":"1.078"},{"price":"1701.38","quantity":"43.641"},{"price":"1727.42","quantity":"0.617"},{"price":"1731.38","quantity":"0.034"},{"price":"1731.41","quantity":"25.491"},{"price":"1731.56","quantity":"108.680"},{"price":"1732.08","quantity":"3.026"},{"price":"1732.27","quantity":"1.745"},{"price":"1733.50","quantity":"10.855"},{"price":"1733.85","quantity":"88.181"},{"price":"1733.95","quantity":"4.460"},{"price":"1733.96","quantity":"4.606"},{"price":"1733.97","quantity":"0.595"},{"price":"1733.99","quantity":"0.014"},{"price":"1734.01","quantity":"20.653"},{"price":"1735.42","quantity":"240.173"},{"price":"1735.82","quantity":"29.854"},{"price":"1736.07","quantity":"0.140"},{"price":"1736.11","quantity":"215.182"}],"asks":[{"price":"1736.12","quantity":"23.882"},{"price":"1736.25","quantity":"7.753"},{"price":"1736.26","quantity":"13.209"},{"price":"1736.29","quantity":"23.868"},{"price":"1737.01","quantity":"75.011"},{"price":"1737.02","quantity":"21.882"},{"price":"1737.36","quantity":"71.029"},{"price":"1737.57","quantity":"43.195"},{"price":"1744.81","quantity":"0.166"},{"price":"1761.99","quantity":"34.016"},{"price":"1765.08","quantity":"5.044"},{"price":"1779.52","quantity":"28.055"},{"price":"2633.93","quantity":"0.001"},{"price":"2633.94","quantity":"0.001"},{"price":"2634.02","quantity":"0.000"},{"price":"2634.03","quantity":"0.000"}],"raw":{"e":"depthUpdate","E":1783517073620,"T":1783517073617,"s":"ETHUSDT","ps":"ETHUSDT","U":10999771182318,"u":10999771191265,"pu":10999771182253,"b":[["1211.11","7.333"],["1216.11","2.048"],["1231.11","0.256"],["1562.49","0.026"],["1562.50","4.516"],["1650.00","1681.223"],["1666.60","1.078"],["1701.38","43.641"],["1727.42","0.617"],["1731.38","0.034"],["1731.41","25.491"],["1731.56","108.680"],["1732.08","3.026"],["1732.27","1.745"],["1733.50","10.855"],["1733.85","88.181"],["1733.95","4.460"],["1733.96","4.606"],["1733.97","0.595"],["1733.99","0.014"],["1734.01","20.653"],["1735.42","240.173"],["1735.82","29.854"],["1736.07","0.140"],["1736.11","215.182"]],"a":[["1736.12","23.882"],["1736.25","7.753"],["1736.26","13.209"],["1736.29","23.868"],["1737.01","75.011"],["1737.02","21.882"],["1737.36","71.029"],["1737.57","43.195"],["1744.81","0.166"],["1761.99","34.016"],["1765.08","5.044"],["1779.52","28.055"],["2633.93","0.001"],["2633.94","0.001"],["2634.02","0.000"],["2634.03","0.000"]],"st":1}}
{"schema_version":"1.3.0","event_id":"d4db017d-b793-4cd9-865f-3661950f2efa","event_type":"raw.depth_update","source":"binance_market_data_recorder","venue":"binance_usdm","market_type":"perpetual_futures","symbol":"ETHUSDT","event_time_ms":1783517073722,"received_time_ms":1783517073816,"trace_id":"99e84b1f-529a-4348-9dc8-b09712be6dbd","first_update_id":10999771191648,"final_update_id":10999771207863,"previous_final_update_id":10999771191265,"bids":[{"price":"200.00","quantity":"7.594"},{"price":"1211.11","quantity":"6.949"},{"price":"1211.28","quantity":"0.256"},{"price":"1216.11","quantity":"1.696"},{"price":"1231.11","quantity":"0.288"},{"price":"1231.28","quantity":"0.448"},{"price":"1236.11","quantity":"0.315"},{"price":"1562.04","quantity":"0.056"},{"price":"1562.20","quantity":"1.935"},{"price":"1562.49","quantity":"0.000"},{"price":"1562.50","quantity":"1.331"},{"price":"1562.65","quantity":"0.145"},{"price":"1562.66","quantity":"0.692"},{"price":"1616.79","quantity":"0.014"},{"price":"1666.80","quantity":"0.348"},{"price":"1684.12","quantity":"0.000"},{"price":"1701.56","quantity":"0.117"},{"price":"1718.65","quantity":"151.240"},{"price":"1719.02","quantity":"3.285"},{"price":"1720.77","quantity":"5.818"},{"price":"1725.35","quantity":"0.221"},{"price":"1726.15","quantity":"1.047"},{"price":"1727.44","quantity":"0.000"},{"price":"1727.81","quantity":"0.116"},{"price":"1728.81","quantity":"0.014"},{"price":"1728.94","quantity":"0.315"},{"price":"1729.50","quantity":"1.052"},{"price":"1729.72","quantity":"0.025"},{"price":"1730.01","quantity":"7.605"},{"price":"1730.17","quantity":"0.528"},{"price":"1730.23","quantity":"23.828"},{"price":"1730.45","quantity":"5.113"},{"price":"1730.46","quantity":"19.431"},{"price":"1730.72","quantity":"0.902"},{"price":"1730.94","quantity":"16.624"},{"price":"1731.24","quantity":"223.992"},{"price":"1731.27","quantity":"0.014"},{"price":"1731.28","quantity":"11.844"},{"price":"1731.33","quantity":"19.254"},{"price":"1731.87","quantity":"21.063"},{"price":"1731.96","quantity":"79.901"},{"price":"1731.98","quantity":"171.132"},{"price":"1732.08","quantity":"0.026"},{"price":"1732.22","quantity":"194.819"},{"price":"1732.30","quantity":"0.076"},{"price":"1732.32","quantity":"102.044"},{"price":"1732.39","quantity":"1.766"},{"price":"1732.41","quantity":"0.192"},{"price":"1732.59","quantity":"27.756"},{"price":"1732.69","quantity":"172.900"},{"price":"1732.75","quantity":"183.118"},{"price":"1732.76","quantity":"164.898"},{"price":"1732.77","quantity":"76.290"},{"price":"1732.81","quantity":"7.366"},{"price":"1733.07","quantity":"21.850"},{"price":"1733.40","quantity":"57.957"},{"price":"1733.41","quantity":"4.583"},{"price":"1733.50","quantity":"13.855"},{"price":"1733.53","quantity":"0.617"},{"price":"1733.65","quantity":"9.919"},{"price":"1733.70","quantity":"16.325"},{"price":"1733.71","quantity":"84.523"},{"price":"1733.74","quantity":"15.812"},{"price":"1733.77","quantity":"17.192"},{"price":"1733.82","quantity":"3.163"},{"price":"1733.88","quantity":"474.412"},{"price":"1733.89","quantity":"2.211"},{"price":"1734.01","quantity":"17.699"},{"price":"1734.04","quantity":"124.770"},{"price":"1734.05","quantity":"116.540"},{"price":"1734.06","quantity":"16.697"},{"price":"1734.13","quantity":"3.167"},{"price":"1734.18","quantity":"0.012"},{"price":"1734.20","quantity":"88.456"},{"price":"1734.21","quantity":"18.126"},{"price":"1734.31","quantity":"17.916"},{"price":"1734.38","quantity":"10.789"},{"price":"1734.50","quantity":"13.417"},{"price":"1734.51","quantity":"13.317"},{"price":"1734.54","quantity":"20.679"},{"price":"1734.56","quantity":"3.962"},{"price":"1734.63","quantity":"19.764"},{"price":"1734.64","quantity":"0.671"},{"price":"1734.68","quantity":"5.041"},{"price":"1734.73","quantity":"96.584"},{"price":"1734.77","quantity":"84.150"},{"price":"1734.78","quantity":"0.444"},{"price":"1734.79","quantity":"7.220"},{"price":"1734.81","quantity":"18.272"},{"price":"1734.82","quantity":"21.691"},{"price":"1734.86","quantity":"38.775"},{"price":"1734.87","quantity":"18.138"},{"price":"1734.88","quantity":"21.916"},{"price":"1734.92","quantity":"59.799"},{"price":"1734.93","quantity":"68.243"},{"price":"1734.94","quantity":"37.522"},{"price":"1734.95","quantity":"8.702"},{"price":"1734.96","quantity":"1.785"},{"price":"1734.97","quantity":"37.413"},{"price":"1734.98","quantity":"70.078"},{"price":"1734.99","quantity":"0.122"},{"price":"1735.00","quantity":"217.826"},{"price":"1735.01","quantity":"19.298"},{"price":"1735.02","quantity":"54.082"},{"price":"1735.07","quantity":"5.335"},{"price":"1735.08","quantity":"9.845"},{"price":"1735.10","quantity":"15.729"},{"price":"1735.11","quantity":"37.053"},{"price":"1735.12","quantity":"131.338"},{"price":"1735.13","quantity":"1.578"},{"price":"1735.14","quantity":"8.718"},{"price":"1735.15","quantity":"5.778"},{"price":"1735.16","quantity":"7.249"},{"price":"1735.17","quantity":"1.762"},{"price":"1735.19","quantity":"2.051"},{"price":"1735.20","quantity":"58.969"},{"price":"1735.21","quantity":"35.503"},{"price":"1735.22","quantity":"16.287"},{"price":"1735.23","quantity":"6.523"},{"price":"1735.24","quantity":"8.346"},{"price":"1735.26","quantity":"1.009"},{"price":"1735.27","quantity":"68.082"},{"price":"1735.28","quantity":"4.565"},{"price":"1735.29","quantity":"31.046"},{"price":"1735.32","quantity":"246.842"},{"price":"1735.33","quantity":"16.517"},{"price":"1735.34","quantity":"0.868"},{"price":"1735.35","quantity":"19.171"},{"price":"1735.36","quantity":"3.774"},{"price":"1735.37","quantity":"3.304"},{"price":"1735.38","quantity":"65.064"},{"price":"1735.39","quantity":"1.417"},{"price":"1735.40","quantity":"3.818"},{"price":"1735.41","quantity":"124.157"},{"price":"1735.42","quantity":"22.341"},{"price":"1735.43","quantity":"0.467"},{"price":"1735.44","quantity":"40.080"},{"price":"1735.45","quantity":"29.571"},{"price":"1735.46","quantity":"19.596"},{"price":"1735.47","quantity":"15.984"},{"price":"1735.48","quantity":"39.793"},{"price":"1735.49","quantity":"5.317"},{"price":"1735.50","quantity":"18.742"},{"price":"1735.51","quantity":"51.652"},{"price":"1735.52","quantity":"94.278"},{"price":"1735.53","quantity":"12.021"},{"price":"1735.54","quantity":"6.546"},{"price":"1735.58","quantity":"3.947"},{"price":"1735.59","quantity":"3.278"},{"price":"1735.60","quantity":"0.097"},{"price":"1735.62","quantity":"13.454"},{"price":"1735.64","quantity":"72.137"},{"price":"1735.65","quantity":"0.103"},{"price":"1735.66","quantity":"0.199"},{"price":"1735.67","quantity":"0.306"},{"price":"1735.68","quantity":"15.140"},{"price":"1735.69","quantity":"0.264"},{"price":"1735.70","quantity":"5.786"},{"price":"1735.71","quantity":"4.572"},{"price":"1735.73","quantity":"21.720"},{"price":"1735.74","quantity":"3.307"},{"price":"1735.75","quantity":"75.180"},{"price":"1735.76","quantity":"7.442"},{"price":"1735.77","quantity":"9.596"},{"price":"1735.78","quantity":"1.728"},{"price":"1735.79","quantity":"7.543"},{"price":"1735.80","quantity":"8.512"},{"price":"1735.81","quantity":"5.346"},{"price":"1735.82","quantity":"1.034"},{"price":"1735.83","quantity":"21.905"},{"price":"1735.84","quantity":"5.973"},{"price":"1735.85","quantity":"25.208"},{"price":"1735.86","quantity":"69.090"},{"price":"1735.87","quantity":"5.872"},{"price":"1735.88","quantity":"2.624"},{"price":"1735.89","quantity":"9.703"},{"price":"1735.90","quantity":"30.880"},{"price":"1735.92","quantity":"31.099"},{"price":"1735.93","quantity":"6.310"},{"price":"1735.94","quantity":"17.826"},{"price":"1735.99","quantity":"0.658"},{"price":"1736.02","quantity":"0.199"},{"price":"1736.03","quantity":"1.810"},{"price":"1736.04","quantity":"1.208"},{"price":"1736.05","quantity":"2.842"},{"price":"1736.06","quantity":"0.026"},{"price":"1736.07","quantity":"0.047"},{"price":"1736.08","quantity":"0.742"},{"price":"1736.09","quantity":"2.037"},{"price":"1736.10","quantity":"4.041"},{"price":"1736.11","quantity":"107.449"},{"price":"1736.12","quantity":"10.065"},{"price":"1736.13","quantity":"67.274"},{"price":"1736.14","quantity":"35.809"},{"price":"1736.15","quantity":"3.732"},{"price":"1736.16","quantity":"0.664"},{"price":"1736.17","quantity":"0.026"},{"price":"1736.18","quantity":"0.012"},{"price":"1736.19","quantity":"0.014"},{"price":"1736.20","quantity":"0.012"},{"price":"1736.21","quantity":"0.040"},{"price":"1736.22","quantity":"22.193"},{"price":"1736.23","quantity":"8.652"},{"price":"1736.24","quantity":"0.038"},{"price":"1736.25","quantity":"0.038"},{"price":"1736.26","quantity":"0.026"},{"price":"1736.27","quantity":"4.917"},{"price":"1736.28","quantity":"119.200"}],"asks":[{"price":"1736.12","quantity":"0.000"},{"price":"1736.13","quantity":"0.000"},{"price":"1736.14","quantity":"0.000"},{"price":"1736.15","quantity":"0.000"},{"price":"1736.16","quantity":"0.000"},{"price":"1736.17","quantity":"0.000"},{"price":"1736.18","quantity":"0.000"},{"price":"1736.19","quantity":"0.000"},{"price":"1736.20","quantity":"0.000"},{"price":"1736.21","quantity":"0.000"},{"price":"1736.22","quantity":"0.000"},{"price":"1736.23","quantity":"0.000"},{"price":"1736.24","quantity":"0.000"},{"price":"1736.25","quantity":"0.000"},{"price":"1736.26","quantity":"0.000"},{"price":"1736.27","quantity":"0.000"},{"price":"1736.28","quantity":"0.000"},{"price":"1736.29","quantity":"134.000"},{"price":"1736.30","quantity":"7.347"},{"price":"1736.31","quantity":"17.360"},{"price":"1736.32","quantity":"0.143"},{"price":"1736.33","quantity":"0.026"},{"price":"1736.34","quantity":"0.041"},{"price":"1736.35","quantity":"2.773"},{"price":"1736.36","quantity":"0.038"},{"price":"1736.37","quantity":"4.044"},{"price":"1736.38","quantity":"0.067"},{"price":"1736.39","quantity":"1.479"},{"price":"1736.40","quantity":"2.833"},{"price":"1736.41","quantity":"22.210"},{"price":"1736.42","quantity":"0.056"},{"price":"1736.43","quantity":"14.207"},{"price":"1736.44","quantity":"1.596"},{"price":"1736.46","quantity":"34.851"},{"price":"1736.47","quantity":"13.941"},{"price":"1736.48","quantity":"6.581"},{"price":"1736.49","quantity":"6.306"},{"price":"1736.50","quantity":"4.519"},{"price":"1736.52","quantity":"1.528"},{"price":"1736.53","quantity":"1.553"},{"price":"1736.54","quantity":"1.756"},{"price":"1736.55","quantity":"38.186"},{"price":"1736.56","quantity":"9.094"},{"price":"1736.57","quantity":"1.306"},{"price":"1736.58","quantity":"78.890"},{"price":"1736.59","quantity":"4.657"},{"price":"1736.60","quantity":"4.969"},{"price":"1736.61","quantity":"11.067"},{"price":"1736.62","quantity":"4.689"},{"price":"1736.63","quantity":"46.415"},{"price":"1736.64","quantity":"10.277"},{"price":"1736.65","quantity":"26.604"},{"price":"1736.66","quantity":"0.026"},{"price":"1736.67","quantity":"0.062"},{"price":"1736.68","quantity":"4.631"},{"price":"1736.70","quantity":"17.278"},{"price":"1736.71","quantity":"68.801"},{"price":"1736.72","quantity":"10.216"},{"price":"1736.73","quantity":"2.157"},{"price":"1736.74","quantity":"11.831"},{"price":"1736.75","quantity":"6.292"},{"price":"1736.76","quantity":"20.522"},{"price":"1736.77","quantity":"0.087"},{"price":"1736.79","quantity":"1.796"},{"price":"1736.80","quantity":"16.764"},{"price":"1736.81","quantity":"24.476"},{"price":"1736.83","quantity":"37.509"},{"price":"1736.85","quantity":"67.690"},{"price":"1736.86","quantity":"1.522"},{"price":"1736.87","quantity":"24.633"},{"price":"1736.88","quantity":"3.282"},{"price":"1736.89","quantity":"20.327"},{"price":"1736.90","quantity":"30.294"},{"price":"1736.91","quantity":"30.688"},{"price":"1736.92","quantity":"0.531"},{"price":"1736.94","quantity":"19.174"},{"price":"1736.95","quantity":"0.063"},{"price":"1736.97","quantity":"2.068"},{"price":"1736.98","quantity":"46.139"},{"price":"1736.99","quantity":"89.619"},{"price":"1737.00","quantity":"69.758"},{"price":"1737.02","quantity":"16.562"},{"price":"1737.03","quantity":"16.355"},{"price":"1737.04","quantity":"29.777"},{"price":"1737.05","quantity":"0.027"},{"price":"1737.07","quantity":"1.901"},{"price":"1737.09","quantity":"35.620"},{"price":"1737.11","quantity":"27.126"},{"price":"1737.13","quantity":"13.123"},{"price":"1737.14","quantity":"99.406"},{"price":"1737.15","quantity":"9.658"},{"price":"1737.16","quantity":"14.723"},{"price":"1737.17","quantity":"5.797"},{"price":"1737.19","quantity":"1.260"},{"price":"1737.20","quantity":"26.327"},{"price":"1737.22","quantity":"1.641"},{"price":"1737.23","quantity":"32.967"},{"price":"1737.25","quantity":"71.686"},{"price":"1737.27","quantity":"17.998"},{"price":"1737.29","quantity":"1.832"},{"price":"1737.30","quantity":"0.447"},{"price":"1737.31","quantity":"12.427"},{"price":"1737.32","quantity":"1.295"},{"price":"1737.33","quantity":"20.043"},{"price":"1737.34","quantity":"32.558"},{"price":"1737.35","quantity":"3.529"},{"price":"1737.36","quantity":"70.087"},{"price":"1737.38","quantity":"90.111"},{"price":"1737.39","quantity":"0.256"},{"price":"1737.46","quantity":"8.656"},{"price":"1737.47","quantity":"5.423"},{"price":"1737.50","quantity":"138.561"},{"price":"1737.51","quantity":"2.858"},{"price":"1737.55","quantity":"37.251"},{"price":"1737.56","quantity":"87.779"},{"price":"1737.59","quantity":"28.831"},{"price":"1737.60","quantity":"4.605"},{"price":"1737.63","quantity":"0.093"},{"price":"1737.67","quantity":"71.197"},{"price":"1737.68","quantity":"3.403"},{"price":"1737.74","quantity":"72.305"},{"price":"1737.84","quantity":"5.894"},{"price":"1737.85","quantity":"92.450"},{"price":"1737.86","quantity":"0.621"},{"price":"1737.93","quantity":"49.310"},{"price":"1737.94","quantity":"1.679"},{"price":"1738.00","quantity":"30.944"},{"price":"1738.03","quantity":"2.848"},{"price":"1738.06","quantity":"13.209"},{"price":"1738.11","quantity":"1.706"},{"price":"1738.20","quantity":"0.256"},{"price":"1738.25","quantity":"2.878"},{"price":"1738.29","quantity":"8.642"},{"price":"1738.39","quantity":"16.540"},{"price":"1738.41","quantity":"4.081"},{"price":"1738.50","quantity":"405.748"},{"price":"1738.55","quantity":"0.389"},{"price":"1738.56","quantity":"1.996"},{"price":"1738.58","quantity":"84.225"},{"price":"1738.61","quantity":"0.048"},{"price":"1738.62","quantity":"13.207"},{"price":"1738.68","quantity":"0.120"},{"price":"1738.78","quantity":"4.109"},{"price":"1738.81","quantity":"12.249"},{"price":"1738.85","quantity":"7.117"},{"price":"1738.87","quantity":"4.417"},{"price":"1738.88","quantity":"13.486"},{"price":"1738.89","quantity":"56.491"},{"price":"1738.90","quantity":"167.629"},{"price":"1738.92","quantity":"36.308"},{"price":"1738.94","quantity":"3.902"},{"price":"1738.96","quantity":"3.196"},{"price":"1738.97","quantity":"185.174"},{"price":"1739.00","quantity":"2.835"},{"price":"1739.01","quantity":"61.455"},{"price":"1739.04","quantity":"13.910"},{"price":"1739.09","quantity":"0.871"},{"price":"1739.20","quantity":"8.642"},{"price":"1739.27","quantity":"6.972"},{"price":"1739.28","quantity":"10.488"},{"price":"1739.30","quantity":"3.959"},{"price":"1739.37","quantity":"0.463"},{"price":"1739.38","quantity":"27.079"},{"price":"1739.39","quantity":"71.566"},{"price":"1739.41","quantity":"21.378"},{"price":"1739.56","quantity":"68.645"},{"price":"1739.61","quantity":"20.938"},{"price":"1739.70","quantity":"9.432"},{"price":"1739.76","quantity":"5.050"},{"price":"1739.79","quantity":"0.426"},{"price":"1740.06","quantity":"41.211"},{"price":"1740.14","quantity":"172.783"},{"price":"1740.16","quantity":"2.509"},{"price":"1740.17","quantity":"30.133"},{"price":"1740.19","quantity":"0.140"},{"price":"1740.23","quantity":"3.840"},{"price":"1740.37","quantity":"41.346"},{"price":"1740.58","quantity":"0.782"},{"price":"1740.59","quantity":"331.925"},{"price":"1740.61","quantity":"12.179"},{"price":"1740.69","quantity":"189.824"},{"price":"1740.75","quantity":"0.062"},{"price":"1740.86","quantity":"4.320"},{"price":"1741.12","quantity":"2.044"},{"price":"1741.75","quantity":"2.539"},{"price":"1742.19","quantity":"3.085"},{"price":"1742.48","quantity":"24.615"},{"price":"1743.51","quantity":"39.929"},{"price":"1747.05","quantity":"6.442"},{"price":"1747.09","quantity":"5.743"},{"price":"1747.10","quantity":"37.216"},{"price":"1747.11","quantity":"0.020"},{"price":"1747.86","quantity":"0.000"},{"price":"1748.41","quantity":"42.905"},{"price":"1748.42","quantity":"0.040"},{"price":"1748.90","quantity":"1.545"},{"price":"1749.44","quantity":"0.000"},{"price":"1750.02","quantity":"0.137"},{"price":"1750.18","quantity":"0.298"},{"price":"1751.26","quantity":"0.058"},{"price":"1757.11","quantity":"11.366"},{"price":"1757.99","quantity":"16.964"},{"price":"1765.63","quantity":"151.813"},{"price":"1777.94","quantity":"0.290"},{"price":"1777.96","quantity":"25.138"},{"price":"1778.83","quantity":"94.810"},{"price":"1800.57","quantity":"0.136"},{"price":"2633.92","quantity":"0.001"},{"price":"2634.01","quantity":"0.020"}],"raw":{"e":"depthUpdate","E":1783517073722,"T":1783517073721,"s":"ETHUSDT","ps":"ETHUSDT","U":10999771191648,"u":10999771207863,"pu":10999771191265,"b":[["200.00","7.594"],["1211.11","6.949"],["1211.28","0.256"],["1216.11","1.696"],["1231.11","0.288"],["1231.28","0.448"],["1236.11","0.315"],["1562.04","0.056"],["1562.20","1.935"],["1562.49","0.000"],["1562.50","1.331"],["1562.65","0.145"],["1562.66","0.692"],["1616.79","0.014"],["1666.80","0.348"],["1684.12","0.000"],["1701.56","0.117"],["1718.65","151.240"],["1719.02","3.285"],["1720.77","5.818"],["1725.35","0.221"],["1726.15","1.047"],["1727.44","0.000"],["1727.81","0.116"],["1728.81","0.014"],["1728.94","0.315"],["1729.50","1.052"],["1729.72","0.025"],["1730.01","7.605"],["1730.17","0.528"],["1730.23","23.828"],["1730.45","5.113"],["1730.46","19.431"],["1730.72","0.902"],["1730.94","16.624"],["1731.24","223.992"],["1731.27","0.014"],["1731.28","11.844"],["1731.33","19.254"],["1731.87","21.063"],["1731.96","79.901"],["1731.98","171.132"],["1732.08","0.026"],["1732.22","194.819"],["1732.30","0.076"],["1732.32","102.044"],["1732.39","1.766"],["1732.41","0.192"],["1732.59","27.756"],["1732.69","172.900"],["1732.75","183.118"],["1732.76","164.898"],["1732.77","76.290"],["1732.81","7.366"],["1733.07","21.850"],["1733.40","57.957"],["1733.41","4.583"],["1733.50","13.855"],["1733.53","0.617"],["1733.65","9.919"],["1733.70","16.325"],["1733.71","84.523"],["1733.74","15.812"],["1733.77","17.192"],["1733.82","3.163"],["1733.88","474.412"],["1733.89","2.211"],["1734.01","17.699"],["1734.04","124.770"],["1734.05","116.540"],["1734.06","16.697"],["1734.13","3.167"],["1734.18","0.012"],["1734.20","88.456"],["1734.21","18.126"],["1734.31","17.916"],["1734.38","10.789"],["1734.50","13.417"],["1734.51","13.317"],["1734.54","20.679"],["1734.56","3.962"],["1734.63","19.764"],["1734.64","0.671"],["1734.68","5.041"],["1734.73","96.584"],["1734.77","84.150"],["1734.78","0.444"],["1734.79","7.220"],["1734.81","18.272"],["1734.82","21.691"],["1734.86","38.775"],["1734.87","18.138"],["1734.88","21.916"],["1734.92","59.799"],["1734.93","68.243"],["1734.94","37.522"],["1734.95","8.702"],["1734.96","1.785"],["1734.97","37.413"],["1734.98","70.078"],["1734.99","0.122"],["1735.00","217.826"],["1735.01","19.298"],["1735.02","54.082"],["1735.07","5.335"],["1735.08","9.845"],["1735.10","15.729"],["1735.11","37.053"],["1735.12","131.338"],["1735.13","1.578"],["1735.14","8.718"],["1735.15","5.778"],["1735.16","7.249"],["1735.17","1.762"],["1735.19","2.051"],["1735.20","58.969"],["1735.21","35.503"],["1735.22","16.287"],["1735.23","6.523"],["1735.24","8.346"],["1735.26","1.009"],["1735.27","68.082"],["1735.28","4.565"],["1735.29","31.046"],["1735.32","246.842"],["1735.33","16.517"],["1735.34","0.868"],["1735.35","19.171"],["1735.36","3.774"],["1735.37","3.304"],["1735.38","65.064"],["1735.39","1.417"],["1735.40","3.818"],["1735.41","124.157"],["1735.42","22.341"],["1735.43","0.467"],["1735.44","40.080"],["1735.45","29.571"],["1735.46","19.596"],["1735.47","15.984"],["1735.48","39.793"],["1735.49","5.317"],["1735.50","18.742"],["1735.51","51.652"],["1735.52","94.278"],["1735.53","12.021"],["1735.54","6.546"],["1735.58","3.947"],["1735.59","3.278"],["1735.60","0.097"],["1735.62","13.454"],["1735.64","72.137"],["1735.65","0.103"],["1735.66","0.199"],["1735.67","0.306"],["1735.68","15.140"],["1735.69","0.264"],["1735.70","5.786"],["1735.71","4.572"],["1735.73","21.720"],["1735.74","3.307"],["1735.75","75.180"],["1735.76","7.442"],["1735.77","9.596"],["1735.78","1.728"],["1735.79","7.543"],["1735.80","8.512"],["1735.81","5.346"],["1735.82","1.034"],["1735.83","21.905"],["1735.84","5.973"],["1735.85","25.208"],["1735.86","69.090"],["1735.87","5.872"],["1735.88","2.624"],["1735.89","9.703"],["1735.90","30.880"],["1735.92","31.099"],["1735.93","6.310"],["1735.94","17.826"],["1735.99","0.658"],["1736.02","0.199"],["1736.03","1.810"],["1736.04","1.208"],["1736.05","2.842"],["1736.06","0.026"],["1736.07","0.047"],["1736.08","0.742"],["1736.09","2.037"],["1736.10","4.041"],["1736.11","107.449"],["1736.12","10.065"],["1736.13","67.274"],["1736.14","35.809"],["1736.15","3.732"],["1736.16","0.664"],["1736.17","0.026"],["1736.18","0.012"],["1736.19","0.014"],["1736.20","0.012"],["1736.21","0.040"],["1736.22","22.193"],["1736.23","8.652"],["1736.24","0.038"],["1736.25","0.038"],["1736.26","0.026"],["1736.27","4.917"],["1736.28","119.200"]],"a":[["1736.12","0.000"],["1736.13","0.000"],["1736.14","0.000"],["1736.15","0.000"],["1736.16","0.000"],["1736.17","0.000"],["1736.18","0.000"],["1736.19","0.000"],["1736.20","0.000"],["1736.21","0.000"],["1736.22","0.000"],["1736.23","0.000"],["1736.24","0.000"],["1736.25","0.000"],["1736.26","0.000"],["1736.27","0.000"],["1736.28","0.000"],["1736.29","134.000"],["1736.30","7.347"],["1736.31","17.360"],["1736.32","0.143"],["1736.33","0.026"],["1736.34","0.041"],["1736.35","2.773"],["1736.36","0.038"],["1736.37","4.044"],["1736.38","0.067"],["1736.39","1.479"],["1736.40","2.833"],["1736.41","22.210"],["1736.42","0.056"],["1736.43","14.207"],["1736.44","1.596"],["1736.46","34.851"],["1736.47","13.941"],["1736.48","6.581"],["1736.49","6.306"],["1736.50","4.519"],["1736.52","1.528"],["1736.53","1.553"],["1736.54","1.756"],["1736.55","38.186"],["1736.56","9.094"],["1736.57","1.306"],["1736.58","78.890"],["1736.59","4.657"],["1736.60","4.969"],["1736.61","11.067"],["1736.62","4.689"],["1736.63","46.415"],["1736.64","10.277"],["1736.65","26.604"],["1736.66","0.026"],["1736.67","0.062"],["1736.68","4.631"],["1736.70","17.278"],["1736.71","68.801"],["1736.72","10.216"],["1736.73","2.157"],["1736.74","11.831"],["1736.75","6.292"],["1736.76","20.522"],["1736.77","0.087"],["1736.79","1.796"],["1736.80","16.764"],["1736.81","24.476"],["1736.83","37.509"],["1736.85","67.690"],["1736.86","1.522"],["1736.87","24.633"],["1736.88","3.282"],["1736.89","20.327"],["1736.90","30.294"],["1736.91","30.688"],["1736.92","0.531"],["1736.94","19.174"],["1736.95","0.063"],["1736.97","2.068"],["1736.98","46.139"],["1736.99","89.619"],["1737.00","69.758"],["1737.02","16.562"],["1737.03","16.355"],["1737.04","29.777"],["1737.05","0.027"],["1737.07","1.901"],["1737.09","35.620"],["1737.11","27.126"],["1737.13","13.123"],["1737.14","99.406"],["1737.15","9.658"],["1737.16","14.723"],["1737.17","5.797"],["1737.19","1.260"],["1737.20","26.327"],["1737.22","1.641"],["1737.23","32.967"],["1737.25","71.686"],["1737.27","17.998"],["1737.29","1.832"],["1737.30","0.447"],["1737.31","12.427"],["1737.32","1.295"],["1737.33","20.043"],["1737.34","32.558"],["1737.35","3.529"],["1737.36","70.087"],["1737.38","90.111"],["1737.39","0.256"],["1737.46","8.656"],["1737.47","5.423"],["1737.50","138.561"],["1737.51","2.858"],["1737.55","37.251"],["1737.56","87.779"],["1737.59","28.831"],["1737.60","4.605"],["1737.63","0.093"],["1737.67","71.197"],["1737.68","3.403"],["1737.74","72.305"],["1737.84","5.894"],["1737.85","92.450"],["1737.86","0.621"],["1737.93","49.310"],["1737.94","1.679"],["1738.00","30.944"],["1738.03","2.848"],["1738.06","13.209"],["1738.11","1.706"],["1738.20","0.256"],["1738.25","2.878"],["1738.29","8.642"],["1738.39","16.540"],["1738.41","4.081"],["1738.50","405.748"],["1738.55","0.389"],["1738.56","1.996"],["1738.58","84.225"],["1738.61","0.048"],["1738.62","13.207"],["1738.68","0.120"],["1738.78","4.109"],["1738.81","12.249"],["1738.85","7.117"],["1738.87","4.417"],["1738.88","13.486"],["1738.89","56.491"],["1738.90","167.629"],["1738.92","36.308"],["1738.94","3.902"],["1738.96","3.196"],["1738.97","185.174"],["1739.00","2.835"],["1739.01","61.455"],["1739.04","13.910"],["1739.09","0.871"],["1739.20","8.642"],["1739.27","6.972"],["1739.28","10.488"],["1739.30","3.959"],["1739.37","0.463"],["1739.38","27.079"],["1739.39","71.566"],["1739.41","21.378"],["1739.56","68.645"],["1739.61","20.938"],["1739.70","9.432"],["1739.76","5.050"],["1739.79","0.426"],["1740.06","41.211"],["1740.14","172.783"],["1740.16","2.509"],["1740.17","30.133"],["1740.19","0.140"],["1740.23","3.840"],["1740.37","41.346"],["1740.58","0.782"],["1740.59","331.925"],["1740.61","12.179"],["1740.69","189.824"],["1740.75","0.062"],["1740.86","4.320"],["1741.12","2.044"],["1741.75","2.539"],["1742.19","3.085"],["1742.48","24.615"],["1743.51","39.929"],["1747.05","6.442"],["1747.09","5.743"],["1747.10","37.216"],["1747.11","0.020"],["1747.86","0.000"],["1748.41","42.905"],["1748.42","0.040"],["1748.90","1.545"],["1749.44","0.000"],["1750.02","0.137"],["1750.18","0.298"],["1751.26","0.058"],["1757.11","11.366"],["1757.99","16.964"],["1765.63","151.813"],["1777.94","0.290"],["1777.96","25.138"],["1778.83","94.810"],["1800.57","0.136"],["2633.92","0.001"],["2634.01","0.020"]],"st":1}}
{"schema_version":"1.3.0","event_id":"8efd8e0c-14d3-485b-99fc-fb2a8531aa51","event_type":"raw.depth_update","source":"binance_market_data_recorder","venue":"binance_usdm","market_type":"perpetual_futures","symbol":"ETHUSDT","event_time_ms":1783517073824,"received_time_ms":1783517073876,"trace_id":"7ba87e91-a036-4943-88db-ad7da0fd3c51","first_update_id":10999771208095,"final_update_id":10999771225088,"previous_final_update_id":10999771207863,"bids":[{"price":"200.00","quantity":"7.594"},{"price":"1211.11","quantity":"6.437"},{"price":"1211.28","quantity":"0.544"},{"price":"1216.11","quantity":"1.408"},{"price":"1231.28","quantity":"0.960"},{"price":"1562.50","quantity":"1.316"},{"price":"1562.65","quantity":"0.145"},{"price":"1562.66","quantity":"1.204"},{"price":"1666.80","quantity":"0.233"},{"price":"1668.33","quantity":"0.000"},{"price":"1693.07","quantity":"79.632"},{"price":"1701.56","quantity":"0.088"},{"price":"1729.11","quantity":"32.814"},{"price":"1729.29","quantity":"1.669"},{"price":"1730.01","quantity":"0.100"},{"price":"1730.23","quantity":"16.323"},{"price":"1730.44","quantity":"11.827"},{"price":"1732.24","quantity":"17.518"},{"price":"1733.71","quantity":"514.219"},{"price":"1733.84","quantity":"15.295"},{"price":"1733.88","quantity":"44.716"},{"price":"1733.89","quantity":"0.765"},{"price":"1734.01","quantity":"19.145"},{"price":"1734.12","quantity":"55.897"},{"price":"1734.15","quantity":"0.082"},{"price":"1734.16","quantity":"2.012"},{"price":"1734.18","quantity":"0.012"},{"price":"1734.37","quantity":"10.113"},{"price":"1734.94","quantity":"12.522"},{"price":"1734.97","quantity":"37.413"},{"price":"1734.98","quantity":"70.065"},{"price":"1735.02","quantity":"54.476"},{"price":"1735.12","quantity":"131.338"},{"price":"1735.14","quantity":"8.718"},{"price":"1735.17","quantity":"2.452"},{"price":"1735.19","quantity":"1.361"},{"price":"1735.21","quantity":"35.503"},{"price":"1735.23","quantity":"6.505"},{"price":"1735.24","quantity":"8.066"},{"price":"1735.25","quantity":"3.048"},{"price":"1735.27","quantity":"287.718"},{"price":"1735.29","quantity":"31.034"},{"price":"1735.31","quantity":"33.978"},{"price":"1735.32","quantity":"27.764"},{"price":"1735.33","quantity":"16.517"},{"price":"1735.34","quantity":"1.108"},{"price":"1735.35","quantity":"87.691"},{"price":"1735.36","quantity":"3.762"},{"price":"1735.37","quantity":"0.497"},{"price":"1735.38","quantity":"48.687"},{"price":"1735.39","quantity":"0.571"},{"price":"1735.40","quantity":"4.682"},{"price":"1735.43","quantity":"0.467"},{"price":"1735.46","quantity":"19.596"},{"price":"1735.52","quantity":"94.278"},{"price":"1735.53","quantity":"10.293"},{"price":"1735.54","quantity":"4.346"},{"price":"1735.55","quantity":"6.804"},{"price":"1735.56","quantity":"28.634"},{"price":"1735.57","quantity":"1.802"},{"price":"1735.58","quantity":"5.675"},{"price":"1735.59","quantity":"3.278"},{"price":"1735.60","quantity":"0.357"},{"price":"1735.62","quantity":"10.454"},{"price":"1735.68","quantity":"18.140"},{"price":"1735.69","quantity":"0.064"},{"price":"1735.70","quantity":"0.025"},{"price":"1735.76","quantity":"7.455"},{"price":"1735.77","quantity":"9.523"},{"price":"1735.87","quantity":"6.072"},{"price":"1735.90","quantity":"2.049"},{"price":"1735.91","quantity":"19.057"},{"price":"1735.95","quantity":"29.504"},{"price":"1735.98","quantity":"69.084"},{"price":"1736.02","quantity":"0.106"},{"price":"1736.03","quantity":"1.810"},{"price":"1736.04","quantity":"5.758"},{"price":"1736.08","quantity":"0.835"},{"price":"1736.09","quantity":"2.156"},{"price":"1736.10","quantity":"5.941"},{"price":"1736.11","quantity":"106.716"},{"price":"1736.12","quantity":"10.353"},{"price":"1736.14","quantity":"35.809"},{"price":"1736.15","quantity":"10.789"},{"price":"1736.16","quantity":"0.688"},{"price":"1736.17","quantity":"0.038"},{"price":"1736.18","quantity":"4.683"},{"price":"1736.19","quantity":"0.026"},{"price":"1736.20","quantity":"0.012"},{"price":"1736.21","quantity":"0.329"},{"price":"1736.22","quantity":"0.024"},{"price":"1736.24","quantity":"22.219"},{"price":"1736.27","quantity":"1.351"},{"price":"1736.28","quantity":"117.806"}],"asks":[{"price":"1736.29","quantity":"92.144"},{"price":"1736.30","quantity":"4.558"},{"price":"1736.31","quantity":"17.360"},{"price":"1736.32","quantity":"0.064"},{"price":"1736.33","quantity":"19.611"},{"price":"1736.39","quantity":"0.038"},{"price":"1736.40","quantity":"4.274"},{"price":"1736.41","quantity":"22.210"},{"price":"1736.43","quantity":"0.319"},{"price":"1736.44","quantity":"1.196"},{"price":"1736.45","quantity":"0.054"},{"price":"1736.46","quantity":"24.632"},{"price":"1736.47","quantity":"0.232"},{"price":"1736.48","quantity":"1.761"},{"price":"1736.49","quantity":"1.778"},{"price":"1736.50","quantity":"0.092"},{"price":"1736.51","quantity":"5.145"},{"price":"1736.52","quantity":"1.792"},{"price":"1736.53","quantity":"2.065"},{"price":"1736.54","quantity":"23.953"},{"price":"1736.55","quantity":"36.611"},{"price":"1736.56","quantity":"78.151"},{"price":"1736.57","quantity":"3.286"},{"price":"1736.58","quantity":"11.642"},{"price":"1736.60","quantity":"7.839"},{"price":"1736.61","quantity":"11.067"},{"price":"1736.62","quantity":"4.601"},{"price":"1736.63","quantity":"14.702"},{"price":"1736.64","quantity":"17.472"},{"price":"1736.66","quantity":"0.108"},{"price":"1736.67","quantity":"28.968"},{"price":"1736.70","quantity":"13.193"},{"price":"1736.72","quantity":"10.202"},{"price":"1736.73","quantity":"2.357"},{"price":"1736.75","quantity":"5.842"},{"price":"1736.79","quantity":"1.810"},{"price":"1736.80","quantity":"16.829"},{"price":"1736.82","quantity":"26.539"},{"price":"1736.84","quantity":"9.275"},{"price":"1736.86","quantity":"3.250"},{"price":"1736.88","quantity":"3.282"},{"price":"1736.89","quantity":"4.503"},{"price":"1736.91","quantity":"32.692"},{"price":"1736.92","quantity":"48.129"},{"price":"1736.93","quantity":"16.398"},{"price":"1736.94","quantity":"19.186"},{"price":"1736.95","quantity":"0.075"},{"price":"1736.96","quantity":"3.511"},{"price":"1736.97","quantity":"4.374"},{"price":"1736.98","quantity":"7.240"},{"price":"1736.99","quantity":"89.762"},{"price":"1737.01","quantity":"86.525"},{"price":"1737.06","quantity":"21.378"},{"price":"1737.07","quantity":"0.891"},{"price":"1737.09","quantity":"35.477"},{"price":"1737.11","quantity":"26.356"},{"price":"1737.12","quantity":"1.611"},{"price":"1737.18","quantity":"41.607"},{"price":"1737.19","quantity":"0.570"},{"price":"1737.22","quantity":"2.411"},{"price":"1737.29","quantity":"1.847"},{"price":"1737.31","quantity":"13.117"},{"price":"1737.34","quantity":"30.891"},{"price":"1737.35","quantity":"0.074"},{"price":"1737.36","quantity":"73.542"},{"price":"1737.38","quantity":"87.923"},{"price":"1737.39","quantity":"2.456"},{"price":"1737.42","quantity":"5.995"},{"price":"1737.51","quantity":"2.858"},{"price":"1737.54","quantity":"2.812"},{"price":"1737.56","quantity":"87.779"},{"price":"1737.59","quantity":"28.831"},{"price":"1737.74","quantity":"71.305"},{"price":"1737.77","quantity":"0.758"},{"price":"1737.78","quantity":"2.355"},{"price":"1737.80","quantity":"3.564"},{"price":"1737.81","quantity":"31.348"},{"price":"1737.82","quantity":"48.778"},{"price":"1737.93","quantity":"49.334"},{"price":"1737.99","quantity":"69.849"},{"price":"1738.01","quantity":"37.396"},{"price":"1738.20","quantity":"1.923"},{"price":"1738.26","quantity":"432.603"},{"price":"1738.29","quantity":"8.642"},{"price":"1738.32","quantity":"1.077"},{"price":"1738.35","quantity":"50.060"},{"price":"1738.50","quantity":"2.278"},{"price":"1738.54","quantity":"19.624"},{"price":"1738.55","quantity":"0.389"},{"price":"1738.98","quantity":"43.748"},{"price":"1739.29","quantity":"0.633"},{"price":"1739.35","quantity":"1.699"},{"price":"1739.38","quantity":"27.079"},{"price":"1739.41","quantity":"13.873"},{"price":"1739.42","quantity":"20.408"},{"price":"1739.63","quantity":"41.189"},{"price":"1739.96","quantity":"26.780"},{"price":"1741.75","quantity":"2.539"},{"price":"1742.47","quantity":"0.012"},{"price":"1747.12","quantity":"15.000"},{"price":"1778.49","quantity":"0.031"},{"price":"1836.33","quantity":"0.015"},{"price":"1869.18","quantity":"0.040"},{"price":"2633.90","quantity":"0.001"},{"price":"2633.91","quantity":"0.001"},{"price":"2633.99","quantity":"0.000"},{"price":"2634.00","quantity":"0.558"}],"raw":{"e":"depthUpdate","E":1783517073824,"T":1783517073823,"s":"ETHUSDT","ps":"ETHUSDT","U":10999771208095,"u":10999771225088,"pu":10999771207863,"b":[["200.00","7.594"],["1211.11","6.437"],["1211.28","0.544"],["1216.11","1.408"],["1231.28","0.960"],["1562.50","1.316"],["1562.65","0.145"],["1562.66","1.204"],["1666.80","0.233"],["1668.33","0.000"],["1693.07","79.632"],["1701.56","0.088"],["1729.11","32.814"],["1729.29","1.669"],["1730.01","0.100"],["1730.23","16.323"],["1730.44","11.827"],["1732.24","17.518"],["1733.71","514.219"],["1733.84","15.295"],["1733.88","44.716"],["1733.89","0.765"],["1734.01","19.145"],["1734.12","55.897"],["1734.15","0.082"],["1734.16","2.012"],["1734.18","0.012"],["1734.37","10.113"],["1734.94","12.522"],["1734.97","37.413"],["1734.98","70.065"],["1735.02","54.476"],["1735.12","131.338"],["1735.14","8.718"],["1735.17","2.452"],["1735.19","1.361"],["1735.21","35.503"],["1735.23","6.505"],["1735.24","8.066"],["1735.25","3.048"],["1735.27","287.718"],["1735.29","31.034"],["1735.31","33.978"],["1735.32","27.764"],["1735.33","16.517"],["1735.34","1.108"],["1735.35","87.691"],["1735.36","3.762"],["1735.37","0.497"],["1735.38","48.687"],["1735.39","0.571"],["1735.40","4.682"],["1735.43","0.467"],["1735.46","19.596"],["1735.52","94.278"],["1735.53","10.293"],["1735.54","4.346"],["1735.55","6.804"],["1735.56","28.634"],["1735.57","1.802"],["1735.58","5.675"],["1735.59","3.278"],["1735.60","0.357"],["1735.62","10.454"],["1735.68","18.140"],["1735.69","0.064"],["1735.70","0.025"],["1735.76","7.455"],["1735.77","9.523"],["1735.87","6.072"],["1735.90","2.049"],["1735.91","19.057"],["1735.95","29.504"],["1735.98","69.084"],["1736.02","0.106"],["1736.03","1.810"],["1736.04","5.758"],["1736.08","0.835"],["1736.09","2.156"],["1736.10","5.941"],["1736.11","106.716"],["1736.12","10.353"],["1736.14","35.809"],["1736.15","10.789"],["1736.16","0.688"],["1736.17","0.038"],["1736.18","4.683"],["1736.19","0.026"],["1736.20","0.012"],["1736.21","0.329"],["1736.22","0.024"],["1736.24","22.219"],["1736.27","1.351"],["1736.28","117.806"]],"a":[["1736.29","92.144"],["1736.30","4.558"],["1736.31","17.360"],["1736.32","0.064"],["1736.33","19.611"],["1736.39","0.038"],["1736.40","4.274"],["1736.41","22.210"],["1736.43","0.319"],["1736.44","1.196"],["1736.45","0.054"],["1736.46","24.632"],["1736.47","0.232"],["1736.48","1.761"],["1736.49","1.778"],["1736.50","0.092"],["1736.51","5.145"],["1736.52","1.792"],["1736.53","2.065"],["1736.54","23.953"],["1736.55","36.611"],["1736.56","78.151"],["1736.57","3.286"],["1736.58","11.642"],["1736.60","7.839"],["1736.61","11.067"],["1736.62","4.601"],["1736.63","14.702"],["1736.64","17.472"],["1736.66","0.108"],["1736.67","28.968"],["1736.70","13.193"],["1736.72","10.202"],["1736.73","2.357"],["1736.75","5.842"],["1736.79","1.810"],["1736.80","16.829"],["1736.82","26.539"],["1736.84","9.275"],["1736.86","3.250"],["1736.88","3.282"],["1736.89","4.503"],["1736.91","32.692"],["1736.92","48.129"],["1736.93","16.398"],["1736.94","19.186"],["1736.95","0.075"],["1736.96","3.511"],["1736.97","4.374"],["1736.98","7.240"],["1736.99","89.762"],["1737.01","86.525"],["1737.06","21.378"],["1737.07","0.891"],["1737.09","35.477"],["1737.11","26.356"],["1737.12","1.611"],["1737.18","41.607"],["1737.19","0.570"],["1737.22","2.411"],["1737.29","1.847"],["1737.31","13.117"],["1737.34","30.891"],["1737.35","0.074"],["1737.36","73.542"],["1737.38","87.923"],["1737.39","2.456"],["1737.42","5.995"],["1737.51","2.858"],["1737.54","2.812"],["1737.56","87.779"],["1737.59","28.831"],["1737.74","71.305"],["1737.77","0.758"],["1737.78","2.355"],["1737.80","3.564"],["1737.81","31.348"],["1737.82","48.778"],["1737.93","49.334"],["1737.99","69.849"],["1738.01","37.396"],["1738.20","1.923"],["1738.26","432.603"],["1738.29","8.642"],["1738.32","1.077"],["1738.35","50.060"],["1738.50","2.278"],["1738.54","19.624"],["1738.55","0.389"],["1738.98","43.748"],["1739.29","0.633"],["1739.35","1.699"],["1739.38","27.079"],["1739.41","13.873"],["1739.42","20.408"],["1739.63","41.189"],["1739.96","26.780"],["1741.75","2.539"],["1742.47","0.012"],["1747.12","15.000"],["1778.49","0.031"],["1836.33","0.015"],["1869.18","0.040"],["2633.90","0.001"],["2633.91","0.001"],["2633.99","0.000"],["2634.00","0.558"]],"st":1}}
{"schema_version":"1.3.0","event_id":"cb075286-bba3-43a5-917d-a9d37242cdf6","event_type":"raw.depth_update","source":"binance_market_data_recorder","venue":"binance_usdm","market_type":"perpetual_futures","symbol":"ETHUSDT","event_time_ms":1783517073926,"received_time_ms":1783517073921,"trace_id":"cb9664c7-3d3d-4730-bc1d-fca2fc563052","first_update_id":10999771225212,"final_update_id":10999771232523,"previous_final_update_id":10999771225088,"bids":[{"price":"1211.11","quantity":"5.861"},{"price":"1211.28","quantity":"0.800"},{"price":"1216.11","quantity":"1.152"},{"price":"1231.28","quantity":"1.536"},{"price":"1562.65","quantity":"0.145"},{"price":"1562.66","quantity":"1.716"},{"price":"1666.80","quantity":"0.348"},{"price":"1693.07","quantity":"53.089"},{"price":"1701.98","quantity":"0.000"},{"price":"1705.75","quantity":"58.547"},{"price":"1711.51","quantity":"0.436"},{"price":"1718.75","quantity":"439.572"},{"price":"1725.54","quantity":"0.013"},{"price":"1725.88","quantity":"0.304"},{"price":"1726.82","quantity":"0.542"},{"price":"1727.18","quantity":"2.698"},{"price":"1727.61","quantity":"0.406"},{"price":"1729.35","quantity":"0.599"},{"price":"1730.44","quantity":"4.322"},{"price":"1731.00","quantity":"76.380"},{"price":"1731.08","quantity":"1.070"},{"price":"1732.78","quantity":"12.149"},{"price":"1732.81","quantity":"7.655"},{"price":"1733.71","quantity":"514.219"},{"price":"1733.83","quantity":"1.162"},{"price":"1734.01","quantity":"19.427"},{"price":"1734.16","quantity":"52.012"},{"price":"1734.18","quantity":"0.012"},{"price":"1734.21","quantity":"78.839"},{"price":"1734.87","quantity":"17.910"},{"price":"1734.94","quantity":"37.522"},{"price":"1735.02","quantity":"50.157"},{"price":"1735.11","quantity":"43.763"},{"price":"1735.24","quantity":"6.853"},{"price":"1735.27","quantity":"68.100"},{"price":"1735.28","quantity":"4.565"},{"price":"1735.32","quantity":"27.764"},{"price":"1735.35","quantity":"87.709"},{"price":"1735.38","quantity":"270.988"},{"price":"1735.39","quantity":"0.553"},{"price":"1735.41","quantity":"124.139"},{"price":"1735.42","quantity":"22.329"},{"price":"1735.51","quantity":"50.672"},{"price":"1735.57","quantity":"0.074"},{"price":"1735.60","quantity":"1.570"},{"price":"1735.61","quantity":"8.709"},{"price":"1735.65","quantity":"16.034"},{"price":"1735.86","quantity":"69.078"},{"price":"1735.93","quantity":"6.322"},{"price":"1735.99","quantity":"1.638"},{"price":"1736.07","quantity":"0.140"},{"price":"1736.08","quantity":"0.742"},{"price":"1736.10","quantity":"5.971"},{"price":"1736.11","quantity":"107.129"},{"price":"1736.12","quantity":"10.327"},{"price":"1736.13","quantity":"67.286"},{"price":"1736.14","quantity":"36.109"},{"price":"1736.15","quantity":"15.120"},{"price":"1736.16","quantity":"0.688"},{"price":"1736.17","quantity":"1.766"},{"price":"1736.19","quantity":"0.026"},{"price":"1736.24","quantity":"0.038"},{"price":"1736.25","quantity":"22.219"},{"price":"1736.27","quantity":"4.535"},{"price":"1736.28","quantity":"117.912"}],"asks":[{"price":"1736.29","quantity":"64.714"},{"price":"1736.30","quantity":"4.558"},{"price":"1736.41","quantity":"22.210"},{"price":"1736.45","quantity":"0.039"},{"price":"1736.46","quantity":"26.725"},{"price":"1736.47","quantity":"0.232"},{"price":"1736.48","quantity":"1.761"},{"price":"1736.52","quantity":"7.824"},{"price":"1736.53","quantity":"2.041"},{"price":"1736.54","quantity":"26.461"},{"price":"1736.55","quantity":"27.385"},{"price":"1736.56","quantity":"13.161"},{"price":"1736.58","quantity":"11.382"},{"price":"1736.60","quantity":"72.187"},{"price":"1736.61","quantity":"39.859"},{"price":"1736.62","quantity":"3.052"},{"price":"1736.64","quantity":"17.472"},{"price":"1736.65","quantity":"26.692"},{"price":"1736.67","quantity":"28.880"},{"price":"1736.70","quantity":"13.193"},{"price":"1736.72","quantity":"10.482"},{"price":"1736.75","quantity":"10.273"},{"price":"1736.79","quantity":"1.796"},{"price":"1736.84","quantity":"9.289"},{"price":"1736.92","quantity":"9.251"},{"price":"1736.93","quantity":"16.658"},{"price":"1736.97","quantity":"4.386"},{"price":"1736.98","quantity":"46.151"},{"price":"1736.99","quantity":"89.774"},{"price":"1737.00","quantity":"97.639"},{"price":"1737.11","quantity":"26.356"},{"price":"1737.15","quantity":"9.646"},{"price":"1737.51","quantity":"0.218"},{"price":"1737.56","quantity":"87.491"},{"price":"1737.78","quantity":"5.075"},{"price":"1737.79","quantity":"3.615"},{"price":"1737.82","quantity":"51.018"},{"price":"1738.02","quantity":"4.347"},{"price":"1738.17","quantity":"71.685"},{"price":"1738.20","quantity":"0.256"},{"price":"1738.48","quantity":"5.098"},{"price":"1738.50","quantity":"2.098"},{"price":"1738.54","quantity":"9.895"},{"price":"1738.98","quantity":"40.552"},{"price":"1739.38","quantity":"19.574"},{"price":"1739.96","quantity":"19.275"},{"price":"1739.97","quantity":"0.057"},{"price":"1739.98","quantity":"1.446"},{"price":"1740.25","quantity":"148.077"},{"price":"1740.58","quantity":"10.511"},{"price":"1742.47","quantity":"7.517"},{"price":"1742.48","quantity":"32.120"},{"price":"1744.99","quantity":"0.331"},{"price":"1745.16","quantity":"1.916"},{"price":"1747.98","quantity":"520.988"},{"price":"1748.12","quantity":"5.857"},{"price":"1748.29","quantity":"417.519"},{"price":"1777.96","quantity":"0.081"},{"price":"1778.28","quantity":"5.161"},{"price":"1778.83","quantity":"119.855"},{"price":"2633.88","quantity":"0.001"},{"price":"2633.89","quantity":"0.001"},{"price":"2633.97","quantity":"50.000"},{"price":"2633.98","quantity":"0.000"}],"raw":{"e":"depthUpdate","E":1783517073926,"T":1783517073925,"s":"ETHUSDT","ps":"ETHUSDT","U":10999771225212,"u":10999771232523,"pu":10999771225088,"b":[["1211.11","5.861"],["1211.28","0.800"],["1216.11","1.152"],["1231.28","1.536"],["1562.65","0.145"],["1562.66","1.716"],["1666.80","0.348"],["1693.07","53.089"],["1701.98","0.000"],["1705.75","58.547"],["1711.51","0.436"],["1718.75","439.572"],["1725.54","0.013"],["1725.88","0.304"],["1726.82","0.542"],["1727.18","2.698"],["1727.61","0.406"],["1729.35","0.599"],["1730.44","4.322"],["1731.00","76.380"],["1731.08","1.070"],["1732.78","12.149"],["1732.81","7.655"],["1733.71","514.219"],["1733.83","1.162"],["1734.01","19.427"],["1734.16","52.012"],["1734.18","0.012"],["1734.21","78.839"],["1734.87","17.910"],["1734.94","37.522"],["1735.02","50.157"],["1735.11","43.763"],["1735.24","6.853"],["1735.27","68.100"],["1735.28","4.565"],["1735.32","27.764"],["1735.35","87.709"],["1735.38","270.988"],["1735.39","0.553"],["1735.41","124.139"],["1735.42","22.329"],["1735.51","50.672"],["1735.57","0.074"],["1735.60","1.570"],["1735.61","8.709"],["1735.65","16.034"],["1735.86","69.078"],["1735.93","6.322"],["1735.99","1.638"],["1736.07","0.140"],["1736.08","0.742"],["1736.10","5.971"],["1736.11","107.129"],["1736.12","10.327"],["1736.13","67.286"],["1736.14","36.109"],["1736.15","15.120"],["1736.16","0.688"],["1736.17","1.766"],["1736.19","0.026"],["1736.24","0.038"],["1736.25","22.219"],["1736.27","4.535"],["1736.28","117.912"]],"a":[["1736.29","64.714"],["1736.30","4.558"],["1736.41","22.210"],["1736.45","0.039"],["1736.46","26.725"],["1736.47","0.232"],["1736.48","1.761"],["1736.52","7.824"],["1736.53","2.041"],["1736.54","26.461"],["1736.55","27.385"],["1736.56","13.161"],["1736.58","11.382"],["1736.60","72.187"],["1736.61","39.859"],["1736.62","3.052"],["1736.64","17.472"],["1736.65","26.692"],["1736.67","28.880"],["1736.70","13.193"],["1736.72","10.482"],["1736.75","10.273"],["1736.79","1.796"],["1736.84","9.289"],["1736.92","9.251"],["1736.93","16.658"],["1736.97","4.386"],["1736.98","46.151"],["1736.99","89.774"],["1737.00","97.639"],["1737.11","26.356"],["1737.15","9.646"],["1737.51","0.218"],["1737.56","87.491"],["1737.78","5.075"],["1737.79","3.615"],["1737.82","51.018"],["1738.02","4.347"],["1738.17","71.685"],["1738.20","0.256"],["1738.48","5.098"],["1738.50","2.098"],["1738.54","9.895"],["1738.98","40.552"],["1739.38","19.574"],["1739.96","19.275"],["1739.97","0.057"],["1739.98","1.446"],["1740.25","148.077"],["1740.58","10.511"],["1742.47","7.517"],["1742.48","32.120"],["1744.99","0.331"],["1745.16","1.916"],["1747.98","520.988"],["1748.12","5.857"],["1748.29","417.519"],["1777.96","0.081"],["1778.28","5.161"],["1778.83","119.855"],["2633.88","0.001"],["2633.89","0.001"],["2633.97","50.000"],["2633.98","0.000"]],"st":1}}
{"schema_version":"1.3.0","event_id":"0a459a9a-4613-4b84-9f52-049f915daa8f","event_type":"raw.depth_update","source":"binance_market_data_recorder","venue":"binance_usdm","market_type":"perpetual_futures","symbol":"ETHUSDT","event_time_ms":1783517074028,"received_time_ms":1783517074024,"trace_id":"8a858d42-c058-4d7f-ab1f-9b7de7b0e97b","first_update_id":10999771232574,"final_update_id":10999771252676,"previous_final_update_id":10999771232523,"bids":[{"price":"200.00","quantity":"7.594"},{"price":"1211.11","quantity":"5.349"},{"price":"1211.28","quantity":"1.088"},{"price":"1216.11","quantity":"0.864"},{"price":"1231.28","quantity":"2.048"},{"price":"1236.11","quantity":"0.295"},{"price":"1562.37","quantity":"0.014"},{"price":"1562.65","quantity":"0.145"},{"price":"1562.66","quantity":"2.370"},{"price":"1666.67","quantity":"31.522"},{"price":"1693.58","quantity":"121.257"},{"price":"1697.92","quantity":"0.122"},{"price":"1701.55","quantity":"15.928"},{"price":"1717.22","quantity":"3.941"},{"price":"1717.29","quantity":"0.000"},{"price":"1718.95","quantity":"0.291"},{"price":"1720.68","quantity":"0.974"},{"price":"1722.42","quantity":"52.555"},{"price":"1724.15","quantity":"0.676"},{"price":"1726.36","quantity":"0.320"},{"price":"1727.18","quantity":"2.712"},{"price":"1730.44","quantity":"4.322"},{"price":"1731.23","quantity":"22.938"},{"price":"1731.24","quantity":"183.992"},{"price":"1731.73","quantity":"30.131"},{"price":"1732.07","quantity":"57.172"},{"price":"1732.13","quantity":"39.379"},{"price":"1732.24","quantity":"17.518"},{"price":"1732.26","quantity":"23.837"},{"price":"1732.39","quantity":"1.766"},{"price":"1732.42","quantity":"145.609"},{"price":"1732.78","quantity":"12.149"},{"price":"1732.80","quantity":"14.381"},{"price":"1733.13","quantity":"30.371"},{"price":"1733.14","quantity":"14.766"},{"price":"1733.28","quantity":"0.015"},{"price":"1733.30","quantity":"14.319"},{"price":"1733.39","quantity":"21.241"},{"price":"1733.50","quantity":"10.855"},{"price":"1733.63","quantity":"50.351"},{"price":"1733.71","quantity":"84.523"},{"price":"1733.77","quantity":"17.192"},{"price":"1733.78","quantity":"1.166"},{"price":"1733.86","quantity":"0.363"},{"price":"1733.88","quantity":"44.716"},{"price":"1733.98","quantity":"0.299"},{"price":"1734.01","quantity":"22.381"},{"price":"1734.05","quantity":"113.344"},{"price":"1734.06","quantity":"16.697"},{"price":"1734.09","quantity":"3.257"},{"price":"1734.20","quantity":"89.115"},{"price":"1734.21","quantity":"18.126"},{"price":"1734.33","quantity":"19.646"},{"price":"1734.39","quantity":"19.503"},{"price":"1734.55","quantity":"0.400"},{"price":"1734.69","quantity":"1.127"},{"price":"1734.73","quantity":"96.318"},{"price":"1734.86","quantity":"38.363"},{"price":"1734.90","quantity":"19.630"},{"price":"1734.93","quantity":"68.301"},{"price":"1734.94","quantity":"37.464"},{"price":"1734.98","quantity":"69.892"},{"price":"1735.00","quantity":"217.768"},{"price":"1735.02","quantity":"50.215"},{"price":"1735.05","quantity":"0.341"},{"price":"1735.06","quantity":"0.300"},{"price":"1735.07","quantity":"5.393"},{"price":"1735.15","quantity":"5.792"},{"price":"1735.17","quantity":"2.337"},{"price":"1735.20","quantity":"58.556"},{"price":"1735.21","quantity":"35.297"},{"price":"1735.24","quantity":"6.968"},{"price":"1735.27","quantity":"68.088"},{"price":"1735.28","quantity":"4.463"},{"price":"1735.29","quantity":"30.434"},{"price":"1735.31","quantity":"33.706"},{"price":"1735.33","quantity":"16.727"},{"price":"1735.34","quantity":"1.218"},{"price":"1735.35","quantity":"87.774"},{"price":"1735.36","quantity":"0.094"},{"price":"1735.37","quantity":"0.494"},{"price":"1735.38","quantity":"51.418"},{"price":"1735.39","quantity":"0.553"},{"price":"1735.41","quantity":"124.157"},{"price":"1735.42","quantity":"22.311"},{"price":"1735.43","quantity":"0.381"},{"price":"1735.45","quantity":"29.530"},{"price":"1735.48","quantity":"0.862"},{"price":"1735.49","quantity":"7.247"},{"price":"1735.50","quantity":"18.742"},{"price":"1735.52","quantity":"94.192"},{"price":"1735.53","quantity":"10.293"},{"price":"1735.54","quantity":"4.346"},{"price":"1735.55","quantity":"4.511"},{"price":"1735.57","quantity":"258.360"},{"price":"1735.58","quantity":"3.947"},{"price":"1735.59","quantity":"6.264"},{"price":"1735.61","quantity":"8.654"},{"price":"1735.62","quantity":"10.558"},{"price":"1735.64","quantity":"72.223"},{"price":"1735.65","quantity":"16.634"},{"price":"1735.68","quantity":"15.342"},{"price":"1735.69","quantity":"3.996"},{"price":"1735.70","quantity":"38.835"},{"price":"1735.72","quantity":"2.407"},{"price":"1735.74","quantity":"3.479"},{"price":"1735.75","quantity":"75.180"},{"price":"1735.76","quantity":"7.456"},{"price":"1735.77","quantity":"8.723"},{"price":"1735.80","quantity":"0.112"},{"price":"1735.81","quantity":"4.960"},{"price":"1735.85","quantity":"25.724"},{"price":"1735.86","quantity":"68.996"},{"price":"1735.87","quantity":"3.710"},{"price":"1735.88","quantity":"2.424"},{"price":"1735.89","quantity":"1.004"},{"price":"1735.90","quantity":"2.061"},{"price":"1735.91","quantity":"19.513"},{"price":"1735.94","quantity":"17.829"},{"price":"1735.95","quantity":"3.322"},{"price":"1735.99","quantity":"1.653"},{"price":"1736.00","quantity":"17.702"},{"price":"1736.01","quantity":"0.650"},{"price":"1736.02","quantity":"0.999"},{"price":"1736.03","quantity":"2.590"},{"price":"1736.05","quantity":"2.924"},{"price":"1736.06","quantity":"29.370"},{"price":"1736.07","quantity":"0.047"},{"price":"1736.08","quantity":"2.481"},{"price":"1736.09","quantity":"2.168"},{"price":"1736.10","quantity":"5.983"},{"price":"1736.11","quantity":"106.121"},{"price":"1736.12","quantity":"10.327"},{"price":"1736.13","quantity":"67.298"},{"price":"1736.15","quantity":"23.819"},{"price":"1736.16","quantity":"0.860"},{"price":"1736.17","quantity":"1.766"},{"price":"1736.19","quantity":"0.050"},{"price":"1736.20","quantity":"2.802"},{"price":"1736.24","quantity":"0.038"},{"price":"1736.25","quantity":"70.015"},{"price":"1736.26","quantity":"0.038"},{"price":"1736.27","quantity":"12.772"},{"price":"1736.28","quantity":"148.377"}],"asks":[{"price":"1736.29","quantity":"1.592"},{"price":"1736.30","quantity":"4.558"},{"price":"1736.31","quantity":"17.318"},{"price":"1736.35","quantity":"0.026"},{"price":"1736.37","quantity":"4.012"},{"price":"1736.39","quantity":"0.038"},{"price":"1736.40","quantity":"0.086"},{"price":"1736.41","quantity":"0.769"},{"price":"1736.42","quantity":"0.056"},{"price":"1736.43","quantity":"0.032"},{"price":"1736.45","quantity":"4.124"},{"price":"1736.46","quantity":"19.806"},{"price":"1736.47","quantity":"0.247"},{"price":"1736.48","quantity":"21.749"},{"price":"1736.51","quantity":"3.065"},{"price":"1736.52","quantity":"13.652"},{"price":"1736.53","quantity":"2.981"},{"price":"1736.54","quantity":"25.208"},{"price":"1736.55","quantity":"19.082"},{"price":"1736.56","quantity":"4.503"},{"price":"1736.58","quantity":"3.570"},{"price":"1736.59","quantity":"7.115"},{"price":"1736.60","quantity":"4.957"},{"price":"1736.61","quantity":"6.517"},{"price":"1736.62","quantity":"0.876"},{"price":"1736.63","quantity":"23.579"},{"price":"1736.64","quantity":"18.503"},{"price":"1736.65","quantity":"26.692"},{"price":"1736.66","quantity":"0.451"},{"price":"1736.67","quantity":"0.062"},{"price":"1736.69","quantity":"26.263"},{"price":"1736.70","quantity":"79.656"},{"price":"1736.71","quantity":"1.553"},{"price":"1736.72","quantity":"10.202"},{"price":"1736.73","quantity":"2.357"},{"price":"1736.75","quantity":"4.516"},{"price":"1736.77","quantity":"31.786"},{"price":"1736.79","quantity":"1.789"},{"price":"1736.80","quantity":"19.036"},{"price":"1736.82","quantity":"26.498"},{"price":"1736.83","quantity":"43.266"},{"price":"1736.84","quantity":"4.979"},{"price":"1736.86","quantity":"2.050"},{"price":"1736.89","quantity":"4.672"},{"price":"1736.91","quantity":"32.692"},{"price":"1736.92","quantity":"8.851"},{"price":"1736.93","quantity":"17.858"},{"price":"1736.97","quantity":"4.386"},{"price":"1736.98","quantity":"7.252"},{"price":"1737.00","quantity":"60.182"},{"price":"1737.01","quantity":"86.903"},{"price":"1737.02","quantity":"55.457"},{"price":"1737.03","quantity":"16.367"},{"price":"1737.04","quantity":"29.789"},{"price":"1737.07","quantity":"0.691"},{"price":"1737.08","quantity":"3.802"},{"price":"1737.09","quantity":"35.271"},{"price":"1737.10","quantity":"46.226"},{"price":"1737.14","quantity":"76.359"},{"price":"1737.17","quantity":"4.103"},{"price":"1737.18","quantity":"43.389"},{"price":"1737.19","quantity":"1.257"},{"price":"1737.20","quantity":"26.499"},{"price":"1737.29","quantity":"1.847"},{"price":"1737.31","quantity":"9.427"},{"price":"1737.32","quantity":"1.985"},{"price":"1737.34","quantity":"15.015"},{"price":"1737.35","quantity":"23.118"},{"price":"1737.36","quantity":"68.335"},{"price":"1737.37","quantity":"29.259"},{"price":"1737.38","quantity":"88.392"},{"price":"1737.39","quantity":"0.256"},{"price":"1737.42","quantity":"6.201"},{"price":"1737.43","quantity":"0.000"},{"price":"1737.46","quantity":"11.656"},{"price":"1737.50","quantity":"137.761"},{"price":"1737.52","quantity":"0.026"},{"price":"1737.54","quantity":"1.118"},{"price":"1737.57","quantity":"45.395"},{"price":"1737.66","quantity":"0.154"},{"price":"1737.68","quantity":"0.763"},{"price":"1737.70","quantity":"35.872"},{"price":"1737.77","quantity":"3.398"},{"price":"1737.78","quantity":"2.355"},{"price":"1737.79","quantity":"3.295"},{"price":"1737.80","quantity":"6.684"},{"price":"1737.82","quantity":"24.888"},{"price":"1737.83","quantity":"35.166"},{"price":"1737.85","quantity":"94.530"},{"price":"1737.89","quantity":"35.103"},{"price":"1737.94","quantity":"0.012"},{"price":"1737.98","quantity":"0.209"},{"price":"1738.06","quantity":"13.852"},{"price":"1738.07","quantity":"34.583"},{"price":"1738.09","quantity":"0.000"},{"price":"1738.11","quantity":"0.039"},{"price":"1738.17","quantity":"7.677"},{"price":"1738.20","quantity":"1.923"},{"price":"1738.21","quantity":"9.161"},{"price":"1738.25","quantity":"29.008"},{"price":"1738.26","quantity":"1.023"},{"price":"1738.32","quantity":"1.077"},{"price":"1738.37","quantity":"88.051"},{"price":"1738.41","quantity":"5.775"},{"price":"1738.52","quantity":"1.963"},{"price":"1738.58","quantity":"83.983"},{"price":"1738.59","quantity":"1.728"},{"price":"1738.65","quantity":"22.729"},{"price":"1738.66","quantity":"4.048"},{"price":"1738.81","quantity":"9.053"},{"price":"1738.87","quantity":"4.359"},{"price":"1738.88","quantity":"3.757"},{"price":"1738.89","quantity":"73.167"},{"price":"1738.91","quantity":"3.541"},{"price":"1738.92","quantity":"36.250"},{"price":"1738.94","quantity":"7.156"},{"price":"1738.96","quantity":"3.196"},{"price":"1738.97","quantity":"181.920"},{"price":"1738.99","quantity":"159.831"},{"price":"1739.01","quantity":"61.387"},{"price":"1739.05","quantity":"0.154"},{"price":"1739.08","quantity":"13.261"},{"price":"1739.28","quantity":"10.373"},{"price":"1739.35","quantity":"0.430"},{"price":"1739.38","quantity":"1.902"},{"price":"1739.41","quantity":"4.422"},{"price":"1739.42","quantity":"10.957"},{"price":"1739.59","quantity":"0.000"},{"price":"1739.61","quantity":"20.766"},{"price":"1739.76","quantity":"7.354"},{"price":"1739.79","quantity":"0.012"},{"price":"1739.93","quantity":"21.860"},{"price":"1740.02","quantity":"8.840"},{"price":"1740.46","quantity":"0.000"},{"price":"1740.58","quantity":"27.467"},{"price":"1740.63","quantity":"3.715"},{"price":"1741.32","quantity":"15.908"},{"price":"1741.49","quantity":"2.304"},{"price":"1741.75","quantity":"12.268"},{"price":"1742.19","quantity":"0.781"},{"price":"1742.36","quantity":"6.080"},{"price":"1742.44","quantity":"5.839"},{"price":"1742.47","quantity":"7.517"},{"price":"1742.48","quantity":"24.615"},{"price":"1743.06","quantity":"0.098"},{"price":"1743.18","quantity":"5.773"},{"price":"1743.23","quantity":"3.209"},{"price":"1745.26","quantity":"0.070"},{"price":"1747.12","quantity":"0.000"},{"price":"1748.04","quantity":"0.014"},{"price":"1771.29","quantity":"15.241"},{"price":"1778.83","quantity":"145.118"},{"price":"2633.87","quantity":"0.001"},{"price":"2633.96","quantity":"0.000"}],"raw":{"e":"depthUpdate","E":1783517074028,"T":1783517074027,"s":"ETHUSDT","ps":"ETHUSDT","U":10999771232574,"u":10999771252676,"pu":10999771232523,"b":[["200.00","7.594"],["1211.11","5.349"],["1211.28","1.088"],["1216.11","0.864"],["1231.28","2.048"],["1236.11","0.295"],["1562.37","0.014"],["1562.65","0.145"],["1562.66","2.370"],["1666.67","31.522"],["1693.58","121.257"],["1697.92","0.122"],["1701.55","15.928"],["1717.22","3.941"],["1717.29","0.000"],["1718.95","0.291"],["1720.68","0.974"],["1722.42","52.555"],["1724.15","0.676"],["1726.36","0.320"],["1727.18","2.712"],["1730.44","4.322"],["1731.23","22.938"],["1731.24","183.992"],["1731.73","30.131"],["1732.07","57.172"],["1732.13","39.379"],["1732.24","17.518"],["1732.26","23.837"],["1732.39","1.766"],["1732.42","145.609"],["1732.78","12.149"],["1732.80","14.381"],["1733.13","30.371"],["1733.14","14.766"],["1733.28","0.015"],["1733.30","14.319"],["1733.39","21.241"],["1733.50","10.855"],["1733.63","50.351"],["1733.71","84.523"],["1733.77","17.192"],["1733.78","1.166"],["1733.86","0.363"],["1733.88","44.716"],["1733.98","0.299"],["1734.01","22.381"],["1734.05","113.344"],["1734.06","16.697"],["1734.09","3.257"],["1734.20","89.115"],["1734.21","18.126"],["1734.33","19.646"],["1734.39","19.503"],["1734.55","0.400"],["1734.69","1.127"],["1734.73","96.318"],["1734.86","38.363"],["1734.90","19.630"],["1734.93","68.301"],["1734.94","37.464"],["1734.98","69.892"],["1735.00","217.768"],["1735.02","50.215"],["1735.05","0.341"],["1735.06","0.300"],["1735.07","5.393"],["1735.15","5.792"],["1735.17","2.337"],["1735.20","58.556"],["1735.21","35.297"],["1735.24","6.968"],["1735.27","68.088"],["1735.28","4.463"],["1735.29","30.434"],["1735.31","33.706"],["1735.33","16.727"],["1735.34","1.218"],["1735.35","87.774"],["1735.36","0.094"],["1735.37","0.494"],["1735.38","51.418"],["1735.39","0.553"],["1735.41","124.157"],["1735.42","22.311"],["1735.43","0.381"],["1735.45","29.530"],["1735.48","0.862"],["1735.49","7.247"],["1735.50","18.742"],["1735.52","94.192"],["1735.53","10.293"],["1735.54","4.346"],["1735.55","4.511"],["1735.57","258.360"],["1735.58","3.947"],["1735.59","6.264"],["1735.61","8.654"],["1735.62","10.558"],["1735.64","72.223"],["1735.65","16.634"],["1735.68","15.342"],["1735.69","3.996"],["1735.70","38.835"],["1735.72","2.407"],["1735.74","3.479"],["1735.75","75.180"],["1735.76","7.456"],["1735.77","8.723"],["1735.80","0.112"],["1735.81","4.960"],["1735.85","25.724"],["1735.86","68.996"],["1735.87","3.710"],["1735.88","2.424"],["1735.89","1.004"],["1735.90","2.061"],["1735.91","19.513"],["1735.94","17.829"],["1735.95","3.322"],["1735.99","1.653"],["1736.00","17.702"],["1736.01","0.650"],["1736.02","0.999"],["1736.03","2.590"],["1736.05","2.924"],["1736.06","29.370"],["1736.07","0.047"],["1736.08","2.481"],["1736.09","2.168"],["1736.10","5.983"],["1736.11","106.121"],["1736.12","10.327"],["1736.13","67.298"],["1736.15","23.819"],["1736.16","0.860"],["1736.17","1.766"],["1736.19","0.050"],["1736.20","2.802"],["1736.24","0.038"],["1736.25","70.015"],["1736.26","0.038"],["1736.27","12.772"],["1736.28","148.377"]],"a":[["1736.29","1.592"],["1736.30","4.558"],["1736.31","17.318"],["1736.35","0.026"],["1736.37","4.012"],["1736.39","0.038"],["1736.40","0.086"],["1736.41","0.769"],["1736.42","0.056"],["1736.43","0.032"],["1736.45","4.124"],["1736.46","19.806"],["1736.47","0.247"],["1736.48","21.749"],["1736.51","3.065"],["1736.52","13.652"],["1736.53","2.981"],["1736.54","25.208"],["1736.55","19.082"],["1736.56","4.503"],["1736.58","3.570"],["1736.59","7.115"],["1736.60","4.957"],["1736.61","6.517"],["1736.62","0.876"],["1736.63","23.579"],["1736.64","18.503"],["1736.65","26.692"],["1736.66","0.451"],["1736.67","0.062"],["1736.69","26.263"],["1736.70","79.656"],["1736.71","1.553"],["1736.72","10.202"],["1736.73","2.357"],["1736.75","4.516"],["1736.77","31.786"],["1736.79","1.789"],["1736.80","19.036"],["1736.82","26.498"],["1736.83","43.266"],["1736.84","4.979"],["1736.86","2.050"],["1736.89","4.672"],["1736.91","32.692"],["1736.92","8.851"],["1736.93","17.858"],["1736.97","4.386"],["1736.98","7.252"],["1737.00","60.182"],["1737.01","86.903"],["1737.02","55.457"],["1737.03","16.367"],["1737.04","29.789"],["1737.07","0.691"],["1737.08","3.802"],["1737.09","35.271"],["1737.10","46.226"],["1737.14","76.359"],["1737.17","4.103"],["1737.18","43.389"],["1737.19","1.257"],["1737.20","26.499"],["1737.29","1.847"],["1737.31","9.427"],["1737.32","1.985"],["1737.34","15.015"],["1737.35","23.118"],["1737.36","68.335"],["1737.37","29.259"],["1737.38","88.392"],["1737.39","0.256"],["1737.42","6.201"],["1737.43","0.000"],["1737.46","11.656"],["1737.50","137.761"],["1737.52","0.026"],["1737.54","1.118"],["1737.57","45.395"],["1737.66","0.154"],["1737.68","0.763"],["1737.70","35.872"],["1737.77","3.398"],["1737.78","2.355"],["1737.79","3.295"],["1737.80","6.684"],["1737.82","24.888"],["1737.83","35.166"],["1737.85","94.530"],["1737.89","35.103"],["1737.94","0.012"],["1737.98","0.209"],["1738.06","13.852"],["1738.07","34.583"],["1738.09","0.000"],["1738.11","0.039"],["1738.17","7.677"],["1738.20","1.923"],["1738.21","9.161"],["1738.25","29.008"],["1738.26","1.023"],["1738.32","1.077"],["1738.37","88.051"],["1738.41","5.775"],["1738.52","1.963"],["1738.58","83.983"],["1738.59","1.728"],["1738.65","22.729"],["1738.66","4.048"],["1738.81","9.053"],["1738.87","4.359"],["1738.88","3.757"],["1738.89","73.167"],["1738.91","3.541"],["1738.92","36.250"],["1738.94","7.156"],["1738.96","3.196"],["1738.97","181.920"],["1738.99","159.831"],["1739.01","61.387"],["1739.05","0.154"],["1739.08","13.261"],["1739.28","10.373"],["1739.35","0.430"],["1739.38","1.902"],["1739.41","4.422"],["1739.42","10.957"],["1739.59","0.000"],["1739.61","20.766"],["1739.76","7.354"],["1739.79","0.012"],["1739.93","21.860"],["1740.02","8.840"],["1740.46","0.000"],["1740.58","27.467"],["1740.63","3.715"],["1741.32","15.908"],["1741.49","2.304"],["1741.75","12.268"],["1742.19","0.781"],["1742.36","6.080"],["1742.44","5.839"],["1742.47","7.517"],["1742.48","24.615"],["1743.06","0.098"],["1743.18","5.773"],["1743.23","3.209"],["1745.26","0.070"],["1747.12","0.000"],["1748.04","0.014"],["1771.29","15.241"],["1778.83","145.118"],["2633.87","0.001"],["2633.96","0.000"]],"st":1}}
{"schema_version":"1.3.0","event_id":"98c31642-05ab-4d99-85d8-734b2acc90b7","event_type":"raw.depth_update","source":"binance_market_data_recorder","venue":"binance_usdm","market_type":"perpetual_futures","symbol":"ETHUSDT","event_time_ms":1783517074130,"received_time_ms":1783517074125,"trace_id":"591e142c-fec4-49c1-9457-dea4c548ac36","first_update_id":10999771252698,"final_update_id":10999771262677,"previous_final_update_id":10999771252676,"bids":[{"price":"200.00","quantity":"7.594"},{"price":"1211.11","quantity":"4.773"},{"price":"1211.28","quantity":"1.344"},{"price":"1216.11","quantity":"0.608"},{"price":"1231.28","quantity":"2.624"},{"price":"1562.65","quantity":"0.145"},{"price":"1562.66","quantity":"3.010"},{"price":"1660.56","quantity":"0.192"},{"price":"1666.80","quantity":"0.233"},{"price":"1667.48","quantity":"0.252"},{"price":"1693.07","quantity":"26.547"},{"price":"1693.58","quantity":"147.792"},{"price":"1701.55","quantity":"15.899"},{"price":"1702.06","quantity":"16.105"},{"price":"1705.22","quantity":"0.118"},{"price":"1715.66","quantity":"0.012"},{"price":"1722.62","quantity":"5.876"},{"price":"1725.78","quantity":"0.513"},{"price":"1732.14","quantity":"26.076"},{"price":"1732.24","quantity":"10.013"},{"price":"1732.26","quantity":"20.837"},{"price":"1732.43","quantity":"7.610"},{"price":"1733.50","quantity":"13.855"},{"price":"1733.70","quantity":"17.154"},{"price":"1733.76","quantity":"35.199"},{"price":"1733.84","quantity":"14.695"},{"price":"1733.91","quantity":"0.465"},{"price":"1734.01","quantity":"19.185"},{"price":"1734.05","quantity":"113.344"},{"price":"1734.06","quantity":"26.426"},{"price":"1734.07","quantity":"2.780"},{"price":"1734.10","quantity":"70.011"},{"price":"1734.11","quantity":"31.166"},{"price":"1734.12","quantity":"55.897"},{"price":"1734.18","quantity":"429.708"},{"price":"1734.94","quantity":"36.756"},{"price":"1735.07","quantity":"5.662"},{"price":"1735.08","quantity":"8.845"},{"price":"1735.13","quantity":"1.937"},{"price":"1735.15","quantity":"5.778"},{"price":"1735.28","quantity":"5.463"},{"price":"1735.32","quantity":"27.764"},{"price":"1735.35","quantity":"87.709"},{"price":"1735.36","quantity":"0.159"},{"price":"1735.41","quantity":"124.157"},{"price":"1735.49","quantity":"5.047"},{"price":"1735.51","quantity":"269.943"},{"price":"1735.53","quantity":"10.293"},{"price":"1735.54","quantity":"43.275"},{"price":"1735.57","quantity":"0.074"},{"price":"1735.59","quantity":"7.597"},{"price":"1735.68","quantity":"18.221"},{"price":"1735.69","quantity":"225.437"},{"price":"1735.70","quantity":"38.835"},{"price":"1735.75","quantity":"75.180"},{"price":"1735.76","quantity":"7.733"},{"price":"1735.79","quantity":"7.584"},{"price":"1735.83","quantity":"24.905"},{"price":"1735.84","quantity":"6.037"},{"price":"1735.85","quantity":"25.124"},{"price":"1735.87","quantity":"3.765"},{"price":"1735.90","quantity":"1.261"},{"price":"1735.93","quantity":"6.322"},{"price":"1735.99","quantity":"2.453"},{"price":"1736.01","quantity":"30.279"},{"price":"1736.02","quantity":"2.399"},{"price":"1736.03","quantity":"3.190"},{"price":"1736.04","quantity":"6.538"},{"price":"1736.05","quantity":"2.904"},{"price":"1736.06","quantity":"0.542"},{"price":"1736.10","quantity":"10.374"},{"price":"1736.11","quantity":"105.932"},{"price":"1736.12","quantity":"10.307"},{"price":"1736.15","quantity":"19.593"},{"price":"1736.16","quantity":"0.840"},{"price":"1736.25","quantity":"70.015"},{"price":"1736.28","quantity":"148.785"}],"asks":[{"price":"1736.29","quantity":"2.099"},{"price":"1736.43","quantity":"2.894"},{"price":"1736.44","quantity":"2.637"},{"price":"1736.45","quantity":"4.124"},{"price":"1736.46","quantity":"19.828"},{"price":"1736.47","quantity":"0.232"},{"price":"1736.48","quantity":"1.749"},{"price":"1736.49","quantity":"37.413"},{"price":"1736.53","quantity":"2.820"},{"price":"1736.55","quantity":"22.509"},{"price":"1736.56","quantity":"8.683"},{"price":"1736.58","quantity":"5.810"},{"price":"1736.59","quantity":"25.810"},{"price":"1736.61","quantity":"3.908"},{"price":"1736.62","quantity":"2.029"},{"price":"1736.63","quantity":"27.955"},{"price":"1736.64","quantity":"18.439"},{"price":"1736.65","quantity":"19.474"},{"price":"1736.71","quantity":"1.641"},{"price":"1736.74","quantity":"17.944"},{"price":"1736.80","quantity":"17.883"},{"price":"1736.81","quantity":"22.809"},{"price":"1736.88","quantity":"3.790"},{"price":"1736.90","quantity":"22.714"},{"price":"1736.99","quantity":"89.792"},{"price":"1737.00","quantity":"49.164"},{"price":"1737.05","quantity":"0.039"},{"price":"1737.09","quantity":"24.497"},{"price":"1737.13","quantity":"13.142"},{"price":"1737.14","quantity":"76.934"},{"price":"1737.15","quantity":"9.687"},{"price":"1737.18","quantity":"43.189"},{"price":"1737.23","quantity":"33.167"},{"price":"1737.30","quantity":"0.090"},{"price":"1737.68","quantity":"3.403"},{"price":"1737.77","quantity":"3.398"},{"price":"1737.81","quantity":"33.908"},{"price":"1737.82","quantity":"22.648"},{"price":"1737.84","quantity":"10.614"},{"price":"1737.85","quantity":"92.450"},{"price":"1737.86","quantity":"2.781"},{"price":"1737.89","quantity":"8.973"},{"price":"1738.12","quantity":"4.331"},{"price":"1738.25","quantity":"2.878"},{"price":"1738.29","quantity":"26.985"},{"price":"1738.32","quantity":"406.527"},{"price":"1738.34","quantity":"36.749"},{"price":"1738.38","quantity":"0.046"},{"price":"1738.46","quantity":"27.583"},{"price":"1738.49","quantity":"19.436"},{"price":"1738.85","quantity":"3.921"},{"price":"1738.88","quantity":"0.561"},{"price":"1738.98","quantity":"40.552"},{"price":"1739.17","quantity":"18.540"},{"price":"1739.18","quantity":"67.255"},{"price":"1740.58","quantity":"19.962"},{"price":"1741.75","quantity":"21.719"},{"price":"1742.48","quantity":"32.120"},{"price":"1745.26","quantity":"0.070"},{"price":"1747.23","quantity":"0.047"},{"price":"1747.97","quantity":"1.638"},{"price":"1751.46","quantity":"22.882"},{"price":"1753.48","quantity":"3.762"},{"price":"1754.80","quantity":"26.276"},{"price":"1757.99","quantity":"25.484"},{"price":"1778.83","quantity":"170.381"},{"price":"2633.85","quantity":"0.190"},{"price":"2633.86","quantity":"0.001"},{"price":"2633.94","quantity":"0.000"},{"price":"2633.95","quantity":"0.042"}],"raw":{"e":"depthUpdate","E":1783517074130,"T":1783517074129,"s":"ETHUSDT","ps":"ETHUSDT","U":10999771252698,"u":10999771262677,"pu":10999771252676,"b":[["200.00","7.594"],["1211.11","4.773"],["1211.28","1.344"],["1216.11","0.608"],["1231.28","2.624"],["1562.65","0.145"],["1562.66","3.010"],["1660.56","0.192"],["1666.80","0.233"],["1667.48","0.252"],["1693.07","26.547"],["1693.58","147.792"],["1701.55","15.899"],["1702.06","16.105"],["1705.22","0.118"],["1715.66","0.012"],["1722.62","5.876"],["1725.78","0.513"],["1732.14","26.076"],["1732.24","10.013"],["1732.26","20.837"],["1732.43","7.610"],["1733.50","13.855"],["1733.70","17.154"],["1733.76","35.199"],["1733.84","14.695"],["1733.91","0.465"],["1734.01","19.185"],["1734.05","113.344"],["1734.06","26.426"],["1734.07","2.780"],["1734.10","70.011"],["1734.11","31.166"],["1734.12","55.897"],["1734.18","429.708"],["1734.94","36.756"],["1735.07","5.662"],["1735.08","8.845"],["1735.13","1.937"],["1735.15","5.778"],["1735.28","5.463"],["1735.32","27.764"],["1735.35","87.709"],["1735.36","0.159"],["1735.41","124.157"],["1735.49","5.047"],["1735.51","269.943"],["1735.53","10.293"],["1735.54","43.275"],["1735.57","0.074"],["1735.59","7.597"],["1735.68","18.221"],["1735.69","225.437"],["1735.70","38.835"],["1735.75","75.180"],["1735.76","7.733"],["1735.79","7.584"],["1735.83","24.905"],["1735.84","6.037"],["1735.85","25.124"],["1735.87","3.765"],["1735.90","1.261"],["1735.93","6.322"],["1735.99","2.453"],["1736.01","30.279"],["1736.02","2.399"],["1736.03","3.190"],["1736.04","6.538"],["1736.05","2.904"],["1736.06","0.542"],["1736.10","10.374"],["1736.11","105.932"],["1736.12","10.307"],["1736.15","19.593"],["1736.16","0.840"],["1736.25","70.015"],["1736.28","148.785"]],"a":[["1736.29","2.099"],["1736.43","2.894"],["1736.44","2.637"],["1736.45","4.124"],["1736.46","19.828"],["1736.47","0.232"],["1736.48","1.749"],["1736.49","37.413"],["1736.53","2.820"],["1736.55","22.509"],["1736.56","8.683"],["1736.58","5.810"],["1736.59","25.810"],["1736.61","3.908"],["1736.62","2.029"],["1736.63","27.955"],["1736.64","18.439"],["1736.65","19.474"],["1736.71","1.641"],["1736.74","17.944"],["1736.80","17.883"],["1736.81","22.809"],["1736.88","3.790"],["1736.90","22.714"],["1736.99","89.792"],["1737.00","49.164"],["1737.05","0.039"],["1737.09","24.497"],["1737.13","13.142"],["1737.14","76.934"],["1737.15","9.687"],["1737.18","43.189"],["1737.23","33.167"],["1737.30","0.090"],["1737.68","3.403"],["1737.77","3.398"],["1737.81","33.908"],["1737.82","22.648"],["1737.84","10.614"],["1737.85","92.450"],["1737.86","2.781"],["1737.89","8.973"],["1738.12","4.331"],["1738.25","2.878"],["1738.29","26.985"],["1738.32","406.527"],["1738.34","36.749"],["1738.38","0.046"],["1738.46","27.583"],["1738.49","19.436"],["1738.85","3.921"],["1738.88","0.561"],["1738.98","40.552"],["1739.17","18.540"],["1739.18","67.255"],["1740.58","19.962"],["1741.75","21.719"],["1742.48","32.120"],["1745.26","0.070"],["1747.23","0.047"],["1747.97","1.638"],["1751.46","22.882"],["1753.48","3.762"],["1754.80","26.276"],["1757.99","25.484"],["1778.83","170.381"],["2633.85","0.190"],["2633.86","0.001"],["2633.94","0.000"],["2633.95","0.042"]],"st":1}}
{"schema_version":"1.3.0","event_id":"21fe8bcf-2c19-4c16-b9f0-6ad61056f2c9","event_type":"raw.depth_update","source":"binance_market_data_recorder","venue":"binance_usdm","market_type":"perpetual_futures","symbol":"ETHUSDT","event_time_ms":1783517074232,"received_time_ms":1783517074227,"trace_id":"dcccc87e-18c7-4c09-9d55-2d7b186603dd","first_update_id":10999771262758,"final_update_id":10999771273073,"previous_final_update_id":10999771262677,"bids":[{"price":"1211.11","quantity":"4.261"},{"price":"1211.28","quantity":"1.632"},{"price":"1216.11","quantity":"0.320"},{"price":"1231.28","quantity":"3.136"},{"price":"1360.60","quantity":"3.500"},{"price":"1562.65","quantity":"0.145"},{"price":"1562.66","quantity":"3.394"},{"price":"1612.45","quantity":"0.139"},{"price":"1666.80","quantity":"0.348"},{"price":"1700.75","quantity":"29.791"},{"price":"1710.24","quantity":"203.198"},{"price":"1711.16","quantity":"0.506"},{"price":"1714.50","quantity":"0.625"},{"price":"1718.10","quantity":"46.200"},{"price":"1727.54","quantity":"47.043"},{"price":"1730.96","quantity":"3.818"},{"price":"1731.33","quantity":"20.607"},{"price":"1732.43","quantity":"0.105"},{"price":"1733.14","quantity":"12.542"},{"price":"1734.10","quantity":"71.457"},{"price":"1734.21","quantity":"27.855"},{"price":"1734.54","quantity":"20.402"},{"price":"1735.20","quantity":"47.556"},{"price":"1735.21","quantity":"36.009"},{"price":"1735.28","quantity":"5.463"},{"price":"1735.30","quantity":"40.959"},{"price":"1735.41","quantity":"124.177"},{"price":"1735.54","quantity":"4.346"},{"price":"1735.57","quantity":"39.002"},{"price":"1735.60","quantity":"1.552"},{"price":"1735.62","quantity":"10.576"},{"price":"1735.69","quantity":"6.196"},{"price":"1735.84","quantity":"5.237"},{"price":"1735.85","quantity":"24.324"},{"price":"1735.93","quantity":"5.522"},{"price":"1735.95","quantity":"1.018"},{"price":"1736.00","quantity":"18.502"},{"price":"1736.01","quantity":"32.583"},{"price":"1736.03","quantity":"3.990"},{"price":"1736.04","quantity":"7.138"},{"price":"1736.05","quantity":"4.304"},{"price":"1736.09","quantity":"1.895"},{"price":"1736.11","quantity":"105.909"},{"price":"1736.24","quantity":"8.902"},{"price":"1736.27","quantity":"12.786"},{"price":"1736.28","quantity":"155.387"}],"asks":[{"price":"1736.29","quantity":"1.622"},{"price":"1736.43","quantity":"0.032"},{"price":"1736.44","quantity":"5.499"},{"price":"1736.45","quantity":"4.139"},{"price":"1736.48","quantity":"8.376"},{"price":"1736.56","quantity":"11.243"},{"price":"1736.57","quantity":"5.086"},{"price":"1736.60","quantity":"7.277"},{"price":"1736.65","quantity":"19.562"},{"price":"1736.69","quantity":"27.957"},{"price":"1736.72","quantity":"11.785"},{"price":"1736.80","quantity":"11.256"},{"price":"1737.00","quantity":"49.272"},{"price":"1737.06","quantity":"21.390"},{"price":"1737.07","quantity":"2.385"},{"price":"1737.20","quantity":"29.499"},{"price":"1737.36","quantity":"70.535"},{"price":"1737.41","quantity":"1.878"},{"price":"1737.46","quantity":"8.656"},{"price":"1737.57","quantity":"43.195"},{"price":"1737.58","quantity":"23.163"},{"price":"1737.70","quantity":"34.178"},{"price":"1737.80","quantity":"3.564"},{"price":"1737.81","quantity":"36.468"},{"price":"1737.82","quantity":"20.488"},{"price":"1737.84","quantity":"8.374"},{"price":"1737.89","quantity":"7.279"},{"price":"1738.07","quantity":"32.889"},{"price":"1738.26","quantity":"27.153"},{"price":"1738.34","quantity":"12.939"},{"price":"1738.41","quantity":"4.081"},{"price":"1738.48","quantity":"2.878"},{"price":"1738.97","quantity":"185.116"},{"price":"1748.63","quantity":"37.939"},{"price":"1774.76","quantity":"0.012"},{"price":"1778.50","quantity":"0.080"},{"price":"2633.84","quantity":"0.001"},{"price":"2633.93","quantity":"0.000"}],"raw":{"e":"depthUpdate","E":1783517074232,"T":1783517074230,"s":"ETHUSDT","ps":"ETHUSDT","U":10999771262758,"u":10999771273073,"pu":10999771262677,"b":[["1211.11","4.261"],["1211.28","1.632"],["1216.11","0.320"],["1231.28","3.136"],["1360.60","3.500"],["1562.65","0.145"],["1562.66","3.394"],["1612.45","0.139"],["1666.80","0.348"],["1700.75","29.791"],["1710.24","203.198"],["1711.16","0.506"],["1714.50","0.625"],["1718.10","46.200"],["1727.54","47.043"],["1730.96","3.818"],["1731.33","20.607"],["1732.43","0.105"],["1733.14","12.542"],["1734.10","71.457"],["1734.21","27.855"],["1734.54","20.402"],["1735.20","47.556"],["1735.21","36.009"],["1735.28","5.463"],["1735.30","40.959"],["1735.41","124.177"],["1735.54","4.346"],["1735.57","39.002"],["1735.60","1.552"],["1735.62","10.576"],["1735.69","6.196"],["1735.84","5.237"],["1735.85","24.324"],["1735.93","5.522"],["1735.95","1.018"],["1736.00","18.502"],["1736.01","32.583"],["1736.03","3.990"],["1736.04","7.138"],["1736.05","4.304"],["1736.09","1.895"],["1736.11","105.909"],["1736.24","8.902"],["1736.27","12.786"],["1736.28","155.387"]],"a":[["1736.29","1.622"],["1736.43","0.032"],["1736.44","5.499"],["1736.45","4.139"],["1736.48","8.376"],["1736.56","11.243"],["1736.57","5.086"],["1736.60","7.277"],["1736.65","19.562"],["1736.69","27.957"],["1736.72","11.785"],["1736.80","11.256"],["1737.00","49.272"],["1737.06","21.390"],["1737.07","2.385"],["1737.20","29.499"],["1737.36","70.535"],["1737.41","1.878"],["1737.46","8.656"],["1737.57","43.195"],["1737.58","23.163"],["1737.70","34.178"],["1737.80","3.564"],["1737.81","36.468"],["1737.82","20.488"],["1737.84","8.374"],["1737.89","7.279"],["1738.07","32.889"],["1738.26","27.153"],["1738.34","12.939"],["1738.41","4.081"],["1738.48","2.878"],["1738.97","185.116"],["1748.63","37.939"],["1774.76","0.012"],["1778.50","0.080"],["2633.84","0.001"],["2633.93","0.000"]],"st":1}}
{"schema_version":"1.3.0","event_id":"f0778483-10e0-471c-9f3a-d8c301fa372a","event_type":"raw.depth_update","source":"binance_market_data_recorder","venue":"binance_usdm","market_type":"perpetual_futures","symbol":"ETHUSDT","event_time_ms":1783517074334,"received_time_ms":1783517074330,"trace_id":"ecfae59f-9138-419f-8529-f9668b197bfb","first_update_id":10999771273283,"final_update_id":10999771284670,"previous_final_update_id":10999771273073,"bids":[{"price":"200.00","quantity":"7.594"},{"price":"1211.11","quantity":"3.685"},{"price":"1211.28","quantity":"1.888"},{"price":"1216.11","quantity":"0.064"},{"price":"1231.28","quantity":"3.712"},{"price":"1562.65","quantity":"0.145"},{"price":"1562.66","quantity":"3.536"},{"price":"1666.80","quantity":"0.233"},{"price":"1693.58","quantity":"174.326"},{"price":"1701.55","quantity":"15.928"},{"price":"1710.24","quantity":"191.521"},{"price":"1710.29","quantity":"70.234"},{"price":"1727.89","quantity":"0.013"},{"price":"1727.91","quantity":"1.256"},{"price":"1728.06","quantity":"10.098"},{"price":"1732.26","quantity":"20.837"},{"price":"1733.50","quantity":"13.855"},{"price":"1733.94","quantity":"29.303"},{"price":"1734.79","quantity":"18.739"},{"price":"1735.13","quantity":"1.903"},{"price":"1735.19","quantity":"1.192"},{"price":"1735.21","quantity":"36.266"},{"price":"1735.33","quantity":"17.039"},{"price":"1735.34","quantity":"1.010"},{"price":"1735.48","quantity":"0.862"},{"price":"1735.68","quantity":"15.342"},{"price":"1735.74","quantity":"3.307"},{"price":"1735.84","quantity":"4.437"},{"price":"1735.85","quantity":"23.008"},{"price":"1735.86","quantity":"68.396"},{"price":"1735.87","quantity":"3.165"},{"price":"1735.88","quantity":"0.836"},{"price":"1735.91","quantity":"18.713"},{"price":"1735.93","quantity":"5.510"},{"price":"1735.95","quantity":"0.674"},{"price":"1736.00","quantity":"19.314"},{"price":"1736.03","quantity":"4.790"},{"price":"1736.05","quantity":"5.104"},{"price":"1736.06","quantity":"0.026"},{"price":"1736.07","quantity":"0.847"},{"price":"1736.14","quantity":"40.659"},{"price":"1736.16","quantity":"0.668"},{"price":"1736.27","quantity":"12.270"},{"price":"1736.28","quantity":"159.340"}],"asks":[{"price":"1736.44","quantity":"2.637"},{"price":"1736.45","quantity":"7.001"},{"price":"1736.48","quantity":"8.376"},{"price":"1736.60","quantity":"9.357"},{"price":"1736.63","quantity":"23.579"},{"price":"1736.64","quantity":"16.772"},{"price":"1736.69","quantity":"26.263"},{"price":"1736.72","quantity":"10.091"},{"price":"1736.79","quantity":"0.089"},{"price":"1736.80","quantity":"15.632"},{"price":"1736.95","quantity":"0.075"},{"price":"1737.01","quantity":"87.103"},{"price":"1737.07","quantity":"0.691"},{"price":"1737.15","quantity":"7.987"},{"price":"1737.17","quantity":"5.797"},{"price":"1737.23","quantity":"32.967"},{"price":"1737.29","quantity":"1.847"},{"price":"1737.30","quantity":"0.090"},{"price":"1737.39","quantity":"3.711"},{"price":"1737.55","quantity":"38.945"},{"price":"1737.64","quantity":"38.581"},{"price":"1737.77","quantity":"0.758"},{"price":"1737.86","quantity":"4.861"},{"price":"1737.89","quantity":"8.973"},{"price":"1738.24","quantity":"26.168"},{"price":"1738.25","quantity":"408.328"},{"price":"1738.26","quantity":"1.023"},{"price":"1738.29","quantity":"8.662"},{"price":"1738.32","quantity":"1.077"},{"price":"1744.33","quantity":"0.085"},{"price":"1744.34","quantity":"0.023"},{"price":"1744.50","quantity":"2.670"},{"price":"1744.51","quantity":"10.026"},{"price":"1747.12","quantity":"15.000"},{"price":"1761.47","quantity":"5.105"},{"price":"1765.08","quantity":"5.657"},{"price":"1770.14","quantity":"153.079"},{"price":"2633.82","quantity":"0.001"},{"price":"2633.83","quantity":"0.001"},{"price":"2633.91","quantity":"0.000"},{"price":"2633.92","quantity":"0.000"}],"raw":{"e":"depthUpdate","E":1783517074334,"T":1783517074333,"s":"ETHUSDT","ps":"ETHUSDT","U":10999771273283,"u":10999771284670,"pu":10999771273073,"b":[["200.00","7.594"],["1211.11","3.685"],["1211.28","1.888"],["1216.11","0.064"],["1231.28","3.712"],["1562.65","0.145"],["1562.66","3.536"],["1666.80","0.233"],["1693.58","174.326"],["1701.55","15.928"],["1710.24","191.521"],["1710.29","70.234"],["1727.89","0.013"],["1727.91","1.256"],["1728.06","10.098"],["1732.26","20.837"],["1733.50","13.855"],["1733.94","29.303"],["1734.79","18.739"],["1735.13","1.903"],["1735.19","1.192"],["1735.21","36.266"],["1735.33","17.039"],["1735.34","1.010"],["1735.48","0.862"],["1735.68","15.342"],["1735.74","3.307"],["1735.84","4.437"],["1735.85","23.008"],["1735.86","68.396"],["1735.87","3.165"],["1735.88","0.836"],["1735.91","18.713"],["1735.93","5.510"],["1735.95","0.674"],["1736.00","19.314"],["1736.03","4.790"],["1736.05","5.104"],["1736.06","0.026"],["1736.07","0.847"],["1736.14","40.659"],["1736.16","0.668"],["1736.27","12.270"],["1736.28","159.340"]],"a":[["1736.44","2.637"],["1736.45","7.001"],["1736.48","8.376"],["1736.60","9.357"],["1736.63","23.579"],["1736.64","16.772"],["1736.69","26.263"],["1736.72","10.091"],["1736.79","0.089"],["1736.80","15.632"],["1736.95","0.075"],["1737.01","87.103"],["1737.07","0.691"],["1737.15","7.987"],["1737.17","5.797"],["1737.23","32.967"],["1737.29","1.847"],["1737.30","0.090"],["1737.39","3.711"],["1737.55","38.945"],["1737.64","38.581"],["1737.77","0.758"],["1737.86","4.861"],["1737.89","8.973"],["1738.24","26.168"],["1738.25","408.328"],["1738.26","1.023"],["1738.29","8.662"],["1738.32","1.077"],["1744.33","0.085"],["1744.34","0.023"],["1744.50","2.670"],["1744.51","10.026"],["1747.12","15.000"],["1761.47","5.105"],["1765.08","5.657"],["1770.14","153.079"],["2633.82","0.001"],["2633.83","0.001"],["2633.91","0.000"],["2633.92","0.000"]],"st":1}}
{"schema_version":"1.3.0","event_id":"8986daf0-61d6-4de0-9cf5-245d7630f17e","event_type":"raw.depth_update","source":"binance_market_data_recorder","venue":"binance_usdm","market_type":"perpetual_futures","symbol":"ETHUSDT","event_time_ms":1783517074436,"received_time_ms":1783517074430,"trace_id":"def77487-993a-43a8-a125-7f7e62c6a118","first_update_id":10999771284710,"final_update_id":10999771296840,"previous_final_update_id":10999771284670,"bids":[{"price":"200.00","quantity":"7.594"},{"price":"1211.11","quantity":"3.173"},{"price":"1211.28","quantity":"1.728"},{"price":"1216.11","quantity":"0.000"},{"price":"1231.28","quantity":"4.448"},{"price":"1562.38","quantity":"0.254"},{"price":"1562.65","quantity":"0.145"},{"price":"1562.66","quantity":"3.536"},{"price":"1666.80","quantity":"0.348"},{"price":"1701.55","quantity":"15.899"},{"price":"1705.75","quantity":"58.547"},{"price":"1709.20","quantity":"110.619"},{"price":"1710.34","quantity":"20.498"},{"price":"1730.76","quantity":"0.528"},{"price":"1730.93","quantity":"16.528"},{"price":"1733.82","quantity":"2.563"},{"price":"1733.84","quantity":"15.295"},{"price":"1734.51","quantity":"14.057"},{"price":"1734.53","quantity":"35.642"},{"price":"1734.81","quantity":"18.157"},{"price":"1735.07","quantity":"5.490"},{"price":"1735.16","quantity":"7.364"},{"price":"1735.21","quantity":"36.009"},{"price":"1735.24","quantity":"7.140"},{"price":"1735.25","quantity":"3.306"},{"price":"1735.26","quantity":"1.138"},{"price":"1735.28","quantity":"5.463"},{"price":"1735.29","quantity":"29.634"},{"price":"1735.33","quantity":"16.911"},{"price":"1735.36","quantity":"0.759"},{"price":"1735.42","quantity":"20.611"},{"price":"1735.72","quantity":"4.107"},{"price":"1735.74","quantity":"6.186"},{"price":"1735.78","quantity":"0.028"},{"price":"1735.87","quantity":"0.965"},{"price":"1735.91","quantity":"17.913"},{"price":"1735.92","quantity":"31.268"},{"price":"1735.95","quantity":"0.074"},{"price":"1735.96","quantity":"0.552"},{"price":"1735.97","quantity":"5.975"},{"price":"1735.98","quantity":"68.284"},{"price":"1736.00","quantity":"20.114"},{"price":"1736.05","quantity":"5.904"},{"price":"1736.06","quantity":"0.826"},{"price":"1736.07","quantity":"1.647"},{"price":"1736.08","quantity":"4.181"},{"price":"1736.28","quantity":"153.712"}],"asks":[{"price":"1736.45","quantity":"4.139"},{"price":"1736.47","quantity":"3.094"},{"price":"1736.49","quantity":"39.113"},{"price":"1736.85","quantity":"69.390"},{"price":"1737.00","quantity":"60.272"},{"price":"1737.79","quantity":"0.015"},{"price":"1737.81","quantity":"33.908"},{"price":"1737.83","quantity":"33.086"},{"price":"1737.84","quantity":"5.894"},{"price":"1738.52","quantity":"0.403"},{"price":"1738.91","quantity":"0.345"},{"price":"1738.94","quantity":"3.960"},{"price":"1738.96","quantity":"0.000"},{"price":"1738.98","quantity":"43.748"},{"price":"1741.48","quantity":"3.661"},{"price":"1741.72","quantity":"14.205"},{"price":"1753.59","quantity":"39.885"},{"price":"1753.66","quantity":"146.044"},{"price":"1758.71","quantity":"62.212"},{"price":"1765.81","quantity":"118.763"},{"price":"2633.81","quantity":"0.001"},{"price":"2633.90","quantity":"0.000"}],"raw":{"e":"depthUpdate","E":1783517074436,"T":1783517074435,"s":"ETHUSDT","ps":"ETHUSDT","U":10999771284710,"u":10999771296840,"pu":10999771284670,"b":[["200.00","7.594"],["1211.11","3.173"],["1211.28","1.728"],["1216.11","0.000"],["1231.28","4.448"],["1562.38","0.254"],["1562.65","0.145"],["1562.66","3.536"],["1666.80","0.348"],["1701.55","15.899"],["1705.75","58.547"],["1709.20","110.619"],["1710.34","20.498"],["1730.76","0.528"],["1730.93","16.528"],["1733.82","2.563"],["1733.84","15.295"],["1734.51","14.057"],["1734.53","35.642"],["1734.81","18.157"],["1735.07","5.490"],["1735.16","7.364"],["1735.21","36.009"],["1735.24","7.140"],["1735.25","3.306"],["1735.26","1.138"],["1735.28","5.463"],["1735.29","29.634"],["1735.33","16.911"],["1735.36","0.759"],["1735.42","20.611"],["1735.72","4.107"],["1735.74","6.186"],["1735.78","0.028"],["1735.87","0.965"],["1735.91","17.913"],["1735.92","31.268"],["1735.95","0.074"],["1735.96","0.552"],["1735.97","5.975"],["1735.98","68.284"],["1736.00","20.114"],["1736.05","5.904"],["1736.06","0.826"],["1736.07","1.647"],["1736.08","4.181"],["1736.28","153.712"]],"a":[["1736.45","4.139"],["1736.47","3.094"],["1736.49","39.113"],["1736.85","69.390"],["1737.00","60.272"],["1737.79","0.015"],["1737.81","33.908"],["1737.83","33.086"],["1737.84","5.894"],["1738.52","0.403"],["1738.91","0.345"],["1738.94","3.960"],["1738.96","0.000"],["1738.98","43.748"],["1741.48","3.661"],["1741.72","14.205"],["1753.59","39.885"],["1753.66","146.044"],["1758.71","62.212"],["1765.81","118.763"],["2633.81","0.001"],["2633.90","0.000"]],"st":1}}
{"schema_version":"1.3.0","event_id":"926a204f-211e-40e0-a6ea-4c3e3d05f7b4","event_type":"raw.depth_update","source":"binance_market_data_recorder","venue":"binance_usdm","market_type":"perpetual_futures","symbol":"ETHUSDT","event_time_ms":1783517074538,"received_time_ms":1783517074609,"trace_id":"84e37122-43a0-4abf-acf7-254a166f0158","first_update_id":10999771297028,"final_update_id":10999771318215,"previous_final_update_id":10999771296840,"bids":[{"price":"100.00","quantity":"136.359"},{"price":"201.00","quantity":"2.300"},{"price":"1211.11","quantity":"2.597"},{"price":"1211.28","quantity":"1.472"},{"price":"1231.28","quantity":"5.280"},{"price":"1562.65","quantity":"0.145"},{"price":"1562.66","quantity":"3.664"},{"price":"1701.55","quantity":"15.928"},{"price":"1705.26","quantity":"29.110"},{"price":"1728.97","quantity":"34.291"},{"price":"1730.07","quantity":"135.808"},{"price":"1730.08","quantity":"26.300"},{"price":"1730.09","quantity":"4.331"},{"price":"1733.71","quantity":"514.219"},{"price":"1733.95","quantity":"5.906"},{"price":"1733.96","quantity":"7.802"},{"price":"1734.10","quantity":"68.261"},{"price":"1734.11","quantity":"29.720"},{"price":"1734.18","quantity":"0.012"},{"price":"1734.79","quantity":"7.220"},{"price":"1735.02","quantity":"50.028"},{"price":"1735.16","quantity":"7.551"},{"price":"1735.21","quantity":"35.209"},{"price":"1735.27","quantity":"67.794"},{"price":"1735.35","quantity":"88.309"},{"price":"1735.36","quantity":"1.359"},{"price":"1735.51","quantity":"50.672"},{"price":"1735.53","quantity":"12.021"},{"price":"1735.54","quantity":"0.027"},{"price":"1735.59","quantity":"3.264"},{"price":"1735.74","quantity":"3.307"},{"price":"1735.76","quantity":"6.005"},{"price":"1735.79","quantity":"226.326"},{"price":"1735.83","quantity":"25.188"},{"price":"1735.86","quantity":"68.408"},{"price":"1735.88","quantity":"0.036"},{"price":"1735.89","quantity":"1.004"},{"price":"1735.92","quantity":"31.268"},{"price":"1735.93","quantity":"5.524"},{"price":"1736.15","quantity":"23.912"},{"price":"1736.24","quantity":"8.914"},{"price":"1736.28","quantity":"183.225"}],"asks":[{"price":"1736.32","quantity":"0.081"},{"price":"1736.38","quantity":"0.055"},{"price":"1736.47","quantity":"3.094"},{"price":"1736.48","quantity":"8.376"},{"price":"1736.63","quantity":"27.955"},{"price":"1736.64","quantity":"15.572"},{"price":"1736.66","quantity":"1.308"},{"price":"1736.80","quantity":"11.256"},{"price":"1737.29","quantity":"1.847"},{"price":"1737.64","quantity":"27.062"},{"price":"1737.81","quantity":"31.348"},{"price":"1737.86","quantity":"2.701"},{"price":"1738.34","quantity":"10.619"},{"price":"1744.81","quantity":"0.154"},{"price":"1745.00","quantity":"57.185"},{"price":"1750.00","quantity":"224.262"},{"price":"1757.99","quantity":"34.003"},{"price":"1778.82","quantity":"25.263"},{"price":"1800.57","quantity":"0.667"},{"price":"2633.79","quantity":"0.079"},{"price":"2633.80","quantity":"0.001"},{"price":"2633.88","quantity":"0.000"},{"price":"2633.89","quantity":"0.000"}],"raw":{"e":"depthUpdate","E":1783517074538,"T":1783517074537,"s":"ETHUSDT","ps":"ETHUSDT","U":10999771297028,"u":10999771318215,"pu":10999771296840,"b":[["100.00","136.359"],["201.00","2.300"],["1211.11","2.597"],["1211.28","1.472"],["1231.28","5.280"],["1562.65","0.145"],["1562.66","3.664"],["1701.55","15.928"],["1705.26","29.110"],["1728.97","34.291"],["1730.07","135.808"],["1730.08","26.300"],["1730.09","4.331"],["1733.71","514.219"],["1733.95","5.906"],["1733.96","7.802"],["1734.10","68.261"],["1734.11","29.720"],["1734.18","0.012"],["1734.79","7.220"],["1735.02","50.028"],["1735.16","7.551"],["1735.21","35.209"],["1735.27","67.794"],["1735.35","88.309"],["1735.36","1.359"],["1735.51","50.672"],["1735.53","12.021"],["1735.54","0.027"],["1735.59","3.264"],["1735.74","3.307"],["1735.76","6.005"],["1735.79","226.326"],["1735.83","25.188"],["1735.86","68.408"],["1735.88","0.036"],["1735.89","1.004"],["1735.92","31.268"],["1735.93","5.524"],["1736.15","23.912"],["1736.24","8.914"],["1736.28","183.225"]],"a":[["1736.32","0.081"],["1736.38","0.055"],["1736.47","3.094"],["1736.48","8.376"],["1736.63","27.955"],["1736.64","15.572"],["1736.66","1.308"],["1736.80","11.256"],["1737.29","1.847"],["1737.64","27.062"],["1737.81","31.348"],["1737.86","2.701"],["1738.34","10.619"],["1744.81","0.154"],["1745.00","57.185"],["1750.00","224.262"],["1757.99","34.003"],["1778.82","25.263"],["1800.57","0.667"],["2633.79","0.079"],["2633.80","0.001"],["2633.88","0.000"],["2633.89","0.000"]],"st":1}}
{"schema_version":"1.3.0","event_id":"0ee8e3e4-88f2-4949-87ff-9ae7d3cd0d3d","event_type":"raw.depth_update","source":"binance_market_data_recorder","venue":"binance_usdm","market_type":"perpetual_futures","symbol":"ETHUSDT","event_time_ms":1783517074640,"received_time_ms":1783517074778,"trace_id":"e05b798a-1e55-40ff-a30b-bd8502bf022a","first_update_id":10999771318400,"final_update_id":10999771334033,"previous_final_update_id":10999771318215,"bids":[{"price":"200.00","quantity":"7.594"},{"price":"1211.11","quantity":"2.085"},{"price":"1211.28","quantity":"1.184"},{"price":"1231.28","quantity":"6.080"},{"price":"1302.13","quantity":"0.000"},{"price":"1562.65","quantity":"0.145"},{"price":"1562.66","quantity":"3.536"},{"price":"1656.22","quantity":"0.035"},{"price":"1664.93","quantity":"0.141"},{"price":"1666.80","quantity":"0.233"},{"price":"1701.55","quantity":"15.899"},{"price":"1708.50","quantity":"91.849"},{"price":"1717.01","quantity":"318.135"},{"price":"1726.17","quantity":"2.917"},{"price":"1726.93","quantity":"106.867"},{"price":"1727.59","quantity":"0.839"},{"price":"1730.36","quantity":"5.765"},{"price":"1730.75","quantity":"10.532"},{"price":"1730.93","quantity":"16.528"},{"price":"1733.71","quantity":"84.523"},{"price":"1733.84","quantity":"14.095"},{"price":"1733.95","quantity":"4.460"},{"price":"1733.96","quantity":"4.606"},{"price":"1734.05","quantity":"116.540"},{"price":"1734.06","quantity":"27.872"},{"price":"1734.18","quantity":"425.651"},{"price":"1734.66","quantity":"1.782"},{"price":"1735.10","quantity":"16.729"},{"price":"1735.28","quantity":"4.463"},{"price":"1735.53","quantity":"10.821"},{"price":"1735.58","quantity":"4.235"},{"price":"1735.71","quantity":"5.772"},{"price":"1735.75","quantity":"75.741"},{"price":"1735.77","quantity":"227.196"},{"price":"1735.79","quantity":"7.584"},{"price":"1735.81","quantity":"4.960"},{"price":"1735.92","quantity":"34.147"},{"price":"1735.99","quantity":"2.511"},{"price":"1736.00","quantity":"20.102"},{"price":"1736.09","quantity":"1.907"},{"price":"1736.11","quantity":"134.709"},{"price":"1736.16","quantity":"0.050"},{"price":"1736.26","quantity":"0.072"},{"price":"1736.28","quantity":"183.855"}],"asks":[{"price":"1736.41","quantity":"0.093"},{"price":"1736.47","quantity":"3.094"},{"price":"1736.48","quantity":"8.433"},{"price":"1736.62","quantity":"2.748"},{"price":"1737.26","quantity":"1.944"},{"price":"1737.58","quantity":"24.163"},{"price":"1737.68","quantity":"3.403"},{"price":"1737.78","quantity":"1.355"},{"price":"1737.86","quantity":"0.621"},{"price":"1738.50","quantity":"0.298"},{"price":"1738.97","quantity":"185.116"},{"price":"1741.38","quantity":"0.707"},{"price":"1741.72","quantity":"14.205"},{"price":"1744.81","quantity":"0.142"},{"price":"1747.12","quantity":"0.000"},{"price":"1753.08","quantity":"0.069"},{"price":"1762.41","quantity":"0.000"},{"price":"1765.81","quantity":"135.732"},{"price":"1781.89","quantity":"0.000"},{"price":"2633.77","quantity":"0.001"},{"price":"2633.78","quantity":"0.071"},{"price":"2633.86","quantity":"0.000"},{"price":"2633.87","quantity":"0.000"}],"raw":{"e":"depthUpdate","E":1783517074640,"T":1783517074638,"s":"ETHUSDT","ps":"ETHUSDT","U":10999771318400,"u":10999771334033,"pu":10999771318215,"b":[["200.00","7.594"],["1211.11","2.085"],["1211.28","1.184"],["1231.28","6.080"],["1302.13","0.000"],["1562.65","0.145"],["1562.66","3.536"],["1656.22","0.035"],["1664.93","0.141"],["1666.80","0.233"],["1701.55","15.899"],["1708.50","91.849"],["1717.01","318.135"],["1726.17","2.917"],["1726.93","106.867"],["1727.59","0.839"],["1730.36","5.765"],["1730.75","10.532"],["1730.93","16.528"],["1733.71","84.523"],["1733.84","14.095"],["1733.95","4.460"],["1733.96","4.606"],["1734.05","116.540"],["1734.06","27.872"],["1734.18","425.651"],["1734.66","1.782"],["1735.10","16.729"],["1735.28","4.463"],["1735.53","10.821"],["1735.58","4.235"],["1735.71","5.772"],["1735.75","75.741"],["1735.77","227.196"],["1735.79","7.584"],["1735.81","4.960"],["1735.92","34.147"],["1735.99","2.511"],["1736.00","20.102"],["1736.09","1.907"],["1736.11","134.709"],["1736.16","0.050"],["1736.26","0.072"],["1736.28","183.855"]],"a":[["1736.41","0.093"],["1736.47","3.094"],["1736.48","8.433"],["1736.62","2.748"],["1737.26","1.944"],["1737.58","24.163"],["1737.68","3.403"],["1737.78","1.355"],["1737.86","0.621"],["1738.50","0.298"],["1738.97","185.116"],["1741.38","0.707"],["1741.72","14.205"],["1744.81","0.142"],["1747.12","0.000"],["1753.08","0.069"],["1762.41","0.000"],["1765.81","135.732"],["1781.89","0.000"],["2633.77","0.001"],["2633.78","0.071"],["2633.86","0.000"],["2633.87","0.000"]],"st":1}}
{"schema_version":"1.3.0","event_id":"63c95b9a-e39b-4dc3-8af8-1f4422eb8403","event_type":"raw.depth_update","source":"binance_market_data_recorder","venue":"binance_usdm","market_type":"perpetual_futures","symbol":"ETHUSDT","event_time_ms":1783517074742,"received_time_ms":1783517074946,"trace_id":"97d187af-ec02-4cb6-aee0-ea2f32096705","first_update_id":10999771334305,"final_update_id":10999771355358,"previous_final_update_id":10999771334033,"bids":[{"price":"200.00","quantity":"7.594"},{"price":"1211.11","quantity":"1.573"},{"price":"1211.28","quantity":"0.928"},{"price":"1226.28","quantity":"0.064"},{"price":"1231.28","quantity":"6.784"},{"price":"1562.65","quantity":"0.145"},{"price":"1562.66","quantity":"3.536"},{"price":"1608.10","quantity":"0.027"},{"price":"1666.80","quantity":"0.348"},{"price":"1701.55","quantity":"15.928"},{"price":"1709.34","quantity":"23.483"},{"price":"1709.71","quantity":"61.808"},{"price":"1710.24","quantity":"220.756"},{"price":"1727.59","quantity":"0.851"},{"price":"1728.47","quantity":"0.043"},{"price":"1729.22","quantity":"10.775"},{"price":"1730.78","quantity":"3.760"},{"price":"1731.26","quantity":"12.801"},{"price":"1732.14","quantity":"21.076"},{"price":"1733.92","quantity":"17.384"},{"price":"1734.72","quantity":"2.947"},{"price":"1735.28","quantity":"4.463"},{"price":"1735.37","quantity":"1.294"},{"price":"1735.74","quantity":"3.307"},{"price":"1735.75","quantity":"78.620"},{"price":"1735.77","quantity":"8.723"},{"price":"1735.80","quantity":"0.112"},{"price":"1735.83","quantity":"3.333"},{"price":"1735.85","quantity":"240.930"},{"price":"1735.91","quantity":"17.913"},{"price":"1735.92","quantity":"56.537"},{"price":"1735.93","quantity":"5.510"},{"price":"1736.01","quantity":"3.754"},{"price":"1736.09","quantity":"30.735"},{"price":"1736.14","quantity":"40.371"},{"price":"1736.24","quantity":"9.202"},{"price":"1736.28","quantity":"183.876"}],"asks":[{"price":"1736.47","quantity":"0.232"},{"price":"1736.48","quantity":"11.295"},{"price":"1736.52","quantity":"1.492"},{"price":"1736.54","quantity":"19.868"},{"price":"1736.56","quantity":"6.843"},{"price":"1736.57","quantity":"3.106"},{"price":"1736.59","quantity":"23.730"},{"price":"1736.61","quantity":"12.788"},{"price":"1736.65","quantity":"21.802"},{"price":"1736.66","quantity":"2.088"},{"price":"1736.68","quantity":"6.711"},{"price":"1736.70","quantity":"79.656"},{"price":"1736.72","quantity":"11.291"},{"price":"1736.81","quantity":"24.476"},{"price":"1737.10","quantity":"43.506"},{"price":"1737.77","quantity":"3.398"},{"price":"1737.78","quantity":"6.635"},{"price":"1737.79","quantity":"3.615"},{"price":"1737.82","quantity":"22.728"},{"price":"1737.85","quantity":"94.530"},{"price":"1738.20","quantity":"1.923"},{"price":"1738.50","quantity":"2.278"},{"price":"1740.09","quantity":"32.626"},{"price":"1767.49","quantity":"5.591"},{"price":"1769.24","quantity":"39.547"},{"price":"1769.46","quantity":"172.215"},{"price":"1771.24","quantity":"11.292"},{"price":"2633.76","quantity":"0.001"},{"price":"2633.85","quantity":"0.189"}],"raw":{"e":"depthUpdate","E":1783517074742,"T":1783517074741,"s":"ETHUSDT","ps":"ETHUSDT","U":10999771334305,"u":10999771355358,"pu":10999771334033,"b":[["200.00","7.594"],["1211.11","1.573"],["1211.28","0.928"],["1226.28","0.064"],["1231.28","6.784"],["1562.65","0.145"],["1562.66","3.536"],["1608.10","0.027"],["1666.80","0.348"],["1701.55","15.928"],["1709.34","23.483"],["1709.71","61.808"],["1710.24","220.756"],["1727.59","0.851"],["1728.47","0.043"],["1729.22","10.775"],["1730.78","3.760"],["1731.26","12.801"],["1732.14","21.076"],["1733.92","17.384"],["1734.72","2.947"],["1735.28","4.463"],["1735.37","1.294"],["1735.74","3.307"],["1735.75","78.620"],["1735.77","8.723"],["1735.80","0.112"],["1735.83","3.333"],["1735.85","240.930"],["1735.91","17.913"],["1735.92","56.537"],["1735.93","5.510"],["1736.01","3.754"],["1736.09","30.735"],["1736.14","40.371"],["1736.24","9.202"],["1736.28","183.876"]],"a":[["1736.47","0.232"],["1736.48","11.295"],["1736.52","1.492"],["1736.54","19.868"],["1736.56","6.843"],["1736.57","3.106"],["1736.59","23.730"],["1736.61","12.788"],["1736.65","21.802"],["1736.66","2.088"],["1736.68","6.711"],["1736.70","79.656"],["1736.72","11.291"],["1736.81","24.476"],["1737.10","43.506"],["1737.77","3.398"],["1737.78","6.635"],["1737.79","3.615"],["1737.82","22.728"],["1737.85","94.530"],["1738.20","1.923"],["1738.50","2.278"],["1740.09","32.626"],["1767.49","5.591"],["1769.24","39.547"],["1769.46","172.215"],["1771.24","11.292"],["2633.76","0.001"],["2633.85","0.189"]],"st":1}}
{"schema_version":"1.3.0","event_id":"a710edb6-4edd-4f1b-9666-db1cf2a4187a","event_type":"raw.depth_update","source":"binance_market_data_recorder","venue":"binance_usdm","market_type":"perpetual_futures","symbol":"ETHUSDT","event_time_ms":1783517074844,"received_time_ms":1783517075100,"trace_id":"ab5d9d45-82d7-4a16-886b-2ff42be4741c","first_update_id":10999771355615,"final_update_id":10999771375914,"previous_final_update_id":10999771355358,"bids":[{"price":"1211.11","quantity":"1.317"},{"price":"1211.28","quantity":"0.640"},{"price":"1226.28","quantity":"0.320"},{"price":"1231.28","quantity":"7.072"},{"price":"1562.65","quantity":"0.145"},{"price":"1562.66","quantity":"3.550"},{"price":"1666.80","quantity":"0.233"},{"price":"1698.57","quantity":"0.143"},{"price":"1701.55","quantity":"15.899"},{"price":"1714.56","quantity":"0.991"},{"price":"1715.44","quantity":"121.193"},{"price":"1720.78","quantity":"0.677"},{"price":"1732.31","quantity":"11.708"},{"price":"1734.72","quantity":"2.947"},{"price":"1735.25","quantity":"3.048"},{"price":"1735.26","quantity":"1.009"},{"price":"1735.37","quantity":"1.555"},{"price":"1735.38","quantity":"52.348"},{"price":"1735.75","quantity":"75.741"},{"price":"1735.78","quantity":"217.730"},{"price":"1735.85","quantity":"23.008"},{"price":"1735.86","quantity":"68.577"},{"price":"1735.92","quantity":"31.099"},{"price":"1735.96","quantity":"3.431"},{"price":"1736.06","quantity":"29.654"},{"price":"1736.07","quantity":"1.672"},{"price":"1736.09","quantity":"1.895"},{"price":"1736.22","quantity":"0.036"},{"price":"1736.28","quantity":"188.782"}],"asks":[{"price":"1736.29","quantity":"2.670"},{"price":"1736.48","quantity":"11.295"},{"price":"1736.56","quantity":"0.103"},{"price":"1736.57","quantity":"1.306"},{"price":"1736.58","quantity":"1.490"},{"price":"1736.59","quantity":"19.690"},{"price":"1736.60","quantity":"4.957"},{"price":"1736.61","quantity":"13.908"},{"price":"1736.62","quantity":"2.460"},{"price":"1736.63","quantity":"33.295"},{"price":"1736.64","quantity":"15.860"},{"price":"1736.65","quantity":"23.602"},{"price":"1736.66","quantity":"4.168"},{"price":"1736.69","quantity":"28.423"},{"price":"1737.11","quantity":"20.516"},{"price":"1737.13","quantity":"10.022"},{"price":"1737.14","quantity":"74.694"},{"price":"1737.18","quantity":"41.109"},{"price":"1737.29","quantity":"1.847"},{"price":"1737.79","quantity":"6.895"},{"price":"1737.80","quantity":"6.684"},{"price":"1737.83","quantity":"35.166"},{"price":"1737.86","quantity":"2.781"},{"price":"1738.48","quantity":"5.098"},{"price":"1738.50","quantity":"4.078"},{"price":"1740.26","quantity":"21.353"},{"price":"1759.58","quantity":"126.706"},{"price":"1762.79","quantity":"77.936"},{"price":"1763.46","quantity":"93.598"},{"price":"2633.74","quantity":"0.001"},{"price":"2633.75","quantity":"0.001"},{"price":"2633.83","quantity":"0.000"},{"price":"2633.84","quantity":"0.000"}],"raw":{"e":"depthUpdate","E":1783517074844,"T":1783517074843,"s":"ETHUSDT","ps":"ETHUSDT","U":10999771355615,"u":10999771375914,"pu":10999771355358,"b":[["1211.11","1.317"],["1211.28","0.640"],["1226.28","0.320"],["1231.28","7.072"],["1562.65","0.145"],["1562.66","3.550"],["1666.80","0.233"],["1698.57","0.143"],["1701.55","15.899"],["1714.56","0.991"],["1715.44","121.193"],["1720.78","0.677"],["1732.31","11.708"],["1734.72","2.947"],["1735.25","3.048"],["1735.26","1.009"],["1735.37","1.555"],["1735.38","52.348"],["1735.75","75.741"],["1735.78","217.730"],["1735.85","23.008"],["1735.86","68.577"],["1735.92","31.099"],["1735.96","3.431"],["1736.06","29.654"],["1736.07","1.672"],["1736.09","1.895"],["1736.22","0.036"],["1736.28","188.782"]],"a":[["1736.29","2.670"],["1736.48","11.295"],["1736.56","0.103"],["1736.57","1.306"],["1736.58","1.490"],["1736.59","19.690"],["1736.60","4.957"],["1736.61","13.908"],["1736.62","2.460"],["1736.63","33.295"],["1736.64","15.860"],["1736.65","23.602"],["1736.66","4.168"],["1736.69","28.423"],["1737.11","20.516"],["1737.13","10.022"],["1737.14","74.694"],["1737.18","41.109"],["1737.29","1.847"],["1737.79","6.895"],["1737.80","6.684"],["1737.83","35.166"],["1737.86","2.781"],["1738.48","5.098"],["1738.50","4.078"],["1740.26","21.353"],["1759.58","126.706"],["1762.79","77.936"],["1763.46","93.598"],["2633.74","0.001"],["2633.75","0.001"],["2633.83","0.000"],["2633.84","0.000"]],"st":1}}
{"schema_version":"1.3.0","event_id":"9390f7b2-82ec-4dda-9d83-924e108c39cf","event_type":"raw.depth_update","source":"binance_market_data_recorder","venue":"binance_usdm","market_type":"perpetual_futures","symbol":"ETHUSDT","event_time_ms":1783517074946,"received_time_ms":1783517075306,"trace_id":"ecb3920e-fdf3-4101-b4ca-1e5019e4f900","first_update_id":10999771375932,"final_update_id":10999771397751,"previous_final_update_id":10999771375914,"bids":[{"price":"200.00","quantity":"7.594"},{"price":"1211.11","quantity":"1.285"},{"price":"1211.28","quantity":"0.384"},{"price":"1226.28","quantity":"0.416"},{"price":"1226.29","quantity":"0.465"},{"price":"1231.28","quantity":"6.624"},{"price":"1231.29","quantity":"0.192"},{"price":"1236.28","quantity":"0.020"},{"price":"1562.38","quantity":"0.240"},{"price":"1562.65","quantity":"0.119"},{"price":"1562.66","quantity":"0.376"},{"price":"1562.67","quantity":"4.670"},{"price":"1636.06","quantity":"0.020"},{"price":"1636.07","quantity":"0.000"},{"price":"1636.29","quantity":"0.040"},{"price":"1666.80","quantity":"0.348"},{"price":"1693.58","quantity":"200.867"},{"price":"1701.52","quantity":"20.727"},{"price":"1701.55","quantity":"15.928"},{"price":"1705.75","quantity":"58.547"},{"price":"1709.19","quantity":"36.310"},{"price":"1731.60","quantity":"38.663"},{"price":"1731.73","quantity":"29.196"},{"price":"1732.27","quantity":"2.687"},{"price":"1732.50","quantity":"43.283"},{"price":"1732.77","quantity":"80.609"},{"price":"1732.78","quantity":"4.644"},{"price":"1733.03","quantity":"67.546"},{"price":"1733.14","quantity":"12.542"},{"price":"1733.71","quantity":"84.523"},{"price":"1733.76","quantity":"35.199"},{"price":"1734.01","quantity":"17.457"},{"price":"1734.05","quantity":"113.344"},{"price":"1734.06","quantity":"26.426"},{"price":"1734.07","quantity":"2.780"},{"price":"1734.10","quantity":"68.261"},{"price":"1734.13","quantity":"6.363"},{"price":"1734.18","quantity":"425.651"},{"price":"1734.19","quantity":"6.749"},{"price":"1734.21","quantity":"35.360"},{"price":"1734.40","quantity":"0.044"},{"price":"1734.72","quantity":"2.933"},{"price":"1734.73","quantity":"96.318"},{"price":"1734.82","quantity":"20.495"},{"price":"1734.86","quantity":"38.363"},{"price":"1734.93","quantity":"68.243"},{"price":"1734.94","quantity":"36.814"},{"price":"1735.02","quantity":"49.970"},{"price":"1735.03","quantity":"0.123"},{"price":"1735.04","quantity":"2.119"},{"price":"1735.06","quantity":"1.012"},{"price":"1735.07","quantity":"5.605"},{"price":"1735.08","quantity":"5.456"},{"price":"1735.10","quantity":"19.176"},{"price":"1735.13","quantity":"0.399"},{"price":"1735.14","quantity":"9.889"},{"price":"1735.15","quantity":"4.274"},{"price":"1735.28","quantity":"4.448"},{"price":"1735.29","quantity":"29.649"},{"price":"1735.34","quantity":"1.024"},{"price":"1735.40","quantity":"3.818"},{"price":"1735.47","quantity":"16.848"},{"price":"1735.48","quantity":"0.977"},{"price":"1735.52","quantity":"94.180"},{"price":"1735.58","quantity":"0.324"},{"price":"1735.72","quantity":"2.407"},{"price":"1735.75","quantity":"75.841"},{"price":"1735.77","quantity":"8.705"},{"price":"1735.78","quantity":"0.028"},{"price":"1735.79","quantity":"7.602"},{"price":"1735.80","quantity":"217.346"},{"price":"1735.81","quantity":"4.960"},{"price":"1735.85","quantity":"22.945"},{"price":"1735.86","quantity":"68.640"},{"price":"1735.87","quantity":"0.977"},{"price":"1735.88","quantity":"0.054"},{"price":"1735.89","quantity":"0.986"},{"price":"1735.91","quantity":"19.613"},{"price":"1735.92","quantity":"31.099"},{"price":"1735.94","quantity":"23.244"},{"price":"1735.96","quantity":"0.552"},{"price":"1736.07","quantity":"1.660"},{"price":"1736.08","quantity":"7.060"},{"price":"1736.10","quantity":"10.386"},{"price":"1736.11","quantity":"134.190"},{"price":"1736.15","quantity":"19.500"},{"price":"1736.20","quantity":"2.897"},{"price":"1736.23","quantity":"8.670"},{"price":"1736.24","quantity":"1.555"},{"price":"1736.25","quantity":"2.771"},{"price":"1736.26","quantity":"0.070"},{"price":"1736.27","quantity":"2.432"},{"price":"1736.28","quantity":"9.159"},{"price":"1736.29","quantity":"326.537"}],"asks":[{"price":"1736.29","quantity":"0.000"},{"price":"1736.30","quantity":"3.013"},{"price":"1736.31","quantity":"17.316"},{"price":"1736.32","quantity":"0.081"},{"price":"1736.34","quantity":"0.120"},{"price":"1736.44","quantity":"1.484"},{"price":"1736.45","quantity":"22.237"},{"price":"1736.47","quantity":"0.247"},{"price":"1736.48","quantity":"8.433"},{"price":"1736.49","quantity":"37.402"},{"price":"1736.53","quantity":"2.771"},{"price":"1736.58","quantity":"1.408"},{"price":"1736.61","quantity":"13.425"},{"price":"1736.63","quantity":"28.919"},{"price":"1736.64","quantity":"12.892"},{"price":"1736.66","quantity":"6.408"},{"price":"1736.67","quantity":"4.102"},{"price":"1736.68","quantity":"8.411"},{"price":"1736.76","quantity":"10.627"},{"price":"1736.78","quantity":"24.461"},{"price":"1736.81","quantity":"38.776"},{"price":"1736.84","quantity":"5.367"},{"price":"1736.85","quantity":"67.690"},{"price":"1736.92","quantity":"10.579"},{"price":"1737.00","quantity":"60.847"},{"price":"1737.03","quantity":"16.432"},{"price":"1737.04","quantity":"30.459"},{"price":"1737.07","quantity":"0.703"},{"price":"1737.09","quantity":"24.109"},{"price":"1737.11","quantity":"16.916"},{"price":"1737.12","quantity":"1.496"},{"price":"1737.14","quantity":"72.714"},{"price":"1737.17","quantity":"5.840"},{"price":"1737.18","quantity":"39.666"},{"price":"1737.20","quantity":"29.499"},{"price":"1737.26","quantity":"1.364"},{"price":"1737.28","quantity":"0.141"},{"price":"1737.30","quantity":"0.780"},{"price":"1737.31","quantity":"8.707"},{"price":"1737.32","quantity":"1.295"},{"price":"1737.36","quantity":"68.335"},{"price":"1737.38","quantity":"88.990"},{"price":"1737.39","quantity":"0.256"},{"price":"1737.40","quantity":"36.339"},{"price":"1737.45","quantity":"49.293"},{"price":"1737.50","quantity":"137.761"},{"price":"1737.54","quantity":"3.318"},{"price":"1737.56","quantity":"87.606"},{"price":"1737.65","quantity":"1.480"},{"price":"1737.69","quantity":"4.763"},{"price":"1737.73","quantity":"4.339"},{"price":"1737.77","quantity":"0.758"},{"price":"1737.78","quantity":"6.635"},{"price":"1737.81","quantity":"33.908"},{"price":"1737.83","quantity":"33.086"},{"price":"1737.84","quantity":"10.614"},{"price":"1737.86","quantity":"19.457"},{"price":"1738.15","quantity":"40.853"},{"price":"1738.17","quantity":"7.695"},{"price":"1738.20","quantity":"1.905"},{"price":"1738.21","quantity":"10.828"},{"price":"1738.25","quantity":"2.878"},{"price":"1738.47","quantity":"57.893"},{"price":"1738.49","quantity":"428.848"},{"price":"1738.52","quantity":"1.603"},{"price":"1738.78","quantity":"4.109"},{"price":"1738.89","quantity":"56.491"},{"price":"1738.94","quantity":"3.902"},{"price":"1738.95","quantity":"12.657"},{"price":"1738.96","quantity":"3.196"},{"price":"1738.98","quantity":"40.552"},{"price":"1738.99","quantity":"159.773"},{"price":"1739.00","quantity":"2.893"},{"price":"1739.05","quantity":"0.096"},{"price":"1739.06","quantity":"5.256"},{"price":"1739.08","quantity":"13.193"},{"price":"1739.09","quantity":"0.939"},{"price":"1739.22","quantity":"1.327"},{"price":"1739.38","quantity":"14.909"},{"price":"1739.99","quantity":"24.173"},{"price":"1740.07","quantity":"0.255"},{"price":"1740.38","quantity":"0.012"},{"price":"1740.51","quantity":"55.132"},{"price":"1740.94","quantity":"0.075"},{"price":"1742.49","quantity":"165.532"},{"price":"1746.53","quantity":"0.000"},{"price":"1746.72","quantity":"1.182"},{"price":"1747.12","quantity":"15.000"},{"price":"1753.48","quantity":"1.640"},{"price":"1757.11","quantity":"0.000"},{"price":"1759.61","quantity":"0.118"},{"price":"1768.41","quantity":"11.293"},{"price":"1779.70","quantity":"34.251"},{"price":"1836.33","quantity":"0.450"},{"price":"2633.72","quantity":"0.001"},{"price":"2633.73","quantity":"0.047"},{"price":"2633.81","quantity":"0.000"},{"price":"2633.82","quantity":"0.000"}],"raw":{"e":"depthUpdate","E":1783517074946,"T":1783517074945,"s":"ETHUSDT","ps":"ETHUSDT","U":10999771375932,"u":10999771397751,"pu":10999771375914,"b":[["200.00","7.594"],["1211.11","1.285"],["1211.28","0.384"],["1226.28","0.416"],["1226.29","0.465"],["1231.28","6.624"],["1231.29","0.192"],["1236.28","0.020"],["1562.38","0.240"],["1562.65","0.119"],["1562.66","0.376"],["1562.67","4.670"],["1636.06","0.020"],["1636.07","0.000"],["1636.29","0.040"],["1666.80","0.348"],["1693.58","200.867"],["1701.52","20.727"],["1701.55","15.928"],["1705.75","58.547"],["1709.19","36.310"],["1731.60","38.663"],["1731.73","29.196"],["1732.27","2.687"],["1732.50","43.283"],["1732.77","80.609"],["1732.78","4.644"],["1733.03","67.546"],["1733.14","12.542"],["1733.71","84.523"],["1733.76","35.199"],["1734.01","17.457"],["1734.05","113.344"],["1734.06","26.426"],["1734.07","2.780"],["1734.10","68.261"],["1734.13","6.363"],["1734.18","425.651"],["1734.19","6.749"],["1734.21","35.360"],["1734.40","0.044"],["1734.72","2.933"],["1734.73","96.318"],["1734.82","20.495"],["1734.86","38.363"],["1734.93","68.243"],["1734.94","36.814"],["1735.02","49.970"],["1735.03","0.123"],["1735.04","2.119"],["1735.06","1.012"],["1735.07","5.605"],["1735.08","5.456"],["1735.10","19.176"],["1735.13","0.399"],["1735.14","9.889"],["1735.15","4.274"],["1735.28","4.448"],["1735.29","29.649"],["1735.34","1.024"],["1735.40","3.818"],["1735.47","16.848"],["1735.48","0.977"],["1735.52","94.180"],["1735.58","0.324"],["1735.72","2.407"],["1735.75","75.841"],["1735.77","8.705"],["1735.78","0.028"],["1735.79","7.602"],["1735.80","217.346"],["1735.81","4.960"],["1735.85","22.945"],["1735.86","68.640"],["1735.87","0.977"],["1735.88","0.054"],["1735.89","0.986"],["1735.91","19.613"],["1735.92","31.099"],["1735.94","23.244"],["1735.96","0.552"],["1736.07","1.660"],["1736.08","7.060"],["1736.10","10.386"],["1736.11","134.190"],["1736.15","19.500"],["1736.20","2.897"],["1736.23","8.670"],["1736.24","1.555"],["1736.25","2.771"],["1736.26","0.070"],["1736.27","2.432"],["1736.28","9.159"],["1736.29","326.537"]],"a":[["1736.29","0.000"],["1736.30","3.013"],["1736.31","17.316"],["1736.32","0.081"],["1736.34","0.120"],["1736.44","1.484"],["1736.45","22.237"],["1736.47","0.247"],["1736.48","8.433"],["1736.49","37.402"],["1736.53","2.771"],["1736.58","1.408"],["1736.61","13.425"],["1736.63","28.919"],["1736.64","12.892"],["1736.66","6.408"],["1736.67","4.102"],["1736.68","8.411"],["1736.76","10.627"],["1736.78","24.461"],["1736.81","38.776"],["1736.84","5.367"],["1736.85","67.690"],["1736.92","10.579"],["1737.00","60.847"],["1737.03","16.432"],["1737.04","30.459"],["1737.07","0.703"],["1737.09","24.109"],["1737.11","16.916"],["1737.12","1.496"],["1737.14","72.714"],["1737.17","5.840"],["1737.18","39.666"],["1737.20","29.499"],["1737.26","1.364"],["1737.28","0.141"],["1737.30","0.780"],["1737.31","8.707"],["1737.32","1.295"],["1737.36","68.335"],["1737.38","88.990"],["1737.39","0.256"],["1737.40","36.339"],["1737.45","49.293"],["1737.50","137.761"],["1737.54","3.318"],["1737.56","87.606"],["1737.65","1.480"],["1737.69","4.763"],["1737.73","4.339"],["1737.77","0.758"],["1737.78","6.635"],["1737.81","33.908"],["1737.83","33.086"],["1737.84","10.614"],["1737.86","19.457"],["1738.15","40.853"],["1738.17","7.695"],["1738.20","1.905"],["1738.21","10.828"],["1738.25","2.878"],["1738.47","57.893"],["1738.49","428.848"],["1738.52","1.603"],["1738.78","4.109"],["1738.89","56.491"],["1738.94","3.902"],["1738.95","12.657"],["1738.96","3.196"],["1738.98","40.552"],["1738.99","159.773"],["1739.00","2.893"],["1739.05","0.096"],["1739.06","5.256"],["1739.08","13.193"],["1739.09","0.939"],["1739.22","1.327"],["1739.38","14.909"],["1739.99","24.173"],["1740.07","0.255"],["1740.38","0.012"],["1740.51","55.132"],["1740.94","0.075"],["1742.49","165.532"],["1746.53","0.000"],["1746.72","1.182"],["1747.12","15.000"],["1753.48","1.640"],["1757.11","0.000"],["1759.61","0.118"],["1768.41","11.293"],["1779.70","34.251"],["1836.33","0.450"],["2633.72","0.001"],["2633.73","0.047"],["2633.81","0.000"],["2633.82","0.000"]],"st":1}}
