{"schema_version":"1.3.0","event_id":"1941f85d-41d9-42d0-aaf3-567fc48fdabe","event_type":"raw.depth_update","source":"binance_market_data_recorder","venue":"binance_usdm","market_type":"perpetual_futures","symbol":"ETHUSDT","event_time_ms":1783517064722,"received_time_ms":1783517064847,"trace_id":"1d5244e4-079a-404b-ab15-f332682f0a66","first_update_id":10999770325756,"final_update_id":10999770337339,"previous_final_update_id":10999770325378,"bids":[{"price":"200.00","quantity":"7.594"},{"price":"1221.16","quantity":"3.936"},{"price":"1226.12","quantity":"2.304"},{"price":"1226.16","quantity":"3.232"},{"price":"1231.12","quantity":"0.096"},{"price":"1562.20","quantity":"2.061"},{"price":"1562.54","quantity":"0.212"},{"price":"1562.55","quantity":"3.315"},{"price":"1664.00","quantity":"1634.980"},{"price":"1666.70","quantity":"0.825"},{"price":"1684.56","quantity":"127.483"},{"price":"1700.40","quantity":"29.731"},{"price":"1701.44","quantity":"50.079"},{"price":"1710.10","quantity":"46.767"},{"price":"1718.79","quantity":"59.185"},{"price":"1730.07","quantity":"135.828"},{"price":"1730.08","quantity":"26.320"},{"price":"1730.09","quantity":"4.351"},{"price":"1732.11","quantity":"4.445"},{"price":"1733.50","quantity":"15.160"},{"price":"1733.94","quantity":"427.279"},{"price":"1733.95","quantity":"5.388"},{"price":"1734.00","quantity":"215.521"},{"price":"1734.05","quantity":"13.575"},{"price":"1734.18","quantity":"0.012"},{"price":"1734.22","quantity":"17.048"},{"price":"1734.54","quantity":"13.457"},{"price":"1735.16","quantity":"3.810"},{"price":"1735.74","quantity":"247.263"},{"price":"1735.80","quantity":"0.118"},{"price":"1735.83","quantity":"47.595"},{"price":"1735.85","quantity":"7.428"},{"price":"1735.94","quantity":"35.092"},{"price":"1735.97","quantity":"7.513"},{"price":"1736.09","quantity":"13.444"},{"price":"1736.11","quantity":"1.178"},{"price":"1736.12","quantity":"24.913"},{"price":"1736.14","quantity":"71.818"},{"price":"1736.16","quantity":"439.072"}],"asks":[{"price":"1736.17","quantity":"16.536"},{"price":"1736.21","quantity":"3.121"},{"price":"1736.36","quantity":"1.740"},{"price":"1736.43","quantity":"10.243"},{"price":"1736.76","quantity":"43.509"},{"price":"1736.85","quantity":"0.458"},{"price":"1736.94","quantity":"19.186"},{"price":"1737.00","quantity":"97.908"},{"price":"1737.09","quantity":"24.470"},{"price":"1737.11","quantity":"23.216"},{"price":"1737.26","quantity":"2.255"},{"price":"1737.29","quantity":"1.832"},{"price":"1737.44","quantity":"49.160"},{"price":"1737.46","quantity":"8.656"},{"price":"1737.61","quantity":"10.732"},{"price":"1737.63","quantity":"0.093"},{"price":"1737.73","quantity":"4.121"},{"price":"1737.78","quantity":"3.890"},{"price":"1738.08","quantity":"411.967"},{"price":"1738.78","quantity":"3.752"},{"price":"1738.89","quantity":"56.491"},{"price":"1738.98","quantity":"43.816"},{"price":"1740.25","quantity":"4.091"},{"price":"1750.81","quantity":"0.003"},{"price":"2635.25","quantity":"0.004"},{"price":"2635.26","quantity":"0.001"},{"price":"2635.34","quantity":"0.000"},{"price":"2635.35","quantity":"0.150"}],"raw":{"e":"depthUpdate","E":1783517064722,"T":1783517064721,"s":"ETHUSDT","ps":"ETHUSDT","U":10999770325756,"u":10999770337339,"pu":10999770325378,"b":[["200.00","7.594"],["1221.16","3.936"],["1226.12","2.304"],["1226.16","3.232"],["1231.12","0.096"],["1562.20","2.061"],["1562.54","0.212"],["1562.55","3.315"],["1664.00","1634.980"],["1666.70","0.825"],["1684.56","127.483"],["1700.40","29.731"],["1701.44","50.079"],["1710.10","46.767"],["1718.79","59.185"],["1730.07","135.828"],["1730.08","26.320"],["1730.09","4.351"],["1732.11","4.445"],["1733.50","15.160"],["1733.94","427.279"],["1733.95","5.388"],["1734.00","215.521"],["1734.05","13.575"],["1734.18","0.012"],["1734.22","17.048"],["1734.54","13.457"],["1735.16","3.810"],["1735.74","247.263"],["1735.80","0.118"],["1735.83","47.595"],["1735.85","7.428"],["1735.94","35.092"],["1735.97","7.513"],["1736.09","13.444"],["1736.11","1.178"],["1736.12","24.913"],["1736.14","71.818"],["1736.16","439.072"]],"a":[["1736.17","16.536"],["1736.21","3.121"],["1736.36","1.740"],["1736.43","10.243"],["1736.76","43.509"],["1736.85","0.458"],["1736.94","19.186"],["1737.00","97.908"],["1737.09","24.470"],["1737.11","23.216"],["1737.26","2.255"],["1737.29","1.832"],["1737.44","49.160"],["1737.46","8.656"],["1737.61","10.732"],["1737.63","0.093"],["1737.73","4.121"],["1737.78","3.890"],["1738.08","411.967"],["1738.78","3.752"],["1738.89","56.491"],["1738.98","43.816"],["1740.25","4.091"],["1750.81","0.003"],["2635.25","0.004"],["2635.26","0.001"],["2635.34","0.000"],["2635.35","0.150"]],"st":1}}
{"schema_version":"1.3.0","event_id":"fd3cefd6-8101-47c5-84d7-189d64d1deed","event_type":"raw.depth_update","source":"binance_market_data_recorder","venue":"binance_usdm","market_type":"perpetual_futures","symbol":"ETHUSDT","event_time_ms":1783517064824,"received_time_ms":1783517064862,"trace_id":"a5a31175-43a5-447d-87f6-2850843fe749","first_update_id":10999770337415,"final_update_id":10999770346741,"previous_final_update_id":10999770337339,"bids":[{"price":"200.00","quantity":"7.594"},{"price":"1221.16","quantity":"4.640"},{"price":"1226.12","quantity":"1.952"},{"price":"1226.13","quantity":"1.032"},{"price":"1226.16","quantity":"3.008"},{"price":"1231.12","quantity":"0.000"},{"price":"1562.20","quantity":"2.047"},{"price":"1562.54","quantity":"0.212"},{"price":"1562.55","quantity":"3.315"},{"price":"1666.70","quantity":"0.940"},{"price":"1701.44","quantity":"50.050"},{"price":"1708.89","quantity":"45.438"},{"price":"1710.82","quantity":"0.062"},{"price":"1732.11","quantity":"1.445"},{"price":"1732.50","quantity":"88.354"},{"price":"1732.69","quantity":"172.912"},{"price":"1733.04","quantity":"3.838"},{"price":"1733.12","quantity":"124.290"},{"price":"1733.13","quantity":"30.189"},{"price":"1733.50","quantity":"18.160"},{"price":"1733.94","quantity":"1.165"},{"price":"1733.95","quantity":"430.056"},{"price":"1734.00","quantity":"214.075"},{"price":"1734.01","quantity":"23.213"},{"price":"1734.03","quantity":"170.423"},{"price":"1734.05","quantity":"15.021"},{"price":"1734.18","quantity":"0.012"},{"price":"1734.23","quantity":"60.276"},{"price":"1735.01","quantity":"54.012"},{"price":"1735.09","quantity":"17.366"},{"price":"1735.45","quantity":"4.024"},{"price":"1735.48","quantity":"11.851"},{"price":"1735.60","quantity":"0.172"},{"price":"1735.74","quantity":"27.064"},{"price":"1735.82","quantity":"0.122"},{"price":"1735.83","quantity":"16.585"},{"price":"1735.85","quantity":"7.446"},{"price":"1735.86","quantity":"231.832"},{"price":"1735.90","quantity":"70.314"},{"price":"1735.91","quantity":"55.166"},{"price":"1736.16","quantity":"431.935"}],"asks":[{"price":"1736.17","quantity":"16.467"},{"price":"1736.21","quantity":"3.122"},{"price":"1737.00","quantity":"98.260"},{"price":"1737.12","quantity":"15.689"},{"price":"1737.15","quantity":"2.125"},{"price":"1737.26","quantity":"4.988"},{"price":"1737.49","quantity":"37.659"},{"price":"1737.69","quantity":"27.641"},{"price":"1737.73","quantity":"1.481"},{"price":"1738.11","quantity":"0.039"},{"price":"1738.13","quantity":"19.864"},{"price":"1738.47","quantity":"91.217"},{"price":"1738.80","quantity":"7.999"},{"price":"1738.97","quantity":"185.102"},{"price":"1739.70","quantity":"9.432"},{"price":"1740.24","quantity":"50.385"},{"price":"1740.97","quantity":"29.654"},{"price":"1743.21","quantity":"13.846"},{"price":"1743.22","quantity":"32.514"},{"price":"1744.38","quantity":"3.339"},{"price":"1747.12","quantity":"37.204"},{"price":"1747.76","quantity":"9.171"},{"price":"1751.20","quantity":"5.890"},{"price":"1756.61","quantity":"196.948"},{"price":"1787.39","quantity":"50.312"},{"price":"2635.23","quantity":"0.001"},{"price":"2635.24","quantity":"0.001"},{"price":"2635.32","quantity":"0.000"},{"price":"2635.33","quantity":"0.000"}],"raw":{"e":"depthUpdate","E":1783517064824,"T":1783517064823,"s":"ETHUSDT","ps":"ETHUSDT","U":10999770337415,"u":10999770346741,"pu":10999770337339,"b":[["200.00","7.594"],["1221.16","4.640"],["1226.12","1.952"],["1226.13","1.032"],["1226.16","3.008"],["1231.12","0.000"],["1562.20","2.047"],["1562.54","0.212"],["1562.55","3.315"],["1666.70","0.940"],["1701.44","50.050"],["1708.89","45.438"],["1710.82","0.062"],["1732.11","1.445"],["1732.50","88.354"],["1732.69","172.912"],["1733.04","3.838"],["1733.12","124.290"],["1733.13","30.189"],["1733.50","18.160"],["1733.94","1.165"],["1733.95","430.056"],["1734.00","214.075"],["1734.01","23.213"],["1734.03","170.423"],["1734.05","15.021"],["1734.18","0.012"],["1734.23","60.276"],["1735.01","54.012"],["1735.09","17.366"],["1735.45","4.024"],["1735.48","11.851"],["1735.60","0.172"],["1735.74","27.064"],["1735.82","0.122"],["1735.83","16.585"],["1735.85","7.446"],["1735.86","231.832"],["1735.90","70.314"],["1735.91","55.166"],["1736.16","431.935"]],"a":[["1736.17","16.467"],["1736.21","3.122"],["1737.00","98.260"],["1737.12","15.689"],["1737.15","2.125"],["1737.26","4.988"],["1737.49","37.659"],["1737.69","27.641"],["1737.73","1.481"],["1738.11","0.039"],["1738.13","19.864"],["1738.47","91.217"],["1738.80","7.999"],["1738.97","185.102"],["1739.70","9.432"],["1740.24","50.385"],["1740.97","29.654"],["1743.21","13.846"],["1743.22","32.514"],["1744.38","3.339"],["1747.12","37.204"],["1747.76","9.171"],["1751.20","5.890"],["1756.61","196.948"],["1787.39","50.312"],["2635.23","0.001"],["2635.24","0.001"],["2635.32","0.000"],["2635.33","0.000"]],"st":1}}
{"schema_version":"1.3.0","event_id":"e23863d9-820c-4fb7-8ac2-f7a8f51c92e8","event_type":"raw.depth_update","source":"binance_market_data_recorder","venue":"binance_usdm","market_type":"perpetual_futures","symbol":"ETHUSDT","event_time_ms":1783517064926,"received_time_ms":1783517065028,"trace_id":"d901460f-0f16-40e7-930f-8513e9428c19","first_update_id":10999770346768,"final_update_id":10999770354008,"previous_final_update_id":10999770346741,"bids":[{"price":"1221.16","quantity":"5.472"},{"price":"1226.12","quantity":"1.376"},{"price":"1226.16","quantity":"2.752"},{"price":"1562.54","quantity":"0.212"},{"price":"1562.55","quantity":"3.187"},{"price":"1684.94","quantity":"80.159"},{"price":"1705.75","quantity":"58.547"},{"price":"1710.29","quantity":"90.674"},{"price":"1714.42","quantity":"34.373"},{"price":"1715.00","quantity":"1024.454"},{"price":"1730.81","quantity":"19.773"},{"price":"1735.48","quantity":"8.972"},{"price":"1735.68","quantity":"18.139"},{"price":"1736.02","quantity":"2.398"},{"price":"1736.16","quantity":"439.095"}],"asks":[{"price":"1736.36","quantity":"1.740"},{"price":"1736.74","quantity":"0.062"},{"price":"1737.17","quantity":"1.620"},{"price":"1741.65","quantity":"15.319"},{"price":"1741.67","quantity":"0.013"},{"price":"1763.25","quantity":"111.485"},{"price":"1763.30","quantity":"63.431"},{"price":"1763.43","quantity":"0.026"},{"price":"1766.35","quantity":"18.079"},{"price":"1767.02","quantity":"98.467"},{"price":"2635.22","quantity":"0.001"},{"price":"2635.31","quantity":"0.000"}],"raw":{"e":"depthUpdate","E":1783517064926,"T":1783517064925,"s":"ETHUSDT","ps":"ETHUSDT","U":10999770346768,"u":10999770354008,"pu":10999770346741,"b":[["1221.16","5.472"],["1226.12","1.376"],["1226.16","2.752"],["1562.54","0.212"],["1562.55","3.187"],["1684.94","80.159"],["1705.75","58.547"],["1710.29","90.674"],["1714.42","34.373"],["1715.00","1024.454"],["1730.81","19.773"],["1735.48","8.972"],["1735.68","18.139"],["1736.02","2.398"],["1736.16","439.095"]],"a":[["1736.36","1.740"],["1736.74","0.062"],["1737.17","1.620"],["1741.65","15.319"],["1741.67","0.013"],["1763.25","111.485"],["1763.30","63.431"],["1763.43","0.026"],["1766.35","18.079"],["1767.02","98.467"],["2635.22","0.001"],["2635.31","0.000"]],"st":1}}
{"schema_version":"1.3.0","event_id":"ae0b4846-9c42-4904-9332-eefa124255ee","event_type":"raw.depth_update","source":"binance_market_data_recorder","venue":"binance_usdm","market_type":"perpetual_futures","symbol":"ETHUSDT","event_time_ms":1783517065028,"received_time_ms":1783517065050,"trace_id":"e70d106f-a5e7-48a6-b01c-3815a638e423","first_update_id":10999770354074,"final_update_id":10999770364171,"previous_final_update_id":10999770354008,"bids":[{"price":"200.00","quantity":"7.594"},{"price":"1221.16","quantity":"6.272"},{"price":"1226.12","quantity":"0.864"},{"price":"1226.16","quantity":"2.464"},{"price":"1562.54","quantity":"0.212"},{"price":"1562.55","quantity":"3.201"},{"price":"1666.70","quantity":"0.825"},{"price":"1684.56","quantity":"100.806"},{"price":"1700.57","quantity":"61.745"},{"price":"1701.44","quantity":"50.079"},{"price":"1706.13","quantity":"40.974"},{"price":"1729.79","quantity":"27.356"},{"price":"1729.95","quantity":"17.689"},{"price":"1730.81","quantity":"19.847"},{"price":"1733.95","quantity":"3.942"},{"price":"1734.01","quantity":"21.767"},{"price":"1734.03","quantity":"111.557"},{"price":"1734.18","quantity":"426.126"},{"price":"1735.16","quantity":"3.810"},{"price":"1735.24","quantity":"1.449"},{"price":"1735.25","quantity":"1.011"},{"price":"1735.26","quantity":"0.123"},{"price":"1735.65","quantity":"19.245"},{"price":"1735.68","quantity":"235.752"},{"price":"1735.73","quantity":"34.593"},{"price":"1735.74","quantity":"58.687"},{"price":"1735.75","quantity":"73.010"},{"price":"1735.86","quantity":"11.574"},{"price":"1735.91","quantity":"18.473"},{"price":"1736.04","quantity":"8.424"},{"price":"1736.16","quantity":"431.883"}],"asks":[{"price":"1736.17","quantity":"27.281"},{"price":"1736.19","quantity":"2.607"},{"price":"1736.27","quantity":"0.059"},{"price":"1736.28","quantity":"1.083"},{"price":"1736.33","quantity":"1.752"},{"price":"1736.37","quantity":"21.093"},{"price":"1736.57","quantity":"12.657"},{"price":"1736.60","quantity":"3.462"},{"price":"1736.61","quantity":"6.517"},{"price":"1736.66","quantity":"67.370"},{"price":"1736.80","quantity":"8.903"},{"price":"1736.82","quantity":"19.064"},{"price":"1736.93","quantity":"33.071"},{"price":"1736.94","quantity":"19.174"},{"price":"1737.06","quantity":"26.658"},{"price":"1737.07","quantity":"7.497"},{"price":"1737.09","quantity":"35.632"},{"price":"1737.12","quantity":"13.995"},{"price":"1737.21","quantity":"3.524"},{"price":"1737.22","quantity":"3.552"},{"price":"1737.65","quantity":"4.106"},{"price":"1737.82","quantity":"16.693"},{"price":"1737.89","quantity":"33.500"},{"price":"1738.96","quantity":"3.196"},{"price":"1738.98","quantity":"40.620"},{"price":"1741.65","quantity":"15.319"},{"price":"1742.27","quantity":"3.761"},{"price":"1742.50","quantity":"9.733"},{"price":"1753.49","quantity":"0.413"},{"price":"1755.00","quantity":"590.178"},{"price":"1760.00","quantity":"903.543"},{"price":"1763.25","quantity":"91.834"},{"price":"2635.20","quantity":"0.016"},{"price":"2635.21","quantity":"0.001"},{"price":"2635.29","quantity":"0.000"},{"price":"2635.30","quantity":"0.016"}],"raw":{"e":"depthUpdate","E":1783517065028,"T":1783517065025,"s":"ETHUSDT","ps":"ETHUSDT","U":10999770354074,"u":10999770364171,"pu":10999770354008,"b":[["200.00","7.594"],["1221.16","6.272"],["1226.12","0.864"],["1226.16","2.464"],["1562.54","0.212"],["1562.55","3.201"],["1666.70","0.825"],["1684.56","100.806"],["1700.57","61.745"],["1701.44","50.079"],["1706.13","40.974"],["1729.79","27.356"],["1729.95","17.689"],["1730.81","19.847"],["1733.95","3.942"],["1734.01","21.767"],["1734.03","111.557"],["1734.18","426.126"],["1735.16","3.810"],["1735.24","1.449"],["1735.25","1.011"],["1735.26","0.123"],["1735.65","19.245"],["1735.68","235.752"],["1735.73","34.593"],["1735.74","58.687"],["1735.75","73.010"],["1735.86","11.574"],["1735.91","18.473"],["1736.04","8.424"],["1736.16","431.883"]],"a":[["1736.17","27.281"],["1736.19","2.607"],["1736.27","0.059"],["1736.28","1.083"],["1736.33","1.752"],["1736.37","21.093"],["1736.57","12.657"],["1736.60","3.462"],["1736.61","6.517"],["1736.66","67.370"],["1736.80","8.903"],["1736.82","19.064"],["1736.93","33.071"],["1736.94","19.174"],["1737.06","26.658"],["1737.07","7.497"],["1737.09","35.632"],["1737.12","13.995"],["1737.21","3.524"],["1737.22","3.552"],["1737.65","4.106"],["1737.82","16.693"],["1737.89","33.500"],["1738.96","3.196"],["1738.98","40.620"],["1741.65","15.319"],["1742.27","3.761"],["1742.50","9.733"],["1753.49","0.413"],["1755.00","590.178"],["1760.00","903.543"],["1763.25","91.834"],["2635.20","0.016"],["2635.21","0.001"],["2635.29","0.000"],["2635.30","0.016"]],"st":1}}
{"schema_version":"1.3.0","event_id":"f82a38be-284e-40a3-9846-8138f9c27211","event_type":"raw.depth_update","source":"binance_market_data_recorder","venue":"binance_usdm","market_type":"perpetual_futures","symbol":"ETHUSDT","event_time_ms":1783517065130,"received_time_ms":1783517065124,"trace_id":"f1b411fa-bc10-491e-9436-348b5fa6baab","first_update_id":10999770364652,"final_update_id":10999770372895,"previous_final_update_id":10999770364171,"bids":[{"price":"200.00","quantity":"7.594"},{"price":"1216.16","quantity":"0.032"},{"price":"1221.16","quantity":"7.040"},{"price":"1226.12","quantity":"0.320"},{"price":"1226.16","quantity":"2.208"},{"price":"1562.54","quantity":"0.212"},{"price":"1562.55","quantity":"3.329"},{"price":"1666.70","quantity":"0.940"},{"price":"1701.44","quantity":"50.050"},{"price":"1704.74","quantity":"0.416"},{"price":"1718.06","quantity":"17.342"},{"price":"1727.47","quantity":"0.012"},{"price":"1734.06","quantity":"55.627"},{"price":"1735.47","quantity":"229.898"},{"price":"1735.68","quantity":"15.278"},{"price":"1735.74","quantity":"27.064"},{"price":"1735.75","quantity":"70.131"},{"price":"1735.81","quantity":"9.313"},{"price":"1735.96","quantity":"6.464"},{"price":"1736.08","quantity":"2.058"},{"price":"1736.09","quantity":"13.432"},{"price":"1736.12","quantity":"25.113"},{"price":"1736.13","quantity":"7.553"},{"price":"1736.16","quantity":"416.626"}],"asks":[{"price":"1736.17","quantity":"36.439"},{"price":"1736.51","quantity":"19.904"},{"price":"1736.52","quantity":"26.302"},{"price":"1736.57","quantity":"10.963"},{"price":"1736.60","quantity":"1.768"},{"price":"1736.65","quantity":"29.063"},{"price":"1737.15","quantity":"0.431"},{"price":"1737.17","quantity":"1.620"},{"price":"1737.34","quantity":"14.909"},{"price":"1738.06","quantity":"81.219"},{"price":"1738.08","quantity":"410.300"},{"price":"1739.30","quantity":"5.271"},{"price":"1739.80","quantity":"5.290"},{"price":"1744.86","quantity":"40.385"},{"price":"1747.12","quantity":"52.204"},{"price":"1761.73","quantity":"0.078"},{"price":"2635.19","quantity":"0.001"},{"price":"2635.28","quantity":"0.000"}],"raw":{"e":"depthUpdate","E":1783517065130,"T":1783517065129,"s":"ETHUSDT","ps":"ETHUSDT","U":10999770364652,"u":10999770372895,"pu":10999770364171,"b":[["200.00","7.594"],["1216.16","0.032"],["1221.16","7.040"],["1226.12","0.320"],["1226.16","2.208"],["1562.54","0.212"],["1562.55","3.329"],["1666.70","0.940"],["1701.44","50.050"],["1704.74","0.416"],["1718.06","17.342"],["1727.47","0.012"],["1734.06","55.627"],["1735.47","229.898"],["1735.68","15.278"],["1735.74","27.064"],["1735.75","70.131"],["1735.81","9.313"],["1735.96","6.464"],["1736.08","2.058"],["1736.09","13.432"],["1736.12","25.113"],["1736.13","7.553"],["1736.16","416.626"]],"a":[["1736.17","36.439"],["1736.51","19.904"],["1736.52","26.302"],["1736.57","10.963"],["1736.60","1.768"],["1736.65","29.063"],["1737.15","0.431"],["1737.17","1.620"],["1737.34","14.909"],["1738.06","81.219"],["1738.08","410.300"],["1739.30","5.271"],["1739.80","5.290"],["1744.86","40.385"],["1747.12","52.204"],["1761.73","0.078"],["2635.19","0.001"],["2635.28","0.000"]],"st":1}}
{"schema_version":"1.3.0","event_id":"f4b22f00-ba22-47a6-ac96-d29c40ef209a","event_type":"raw.depth_update","source":"binance_market_data_recorder","venue":"binance_usdm","market_type":"perpetual_futures","symbol":"ETHUSDT","event_time_ms":1783517065232,"received_time_ms":1783517065226,"trace_id":"7d07e169-9a91-4cfd-91d8-e7ce32748ced","first_update_id":10999770372925,"final_update_id":10999770388529,"previous_final_update_id":10999770372895,"bids":[{"price":"1216.16","quantity":"0.288"},{"price":"1221.16","quantity":"7.328"},{"price":"1226.12","quantity":"0.064"},{"price":"1226.16","quantity":"1.920"},{"price":"1562.54","quantity":"0.212"},{"price":"1562.55","quantity":"3.201"},{"price":"1666.70","quantity":"0.825"},{"price":"1701.44","quantity":"50.079"},{"price":"1706.06","quantity":"30.519"},{"price":"1733.67","quantity":"0.332"},{"price":"1733.95","quantity":"430.056"},{"price":"1734.01","quantity":"21.767"},{"price":"1734.05","quantity":"11.825"},{"price":"1734.06","quantity":"54.181"},{"price":"1734.16","quantity":"5.208"},{"price":"1734.18","quantity":"0.012"},{"price":"1734.36","quantity":"13.419"},{"price":"1735.47","quantity":"9.416"},{"price":"1735.59","quantity":"223.745"},{"price":"1735.60","quantity":"0.172"},{"price":"1736.00","quantity":"1.734"},{"price":"1736.03","quantity":"6.354"},{"price":"1736.08","quantity":"2.046"},{"price":"1736.16","quantity":"401.507"}],"asks":[{"price":"1736.17","quantity":"27.293"},{"price":"1736.18","quantity":"0.024"},{"price":"1736.27","quantity":"0.059"},{"price":"1736.36","quantity":"1.740"},{"price":"1736.62","quantity":"5.860"},{"price":"1736.66","quantity":"67.539"},{"price":"1736.83","quantity":"36.581"},{"price":"1736.96","quantity":"188.134"},{"price":"1736.97","quantity":"7.320"},{"price":"1737.27","quantity":"19.154"},{"price":"1737.82","quantity":"33.369"},{"price":"1738.80","quantity":"4.943"},{"price":"1738.86","quantity":"19.557"},{"price":"1751.13","quantity":"0.689"},{"price":"1753.54","quantity":"122.436"},{"price":"1762.04","quantity":"17.022"},{"price":"1763.89","quantity":"20.177"},{"price":"2635.17","quantity":"0.032"},{"price":"2635.18","quantity":"0.040"},{"price":"2635.26","quantity":"0.000"},{"price":"2635.27","quantity":"0.000"}],"raw":{"e":"depthUpdate","E":1783517065232,"T":1783517065229,"s":"ETHUSDT","ps":"ETHUSDT","U":10999770372925,"u":10999770388529,"pu":10999770372895,"b":[["1216.16","0.288"],["1221.16","7.328"],["1226.12","0.064"],["1226.16","1.920"],["1562.54","0.212"],["1562.55","3.201"],["1666.70","0.825"],["1701.44","50.079"],["1706.06","30.519"],["1733.67","0.332"],["1733.95","430.056"],["1734.01","21.767"],["1734.05","11.825"],["1734.06","54.181"],["1734.16","5.208"],["1734.18","0.012"],["1734.36","13.419"],["1735.47","9.416"],["1735.59","223.745"],["1735.60","0.172"],["1736.00","1.734"],["1736.03","6.354"],["1736.08","2.046"],["1736.16","401.507"]],"a":[["1736.17","27.293"],["1736.18","0.024"],["1736.27","0.059"],["1736.36","1.740"],["1736.62","5.860"],["1736.66","67.539"],["1736.83","36.581"],["1736.96","188.134"],["1736.97","7.320"],["1737.27","19.154"],["1737.82","33.369"],["1738.80","4.943"],["1738.86","19.557"],["1751.13","0.689"],["1753.54","122.436"],["1762.04","17.022"],["1763.89","20.177"],["2635.17","0.032"],["2635.18","0.040"],["2635.26","0.000"],["2635.27","0.000"]],"st":1}}
{"schema_version":"1.3.0","event_id":"3bb0deca-bf15-4442-a400-48f2c3839c21","event_type":"raw.depth_update","source":"binance_market_data_recorder","venue":"binance_usdm","market_type":"perpetual_futures","symbol":"ETHUSDT","event_time_ms":1783517065334,"received_time_ms":1783517065328,"trace_id":"c5a09865-a1a6-42fa-af84-3063ac671fa3","first_update_id":10999770388940,"final_update_id":10999770399935,"previous_final_update_id":10999770388529,"bids":[{"price":"200.00","quantity":"7.594"},{"price":"1216.16","quantity":"0.800"},{"price":"1221.16","quantity":"7.136"},{"price":"1226.12","quantity":"0.000"},{"price":"1226.16","quantity":"1.664"},{"price":"1562.54","quantity":"0.212"},{"price":"1562.55","quantity":"3.215"},{"price":"1684.94","quantity":"106.830"},{"price":"1701.44","quantity":"50.050"},{"price":"1703.52","quantity":"31.977"},{"price":"1704.91","quantity":"36.369"},{"price":"1708.27","quantity":"0.076"},{"price":"1714.71","quantity":"61.653"},{"price":"1718.79","quantity":"76.615"},{"price":"1727.47","quantity":"0.000"},{"price":"1733.95","quantity":"3.942"},{"price":"1733.96","quantity":"4.848"},{"price":"1734.05","quantity":"13.271"},{"price":"1734.18","quantity":"426.126"},{"price":"1735.16","quantity":"3.810"},{"price":"1735.40","quantity":"8.527"}],"asks":[{"price":"1736.17","quantity":"27.152"},{"price":"1736.52","quantity":"24.635"},{"price":"1736.79","quantity":"0.108"},{"price":"1736.88","quantity":"3.670"},{"price":"1736.91","quantity":"53.794"},{"price":"1737.07","quantity":"9.464"},{"price":"1737.08","quantity":"9.700"},{"price":"1737.12","quantity":"15.689"},{"price":"1737.21","quantity":"0.850"},{"price":"1737.22","quantity":"2.641"},{"price":"1737.34","quantity":"13.215"},{"price":"1737.83","quantity":"104.229"},{"price":"1738.06","quantity":"79.525"},{"price":"1744.86","quantity":"40.397"},{"price":"2635.16","quantity":"0.001"},{"price":"2635.25","quantity":"0.003"}],"raw":{"e":"depthUpdate","E":1783517065334,"T":1783517065333,"s":"ETHUSDT","ps":"ETHUSDT","U":10999770388940,"u":10999770399935,"pu":10999770388529,"b":[["200.00","7.594"],["1216.16","0.800"],["1221.16","7.136"],["1226.12","0.000"],["1226.16","1.664"],["1562.54","0.212"],["1562.55","3.215"],["1684.94","106.830"],["1701.44","50.050"],["1703.52","31.977"],["1704.91","36.369"],["1708.27","0.076"],["1714.71","61.653"],["1718.79","76.615"],["1727.47","0.000"],["1733.95","3.942"],["1733.96","4.848"],["1734.05","13.271"],["1734.18","426.126"],["1735.16","3.810"],["1735.40","8.527"]],"a":[["1736.17","27.152"],["1736.52","24.635"],["1736.79","0.108"],["1736.88","3.670"],["1736.91","53.794"],["1737.07","9.464"],["1737.08","9.700"],["1737.12","15.689"],["1737.21","0.850"],["1737.22","2.641"],["1737.34","13.215"],["1737.83","104.229"],["1738.06","79.525"],["1744.86","40.397"],["2635.16","0.001"],["2635.25","0.003"]],"st":1}}
{"schema_version":"1.3.0","event_id":"33d731c9-3f9c-4cb1-808d-c20b82ad5cf6","event_type":"raw.depth_update","source":"binance_market_data_recorder","venue":"binance_usdm","market_type":"perpetual_futures","symbol":"ETHUSDT","event_time_ms":1783517065438,"received_time_ms":1783517065433,"trace_id":"e3e67fc7-ea30-4b2c-8975-6340fa0e2e42","first_update_id":10999770400361,"final_update_id":10999770410770,"previous_final_update_id":10999770399935,"bids":[{"price":"200.00","quantity":"7.594"},{"price":"1216.16","quantity":"1.344"},{"price":"1221.16","quantity":"6.880"},{"price":"1226.16","quantity":"1.376"},{"price":"1562.54","quantity":"0.212"},{"price":"1562.55","quantity":"3.471"},{"price":"1666.70","quantity":"0.940"},{"price":"1704.71","quantity":"29.292"},{"price":"1705.75","quantity":"58.547"},{"price":"1720.39","quantity":"1.651"},{"price":"1730.81","quantity":"19.847"},{"price":"1735.59","quantity":"3.201"},{"price":"1736.13","quantity":"7.826"},{"price":"1736.16","quantity":"401.292"}],"asks":[{"price":"1736.17","quantity":"36.784"},{"price":"1736.20","quantity":"0.076"},{"price":"1736.36","quantity":"1.740"},{"price":"1736.43","quantity":"10.243"},{"price":"1736.52","quantity":"26.302"},{"price":"1736.77","quantity":"83.694"},{"price":"1737.17","quantity":"1.620"},{"price":"1737.71","quantity":"1.975"},{"price":"1739.30","quantity":"3.887"},{"price":"1739.80","quantity":"6.674"},{"price":"1741.64","quantity":"38.004"},{"price":"1741.65","quantity":"0.632"},{"price":"1743.34","quantity":"104.627"},{"price":"1747.12","quantity":"37.204"},{"price":"1757.87","quantity":"16.497"},{"price":"1771.33","quantity":"2.822"},{"price":"1868.58","quantity":"0.101"},{"price":"2635.14","quantity":"0.014"},{"price":"2635.15","quantity":"0.001"},{"price":"2635.23","quantity":"0.000"},{"price":"2635.24","quantity":"0.000"}],"raw":{"e":"depthUpdate","E":1783517065438,"T":1783517065437,"s":"ETHUSDT","ps":"ETHUSDT","U":10999770400361,"u":10999770410770,"pu":10999770399935,"b":[["200.00","7.594"],["1216.16","1.344"],["1221.16","6.880"],["1226.16","1.376"],["1562.54","0.212"],["1562.55","3.471"],["1666.70","0.940"],["1704.71","29.292"],["1705.75","58.547"],["1720.39","1.651"],["1730.81","19.847"],["1735.59","3.201"],["1736.13","7.826"],["1736.16","401.292"]],"a":[["1736.17","36.784"],["1736.20","0.076"],["1736.36","1.740"],["1736.43","10.243"],["1736.52","26.302"],["1736.77","83.694"],["1737.17","1.620"],["1737.71","1.975"],["1739.30","3.887"],["1739.80","6.674"],["1741.64","38.004"],["1741.65","0.632"],["1743.34","104.627"],["1747.12","37.204"],["1757.87","16.497"],["1771.33","2.822"],["1868.58","0.101"],["2635.14","0.014"],["2635.15","0.001"],["2635.23","0.000"],["2635.24","0.000"]],"st":1}}
{"schema_version":"1.3.0","event_id":"f85c5f90-e955-4d88-9fe5-7460ff7b05c7","event_type":"raw.depth_update","source":"binance_market_data_recorder","venue":"binance_usdm","market_type":"perpetual_futures","symbol":"ETHUSDT","event_time_ms":1783517065540,"received_time_ms":1783517065534,"trace_id":"8aee23a2-f850-43c0-825b-ece5d034ed41","first_update_id":10999770410790,"final_update_id":10999770420271,"previous_final_update_id":10999770410770,"bids":[{"price":"201.00","quantity":"2.300"},{"price":"1216.16","quantity":"1.888"},{"price":"1221.16","quantity":"6.592"},{"price":"1226.16","quantity":"1.120"},{"price":"1562.54","quantity":"0.212"},{"price":"1562.55","quantity":"3.485"},{"price":"1666.70","quantity":"0.825"},{"price":"1701.44","quantity":"50.079"},{"price":"1713.71","quantity":"8.747"},{"price":"1732.52","quantity":"0.000"},{"price":"1733.04","quantity":"11.343"},{"price":"1733.95","quantity":"3.942"},{"price":"1734.05","quantity":"11.825"},{"price":"1734.12","quantity":"455.725"},{"price":"1734.13","quantity":"4.338"},{"price":"1734.18","quantity":"0.012"},{"price":"1734.27","quantity":"0.670"},{"price":"1735.12","quantity":"28.273"},{"price":"1735.16","quantity":"3.810"},{"price":"1735.28","quantity":"3.648"},{"price":"1735.29","quantity":"29.748"},{"price":"1735.40","quantity":"229.132"},{"price":"1735.43","quantity":"42.789"},{"price":"1735.49","quantity":"3.990"},{"price":"1735.68","quantity":"15.278"},{"price":"1735.79","quantity":"7.374"},{"price":"1735.82","quantity":"5.888"},{"price":"1735.85","quantity":"7.277"},{"price":"1735.86","quantity":"5.808"},{"price":"1735.91","quantity":"47.304"},{"price":"1735.94","quantity":"6.262"},{"price":"1736.01","quantity":"79.891"},{"price":"1736.06","quantity":"0.314"},{"price":"1736.08","quantity":"10.694"},{"price":"1736.10","quantity":"3.735"},{"price":"1736.11","quantity":"0.890"},{"price":"1736.12","quantity":"15.679"},{"price":"1736.16","quantity":"395.278"}],"asks":[{"price":"1736.17","quantity":"27.149"},{"price":"1736.32","quantity":"17.978"},{"price":"1736.33","quantity":"21.752"},{"price":"1736.36","quantity":"6.348"},{"price":"1736.38","quantity":"9.808"},{"price":"1736.39","quantity":"20.070"},{"price":"1736.41","quantity":"0.080"},{"price":"1736.46","quantity":"19.812"},{"price":"1736.47","quantity":"14.886"},{"price":"1736.49","quantity":"6.160"},{"price":"1736.51","quantity":"15.240"},{"price":"1736.52","quantity":"25.802"},{"price":"1736.54","quantity":"16.957"},{"price":"1736.55","quantity":"90.978"},{"price":"1736.61","quantity":"35.336"},{"price":"1736.68","quantity":"4.506"},{"price":"1736.77","quantity":"84.161"},{"price":"1736.86","quantity":"5.826"},{"price":"1736.90","quantity":"39.121"},{"price":"1736.92","quantity":"69.043"},{"price":"1737.07","quantity":"7.497"},{"price":"1737.08","quantity":"9.142"},{"price":"1737.09","quantity":"37.599"},{"price":"1737.10","quantity":"6.799"},{"price":"1737.12","quantity":"13.995"},{"price":"1737.34","quantity":"14.909"},{"price":"1737.56","quantity":"33.338"},{"price":"1737.65","quantity":"1.466"},{"price":"1738.96","quantity":"3.196"},{"price":"1742.44","quantity":"8.041"},{"price":"1742.47","quantity":"9.741"},{"price":"1742.48","quantity":"40.122"},{"price":"1744.75","quantity":"1.894"},{"price":"1744.83","quantity":"0.012"},{"price":"1744.99","quantity":"7.836"},{"price":"1751.52","quantity":"5.716"},{"price":"1778.71","quantity":"76.174"},{"price":"2635.13","quantity":"0.001"},{"price":"2635.22","quantity":"0.000"}],"raw":{"e":"depthUpdate","E":1783517065540,"T":1783517065538,"s":"ETHUSDT","ps":"ETHUSDT","U":10999770410790,"u":10999770420271,"pu":10999770410770,"b":[["201.00","2.300"],["1216.16","1.888"],["1221.16","6.592"],["1226.16","1.120"],["1562.54","0.212"],["1562.55","3.485"],["1666.70","0.825"],["1701.44","50.079"],["1713.71","8.747"],["1732.52","0.000"],["1733.04","11.343"],["1733.95","3.942"],["1734.05","11.825"],["1734.12","455.725"],["1734.13","4.338"],["1734.18","0.012"],["1734.27","0.670"],["1735.12","28.273"],["1735.16","3.810"],["1735.28","3.648"],["1735.29","29.748"],["1735.40","229.132"],["1735.43","42.789"],["1735.49","3.990"],["1735.68","15.278"],["1735.79","7.374"],["1735.82","5.888"],["1735.85","7.277"],["1735.86","5.808"],["1735.91","47.304"],["1735.94","6.262"],["1736.01","79.891"],["1736.06","0.314"],["1736.08","10.694"],["1736.10","3.735"],["1736.11","0.890"],["1736.12","15.679"],["1736.16","395.278"]],"a":[["1736.17","27.149"],["1736.32","17.978"],["1736.33","21.752"],["1736.36","6.348"],["1736.38","9.808"],["1736.39","20.070"],["1736.41","0.080"],["1736.46","19.812"],["1736.47","14.886"],["1736.49","6.160"],["1736.51","15.240"],["1736.52","25.802"],["1736.54","16.957"],["1736.55","90.978"],["1736.61","35.336"],["1736.68","4.506"],["1736.77","84.161"],["1736.86","5.826"],["1736.90","39.121"],["1736.92","69.043"],["1737.07","7.497"],["1737.08","9.142"],["1737.09","37.599"],["1737.10","6.799"],["1737.12","13.995"],["1737.34","14.909"],["1737.56","33.338"],["1737.65","1.466"],["1738.96","3.196"],["1742.44","8.041"],["1742.47","9.741"],["1742.48","40.122"],["1744.75","1.894"],["1744.83","0.012"],["1744.99","7.836"],["1751.52","5.716"],["1778.71","76.174"],["2635.13","0.001"],["2635.22","0.000"]],"st":1}}
{"schema_version":"1.3.0","event_id":"6b5652a0-bf3f-44e9-a243-3bd23ec14260","event_type":"raw.depth_update","source":"binance_market_data_recorder","venue":"binance_usdm","market_type":"perpetual_futures","symbol":"ETHUSDT","event_time_ms":1783517065642,"received_time_ms":1783517065636,"trace_id":"a2b10920-7278-4b4b-9877-a5702ef710f9","first_update_id":10999770420568,"final_update_id":10999770427587,"previous_final_update_id":10999770420271,"bids":[{"price":"200.00","quantity":"7.594"},{"price":"1216.16","quantity":"2.432"},{"price":"1221.16","quantity":"6.336"},{"price":"1226.16","quantity":"0.832"},{"price":"1562.54","quantity":"0.212"},{"price":"1562.55","quantity":"3.357"},{"price":"1666.70","quantity":"0.940"},{"price":"1694.46","quantity":"0.000"},{"price":"1701.44","quantity":"50.050"},{"price":"1704.39","quantity":"29.299"},{"price":"1710.87","quantity":"6.265"},{"price":"1713.59","quantity":"11.684"},{"price":"1721.02","quantity":"325.128"},{"price":"1721.25","quantity":"11.630"},{"price":"1723.45","quantity":"154.330"},{"price":"1730.39","quantity":"2.936"},{"price":"1734.12","quantity":"26.918"},{"price":"1734.16","quantity":"2.012"},{"price":"1734.18","quantity":"428.819"},{"price":"1735.17","quantity":"1.204"},{"price":"1735.18","quantity":"69.991"},{"price":"1735.25","quantity":"0.840"},{"price":"1735.26","quantity":"0.038"},{"price":"1735.70","quantity":"0.037"},{"price":"1736.16","quantity":"395.210"}],"asks":[{"price":"1736.36","quantity":"6.348"},{"price":"1736.60","quantity":"1.768"},{"price":"1736.62","quantity":"0.100"},{"price":"1737.06","quantity":"28.625"},{"price":"1737.07","quantity":"8.055"},{"price":"1737.09","quantity":"35.632"},{"price":"1737.10","quantity":"6.241"},{"price":"1737.17","quantity":"1.620"},{"price":"1738.05","quantity":"16.399"},{"price":"1739.30","quantity":"5.271"},{"price":"1739.80","quantity":"5.290"},{"price":"1743.34","quantity":"104.684"},{"price":"1747.12","quantity":"52.204"},{"price":"1750.53","quantity":"34.574"},{"price":"1788.26","quantity":"0.120"},{"price":"2635.12","quantity":"0.001"},{"price":"2635.21","quantity":"0.000"}],"raw":{"e":"depthUpdate","E":1783517065642,"T":1783517065641,"s":"ETHUSDT","ps":"ETHUSDT","U":10999770420568,"u":10999770427587,"pu":10999770420271,"b":[["200.00","7.594"],["1216.16","2.432"],["1221.16","6.336"],["1226.16","0.832"],["1562.54","0.212"],["1562.55","3.357"],["1666.70","0.940"],["1694.46","0.000"],["1701.44","50.050"],["1704.39","29.299"],["1710.87","6.265"],["1713.59","11.684"],["1721.02","325.128"],["1721.25","11.630"],["1723.45","154.330"],["1730.39","2.936"],["1734.12","26.918"],["1734.16","2.012"],["1734.18","428.819"],["1735.17","1.204"],["1735.18","69.991"],["1735.25","0.840"],["1735.26","0.038"],["1735.70","0.037"],["1736.16","395.210"]],"a":[["1736.36","6.348"],["1736.60","1.768"],["1736.62","0.100"],["1737.06","28.625"],["1737.07","8.055"],["1737.09","35.632"],["1737.10","6.241"],["1737.17","1.620"],["1738.05","16.399"],["1739.30","5.271"],["1739.80","5.290"],["1743.34","104.684"],["1747.12","52.204"],["1750.53","34.574"],["1788.26","0.120"],["2635.12","0.001"],["2635.21","0.000"]],"st":1}}
{"schema_version":"1.3.0","event_id":"e37fdbf1-20ce-44a3-bd38-85eb19dd31e3","event_type":"raw.depth_update","source":"binance_market_data_recorder","venue":"binance_usdm","market_type":"perpetual_futures","symbol":"ETHUSDT","event_time_ms":1783517065744,"received_time_ms":1783517065738,"trace_id":"1db006d4-efca-4a6c-aa31-e63ab29413ff","first_update_id":10999770427609,"final_update_id":10999770434258,"previous_final_update_id":10999770427587,"bids":[{"price":"200.00","quantity":"7.594"},{"price":"1216.16","quantity":"2.976"},{"price":"1221.16","quantity":"6.048"},{"price":"1226.16","quantity":"0.576"},{"price":"1562.54","quantity":"0.212"},{"price":"1562.55","quantity":"3.371"},{"price":"1666.70","quantity":"0.825"},{"price":"1690.56","quantity":"29.536"},{"price":"1701.43","quantity":"0.171"},{"price":"1703.17","quantity":"12.469"},{"price":"1733.94","quantity":"1.165"},{"price":"1734.05","quantity":"11.825"},{"price":"1734.06","quantity":"482.988"},{"price":"1734.07","quantity":"5.976"},{"price":"1734.18","quantity":"0.012"},{"price":"1735.27","quantity":"2.573"},{"price":"1735.40","quantity":"8.527"},{"price":"1735.43","quantity":"3.857"},{"price":"1735.49","quantity":"42.921"},{"price":"1735.56","quantity":"242.973"},{"price":"1735.68","quantity":"25.278"},{"price":"1736.16","quantity":"395.867"}],"asks":[{"price":"1736.88","quantity":"5.364"},{"price":"1736.98","quantity":"6.419"},{"price":"1737.02","quantity":"30.065"},{"price":"1737.34","quantity":"13.215"},{"price":"1737.82","quantity":"33.384"},{"price":"1751.07","quantity":"24.925"},{"price":"1779.19","quantity":"0.036"},{"price":"2635.10","quantity":"0.001"},{"price":"2635.11","quantity":"0.001"},{"price":"2635.19","quantity":"0.000"},{"price":"2635.20","quantity":"0.015"}],"raw":{"e":"depthUpdate","E":1783517065744,"T":1783517065743,"s":"ETHUSDT","ps":"ETHUSDT","U":10999770427609,"u":10999770434258,"pu":10999770427587,"b":[["200.00","7.594"],["1216.16","2.976"],["1221.16","6.048"],["1226.16","0.576"],["1562.54","0.212"],["1562.55","3.371"],["1666.70","0.825"],["1690.56","29.536"],["1701.43","0.171"],["1703.17","12.469"],["1733.94","1.165"],["1734.05","11.825"],["1734.06","482.988"],["1734.07","5.976"],["1734.18","0.012"],["1735.27","2.573"],["1735.40","8.527"],["1735.43","3.857"],["1735.49","42.921"],["1735.56","242.973"],["1735.68","25.278"],["1736.16","395.867"]],"a":[["1736.88","5.364"],["1736.98","6.419"],["1737.02","30.065"],["1737.34","13.215"],["1737.82","33.384"],["1751.07","24.925"],["1779.19","0.036"],["2635.10","0.001"],["2635.11","0.001"],["2635.19","0.000"],["2635.20","0.015"]],"st":1}}
{"schema_version":"1.3.0","event_id":"5c602dbe-6796-4dcc-bc0d-0f4850156c2e","event_type":"raw.depth_update","source":"binance_market_data_recorder","venue":"binance_usdm","market_type":"perpetual_futures","symbol":"ETHUSDT","event_time_ms":1783517065846,"received_time_ms":1783517065847,"trace_id":"4b5babf3-71cd-40f4-bc68-e03b52db2eca","first_update_id":10999770434508,"final_update_id":10999770443421,"previous_final_update_id":10999770434258,"bids":[{"price":"1216.16","quantity":"3.520"},{"price":"1221.16","quantity":"5.792"},{"price":"1226.16","quantity":"0.288"},{"price":"1562.54","quantity":"0.212"},{"price":"1562.55","quantity":"3.499"},{"price":"1701.43","quantity":"0.142"},{"price":"1705.75","quantity":"58.547"},{"price":"1710.17","quantity":"22.211"},{"price":"1721.40","quantity":"23.803"},{"price":"1724.99","quantity":"0.588"},{"price":"1725.03","quantity":"0.345"},{"price":"1732.77","quantity":"76.302"},{"price":"1733.95","quantity":"432.749"},{"price":"1734.06","quantity":"54.181"},{"price":"1734.18","quantity":"0.012"},{"price":"1734.19","quantity":"5.021"},{"price":"1734.75","quantity":"67.153"},{"price":"1735.16","quantity":"3.810"},{"price":"1735.56","quantity":"22.341"},{"price":"1735.60","quantity":"1.872"},{"price":"1735.67","quantity":"229.813"},{"price":"1735.78","quantity":"4.416"},{"price":"1736.10","quantity":"12.375"},{"price":"1736.16","quantity":"408.372"}],"asks":[{"price":"1736.20","quantity":"0.088"},{"price":"1736.36","quantity":"6.348"},{"price":"1736.39","quantity":"0.095"},{"price":"1736.55","quantity":"89.278"},{"price":"1736.73","quantity":"8.318"},{"price":"1736.83","quantity":"36.593"},{"price":"1736.88","quantity":"3.670"},{"price":"1737.12","quantity":"15.689"},{"price":"1738.46","quantity":"33.701"},{"price":"1739.98","quantity":"40.338"},{"price":"1750.93","quantity":"113.568"},{"price":"1776.10","quantity":"28.114"},{"price":"2635.09","quantity":"0.001"},{"price":"2635.18","quantity":"0.039"}],"raw":{"e":"depthUpdate","E":1783517065846,"T":1783517065845,"s":"ETHUSDT","ps":"ETHUSDT","U":10999770434508,"u":10999770443421,"pu":10999770434258,"b":[["1216.16","3.520"],["1221.16","5.792"],["1226.16","0.288"],["1562.54","0.212"],["1562.55","3.499"],["1701.43","0.142"],["1705.75","58.547"],["1710.17","22.211"],["1721.40","23.803"],["1724.99","0.588"],["1725.03","0.345"],["1732.77","76.302"],["1733.95","432.749"],["1734.06","54.181"],["1734.18","0.012"],["1734.19","5.021"],["1734.75","67.153"],["1735.16","3.810"],["1735.56","22.341"],["1735.60","1.872"],["1735.67","229.813"],["1735.78","4.416"],["1736.10","12.375"],["1736.16","408.372"]],"a":[["1736.20","0.088"],["1736.36","6.348"],["1736.39","0.095"],["1736.55","89.278"],["1736.73","8.318"],["1736.83","36.593"],["1736.88","3.670"],["1737.12","15.689"],["1738.46","33.701"],["1739.98","40.338"],["1750.93","113.568"],["1776.10","28.114"],["2635.09","0.001"],["2635.18","0.039"]],"st":1}}
{"schema_version":"1.3.0","event_id":"8f51305e-2ca5-4af6-a7e8-b974cc6e2a7b","event_type":"raw.depth_update","source":"binance_market_data_recorder","venue":"binance_usdm","market_type":"perpetual_futures","symbol":"ETHUSDT","event_time_ms":1783517065948,"received_time_ms":1783517065944,"trace_id":"ac6231b1-5537-4351-83c2-810eaff105c7","first_update_id":10999770443566,"final_update_id":10999770452298,"previous_final_update_id":10999770443421,"bids":[{"price":"200.00","quantity":"7.594"},{"price":"1216.16","quantity":"4.064"},{"price":"1221.16","quantity":"5.504"},{"price":"1226.16","quantity":"0.032"},{"price":"1562.54","quantity":"0.212"},{"price":"1562.55","quantity":"3.257"},{"price":"1666.70","quantity":"0.940"},{"price":"1684.56","quantity":"74.123"},{"price":"1701.43","quantity":"0.171"},{"price":"1703.17","quantity":"27.125"},{"price":"1705.72","quantity":"29.335"},{"price":"1708.32","quantity":"39.350"},{"price":"1709.53","quantity":"27.624"},{"price":"1710.12","quantity":"34.229"},{"price":"1727.25","quantity":"0.226"},{"price":"1727.29","quantity":"0.318"},{"price":"1733.04","quantity":"3.838"},{"price":"1733.95","quantity":"3.942"},{"price":"1734.07","quantity":"13.481"},{"price":"1734.13","quantity":"431.699"},{"price":"1735.17","quantity":"1.064"},{"price":"1735.18","quantity":"69.921"},{"price":"1735.25","quantity":"0.980"},{"price":"1735.26","quantity":"0.108"},{"price":"1735.64","quantity":"224.933"},{"price":"1735.67","quantity":"9.174"},{"price":"1735.79","quantity":"7.374"},{"price":"1736.08","quantity":"2.046"},{"price":"1736.13","quantity":"16.473"},{"price":"1736.16","quantity":"395.253"}],"asks":[{"price":"1736.21","quantity":"3.134"},{"price":"1736.28","quantity":"1.069"},{"price":"1736.41","quantity":"10.483"},{"price":"1736.81","quantity":"19.090"},{"price":"1737.17","quantity":"1.620"},{"price":"1737.39","quantity":"16.747"},{"price":"1737.42","quantity":"3.693"},{"price":"1737.56","quantity":"30.698"},{"price":"1737.65","quantity":"4.106"},{"price":"1738.97","quantity":"185.102"},{"price":"1740.00","quantity":"55.806"},{"price":"1747.12","quantity":"37.204"},{"price":"1762.52","quantity":"2.833"},{"price":"2635.08","quantity":"0.001"},{"price":"2635.17","quantity":"0.031"}],"raw":{"e":"depthUpdate","E":1783517065948,"T":1783517065945,"s":"ETHUSDT","ps":"ETHUSDT","U":10999770443566,"u":10999770452298,"pu":10999770443421,"b":[["200.00","7.594"],["1216.16","4.064"],["1221.16","5.504"],["1226.16","0.032"],["1562.54","0.212"],["1562.55","3.257"],["1666.70","0.940"],["1684.56","74.123"],["1701.43","0.171"],["1703.17","27.125"],["1705.72","29.335"],["1708.32","39.350"],["1709.53","27.624"],["1710.12","34.229"],["1727.25","0.226"],["1727.29","0.318"],["1733.04","3.838"],["1733.95","3.942"],["1734.07","13.481"],["1734.13","431.699"],["1735.17","1.064"],["1735.18","69.921"],["1735.25","0.980"],["1735.26","0.108"],["1735.64","224.933"],["1735.67","9.174"],["1735.79","7.374"],["1736.08","2.046"],["1736.13","16.473"],["1736.16","395.253"]],"a":[["1736.21","3.134"],["1736.28","1.069"],["1736.41","10.483"],["1736.81","19.090"],["1737.17","1.620"],["1737.39","16.747"],["1737.42","3.693"],["1737.56","30.698"],["1737.65","4.106"],["1738.97","185.102"],["1740.00","55.806"],["1747.12","37.204"],["1762.52","2.833"],["2635.08","0.001"],["2635.17","0.031"]],"st":1}}
{"schema_version":"1.3.0","event_id":"f575bd9b-2d8c-4633-9ddd-4a3bcd7b883c","event_type":"raw.depth_update","source":"binance_market_data_recorder","venue":"binance_usdm","market_type":"perpetual_futures","symbol":"ETHUSDT","event_time_ms":1783517066050,"received_time_ms":1783517066045,"trace_id":"f773e33c-b0c7-4d90-8923-61d8c486cb91","first_update_id":10999770452523,"final_update_id":10999770460396,"previous_final_update_id":10999770452298,"bids":[{"price":"200.00","quantity":"7.594"},{"price":"1216.16","quantity":"4.864"},{"price":"1221.16","quantity":"4.736"},{"price":"1226.16","quantity":"0.000"},{"price":"1562.54","quantity":"0.212"},{"price":"1562.55","quantity":"3.257"},{"price":"1666.70","quantity":"0.825"},{"price":"1701.43","quantity":"0.142"},{"price":"1703.02","quantity":"29.485"},{"price":"1732.26","quantity":"20.837"},{"price":"1732.27","quantity":"35.499"},{"price":"1733.81","quantity":"25.379"},{"price":"1733.85","quantity":"55.264"},{"price":"1733.95","quantity":"432.749"},{"price":"1734.05","quantity":"13.271"},{"price":"1734.13","quantity":"2.892"},{"price":"1734.18","quantity":"0.012"},{"price":"1735.16","quantity":"3.810"},{"price":"1735.25","quantity":"0.929"},{"price":"1735.81","quantity":"9.457"},{"price":"1736.12","quantity":"11.547"},{"price":"1736.16","quantity":"399.427"}],"asks":[{"price":"1736.36","quantity":"6.348"},{"price":"1736.52","quantity":"24.279"},{"price":"1736.69","quantity":"9.640"},{"price":"1736.73","quantity":"8.836"},{"price":"1737.12","quantity":"13.995"},{"price":"1737.34","quantity":"14.909"},{"price":"1737.69","quantity":"27.123"},{"price":"1737.73","quantity":"1.999"},{"price":"1738.84","quantity":"2.936"},{"price":"1738.88","quantity":"1.122"},{"price":"1738.96","quantity":"0.000"},{"price":"1739.64","quantity":"7.141"},{"price":"1739.65","quantity":"0.055"},{"price":"1739.92","quantity":"31.490"},{"price":"1740.51","quantity":"32.875"},{"price":"1740.52","quantity":"0.024"},{"price":"1741.37","quantity":"12.199"},{"price":"1741.38","quantity":"0.673"},{"price":"1742.24","quantity":"22.246"},{"price":"1742.25","quantity":"16.413"},{"price":"1743.11","quantity":"2.304"},{"price":"1743.12","quantity":"33.605"},{"price":"1751.46","quantity":"24.520"},{"price":"2635.06","quantity":"0.012"},{"price":"2635.07","quantity":"0.001"},{"price":"2635.15","quantity":"0.000"},{"price":"2635.16","quantity":"0.000"}],"raw":{"e":"depthUpdate","E":1783517066050,"T":1783517066049,"s":"ETHUSDT","ps":"ETHUSDT","U":10999770452523,"u":10999770460396,"pu":10999770452298,"b":[["200.00","7.594"],["1216.16","4.864"],["1221.16","4.736"],["1226.16","0.000"],["1562.54","0.212"],["1562.55","3.257"],["1666.70","0.825"],["1701.43","0.142"],["1703.02","29.485"],["1732.26","20.837"],["1732.27","35.499"],["1733.81","25.379"],["1733.85","55.264"],["1733.95","432.749"],["1734.05","13.271"],["1734.13","2.892"],["1734.18","0.012"],["1735.16","3.810"],["1735.25","0.929"],["1735.81","9.457"],["1736.12","11.547"],["1736.16","399.427"]],"a":[["1736.36","6.348"],["1736.52","24.279"],["1736.69","9.640"],["1736.73","8.836"],["1737.12","13.995"],["1737.34","14.909"],["1737.69","27.123"],["1737.73","1.999"],["1738.84","2.936"],["1738.88","1.122"],["1738.96","0.000"],["1739.64","7.141"],["1739.65","0.055"],["1739.92","31.490"],["1740.51","32.875"],["1740.52","0.024"],["1741.37","12.199"],["1741.38","0.673"],["1742.24","22.246"],["1742.25","16.413"],["1743.11","2.304"],["1743.12","33.605"],["1751.46","24.520"],["2635.06","0.012"],["2635.07","0.001"],["2635.15","0.000"],["2635.16","0.000"]],"st":1}}
{"schema_version":"1.3.0","event_id":"08cf514d-b838-4479-8a73-428e2e996ee6","event_type":"raw.depth_update","source":"binance_market_data_recorder","venue":"binance_usdm","market_type":"perpetual_futures","symbol":"ETHUSDT","event_time_ms":1783517066152,"received_time_ms":1783517066167,"trace_id":"093d427f-cc36-4dec-a7d4-405f3610775e","first_update_id":10999770460510,"final_update_id":10999770472217,"previous_final_update_id":10999770460396,"bids":[{"price":"1216.16","quantity":"5.664"},{"price":"1221.16","quantity":"3.936"},{"price":"1562.54","quantity":"0.212"},{"price":"1562.55","quantity":"3.385"},{"price":"1666.70","quantity":"0.940"},{"price":"1685.35","quantity":"0.033"},{"price":"1701.43","quantity":"0.171"},{"price":"1703.82","quantity":"173.374"},{"price":"1705.02","quantity":"134.763"},{"price":"1733.95","quantity":"3.942"},{"price":"1734.13","quantity":"2.892"},{"price":"1734.18","quantity":"428.819"},{"price":"1735.55","quantity":"3.080"},{"price":"1735.60","quantity":"0.172"},{"price":"1735.77","quantity":"13.310"},{"price":"1735.78","quantity":"6.116"},{"price":"1735.81","quantity":"9.313"},{"price":"1736.00","quantity":"1.754"},{"price":"1736.12","quantity":"11.106"},{"price":"1736.16","quantity":"399.859"}],"asks":[{"price":"1736.17","quantity":"27.296"},{"price":"1736.43","quantity":"10.243"},{"price":"1736.52","quantity":"25.802"},{"price":"1736.55","quantity":"90.978"},{"price":"1736.61","quantity":"6.517"},{"price":"1736.64","quantity":"46.656"},{"price":"1736.73","quantity":"7.136"},{"price":"1737.17","quantity":"1.620"},{"price":"1738.00","quantity":"14.422"},{"price":"1738.86","quantity":"2.881"},{"price":"1744.86","quantity":"40.385"},{"price":"1767.72","quantity":"107.354"},{"price":"2635.05","quantity":"0.001"},{"price":"2635.14","quantity":"0.013"}],"raw":{"e":"depthUpdate","E":1783517066152,"T":1783517066151,"s":"ETHUSDT","ps":"ETHUSDT","U":10999770460510,"u":10999770472217,"pu":10999770460396,"b":[["1216.16","5.664"],["1221.16","3.936"],["1562.54","0.212"],["1562.55","3.385"],["1666.70","0.940"],["1685.35","0.033"],["1701.43","0.171"],["1703.82","173.374"],["1705.02","134.763"],["1733.95","3.942"],["1734.13","2.892"],["1734.18","428.819"],["1735.55","3.080"],["1735.60","0.172"],["1735.77","13.310"],["1735.78","6.116"],["1735.81","9.313"],["1736.00","1.754"],["1736.12","11.106"],["1736.16","399.859"]],"a":[["1736.17","27.296"],["1736.43","10.243"],["1736.52","25.802"],["1736.55","90.978"],["1736.61","6.517"],["1736.64","46.656"],["1736.73","7.136"],["1737.17","1.620"],["1738.00","14.422"],["1738.86","2.881"],["1744.86","40.385"],["1767.72","107.354"],["2635.05","0.001"],["2635.14","0.013"]],"st":1}}
{"schema_version":"1.3.0","event_id":"598f564c-779f-4426-a24c-9aec5903c4f1","event_type":"raw.depth_update","source":"binance_market_data_recorder","venue":"binance_usdm","market_type":"perpetual_futures","symbol":"ETHUSDT","event_time_ms":1783517066254,"received_time_ms":1783517066932,"trace_id":"67950e9f-f414-43cf-b7b5-166b775617c5","first_update_id":10999770472387,"final_update_id":10999770515220,"previous_final_update_id":10999770472217,"bids":[{"price":"200.00","quantity":"7.594"},{"price":"1216.13","quantity":"0.064"},{"price":"1216.16","quantity":"5.792"},{"price":"1216.22","quantity":"0.032"},{"price":"1216.23","quantity":"0.032"},{"price":"1216.27","quantity":"0.628"},{"price":"1221.16","quantity":"3.136"},{"price":"1562.04","quantity":"0.168"},{"price":"1562.12","quantity":"0.000"},{"price":"1562.20","quantity":"1.949"},{"price":"1562.51","quantity":"5.636"},{"price":"1562.54","quantity":"0.186"},{"price":"1562.55","quantity":"0.199"},{"price":"1562.60","quantity":"0.014"},{"price":"1562.64","quantity":"0.114"},{"price":"1562.65","quantity":"0.119"},{"price":"1635.92","quantity":"0.000"},{"price":"1635.97","quantity":"0.025"},{"price":"1636.06","quantity":"0.040"},{"price":"1636.08","quantity":"0.000"},{"price":"1636.21","quantity":"0.318"},{"price":"1636.22","quantity":"0.060"},{"price":"1636.27","quantity":"0.114"},{"price":"1666.70","quantity":"0.825"},{"price":"1684.94","quantity":"133.507"},{"price":"1701.43","quantity":"0.142"},{"price":"1709.08","quantity":"14.639"},{"price":"1709.42","quantity":"78.388"},{"price":"1721.02","quantity":"238.098"},{"price":"1723.92","quantity":"0.314"},{"price":"1724.12","quantity":"70.269"},{"price":"1724.78","quantity":"3.254"},{"price":"1724.87","quantity":"154.897"},{"price":"1725.58","quantity":"0.567"},{"price":"1725.61","quantity":"0.084"},{"price":"1725.70","quantity":"151.945"},{"price":"1725.79","quantity":"1.219"},{"price":"1726.04","quantity":"0.653"},{"price":"1726.72","quantity":"12.411"},{"price":"1726.74","quantity":"313.902"},{"price":"1726.82","quantity":"0.763"},{"price":"1727.23","quantity":"0.000"},{"price":"1727.47","quantity":"0.012"},{"price":"1728.66","quantity":"0.225"},{"price":"1728.91","quantity":"0.109"},{"price":"1729.04","quantity":"6.250"},{"price":"1729.11","quantity":"32.814"},{"price":"1729.13","quantity":"4.338"},{"price":"1729.24","quantity":"4.022"},{"price":"1729.29","quantity":"1.669"},{"price":"1729.35","quantity":"4.620"},{"price":"1729.57","quantity":"4.310"},{"price":"1729.73","quantity":"16.409"},{"price":"1729.82","quantity":"4.310"},{"price":"1730.01","quantity":"4.410"},{"price":"1730.07","quantity":"135.808"},{"price":"1730.08","quantity":"26.300"},{"price":"1730.09","quantity":"4.331"},{"price":"1730.23","quantity":"16.323"},{"price":"1730.44","quantity":"4.322"},{"price":"1730.45","quantity":"5.216"},{"price":"1730.74","quantity":"16.553"},{"price":"1730.77","quantity":"23.000"},{"price":"1730.78","quantity":"11.884"},{"price":"1731.12","quantity":"0.000"},{"price":"1731.16","quantity":"5.197"},{"price":"1731.21","quantity":"4.280"},{"price":"1731.25","quantity":"6.640"},{"price":"1731.27","quantity":"4.095"},{"price":"1731.31","quantity":"0.576"},{"price":"1731.36","quantity":"6.627"},{"price":"1731.42","quantity":"4.961"},{"price":"1731.44","quantity":"25.235"},{"price":"1731.49","quantity":"1.184"},{"price":"1731.62","quantity":"0.692"},{"price":"1731.63","quantity":"0.089"},{"price":"1731.66","quantity":"17.452"},{"price":"1731.70","quantity":"16.361"},{"price":"1731.73","quantity":"30.143"},{"price":"1731.84","quantity":"0.133"},{"price":"1731.87","quantity":"194.162"},{"price":"1731.91","quantity":"83.650"},{"price":"1732.05","quantity":"51.914"},{"price":"1732.10","quantity":"77.670"},{"price":"1732.16","quantity":"0.023"},{"price":"1732.19","quantity":"5.100"},{"price":"1732.26","quantity":"20.852"},{"price":"1732.27","quantity":"36.014"},{"price":"1732.29","quantity":"14.787"},{"price":"1732.31","quantity":"73.938"},{"price":"1732.43","quantity":"144.091"},{"price":"1732.46","quantity":"13.098"},{"price":"1732.47","quantity":"22.697"},{"price":"1732.51","quantity":"115.548"},{"price":"1732.52","quantity":"67.230"},{"price":"1732.54","quantity":"10.178"},{"price":"1732.55","quantity":"16.340"},{"price":"1732.56","quantity":"16.669"},{"price":"1732.59","quantity":"27.771"},{"price":"1732.61","quantity":"0.157"},{"price":"1732.64","quantity":"16.727"},{"price":"1732.69","quantity":"0.117"},{"price":"1732.70","quantity":"74.797"},{"price":"1732.71","quantity":"0.446"},{"price":"1732.74","quantity":"0.063"},{"price":"1732.77","quantity":"76.290"},{"price":"1732.78","quantity":"4.644"},{"price":"1732.80","quantity":"18.715"},{"price":"1732.87","quantity":"68.034"},{"price":"1733.01","quantity":"21.655"},{"price":"1733.03","quantity":"63.227"},{"price":"1733.04","quantity":"3.824"},{"price":"1733.07","quantity":"89.080"},{"price":"1733.08","quantity":"0.071"},{"price":"1733.10","quantity":"16.428"},{"price":"1733.14","quantity":"9.356"},{"price":"1733.22","quantity":"7.070"},{"price":"1733.23","quantity":"17.418"},{"price":"1733.26","quantity":"20.811"},{"price":"1733.27","quantity":"28.157"},{"price":"1733.28","quantity":"496.052"},{"price":"1733.31","quantity":"2.028"},{"price":"1733.35","quantity":"17.333"},{"price":"1733.40","quantity":"20.470"},{"price":"1733.41","quantity":"40.697"},{"price":"1733.43","quantity":"0.788"},{"price":"1733.47","quantity":"0.467"},{"price":"1733.49","quantity":"84.409"},{"price":"1733.50","quantity":"13.855"},{"price":"1733.51","quantity":"13.194"},{"price":"1733.52","quantity":"19.248"},{"price":"1733.53","quantity":"19.851"},{"price":"1733.57","quantity":"4.362"},{"price":"1733.58","quantity":"1.782"},{"price":"1733.60","quantity":"0.877"},{"price":"1733.61","quantity":"17.711"},{"price":"1733.63","quantity":"50.351"},{"price":"1733.65","quantity":"9.919"},{"price":"1733.67","quantity":"5.201"},{"price":"1733.70","quantity":"17.168"},{"price":"1733.71","quantity":"84.523"},{"price":"1733.76","quantity":"35.199"},{"price":"1733.82","quantity":"2.563"},{"price":"1733.83","quantity":"18.481"},{"price":"1733.89","quantity":"0.765"},{"price":"1733.90","quantity":"72.148"},{"price":"1733.92","quantity":"17.384"},{"price":"1733.93","quantity":"3.746"},{"price":"1733.94","quantity":"79.580"},{"price":"1733.95","quantity":"3.942"},{"price":"1733.96","quantity":"4.606"},{"price":"1734.01","quantity":"17.457"},{"price":"1734.03","quantity":"44.312"},{"price":"1734.04","quantity":"129.936"},{"price":"1734.05","quantity":"75.860"},{"price":"1734.07","quantity":"2.780"},{"price":"1734.08","quantity":"0.968"},{"price":"1734.09","quantity":"3.015"},{"price":"1734.10","quantity":"68.261"},{"price":"1734.12","quantity":"44.464"},{"price":"1734.14","quantity":"2.735"},{"price":"1734.15","quantity":"0.370"},{"price":"1734.18","quantity":"16.807"},{"price":"1734.19","quantity":"5.955"},{"price":"1734.20","quantity":"97.096"},{"price":"1734.24","quantity":"1.474"},{"price":"1734.25","quantity":"0.024"},{"price":"1734.26","quantity":"0.953"},{"price":"1734.27","quantity":"1.895"},{"price":"1734.29","quantity":"8.551"},{"price":"1734.30","quantity":"21.202"},{"price":"1734.31","quantity":"17.666"},{"price":"1734.33","quantity":"19.646"},{"price":"1734.35","quantity":"8.782"},{"price":"1734.37","quantity":"2.350"},{"price":"1734.38","quantity":"11.407"},{"price":"1734.41","quantity":"80.933"},{"price":"1734.42","quantity":"1.447"},{"price":"1734.43","quantity":"0.384"},{"price":"1734.45","quantity":"0.056"},{"price":"1734.46","quantity":"25.640"},{"price":"1734.47","quantity":"7.314"},{"price":"1734.48","quantity":"18.044"},{"price":"1734.49","quantity":"53.052"},{"price":"1734.50","quantity":"9.297"},{"price":"1734.51","quantity":"12.717"},{"price":"1734.52","quantity":"0.039"},{"price":"1734.53","quantity":"34.922"},{"price":"1734.54","quantity":"18.103"},{"price":"1734.55","quantity":"0.155"},{"price":"1734.56","quantity":"3.980"},{"price":"1734.57","quantity":"29.333"},{"price":"1734.62","quantity":"119.388"},{"price":"1734.63","quantity":"1.527"},{"price":"1734.66","quantity":"11.728"},{"price":"1734.67","quantity":"0.054"},{"price":"1734.68","quantity":"11.509"},{"price":"1734.69","quantity":"0.401"},{"price":"1734.72","quantity":"2.933"},{"price":"1734.73","quantity":"96.801"},{"price":"1734.74","quantity":"10.602"},{"price":"1734.75","quantity":"67.118"},{"price":"1734.77","quantity":"85.150"},{"price":"1734.79","quantity":"7.220"},{"price":"1734.82","quantity":"18.237"},{"price":"1734.83","quantity":"6.689"},{"price":"1734.84","quantity":"272.762"},{"price":"1734.85","quantity":"1.504"},{"price":"1734.86","quantity":"38.363"},{"price":"1734.87","quantity":"16.928"},{"price":"1734.88","quantity":"21.956"},{"price":"1734.89","quantity":"0.389"},{"price":"1734.90","quantity":"19.409"},{"price":"1734.91","quantity":"0.660"},{"price":"1734.92","quantity":"59.567"},{"price":"1734.93","quantity":"60.059"},{"price":"1734.94","quantity":"15.221"},{"price":"1734.95","quantity":"9.713"},{"price":"1734.96","quantity":"5.239"},{"price":"1734.97","quantity":"37.471"},{"price":"1734.98","quantity":"69.905"},{"price":"1734.99","quantity":"1.089"},{"price":"1735.00","quantity":"217.808"},{"price":"1735.01","quantity":"44.586"},{"price":"1735.02","quantity":"49.821"},{"price":"1735.03","quantity":"0.065"},{"price":"1735.04","quantity":"2.899"},{"price":"1735.05","quantity":"3.624"},{"price":"1735.06","quantity":"0.127"},{"price":"1735.07","quantity":"6.745"},{"price":"1735.08","quantity":"6.291"},{"price":"1735.09","quantity":"17.566"},{"price":"1735.10","quantity":"14.675"},{"price":"1735.11","quantity":"37.853"},{"price":"1735.12","quantity":"96.082"},{"price":"1735.13","quantity":"5.217"},{"price":"1735.14","quantity":"8.718"},{"price":"1735.15","quantity":"5.663"},{"price":"1735.16","quantity":"3.924"},{"price":"1735.17","quantity":"1.084"},{"price":"1735.18","quantity":"0.385"},{"price":"1735.19","quantity":"13.415"},{"price":"1735.20","quantity":"8.860"},{"price":"1735.21","quantity":"34.412"},{"price":"1735.22","quantity":"18.033"},{"price":"1735.23","quantity":"6.281"},{"price":"1735.24","quantity":"10.126"},{"price":"1735.25","quantity":"0.874"},{"price":"1735.27","quantity":"70.082"},{"price":"1735.28","quantity":"3.660"},{"price":"1735.29","quantity":"29.646"},{"price":"1735.30","quantity":"29.930"},{"price":"1735.31","quantity":"33.996"},{"price":"1735.32","quantity":"17.078"},{"price":"1735.33","quantity":"16.311"},{"price":"1735.34","quantity":"0.098"},{"price":"1735.35","quantity":"17.776"},{"price":"1735.36","quantity":"3.774"},{"price":"1735.37","quantity":"0.580"},{"price":"1735.38","quantity":"48.687"},{"price":"1735.39","quantity":"0.559"},{"price":"1735.40","quantity":"3.818"},{"price":"1735.41","quantity":"83.496"},{"price":"1735.42","quantity":"16.319"},{"price":"1735.43","quantity":"4.025"},{"price":"1735.44","quantity":"27.398"},{"price":"1735.45","quantity":"0.125"},{"price":"1735.46","quantity":"21.312"},{"price":"1735.47","quantity":"16.697"},{"price":"1735.48","quantity":"0.862"},{"price":"1735.49","quantity":"6.804"},{"price":"1735.50","quantity":"9.853"},{"price":"1735.51","quantity":"51.875"},{"price":"1735.52","quantity":"0.333"},{"price":"1735.53","quantity":"0.774"},{"price":"1735.54","quantity":"4.443"},{"price":"1735.55","quantity":"0.201"},{"price":"1735.56","quantity":"52.070"},{"price":"1735.57","quantity":"1.802"},{"price":"1735.58","quantity":"0.754"},{"price":"1735.59","quantity":"4.353"},{"price":"1735.60","quantity":"0.172"},{"price":"1735.61","quantity":"8.654"},{"price":"1735.62","quantity":"10.466"},{"price":"1735.63","quantity":"0.159"},{"price":"1735.64","quantity":"4.907"},{"price":"1735.65","quantity":"30.180"},{"price":"1735.66","quantity":"20.157"},{"price":"1735.67","quantity":"0.051"},{"price":"1735.68","quantity":"15.158"},{"price":"1735.69","quantity":"0.264"},{"price":"1735.70","quantity":"0.837"},{"price":"1735.71","quantity":"0.038"},{"price":"1735.72","quantity":"90.480"},{"price":"1735.73","quantity":"11.825"},{"price":"1735.74","quantity":"27.064"},{"price":"1735.75","quantity":"2.948"},{"price":"1735.76","quantity":"11.771"},{"price":"1735.77","quantity":"0.138"},{"price":"1735.78","quantity":"0.052"},{"price":"1735.79","quantity":"1.795"},{"price":"1735.80","quantity":"0.159"},{"price":"1735.81","quantity":"4.898"},{"price":"1735.82","quantity":"4.576"},{"price":"1735.83","quantity":"16.561"},{"price":"1735.84","quantity":"0.058"},{"price":"1735.85","quantity":"2.951"},{"price":"1735.86","quantity":"0.048"},{"price":"1735.87","quantity":"4.750"},{"price":"1735.88","quantity":"1.191"},{"price":"1735.89","quantity":"1.068"},{"price":"1735.90","quantity":"6.674"},{"price":"1735.91","quantity":"19.935"},{"price":"1735.92","quantity":"10.528"},{"price":"1735.93","quantity":"0.596"},{"price":"1735.94","quantity":"5.111"},{"price":"1735.95","quantity":"4.891"},{"price":"1735.96","quantity":"0.552"},{"price":"1735.97","quantity":"3.383"},{"price":"1735.98","quantity":"1.941"},{"price":"1735.99","quantity":"1.064"},{"price":"1736.00","quantity":"0.074"},{"price":"1736.01","quantity":"0.050"},{"price":"1736.02","quantity":"0.061"},{"price":"1736.03","quantity":"1.262"},{"price":"1736.04","quantity":"0.024"},{"price":"1736.05","quantity":"0.075"},{"price":"1736.06","quantity":"0.038"},{"price":"1736.07","quantity":"0.048"},{"price":"1736.08","quantity":"1.323"},{"price":"1736.09","quantity":"1.764"},{"price":"1736.10","quantity":"3.736"},{"price":"1736.11","quantity":"0.012"},{"price":"1736.12","quantity":"7.921"},{"price":"1736.13","quantity":"27.898"},{"price":"1736.14","quantity":"0.000"},{"price":"1736.15","quantity":"0.000"},{"price":"1736.16","quantity":"0.000"},{"price":"1736.17","quantity":"0.000"},{"price":"1736.18","quantity":"0.000"},{"price":"1736.19","quantity":"0.000"},{"price":"1736.20","quantity":"0.000"},{"price":"1736.21","quantity":"0.000"},{"price":"1736.22","quantity":"0.000"},{"price":"1736.23","quantity":"0.000"},{"price":"1736.24","quantity":"0.000"},{"price":"1736.25","quantity":"0.000"},{"price":"1736.26","quantity":"0.000"},{"price":"1736.27","quantity":"0.000"},{"price":"1736.28","quantity":"0.000"}],"asks":[{"price":"1736.14","quantity":"237.015"},{"price":"1736.15","quantity":"23.318"},{"price":"1736.16","quantity":"0.026"},{"price":"1736.17","quantity":"41.155"},{"price":"1736.18","quantity":"0.029"},{"price":"1736.19","quantity":"6.617"},{"price":"1736.20","quantity":"1.762"},{"price":"1736.21","quantity":"0.000"},{"price":"1736.22","quantity":"6.530"},{"price":"1736.23","quantity":"8.622"},{"price":"1736.24","quantity":"29.227"},{"price":"1736.25","quantity":"6.923"},{"price":"1736.26","quantity":"0.026"},{"price":"1736.27","quantity":"0.014"},{"price":"1736.28","quantity":"75.752"},{"price":"1736.29","quantity":"2.605"},{"price":"1736.30","quantity":"7.293"},{"price":"1736.31","quantity":"0.166"},{"price":"1736.32","quantity":"0.118"},{"price":"1736.33","quantity":"0.012"},{"price":"1736.34","quantity":"0.041"},{"price":"1736.35","quantity":"4.525"},{"price":"1736.36","quantity":"29.473"},{"price":"1736.37","quantity":"8.398"},{"price":"1736.38","quantity":"0.067"},{"price":"1736.39","quantity":"0.038"},{"price":"1736.40","quantity":"18.647"},{"price":"1736.41","quantity":"0.068"},{"price":"1736.42","quantity":"0.038"},{"price":"1736.43","quantity":"6.887"},{"price":"1736.44","quantity":"41.547"},{"price":"1736.45","quantity":"72.394"},{"price":"1736.46","quantity":"46.502"},{"price":"1736.47","quantity":"17.496"},{"price":"1736.48","quantity":"1.719"},{"price":"1736.49","quantity":"2.957"},{"price":"1736.50","quantity":"0.107"},{"price":"1736.51","quantity":"3.065"},{"price":"1736.52","quantity":"0.287"},{"price":"1736.53","quantity":"1.342"},{"price":"1736.54","quantity":"2.889"},{"price":"1736.55","quantity":"6.456"},{"price":"1736.56","quantity":"10.882"},{"price":"1736.57","quantity":"2.094"},{"price":"1736.58","quantity":"1.405"},{"price":"1736.59","quantity":"4.554"},{"price":"1736.60","quantity":"0.768"},{"price":"1736.61","quantity":"11.082"},{"price":"1736.62","quantity":"1.599"},{"price":"1736.63","quantity":"10.299"},{"price":"1736.64","quantity":"71.111"},{"price":"1736.65","quantity":"23.329"},{"price":"1736.66","quantity":"6.530"},{"price":"1736.67","quantity":"3.518"},{"price":"1736.68","quantity":"0.204"},{"price":"1736.69","quantity":"7.376"},{"price":"1736.70","quantity":"48.979"},{"price":"1736.71","quantity":"13.166"},{"price":"1736.72","quantity":"9.524"},{"price":"1736.73","quantity":"2.675"},{"price":"1736.74","quantity":"24.750"},{"price":"1736.75","quantity":"67.315"},{"price":"1736.76","quantity":"24.935"},{"price":"1736.77","quantity":"0.161"},{"price":"1736.78","quantity":"17.781"},{"price":"1736.79","quantity":"23.129"},{"price":"1736.80","quantity":"9.959"},{"price":"1736.81","quantity":"19.120"},{"price":"1736.82","quantity":"18.978"},{"price":"1736.83","quantity":"33.683"},{"price":"1736.84","quantity":"5.057"},{"price":"1736.86","quantity":"4.759"},{"price":"1736.87","quantity":"25.010"},{"price":"1736.88","quantity":"3.380"},{"price":"1736.89","quantity":"8.208"},{"price":"1736.90","quantity":"12.768"},{"price":"1736.91","quantity":"30.676"},{"price":"1736.92","quantity":"67.361"},{"price":"1736.93","quantity":"16.386"},{"price":"1736.94","quantity":"19.272"},{"price":"1736.95","quantity":"0.063"},{"price":"1736.96","quantity":"3.511"},{"price":"1736.97","quantity":"2.975"},{"price":"1736.98","quantity":"5.315"},{"price":"1736.99","quantity":"31.171"},{"price":"1737.00","quantity":"68.401"},{"price":"1737.01","quantity":"74.995"},{"price":"1737.02","quantity":"34.375"},{"price":"1737.04","quantity":"46.112"},{"price":"1737.05","quantity":"0.109"},{"price":"1737.06","quantity":"29.025"},{"price":"1737.07","quantity":"7.916"},{"price":"1737.08","quantity":"9.142"},{"price":"1737.09","quantity":"43.267"},{"price":"1737.10","quantity":"12.251"},{"price":"1737.12","quantity":"5.551"},{"price":"1737.13","quantity":"4.430"},{"price":"1737.14","quantity":"70.120"},{"price":"1737.15","quantity":"0.854"},{"price":"1737.16","quantity":"9.010"},{"price":"1737.17","quantity":"1.661"},{"price":"1737.18","quantity":"22.765"},{"price":"1737.19","quantity":"17.679"},{"price":"1737.21","quantity":"0.022"},{"price":"1737.22","quantity":"1.641"},{"price":"1737.23","quantity":"32.967"},{"price":"1737.24","quantity":"1.151"},{"price":"1737.25","quantity":"71.600"},{"price":"1737.26","quantity":"4.390"},{"price":"1737.27","quantity":"18.856"},{"price":"1737.28","quantity":"0.256"},{"price":"1737.30","quantity":"0.078"},{"price":"1737.31","quantity":"9.427"},{"price":"1737.32","quantity":"9.994"},{"price":"1737.33","quantity":"19.390"},{"price":"1737.34","quantity":"13.215"},{"price":"1737.36","quantity":"68.335"},{"price":"1737.37","quantity":"40.106"},{"price":"1737.38","quantity":"93.231"},{"price":"1737.39","quantity":"69.389"},{"price":"1737.41","quantity":"0.184"},{"price":"1737.42","quantity":"3.675"},{"price":"1737.43","quantity":"8.581"},{"price":"1737.44","quantity":"49.424"},{"price":"1737.45","quantity":"35.003"},{"price":"1737.49","quantity":"35.965"},{"price":"1737.51","quantity":"2.418"},{"price":"1737.52","quantity":"0.026"},{"price":"1737.53","quantity":"2.652"},{"price":"1737.55","quantity":"51.070"},{"price":"1737.56","quantity":"87.491"},{"price":"1737.57","quantity":"134.828"},{"price":"1737.58","quantity":"23.496"},{"price":"1737.59","quantity":"4.188"},{"price":"1737.60","quantity":"4.591"},{"price":"1737.61","quantity":"10.320"},{"price":"1737.62","quantity":"68.826"},{"price":"1737.64","quantity":"25.705"},{"price":"1737.65","quantity":"1.466"},{"price":"1737.67","quantity":"1.336"},{"price":"1737.68","quantity":"0.763"},{"price":"1737.70","quantity":"34.178"},{"price":"1737.71","quantity":"1.736"},{"price":"1737.72","quantity":"51.587"},{"price":"1737.73","quantity":"3.681"},{"price":"1737.74","quantity":"143.144"},{"price":"1737.75","quantity":"16.839"},{"price":"1737.78","quantity":"3.155"},{"price":"1737.79","quantity":"3.555"},{"price":"1737.81","quantity":"16.496"},{"price":"1737.82","quantity":"16.708"},{"price":"1737.83","quantity":"34.798"},{"price":"1737.85","quantity":"0.279"},{"price":"1737.87","quantity":"7.835"},{"price":"1737.89","quantity":"33.409"},{"price":"1737.92","quantity":"92.879"},{"price":"1737.99","quantity":"0.597"},{"price":"1738.00","quantity":"14.410"},{"price":"1738.02","quantity":"4.335"},{"price":"1738.04","quantity":"9.906"},{"price":"1738.05","quantity":"16.399"},{"price":"1738.06","quantity":"13.118"},{"price":"1738.08","quantity":"1.109"},{"price":"1738.12","quantity":"4.331"},{"price":"1738.21","quantity":"0.521"},{"price":"1738.23","quantity":"0.309"},{"price":"1738.26","quantity":"1.023"},{"price":"1738.27","quantity":"21.453"},{"price":"1738.31","quantity":"0.852"},{"price":"1738.34","quantity":"36.769"},{"price":"1738.35","quantity":"46.110"},{"price":"1738.41","quantity":"4.196"},{"price":"1738.43","quantity":"0.012"},{"price":"1738.44","quantity":"2.710"},{"price":"1738.45","quantity":"18.512"},{"price":"1738.48","quantity":"2.878"},{"price":"1738.49","quantity":"19.436"},{"price":"1738.53","quantity":"13.271"},{"price":"1738.54","quantity":"92.362"},{"price":"1738.55","quantity":"408.233"},{"price":"1738.56","quantity":"1.044"},{"price":"1738.57","quantity":"34.780"},{"price":"1738.58","quantity":"83.983"},{"price":"1738.61","quantity":"0.290"},{"price":"1738.63","quantity":"0.000"},{"price":"1738.64","quantity":"7.862"},{"price":"1738.65","quantity":"22.729"},{"price":"1738.68","quantity":"0.120"},{"price":"1738.71","quantity":"38.634"},{"price":"1738.78","quantity":"1.109"},{"price":"1738.80","quantity":"10.921"},{"price":"1738.81","quantity":"9.053"},{"price":"1738.83","quantity":"0.749"},{"price":"1738.86","quantity":"19.557"},{"price":"1738.88","quantity":"1.079"},{"price":"1738.89","quantity":"59.549"},{"price":"1738.93","quantity":"0.047"},{"price":"1738.94","quantity":"3.960"},{"price":"1738.95","quantity":"12.599"},{"price":"1738.96","quantity":"0.000"},{"price":"1738.97","quantity":"181.906"},{"price":"1738.98","quantity":"40.552"},{"price":"1738.99","quantity":"159.773"},{"price":"1739.00","quantity":"2.893"},{"price":"1739.03","quantity":"11.224"},{"price":"1739.04","quantity":"13.978"},{"price":"1739.08","quantity":"13.193"},{"price":"1739.19","quantity":"16.354"},{"price":"1739.25","quantity":"0.037"},{"price":"1739.27","quantity":"7.144"},{"price":"1739.30","quantity":"5.271"},{"price":"1739.34","quantity":"1.094"},{"price":"1739.36","quantity":"3.358"},{"price":"1739.42","quantity":"17.925"},{"price":"1739.51","quantity":"5.793"},{"price":"1739.75","quantity":"0.861"},{"price":"1739.81","quantity":"8.363"},{"price":"1739.82","quantity":"16.241"},{"price":"1739.88","quantity":"16.410"},{"price":"1739.93","quantity":"20.476"},{"price":"1739.99","quantity":"0.299"},{"price":"1740.10","quantity":"17.856"},{"price":"1740.17","quantity":"44.465"},{"price":"1740.20","quantity":"0.082"},{"price":"1740.24","quantity":"223.169"},{"price":"1740.25","quantity":"4.091"},{"price":"1740.26","quantity":"160.339"},{"price":"1740.30","quantity":"6.280"},{"price":"1740.32","quantity":"8.093"},{"price":"1740.33","quantity":"0.084"},{"price":"1740.42","quantity":"9.486"},{"price":"1740.43","quantity":"10.036"},{"price":"1740.46","quantity":"0.000"},{"price":"1740.57","quantity":"16.364"},{"price":"1740.61","quantity":"12.167"},{"price":"1740.64","quantity":"175.715"},{"price":"1740.66","quantity":"14.597"},{"price":"1740.71","quantity":"26.759"},{"price":"1740.74","quantity":"34.522"},{"price":"1740.75","quantity":"0.050"},{"price":"1740.80","quantity":"173.006"},{"price":"1740.81","quantity":"7.153"},{"price":"1741.07","quantity":"4.917"},{"price":"1741.19","quantity":"13.574"},{"price":"1741.20","quantity":"0.628"},{"price":"1741.39","quantity":"71.207"},{"price":"1742.43","quantity":"2.691"},{"price":"1742.47","quantity":"0.012"},{"price":"1742.48","quantity":"22.888"},{"price":"1742.53","quantity":"5.765"},{"price":"1743.48","quantity":"16.023"},{"price":"1743.49","quantity":"26.192"},{"price":"1743.50","quantity":"27.224"},{"price":"1743.68","quantity":"0.777"},{"price":"1743.73","quantity":"0.000"},{"price":"1744.56","quantity":"62.250"},{"price":"1744.57","quantity":"413.276"},{"price":"1744.99","quantity":"0.331"},{"price":"1745.53","quantity":"0.026"},{"price":"1746.34","quantity":"1.349"},{"price":"1746.60","quantity":"0.040"},{"price":"1747.12","quantity":"52.204"},{"price":"1749.57","quantity":"0.047"},{"price":"1750.00","quantity":"224.397"},{"price":"1750.18","quantity":"0.012"},{"price":"1751.22","quantity":"84.048"},{"price":"1751.86","quantity":"10.080"},{"price":"1752.75","quantity":"83.594"},{"price":"1753.07","quantity":"0.031"},{"price":"1753.53","quantity":"0.293"},{"price":"1760.58","quantity":"28.134"},{"price":"1763.15","quantity":"42.522"},{"price":"1770.35","quantity":"0.254"},{"price":"1777.88","quantity":"3.576"},{"price":"1777.89","quantity":"0.012"},{"price":"1778.80","quantity":"75.218"},{"price":"1835.77","quantity":"0.123"},{"price":"1835.83","quantity":"0.000"},{"price":"1835.88","quantity":"1.997"},{"price":"1836.14","quantity":"0.169"},{"price":"1836.18","quantity":"0.096"},{"price":"2236.18","quantity":"0.020"},{"price":"2484.56","quantity":"0.021"},{"price":"2635.03","quantity":"0.001"},{"price":"2635.04","quantity":"0.001"},{"price":"2635.12","quantity":"0.000"},{"price":"2635.13","quantity":"0.000"},{"price":"3508.19","quantity":"0.000"}],"raw":{"e":"depthUpdate","E":1783517066254,"T":1783517066253,"s":"ETHUSDT","ps":"ETHUSDT","U":10999770472387,"u":10999770515220,"pu":10999770472217,"b":[["200.00","7.594"],["1216.13","0.064"],["1216.16","5.792"],["1216.22","0.032"],["1216.23","0.032"],["1216.27","0.628"],["1221.16","3.136"],["1562.04","0.168"],["1562.12","0.000"],["1562.20","1.949"],["1562.51","5.636"],["1562.54","0.186"],["1562.55","0.199"],["1562.60","0.014"],["1562.64","0.114"],["1562.65","0.119"],["1635.92","0.000"],["1635.97","0.025"],["1636.06","0.040"],["1636.08","0.000"],["1636.21","0.318"],["1636.22","0.060"],["1636.27","0.114"],["1666.70","0.825"],["1684.94","133.507"],["1701.43","0.142"],["1709.08","14.639"],["1709.42","78.388"],["1721.02","238.098"],["1723.92","0.314"],["1724.12","70.269"],["1724.78","3.254"],["1724.87","154.897"],["1725.58","0.567"],["1725.61","0.084"],["1725.70","151.945"],["1725.79","1.219"],["1726.04","0.653"],["1726.72","12.411"],["1726.74","313.902"],["1726.82","0.763"],["1727.23","0.000"],["1727.47","0.012"],["1728.66","0.225"],["1728.91","0.109"],["1729.04","6.250"],["1729.11","32.814"],["1729.13","4.338"],["1729.24","4.022"],["1729.29","1.669"],["1729.35","4.620"],["1729.57","4.310"],["1729.73","16.409"],["1729.82","4.310"],["1730.01","4.410"],["1730.07","135.808"],["1730.08","26.300"],["1730.09","4.331"],["1730.23","16.323"],["1730.44","4.322"],["1730.45","5.216"],["1730.74","16.553"],["1730.77","23.000"],["1730.78","11.884"],["1731.12","0.000"],["1731.16","5.197"],["1731.21","4.280"],["1731.25","6.640"],["1731.27","4.095"],["1731.31","0.576"],["1731.36","6.627"],["1731.42","4.961"],["1731.44","25.235"],["1731.49","1.184"],["1731.62","0.692"],["1731.63","0.089"],["1731.66","17.452"],["1731.70","16.361"],["1731.73","30.143"],["1731.84","0.133"],["1731.87","194.162"],["1731.91","83.650"],["1732.05","51.914"],["1732.10","77.670"],["1732.16","0.023"],["1732.19","5.100"],["1732.26","20.852"],["1732.27","36.014"],["1732.29","14.787"],["1732.31","73.938"],["1732.43","144.091"],["1732.46","13.098"],["1732.47","22.697"],["1732.51","115.548"],["1732.52","67.230"],["1732.54","10.178"],["1732.55","16.340"],["1732.56","16.669"],["1732.59","27.771"],["1732.61","0.157"],["1732.64","16.727"],["1732.69","0.117"],["1732.70","74.797"],["1732.71","0.446"],["1732.74","0.063"],["1732.77","76.290"],["1732.78","4.644"],["1732.80","18.715"],["1732.87","68.034"],["1733.01","21.655"],["1733.03","63.227"],["1733.04","3.824"],["1733.07","89.080"],["1733.08","0.071"],["1733.10","16.428"],["1733.14","9.356"],["1733.22","7.070"],["1733.23","17.418"],["1733.26","20.811"],["1733.27","28.157"],["1733.28","496.052"],["1733.31","2.028"],["1733.35","17.333"],["1733.40","20.470"],["1733.41","40.697"],["1733.43","0.788"],["1733.47","0.467"],["1733.49","84.409"],["1733.50","13.855"],["1733.51","13.194"],["1733.52","19.248"],["1733.53","19.851"],["1733.57","4.362"],["1733.58","1.782"],["1733.60","0.877"],["1733.61","17.711"],["1733.63","50.351"],["1733.65","9.919"],["1733.67","5.201"],["1733.70","17.168"],["1733.71","84.523"],["1733.76","35.199"],["1733.82","2.563"],["1733.83","18.481"],["1733.89","0.765"],["1733.90","72.148"],["1733.92","17.384"],["1733.93","3.746"],["1733.94","79.580"],["1733.95","3.942"],["1733.96","4.606"],["1734.01","17.457"],["1734.03","44.312"],["1734.04","129.936"],["1734.05","75.860"],["1734.07","2.780"],["1734.08","0.968"],["1734.09","3.015"],["1734.10","68.261"],["1734.12","44.464"],["1734.14","2.735"],["1734.15","0.370"],["1734.18","16.807"],["1734.19","5.955"],["1734.20","97.096"],["1734.24","1.474"],["1734.25","0.024"],["1734.26","0.953"],["1734.27","1.895"],["1734.29","8.551"],["1734.30","21.202"],["1734.31","17.666"],["1734.33","19.646"],["1734.35","8.782"],["1734.37","2.350"],["1734.38","11.407"],["1734.41","80.933"],["1734.42","1.447"],["1734.43","0.384"],["1734.45","0.056"],["1734.46","25.640"],["1734.47","7.314"],["1734.48","18.044"],["1734.49","53.052"],["1734.50","9.297"],["1734.51","12.717"],["1734.52","0.039"],["1734.53","34.922"],["1734.54","18.103"],["1734.55","0.155"],["1734.56","3.980"],["1734.57","29.333"],["1734.62","119.388"],["1734.63","1.527"],["1734.66","11.728"],["1734.67","0.054"],["1734.68","11.509"],["1734.69","0.401"],["1734.72","2.933"],["1734.73","96.801"],["1734.74","10.602"],["1734.75","67.118"],["1734.77","85.150"],["1734.79","7.220"],["1734.82","18.237"],["1734.83","6.689"],["1734.84","272.762"],["1734.85","1.504"],["1734.86","38.363"],["1734.87","16.928"],["1734.88","21.956"],["1734.89","0.389"],["1734.90","19.409"],["1734.91","0.660"],["1734.92","59.567"],["1734.93","60.059"],["1734.94","15.221"],["1734.95","9.713"],["1734.96","5.239"],["1734.97","37.471"],["1734.98","69.905"],["1734.99","1.089"],["1735.00","217.808"],["1735.01","44.586"],["1735.02","49.821"],["1735.03","0.065"],["1735.04","2.899"],["1735.05","3.624"],["1735.06","0.127"],["1735.07","6.745"],["1735.08","6.291"],["1735.09","17.566"],["1735.10","14.675"],["1735.11","37.853"],["1735.12","96.082"],["1735.13","5.217"],["1735.14","8.718"],["1735.15","5.663"],["1735.16","3.924"],["1735.17","1.084"],["1735.18","0.385"],["1735.19","13.415"],["1735.20","8.860"],["1735.21","34.412"],["1735.22","18.033"],["1735.23","6.281"],["1735.24","10.126"],["1735.25","0.874"],["1735.27","70.082"],["1735.28","3.660"],["1735.29","29.646"],["1735.30","29.930"],["1735.31","33.996"],["1735.32","17.078"],["1735.33","16.311"],["1735.34","0.098"],["1735.35","17.776"],["1735.36","3.774"],["1735.37","0.580"],["1735.38","48.687"],["1735.39","0.559"],["1735.40","3.818"],["1735.41","83.496"],["1735.42","16.319"],["1735.43","4.025"],["1735.44","27.398"],["1735.45","0.125"],["1735.46","21.312"],["1735.47","16.697"],["1735.48","0.862"],["1735.49","6.804"],["1735.50","9.853"],["1735.51","51.875"],["1735.52","0.333"],["1735.53","0.774"],["1735.54","4.443"],["1735.55","0.201"],["1735.56","52.070"],["1735.57","1.802"],["1735.58","0.754"],["1735.59","4.353"],["1735.60","0.172"],["1735.61","8.654"],["1735.62","10.466"],["1735.63","0.159"],["1735.64","4.907"],["1735.65","30.180"],["1735.66","20.157"],["1735.67","0.051"],["1735.68","15.158"],["1735.69","0.264"],["1735.70","0.837"],["1735.71","0.038"],["1735.72","90.480"],["1735.73","11.825"],["1735.74","27.064"],["1735.75","2.948"],["1735.76","11.771"],["1735.77","0.138"],["1735.78","0.052"],["1735.79","1.795"],["1735.80","0.159"],["1735.81","4.898"],["1735.82","4.576"],["1735.83","16.561"],["1735.84","0.058"],["1735.85","2.951"],["1735.86","0.048"],["1735.87","4.750"],["1735.88","1.191"],["1735.89","1.068"],["1735.90","6.674"],["1735.91","19.935"],["1735.92","10.528"],["1735.93","0.596"],["1735.94","5.111"],["1735.95","4.891"],["1735.96","0.552"],["1735.97","3.383"],["1735.98","1.941"],["1735.99","1.064"],["1736.00","0.074"],["1736.01","0.050"],["1736.02","0.061"],["1736.03","1.262"],["1736.04","0.024"],["1736.05","0.075"],["1736.06","0.038"],["1736.07","0.048"],["1736.08","1.323"],["1736.09","1.764"],["1736.10","3.736"],["1736.11","0.012"],["1736.12","7.921"],["1736.13","27.898"],["1736.14","0.000"],["1736.15","0.000"],["1736.16","0.000"],["1736.17","0.000"],["1736.18","0.000"],["1736.19","0.000"],["1736.20","0.000"],["1736.21","0.000"],["1736.22","0.000"],["1736.23","0.000"],["1736.24","0.000"],["1736.25","0.000"],["1736.26","0.000"],["1736.27","0.000"],["1736.28","0.000"]],"a":[["1736.14","237.015"],["1736.15","23.318"],["1736.16","0.026"],["1736.17","41.155"],["1736.18","0.029"],["1736.19","6.617"],["1736.20","1.762"],["1736.21","0.000"],["1736.22","6.530"],["1736.23","8.622"],["1736.24","29.227"],["1736.25","6.923"],["1736.26","0.026"],["1736.27","0.014"],["1736.28","75.752"],["1736.29","2.605"],["1736.30","7.293"],["1736.31","0.166"],["1736.32","0.118"],["1736.33","0.012"],["1736.34","0.041"],["1736.35","4.525"],["1736.36","29.473"],["1736.37","8.398"],["1736.38","0.067"],["1736.39","0.038"],["1736.40","18.647"],["1736.41","0.068"],["1736.42","0.038"],["1736.43","6.887"],["1736.44","41.547"],["1736.45","72.394"],["1736.46","46.502"],["1736.47","17.496"],["1736.48","1.719"],["1736.49","2.957"],["1736.50","0.107"],["1736.51","3.065"],["1736.52","0.287"],["1736.53","1.342"],["1736.54","2.889"],["1736.55","6.456"],["1736.56","10.882"],["1736.57","2.094"],["1736.58","1.405"],["1736.59","4.554"],["1736.60","0.768"],["1736.61","11.082"],["1736.62","1.599"],["1736.63","10.299"],["1736.64","71.111"],["1736.65","23.329"],["1736.66","6.530"],["1736.67","3.518"],["1736.68","0.204"],["1736.69","7.376"],["1736.70","48.979"],["1736.71","13.166"],["1736.72","9.524"],["1736.73","2.675"],["1736.74","24.750"],["1736.75","67.315"],["1736.76","24.935"],["1736.77","0.161"],["1736.78","17.781"],["1736.79","23.129"],["1736.80","9.959"],["1736.81","19.120"],["1736.82","18.978"],["1736.83","33.683"],["1736.84","5.057"],["1736.86","4.759"],["1736.87","25.010"],["1736.88","3.380"],["1736.89","8.208"],["1736.90","12.768"],["1736.91","30.676"],["1736.92","67.361"],["1736.93","16.386"],["1736.94","19.272"],["1736.95","0.063"],["1736.96","3.511"],["1736.97","2.975"],["1736.98","5.315"],["1736.99","31.171"],["1737.00","68.401"],["1737.01","74.995"],["1737.02","34.375"],["1737.04","46.112"],["1737.05","0.109"],["1737.06","29.025"],["1737.07","7.916"],["1737.08","9.142"],["1737.09","43.267"],["1737.10","12.251"],["1737.12","5.551"],["1737.13","4.430"],["1737.14","70.120"],["1737.15","0.854"],["1737.16","9.010"],["1737.17","1.661"],["1737.18","22.765"],["1737.19","17.679"],["1737.21","0.022"],["1737.22","1.641"],["1737.23","32.967"],["1737.24","1.151"],["1737.25","71.600"],["1737.26","4.390"],["1737.27","18.856"],["1737.28","0.256"],["1737.30","0.078"],["1737.31","9.427"],["1737.32","9.994"],["1737.33","19.390"],["1737.34","13.215"],["1737.36","68.335"],["1737.37","40.106"],["1737.38","93.231"],["1737.39","69.389"],["1737.41","0.184"],["1737.42","3.675"],["1737.43","8.581"],["1737.44","49.424"],["1737.45","35.003"],["1737.49","35.965"],["1737.51","2.418"],["1737.52","0.026"],["1737.53","2.652"],["1737.55","51.070"],["1737.56","87.491"],["1737.57","134.828"],["1737.58","23.496"],["1737.59","4.188"],["1737.60","4.591"],["1737.61","10.320"],["1737.62","68.826"],["1737.64","25.705"],["1737.65","1.466"],["1737.67","1.336"],["1737.68","0.763"],["1737.70","34.178"],["1737.71","1.736"],["1737.72","51.587"],["1737.73","3.681"],["1737.74","143.144"],["1737.75","16.839"],["1737.78","3.155"],["1737.79","3.555"],["1737.81","16.496"],["1737.82","16.708"],["1737.83","34.798"],["1737.85","0.279"],["1737.87","7.835"],["1737.89","33.409"],["1737.92","92.879"],["1737.99","0.597"],["1738.00","14.410"],["1738.02","4.335"],["1738.04","9.906"],["1738.05","16.399"],["1738.06","13.118"],["1738.08","1.109"],["1738.12","4.331"],["1738.21","0.521"],["1738.23","0.309"],["1738.26","1.023"],["1738.27","21.453"],["1738.31","0.852"],["1738.34","36.769"],["1738.35","46.110"],["1738.41","4.196"],["1738.43","0.012"],["1738.44","2.710"],["1738.45","18.512"],["1738.48","2.878"],["1738.49","19.436"],["1738.53","13.271"],["1738.54","92.362"],["1738.55","408.233"],["1738.56","1.044"],["1738.57","34.780"],["1738.58","83.983"],["1738.61","0.290"],["1738.63","0.000"],["1738.64","7.862"],["1738.65","22.729"],["1738.68","0.120"],["1738.71","38.634"],["1738.78","1.109"],["1738.80","10.921"],["1738.81","9.053"],["1738.83","0.749"],["1738.86","19.557"],["1738.88","1.079"],["1738.89","59.549"],["1738.93","0.047"],["1738.94","3.960"],["1738.95","12.599"],["1738.96","0.000"],["1738.97","181.906"],["1738.98","40.552"],["1738.99","159.773"],["1739.00","2.893"],["1739.03","11.224"],["1739.04","13.978"],["1739.08","13.193"],["1739.19","16.354"],["1739.25","0.037"],["1739.27","7.144"],["1739.30","5.271"],["1739.34","1.094"],["1739.36","3.358"],["1739.42","17.925"],["1739.51","5.793"],["1739.75","0.861"],["1739.81","8.363"],["1739.82","16.241"],["1739.88","16.410"],["1739.93","20.476"],["1739.99","0.299"],["1740.10","17.856"],["1740.17","44.465"],["1740.20","0.082"],["1740.24","223.169"],["1740.25","4.091"],["1740.26","160.339"],["1740.30","6.280"],["1740.32","8.093"],["1740.33","0.084"],["1740.42","9.486"],["1740.43","10.036"],["1740.46","0.000"],["1740.57","16.364"],["1740.61","12.167"],["1740.64","175.715"],["1740.66","14.597"],["1740.71","26.759"],["1740.74","34.522"],["1740.75","0.050"],["1740.80","173.006"],["1740.81","7.153"],["1741.07","4.917"],["1741.19","13.574"],["1741.20","0.628"],["1741.39","71.207"],["1742.43","2.691"],["1742.47","0.012"],["1742.48","22.888"],["1742.53","5.765"],["1743.48","16.023"],["1743.49","26.192"],["1743.50","27.224"],["1743.68","0.777"],["1743.73","0.000"],["1744.56","62.250"],["1744.57","413.276"],["1744.99","0.331"],["1745.53","0.026"],["1746.34","1.349"],["1746.60","0.040"],["1747.12","52.204"],["1749.57","0.047"],["1750.00","224.397"],["1750.18","0.012"],["1751.22","84.048"],["1751.86","10.080"],["1752.75","83.594"],["1753.07","0.031"],["1753.53","0.293"],["1760.58","28.134"],["1763.15","42.522"],["1770.35","0.254"],["1777.88","3.576"],["1777.89","0.012"],["1778.80","75.218"],["1835.77","0.123"],["1835.83","0.000"],["1835.88","1.997"],["1836.14","0.169"],["1836.18","0.096"],["2236.18","0.020"],["2484.56","0.021"],["2635.03","0.001"],["2635.04","0.001"],["2635.12","0.000"],["2635.13","0.000"],["3508.19","0.000"]],"st":1}}
{"schema_version":"1.3.0","event_id":"59d2d6c9-c9dd-432b-9f06-93dec0e11373","event_type":"raw.depth_update","source":"binance_market_data_recorder","venue":"binance_usdm","market_type":"perpetual_futures","symbol":"ETHUSDT","event_time_ms":1783517066356,"received_time_ms":1783517067147,"trace_id":"15dc595a-b504-4476-b056-b95f6b6887fb","first_update_id":10999770515262,"final_update_id":10999770540664,"previous_final_update_id":10999770515220,"bids":[{"price":"200.00","quantity":"7.594"},{"price":"1211.12","quantity":"0.289"},{"price":"1216.12","quantity":"0.160"},{"price":"1216.13","quantity":"0.640"},{"price":"1216.27","quantity":"0.532"},{"price":"1221.16","quantity":"2.400"},{"price":"1562.50","quantity":"1.060"},{"price":"1562.51","quantity":"5.880"},{"price":"1562.52","quantity":"0.000"},{"price":"1667.58","quantity":"0.060"},{"price":"1693.39","quantity":"0.000"},{"price":"1700.44","quantity":"29.399"},{"price":"1704.88","quantity":"40.317"},{"price":"1710.75","quantity":"43.994"},{"price":"1724.90","quantity":"43.360"},{"price":"1725.72","quantity":"60.118"},{"price":"1726.10","quantity":"2.608"},{"price":"1726.83","quantity":"46.883"},{"price":"1727.44","quantity":"0.024"},{"price":"1729.13","quantity":"0.028"},{"price":"1729.35","quantity":"0.310"},{"price":"1729.57","quantity":"0.000"},{"price":"1730.01","quantity":"21.644"},{"price":"1730.23","quantity":"33.557"},{"price":"1730.26","quantity":"5.916"},{"price":"1731.24","quantity":"223.992"},{"price":"1731.26","quantity":"4.677"},{"price":"1731.33","quantity":"19.266"},{"price":"1731.40","quantity":"7.047"},{"price":"1731.41","quantity":"43.977"},{"price":"1731.51","quantity":"1.976"},{"price":"1731.84","quantity":"0.118"},{"price":"1731.91","quantity":"16.420"},{"price":"1731.94","quantity":"0.042"},{"price":"1731.96","quantity":"108.350"},{"price":"1732.05","quantity":"51.899"},{"price":"1732.10","quantity":"10.440"},{"price":"1732.28","quantity":"16.371"},{"price":"1732.29","quantity":"0.493"},{"price":"1732.30","quantity":"172.874"},{"price":"1732.31","quantity":"6.708"},{"price":"1732.32","quantity":"135.425"},{"price":"1732.50","quantity":"54.587"},{"price":"1732.53","quantity":"1.871"},{"price":"1732.63","quantity":"0.876"},{"price":"1732.72","quantity":"22.451"},{"price":"1732.95","quantity":"24.467"},{"price":"1733.13","quantity":"30.371"},{"price":"1733.23","quantity":"17.236"},{"price":"1733.27","quantity":"0.012"},{"price":"1733.28","quantity":"67.245"},{"price":"1733.29","quantity":"24.558"},{"price":"1733.30","quantity":"24.381"},{"price":"1733.32","quantity":"4.367"},{"price":"1733.34","quantity":"0.000"},{"price":"1733.36","quantity":"20.130"},{"price":"1733.39","quantity":"22.071"},{"price":"1733.42","quantity":"5.753"},{"price":"1733.44","quantity":"10.089"},{"price":"1733.53","quantity":"429.699"},{"price":"1733.54","quantity":"83.739"},{"price":"1733.63","quantity":"51.010"},{"price":"1733.70","quantity":"16.600"},{"price":"1733.71","quantity":"85.123"},{"price":"1733.74","quantity":"15.812"},{"price":"1733.82","quantity":"2.575"},{"price":"1733.83","quantity":"0.562"},{"price":"1733.85","quantity":"65.288"},{"price":"1733.86","quantity":"2.091"},{"price":"1733.94","quantity":"29.283"},{"price":"1733.98","quantity":"0.245"},{"price":"1734.01","quantity":"17.457"},{"price":"1734.04","quantity":"125.012"},{"price":"1734.18","quantity":"0.012"},{"price":"1734.19","quantity":"5.021"},{"price":"1734.21","quantity":"19.027"},{"price":"1734.22","quantity":"17.049"},{"price":"1734.24","quantity":"1.874"},{"price":"1734.25","quantity":"0.059"},{"price":"1734.26","quantity":"0.703"},{"price":"1734.27","quantity":"0.449"},{"price":"1734.30","quantity":"21.202"},{"price":"1734.32","quantity":"231.107"},{"price":"1734.33","quantity":"19.958"},{"price":"1734.35","quantity":"8.782"},{"price":"1734.36","quantity":"43.618"},{"price":"1734.37","quantity":"0.150"},{"price":"1734.42","quantity":"3.047"},{"price":"1734.43","quantity":"1.184"},{"price":"1734.45","quantity":"0.056"},{"price":"1734.46","quantity":"51.458"},{"price":"1734.47","quantity":"4.441"},{"price":"1734.48","quantity":"18.044"},{"price":"1734.49","quantity":"53.052"},{"price":"1734.50","quantity":"9.332"},{"price":"1734.51","quantity":"12.717"},{"price":"1734.52","quantity":"1.949"},{"price":"1734.53","quantity":"255.759"},{"price":"1734.54","quantity":"17.767"},{"price":"1734.55","quantity":"0.955"},{"price":"1734.57","quantity":"29.333"},{"price":"1734.59","quantity":"1.211"},{"price":"1734.62","quantity":"119.388"},{"price":"1734.63","quantity":"19.810"},{"price":"1734.65","quantity":"13.647"},{"price":"1734.66","quantity":"1.206"},{"price":"1734.68","quantity":"8.509"},{"price":"1734.70","quantity":"0.870"},{"price":"1734.73","quantity":"97.067"},{"price":"1734.75","quantity":"68.153"},{"price":"1734.77","quantity":"84.150"},{"price":"1734.79","quantity":"8.220"},{"price":"1734.81","quantity":"19.072"},{"price":"1734.82","quantity":"18.237"},{"price":"1734.83","quantity":"8.889"},{"price":"1734.84","quantity":"272.072"},{"price":"1734.86","quantity":"38.717"},{"price":"1734.87","quantity":"19.856"},{"price":"1734.88","quantity":"59.458"},{"price":"1734.89","quantity":"0.168"},{"price":"1734.90","quantity":"19.409"},{"price":"1734.92","quantity":"58.981"},{"price":"1734.93","quantity":"63.524"},{"price":"1734.94","quantity":"12.464"},{"price":"1734.99","quantity":"0.689"},{"price":"1735.00","quantity":"217.843"},{"price":"1735.01","quantity":"44.586"},{"price":"1735.02","quantity":"50.511"},{"price":"1735.03","quantity":"0.065"},{"price":"1735.04","quantity":"2.899"},{"price":"1735.05","quantity":"1.232"},{"price":"1735.06","quantity":"0.927"},{"price":"1735.08","quantity":"6.025"},{"price":"1735.09","quantity":"1.235"},{"price":"1735.11","quantity":"44.136"},{"price":"1735.13","quantity":"1.559"},{"price":"1735.15","quantity":"47.601"},{"price":"1735.16","quantity":"3.909"},{"price":"1735.19","quantity":"70.115"},{"price":"1735.20","quantity":"45.938"},{"price":"1735.21","quantity":"34.467"},{"price":"1735.22","quantity":"16.287"},{"price":"1735.23","quantity":"5.796"},{"price":"1735.24","quantity":"8.926"},{"price":"1735.25","quantity":"0.769"},{"price":"1735.26","quantity":"0.038"},{"price":"1735.27","quantity":"70.102"},{"price":"1735.28","quantity":"4.962"},{"price":"1735.32","quantity":"26.988"},{"price":"1735.33","quantity":"16.311"},{"price":"1735.37","quantity":"0.752"},{"price":"1735.38","quantity":"65.064"},{"price":"1735.39","quantity":"0.541"},{"price":"1735.41","quantity":"124.157"},{"price":"1735.42","quantity":"20.611"},{"price":"1735.43","quantity":"4.041"},{"price":"1735.44","quantity":"27.461"},{"price":"1735.45","quantity":"0.166"},{"price":"1735.47","quantity":"17.509"},{"price":"1735.48","quantity":"0.874"},{"price":"1735.49","quantity":"7.056"},{"price":"1735.50","quantity":"18.754"},{"price":"1735.51","quantity":"58.185"},{"price":"1735.52","quantity":"77.458"},{"price":"1735.53","quantity":"5.205"},{"price":"1735.54","quantity":"5.779"},{"price":"1735.55","quantity":"4.511"},{"price":"1735.56","quantity":"28.286"},{"price":"1735.57","quantity":"1.802"},{"price":"1735.58","quantity":"0.766"},{"price":"1735.59","quantity":"4.353"},{"price":"1735.60","quantity":"33.449"},{"price":"1735.61","quantity":"8.709"},{"price":"1735.63","quantity":"0.576"},{"price":"1735.64","quantity":"76.667"},{"price":"1735.65","quantity":"20.560"},{"price":"1735.66","quantity":"0.157"},{"price":"1735.67","quantity":"1.451"},{"price":"1735.69","quantity":"4.767"},{"price":"1735.70","quantity":"0.037"},{"price":"1735.72","quantity":"89.558"},{"price":"1735.73","quantity":"26.847"},{"price":"1735.74","quantity":"27.864"},{"price":"1735.75","quantity":"86.033"},{"price":"1735.76","quantity":"5.511"},{"price":"1735.77","quantity":"22.995"},{"price":"1735.78","quantity":"21.175"},{"price":"1735.79","quantity":"1.795"},{"price":"1735.80","quantity":"0.242"},{"price":"1735.81","quantity":"5.186"},{"price":"1735.82","quantity":"14.191"},{"price":"1735.83","quantity":"28.903"},{"price":"1735.84","quantity":"5.090"},{"price":"1735.85","quantity":"6.839"},{"price":"1735.86","quantity":"1.148"},{"price":"1735.87","quantity":"0.220"},{"price":"1735.88","quantity":"22.221"},{"price":"1735.89","quantity":"1.159"},{"price":"1735.90","quantity":"3.012"},{"price":"1735.91","quantity":"12.427"},{"price":"1735.92","quantity":"9.714"},{"price":"1735.93","quantity":"0.197"},{"price":"1735.94","quantity":"3.711"},{"price":"1735.95","quantity":"0.074"},{"price":"1735.96","quantity":"2.280"},{"price":"1735.98","quantity":"3.677"},{"price":"1735.99","quantity":"0.052"},{"price":"1736.00","quantity":"1.084"},{"price":"1736.01","quantity":"0.038"},{"price":"1736.02","quantity":"0.049"},{"price":"1736.03","quantity":"0.050"},{"price":"1736.04","quantity":"0.012"},{"price":"1736.05","quantity":"0.051"},{"price":"1736.06","quantity":"0.014"},{"price":"1736.07","quantity":"0.048"},{"price":"1736.08","quantity":"0.709"},{"price":"1736.09","quantity":"0.669"},{"price":"1736.10","quantity":"3.722"},{"price":"1736.11","quantity":"0.029"},{"price":"1736.12","quantity":"75.293"},{"price":"1736.13","quantity":"0.000"}],"asks":[{"price":"1736.13","quantity":"347.586"},{"price":"1736.14","quantity":"0.040"},{"price":"1736.15","quantity":"0.000"},{"price":"1736.16","quantity":"0.538"},{"price":"1736.17","quantity":"0.024"},{"price":"1736.18","quantity":"0.036"},{"price":"1736.19","quantity":"0.300"},{"price":"1736.20","quantity":"2.807"},{"price":"1736.21","quantity":"1.740"},{"price":"1736.22","quantity":"20.724"},{"price":"1736.23","quantity":"3.275"},{"price":"1736.24","quantity":"29.245"},{"price":"1736.25","quantity":"2.800"},{"price":"1736.27","quantity":"11.637"},{"price":"1736.28","quantity":"44.020"},{"price":"1736.29","quantity":"1.164"},{"price":"1736.30","quantity":"11.736"},{"price":"1736.31","quantity":"89.094"},{"price":"1736.32","quantity":"0.176"},{"price":"1736.33","quantity":"0.012"},{"price":"1736.34","quantity":"28.865"},{"price":"1736.35","quantity":"4.525"},{"price":"1736.36","quantity":"0.548"},{"price":"1736.37","quantity":"9.021"},{"price":"1736.38","quantity":"0.256"},{"price":"1736.39","quantity":"0.098"},{"price":"1736.40","quantity":"18.642"},{"price":"1736.41","quantity":"9.520"},{"price":"1736.42","quantity":"3.358"},{"price":"1736.43","quantity":"29.927"},{"price":"1736.44","quantity":"9.485"},{"price":"1736.45","quantity":"74.946"},{"price":"1736.46","quantity":"43.794"},{"price":"1736.47","quantity":"13.186"},{"price":"1736.48","quantity":"7.730"},{"price":"1736.49","quantity":"3.215"},{"price":"1736.50","quantity":"0.090"},{"price":"1736.52","quantity":"0.087"},{"price":"1736.53","quantity":"1.419"},{"price":"1736.54","quantity":"2.869"},{"price":"1736.55","quantity":"31.365"},{"price":"1736.58","quantity":"1.665"},{"price":"1736.59","quantity":"8.864"},{"price":"1736.60","quantity":"5.067"},{"price":"1736.62","quantity":"1.645"},{"price":"1736.63","quantity":"6.912"},{"price":"1736.64","quantity":"76.115"},{"price":"1736.65","quantity":"23.605"},{"price":"1736.66","quantity":"3.202"},{"price":"1736.67","quantity":"42.423"},{"price":"1736.68","quantity":"4.735"},{"price":"1736.69","quantity":"7.376"},{"price":"1736.70","quantity":"11.534"},{"price":"1736.71","quantity":"1.647"},{"price":"1736.72","quantity":"9.617"},{"price":"1736.73","quantity":"6.985"},{"price":"1736.74","quantity":"41.426"},{"price":"1736.75","quantity":"97.173"},{"price":"1736.76","quantity":"18.794"},{"price":"1736.79","quantity":"23.148"},{"price":"1736.80","quantity":"4.218"},{"price":"1736.81","quantity":"19.320"},{"price":"1736.82","quantity":"57.462"},{"price":"1736.83","quantity":"33.747"},{"price":"1736.84","quantity":"5.057"},{"price":"1736.86","quantity":"46.430"},{"price":"1736.87","quantity":"25.010"},{"price":"1736.88","quantity":"3.731"},{"price":"1736.89","quantity":"8.553"},{"price":"1736.90","quantity":"29.164"},{"price":"1736.91","quantity":"30.664"},{"price":"1736.92","quantity":"78.863"},{"price":"1736.93","quantity":"16.374"},{"price":"1736.94","quantity":"19.401"},{"price":"1736.95","quantity":"0.434"},{"price":"1736.96","quantity":"3.499"},{"price":"1736.97","quantity":"2.963"},{"price":"1736.98","quantity":"13.096"},{"price":"1736.99","quantity":"24.442"},{"price":"1737.00","quantity":"57.866"},{"price":"1737.02","quantity":"23.872"},{"price":"1737.03","quantity":"85.611"},{"price":"1737.04","quantity":"99.212"},{"price":"1737.06","quantity":"23.938"},{"price":"1737.07","quantity":"7.358"},{"price":"1737.08","quantity":"9.141"},{"price":"1737.09","quantity":"43.267"},{"price":"1737.12","quantity":"5.651"},{"price":"1737.13","quantity":"4.987"},{"price":"1737.16","quantity":"9.170"},{"price":"1737.17","quantity":"1.620"},{"price":"1737.18","quantity":"23.455"},{"price":"1737.19","quantity":"6.167"},{"price":"1737.20","quantity":"26.327"},{"price":"1737.22","quantity":"1.835"},{"price":"1737.23","quantity":"32.967"},{"price":"1737.24","quantity":"0.141"},{"price":"1737.25","quantity":"72.370"},{"price":"1737.26","quantity":"5.190"},{"price":"1737.27","quantity":"20.256"},{"price":"1737.30","quantity":"0.435"},{"price":"1737.33","quantity":"19.563"},{"price":"1737.35","quantity":"38.543"},{"price":"1737.36","quantity":"70.002"},{"price":"1737.38","quantity":"90.231"},{"price":"1737.40","quantity":"32.884"},{"price":"1737.44","quantity":"46.784"},{"price":"1737.45","quantity":"34.233"},{"price":"1737.50","quantity":"67.937"},{"price":"1737.51","quantity":"0.218"},{"price":"1737.53","quantity":"0.012"},{"price":"1737.55","quantity":"51.056"},{"price":"1737.56","quantity":"89.012"},{"price":"1737.57","quantity":"134.845"},{"price":"1737.58","quantity":"22.806"},{"price":"1737.59","quantity":"3.831"},{"price":"1737.62","quantity":"68.808"},{"price":"1737.68","quantity":"0.970"},{"price":"1737.72","quantity":"40.016"},{"price":"1737.74","quantity":"83.465"},{"price":"1737.75","quantity":"15.839"},{"price":"1737.76","quantity":"14.004"},{"price":"1737.77","quantity":"4.618"},{"price":"1737.78","quantity":"4.822"},{"price":"1737.81","quantity":"31.808"},{"price":"1737.83","quantity":"34.780"},{"price":"1737.84","quantity":"73.782"},{"price":"1737.87","quantity":"19.322"},{"price":"1737.89","quantity":"7.279"},{"price":"1737.95","quantity":"89.115"},{"price":"1738.00","quantity":"30.118"},{"price":"1738.01","quantity":"37.396"},{"price":"1738.04","quantity":"0.239"},{"price":"1738.05","quantity":"16.400"},{"price":"1738.09","quantity":"0.252"},{"price":"1738.16","quantity":"67.260"},{"price":"1738.33","quantity":"0.053"},{"price":"1738.34","quantity":"18.144"},{"price":"1738.39","quantity":"18.268"},{"price":"1738.45","quantity":"1.836"},{"price":"1738.46","quantity":"35.681"},{"price":"1738.53","quantity":"20.776"},{"price":"1738.54","quantity":"95.558"},{"price":"1738.56","quantity":"4.240"},{"price":"1738.57","quantity":"36.248"},{"price":"1738.65","quantity":"22.477"},{"price":"1738.68","quantity":"0.108"},{"price":"1738.70","quantity":"0.197"},{"price":"1738.71","quantity":"35.150"},{"price":"1738.72","quantity":"54.567"},{"price":"1738.74","quantity":"0.752"},{"price":"1738.78","quantity":"1.109"},{"price":"1738.79","quantity":"83.666"},{"price":"1738.80","quantity":"4.943"},{"price":"1738.82","quantity":"5.011"},{"price":"1738.85","quantity":"3.921"},{"price":"1738.86","quantity":"2.881"},{"price":"1739.09","quantity":"0.856"},{"price":"1739.30","quantity":"3.887"},{"price":"1739.38","quantity":"10.084"},{"price":"1739.41","quantity":"6.891"},{"price":"1739.42","quantity":"17.925"},{"price":"1739.62","quantity":"23.603"},{"price":"1739.64","quantity":"93.540"},{"price":"1739.70","quantity":"34.145"},{"price":"1739.76","quantity":"177.848"},{"price":"1739.94","quantity":"2.045"},{"price":"1739.98","quantity":"12.540"},{"price":"1740.06","quantity":"14.476"},{"price":"1740.08","quantity":"0.000"},{"price":"1740.09","quantity":"32.626"},{"price":"1740.23","quantity":"176.638"},{"price":"1740.24","quantity":"50.385"},{"price":"1740.30","quantity":"19.737"},{"price":"1740.60","quantity":"58.931"},{"price":"1740.62","quantity":"1.235"},{"price":"1740.69","quantity":"189.824"},{"price":"1740.78","quantity":"14.288"},{"price":"1740.80","quantity":"0.222"},{"price":"1741.14","quantity":"95.834"},{"price":"1742.44","quantity":"5.839"},{"price":"1744.86","quantity":"40.373"},{"price":"1753.53","quantity":"0.293"},{"price":"1767.53","quantity":"73.466"},{"price":"1835.77","quantity":"0.103"},{"price":"1835.78","quantity":"0.039"},{"price":"1836.13","quantity":"0.035"},{"price":"1836.14","quantity":"0.189"},{"price":"2480.19","quantity":"0.036"},{"price":"2635.01","quantity":"0.001"},{"price":"2635.02","quantity":"0.001"},{"price":"2635.10","quantity":"0.000"},{"price":"2635.11","quantity":"0.000"},{"price":"3472.27","quantity":"0.009"}],"raw":{"e":"depthUpdate","E":1783517066356,"T":1783517066355,"s":"ETHUSDT","ps":"ETHUSDT","U":10999770515262,"u":10999770540664,"pu":10999770515220,"b":[["200.00","7.594"],["1211.12","0.289"],["1216.12","0.160"],["1216.13","0.640"],["1216.27","0.532"],["1221.16","2.400"],["1562.50","1.060"],["1562.51","5.880"],["1562.52","0.000"],["1667.58","0.060"],["1693.39","0.000"],["1700.44","29.399"],["1704.88","40.317"],["1710.75","43.994"],["1724.90","43.360"],["1725.72","60.118"],["1726.10","2.608"],["1726.83","46.883"],["1727.44","0.024"],["1729.13","0.028"],["1729.35","0.310"],["1729.57","0.000"],["1730.01","21.644"],["1730.23","33.557"],["1730.26","5.916"],["1731.24","223.992"],["1731.26","4.677"],["1731.33","19.266"],["1731.40","7.047"],["1731.41","43.977"],["1731.51","1.976"],["1731.84","0.118"],["1731.91","16.420"],["1731.94","0.042"],["1731.96","108.350"],["1732.05","51.899"],["1732.10","10.440"],["1732.28","16.371"],["1732.29","0.493"],["1732.30","172.874"],["1732.31","6.708"],["1732.32","135.425"],["1732.50","54.587"],["1732.53","1.871"],["1732.63","0.876"],["1732.72","22.451"],["1732.95","24.467"],["1733.13","30.371"],["1733.23","17.236"],["1733.27","0.012"],["1733.28","67.245"],["1733.29","24.558"],["1733.30","24.381"],["1733.32","4.367"],["1733.34","0.000"],["1733.36","20.130"],["1733.39","22.071"],["1733.42","5.753"],["1733.44","10.089"],["1733.53","429.699"],["1733.54","83.739"],["1733.63","51.010"],["1733.70","16.600"],["1733.71","85.123"],["1733.74","15.812"],["1733.82","2.575"],["1733.83","0.562"],["1733.85","65.288"],["1733.86","2.091"],["1733.94","29.283"],["1733.98","0.245"],["1734.01","17.457"],["1734.04","125.012"],["1734.18","0.012"],["1734.19","5.021"],["1734.21","19.027"],["1734.22","17.049"],["1734.24","1.874"],["1734.25","0.059"],["1734.26","0.703"],["1734.27","0.449"],["1734.30","21.202"],["1734.32","231.107"],["1734.33","19.958"],["1734.35","8.782"],["1734.36","43.618"],["1734.37","0.150"],["1734.42","3.047"],["1734.43","1.184"],["1734.45","0.056"],["1734.46","51.458"],["1734.47","4.441"],["1734.48","18.044"],["1734.49","53.052"],["1734.50","9.332"],["1734.51","12.717"],["1734.52","1.949"],["1734.53","255.759"],["1734.54","17.767"],["1734.55","0.955"],["1734.57","29.333"],["1734.59","1.211"],["1734.62","119.388"],["1734.63","19.810"],["1734.65","13.647"],["1734.66","1.206"],["1734.68","8.509"],["1734.70","0.870"],["1734.73","97.067"],["1734.75","68.153"],["1734.77","84.150"],["1734.79","8.220"],["1734.81","19.072"],["1734.82","18.237"],["1734.83","8.889"],["1734.84","272.072"],["1734.86","38.717"],["1734.87","19.856"],["1734.88","59.458"],["1734.89","0.168"],["1734.90","19.409"],["1734.92","58.981"],["1734.93","63.524"],["1734.94","12.464"],["1734.99","0.689"],["1735.00","217.843"],["1735.01","44.586"],["1735.02","50.511"],["1735.03","0.065"],["1735.04","2.899"],["1735.05","1.232"],["1735.06","0.927"],["1735.08","6.025"],["1735.09","1.235"],["1735.11","44.136"],["1735.13","1.559"],["1735.15","47.601"],["1735.16","3.909"],["1735.19","70.115"],["1735.20","45.938"],["1735.21","34.467"],["1735.22","16.287"],["1735.23","5.796"],["1735.24","8.926"],["1735.25","0.769"],["1735.26","0.038"],["1735.27","70.102"],["1735.28","4.962"],["1735.32","26.988"],["1735.33","16.311"],["1735.37","0.752"],["1735.38","65.064"],["1735.39","0.541"],["1735.41","124.157"],["1735.42","20.611"],["1735.43","4.041"],["1735.44","27.461"],["1735.45","0.166"],["1735.47","17.509"],["1735.48","0.874"],["1735.49","7.056"],["1735.50","18.754"],["1735.51","58.185"],["1735.52","77.458"],["1735.53","5.205"],["1735.54","5.779"],["1735.55","4.511"],["1735.56","28.286"],["1735.57","1.802"],["1735.58","0.766"],["1735.59","4.353"],["1735.60","33.449"],["1735.61","8.709"],["1735.63","0.576"],["1735.64","76.667"],["1735.65","20.560"],["1735.66","0.157"],["1735.67","1.451"],["1735.69","4.767"],["1735.70","0.037"],["1735.72","89.558"],["1735.73","26.847"],["1735.74","27.864"],["1735.75","86.033"],["1735.76","5.511"],["1735.77","22.995"],["1735.78","21.175"],["1735.79","1.795"],["1735.80","0.242"],["1735.81","5.186"],["1735.82","14.191"],["1735.83","28.903"],["1735.84","5.090"],["1735.85","6.839"],["1735.86","1.148"],["1735.87","0.220"],["1735.88","22.221"],["1735.89","1.159"],["1735.90","3.012"],["1735.91","12.427"],["1735.92","9.714"],["1735.93","0.197"],["1735.94","3.711"],["1735.95","0.074"],["1735.96","2.280"],["1735.98","3.677"],["1735.99","0.052"],["1736.00","1.084"],["1736.01","0.038"],["1736.02","0.049"],["1736.03","0.050"],["1736.04","0.012"],["1736.05","0.051"],["1736.06","0.014"],["1736.07","0.048"],["1736.08","0.709"],["1736.09","0.669"],["1736.10","3.722"],["1736.11","0.029"],["1736.12","75.293"],["1736.13","0.000"]],"a":[["1736.13","347.586"],["1736.14","0.040"],["1736.15","0.000"],["1736.16","0.538"],["1736.17","0.024"],["1736.18","0.036"],["1736.19","0.300"],["1736.20","2.807"],["1736.21","1.740"],["1736.22","20.724"],["1736.23","3.275"],["1736.24","29.245"],["1736.25","2.800"],["1736.27","11.637"],["1736.28","44.020"],["1736.29","1.164"],["1736.30","11.736"],["1736.31","89.094"],["1736.32","0.176"],["1736.33","0.012"],["1736.34","28.865"],["1736.35","4.525"],["1736.36","0.548"],["1736.37","9.021"],["1736.38","0.256"],["1736.39","0.098"],["1736.40","18.642"],["1736.41","9.520"],["1736.42","3.358"],["1736.43","29.927"],["1736.44","9.485"],["1736.45","74.946"],["1736.46","43.794"],["1736.47","13.186"],["1736.48","7.730"],["1736.49","3.215"],["1736.50","0.090"],["1736.52","0.087"],["1736.53","1.419"],["1736.54","2.869"],["1736.55","31.365"],["1736.58","1.665"],["1736.59","8.864"],["1736.60","5.067"],["1736.62","1.645"],["1736.63","6.912"],["1736.64","76.115"],["1736.65","23.605"],["1736.66","3.202"],["1736.67","42.423"],["1736.68","4.735"],["1736.69","7.376"],["1736.70","11.534"],["1736.71","1.647"],["1736.72","9.617"],["1736.73","6.985"],["1736.74","41.426"],["1736.75","97.173"],["1736.76","18.794"],["1736.79","23.148"],["1736.80","4.218"],["1736.81","19.320"],["1736.82","57.462"],["1736.83","33.747"],["1736.84","5.057"],["1736.86","46.430"],["1736.87","25.010"],["1736.88","3.731"],["1736.89","8.553"],["1736.90","29.164"],["1736.91","30.664"],["1736.92","78.863"],["1736.93","16.374"],["1736.94","19.401"],["1736.95","0.434"],["1736.96","3.499"],["1736.97","2.963"],["1736.98","13.096"],["1736.99","24.442"],["1737.00","57.866"],["1737.02","23.872"],["1737.03","85.611"],["1737.04","99.212"],["1737.06","23.938"],["1737.07","7.358"],["1737.08","9.141"],["1737.09","43.267"],["1737.12","5.651"],["1737.13","4.987"],["1737.16","9.170"],["1737.17","1.620"],["1737.18","23.455"],["1737.19","6.167"],["1737.20","26.327"],["1737.22","1.835"],["1737.23","32.967"],["1737.24","0.141"],["1737.25","72.370"],["1737.26","5.190"],["1737.27","20.256"],["1737.30","0.435"],["1737.33","19.563"],["1737.35","38.543"],["1737.36","70.002"],["1737.38","90.231"],["1737.40","32.884"],["1737.44","46.784"],["1737.45","34.233"],["1737.50","67.937"],["1737.51","0.218"],["1737.53","0.012"],["1737.55","51.056"],["1737.56","89.012"],["1737.57","134.845"],["1737.58","22.806"],["1737.59","3.831"],["1737.62","68.808"],["1737.68","0.970"],["1737.72","40.016"],["1737.74","83.465"],["1737.75","15.839"],["1737.76","14.004"],["1737.77","4.618"],["1737.78","4.822"],["1737.81","31.808"],["1737.83","34.780"],["1737.84","73.782"],["1737.87","19.322"],["1737.89","7.279"],["1737.95","89.115"],["1738.00","30.118"],["1738.01","37.396"],["1738.04","0.239"],["1738.05","16.400"],["1738.09","0.252"],["1738.16","67.260"],["1738.33","0.053"],["1738.34","18.144"],["1738.39","18.268"],["1738.45","1.836"],["1738.46","35.681"],["1738.53","20.776"],["1738.54","95.558"],["1738.56","4.240"],["1738.57","36.248"],["1738.65","22.477"],["1738.68","0.108"],["1738.70","0.197"],["1738.71","35.150"],["1738.72","54.567"],["1738.74","0.752"],["1738.78","1.109"],["1738.79","83.666"],["1738.80","4.943"],["1738.82","5.011"],["1738.85","3.921"],["1738.86","2.881"],["1739.09","0.856"],["1739.30","3.887"],["1739.38","10.084"],["1739.41","6.891"],["1739.42","17.925"],["1739.62","23.603"],["1739.64","93.540"],["1739.70","34.145"],["1739.76","177.848"],["1739.94","2.045"],["1739.98","12.540"],["1740.06","14.476"],["1740.08","0.000"],["1740.09","32.626"],["1740.23","176.638"],["1740.24","50.385"],["1740.30","19.737"],["1740.60","58.931"],["1740.62","1.235"],["1740.69","189.824"],["1740.78","14.288"],["1740.80","0.222"],["1741.14","95.834"],["1742.44","5.839"],["1744.86","40.373"],["1753.53","0.293"],["1767.53","73.466"],["1835.77","0.103"],["1835.78","0.039"],["1836.13","0.035"],["1836.14","0.189"],["2480.19","0.036"],["2635.01","0.001"],["2635.02","0.001"],["2635.10","0.000"],["2635.11","0.000"],["3472.27","0.009"]],"st":1}}
{"schema_version":"1.3.0","event_id":"980dcaa6-38df-448d-91a0-dcc8ef203491","event_type":"raw.depth_update","source":"binance_market_data_recorder","venue":"binance_usdm","market_type":"perpetual_futures","symbol":"ETHUSDT","event_time_ms":1783517066458,"received_time_ms":1783517067172,"trace_id":"398b574a-a448-46db-bfc4-d9ecbeceea5c","first_update_id":10999770540675,"final_update_id":10999770552351,"previous_final_update_id":10999770540664,"bids":[{"price":"1211.12","quantity":"0.577"},{"price":"1216.12","quantity":"0.704"},{"price":"1216.16","quantity":"5.632"},{"price":"1216.22","quantity":"0.000"},{"price":"1216.23","quantity":"0.000"},{"price":"1216.27","quantity":"0.468"},{"price":"1221.16","quantity":"1.856"},{"price":"1562.50","quantity":"1.060"},{"price":"1562.51","quantity":"6.520"},{"price":"1666.60","quantity":"1.193"},{"price":"1701.40","quantity":"0.402"},{"price":"1702.49","quantity":"34.934"},{"price":"1702.64","quantity":"0.030"},{"price":"1703.17","quantity":"27.177"},{"price":"1708.84","quantity":"0.033"},{"price":"1711.63","quantity":"46.492"},{"price":"1721.37","quantity":"87.996"},{"price":"1729.11","quantity":"34.452"},{"price":"1729.29","quantity":"0.031"},{"price":"1731.16","quantity":"5.197"},{"price":"1731.24","quantity":"224.004"},{"price":"1733.05","quantity":"2.031"},{"price":"1733.53","quantity":"0.892"},{"price":"1733.54","quantity":"0.099"},{"price":"1733.65","quantity":"9.919"},{"price":"1733.66","quantity":"23.837"},{"price":"1733.71","quantity":"84.523"},{"price":"1733.74","quantity":"16.412"},{"price":"1733.82","quantity":"2.575"},{"price":"1733.85","quantity":"128.008"},{"price":"1733.89","quantity":"429.572"},{"price":"1734.24","quantity":"1.474"},{"price":"1734.32","quantity":"11.558"},{"price":"1734.33","quantity":"19.867"},{"price":"1734.36","quantity":"13.419"},{"price":"1734.37","quantity":"0.950"},{"price":"1734.38","quantity":"11.389"},{"price":"1734.39","quantity":"240.097"},{"price":"1734.40","quantity":"4.555"},{"price":"1734.42","quantity":"2.247"},{"price":"1734.43","quantity":"0.384"},{"price":"1734.45","quantity":"0.038"},{"price":"1734.46","quantity":"51.590"},{"price":"1734.49","quantity":"53.070"},{"price":"1734.51","quantity":"232.678"},{"price":"1734.53","quantity":"35.877"},{"price":"1734.56","quantity":"3.962"},{"price":"1734.57","quantity":"29.351"},{"price":"1734.58","quantity":"0.519"},{"price":"1734.61","quantity":"0.240"},{"price":"1734.65","quantity":"13.554"},{"price":"1734.70","quantity":"0.670"},{"price":"1734.82","quantity":"18.237"},{"price":"1734.83","quantity":"6.689"},{"price":"1734.84","quantity":"272.072"},{"price":"1734.87","quantity":"19.838"},{"price":"1734.88","quantity":"59.476"},{"price":"1735.01","quantity":"19.586"},{"price":"1735.10","quantity":"14.768"},{"price":"1735.12","quantity":"95.482"},{"price":"1735.15","quantity":"5.663"},{"price":"1735.16","quantity":"4.509"},{"price":"1735.17","quantity":"3.284"},{"price":"1735.22","quantity":"16.399"},{"price":"1735.25","quantity":"39.105"},{"price":"1735.31","quantity":"33.996"},{"price":"1735.35","quantity":"20.776"},{"price":"1735.37","quantity":"0.583"},{"price":"1735.43","quantity":"4.210"},{"price":"1735.46","quantity":"21.324"},{"price":"1735.51","quantity":"58.285"},{"price":"1735.59","quantity":"4.365"},{"price":"1735.60","quantity":"4.613"},{"price":"1735.61","quantity":"17.408"},{"price":"1735.63","quantity":"29.411"},{"price":"1735.65","quantity":"20.560"},{"price":"1735.66","quantity":"0.157"},{"price":"1735.73","quantity":"27.647"},{"price":"1735.74","quantity":"28.064"},{"price":"1735.76","quantity":"2.001"},{"price":"1735.77","quantity":"23.595"},{"price":"1735.78","quantity":"21.763"},{"price":"1735.79","quantity":"7.539"},{"price":"1735.81","quantity":"5.646"},{"price":"1735.83","quantity":"20.204"},{"price":"1735.84","quantity":"4.090"},{"price":"1735.85","quantity":"6.839"},{"price":"1735.88","quantity":"0.036"},{"price":"1735.89","quantity":"23.252"},{"price":"1735.91","quantity":"15.361"},{"price":"1735.92","quantity":"9.819"},{"price":"1735.93","quantity":"0.176"},{"price":"1735.94","quantity":"3.729"},{"price":"1735.98","quantity":"3.764"},{"price":"1736.00","quantity":"1.096"},{"price":"1736.01","quantity":"0.050"},{"price":"1736.05","quantity":"0.063"},{"price":"1736.06","quantity":"0.026"},{"price":"1736.08","quantity":"0.723"},{"price":"1736.10","quantity":"3.736"},{"price":"1736.12","quantity":"21.443"}],"asks":[{"price":"1736.13","quantity":"343.338"},{"price":"1736.14","quantity":"0.106"},{"price":"1736.16","quantity":"0.038"},{"price":"1736.20","quantity":"3.328"},{"price":"1736.22","quantity":"20.736"},{"price":"1736.23","quantity":"3.287"},{"price":"1736.25","quantity":"2.813"},{"price":"1736.26","quantity":"0.426"},{"price":"1736.28","quantity":"30.808"},{"price":"1736.30","quantity":"16.224"},{"price":"1736.31","quantity":"17.372"},{"price":"1736.32","quantity":"0.162"},{"price":"1736.33","quantity":"0.012"},{"price":"1736.34","quantity":"29.034"},{"price":"1736.35","quantity":"4.525"},{"price":"1736.42","quantity":"3.658"},{"price":"1736.43","quantity":"27.285"},{"price":"1736.44","quantity":"11.299"},{"price":"1736.45","quantity":"77.026"},{"price":"1736.46","quantity":"46.108"},{"price":"1736.47","quantity":"13.186"},{"price":"1736.48","quantity":"9.902"},{"price":"1736.59","quantity":"4.554"},{"price":"1736.63","quantity":"11.774"},{"price":"1736.74","quantity":"41.892"},{"price":"1736.87","quantity":"24.551"},{"price":"1737.05","quantity":"0.879"},{"price":"1737.09","quantity":"41.647"},{"price":"1737.13","quantity":"5.002"},{"price":"1737.14","quantity":"70.031"},{"price":"1737.17","quantity":"1.605"},{"price":"1737.20","quantity":"29.782"},{"price":"1737.25","quantity":"71.600"},{"price":"1737.34","quantity":"14.909"},{"price":"1737.36","quantity":"68.335"},{"price":"1737.37","quantity":"41.800"},{"price":"1737.43","quantity":"11.221"},{"price":"1737.73","quantity":"1.987"},{"price":"1737.74","quantity":"76.585"},{"price":"1737.79","quantity":"5.635"},{"price":"1737.81","quantity":"33.968"},{"price":"1738.17","quantity":"67.911"},{"price":"1738.26","quantity":"408.982"},{"price":"1738.43","quantity":"2.232"},{"price":"1738.45","quantity":"0.142"},{"price":"1738.46","quantity":"33.701"},{"price":"1738.50","quantity":"0.298"},{"price":"1738.53","quantity":"58.124"},{"price":"1738.54","quantity":"13.091"},{"price":"1738.55","quantity":"0.274"},{"price":"1738.62","quantity":"16.391"},{"price":"1738.64","quantity":"7.862"},{"price":"1739.42","quantity":"19.309"},{"price":"1739.94","quantity":"0.661"},{"price":"1742.45","quantity":"9.579"},{"price":"1743.49","quantity":"9.908"},{"price":"1745.03","quantity":"0.000"},{"price":"1745.15","quantity":"0.358"},{"price":"1747.10","quantity":"5.676"},{"price":"1747.11","quantity":"37.224"},{"price":"1747.12","quantity":"0.000"},{"price":"1748.16","quantity":"2.528"},{"price":"1748.28","quantity":"0.283"},{"price":"1748.42","quantity":"37.216"},{"price":"1748.43","quantity":"0.658"},{"price":"1763.19","quantity":"35.926"},{"price":"2635.00","quantity":"0.194"},{"price":"2635.09","quantity":"0.000"}],"raw":{"e":"depthUpdate","E":1783517066458,"T":1783517066457,"s":"ETHUSDT","ps":"ETHUSDT","U":10999770540675,"u":10999770552351,"pu":10999770540664,"b":[["1211.12","0.577"],["1216.12","0.704"],["1216.16","5.632"],["1216.22","0.000"],["1216.23","0.000"],["1216.27","0.468"],["1221.16","1.856"],["1562.50","1.060"],["1562.51","6.520"],["1666.60","1.193"],["1701.40","0.402"],["1702.49","34.934"],["1702.64","0.030"],["1703.17","27.177"],["1708.84","0.033"],["1711.63","46.492"],["1721.37","87.996"],["1729.11","34.452"],["1729.29","0.031"],["1731.16","5.197"],["1731.24","224.004"],["1733.05","2.031"],["1733.53","0.892"],["1733.54","0.099"],["1733.65","9.919"],["1733.66","23.837"],["1733.71","84.523"],["1733.74","16.412"],["1733.82","2.575"],["1733.85","128.008"],["1733.89","429.572"],["1734.24","1.474"],["1734.32","11.558"],["1734.33","19.867"],["1734.36","13.419"],["1734.37","0.950"],["1734.38","11.389"],["1734.39","240.097"],["1734.40","4.555"],["1734.42","2.247"],["1734.43","0.384"],["1734.45","0.038"],["1734.46","51.590"],["1734.49","53.070"],["1734.51","232.678"],["1734.53","35.877"],["1734.56","3.962"],["1734.57","29.351"],["1734.58","0.519"],["1734.61","0.240"],["1734.65","13.554"],["1734.70","0.670"],["1734.82","18.237"],["1734.83","6.689"],["1734.84","272.072"],["1734.87","19.838"],["1734.88","59.476"],["1735.01","19.586"],["1735.10","14.768"],["1735.12","95.482"],["1735.15","5.663"],["1735.16","4.509"],["1735.17","3.284"],["1735.22","16.399"],["1735.25","39.105"],["1735.31","33.996"],["1735.35","20.776"],["1735.37","0.583"],["1735.43","4.210"],["1735.46","21.324"],["1735.51","58.285"],["1735.59","4.365"],["1735.60","4.613"],["1735.61","17.408"],["1735.63","29.411"],["1735.65","20.560"],["1735.66","0.157"],["1735.73","27.647"],["1735.74","28.064"],["1735.76","2.001"],["1735.77","23.595"],["1735.78","21.763"],["1735.79","7.539"],["1735.81","5.646"],["1735.83","20.204"],["1735.84","4.090"],["1735.85","6.839"],["1735.88","0.036"],["1735.89","23.252"],["1735.91","15.361"],["1735.92","9.819"],["1735.93","0.176"],["1735.94","3.729"],["1735.98","3.764"],["1736.00","1.096"],["1736.01","0.050"],["1736.05","0.063"],["1736.06","0.026"],["1736.08","0.723"],["1736.10","3.736"],["1736.12","21.443"]],"a":[["1736.13","343.338"],["1736.14","0.106"],["1736.16","0.038"],["1736.20","3.328"],["1736.22","20.736"],["1736.23","3.287"],["1736.25","2.813"],["1736.26","0.426"],["1736.28","30.808"],["1736.30","16.224"],["1736.31","17.372"],["1736.32","0.162"],["1736.33","0.012"],["1736.34","29.034"],["1736.35","4.525"],["1736.42","3.658"],["1736.43","27.285"],["1736.44","11.299"],["1736.45","77.026"],["1736.46","46.108"],["1736.47","13.186"],["1736.48","9.902"],["1736.59","4.554"],["1736.63","11.774"],["1736.74","41.892"],["1736.87","24.551"],["1737.05","0.879"],["1737.09","41.647"],["1737.13","5.002"],["1737.14","70.031"],["1737.17","1.605"],["1737.20","29.782"],["1737.25","71.600"],["1737.34","14.909"],["1737.36","68.335"],["1737.37","41.800"],["1737.43","11.221"],["1737.73","1.987"],["1737.74","76.585"],["1737.79","5.635"],["1737.81","33.968"],["1738.17","67.911"],["1738.26","408.982"],["1738.43","2.232"],["1738.45","0.142"],["1738.46","33.701"],["1738.50","0.298"],["1738.53","58.124"],["1738.54","13.091"],["1738.55","0.274"],["1738.62","16.391"],["1738.64","7.862"],["1739.42","19.309"],["1739.94","0.661"],["1742.45","9.579"],["1743.49","9.908"],["1745.03","0.000"],["1745.15","0.358"],["1747.10","5.676"],["1747.11","37.224"],["1747.12","0.000"],["1748.16","2.528"],["1748.28","0.283"],["1748.42","37.216"],["1748.43","0.658"],["1763.19","35.926"],["2635.00","0.194"],["2635.09","0.000"]],"st":1}}
{"schema_version":"1.3.0","event_id":"e26188d8-3fc0-4650-b694-f0f090bb8dfb","event_type":"raw.depth_update","source":"binance_market_data_recorder","venue":"binance_usdm","market_type":"perpetual_futures","symbol":"ETHUSDT","event_time_ms":1783517066560,"received_time_ms":1783517067190,"trace_id":"33359fa0-ae72-4809-9445-87f28f915f8d","first_update_id":10999770552523,"final_update_id":10999770563387,"previous_final_update_id":10999770552351,"bids":[{"price":"200.00","quantity":"7.594"},{"price":"201.00","quantity":"2.300"},{"price":"1211.12","quantity":"1.121"},{"price":"1216.12","quantity":"0.960"},{"price":"1216.16","quantity":"5.280"},{"price":"1216.27","quantity":"0.276"},{"price":"1221.16","quantity":"1.600"},{"price":"1562.50","quantity":"1.060"},{"price":"1562.51","quantity":"7.032"},{"price":"1666.60","quantity":"1.078"},{"price":"1693.59","quantity":"187.007"},{"price":"1701.40","quantity":"0.373"},{"price":"1725.00","quantity":"1296.499"},{"price":"1725.03","quantity":"0.058"},{"price":"1727.26","quantity":"0.804"},{"price":"1727.29","quantity":"0.031"},{"price":"1732.60","quantity":"0.448"},{"price":"1733.05","quantity":"1.431"},{"price":"1733.43","quantity":"0.377"},{"price":"1733.52","quantity":"35.883"},{"price":"1733.61","quantity":"17.538"},{"price":"1733.71","quantity":"84.523"},{"price":"1733.72","quantity":"0.169"},{"price":"1733.73","quantity":"43.339"},{"price":"1733.74","quantity":"15.812"},{"price":"1733.85","quantity":"65.288"},{"price":"1733.89","quantity":"429.572"},{"price":"1733.94","quantity":"90.517"},{"price":"1734.24","quantity":"1.565"},{"price":"1734.37","quantity":"0.150"},{"price":"1734.38","quantity":"10.789"},{"price":"1734.39","quantity":"19.545"},{"price":"1734.40","quantity":"3.064"},{"price":"1734.41","quantity":"80.333"},{"price":"1734.42","quantity":"0.847"},{"price":"1734.46","quantity":"25.640"},{"price":"1734.51","quantity":"12.717"},{"price":"1734.55","quantity":"0.155"},{"price":"1734.56","quantity":"4.362"},{"price":"1734.57","quantity":"52.200"},{"price":"1734.59","quantity":"0.411"},{"price":"1734.61","quantity":"220.204"},{"price":"1734.63","quantity":"50.178"},{"price":"1734.81","quantity":"18.272"},{"price":"1734.86","quantity":"39.120"},{"price":"1735.03","quantity":"0.237"},{"price":"1735.04","quantity":"2.099"},{"price":"1735.05","quantity":"0.432"},{"price":"1735.06","quantity":"0.127"},{"price":"1735.07","quantity":"5.145"},{"price":"1735.08","quantity":"5.225"},{"price":"1735.09","quantity":"0.635"},{"price":"1735.10","quantity":"12.368"},{"price":"1735.11","quantity":"43.336"},{"price":"1735.12","quantity":"94.697"},{"price":"1735.13","quantity":"1.544"},{"price":"1735.16","quantity":"3.909"},{"price":"1735.23","quantity":"4.996"},{"price":"1735.24","quantity":"7.526"},{"price":"1735.27","quantity":"68.102"},{"price":"1735.46","quantity":"21.336"},{"price":"1735.57","quantity":"1.884"},{"price":"1735.67","quantity":"0.051"},{"price":"1735.72","quantity":"88.758"},{"price":"1735.73","quantity":"26.047"},{"price":"1735.74","quantity":"28.064"},{"price":"1735.75","quantity":"85.233"},{"price":"1735.76","quantity":"1.201"},{"price":"1735.77","quantity":"22.995"},{"price":"1735.78","quantity":"21.163"},{"price":"1735.83","quantity":"28.853"},{"price":"1735.89","quantity":"23.170"},{"price":"1736.02","quantity":"0.061"},{"price":"1736.03","quantity":"0.062"},{"price":"1736.04","quantity":"0.024"},{"price":"1736.11","quantity":"0.735"},{"price":"1736.12","quantity":"21.608"}],"asks":[{"price":"1736.13","quantity":"333.235"},{"price":"1736.24","quantity":"29.257"},{"price":"1736.25","quantity":"2.825"},{"price":"1736.26","quantity":"0.438"},{"price":"1736.27","quantity":"11.649"},{"price":"1736.29","quantity":"1.186"},{"price":"1736.34","quantity":"28.865"},{"price":"1736.41","quantity":"0.080"},{"price":"1736.42","quantity":"0.538"},{"price":"1736.43","quantity":"25.065"},{"price":"1736.44","quantity":"7.259"},{"price":"1736.45","quantity":"72.966"},{"price":"1736.46","quantity":"46.108"},{"price":"1736.48","quantity":"5.662"},{"price":"1736.55","quantity":"31.534"},{"price":"1736.56","quantity":"9.082"},{"price":"1736.59","quantity":"1.834"},{"price":"1736.63","quantity":"10.154"},{"price":"1736.64","quantity":"76.197"},{"price":"1737.03","quantity":"85.783"},{"price":"1737.05","quantity":"0.797"},{"price":"1737.06","quantity":"21.378"},{"price":"1737.07","quantity":"0.478"},{"price":"1737.08","quantity":"3.801"},{"price":"1737.09","quantity":"36.527"},{"price":"1737.10","quantity":"6.051"},{"price":"1737.11","quantity":"16.916"},{"price":"1737.12","quantity":"1.611"},{"price":"1737.13","quantity":"0.842"},{"price":"1737.14","quantity":"67.871"},{"price":"1737.36","quantity":"69.335"},{"price":"1737.38","quantity":"87.911"},{"price":"1737.56","quantity":"88.012"},{"price":"1737.74","quantity":"71.305"},{"price":"1737.76","quantity":"8.664"},{"price":"1737.77","quantity":"0.758"},{"price":"1737.78","quantity":"3.022"},{"price":"1737.79","quantity":"0.015"},{"price":"1737.80","quantity":"1.344"},{"price":"1737.81","quantity":"29.728"},{"price":"1737.99","quantity":"0.425"},{"price":"1738.30","quantity":"24.606"},{"price":"1738.43","quantity":"0.012"},{"price":"1738.44","quantity":"1.090"},{"price":"1738.47","quantity":"91.217"},{"price":"1738.53","quantity":"46.293"},{"price":"1738.58","quantity":"87.179"},{"price":"1738.61","quantity":"0.290"},{"price":"1738.62","quantity":"16.391"},{"price":"1739.30","quantity":"5.271"},{"price":"1739.42","quantity":"17.925"},{"price":"1739.74","quantity":"0.448"},{"price":"1742.04","quantity":"30.634"},{"price":"1742.52","quantity":"6.764"},{"price":"1758.85","quantity":"30.476"},{"price":"2634.98","quantity":"0.001"},{"price":"2634.99","quantity":"0.001"},{"price":"2635.07","quantity":"0.000"},{"price":"2635.08","quantity":"0.000"}],"raw":{"e":"depthUpdate","E":1783517066560,"T":1783517066559,"s":"ETHUSDT","ps":"ETHUSDT","U":10999770552523,"u":10999770563387,"pu":10999770552351,"b":[["200.00","7.594"],["201.00","2.300"],["1211.12","1.121"],["1216.12","0.960"],["1216.16","5.280"],["1216.27","0.276"],["1221.16","1.600"],["1562.50","1.060"],["1562.51","7.032"],["1666.60","1.078"],["1693.59","187.007"],["1701.40","0.373"],["1725.00","1296.499"],["1725.03","0.058"],["1727.26","0.804"],["1727.29","0.031"],["1732.60","0.448"],["1733.05","1.431"],["1733.43","0.377"],["1733.52","35.883"],["1733.61","17.538"],["1733.71","84.523"],["1733.72","0.169"],["1733.73","43.339"],["1733.74","15.812"],["1733.85","65.288"],["1733.89","429.572"],["1733.94","90.517"],["1734.24","1.565"],["1734.37","0.150"],["1734.38","10.789"],["1734.39","19.545"],["1734.40","3.064"],["1734.41","80.333"],["1734.42","0.847"],["1734.46","25.640"],["1734.51","12.717"],["1734.55","0.155"],["1734.56","4.362"],["1734.57","52.200"],["1734.59","0.411"],["1734.61","220.204"],["1734.63","50.178"],["1734.81","18.272"],["1734.86","39.120"],["1735.03","0.237"],["1735.04","2.099"],["1735.05","0.432"],["1735.06","0.127"],["1735.07","5.145"],["1735.08","5.225"],["1735.09","0.635"],["1735.10","12.368"],["1735.11","43.336"],["1735.12","94.697"],["1735.13","1.544"],["1735.16","3.909"],["1735.23","4.996"],["1735.24","7.526"],["1735.27","68.102"],["1735.46","21.336"],["1735.57","1.884"],["1735.67","0.051"],["1735.72","88.758"],["1735.73","26.047"],["1735.74","28.064"],["1735.75","85.233"],["1735.76","1.201"],["1735.77","22.995"],["1735.78","21.163"],["1735.83","28.853"],["1735.89","23.170"],["1736.02","0.061"],["1736.03","0.062"],["1736.04","0.024"],["1736.11","0.735"],["1736.12","21.608"]],"a":[["1736.13","333.235"],["1736.24","29.257"],["1736.25","2.825"],["1736.26","0.438"],["1736.27","11.649"],["1736.29","1.186"],["1736.34","28.865"],["1736.41","0.080"],["1736.42","0.538"],["1736.43","25.065"],["1736.44","7.259"],["1736.45","72.966"],["1736.46","46.108"],["1736.48","5.662"],["1736.55","31.534"],["1736.56","9.082"],["1736.59","1.834"],["1736.63","10.154"],["1736.64","76.197"],["1737.03","85.783"],["1737.05","0.797"],["1737.06","21.378"],["1737.07","0.478"],["1737.08","3.801"],["1737.09","36.527"],["1737.10","6.051"],["1737.11","16.916"],["1737.12","1.611"],["1737.13","0.842"],["1737.14","67.871"],["1737.36","69.335"],["1737.38","87.911"],["1737.56","88.012"],["1737.74","71.305"],["1737.76","8.664"],["1737.77","0.758"],["1737.78","3.022"],["1737.79","0.015"],["1737.80","1.344"],["1737.81","29.728"],["1737.99","0.425"],["1738.30","24.606"],["1738.43","0.012"],["1738.44","1.090"],["1738.47","91.217"],["1738.53","46.293"],["1738.58","87.179"],["1738.61","0.290"],["1738.62","16.391"],["1739.30","5.271"],["1739.42","17.925"],["1739.74","0.448"],["1742.04","30.634"],["1742.52","6.764"],["1758.85","30.476"],["2634.98","0.001"],["2634.99","0.001"],["2635.07","0.000"],["2635.08","0.000"]],"st":1}}
{"schema_version":"1.3.0","event_id":"da6aa1bc-03d7-474a-a04c-5bc8ffaa9546","event_type":"raw.depth_update","source":"binance_market_data_recorder","venue":"binance_usdm","market_type":"perpetual_futures","symbol":"ETHUSDT","event_time_ms":1783517066662,"received_time_ms":1783517067228,"trace_id":"fa2d1382-fc4f-45f6-91c4-22b2ce4bb084","first_update_id":10999770563541,"final_update_id":10999770572595,"previous_final_update_id":10999770563387,"bids":[{"price":"200.00","quantity":"7.594"},{"price":"1211.12","quantity":"1.665"},{"price":"1216.12","quantity":"1.248"},{"price":"1216.16","quantity":"4.736"},{"price":"1221.16","quantity":"1.312"},{"price":"1562.50","quantity":"1.060"},{"price":"1562.51","quantity":"7.686"},{"price":"1666.02","quantity":"29.999"},{"price":"1666.60","quantity":"1.193"},{"price":"1701.39","quantity":"32.216"},{"price":"1709.51","quantity":"39.542"},{"price":"1710.22","quantity":"31.807"},{"price":"1729.82","quantity":"0.000"},{"price":"1730.01","quantity":"4.410"},{"price":"1730.23","quantity":"16.323"},{"price":"1730.44","quantity":"4.322"},{"price":"1731.25","quantity":"14.145"},{"price":"1731.51","quantity":"1.964"},{"price":"1731.98","quantity":"173.156"},{"price":"1732.52","quantity":"0.000"},{"price":"1732.53","quantity":"19.105"},{"price":"1732.75","quantity":"145.605"},{"price":"1733.53","quantity":"0.892"},{"price":"1733.65","quantity":"429.945"},{"price":"1733.66","quantity":"82.631"},{"price":"1733.70","quantity":"16.350"},{"price":"1733.85","quantity":"88.400"},{"price":"1733.89","quantity":"0.765"},{"price":"1733.94","quantity":"29.283"},{"price":"1734.40","quantity":"3.664"},{"price":"1734.44","quantity":"55.636"},{"price":"1734.45","quantity":"1.951"},{"price":"1734.46","quantity":"26.596"},{"price":"1734.52","quantity":"0.039"},{"price":"1734.53","quantity":"34.922"},{"price":"1734.56","quantity":"3.962"},{"price":"1734.57","quantity":"29.333"},{"price":"1734.58","quantity":"25.519"},{"price":"1734.61","quantity":"0.258"},{"price":"1734.63","quantity":"19.810"},{"price":"1734.84","quantity":"272.072"},{"price":"1734.85","quantity":"1.504"},{"price":"1734.88","quantity":"59.458"},{"price":"1734.90","quantity":"19.427"},{"price":"1734.93","quantity":"71.602"},{"price":"1734.96","quantity":"5.239"},{"price":"1735.02","quantity":"53.535"},{"price":"1735.06","quantity":"0.127"},{"price":"1735.09","quantity":"0.435"},{"price":"1735.10","quantity":"12.275"},{"price":"1735.11","quantity":"43.336"},{"price":"1735.13","quantity":"1.544"},{"price":"1735.22","quantity":"236.367"},{"price":"1735.27","quantity":"68.101"},{"price":"1735.28","quantity":"4.962"},{"price":"1735.31","quantity":"34.596"},{"price":"1735.33","quantity":"16.517"},{"price":"1735.38","quantity":"285.061"},{"price":"1735.42","quantity":"20.623"},{"price":"1735.43","quantity":"4.053"},{"price":"1735.44","quantity":"67.218"},{"price":"1735.45","quantity":"0.178"},{"price":"1735.46","quantity":"19.608"},{"price":"1735.47","quantity":"16.709"},{"price":"1735.49","quantity":"5.329"},{"price":"1735.54","quantity":"0.012"},{"price":"1735.55","quantity":"4.604"},{"price":"1735.56","quantity":"28.455"},{"price":"1735.57","quantity":"1.802"},{"price":"1735.58","quantity":"0.094"},{"price":"1735.59","quantity":"4.353"},{"price":"1735.63","quantity":"0.576"},{"price":"1735.65","quantity":"20.560"},{"price":"1735.66","quantity":"5.924"},{"price":"1735.68","quantity":"15.170"},{"price":"1735.69","quantity":"24.767"},{"price":"1735.70","quantity":"28.871"},{"price":"1735.72","quantity":"89.558"},{"price":"1735.74","quantity":"28.664"},{"price":"1735.75","quantity":"70.644"},{"price":"1735.76","quantity":"9.144"},{"price":"1735.77","quantity":"23.795"},{"price":"1735.78","quantity":"19.300"},{"price":"1735.79","quantity":"16.959"},{"price":"1735.80","quantity":"0.130"},{"price":"1735.81","quantity":"5.358"},{"price":"1735.82","quantity":"14.215"},{"price":"1735.83","quantity":"21.004"},{"price":"1735.84","quantity":"0.058"},{"price":"1735.85","quantity":"2.933"},{"price":"1735.86","quantity":"68.508"},{"price":"1735.87","quantity":"24.344"},{"price":"1735.89","quantity":"0.986"},{"price":"1735.90","quantity":"4.012"},{"price":"1735.91","quantity":"10.233"},{"price":"1735.92","quantity":"33.465"},{"price":"1735.93","quantity":"5.088"},{"price":"1735.94","quantity":"3.929"},{"price":"1735.95","quantity":"1.226"},{"price":"1735.96","quantity":"2.280"},{"price":"1735.98","quantity":"23.325"},{"price":"1735.99","quantity":"6.258"},{"price":"1736.00","quantity":"0.113"},{"price":"1736.02","quantity":"1.789"},{"price":"1736.05","quantity":"0.154"},{"price":"1736.08","quantity":"0.735"},{"price":"1736.12","quantity":"131.311"}],"asks":[{"price":"1736.13","quantity":"60.825"},{"price":"1736.14","quantity":"0.082"},{"price":"1736.17","quantity":"0.036"},{"price":"1736.19","quantity":"0.843"},{"price":"1736.20","quantity":"2.917"},{"price":"1736.21","quantity":"0.012"},{"price":"1736.22","quantity":"15.476"},{"price":"1736.23","quantity":"0.052"},{"price":"1736.24","quantity":"0.098"},{"price":"1736.25","quantity":"2.825"},{"price":"1736.27","quantity":"1.754"},{"price":"1736.28","quantity":"49.092"},{"price":"1736.29","quantity":"1.198"},{"price":"1736.30","quantity":"7.929"},{"price":"1736.31","quantity":"17.384"},{"price":"1736.33","quantity":"0.012"},{"price":"1736.34","quantity":"0.041"},{"price":"1736.37","quantity":"7.821"},{"price":"1736.38","quantity":"17.501"},{"price":"1736.39","quantity":"4.248"},{"price":"1736.40","quantity":"21.362"},{"price":"1736.41","quantity":"18.185"},{"price":"1736.42","quantity":"29.361"},{"price":"1736.43","quantity":"27.625"},{"price":"1736.44","quantity":"7.245"},{"price":"1736.45","quantity":"77.106"},{"price":"1736.46","quantity":"41.550"},{"price":"1736.47","quantity":"19.642"},{"price":"1736.48","quantity":"6.182"},{"price":"1736.49","quantity":"3.015"},{"price":"1736.50","quantity":"0.102"},{"price":"1736.52","quantity":"5.845"},{"price":"1736.56","quantity":"9.082"},{"price":"1736.60","quantity":"5.055"},{"price":"1736.62","quantity":"2.245"},{"price":"1736.63","quantity":"8.821"},{"price":"1736.66","quantity":"3.216"},{"price":"1736.67","quantity":"3.518"},{"price":"1736.73","quantity":"45.889"},{"price":"1736.74","quantity":"43.559"},{"price":"1736.75","quantity":"95.506"},{"price":"1736.83","quantity":"37.658"},{"price":"1736.86","quantity":"0.328"},{"price":"1736.88","quantity":"5.425"},{"price":"1736.89","quantity":"8.153"},{"price":"1736.96","quantity":"12.198"},{"price":"1737.00","quantity":"72.152"},{"price":"1737.02","quantity":"25.898"},{"price":"1737.03","quantity":"84.344"},{"price":"1737.04","quantity":"98.625"},{"price":"1737.05","quantity":"46.894"},{"price":"1737.08","quantity":"6.521"},{"price":"1737.09","quantity":"28.385"},{"price":"1737.10","quantity":"8.611"},{"price":"1737.12","quantity":"3.771"},{"price":"1737.13","quantity":"2.822"},{"price":"1737.15","quantity":"2.934"},{"price":"1737.26","quantity":"6.857"},{"price":"1737.32","quantity":"1.295"},{"price":"1737.34","quantity":"13.215"},{"price":"1737.35","quantity":"27.841"},{"price":"1737.52","quantity":"2.666"},{"price":"1737.54","quantity":"27.248"},{"price":"1737.78","quantity":"1.355"},{"price":"1737.80","quantity":"3.324"},{"price":"1737.87","quantity":"7.926"},{"price":"1737.95","quantity":"90.782"},{"price":"1738.04","quantity":"0.239"},{"price":"1738.20","quantity":"408.215"},{"price":"1738.26","quantity":"1.023"},{"price":"1738.34","quantity":"10.639"},{"price":"1738.53","quantity":"29.337"},{"price":"1738.54","quantity":"9.895"},{"price":"1738.56","quantity":"1.044"},{"price":"1738.57","quantity":"33.052"},{"price":"1738.71","quantity":"38.346"},{"price":"1738.72","quantity":"56.323"},{"price":"1738.78","quantity":"7.305"},{"price":"1738.80","quantity":"6.458"},{"price":"1738.86","quantity":"6.077"},{"price":"1738.89","quantity":"59.745"},{"price":"1739.38","quantity":"7.600"},{"price":"1739.41","quantity":"4.407"},{"price":"1739.42","quantity":"27.654"},{"price":"1739.43","quantity":"70.670"},{"price":"1740.16","quantity":"26.711"},{"price":"1740.58","quantity":"8.287"},{"price":"1740.84","quantity":"0.172"},{"price":"1741.03","quantity":"1.152"},{"price":"1743.50","quantity":"10.964"},{"price":"1757.12","quantity":"54.225"},{"price":"1771.38","quantity":"0.013"},{"price":"1909.74","quantity":"0.012"},{"price":"2634.97","quantity":"0.001"},{"price":"2635.06","quantity":"0.011"}],"raw":{"e":"depthUpdate","E":1783517066662,"T":1783517066661,"s":"ETHUSDT","ps":"ETHUSDT","U":10999770563541,"u":10999770572595,"pu":10999770563387,"b":[["200.00","7.594"],["1211.12","1.665"],["1216.12","1.248"],["1216.16","4.736"],["1221.16","1.312"],["1562.50","1.060"],["1562.51","7.686"],["1666.02","29.999"],["1666.60","1.193"],["1701.39","32.216"],["1709.51","39.542"],["1710.22","31.807"],["1729.82","0.000"],["1730.01","4.410"],["1730.23","16.323"],["1730.44","4.322"],["1731.25","14.145"],["1731.51","1.964"],["1731.98","173.156"],["1732.52","0.000"],["1732.53","19.105"],["1732.75","145.605"],["1733.53","0.892"],["1733.65","429.945"],["1733.66","82.631"],["1733.70","16.350"],["1733.85","88.400"],["1733.89","0.765"],["1733.94","29.283"],["1734.40","3.664"],["1734.44","55.636"],["1734.45","1.951"],["1734.46","26.596"],["1734.52","0.039"],["1734.53","34.922"],["1734.56","3.962"],["1734.57","29.333"],["1734.58","25.519"],["1734.61","0.258"],["1734.63","19.810"],["1734.84","272.072"],["1734.85","1.504"],["1734.88","59.458"],["1734.90","19.427"],["1734.93","71.602"],["1734.96","5.239"],["1735.02","53.535"],["1735.06","0.127"],["1735.09","0.435"],["1735.10","12.275"],["1735.11","43.336"],["1735.13","1.544"],["1735.22","236.367"],["1735.27","68.101"],["1735.28","4.962"],["1735.31","34.596"],["1735.33","16.517"],["1735.38","285.061"],["1735.42","20.623"],["1735.43","4.053"],["1735.44","67.218"],["1735.45","0.178"],["1735.46","19.608"],["1735.47","16.709"],["1735.49","5.329"],["1735.54","0.012"],["1735.55","4.604"],["1735.56","28.455"],["1735.57","1.802"],["1735.58","0.094"],["1735.59","4.353"],["1735.63","0.576"],["1735.65","20.560"],["1735.66","5.924"],["1735.68","15.170"],["1735.69","24.767"],["1735.70","28.871"],["1735.72","89.558"],["1735.74","28.664"],["1735.75","70.644"],["1735.76","9.144"],["1735.77","23.795"],["1735.78","19.300"],["1735.79","16.959"],["1735.80","0.130"],["1735.81","5.358"],["1735.82","14.215"],["1735.83","21.004"],["1735.84","0.058"],["1735.85","2.933"],["1735.86","68.508"],["1735.87","24.344"],["1735.89","0.986"],["1735.90","4.012"],["1735.91","10.233"],["1735.92","33.465"],["1735.93","5.088"],["1735.94","3.929"],["1735.95","1.226"],["1735.96","2.280"],["1735.98","23.325"],["1735.99","6.258"],["1736.00","0.113"],["1736.02","1.789"],["1736.05","0.154"],["1736.08","0.735"],["1736.12","131.311"]],"a":[["1736.13","60.825"],["1736.14","0.082"],["1736.17","0.036"],["1736.19","0.843"],["1736.20","2.917"],["1736.21","0.012"],["1736.22","15.476"],["1736.23","0.052"],["1736.24","0.098"],["1736.25","2.825"],["1736.27","1.754"],["1736.28","49.092"],["1736.29","1.198"],["1736.30","7.929"],["1736.31","17.384"],["1736.33","0.012"],["1736.34","0.041"],["1736.37","7.821"],["1736.38","17.501"],["1736.39","4.248"],["1736.40","21.362"],["1736.41","18.185"],["1736.42","29.361"],["1736.43","27.625"],["1736.44","7.245"],["1736.45","77.106"],["1736.46","41.550"],["1736.47","19.642"],["1736.48","6.182"],["1736.49","3.015"],["1736.50","0.102"],["1736.52","5.845"],["1736.56","9.082"],["1736.60","5.055"],["1736.62","2.245"],["1736.63","8.821"],["1736.66","3.216"],["1736.67","3.518"],["1736.73","45.889"],["1736.74","43.559"],["1736.75","95.506"],["1736.83","37.658"],["1736.86","0.328"],["1736.88","5.425"],["1736.89","8.153"],["1736.96","12.198"],["1737.00","72.152"],["1737.02","25.898"],["1737.03","84.344"],["1737.04","98.625"],["1737.05","46.894"],["1737.08","6.521"],["1737.09","28.385"],["1737.10","8.611"],["1737.12","3.771"],["1737.13","2.822"],["1737.15","2.934"],["1737.26","6.857"],["1737.32","1.295"],["1737.34","13.215"],["1737.35","27.841"],["1737.52","2.666"],["1737.54","27.248"],["1737.78","1.355"],["1737.80","3.324"],["1737.87","7.926"],["1737.95","90.782"],["1738.04","0.239"],["1738.20","408.215"],["1738.26","1.023"],["1738.34","10.639"],["1738.53","29.337"],["1738.54","9.895"],["1738.56","1.044"],["1738.57","33.052"],["1738.71","38.346"],["1738.72","56.323"],["1738.78","7.305"],["1738.80","6.458"],["1738.86","6.077"],["1738.89","59.745"],["1739.38","7.600"],["1739.41","4.407"],["1739.42","27.654"],["1739.43","70.670"],["1740.16","26.711"],["1740.58","8.287"],["1740.84","0.172"],["1741.03","1.152"],["1743.50","10.964"],["1757.12","54.225"],["1771.38","0.013"],["1909.74","0.012"],["2634.97","0.001"],["2635.06","0.011"]],"st":1}}
{"schema_version":"1.3.0","event_id":"730bd1c2-abe6-4945-9243-828d940e222a","event_type":"raw.depth_update","source":"binance_market_data_recorder","venue":"binance_usdm","market_type":"perpetual_futures","symbol":"ETHUSDT","event_time_ms":1783517066764,"received_time_ms":1783517067240,"trace_id":"47415f74-47d0-497c-94f3-3911c6a56fa3","first_update_id":10999770572661,"final_update_id":10999770579204,"previous_final_update_id":10999770572595,"bids":[{"price":"1211.12","quantity":"2.209"},{"price":"1216.12","quantity":"1.504"},{"price":"1216.16","quantity":"4.192"},{"price":"1221.16","quantity":"1.056"},{"price":"1562.50","quantity":"1.060"},{"price":"1562.51","quantity":"8.340"},{"price":"1699.00","quantity":"152.240"},{"price":"1701.39","quantity":"32.187"},{"price":"1710.25","quantity":"126.003"},{"price":"1732.52","quantity":"9.729"},{"price":"1733.65","quantity":"9.919"},{"price":"1733.66","quantity":"23.837"},{"price":"1733.70","quantity":"16.600"},{"price":"1733.71","quantity":"84.523"},{"price":"1733.76","quantity":"35.199"},{"price":"1733.91","quantity":"0.465"},{"price":"1733.95","quantity":"3.942"},{"price":"1734.18","quantity":"420.038"},{"price":"1734.21","quantity":"79.237"},{"price":"1734.43","quantity":"0.984"},{"price":"1734.45","quantity":"0.638"},{"price":"1734.46","quantity":"25.640"},{"price":"1734.99","quantity":"220.634"},{"price":"1735.00","quantity":"228.843"},{"price":"1735.02","quantity":"94.800"},{"price":"1735.10","quantity":"232.216"},{"price":"1735.11","quantity":"74.437"},{"price":"1735.15","quantity":"6.463"},{"price":"1735.20","quantity":"45.938"},{"price":"1735.21","quantity":"36.379"},{"price":"1735.22","quantity":"17.355"},{"price":"1735.25","quantity":"39.125"},{"price":"1735.27","quantity":"68.102"},{"price":"1735.38","quantity":"65.076"},{"price":"1735.39","quantity":"0.553"},{"price":"1735.40","quantity":"3.830"},{"price":"1735.41","quantity":"124.169"},{"price":"1735.44","quantity":"27.473"},{"price":"1735.47","quantity":"16.709"},{"price":"1735.60","quantity":"4.695"},{"price":"1735.72","quantity":"89.558"},{"price":"1735.76","quantity":"9.944"},{"price":"1735.78","quantity":"1.373"},{"price":"1735.79","quantity":"8.630"},{"price":"1735.80","quantity":"0.730"},{"price":"1735.81","quantity":"6.958"},{"price":"1735.82","quantity":"0.866"},{"price":"1735.93","quantity":"5.111"},{"price":"1735.95","quantity":"9.874"},{"price":"1735.99","quantity":"9.910"},{"price":"1736.12","quantity":"131.384"}],"asks":[{"price":"1736.13","quantity":"65.737"},{"price":"1736.18","quantity":"0.041"},{"price":"1736.22","quantity":"9.992"},{"price":"1736.26","quantity":"7.529"},{"price":"1736.27","quantity":"21.846"},{"price":"1736.28","quantity":"48.804"},{"price":"1736.31","quantity":"17.672"},{"price":"1736.32","quantity":"0.174"},{"price":"1736.35","quantity":"4.537"},{"price":"1736.36","quantity":"0.560"},{"price":"1736.41","quantity":"27.625"},{"price":"1736.42","quantity":"5.878"},{"price":"1736.44","quantity":"6.677"},{"price":"1736.45","quantity":"105.759"},{"price":"1736.48","quantity":"8.262"},{"price":"1736.60","quantity":"9.365"},{"price":"1736.62","quantity":"2.196"},{"price":"1736.72","quantity":"9.786"},{"price":"1736.76","quantity":"20.522"},{"price":"1736.82","quantity":"20.001"},{"price":"1736.85","quantity":"0.619"},{"price":"1736.91","quantity":"68.123"},{"price":"1737.01","quantity":"75.007"},{"price":"1737.02","quantity":"23.872"},{"price":"1737.03","quantity":"83.757"},{"price":"1737.08","quantity":"15.961"},{"price":"1737.10","quantity":"13.951"},{"price":"1737.11","quantity":"17.097"},{"price":"1737.12","quantity":"7.811"},{"price":"1737.15","quantity":"5.014"},{"price":"1737.16","quantity":"11.200"},{"price":"1737.17","quantity":"2.194"},{"price":"1737.20","quantity":"26.327"},{"price":"1737.21","quantity":"3.477"},{"price":"1737.29","quantity":"2.293"},{"price":"1737.43","quantity":"8.581"},{"price":"1737.46","quantity":"9.147"},{"price":"1737.63","quantity":"0.314"},{"price":"1737.78","quantity":"3.575"},{"price":"1737.80","quantity":"5.124"},{"price":"1738.78","quantity":"4.305"},{"price":"1738.82","quantity":"8.207"},{"price":"1738.86","quantity":"2.881"},{"price":"1738.89","quantity":"56.549"},{"price":"1740.17","quantity":"46.948"},{"price":"1740.21","quantity":"8.357"},{"price":"1741.69","quantity":"4.136"},{"price":"1742.38","quantity":"4.136"},{"price":"1747.12","quantity":"15.000"},{"price":"1760.59","quantity":"58.998"},{"price":"1767.53","quantity":"101.712"},{"price":"1775.37","quantity":"0.015"},{"price":"1909.74","quantity":"0.000"},{"price":"2634.95","quantity":"0.001"},{"price":"2634.96","quantity":"0.001"},{"price":"2635.04","quantity":"0.000"},{"price":"2635.05","quantity":"0.000"}],"raw":{"e":"depthUpdate","E":1783517066764,"T":1783517066763,"s":"ETHUSDT","ps":"ETHUSDT","U":10999770572661,"u":10999770579204,"pu":10999770572595,"b":[["1211.12","2.209"],["1216.12","1.504"],["1216.16","4.192"],["1221.16","1.056"],["1562.50","1.060"],["1562.51","8.340"],["1699.00","152.240"],["1701.39","32.187"],["1710.25","126.003"],["1732.52","9.729"],["1733.65","9.919"],["1733.66","23.837"],["1733.70","16.600"],["1733.71","84.523"],["1733.76","35.199"],["1733.91","0.465"],["1733.95","3.942"],["1734.18","420.038"],["1734.21","79.237"],["1734.43","0.984"],["1734.45","0.638"],["1734.46","25.640"],["1734.99","220.634"],["1735.00","228.843"],["1735.02","94.800"],["1735.10","232.216"],["1735.11","74.437"],["1735.15","6.463"],["1735.20","45.938"],["1735.21","36.379"],["1735.22","17.355"],["1735.25","39.125"],["1735.27","68.102"],["1735.38","65.076"],["1735.39","0.553"],["1735.40","3.830"],["1735.41","124.169"],["1735.44","27.473"],["1735.47","16.709"],["1735.60","4.695"],["1735.72","89.558"],["1735.76","9.944"],["1735.78","1.373"],["1735.79","8.630"],["1735.80","0.730"],["1735.81","6.958"],["1735.82","0.866"],["1735.93","5.111"],["1735.95","9.874"],["1735.99","9.910"],["1736.12","131.384"]],"a":[["1736.13","65.737"],["1736.18","0.041"],["1736.22","9.992"],["1736.26","7.529"],["1736.27","21.846"],["1736.28","48.804"],["1736.31","17.672"],["1736.32","0.174"],["1736.35","4.537"],["1736.36","0.560"],["1736.41","27.625"],["1736.42","5.878"],["1736.44","6.677"],["1736.45","105.759"],["1736.48","8.262"],["1736.60","9.365"],["1736.62","2.196"],["1736.72","9.786"],["1736.76","20.522"],["1736.82","20.001"],["1736.85","0.619"],["1736.91","68.123"],["1737.01","75.007"],["1737.02","23.872"],["1737.03","83.757"],["1737.08","15.961"],["1737.10","13.951"],["1737.11","17.097"],["1737.12","7.811"],["1737.15","5.014"],["1737.16","11.200"],["1737.17","2.194"],["1737.20","26.327"],["1737.21","3.477"],["1737.29","2.293"],["1737.43","8.581"],["1737.46","9.147"],["1737.63","0.314"],["1737.78","3.575"],["1737.80","5.124"],["1738.78","4.305"],["1738.82","8.207"],["1738.86","2.881"],["1738.89","56.549"],["1740.17","46.948"],["1740.21","8.357"],["1741.69","4.136"],["1742.38","4.136"],["1747.12","15.000"],["1760.59","58.998"],["1767.53","101.712"],["1775.37","0.015"],["1909.74","0.000"],["2634.95","0.001"],["2634.96","0.001"],["2635.04","0.000"],["2635.05","0.000"]],"st":1}}
{"schema_version":"1.3.0","event_id":"4f5e5b7c-83eb-41ab-a0dc-a5949fdbfaa4","event_type":"raw.depth_update","source":"binance_market_data_recorder","venue":"binance_usdm","market_type":"perpetual_futures","symbol":"ETHUSDT","event_time_ms":1783517066866,"received_time_ms":1783517067250,"trace_id":"3d60eb80-d2ef-4f82-aea9-f56f2157b9c4","first_update_id":10999770579253,"final_update_id":10999770586155,"previous_final_update_id":10999770579204,"bids":[{"price":"200.00","quantity":"7.594"},{"price":"1211.12","quantity":"2.753"},{"price":"1216.12","quantity":"1.792"},{"price":"1216.16","quantity":"3.648"},{"price":"1221.16","quantity":"0.768"},{"price":"1562.50","quantity":"1.060"},{"price":"1562.51","quantity":"8.852"},{"price":"1666.60","quantity":"1.078"},{"price":"1730.22","quantity":"65.350"},{"price":"1730.56","quantity":"1.729"},{"price":"1734.01","quantity":"20.653"},{"price":"1734.04","quantity":"126.458"},{"price":"1734.42","quantity":"1.447"},{"price":"1734.44","quantity":"56.236"},{"price":"1734.89","quantity":"220.103"},{"price":"1734.99","quantity":"0.689"},{"price":"1735.02","quantity":"53.535"},{"price":"1735.10","quantity":"12.293"},{"price":"1735.11","quantity":"43.336"},{"price":"1735.12","quantity":"94.679"},{"price":"1735.36","quantity":"3.786"},{"price":"1735.37","quantity":"0.595"},{"price":"1735.42","quantity":"20.653"},{"price":"1735.62","quantity":"12.166"},{"price":"1735.75","quantity":"71.444"},{"price":"1735.77","quantity":"15.801"},{"price":"1735.78","quantity":"2.173"},{"price":"1735.80","quantity":"1.330"},{"price":"1735.87","quantity":"3.043"},{"price":"1735.88","quantity":"0.036"},{"price":"1735.90","quantity":"11.661"},{"price":"1735.95","quantity":"1.226"},{"price":"1735.98","quantity":"23.307"},{"price":"1735.99","quantity":"8.758"},{"price":"1736.12","quantity":"122.467"}],"asks":[{"price":"1736.13","quantity":"119.956"},{"price":"1736.23","quantity":"20.052"},{"price":"1736.24","quantity":"0.617"},{"price":"1736.25","quantity":"10.094"},{"price":"1736.26","quantity":"0.438"},{"price":"1736.27","quantity":"14.992"},{"price":"1736.28","quantity":"28.804"},{"price":"1736.30","quantity":"9.657"},{"price":"1736.33","quantity":"0.042"},{"price":"1736.39","quantity":"7.189"},{"price":"1736.44","quantity":"8.297"},{"price":"1736.45","quantity":"107.857"},{"price":"1736.46","quantity":"43.092"},{"price":"1736.48","quantity":"10.452"},{"price":"1736.57","quantity":"2.108"},{"price":"1736.63","quantity":"10.521"},{"price":"1736.66","quantity":"3.202"},{"price":"1736.68","quantity":"4.705"},{"price":"1736.88","quantity":"3.731"},{"price":"1737.11","quantity":"20.411"},{"price":"1737.13","quantity":"4.902"},{"price":"1737.14","quantity":"69.431"},{"price":"1737.16","quantity":"13.360"},{"price":"1737.21","quantity":"0.022"},{"price":"1737.22","quantity":"5.290"},{"price":"1737.79","quantity":"1.635"},{"price":"1737.81","quantity":"31.288"},{"price":"1737.95","quantity":"89.115"},{"price":"1738.20","quantity":"0.256"},{"price":"1738.25","quantity":"410.177"},{"price":"1738.82","quantity":"5.011"},{"price":"1738.86","quantity":"2.881"},{"price":"1740.16","quantity":"16.982"},{"price":"1749.67","quantity":"0.038"},{"price":"1762.98","quantity":"689.407"},{"price":"2634.93","quantity":"0.001"},{"price":"2634.94","quantity":"0.082"},{"price":"2635.02","quantity":"0.000"},{"price":"2635.03","quantity":"0.000"}],"raw":{"e":"depthUpdate","E":1783517066866,"T":1783517066865,"s":"ETHUSDT","ps":"ETHUSDT","U":10999770579253,"u":10999770586155,"pu":10999770579204,"b":[["200.00","7.594"],["1211.12","2.753"],["1216.12","1.792"],["1216.16","3.648"],["1221.16","0.768"],["1562.50","1.060"],["1562.51","8.852"],["1666.60","1.078"],["1730.22","65.350"],["1730.56","1.729"],["1734.01","20.653"],["1734.04","126.458"],["1734.42","1.447"],["1734.44","56.236"],["1734.89","220.103"],["1734.99","0.689"],["1735.02","53.535"],["1735.10","12.293"],["1735.11","43.336"],["1735.12","94.679"],["1735.36","3.786"],["1735.37","0.595"],["1735.42","20.653"],["1735.62","12.166"],["1735.75","71.444"],["1735.77","15.801"],["1735.78","2.173"],["1735.80","1.330"],["1735.87","3.043"],["1735.88","0.036"],["1735.90","11.661"],["1735.95","1.226"],["1735.98","23.307"],["1735.99","8.758"],["1736.12","122.467"]],"a":[["1736.13","119.956"],["1736.23","20.052"],["1736.24","0.617"],["1736.25","10.094"],["1736.26","0.438"],["1736.27","14.992"],["1736.28","28.804"],["1736.30","9.657"],["1736.33","0.042"],["1736.39","7.189"],["1736.44","8.297"],["1736.45","107.857"],["1736.46","43.092"],["1736.48","10.452"],["1736.57","2.108"],["1736.63","10.521"],["1736.66","3.202"],["1736.68","4.705"],["1736.88","3.731"],["1737.11","20.411"],["1737.13","4.902"],["1737.14","69.431"],["1737.16","13.360"],["1737.21","0.022"],["1737.22","5.290"],["1737.79","1.635"],["1737.81","31.288"],["1737.95","89.115"],["1738.20","0.256"],["1738.25","410.177"],["1738.82","5.011"],["1738.86","2.881"],["1740.16","16.982"],["1749.67","0.038"],["1762.98","689.407"],["2634.93","0.001"],["2634.94","0.082"],["2635.02","0.000"],["2635.03","0.000"]],"st":1}}
{"schema_version":"1.3.0","event_id":"9cea3ae5-6502-4ce7-805a-fef4703cedd3","event_type":"raw.depth_update","source":"binance_market_data_recorder","venue":"binance_usdm","market_type":"perpetual_futures","symbol":"ETHUSDT","event_time_ms":1783517066968,"received_time_ms":1783517067264,"trace_id":"2c579f6f-b32f-4b98-af86-8fc7ab9e7638","first_update_id":10999770586157,"final_update_id":10999770592650,"previous_final_update_id":10999770586155,"bids":[{"price":"1211.12","quantity":"3.297"},{"price":"1216.12","quantity":"2.048"},{"price":"1216.16","quantity":"3.104"},{"price":"1221.16","quantity":"0.512"},{"price":"1562.50","quantity":"1.060"},{"price":"1562.51","quantity":"8.852"},{"price":"1666.60","quantity":"1.193"},{"price":"1700.62","quantity":"29.596"},{"price":"1701.40","quantity":"0.373"},{"price":"1713.47","quantity":"0.826"},{"price":"1714.57","quantity":"1.044"},{"price":"1730.01","quantity":"11.915"},{"price":"1732.53","quantity":"11.600"},{"price":"1733.73","quantity":"43.939"},{"price":"1734.04","quantity":"125.012"},{"price":"1734.18","quantity":"0.012"},{"price":"1734.21","quantity":"19.027"},{"price":"1734.61","quantity":"220.129"},{"price":"1734.73","quantity":"97.067"},{"price":"1734.87","quantity":"19.856"},{"price":"1734.88","quantity":"59.458"},{"price":"1734.89","quantity":"0.168"},{"price":"1734.90","quantity":"19.409"},{"price":"1735.03","quantity":"0.065"},{"price":"1735.10","quantity":"12.275"},{"price":"1735.11","quantity":"41.730"},{"price":"1735.12","quantity":"94.697"},{"price":"1735.21","quantity":"36.551"},{"price":"1735.23","quantity":"4.905"},{"price":"1735.47","quantity":"17.509"},{"price":"1735.64","quantity":"76.667"},{"price":"1735.65","quantity":"20.572"},{"price":"1735.66","quantity":"5.936"},{"price":"1735.68","quantity":"15.158"},{"price":"1735.69","quantity":"4.767"},{"price":"1735.72","quantity":"88.758"},{"price":"1735.76","quantity":"15.145"},{"price":"1735.77","quantity":"16.601"},{"price":"1735.78","quantity":"4.419"},{"price":"1735.79","quantity":"4.320"},{"price":"1735.80","quantity":"2.242"},{"price":"1735.82","quantity":"0.842"},{"price":"1735.86","quantity":"68.396"},{"price":"1735.88","quantity":"0.324"},{"price":"1735.90","quantity":"3.012"},{"price":"1735.91","quantity":"9.945"},{"price":"1735.93","quantity":"0.801"},{"price":"1735.99","quantity":"8.849"},{"price":"1736.05","quantity":"0.063"},{"price":"1736.12","quantity":"33.710"}],"asks":[{"price":"1736.13","quantity":"122.857"},{"price":"1736.15","quantity":"0.831"},{"price":"1736.16","quantity":"0.127"},{"price":"1736.19","quantity":"0.012"},{"price":"1736.20","quantity":"2.828"},{"price":"1736.21","quantity":"18.116"},{"price":"1736.22","quantity":"20.013"},{"price":"1736.23","quantity":"21.780"},{"price":"1736.25","quantity":"3.977"},{"price":"1736.33","quantity":"14.352"},{"price":"1736.36","quantity":"1.560"},{"price":"1736.37","quantity":"9.262"},{"price":"1736.39","quantity":"8.630"},{"price":"1736.44","quantity":"12.298"},{"price":"1736.46","quantity":"47.812"},{"price":"1736.48","quantity":"12.772"},{"price":"1736.49","quantity":"3.029"},{"price":"1736.57","quantity":"2.094"},{"price":"1736.63","quantity":"11.962"},{"price":"1736.64","quantity":"76.246"},{"price":"1736.72","quantity":"11.227"},{"price":"1736.85","quantity":"1.360"},{"price":"1736.86","quantity":"0.310"},{"price":"1736.90","quantity":"40.182"},{"price":"1737.11","quantity":"22.971"},{"price":"1737.13","quantity":"7.142"},{"price":"1737.14","quantity":"71.911"},{"price":"1737.35","quantity":"26.174"},{"price":"1737.39","quantity":"71.709"},{"price":"1737.43","quantity":"11.221"},{"price":"1737.52","quantity":"0.026"},{"price":"1738.58","quantity":"83.983"},{"price":"1738.72","quantity":"57.763"},{"price":"1738.74","quantity":"0.752"},{"price":"1738.78","quantity":"4.109"},{"price":"1738.88","quantity":"10.808"},{"price":"1739.41","quantity":"21.363"},{"price":"1739.42","quantity":"25.430"},{"price":"1740.16","quantity":"0.026"},{"price":"1740.21","quantity":"5.357"},{"price":"1740.58","quantity":"0.782"},{"price":"1741.75","quantity":"2.539"},{"price":"1747.12","quantity":"0.000"},{"price":"1757.13","quantity":"33.242"},{"price":"2634.92","quantity":"0.020"},{"price":"2635.01","quantity":"0.000"}],"raw":{"e":"depthUpdate","E":1783517066968,"T":1783517066967,"s":"ETHUSDT","ps":"ETHUSDT","U":10999770586157,"u":10999770592650,"pu":10999770586155,"b":[["1211.12","3.297"],["1216.12","2.048"],["1216.16","3.104"],["1221.16","0.512"],["1562.50","1.060"],["1562.51","8.852"],["1666.60","1.193"],["1700.62","29.596"],["1701.40","0.373"],["1713.47","0.826"],["1714.57","1.044"],["1730.01","11.915"],["1732.53","11.600"],["1733.73","43.939"],["1734.04","125.012"],["1734.18","0.012"],["1734.21","19.027"],["1734.61","220.129"],["1734.73","97.067"],["1734.87","19.856"],["1734.88","59.458"],["1734.89","0.168"],["1734.90","19.409"],["1735.03","0.065"],["1735.10","12.275"],["1735.11","41.730"],["1735.12","94.697"],["1735.21","36.551"],["1735.23","4.905"],["1735.47","17.509"],["1735.64","76.667"],["1735.65","20.572"],["1735.66","5.936"],["1735.68","15.158"],["1735.69","4.767"],["1735.72","88.758"],["1735.76","15.145"],["1735.77","16.601"],["1735.78","4.419"],["1735.79","4.320"],["1735.80","2.242"],["1735.82","0.842"],["1735.86","68.396"],["1735.88","0.324"],["1735.90","3.012"],["1735.91","9.945"],["1735.93","0.801"],["1735.99","8.849"],["1736.05","0.063"],["1736.12","33.710"]],"a":[["1736.13","122.857"],["1736.15","0.831"],["1736.16","0.127"],["1736.19","0.012"],["1736.20","2.828"],["1736.21","18.116"],["1736.22","20.013"],["1736.23","21.780"],["1736.25","3.977"],["1736.33","14.352"],["1736.36","1.560"],["1736.37","9.262"],["1736.39","8.630"],["1736.44","12.298"],["1736.46","47.812"],["1736.48","12.772"],["1736.49","3.029"],["1736.57","2.094"],["1736.63","11.962"],["1736.64","76.246"],["1736.72","11.227"],["1736.85","1.360"],["1736.86","0.310"],["1736.90","40.182"],["1737.11","22.971"],["1737.13","7.142"],["1737.14","71.911"],["1737.35","26.174"],["1737.39","71.709"],["1737.43","11.221"],["1737.52","0.026"],["1738.58","83.983"],["1738.72","57.763"],["1738.74","0.752"],["1738.78","4.109"],["1738.88","10.808"],["1739.41","21.363"],["1739.42","25.430"],["1740.16","0.026"],["1740.21","5.357"],["1740.58","0.782"],["1741.75","2.539"],["1747.12","0.000"],["1757.13","33.242"],["2634.92","0.020"],["2635.01","0.000"]],"st":1}}
{"schema_version":"1.3.0","event_id":"66ef18bf-23bf-4725-a578-91e4b3f5ec9e","event_type":"raw.depth_update","source":"binance_market_data_recorder","venue":"binance_usdm","market_type":"perpetual_futures","symbol":"ETHUSDT","event_time_ms":1783517067070,"received_time_ms":1783517067272,"trace_id":"b33e889b-de22-4eaa-86eb-52c0f4d04b41","first_update_id":10999770592694,"final_update_id":10999770604649,"previous_final_update_id":10999770592650,"bids":[{"price":"1211.12","quantity":"3.841"},{"price":"1216.12","quantity":"2.336"},{"price":"1216.16","quantity":"2.560"},{"price":"1221.16","quantity":"0.224"},{"price":"1562.50","quantity":"1.060"},{"price":"1562.51","quantity":"8.852"},{"price":"1666.60","quantity":"1.078"},{"price":"1733.76","quantity":"35.799"},{"price":"1733.77","quantity":"17.792"},{"price":"1734.01","quantity":"17.457"},{"price":"1734.06","quantity":"474.207"},{"price":"1734.12","quantity":"113.048"},{"price":"1734.50","quantity":"229.164"},{"price":"1734.57","quantity":"51.615"},{"price":"1734.61","quantity":"0.258"},{"price":"1734.63","quantity":"19.810"},{"price":"1734.87","quantity":"19.838"},{"price":"1734.88","quantity":"59.476"},{"price":"1735.00","quantity":"217.843"},{"price":"1735.07","quantity":"5.945"},{"price":"1735.09","quantity":"1.235"},{"price":"1735.10","quantity":"23.275"},{"price":"1735.11","quantity":"44.574"},{"price":"1735.16","quantity":"4.709"},{"price":"1735.43","quantity":"4.065"},{"price":"1735.62","quantity":"17.933"},{"price":"1735.66","quantity":"0.169"},{"price":"1735.75","quantity":"71.556"},{"price":"1735.77","quantity":"18.047"},{"price":"1735.78","quantity":"1.640"},{"price":"1735.80","quantity":"2.130"},{"price":"1735.86","quantity":"77.045"},{"price":"1735.87","quantity":"1.139"},{"price":"1735.89","quantity":"5.536"},{"price":"1735.93","quantity":"22.985"},{"price":"1735.94","quantity":"7.074"},{"price":"1735.95","quantity":"3.530"},{"price":"1735.96","quantity":"2.280"},{"price":"1735.98","quantity":"1.123"},{"price":"1735.99","quantity":"8.758"},{"price":"1736.02","quantity":"0.061"},{"price":"1736.12","quantity":"21.486"}],"asks":[{"price":"1736.13","quantity":"123.840"},{"price":"1736.15","quantity":"0.012"},{"price":"1736.16","quantity":"0.038"},{"price":"1736.20","quantity":"3.980"},{"price":"1736.25","quantity":"4.477"},{"price":"1736.28","quantity":"31.446"},{"price":"1736.30","quantity":"13.533"},{"price":"1736.36","quantity":"0.560"},{"price":"1736.37","quantity":"7.821"},{"price":"1736.39","quantity":"33.529"},{"price":"1736.44","quantity":"10.857"},{"price":"1736.45","quantity":"79.035"},{"price":"1736.47","quantity":"15.266"},{"price":"1736.48","quantity":"12.772"},{"price":"1736.53","quantity":"3.113"},{"price":"1736.56","quantity":"10.776"},{"price":"1736.63","quantity":"10.521"},{"price":"1736.72","quantity":"9.786"},{"price":"1736.91","quantity":"69.817"},{"price":"1737.11","quantity":"21.277"},{"price":"1737.71","quantity":"0.042"},{"price":"1737.83","quantity":"33.086"},{"price":"1737.87","quantity":"9.593"},{"price":"1738.20","quantity":"407.555"},{"price":"1738.25","quantity":"2.878"},{"price":"1738.62","quantity":"13.195"},{"price":"1739.61","quantity":"23.070"},{"price":"1739.64","quantity":"91.236"},{"price":"1740.48","quantity":"19.360"},{"price":"1740.51","quantity":"30.571"},{"price":"1741.34","quantity":"18.784"},{"price":"1741.37","quantity":"9.895"},{"price":"1742.21","quantity":"52.963"},{"price":"1742.24","quantity":"19.942"},{"price":"1743.08","quantity":"7.051"},{"price":"1743.11","quantity":"0.000"},{"price":"2236.18","quantity":"0.000"},{"price":"2634.91","quantity":"0.001"},{"price":"2635.00","quantity":"0.193"}],"raw":{"e":"depthUpdate","E":1783517067070,"T":1783517067069,"s":"ETHUSDT","ps":"ETHUSDT","U":10999770592694,"u":10999770604649,"pu":10999770592650,"b":[["1211.12","3.841"],["1216.12","2.336"],["1216.16","2.560"],["1221.16","0.224"],["1562.50","1.060"],["1562.51","8.852"],["1666.60","1.078"],["1733.76","35.799"],["1733.77","17.792"],["1734.01","17.457"],["1734.06","474.207"],["1734.12","113.048"],["1734.50","229.164"],["1734.57","51.615"],["1734.61","0.258"],["1734.63","19.810"],["1734.87","19.838"],["1734.88","59.476"],["1735.00","217.843"],["1735.07","5.945"],["1735.09","1.235"],["1735.10","23.275"],["1735.11","44.574"],["1735.16","4.709"],["1735.43","4.065"],["1735.62","17.933"],["1735.66","0.169"],["1735.75","71.556"],["1735.77","18.047"],["1735.78","1.640"],["1735.80","2.130"],["1735.86","77.045"],["1735.87","1.139"],["1735.89","5.536"],["1735.93","22.985"],["1735.94","7.074"],["1735.95","3.530"],["1735.96","2.280"],["1735.98","1.123"],["1735.99","8.758"],["1736.02","0.061"],["1736.12","21.486"]],"a":[["1736.13","123.840"],["1736.15","0.012"],["1736.16","0.038"],["1736.20","3.980"],["1736.25","4.477"],["1736.28","31.446"],["1736.30","13.533"],["1736.36","0.560"],["1736.37","7.821"],["1736.39","33.529"],["1736.44","10.857"],["1736.45","79.035"],["1736.47","15.266"],["1736.48","12.772"],["1736.53","3.113"],["1736.56","10.776"],["1736.63","10.521"],["1736.72","9.786"],["1736.91","69.817"],["1737.11","21.277"],["1737.71","0.042"],["1737.83","33.086"],["1737.87","9.593"],["1738.20","407.555"],["1738.25","2.878"],["1738.62","13.195"],["1739.61","23.070"],["1739.64","91.236"],["1740.48","19.360"],["1740.51","30.571"],["1741.34","18.784"],["1741.37","9.895"],["1742.21","52.963"],["1742.24","19.942"],["1743.08","7.051"],["1743.11","0.000"],["2236.18","0.000"],["2634.91","0.001"],["2635.00","0.193"]],"st":1}}
{"schema_version":"1.3.0","event_id":"49cbdb0b-afb9-492f-960f-c002965ae937","event_type":"raw.depth_update","source":"binance_market_data_recorder","venue":"binance_usdm","market_type":"perpetual_futures","symbol":"ETHUSDT","event_time_ms":1783517067172,"received_time_ms":1783517067276,"trace_id":"57e70dad-ee7b-4e8a-807c-b6b2a0ae6b8f","first_update_id":10999770604871,"final_update_id":10999770612942,"previous_final_update_id":10999770604649,"bids":[{"price":"200.00","quantity":"7.594"},{"price":"1211.12","quantity":"4.417"},{"price":"1216.12","quantity":"2.560"},{"price":"1216.16","quantity":"2.016"},{"price":"1216.27","quantity":"0.244"},{"price":"1221.16","quantity":"0.000"},{"price":"1562.50","quantity":"1.060"},{"price":"1562.51","quantity":"8.738"},{"price":"1666.60","quantity":"1.193"},{"price":"1701.40","quantity":"0.402"},{"price":"1708.13","quantity":"52.333"},{"price":"1708.36","quantity":"1.189"},{"price":"1713.52","quantity":"27.295"},{"price":"1713.56","quantity":"81.234"},{"price":"1727.47","quantity":"0.000"},{"price":"1729.72","quantity":"0.082"},{"price":"1732.63","quantity":"3.761"},{"price":"1733.74","quantity":"16.412"},{"price":"1733.77","quantity":"18.392"},{"price":"1734.06","quantity":"54.181"},{"price":"1734.12","quantity":"55.897"},{"price":"1734.21","quantity":"26.784"},{"price":"1734.51","quantity":"13.293"},{"price":"1735.02","quantity":"55.437"},{"price":"1735.03","quantity":"1.016"},{"price":"1735.08","quantity":"6.025"},{"price":"1735.12","quantity":"95.497"},{"price":"1735.13","quantity":"3.178"},{"price":"1735.14","quantity":"9.518"},{"price":"1735.21","quantity":"34.639"},{"price":"1735.22","quantity":"16.399"},{"price":"1735.44","quantity":"27.761"},{"price":"1735.60","quantity":"4.613"},{"price":"1735.77","quantity":"16.601"},{"price":"1736.12","quantity":"21.543"}],"asks":[{"price":"1736.13","quantity":"123.828"},{"price":"1736.28","quantity":"31.469"},{"price":"1736.32","quantity":"0.174"},{"price":"1736.35","quantity":"4.594"},{"price":"1736.36","quantity":"5.168"},{"price":"1736.39","quantity":"28.921"},{"price":"1736.40","quantity":"21.374"},{"price":"1736.44","quantity":"9.416"},{"price":"1736.53","quantity":"1.419"},{"price":"1736.56","quantity":"9.082"},{"price":"1736.62","quantity":"0.755"},{"price":"1736.74","quantity":"41.892"},{"price":"1736.88","quantity":"3.731"},{"price":"1736.91","quantity":"68.123"},{"price":"1737.02","quantity":"25.859"},{"price":"1737.03","quantity":"84.325"},{"price":"1737.11","quantity":"22.971"},{"price":"1737.14","quantity":"72.198"},{"price":"1737.16","quantity":"11.330"},{"price":"1737.17","quantity":"1.605"},{"price":"1737.60","quantity":"6.285"},{"price":"1737.83","quantity":"34.780"},{"price":"1738.08","quantity":"1.684"},{"price":"1738.71","quantity":"38.346"},{"price":"1739.96","quantity":"19.275"},{"price":"1748.32","quantity":"2.989"},{"price":"1762.17","quantity":"38.828"},{"price":"1763.65","quantity":"0.000"},{"price":"1770.03","quantity":"29.906"},{"price":"2634.89","quantity":"0.001"},{"price":"2634.90","quantity":"0.001"},{"price":"2634.98","quantity":"0.000"},{"price":"2634.99","quantity":"0.000"}],"raw":{"e":"depthUpdate","E":1783517067172,"T":1783517067171,"s":"ETHUSDT","ps":"ETHUSDT","U":10999770604871,"u":10999770612942,"pu":10999770604649,"b":[["200.00","7.594"],["1211.12","4.417"],["1216.12","2.560"],["1216.16","2.016"],["1216.27","0.244"],["1221.16","0.000"],["1562.50","1.060"],["1562.51","8.738"],["1666.60","1.193"],["1701.40","0.402"],["1708.13","52.333"],["1708.36","1.189"],["1713.52","27.295"],["1713.56","81.234"],["1727.47","0.000"],["1729.72","0.082"],["1732.63","3.761"],["1733.74","16.412"],["1733.77","18.392"],["1734.06","54.181"],["1734.12","55.897"],["1734.21","26.784"],["1734.51","13.293"],["1735.02","55.437"],["1735.03","1.016"],["1735.08","6.025"],["1735.12","95.497"],["1735.13","3.178"],["1735.14","9.518"],["1735.21","34.639"],["1735.22","16.399"],["1735.44","27.761"],["1735.60","4.613"],["1735.77","16.601"],["1736.12","21.543"]],"a":[["1736.13","123.828"],["1736.28","31.469"],["1736.32","0.174"],["1736.35","4.594"],["1736.36","5.168"],["1736.39","28.921"],["1736.40","21.374"],["1736.44","9.416"],["1736.53","1.419"],["1736.56","9.082"],["1736.62","0.755"],["1736.74","41.892"],["1736.88","3.731"],["1736.91","68.123"],["1737.02","25.859"],["1737.03","84.325"],["1737.11","22.971"],["1737.14","72.198"],["1737.16","11.330"],["1737.17","1.605"],["1737.60","6.285"],["1737.83","34.780"],["1738.08","1.684"],["1738.71","38.346"],["1739.96","19.275"],["1748.32","2.989"],["1762.17","38.828"],["1763.65","0.000"],["1770.03","29.906"],["2634.89","0.001"],["2634.90","0.001"],["2634.98","0.000"],["2634.99","0.000"]],"st":1}}
{"schema_version":"1.3.0","event_id":"2df152ff-45f6-4881-a9f2-aaab9e7f8c95","event_type":"raw.depth_update","source":"binance_market_data_recorder","venue":"binance_usdm","market_type":"perpetual_futures","symbol":"ETHUSDT","event_time_ms":1783517067274,"received_time_ms":1783517067295,"trace_id":"3f91cedf-487d-46af-b38d-848ee3c4674e","first_update_id":10999770612990,"final_update_id":10999770622458,"previous_final_update_id":10999770612942,"bids":[{"price":"1211.12","quantity":"5.249"},{"price":"1216.16","quantity":"1.344"},{"price":"1216.27","quantity":"0.084"},{"price":"1562.50","quantity":"1.060"},{"price":"1562.51","quantity":"8.738"},{"price":"1698.07","quantity":"0.145"},{"price":"1701.40","quantity":"0.373"},{"price":"1729.70","quantity":"2790.824"},{"price":"1734.06","quantity":"474.207"},{"price":"1734.12","quantity":"111.586"},{"price":"1734.24","quantity":"1.474"},{"price":"1734.28","quantity":"22.858"},{"price":"1734.29","quantity":"8.642"},{"price":"1734.38","quantity":"13.652"},{"price":"1734.40","quantity":"223.405"},{"price":"1734.41","quantity":"80.333"},{"price":"1734.50","quantity":"9.332"},{"price":"1734.57","quantity":"29.351"},{"price":"1734.61","quantity":"0.240"},{"price":"1734.66","quantity":"1.206"},{"price":"1735.01","quantity":"19.586"},{"price":"1735.08","quantity":"6.825"},{"price":"1735.11","quantity":"45.374"},{"price":"1735.25","quantity":"39.105"},{"price":"1735.35","quantity":"20.776"},{"price":"1735.69","quantity":"4.849"},{"price":"1735.70","quantity":"28.978"},{"price":"1735.74","quantity":"29.064"},{"price":"1735.75","quantity":"71.444"},{"price":"1735.76","quantity":"11.833"},{"price":"1735.77","quantity":"16.201"},{"price":"1735.86","quantity":"68.396"},{"price":"1735.87","quantity":"1.139"},{"price":"1735.90","quantity":"25.196"},{"price":"1735.93","quantity":"4.113"},{"price":"1735.94","quantity":"3.390"},{"price":"1735.95","quantity":"3.824"},{"price":"1735.96","quantity":"0.552"},{"price":"1735.97","quantity":"3.095"},{"price":"1735.99","quantity":"6.258"},{"price":"1736.11","quantity":"0.749"},{"price":"1736.12","quantity":"7.951"}],"asks":[{"price":"1736.13","quantity":"132.837"},{"price":"1736.16","quantity":"0.255"},{"price":"1736.18","quantity":"1.769"},{"price":"1736.22","quantity":"24.022"},{"price":"1736.29","quantity":"1.210"},{"price":"1736.36","quantity":"5.168"},{"price":"1736.37","quantity":"7.833"},{"price":"1736.76","quantity":"18.794"},{"price":"1736.81","quantity":"19.320"},{"price":"1736.88","quantity":"3.621"},{"price":"1736.90","quantity":"40.757"},{"price":"1737.00","quantity":"71.577"},{"price":"1737.11","quantity":"21.277"},{"price":"1737.13","quantity":"7.142"},{"price":"1737.16","quantity":"11.330"},{"price":"1737.26","quantity":"5.190"},{"price":"1737.37","quantity":"40.106"},{"price":"1737.50","quantity":"67.957"},{"price":"1737.51","quantity":"11.738"},{"price":"1737.60","quantity":"4.591"},{"price":"1737.69","quantity":"28.817"},{"price":"1738.07","quantity":"34.583"},{"price":"1738.15","quantity":"24.452"},{"price":"1738.37","quantity":"88.051"},{"price":"1738.41","quantity":"5.890"},{"price":"1738.56","quantity":"1.996"},{"price":"1744.82","quantity":"0.066"},{"price":"1747.12","quantity":"15.000"},{"price":"1749.44","quantity":"0.057"},{"price":"1763.90","quantity":"15.787"},{"price":"1770.18","quantity":"56.565"},{"price":"1776.06","quantity":"11.248"},{"price":"2634.88","quantity":"0.001"},{"price":"2634.97","quantity":"0.000"}],"raw":{"e":"depthUpdate","E":1783517067274,"T":1783517067273,"s":"ETHUSDT","ps":"ETHUSDT","U":10999770612990,"u":10999770622458,"pu":10999770612942,"b":[["1211.12","5.249"],["1216.16","1.344"],["1216.27","0.084"],["1562.50","1.060"],["1562.51","8.738"],["1698.07","0.145"],["1701.40","0.373"],["1729.70","2790.824"],["1734.06","474.207"],["1734.12","111.586"],["1734.24","1.474"],["1734.28","22.858"],["1734.29","8.642"],["1734.38","13.652"],["1734.40","223.405"],["1734.41","80.333"],["1734.50","9.332"],["1734.57","29.351"],["1734.61","0.240"],["1734.66","1.206"],["1735.01","19.586"],["1735.08","6.825"],["1735.11","45.374"],["1735.25","39.105"],["1735.35","20.776"],["1735.69","4.849"],["1735.70","28.978"],["1735.74","29.064"],["1735.75","71.444"],["1735.76","11.833"],["1735.77","16.201"],["1735.86","68.396"],["1735.87","1.139"],["1735.90","25.196"],["1735.93","4.113"],["1735.94","3.390"],["1735.95","3.824"],["1735.96","0.552"],["1735.97","3.095"],["1735.99","6.258"],["1736.11","0.749"],["1736.12","7.951"]],"a":[["1736.13","132.837"],["1736.16","0.255"],["1736.18","1.769"],["1736.22","24.022"],["1736.29","1.210"],["1736.36","5.168"],["1736.37","7.833"],["1736.76","18.794"],["1736.81","19.320"],["1736.88","3.621"],["1736.90","40.757"],["1737.00","71.577"],["1737.11","21.277"],["1737.13","7.142"],["1737.16","11.330"],["1737.26","5.190"],["1737.37","40.106"],["1737.50","67.957"],["1737.51","11.738"],["1737.60","4.591"],["1737.69","28.817"],["1738.07","34.583"],["1738.15","24.452"],["1738.37","88.051"],["1738.41","5.890"],["1738.56","1.996"],["1744.82","0.066"],["1747.12","15.000"],["1749.44","0.057"],["1763.90","15.787"],["1770.18","56.565"],["1776.06","11.248"],["2634.88","0.001"],["2634.97","0.000"]],"st":1}}
{"schema_version":"1.3.0","event_id":"b7b2bae4-a4cb-4247-acb4-81c83bc678cb","event_type":"raw.depth_update","source":"binance_market_data_recorder","venue":"binance_usdm","market_type":"perpetual_futures","symbol":"ETHUSDT","event_time_ms":1783517067376,"received_time_ms":1783517067371,"trace_id":"a1abb571-cc09-43bc-ac61-17b1141101a2","first_update_id":10999770622549,"final_update_id":10999770631686,"previous_final_update_id":10999770622458,"bids":[{"price":"1211.12","quantity":"6.049"},{"price":"1216.16","quantity":"0.544"},{"price":"1562.50","quantity":"1.060"},{"price":"1562.51","quantity":"8.880"},{"price":"1666.60","quantity":"1.078"},{"price":"1701.40","quantity":"0.402"},{"price":"1714.43","quantity":"8.763"},{"price":"1720.48","quantity":"0.064"},{"price":"1727.44","quantity":"0.012"},{"price":"1734.06","quantity":"54.181"},{"price":"1734.12","quantity":"55.897"},{"price":"1734.18","quantity":"0.012"},{"price":"1734.21","quantity":"79.952"},{"price":"1734.24","quantity":"1.474"},{"price":"1734.29","quantity":"8.551"},{"price":"1734.30","quantity":"21.202"},{"price":"1734.35","quantity":"8.764"},{"price":"1734.36","quantity":"2.988"},{"price":"1734.37","quantity":"0.168"},{"price":"1734.38","quantity":"56.188"},{"price":"1734.39","quantity":"19.527"},{"price":"1734.40","quantity":"3.664"},{"price":"1734.41","quantity":"80.351"},{"price":"1734.46","quantity":"25.640"},{"price":"1734.63","quantity":"239.299"},{"price":"1734.75","quantity":"287.604"},{"price":"1734.84","quantity":"272.872"},{"price":"1735.00","quantity":"216.833"},{"price":"1735.02","quantity":"53.535"},{"price":"1735.09","quantity":"2.035"},{"price":"1735.10","quantity":"24.075"},{"price":"1735.12","quantity":"96.297"},{"price":"1735.18","quantity":"2.293"},{"price":"1735.25","quantity":"0.169"},{"price":"1735.27","quantity":"69.112"},{"price":"1735.32","quantity":"65.935"},{"price":"1735.33","quantity":"16.529"},{"price":"1735.34","quantity":"0.110"},{"price":"1735.35","quantity":"20.788"},{"price":"1735.58","quantity":"5.861"},{"price":"1735.61","quantity":"8.709"},{"price":"1735.62","quantity":"32.166"},{"price":"1735.65","quantity":"20.679"},{"price":"1735.66","quantity":"29.004"},{"price":"1735.68","quantity":"15.094"},{"price":"1735.70","quantity":"0.037"},{"price":"1735.76","quantity":"11.257"},{"price":"1735.77","quantity":"17.647"},{"price":"1735.79","quantity":"3.983"},{"price":"1735.81","quantity":"7.246"},{"price":"1735.84","quantity":"0.058"},{"price":"1735.88","quantity":"0.036"},{"price":"1735.89","quantity":"14.235"},{"price":"1735.90","quantity":"3.103"},{"price":"1735.92","quantity":"24.825"},{"price":"1735.93","quantity":"3.974"},{"price":"1735.94","quantity":"0.103"},{"price":"1735.95","quantity":"2.378"},{"price":"1735.99","quantity":"26.090"},{"price":"1736.04","quantity":"0.012"},{"price":"1736.05","quantity":"0.051"},{"price":"1736.06","quantity":"0.014"},{"price":"1736.07","quantity":"0.036"},{"price":"1736.08","quantity":"0.723"},{"price":"1736.09","quantity":"0.930"},{"price":"1736.10","quantity":"3.724"},{"price":"1736.12","quantity":"61.868"}],"asks":[{"price":"1736.13","quantity":"153.647"},{"price":"1736.17","quantity":"2.816"},{"price":"1736.18","quantity":"18.616"},{"price":"1736.21","quantity":"18.136"},{"price":"1736.23","quantity":"22.568"},{"price":"1736.25","quantity":"3.977"},{"price":"1736.26","quantity":"0.482"},{"price":"1736.27","quantity":"0.026"},{"price":"1736.31","quantity":"22.913"},{"price":"1736.32","quantity":"0.130"},{"price":"1736.33","quantity":"0.012"},{"price":"1736.36","quantity":"5.168"},{"price":"1736.37","quantity":"7.833"},{"price":"1736.41","quantity":"9.520"},{"price":"1736.44","quantity":"9.416"},{"price":"1736.45","quantity":"73.507"},{"price":"1736.63","quantity":"10.521"},{"price":"1736.64","quantity":"76.197"},{"price":"1736.72","quantity":"9.786"},{"price":"1736.73","quantity":"45.967"},{"price":"1736.74","quantity":"25.216"},{"price":"1736.91","quantity":"84.799"},{"price":"1737.00","quantity":"73.244"},{"price":"1737.17","quantity":"1.527"},{"price":"1737.26","quantity":"5.190"},{"price":"1737.50","quantity":"67.937"},{"price":"1737.51","quantity":"0.218"},{"price":"1737.89","quantity":"17.008"},{"price":"1738.15","quantity":"31.957"},{"price":"1738.66","quantity":"7.002"},{"price":"1738.70","quantity":"3.393"},{"price":"1738.71","quantity":"35.150"},{"price":"1738.72","quantity":"54.567"},{"price":"1738.88","quantity":"8.584"},{"price":"1739.41","quantity":"13.858"},{"price":"1739.42","quantity":"17.925"},{"price":"1744.82","quantity":"0.078"},{"price":"1781.13","quantity":"5.002"},{"price":"2634.86","quantity":"0.001"},{"price":"2634.87","quantity":"0.001"},{"price":"2634.95","quantity":"0.000"},{"price":"2634.96","quantity":"0.000"}],"raw":{"e":"depthUpdate","E":1783517067376,"T":1783517067375,"s":"ETHUSDT","ps":"ETHUSDT","U":10999770622549,"u":10999770631686,"pu":10999770622458,"b":[["1211.12","6.049"],["1216.16","0.544"],["1562.50","1.060"],["1562.51","8.880"],["1666.60","1.078"],["1701.40","0.402"],["1714.43","8.763"],["1720.48","0.064"],["1727.44","0.012"],["1734.06","54.181"],["1734.12","55.897"],["1734.18","0.012"],["1734.21","79.952"],["1734.24","1.474"],["1734.29","8.551"],["1734.30","21.202"],["1734.35","8.764"],["1734.36","2.988"],["1734.37","0.168"],["1734.38","56.188"],["1734.39","19.527"],["1734.40","3.664"],["1734.41","80.351"],["1734.46","25.640"],["1734.63","239.299"],["1734.75","287.604"],["1734.84","272.872"],["1735.00","216.833"],["1735.02","53.535"],["1735.09","2.035"],["1735.10","24.075"],["1735.12","96.297"],["1735.18","2.293"],["1735.25","0.169"],["1735.27","69.112"],["1735.32","65.935"],["1735.33","16.529"],["1735.34","0.110"],["1735.35","20.788"],["1735.58","5.861"],["1735.61","8.709"],["1735.62","32.166"],["1735.65","20.679"],["1735.66","29.004"],["1735.68","15.094"],["1735.70","0.037"],["1735.76","11.257"],["1735.77","17.647"],["1735.79","3.983"],["1735.81","7.246"],["1735.84","0.058"],["1735.88","0.036"],["1735.89","14.235"],["1735.90","3.103"],["1735.92","24.825"],["1735.93","3.974"],["1735.94","0.103"],["1735.95","2.378"],["1735.99","26.090"],["1736.04","0.012"],["1736.05","0.051"],["1736.06","0.014"],["1736.07","0.036"],["1736.08","0.723"],["1736.09","0.930"],["1736.10","3.724"],["1736.12","61.868"]],"a":[["1736.13","153.647"],["1736.17","2.816"],["1736.18","18.616"],["1736.21","18.136"],["1736.23","22.568"],["1736.25","3.977"],["1736.26","0.482"],["1736.27","0.026"],["1736.31","22.913"],["1736.32","0.130"],["1736.33","0.012"],["1736.36","5.168"],["1736.37","7.833"],["1736.41","9.520"],["1736.44","9.416"],["1736.45","73.507"],["1736.63","10.521"],["1736.64","76.197"],["1736.72","9.786"],["1736.73","45.967"],["1736.74","25.216"],["1736.91","84.799"],["1737.00","73.244"],["1737.17","1.527"],["1737.26","5.190"],["1737.50","67.937"],["1737.51","0.218"],["1737.89","17.008"],["1738.15","31.957"],["1738.66","7.002"],["1738.70","3.393"],["1738.71","35.150"],["1738.72","54.567"],["1738.88","8.584"],["1739.41","13.858"],["1739.42","17.925"],["1744.82","0.078"],["1781.13","5.002"],["2634.86","0.001"],["2634.87","0.001"],["2634.95","0.000"],["2634.96","0.000"]],"st":1}}
{"schema_version":"1.3.0","event_id":"1ce75518-c69e-4d08-a465-9e4aed3aa735","event_type":"raw.depth_update","source":"binance_market_data_recorder","venue":"binance_usdm","market_type":"perpetual_futures","symbol":"ETHUSDT","event_time_ms":1783517067478,"received_time_ms":1783517067472,"trace_id":"15728fc7-a504-4102-9b11-d09bcfc2125a","first_update_id":10999770631816,"final_update_id":10999770638173,"previous_final_update_id":10999770631686,"bids":[{"price":"200.00","quantity":"7.594"},{"price":"1211.12","quantity":"6.881"},{"price":"1216.13","quantity":"0.352"},{"price":"1216.16","quantity":"0.000"},{"price":"1562.50","quantity":"1.060"},{"price":"1562.51","quantity":"8.880"},{"price":"1650.00","quantity":"1681.405"},{"price":"1666.60","quantity":"1.193"},{"price":"1701.40","quantity":"0.373"},{"price":"1718.04","quantity":"86.464"},{"price":"1733.71","quantity":"84.523"},{"price":"1734.06","quantity":"474.207"},{"price":"1734.12","quantity":"111.586"},{"price":"1734.21","quantity":"18.716"},{"price":"1734.24","quantity":"1.565"},{"price":"1734.37","quantity":"9.825"},{"price":"1734.38","quantity":"13.652"},{"price":"1734.49","quantity":"272.500"},{"price":"1734.62","quantity":"119.370"},{"price":"1734.63","quantity":"1.545"},{"price":"1734.64","quantity":"55.338"},{"price":"1734.75","quantity":"68.153"},{"price":"1734.84","quantity":"272.872"},{"price":"1735.28","quantity":"43.898"},{"price":"1735.32","quantity":"26.988"},{"price":"1735.33","quantity":"16.517"},{"price":"1735.34","quantity":"0.098"},{"price":"1735.35","quantity":"20.776"},{"price":"1735.62","quantity":"10.466"},{"price":"1735.65","quantity":"20.572"},{"price":"1735.73","quantity":"26.154"},{"price":"1735.76","quantity":"15.145"},{"price":"1735.77","quantity":"19.397"},{"price":"1735.87","quantity":"1.139"},{"price":"1735.90","quantity":"4.458"},{"price":"1735.91","quantity":"32.141"},{"price":"1735.92","quantity":"26.525"},{"price":"1735.93","quantity":"0.778"},{"price":"1735.94","quantity":"1.255"},{"price":"1735.97","quantity":"3.186"},{"price":"1735.99","quantity":"0.052"},{"price":"1736.00","quantity":"5.731"},{"price":"1736.06","quantity":"0.026"},{"price":"1736.07","quantity":"0.048"},{"price":"1736.08","quantity":"0.735"},{"price":"1736.09","quantity":"0.942"},{"price":"1736.12","quantity":"18.426"}],"asks":[{"price":"1736.17","quantity":"0.036"},{"price":"1736.18","quantity":"1.769"},{"price":"1736.23","quantity":"22.068"},{"price":"1736.25","quantity":"4.477"},{"price":"1736.33","quantity":"1.712"},{"price":"1736.37","quantity":"10.715"},{"price":"1736.44","quantity":"10.857"},{"price":"1736.63","quantity":"10.262"},{"price":"1736.86","quantity":"0.322"},{"price":"1736.88","quantity":"3.621"},{"price":"1736.89","quantity":"9.594"},{"price":"1736.91","quantity":"86.466"},{"price":"1737.16","quantity":"13.024"},{"price":"1737.26","quantity":"6.884"},{"price":"1737.43","quantity":"11.221"},{"price":"1737.69","quantity":"27.123"},{"price":"1737.88","quantity":"36.568"},{"price":"1738.07","quantity":"32.889"},{"price":"1738.15","quantity":"24.452"},{"price":"1738.20","quantity":"0.256"},{"price":"1738.25","quantity":"410.177"},{"price":"1738.41","quantity":"4.196"},{"price":"1738.71","quantity":"38.346"},{"price":"1738.97","quantity":"181.920"},{"price":"1740.16","quantity":"0.026"},{"price":"1768.81","quantity":"71.211"},{"price":"1773.23","quantity":"63.843"},{"price":"1779.54","quantity":"157.303"},{"price":"2634.85","quantity":"0.001"},{"price":"2634.94","quantity":"0.081"}],"raw":{"e":"depthUpdate","E":1783517067478,"T":1783517067477,"s":"ETHUSDT","ps":"ETHUSDT","U":10999770631816,"u":10999770638173,"pu":10999770631686,"b":[["200.00","7.594"],["1211.12","6.881"],["1216.13","0.352"],["1216.16","0.000"],["1562.50","1.060"],["1562.51","8.880"],["1650.00","1681.405"],["1666.60","1.193"],["1701.40","0.373"],["1718.04","86.464"],["1733.71","84.523"],["1734.06","474.207"],["1734.12","111.586"],["1734.21","18.716"],["1734.24","1.565"],["1734.37","9.825"],["1734.38","13.652"],["1734.49","272.500"],["1734.62","119.370"],["1734.63","1.545"],["1734.64","55.338"],["1734.75","68.153"],["1734.84","272.872"],["1735.28","43.898"],["1735.32","26.988"],["1735.33","16.517"],["1735.34","0.098"],["1735.35","20.776"],["1735.62","10.466"],["1735.65","20.572"],["1735.73","26.154"],["1735.76","15.145"],["1735.77","19.397"],["1735.87","1.139"],["1735.90","4.458"],["1735.91","32.141"],["1735.92","26.525"],["1735.93","0.778"],["1735.94","1.255"],["1735.97","3.186"],["1735.99","0.052"],["1736.00","5.731"],["1736.06","0.026"],["1736.07","0.048"],["1736.08","0.735"],["1736.09","0.942"],["1736.12","18.426"]],"a":[["1736.17","0.036"],["1736.18","1.769"],["1736.23","22.068"],["1736.25","4.477"],["1736.33","1.712"],["1736.37","10.715"],["1736.44","10.857"],["1736.63","10.262"],["1736.86","0.322"],["1736.88","3.621"],["1736.89","9.594"],["1736.91","86.466"],["1737.16","13.024"],["1737.26","6.884"],["1737.43","11.221"],["1737.69","27.123"],["1737.88","36.568"],["1738.07","32.889"],["1738.15","24.452"],["1738.20","0.256"],["1738.25","410.177"],["1738.41","4.196"],["1738.71","38.346"],["1738.97","181.920"],["1740.16","0.026"],["1768.81","71.211"],["1773.23","63.843"],["1779.54","157.303"],["2634.85","0.001"],["2634.94","0.081"]],"st":1}}
