{"schema_version":"1.3.0","event_id":"91f6f179-788c-4198-8e42-69580e79598b","event_type":"raw.depth_update","source":"binance_market_data_recorder","venue":"binance_usdm","market_type":"perpetual_futures","symbol":"ETHUSDT","event_time_ms":1783517075048,"received_time_ms":1783517075399,"trace_id":"88f0049a-2efd-4d4d-a636-e887ded939d0","first_update_id":10999771397824,"final_update_id":10999771412702,"previous_final_update_id":10999771397751,"bids":[{"price":"200.00","quantity":"7.594"},{"price":"1211.28","quantity":"0.096"},{"price":"1226.29","quantity":"0.977"},{"price":"1231.28","quantity":"6.112"},{"price":"1231.29","quantity":"0.480"},{"price":"1236.28","quantity":"0.000"},{"price":"1562.66","quantity":"0.376"},{"price":"1562.67","quantity":"5.324"},{"price":"1696.18","quantity":"74.690"},{"price":"1701.55","quantity":"15.899"},{"price":"1730.07","quantity":"135.828"},{"price":"1730.08","quantity":"26.320"},{"price":"1730.09","quantity":"4.351"},{"price":"1730.44","quantity":"11.827"},{"price":"1732.43","quantity":"7.610"},{"price":"1733.14","quantity":"5.037"},{"price":"1733.71","quantity":"84.523"},{"price":"1733.77","quantity":"442.831"},{"price":"1734.05","quantity":"113.345"},{"price":"1734.06","quantity":"27.872"},{"price":"1734.18","quantity":"0.012"},{"price":"1734.21","quantity":"27.855"},{"price":"1734.73","quantity":"96.332"},{"price":"1735.17","quantity":"219.625"},{"price":"1735.20","quantity":"66.462"},{"price":"1735.32","quantity":"27.829"},{"price":"1735.34","quantity":"1.010"},{"price":"1735.36","quantity":"1.294"},{"price":"1735.42","quantity":"30.983"},{"price":"1735.45","quantity":"29.530"},{"price":"1735.52","quantity":"94.094"},{"price":"1735.54","quantity":"38.957"},{"price":"1735.55","quantity":"4.511"},{"price":"1735.57","quantity":"0.074"},{"price":"1735.69","quantity":"6.196"},{"price":"1735.79","quantity":"7.584"},{"price":"1735.80","quantity":"0.130"},{"price":"1735.86","quantity":"70.144"},{"price":"1735.87","quantity":"0.953"},{"price":"1735.90","quantity":"2.061"},{"price":"1735.91","quantity":"19.708"},{"price":"1735.94","quantity":"23.388"},{"price":"1735.99","quantity":"2.453"},{"price":"1736.01","quantity":"1.450"},{"price":"1736.02","quantity":"31.228"},{"price":"1736.03","quantity":"3.990"},{"price":"1736.05","quantity":"5.916"},{"price":"1736.06","quantity":"3.130"},{"price":"1736.07","quantity":"1.660"},{"price":"1736.08","quantity":"4.181"},{"price":"1736.09","quantity":"0.743"},{"price":"1736.10","quantity":"10.374"},{"price":"1736.11","quantity":"125.550"},{"price":"1736.14","quantity":"44.776"},{"price":"1736.15","quantity":"15.190"},{"price":"1736.17","quantity":"0.326"},{"price":"1736.18","quantity":"4.683"},{"price":"1736.20","quantity":"2.802"},{"price":"1736.24","quantity":"23.448"},{"price":"1736.25","quantity":"2.771"},{"price":"1736.27","quantity":"2.432"},{"price":"1736.28","quantity":"5.227"},{"price":"1736.29","quantity":"226.101"}],"asks":[{"price":"1736.30","quantity":"82.223"},{"price":"1736.31","quantity":"17.437"},{"price":"1736.32","quantity":"0.069"},{"price":"1736.34","quantity":"0.041"},{"price":"1736.35","quantity":"0.038"},{"price":"1736.38","quantity":"0.077"},{"price":"1736.39","quantity":"1.190"},{"price":"1736.40","quantity":"20.086"},{"price":"1736.43","quantity":"1.760"},{"price":"1736.44","quantity":"2.636"},{"price":"1736.45","quantity":"18.152"},{"price":"1736.46","quantity":"19.828"},{"price":"1736.47","quantity":"0.186"},{"price":"1736.48","quantity":"13.120"},{"price":"1736.49","quantity":"17.402"},{"price":"1736.53","quantity":"2.795"},{"price":"1736.55","quantity":"31.149"},{"price":"1736.56","quantity":"0.891"},{"price":"1736.60","quantity":"9.042"},{"price":"1736.62","quantity":"1.960"},{"price":"1736.63","quantity":"41.374"},{"price":"1736.64","quantity":"18.600"},{"price":"1736.65","quantity":"27.573"},{"price":"1736.68","quantity":"12.811"},{"price":"1736.69","quantity":"19.619"},{"price":"1736.81","quantity":"32.733"},{"price":"1737.13","quantity":"5.242"},{"price":"1737.15","quantity":"6.187"},{"price":"1737.16","quantity":"8.922"},{"price":"1737.18","quantity":"38.084"},{"price":"1737.19","quantity":"2.514"},{"price":"1737.20","quantity":"29.912"},{"price":"1737.23","quantity":"43.328"},{"price":"1737.29","quantity":"1.832"},{"price":"1737.30","quantity":"0.795"},{"price":"1737.81","quantity":"33.908"},{"price":"1737.82","quantity":"24.888"},{"price":"1737.86","quantity":"21.537"},{"price":"1738.12","quantity":"5.998"},{"price":"1738.20","quantity":"0.238"},{"price":"1738.21","quantity":"9.161"},{"price":"1738.26","quantity":"410.435"},{"price":"1738.30","quantity":"41.282"},{"price":"1738.34","quantity":"10.619"},{"price":"1738.37","quantity":"88.051"},{"price":"1738.47","quantity":"41.217"},{"price":"1738.49","quantity":"21.056"},{"price":"1738.60","quantity":"13.228"},{"price":"1738.80","quantity":"5.949"},{"price":"1738.86","quantity":"2.905"},{"price":"1739.76","quantity":"5.050"},{"price":"1739.77","quantity":"2.337"},{"price":"1740.13","quantity":"17.234"},{"price":"1740.58","quantity":"27.467"},{"price":"1740.63","quantity":"1.411"},{"price":"1740.64","quantity":"178.031"},{"price":"1741.49","quantity":"0.000"},{"price":"1741.50","quantity":"10.631"},{"price":"1741.75","quantity":"2.539"},{"price":"1742.36","quantity":"3.776"},{"price":"1742.37","quantity":"2.304"},{"price":"1742.47","quantity":"0.012"},{"price":"1742.48","quantity":"24.615"},{"price":"1743.23","quantity":"0.905"},{"price":"1743.24","quantity":"10.519"},{"price":"1747.10","quantity":"37.217"},{"price":"1747.74","quantity":"9.852"},{"price":"1747.75","quantity":"37.260"},{"price":"1747.76","quantity":"0.259"},{"price":"1753.66","quantity":"62.493"},{"price":"1754.53","quantity":"162.707"},{"price":"1757.13","quantity":"8.451"},{"price":"1757.40","quantity":"0.000"},{"price":"1758.00","quantity":"418.318"},{"price":"1758.87","quantity":"103.354"},{"price":"1767.83","quantity":"45.951"},{"price":"1780.77","quantity":"0.106"},{"price":"2633.71","quantity":"0.001"},{"price":"2633.80","quantity":"0.000"}],"raw":{"e":"depthUpdate","E":1783517075048,"T":1783517075047,"s":"ETHUSDT","ps":"ETHUSDT","U":10999771397824,"u":10999771412702,"pu":10999771397751,"b":[["200.00","7.594"],["1211.28","0.096"],["1226.29","0.977"],["1231.28","6.112"],["1231.29","0.480"],["1236.28","0.000"],["1562.66","0.376"],["1562.67","5.324"],["1696.18","74.690"],["1701.55","15.899"],["1730.07","135.828"],["1730.08","26.320"],["1730.09","4.351"],["1730.44","11.827"],["1732.43","7.610"],["1733.14","5.037"],["1733.71","84.523"],["1733.77","442.831"],["1734.05","113.345"],["1734.06","27.872"],["1734.18","0.012"],["1734.21","27.855"],["1734.73","96.332"],["1735.17","219.625"],["1735.20","66.462"],["1735.32","27.829"],["1735.34","1.010"],["1735.36","1.294"],["1735.42","30.983"],["1735.45","29.530"],["1735.52","94.094"],["1735.54","38.957"],["1735.55","4.511"],["1735.57","0.074"],["1735.69","6.196"],["1735.79","7.584"],["1735.80","0.130"],["1735.86","70.144"],["1735.87","0.953"],["1735.90","2.061"],["1735.91","19.708"],["1735.94","23.388"],["1735.99","2.453"],["1736.01","1.450"],["1736.02","31.228"],["1736.03","3.990"],["1736.05","5.916"],["1736.06","3.130"],["1736.07","1.660"],["1736.08","4.181"],["1736.09","0.743"],["1736.10","10.374"],["1736.11","125.550"],["1736.14","44.776"],["1736.15","15.190"],["1736.17","0.326"],["1736.18","4.683"],["1736.20","2.802"],["1736.24","23.448"],["1736.25","2.771"],["1736.27","2.432"],["1736.28","5.227"],["1736.29","226.101"]],"a":[["1736.30","82.223"],["1736.31","17.437"],["1736.32","0.069"],["1736.34","0.041"],["1736.35","0.038"],["1736.38","0.077"],["1736.39","1.190"],["1736.40","20.086"],["1736.43","1.760"],["1736.44","2.636"],["1736.45","18.152"],["1736.46","19.828"],["1736.47","0.186"],["1736.48","13.120"],["1736.49","17.402"],["1736.53","2.795"],["1736.55","31.149"],["1736.56","0.891"],["1736.60","9.042"],["1736.62","1.960"],["1736.63","41.374"],["1736.64","18.600"],["1736.65","27.573"],["1736.68","12.811"],["1736.69","19.619"],["1736.81","32.733"],["1737.13","5.242"],["1737.15","6.187"],["1737.16","8.922"],["1737.18","38.084"],["1737.19","2.514"],["1737.20","29.912"],["1737.23","43.328"],["1737.29","1.832"],["1737.30","0.795"],["1737.81","33.908"],["1737.82","24.888"],["1737.86","21.537"],["1738.12","5.998"],["1738.20","0.238"],["1738.21","9.161"],["1738.26","410.435"],["1738.30","41.282"],["1738.34","10.619"],["1738.37","88.051"],["1738.47","41.217"],["1738.49","21.056"],["1738.60","13.228"],["1738.80","5.949"],["1738.86","2.905"],["1739.76","5.050"],["1739.77","2.337"],["1740.13","17.234"],["1740.58","27.467"],["1740.63","1.411"],["1740.64","178.031"],["1741.49","0.000"],["1741.50","10.631"],["1741.75","2.539"],["1742.36","3.776"],["1742.37","2.304"],["1742.47","0.012"],["1742.48","24.615"],["1743.23","0.905"],["1743.24","10.519"],["1747.10","37.217"],["1747.74","9.852"],["1747.75","37.260"],["1747.76","0.259"],["1753.66","62.493"],["1754.53","162.707"],["1757.13","8.451"],["1757.40","0.000"],["1758.00","418.318"],["1758.87","103.354"],["1767.83","45.951"],["1780.77","0.106"],["2633.71","0.001"],["2633.80","0.000"]],"st":1}}
{"schema_version":"1.3.0","event_id":"e1d6130b-0768-4ee7-af8a-47bb4380a549","event_type":"raw.depth_update","source":"binance_market_data_recorder","venue":"binance_usdm","market_type":"perpetual_futures","symbol":"ETHUSDT","event_time_ms":1783517075150,"received_time_ms":1783517075418,"trace_id":"78f2dab6-4fbf-473f-8ad8-9222719579c7","first_update_id":10999771412826,"final_update_id":10999771421161,"previous_final_update_id":10999771412702,"bids":[{"price":"1211.11","quantity":"1.125"},{"price":"1211.28","quantity":"0.000"},{"price":"1226.29","quantity":"1.553"},{"price":"1231.28","quantity":"5.536"},{"price":"1231.29","quantity":"0.736"},{"price":"1562.66","quantity":"0.376"},{"price":"1562.67","quantity":"5.964"},{"price":"1651.87","quantity":"0.014"},{"price":"1662.38","quantity":"0.148"},{"price":"1666.80","quantity":"0.233"},{"price":"1698.89","quantity":"59.961"},{"price":"1733.77","quantity":"17.192"},{"price":"1733.82","quantity":"2.563"},{"price":"1734.18","quantity":"425.651"},{"price":"1734.73","quantity":"96.318"},{"price":"1735.01","quantity":"236.594"},{"price":"1735.11","quantity":"43.763"},{"price":"1735.15","quantity":"4.274"},{"price":"1735.17","quantity":"2.337"},{"price":"1735.20","quantity":"47.556"},{"price":"1735.22","quantity":"16.287"},{"price":"1735.29","quantity":"29.667"},{"price":"1735.32","quantity":"27.746"},{"price":"1735.38","quantity":"52.336"},{"price":"1735.39","quantity":"0.805"},{"price":"1735.51","quantity":"89.603"},{"price":"1735.54","quantity":"0.027"},{"price":"1735.60","quantity":"1.566"},{"price":"1735.80","quantity":"0.299"},{"price":"1735.83","quantity":"3.345"},{"price":"1735.86","quantity":"69.975"},{"price":"1735.94","quantity":"23.244"},{"price":"1735.99","quantity":"31.294"},{"price":"1736.00","quantity":"22.406"},{"price":"1736.02","quantity":"2.399"},{"price":"1736.05","quantity":"5.904"},{"price":"1736.06","quantity":"0.826"},{"price":"1736.10","quantity":"8.083"},{"price":"1736.11","quantity":"123.822"},{"price":"1736.15","quantity":"15.478"},{"price":"1736.17","quantity":"0.038"},{"price":"1736.19","quantity":"0.050"},{"price":"1736.24","quantity":"23.941"},{"price":"1736.26","quantity":"0.050"},{"price":"1736.27","quantity":"5.387"},{"price":"1736.29","quantity":"207.400"}],"asks":[{"price":"1736.30","quantity":"132.654"},{"price":"1736.31","quantity":"17.358"},{"price":"1736.39","quantity":"9.830"},{"price":"1736.49","quantity":"17.402"},{"price":"1736.58","quantity":"5.493"},{"price":"1736.60","quantity":"4.957"},{"price":"1736.65","quantity":"34.437"},{"price":"1736.69","quantity":"48.437"},{"price":"1736.71","quantity":"1.553"},{"price":"1736.74","quantity":"17.958"},{"price":"1736.77","quantity":"2.969"},{"price":"1736.84","quantity":"5.353"},{"price":"1736.92","quantity":"49.478"},{"price":"1736.99","quantity":"91.459"},{"price":"1737.02","quantity":"16.560"},{"price":"1737.07","quantity":"0.691"},{"price":"1737.14","quantity":"68.534"},{"price":"1737.17","quantity":"3.360"},{"price":"1737.18","quantity":"36.004"},{"price":"1737.68","quantity":"0.763"},{"price":"1737.86","quantity":"19.457"},{"price":"1738.91","quantity":"3.541"},{"price":"1738.94","quantity":"3.902"},{"price":"1738.96","quantity":"0.000"},{"price":"1738.97","quantity":"181.920"},{"price":"1747.12","quantity":"0.000"},{"price":"1757.21","quantity":"43.223"},{"price":"1759.45","quantity":"10.024"},{"price":"1762.16","quantity":"126.307"},{"price":"1770.24","quantity":"0.000"},{"price":"1778.63","quantity":"365.822"},{"price":"2633.69","quantity":"0.001"},{"price":"2633.70","quantity":"0.012"},{"price":"2633.78","quantity":"0.070"},{"price":"2633.79","quantity":"0.078"}],"raw":{"e":"depthUpdate","E":1783517075150,"T":1783517075149,"s":"ETHUSDT","ps":"ETHUSDT","U":10999771412826,"u":10999771421161,"pu":10999771412702,"b":[["1211.11","1.125"],["1211.28","0.000"],["1226.29","1.553"],["1231.28","5.536"],["1231.29","0.736"],["1562.66","0.376"],["1562.67","5.964"],["1651.87","0.014"],["1662.38","0.148"],["1666.80","0.233"],["1698.89","59.961"],["1733.77","17.192"],["1733.82","2.563"],["1734.18","425.651"],["1734.73","96.318"],["1735.01","236.594"],["1735.11","43.763"],["1735.15","4.274"],["1735.17","2.337"],["1735.20","47.556"],["1735.22","16.287"],["1735.29","29.667"],["1735.32","27.746"],["1735.38","52.336"],["1735.39","0.805"],["1735.51","89.603"],["1735.54","0.027"],["1735.60","1.566"],["1735.80","0.299"],["1735.83","3.345"],["1735.86","69.975"],["1735.94","23.244"],["1735.99","31.294"],["1736.00","22.406"],["1736.02","2.399"],["1736.05","5.904"],["1736.06","0.826"],["1736.10","8.083"],["1736.11","123.822"],["1736.15","15.478"],["1736.17","0.038"],["1736.19","0.050"],["1736.24","23.941"],["1736.26","0.050"],["1736.27","5.387"],["1736.29","207.400"]],"a":[["1736.30","132.654"],["1736.31","17.358"],["1736.39","9.830"],["1736.49","17.402"],["1736.58","5.493"],["1736.60","4.957"],["1736.65","34.437"],["1736.69","48.437"],["1736.71","1.553"],["1736.74","17.958"],["1736.77","2.969"],["1736.84","5.353"],["1736.92","49.478"],["1736.99","91.459"],["1737.02","16.560"],["1737.07","0.691"],["1737.14","68.534"],["1737.17","3.360"],["1737.18","36.004"],["1737.68","0.763"],["1737.86","19.457"],["1738.91","3.541"],["1738.94","3.902"],["1738.96","0.000"],["1738.97","181.920"],["1747.12","0.000"],["1757.21","43.223"],["1759.45","10.024"],["1762.16","126.307"],["1770.24","0.000"],["1778.63","365.822"],["2633.69","0.001"],["2633.70","0.012"],["2633.78","0.070"],["2633.79","0.078"]],"st":1}}
{"schema_version":"1.3.0","event_id":"92e9da50-5a97-44e1-8893-69faeb075753","event_type":"raw.depth_update","source":"binance_market_data_recorder","venue":"binance_usdm","market_type":"perpetual_futures","symbol":"ETHUSDT","event_time_ms":1783517075252,"received_time_ms":1783517075427,"trace_id":"7e954aa9-874b-4cd1-ab9a-815e18aca7ea","first_update_id":10999771421272,"final_update_id":10999771427493,"previous_final_update_id":10999771421161,"bids":[{"price":"200.00","quantity":"7.594"},{"price":"1211.11","quantity":"0.837"},{"price":"1226.29","quantity":"2.065"},{"price":"1231.28","quantity":"5.024"},{"price":"1231.29","quantity":"1.024"},{"price":"1562.66","quantity":"0.376"},{"price":"1562.67","quantity":"6.476"},{"price":"1666.80","quantity":"0.348"},{"price":"1701.56","quantity":"0.117"},{"price":"1710.21","quantity":"0.000"},{"price":"1711.10","quantity":"97.870"},{"price":"1711.96","quantity":"82.118"},{"price":"1712.84","quantity":"28.899"},{"price":"1730.93","quantity":"0.028"},{"price":"1732.63","quantity":"0.876"},{"price":"1732.82","quantity":"3.274"},{"price":"1734.66","quantity":"1.206"},{"price":"1734.67","quantity":"0.630"},{"price":"1735.29","quantity":"29.667"},{"price":"1735.58","quantity":"0.036"},{"price":"1735.59","quantity":"3.552"},{"price":"1735.82","quantity":"1.058"},{"price":"1736.11","quantity":"124.341"},{"price":"1736.18","quantity":"13.330"},{"price":"1736.28","quantity":"5.184"},{"price":"1736.29","quantity":"202.971"}],"asks":[{"price":"1736.41","quantity":"0.093"},{"price":"1736.48","quantity":"13.120"},{"price":"1736.49","quantity":"1.797"},{"price":"1736.59","quantity":"3.554"},{"price":"1736.63","quantity":"23.259"},{"price":"1736.65","quantity":"39.965"},{"price":"1736.74","quantity":"11.845"},{"price":"1736.78","quantity":"18.933"},{"price":"1736.89","quantity":"5.472"},{"price":"1737.15","quantity":"4.027"},{"price":"1737.16","quantity":"8.843"},{"price":"1737.26","quantity":"1.364"},{"price":"1737.34","quantity":"16.295"},{"price":"1737.82","quantity":"22.728"},{"price":"1738.08","quantity":"1.109"},{"price":"1738.18","quantity":"18.410"},{"price":"1738.94","quantity":"7.098"},{"price":"1738.96","quantity":"3.196"},{"price":"1739.96","quantity":"16.402"},{"price":"1740.02","quantity":"11.713"},{"price":"1741.61","quantity":"18.543"},{"price":"1741.72","quantity":"0.000"},{"price":"1742.34","quantity":"19.795"},{"price":"1757.09","quantity":"32.991"},{"price":"1757.99","quantity":"41.956"},{"price":"1778.84","quantity":"25.423"},{"price":"1869.18","quantity":"0.467"},{"price":"2633.67","quantity":"0.001"},{"price":"2633.68","quantity":"0.001"},{"price":"2633.76","quantity":"0.000"},{"price":"2633.77","quantity":"0.000"}],"raw":{"e":"depthUpdate","E":1783517075252,"T":1783517075251,"s":"ETHUSDT","ps":"ETHUSDT","U":10999771421272,"u":10999771427493,"pu":10999771421161,"b":[["200.00","7.594"],["1211.11","0.837"],["1226.29","2.065"],["1231.28","5.024"],["1231.29","1.024"],["1562.66","0.376"],["1562.67","6.476"],["1666.80","0.348"],["1701.56","0.117"],["1710.21","0.000"],["1711.10","97.870"],["1711.96","82.118"],["1712.84","28.899"],["1730.93","0.028"],["1732.63","0.876"],["1732.82","3.274"],["1734.66","1.206"],["1734.67","0.630"],["1735.29","29.667"],["1735.58","0.036"],["1735.59","3.552"],["1735.82","1.058"],["1736.11","124.341"],["1736.18","13.330"],["1736.28","5.184"],["1736.29","202.971"]],"a":[["1736.41","0.093"],["1736.48","13.120"],["1736.49","1.797"],["1736.59","3.554"],["1736.63","23.259"],["1736.65","39.965"],["1736.74","11.845"],["1736.78","18.933"],["1736.89","5.472"],["1737.15","4.027"],["1737.16","8.843"],["1737.26","1.364"],["1737.34","16.295"],["1737.82","22.728"],["1738.08","1.109"],["1738.18","18.410"],["1738.94","7.098"],["1738.96","3.196"],["1739.96","16.402"],["1740.02","11.713"],["1741.61","18.543"],["1741.72","0.000"],["1742.34","19.795"],["1757.09","32.991"],["1757.99","41.956"],["1778.84","25.423"],["1869.18","0.467"],["2633.67","0.001"],["2633.68","0.001"],["2633.76","0.000"],["2633.77","0.000"]],"st":1}}
{"schema_version":"1.3.0","event_id":"1403f7d0-bebb-4cd3-ab60-03c225f82767","event_type":"raw.depth_update","source":"binance_market_data_recorder","venue":"binance_usdm","market_type":"perpetual_futures","symbol":"ETHUSDT","event_time_ms":1783517075354,"received_time_ms":1783517075431,"trace_id":"55016b1f-1580-4ae6-81e4-2bf42bfcdfeb","first_update_id":10999771427534,"final_update_id":10999771434703,"previous_final_update_id":10999771427493,"bids":[{"price":"200.00","quantity":"7.594"},{"price":"1211.11","quantity":"0.581"},{"price":"1226.29","quantity":"2.641"},{"price":"1231.28","quantity":"4.448"},{"price":"1231.29","quantity":"1.280"},{"price":"1562.66","quantity":"0.376"},{"price":"1562.67","quantity":"7.116"},{"price":"1603.75","quantity":"0.366"},{"price":"1666.80","quantity":"0.233"},{"price":"1700.19","quantity":"0.166"},{"price":"1701.56","quantity":"0.088"},{"price":"1705.75","quantity":"58.547"},{"price":"1711.32","quantity":"0.330"},{"price":"1716.24","quantity":"2.665"},{"price":"1730.93","quantity":"16.528"},{"price":"1734.19","quantity":"18.268"},{"price":"1734.54","quantity":"26.070"},{"price":"1734.55","quantity":"0.491"},{"price":"1734.89","quantity":"3.048"},{"price":"1735.09","quantity":"0.835"},{"price":"1735.41","quantity":"124.377"},{"price":"1735.65","quantity":"16.034"},{"price":"1736.13","quantity":"67.586"},{"price":"1736.15","quantity":"15.190"},{"price":"1736.28","quantity":"4.578"},{"price":"1736.29","quantity":"203.580"}],"asks":[{"price":"1736.30","quantity":"132.700"},{"price":"1736.41","quantity":"0.093"},{"price":"1736.49","quantity":"1.767"},{"price":"1736.76","quantity":"10.627"},{"price":"1736.89","quantity":"4.672"},{"price":"1736.91","quantity":"34.386"},{"price":"1737.01","quantity":"86.703"},{"price":"1737.08","quantity":"3.802"},{"price":"1737.11","quantity":"16.916"},{"price":"1737.30","quantity":"0.795"},{"price":"1737.32","quantity":"3.855"},{"price":"1737.33","quantity":"20.843"},{"price":"1737.34","quantity":"16.695"},{"price":"1737.84","quantity":"36.744"},{"price":"1737.89","quantity":"7.279"},{"price":"1738.24","quantity":"0.038"},{"price":"1741.71","quantity":"14.236"},{"price":"1757.41","quantity":"14.559"},{"price":"1757.42","quantity":"20.641"},{"price":"1778.51","quantity":"0.000"},{"price":"2633.66","quantity":"0.092"},{"price":"2633.75","quantity":"0.000"}],"raw":{"e":"depthUpdate","E":1783517075354,"T":1783517075353,"s":"ETHUSDT","ps":"ETHUSDT","U":10999771427534,"u":10999771434703,"pu":10999771427493,"b":[["200.00","7.594"],["1211.11","0.581"],["1226.29","2.641"],["1231.28","4.448"],["1231.29","1.280"],["1562.66","0.376"],["1562.67","7.116"],["1603.75","0.366"],["1666.80","0.233"],["1700.19","0.166"],["1701.56","0.088"],["1705.75","58.547"],["1711.32","0.330"],["1716.24","2.665"],["1730.93","16.528"],["1734.19","18.268"],["1734.54","26.070"],["1734.55","0.491"],["1734.89","3.048"],["1735.09","0.835"],["1735.41","124.377"],["1735.65","16.034"],["1736.13","67.586"],["1736.15","15.190"],["1736.28","4.578"],["1736.29","203.580"]],"a":[["1736.30","132.700"],["1736.41","0.093"],["1736.49","1.767"],["1736.76","10.627"],["1736.89","4.672"],["1736.91","34.386"],["1737.01","86.703"],["1737.08","3.802"],["1737.11","16.916"],["1737.30","0.795"],["1737.32","3.855"],["1737.33","20.843"],["1737.34","16.695"],["1737.84","36.744"],["1737.89","7.279"],["1738.24","0.038"],["1741.71","14.236"],["1757.41","14.559"],["1757.42","20.641"],["1778.51","0.000"],["2633.66","0.092"],["2633.75","0.000"]],"st":1}}
{"schema_version":"1.3.0","event_id":"77d8fac0-cfd0-4bd9-ba90-3991468f8128","event_type":"raw.depth_update","source":"binance_market_data_recorder","venue":"binance_usdm","market_type":"perpetual_futures","symbol":"ETHUSDT","event_time_ms":1783517075458,"received_time_ms":1783517075472,"trace_id":"78445c65-73e2-45d9-8950-8eec18df2289","first_update_id":10999771434847,"final_update_id":10999771441526,"previous_final_update_id":10999771434703,"bids":[{"price":"1211.11","quantity":"0.293"},{"price":"1226.29","quantity":"3.185"},{"price":"1231.28","quantity":"3.904"},{"price":"1231.29","quantity":"1.568"},{"price":"1562.38","quantity":"0.226"},{"price":"1562.66","quantity":"0.376"},{"price":"1562.67","quantity":"7.628"},{"price":"1666.80","quantity":"0.348"},{"price":"1707.35","quantity":"0.013"},{"price":"1709.19","quantity":"56.583"},{"price":"1717.01","quantity":"434.482"},{"price":"1718.75","quantity":"526.726"},{"price":"1730.93","quantity":"0.028"},{"price":"1734.05","quantity":"116.541"},{"price":"1734.06","quantity":"26.426"},{"price":"1734.13","quantity":"3.167"},{"price":"1735.29","quantity":"29.667"},{"price":"1735.37","quantity":"1.294"},{"price":"1735.38","quantity":"52.469"},{"price":"1735.39","quantity":"0.936"},{"price":"1735.81","quantity":"4.972"},{"price":"1736.09","quantity":"2.471"},{"price":"1736.25","quantity":"2.784"},{"price":"1736.26","quantity":"0.323"},{"price":"1736.27","quantity":"5.399"},{"price":"1736.28","quantity":"3.940"},{"price":"1736.29","quantity":"203.707"}],"asks":[{"price":"1736.30","quantity":"132.687"},{"price":"1736.49","quantity":"1.767"},{"price":"1736.65","quantity":"38.298"},{"price":"1736.99","quantity":"89.792"},{"price":"1737.19","quantity":"0.862"},{"price":"1737.20","quantity":"29.499"},{"price":"1737.21","quantity":"1.670"},{"price":"1737.22","quantity":"2.823"},{"price":"1737.33","quantity":"23.003"},{"price":"1737.35","quantity":"25.198"},{"price":"1737.69","quantity":"4.763"},{"price":"1740.00","quantity":"142.436"},{"price":"1740.07","quantity":"0.975"},{"price":"1741.71","quantity":"0.031"},{"price":"1747.12","quantity":"15.000"},{"price":"1753.66","quantity":"62.481"},{"price":"1759.51","quantity":"825.838"},{"price":"1765.97","quantity":"1.774"},{"price":"2633.64","quantity":"0.001"},{"price":"2633.65","quantity":"0.001"},{"price":"2633.73","quantity":"0.046"},{"price":"2633.74","quantity":"0.000"}],"raw":{"e":"depthUpdate","E":1783517075458,"T":1783517075457,"s":"ETHUSDT","ps":"ETHUSDT","U":10999771434847,"u":10999771441526,"pu":10999771434703,"b":[["1211.11","0.293"],["1226.29","3.185"],["1231.28","3.904"],["1231.29","1.568"],["1562.38","0.226"],["1562.66","0.376"],["1562.67","7.628"],["1666.80","0.348"],["1707.35","0.013"],["1709.19","56.583"],["1717.01","434.482"],["1718.75","526.726"],["1730.93","0.028"],["1734.05","116.541"],["1734.06","26.426"],["1734.13","3.167"],["1735.29","29.667"],["1735.37","1.294"],["1735.38","52.469"],["1735.39","0.936"],["1735.81","4.972"],["1736.09","2.471"],["1736.25","2.784"],["1736.26","0.323"],["1736.27","5.399"],["1736.28","3.940"],["1736.29","203.707"]],"a":[["1736.30","132.687"],["1736.49","1.767"],["1736.65","38.298"],["1736.99","89.792"],["1737.19","0.862"],["1737.20","29.499"],["1737.21","1.670"],["1737.22","2.823"],["1737.33","23.003"],["1737.35","25.198"],["1737.69","4.763"],["1740.00","142.436"],["1740.07","0.975"],["1741.71","0.031"],["1747.12","15.000"],["1753.66","62.481"],["1759.51","825.838"],["1765.97","1.774"],["2633.64","0.001"],["2633.65","0.001"],["2633.73","0.046"],["2633.74","0.000"]],"st":1}}
{"schema_version":"1.3.0","event_id":"e0a06359-c02a-43ad-b6ad-da1b8260133b","event_type":"raw.depth_update","source":"binance_market_data_recorder","venue":"binance_usdm","market_type":"perpetual_futures","symbol":"ETHUSDT","event_time_ms":1783517075560,"received_time_ms":1783517075601,"trace_id":"ebd59dd3-257e-4426-95d8-e98856a8c4c3","first_update_id":10999771441574,"final_update_id":10999771445920,"previous_final_update_id":10999771441526,"bids":[{"price":"200.00","quantity":"7.594"},{"price":"201.00","quantity":"2.300"},{"price":"1211.11","quantity":"0.037"},{"price":"1226.29","quantity":"3.729"},{"price":"1231.28","quantity":"3.360"},{"price":"1231.29","quantity":"1.824"},{"price":"1562.66","quantity":"0.376"},{"price":"1562.67","quantity":"7.628"},{"price":"1699.01","quantity":"29.416"},{"price":"1701.11","quantity":"3.669"},{"price":"1701.57","quantity":"29.377"},{"price":"1710.20","quantity":"3.000"},{"price":"1710.23","quantity":"42.114"},{"price":"1711.10","quantity":"126.799"},{"price":"1727.59","quantity":"0.839"},{"price":"1730.93","quantity":"16.528"},{"price":"1735.13","quantity":"0.450"},{"price":"1736.24","quantity":"24.062"},{"price":"1736.29","quantity":"213.529"}],"asks":[{"price":"1741.71","quantity":"14.236"},{"price":"1768.68","quantity":"56.913"}],"raw":{"e":"depthUpdate","E":1783517075560,"T":1783517075559,"s":"ETHUSDT","ps":"ETHUSDT","U":10999771441574,"u":10999771445920,"pu":10999771441526,"b":[["200.00","7.594"],["201.00","2.300"],["1211.11","0.037"],["1226.29","3.729"],["1231.28","3.360"],["1231.29","1.824"],["1562.66","0.376"],["1562.67","7.628"],["1699.01","29.416"],["1701.11","3.669"],["1701.57","29.377"],["1710.20","3.000"],["1710.23","42.114"],["1711.10","126.799"],["1727.59","0.839"],["1730.93","16.528"],["1735.13","0.450"],["1736.24","24.062"],["1736.29","213.529"]],"a":[["1741.71","14.236"],["1768.68","56.913"]],"st":1}}
{"schema_version":"1.3.0","event_id":"94a196aa-4eb1-4072-9b4d-121f155c8b5e","event_type":"raw.depth_update","source":"binance_market_data_recorder","venue":"binance_usdm","market_type":"perpetual_futures","symbol":"ETHUSDT","event_time_ms":1783517075662,"received_time_ms":1783517075657,"trace_id":"8a9b657a-35cb-4b65-b78a-b4e5538bf5de","first_update_id":10999771445988,"final_update_id":10999771454030,"previous_final_update_id":10999771445920,"bids":[{"price":"200.00","quantity":"7.594"},{"price":"1226.29","quantity":"4.561"},{"price":"1231.28","quantity":"2.816"},{"price":"1231.29","quantity":"1.536"},{"price":"1562.66","quantity":"0.376"},{"price":"1562.67","quantity":"7.500"},{"price":"1666.80","quantity":"0.233"},{"price":"1700.00","quantity":"1540.345"},{"price":"1701.57","quantity":"29.348"},{"price":"1707.03","quantity":"29.247"},{"price":"1712.30","quantity":"62.938"},{"price":"1715.27","quantity":"113.893"},{"price":"1727.02","quantity":"1.248"},{"price":"1730.93","quantity":"0.028"},{"price":"1731.20","quantity":"11.107"},{"price":"1731.24","quantity":"166.425"},{"price":"1731.41","quantity":"185.534"},{"price":"1732.29","quantity":"0.493"},{"price":"1732.32","quantity":"87.401"},{"price":"1732.47","quantity":"22.682"},{"price":"1734.54","quantity":"20.402"},{"price":"1734.55","quantity":"0.400"},{"price":"1734.89","quantity":"0.168"},{"price":"1735.26","quantity":"1.095"},{"price":"1735.30","quantity":"40.937"},{"price":"1735.35","quantity":"88.595"},{"price":"1735.39","quantity":"0.914"},{"price":"1735.41","quantity":"124.177"},{"price":"1735.44","quantity":"40.166"},{"price":"1735.48","quantity":"0.955"},{"price":"1735.57","quantity":"0.051"},{"price":"1735.64","quantity":"72.137"},{"price":"1735.66","quantity":"0.177"},{"price":"1735.72","quantity":"2.321"},{"price":"1735.75","quantity":"75.818"},{"price":"1735.79","quantity":"7.596"},{"price":"1735.81","quantity":"4.886"},{"price":"1735.84","quantity":"4.436"},{"price":"1735.93","quantity":"5.488"},{"price":"1736.00","quantity":"22.464"},{"price":"1736.02","quantity":"2.378"},{"price":"1736.11","quantity":"124.320"},{"price":"1736.20","quantity":"2.779"},{"price":"1736.22","quantity":"0.048"},{"price":"1736.29","quantity":"213.518"}],"asks":[{"price":"1736.30","quantity":"132.687"},{"price":"1736.39","quantity":"8.678"},{"price":"1736.47","quantity":"0.185"},{"price":"1736.56","quantity":"0.870"},{"price":"1736.65","quantity":"38.276"},{"price":"1736.70","quantity":"81.350"},{"price":"1736.74","quantity":"11.822"},{"price":"1736.83","quantity":"43.245"},{"price":"1736.90","quantity":"22.628"},{"price":"1736.92","quantity":"10.558"},{"price":"1736.98","quantity":"46.151"},{"price":"1736.99","quantity":"89.706"},{"price":"1737.07","quantity":"0.605"},{"price":"1737.13","quantity":"5.156"},{"price":"1737.17","quantity":"1.666"},{"price":"1737.19","quantity":"0.948"},{"price":"1737.25","quantity":"71.600"},{"price":"1737.28","quantity":"0.227"},{"price":"1737.30","quantity":"0.795"},{"price":"1737.34","quantity":"33.371"},{"price":"1737.36","quantity":"68.421"},{"price":"1737.45","quantity":"49.379"},{"price":"1737.54","quantity":"3.404"},{"price":"1738.26","quantity":"1.023"},{"price":"1738.30","quantity":"24.606"},{"price":"1738.61","quantity":"414.182"},{"price":"1738.67","quantity":"16.659"},{"price":"1738.91","quantity":"0.345"},{"price":"1738.94","quantity":"3.902"},{"price":"1739.81","quantity":"8.363"},{"price":"1739.87","quantity":"1.224"},{"price":"1740.06","quantity":"41.211"},{"price":"1740.97","quantity":"15.136"},{"price":"1740.99","quantity":"9.895"},{"price":"1741.05","quantity":"31.331"},{"price":"1741.12","quantity":"130.556"},{"price":"1741.71","quantity":"0.031"},{"price":"1744.99","quantity":"0.343"},{"price":"1764.08","quantity":"36.211"},{"price":"1778.84","quantity":"50.691"},{"price":"2633.62","quantity":"0.001"},{"price":"2633.63","quantity":"0.001"},{"price":"2633.71","quantity":"0.000"},{"price":"2633.72","quantity":"0.000"}],"raw":{"e":"depthUpdate","E":1783517075662,"T":1783517075661,"s":"ETHUSDT","ps":"ETHUSDT","U":10999771445988,"u":10999771454030,"pu":10999771445920,"b":[["200.00","7.594"],["1226.29","4.561"],["1231.28","2.816"],["1231.29","1.536"],["1562.66","0.376"],["1562.67","7.500"],["1666.80","0.233"],["1700.00","1540.345"],["1701.57","29.348"],["1707.03","29.247"],["1712.30","62.938"],["1715.27","113.893"],["1727.02","1.248"],["1730.93","0.028"],["1731.20","11.107"],["1731.24","166.425"],["1731.41","185.534"],["1732.29","0.493"],["1732.32","87.401"],["1732.47","22.682"],["1734.54","20.402"],["1734.55","0.400"],["1734.89","0.168"],["1735.26","1.095"],["1735.30","40.937"],["1735.35","88.595"],["1735.39","0.914"],["1735.41","124.177"],["1735.44","40.166"],["1735.48","0.955"],["1735.57","0.051"],["1735.64","72.137"],["1735.66","0.177"],["1735.72","2.321"],["1735.75","75.818"],["1735.79","7.596"],["1735.81","4.886"],["1735.84","4.436"],["1735.93","5.488"],["1736.00","22.464"],["1736.02","2.378"],["1736.11","124.320"],["1736.20","2.779"],["1736.22","0.048"],["1736.29","213.518"]],"a":[["1736.30","132.687"],["1736.39","8.678"],["1736.47","0.185"],["1736.56","0.870"],["1736.65","38.276"],["1736.70","81.350"],["1736.74","11.822"],["1736.83","43.245"],["1736.90","22.628"],["1736.92","10.558"],["1736.98","46.151"],["1736.99","89.706"],["1737.07","0.605"],["1737.13","5.156"],["1737.17","1.666"],["1737.19","0.948"],["1737.25","71.600"],["1737.28","0.227"],["1737.30","0.795"],["1737.34","33.371"],["1737.36","68.421"],["1737.45","49.379"],["1737.54","3.404"],["1738.26","1.023"],["1738.30","24.606"],["1738.61","414.182"],["1738.67","16.659"],["1738.91","0.345"],["1738.94","3.902"],["1739.81","8.363"],["1739.87","1.224"],["1740.06","41.211"],["1740.97","15.136"],["1740.99","9.895"],["1741.05","31.331"],["1741.12","130.556"],["1741.71","0.031"],["1744.99","0.343"],["1764.08","36.211"],["1778.84","50.691"],["2633.62","0.001"],["2633.63","0.001"],["2633.71","0.000"],["2633.72","0.000"]],"st":1}}
{"schema_version":"1.3.0","event_id":"d3b7abd0-6ffc-4a0f-9435-85444d3d68cd","event_type":"raw.depth_update","source":"binance_market_data_recorder","venue":"binance_usdm","market_type":"perpetual_futures","symbol":"ETHUSDT","event_time_ms":1783517075764,"received_time_ms":1783517075759,"trace_id":"c93d1df1-f131-456c-9fdc-056151cda1f7","first_update_id":10999771454143,"final_update_id":10999771461788,"previous_final_update_id":10999771454030,"bids":[{"price":"1226.29","quantity":"5.361"},{"price":"1231.28","quantity":"2.272"},{"price":"1231.29","quantity":"1.280"},{"price":"1562.66","quantity":"0.376"},{"price":"1562.67","quantity":"7.500"},{"price":"1647.52","quantity":"0.014"},{"price":"1659.83","quantity":"0.172"},{"price":"1666.80","quantity":"0.348"},{"price":"1699.05","quantity":"29.395"},{"price":"1701.57","quantity":"29.377"},{"price":"1704.60","quantity":"29.312"},{"price":"1710.94","quantity":"76.515"},{"price":"1727.59","quantity":"0.827"},{"price":"1730.93","quantity":"16.528"},{"price":"1732.47","quantity":"63.064"},{"price":"1735.10","quantity":"19.176"},{"price":"1735.16","quantity":"7.565"},{"price":"1735.29","quantity":"29.667"},{"price":"1735.30","quantity":"41.137"},{"price":"1735.35","quantity":"88.395"},{"price":"1735.60","quantity":"1.552"},{"price":"1735.80","quantity":"0.299"},{"price":"1736.18","quantity":"4.683"},{"price":"1736.20","quantity":"11.447"}],"asks":[{"price":"1736.49","quantity":"1.767"},{"price":"1736.56","quantity":"0.893"},{"price":"1736.70","quantity":"79.656"},{"price":"1736.89","quantity":"6.366"},{"price":"1737.86","quantity":"2.781"},{"price":"1738.12","quantity":"5.998"},{"price":"1738.56","quantity":"18.672"},{"price":"1738.96","quantity":"3.196"},{"price":"1740.00","quantity":"141.436"},{"price":"1740.06","quantity":"72.890"},{"price":"1741.71","quantity":"14.236"},{"price":"1744.99","quantity":"0.355"},{"price":"1747.12","quantity":"0.000"},{"price":"1759.45","quantity":"19.959"},{"price":"1762.28","quantity":"0.319"},{"price":"1767.55","quantity":"11.338"},{"price":"2633.61","quantity":"0.001"},{"price":"2633.70","quantity":"0.011"}],"raw":{"e":"depthUpdate","E":1783517075764,"T":1783517075763,"s":"ETHUSDT","ps":"ETHUSDT","U":10999771454143,"u":10999771461788,"pu":10999771454030,"b":[["1226.29","5.361"],["1231.28","2.272"],["1231.29","1.280"],["1562.66","0.376"],["1562.67","7.500"],["1647.52","0.014"],["1659.83","0.172"],["1666.80","0.348"],["1699.05","29.395"],["1701.57","29.377"],["1704.60","29.312"],["1710.94","76.515"],["1727.59","0.827"],["1730.93","16.528"],["1732.47","63.064"],["1735.10","19.176"],["1735.16","7.565"],["1735.29","29.667"],["1735.30","41.137"],["1735.35","88.395"],["1735.60","1.552"],["1735.80","0.299"],["1736.18","4.683"],["1736.20","11.447"]],"a":[["1736.49","1.767"],["1736.56","0.893"],["1736.70","79.656"],["1736.89","6.366"],["1737.86","2.781"],["1738.12","5.998"],["1738.56","18.672"],["1738.96","3.196"],["1740.00","141.436"],["1740.06","72.890"],["1741.71","14.236"],["1744.99","0.355"],["1747.12","0.000"],["1759.45","19.959"],["1762.28","0.319"],["1767.55","11.338"],["2633.61","0.001"],["2633.70","0.011"]],"st":1}}
{"schema_version":"1.3.0","event_id":"21dd223a-46fc-411e-b133-d1387473b28f","event_type":"raw.depth_update","source":"binance_market_data_recorder","venue":"binance_usdm","market_type":"perpetual_futures","symbol":"ETHUSDT","event_time_ms":1783517075866,"received_time_ms":1783517075861,"trace_id":"3eb7fa9b-db30-4d60-acd8-ca13b39a005e","first_update_id":10999771461871,"final_update_id":10999771467596,"previous_final_update_id":10999771461788,"bids":[{"price":"200.00","quantity":"7.594"},{"price":"1226.29","quantity":"6.193"},{"price":"1231.11","quantity":"0.128"},{"price":"1231.28","quantity":"1.888"},{"price":"1231.29","quantity":"0.992"},{"price":"1562.66","quantity":"0.376"},{"price":"1562.67","quantity":"7.628"},{"price":"1599.41","quantity":"0.014"},{"price":"1666.80","quantity":"0.233"},{"price":"1701.57","quantity":"29.348"},{"price":"1705.75","quantity":"58.547"},{"price":"1714.80","quantity":"119.398"},{"price":"1732.12","quantity":"0.015"},{"price":"1734.84","quantity":"268.795"},{"price":"1735.20","quantity":"47.377"},{"price":"1735.59","quantity":"3.527"},{"price":"1736.11","quantity":"124.342"},{"price":"1736.28","quantity":"4.018"},{"price":"1736.29","quantity":"213.596"}],"asks":[{"price":"1736.30","quantity":"121.867"},{"price":"1736.65","quantity":"38.297"},{"price":"1736.89","quantity":"4.672"},{"price":"1736.91","quantity":"32.692"},{"price":"1737.11","quantity":"18.610"},{"price":"1737.83","quantity":"34.780"},{"price":"1738.25","quantity":"417.012"},{"price":"1738.61","quantity":"0.048"},{"price":"1739.00","quantity":"2.893"},{"price":"1739.02","quantity":"4.452"},{"price":"2633.59","quantity":"0.001"},{"price":"2633.60","quantity":"0.001"},{"price":"2633.68","quantity":"0.000"},{"price":"2633.69","quantity":"0.000"}],"raw":{"e":"depthUpdate","E":1783517075866,"T":1783517075865,"s":"ETHUSDT","ps":"ETHUSDT","U":10999771461871,"u":10999771467596,"pu":10999771461788,"b":[["200.00","7.594"],["1226.29","6.193"],["1231.11","0.128"],["1231.28","1.888"],["1231.29","0.992"],["1562.66","0.376"],["1562.67","7.628"],["1599.41","0.014"],["1666.80","0.233"],["1701.57","29.348"],["1705.75","58.547"],["1714.80","119.398"],["1732.12","0.015"],["1734.84","268.795"],["1735.20","47.377"],["1735.59","3.527"],["1736.11","124.342"],["1736.28","4.018"],["1736.29","213.596"]],"a":[["1736.30","121.867"],["1736.65","38.297"],["1736.89","4.672"],["1736.91","32.692"],["1737.11","18.610"],["1737.83","34.780"],["1738.25","417.012"],["1738.61","0.048"],["1739.00","2.893"],["1739.02","4.452"],["2633.59","0.001"],["2633.60","0.001"],["2633.68","0.000"],["2633.69","0.000"]],"st":1}}
{"schema_version":"1.3.0","event_id":"c108cb5f-61a4-41a9-9d40-b766c9125e6b","event_type":"raw.depth_update","source":"binance_market_data_recorder","venue":"binance_usdm","market_type":"perpetual_futures","symbol":"ETHUSDT","event_time_ms":1783517075968,"received_time_ms":1783517075963,"trace_id":"490949f6-d561-4d82-96d5-d2ba1b36b8b3","first_update_id":10999771467701,"final_update_id":10999771475595,"previous_final_update_id":10999771467596,"bids":[{"price":"200.00","quantity":"7.594"},{"price":"1221.29","quantity":"0.128"},{"price":"1226.29","quantity":"6.737"},{"price":"1231.11","quantity":"0.000"},{"price":"1231.28","quantity":"1.600"},{"price":"1231.29","quantity":"0.736"},{"price":"1562.66","quantity":"0.376"},{"price":"1562.67","quantity":"7.372"},{"price":"1615.00","quantity":"68.017"},{"price":"1701.57","quantity":"29.348"},{"price":"1709.19","quantity":"77.036"},{"price":"1730.44","quantity":"4.322"},{"price":"1731.41","quantity":"174.853"},{"price":"1731.42","quantity":"41.939"},{"price":"1732.29","quantity":"8.608"},{"price":"1732.78","quantity":"12.149"},{"price":"1732.86","quantity":"46.787"},{"price":"1734.05","quantity":"113.345"},{"price":"1734.06","quantity":"27.872"},{"price":"1734.13","quantity":"6.363"},{"price":"1734.21","quantity":"97.500"},{"price":"1735.01","quantity":"19.298"},{"price":"1735.16","quantity":"7.551"},{"price":"1735.18","quantity":"1.494"},{"price":"1735.28","quantity":"221.758"},{"price":"1735.59","quantity":"3.502"},{"price":"1735.60","quantity":"1.566"},{"price":"1735.78","quantity":"14.045"},{"price":"1736.02","quantity":"2.400"},{"price":"1736.21","quantity":"0.341"},{"price":"1736.28","quantity":"4.542"},{"price":"1736.29","quantity":"213.614"}],"asks":[{"price":"1736.30","quantity":"110.139"},{"price":"1736.39","quantity":"0.038"},{"price":"1736.44","quantity":"1.195"},{"price":"1736.49","quantity":"1.767"},{"price":"1736.74","quantity":"11.844"},{"price":"1737.19","quantity":"2.596"},{"price":"1737.20","quantity":"29.911"},{"price":"1737.21","quantity":"0.022"},{"price":"1737.22","quantity":"2.411"},{"price":"1737.30","quantity":"0.795"},{"price":"1737.69","quantity":"4.763"},{"price":"1738.15","quantity":"14.723"},{"price":"1738.17","quantity":"7.695"},{"price":"1738.25","quantity":"2.878"},{"price":"1738.56","quantity":"432.806"},{"price":"1738.91","quantity":"3.541"},{"price":"1738.94","quantity":"7.098"},{"price":"1738.96","quantity":"3.196"},{"price":"1740.24","quantity":"51.728"},{"price":"1747.12","quantity":"15.000"},{"price":"1762.34","quantity":"0.000"},{"price":"1763.21","quantity":"59.803"},{"price":"2633.58","quantity":"0.001"},{"price":"2633.67","quantity":"0.000"}],"raw":{"e":"depthUpdate","E":1783517075968,"T":1783517075967,"s":"ETHUSDT","ps":"ETHUSDT","U":10999771467701,"u":10999771475595,"pu":10999771467596,"b":[["200.00","7.594"],["1221.29","0.128"],["1226.29","6.737"],["1231.11","0.000"],["1231.28","1.600"],["1231.29","0.736"],["1562.66","0.376"],["1562.67","7.372"],["1615.00","68.017"],["1701.57","29.348"],["1709.19","77.036"],["1730.44","4.322"],["1731.41","174.853"],["1731.42","41.939"],["1732.29","8.608"],["1732.78","12.149"],["1732.86","46.787"],["1734.05","113.345"],["1734.06","27.872"],["1734.13","6.363"],["1734.21","97.500"],["1735.01","19.298"],["1735.16","7.551"],["1735.18","1.494"],["1735.28","221.758"],["1735.59","3.502"],["1735.60","1.566"],["1735.78","14.045"],["1736.02","2.400"],["1736.21","0.341"],["1736.28","4.542"],["1736.29","213.614"]],"a":[["1736.30","110.139"],["1736.39","0.038"],["1736.44","1.195"],["1736.49","1.767"],["1736.74","11.844"],["1737.19","2.596"],["1737.20","29.911"],["1737.21","0.022"],["1737.22","2.411"],["1737.30","0.795"],["1737.69","4.763"],["1738.15","14.723"],["1738.17","7.695"],["1738.25","2.878"],["1738.56","432.806"],["1738.91","3.541"],["1738.94","7.098"],["1738.96","3.196"],["1740.24","51.728"],["1747.12","15.000"],["1762.34","0.000"],["1763.21","59.803"],["2633.58","0.001"],["2633.67","0.000"]],"st":1}}
{"schema_version":"1.3.0","event_id":"797dbf46-18d0-485a-bf41-168338ac742c","event_type":"raw.depth_update","source":"binance_market_data_recorder","venue":"binance_usdm","market_type":"perpetual_futures","symbol":"ETHUSDT","event_time_ms":1783517076070,"received_time_ms":1783517076065,"trace_id":"6f9ba665-4a59-4d9b-bd79-e1787a6bf93e","first_update_id":10999771475711,"final_update_id":10999771483795,"previous_final_update_id":10999771475595,"bids":[{"price":"1221.29","quantity":"0.448"},{"price":"1226.29","quantity":"6.929"},{"price":"1231.28","quantity":"1.376"},{"price":"1231.29","quantity":"0.448"},{"price":"1562.66","quantity":"0.350"},{"price":"1562.67","quantity":"7.258"},{"price":"1666.80","quantity":"0.348"},{"price":"1704.73","quantity":"20.396"},{"price":"1732.94","quantity":"4.414"},{"price":"1733.95","quantity":"3.942"},{"price":"1734.06","quantity":"26.426"},{"price":"1734.09","quantity":"3.775"},{"price":"1735.08","quantity":"222.765"},{"price":"1735.09","quantity":"1.353"},{"price":"1735.29","quantity":"29.667"},{"price":"1735.93","quantity":"5.509"},{"price":"1735.94","quantity":"23.244"},{"price":"1736.09","quantity":"3.623"},{"price":"1736.20","quantity":"2.800"},{"price":"1736.21","quantity":"8.988"},{"price":"1736.28","quantity":"4.018"},{"price":"1736.29","quantity":"203.844"}],"asks":[{"price":"1736.30","quantity":"109.803"},{"price":"1736.43","quantity":"0.032"},{"price":"1736.48","quantity":"10.356"},{"price":"1736.52","quantity":"0.051"},{"price":"1736.53","quantity":"1.354"},{"price":"1736.63","quantity":"21.818"},{"price":"1736.64","quantity":"18.082"},{"price":"1736.65","quantity":"38.297"},{"price":"1736.80","quantity":"9.815"},{"price":"1736.83","quantity":"43.266"},{"price":"1736.84","quantity":"5.871"},{"price":"1736.98","quantity":"44.710"},{"price":"1737.57","quantity":"42.677"},{"price":"1737.78","quantity":"7.153"},{"price":"1738.19","quantity":"430.454"},{"price":"1738.26","quantity":"1.023"},{"price":"1738.31","quantity":"0.852"},{"price":"1738.56","quantity":"18.672"},{"price":"1738.64","quantity":"7.862"},{"price":"1738.87","quantity":"4.877"},{"price":"1739.77","quantity":"0.033"},{"price":"1739.78","quantity":"10.521"},{"price":"1740.13","quantity":"9.729"},{"price":"1740.64","quantity":"175.727"},{"price":"1740.65","quantity":"18.635"},{"price":"1741.50","quantity":"8.327"},{"price":"1741.51","quantity":"2.304"},{"price":"1742.37","quantity":"0.000"},{"price":"1742.38","quantity":"6.440"},{"price":"1742.48","quantity":"32.120"},{"price":"1743.24","quantity":"8.215"},{"price":"1743.25","quantity":"2.703"},{"price":"1760.61","quantity":"27.588"},{"price":"1760.92","quantity":"56.719"},{"price":"1769.13","quantity":"0.047"},{"price":"2633.57","quantity":"0.001"},{"price":"2633.66","quantity":"0.091"}],"raw":{"e":"depthUpdate","E":1783517076070,"T":1783517076069,"s":"ETHUSDT","ps":"ETHUSDT","U":10999771475711,"u":10999771483795,"pu":10999771475595,"b":[["1221.29","0.448"],["1226.29","6.929"],["1231.28","1.376"],["1231.29","0.448"],["1562.66","0.350"],["1562.67","7.258"],["1666.80","0.348"],["1704.73","20.396"],["1732.94","4.414"],["1733.95","3.942"],["1734.06","26.426"],["1734.09","3.775"],["1735.08","222.765"],["1735.09","1.353"],["1735.29","29.667"],["1735.93","5.509"],["1735.94","23.244"],["1736.09","3.623"],["1736.20","2.800"],["1736.21","8.988"],["1736.28","4.018"],["1736.29","203.844"]],"a":[["1736.30","109.803"],["1736.43","0.032"],["1736.48","10.356"],["1736.52","0.051"],["1736.53","1.354"],["1736.63","21.818"],["1736.64","18.082"],["1736.65","38.297"],["1736.80","9.815"],["1736.83","43.266"],["1736.84","5.871"],["1736.98","44.710"],["1737.57","42.677"],["1737.78","7.153"],["1738.19","430.454"],["1738.26","1.023"],["1738.31","0.852"],["1738.56","18.672"],["1738.64","7.862"],["1738.87","4.877"],["1739.77","0.033"],["1739.78","10.521"],["1740.13","9.729"],["1740.64","175.727"],["1740.65","18.635"],["1741.50","8.327"],["1741.51","2.304"],["1742.37","0.000"],["1742.38","6.440"],["1742.48","32.120"],["1743.24","8.215"],["1743.25","2.703"],["1760.61","27.588"],["1760.92","56.719"],["1769.13","0.047"],["2633.57","0.001"],["2633.66","0.091"]],"st":1}}
{"schema_version":"1.3.0","event_id":"7ac1b82c-babf-4d7c-9fd5-191cd5ef5832","event_type":"raw.depth_update","source":"binance_market_data_recorder","venue":"binance_usdm","market_type":"perpetual_futures","symbol":"ETHUSDT","event_time_ms":1783517076172,"received_time_ms":1783517076167,"trace_id":"4e0cb909-4a49-4900-98c2-82e2b0e4e712","first_update_id":10999771483803,"final_update_id":10999771491544,"previous_final_update_id":10999771483795,"bids":[{"price":"200.00","quantity":"7.594"},{"price":"1221.29","quantity":"0.992"},{"price":"1226.29","quantity":"6.641"},{"price":"1231.29","quantity":"0.192"},{"price":"1562.38","quantity":"0.212"},{"price":"1562.66","quantity":"0.376"},{"price":"1562.67","quantity":"7.386"},{"price":"1666.80","quantity":"0.233"},{"price":"1701.56","quantity":"0.117"},{"price":"1708.36","quantity":"0.711"},{"price":"1708.50","quantity":"76.204"},{"price":"1708.53","quantity":"0.535"},{"price":"1710.39","quantity":"231.271"},{"price":"1713.72","quantity":"12.021"},{"price":"1724.98","quantity":"0.608"},{"price":"1725.15","quantity":"10.671"},{"price":"1727.24","quantity":"3.100"},{"price":"1727.41","quantity":"0.287"},{"price":"1730.44","quantity":"14.051"},{"price":"1732.27","quantity":"2.687"},{"price":"1733.50","quantity":"13.855"},{"price":"1734.01","quantity":"17.457"},{"price":"1734.04","quantity":"126.216"},{"price":"1734.18","quantity":"421.933"},{"price":"1734.19","quantity":"6.749"},{"price":"1734.21","quantity":"18.126"},{"price":"1734.83","quantity":"224.125"},{"price":"1734.85","quantity":"1.504"},{"price":"1734.96","quantity":"1.785"},{"price":"1734.97","quantity":"254.663"},{"price":"1735.08","quantity":"5.456"},{"price":"1735.28","quantity":"4.448"},{"price":"1735.29","quantity":"29.649"},{"price":"1735.30","quantity":"41.155"},{"price":"1735.41","quantity":"124.157"},{"price":"1735.58","quantity":"3.947"},{"price":"1735.62","quantity":"10.588"},{"price":"1735.74","quantity":"3.707"},{"price":"1735.82","quantity":"1.034"},{"price":"1735.91","quantity":"19.720"},{"price":"1735.94","quantity":"19.333"},{"price":"1735.95","quantity":"28.904"},{"price":"1735.99","quantity":"2.453"},{"price":"1736.00","quantity":"19.560"},{"price":"1736.09","quantity":"2.566"},{"price":"1736.11","quantity":"124.630"},{"price":"1736.13","quantity":"67.298"},{"price":"1736.14","quantity":"44.681"},{"price":"1736.16","quantity":"2.354"},{"price":"1736.17","quantity":"0.038"},{"price":"1736.19","quantity":"22.231"},{"price":"1736.21","quantity":"0.353"},{"price":"1736.23","quantity":"0.030"},{"price":"1736.24","quantity":"1.881"},{"price":"1736.27","quantity":"5.426"},{"price":"1736.28","quantity":"3.705"},{"price":"1736.29","quantity":"75.290"}],"asks":[{"price":"1736.30","quantity":"120.023"},{"price":"1736.36","quantity":"8.678"},{"price":"1736.38","quantity":"0.100"},{"price":"1736.39","quantity":"10.320"},{"price":"1736.41","quantity":"1.821"},{"price":"1736.46","quantity":"19.840"},{"price":"1736.49","quantity":"1.767"},{"price":"1736.51","quantity":"3.853"},{"price":"1736.55","quantity":"43.572"},{"price":"1736.56","quantity":"0.105"},{"price":"1736.59","quantity":"70.784"},{"price":"1736.60","quantity":"23.071"},{"price":"1736.61","quantity":"13.508"},{"price":"1736.62","quantity":"18.921"},{"price":"1736.65","quantity":"38.214"},{"price":"1736.69","quantity":"41.810"},{"price":"1736.79","quantity":"0.077"},{"price":"1736.84","quantity":"10.181"},{"price":"1736.97","quantity":"12.166"},{"price":"1737.30","quantity":"0.795"},{"price":"1737.60","quantity":"7.245"},{"price":"1737.69","quantity":"2.123"},{"price":"1737.80","quantity":"32.814"},{"price":"1738.89","quantity":"59.687"},{"price":"1738.91","quantity":"0.345"},{"price":"1738.94","quantity":"3.902"},{"price":"1738.96","quantity":"0.000"},{"price":"1739.98","quantity":"11.175"},{"price":"1740.13","quantity":"26.685"},{"price":"1740.58","quantity":"17.738"},{"price":"1742.48","quantity":"24.615"},{"price":"1758.00","quantity":"426.837"},{"price":"1763.90","quantity":"23.803"},{"price":"1772.10","quantity":"28.714"},{"price":"2633.55","quantity":"0.001"},{"price":"2633.56","quantity":"0.001"},{"price":"2633.64","quantity":"0.000"},{"price":"2633.65","quantity":"0.000"}],"raw":{"e":"depthUpdate","E":1783517076172,"T":1783517076169,"s":"ETHUSDT","ps":"ETHUSDT","U":10999771483803,"u":10999771491544,"pu":10999771483795,"b":[["200.00","7.594"],["1221.29","0.992"],["1226.29","6.641"],["1231.29","0.192"],["1562.38","0.212"],["1562.66","0.376"],["1562.67","7.386"],["1666.80","0.233"],["1701.56","0.117"],["1708.36","0.711"],["1708.50","76.204"],["1708.53","0.535"],["1710.39","231.271"],["1713.72","12.021"],["1724.98","0.608"],["1725.15","10.671"],["1727.24","3.100"],["1727.41","0.287"],["1730.44","14.051"],["1732.27","2.687"],["1733.50","13.855"],["1734.01","17.457"],["1734.04","126.216"],["1734.18","421.933"],["1734.19","6.749"],["1734.21","18.126"],["1734.83","224.125"],["1734.85","1.504"],["1734.96","1.785"],["1734.97","254.663"],["1735.08","5.456"],["1735.28","4.448"],["1735.29","29.649"],["1735.30","41.155"],["1735.41","124.157"],["1735.58","3.947"],["1735.62","10.588"],["1735.74","3.707"],["1735.82","1.034"],["1735.91","19.720"],["1735.94","19.333"],["1735.95","28.904"],["1735.99","2.453"],["1736.00","19.560"],["1736.09","2.566"],["1736.11","124.630"],["1736.13","67.298"],["1736.14","44.681"],["1736.16","2.354"],["1736.17","0.038"],["1736.19","22.231"],["1736.21","0.353"],["1736.23","0.030"],["1736.24","1.881"],["1736.27","5.426"],["1736.28","3.705"],["1736.29","75.290"]],"a":[["1736.30","120.023"],["1736.36","8.678"],["1736.38","0.100"],["1736.39","10.320"],["1736.41","1.821"],["1736.46","19.840"],["1736.49","1.767"],["1736.51","3.853"],["1736.55","43.572"],["1736.56","0.105"],["1736.59","70.784"],["1736.60","23.071"],["1736.61","13.508"],["1736.62","18.921"],["1736.65","38.214"],["1736.69","41.810"],["1736.79","0.077"],["1736.84","10.181"],["1736.97","12.166"],["1737.30","0.795"],["1737.60","7.245"],["1737.69","2.123"],["1737.80","32.814"],["1738.89","59.687"],["1738.91","0.345"],["1738.94","3.902"],["1738.96","0.000"],["1739.98","11.175"],["1740.13","26.685"],["1740.58","17.738"],["1742.48","24.615"],["1758.00","426.837"],["1763.90","23.803"],["1772.10","28.714"],["2633.55","0.001"],["2633.56","0.001"],["2633.64","0.000"],["2633.65","0.000"]],"st":1}}
{"schema_version":"1.3.0","event_id":"a57aeffc-9782-4aa5-88ae-d5d5db305d81","event_type":"raw.depth_update","source":"binance_market_data_recorder","venue":"binance_usdm","market_type":"perpetual_futures","symbol":"ETHUSDT","event_time_ms":1783517076274,"received_time_ms":1783517076269,"trace_id":"29a11e1a-519d-4fa7-878f-46fbe0fc7bb3","first_update_id":10999771491660,"final_update_id":10999771501019,"previous_final_update_id":10999771491544,"bids":[{"price":"200.00","quantity":"7.594"},{"price":"1221.29","quantity":"1.536"},{"price":"1226.29","quantity":"6.385"},{"price":"1231.28","quantity":"1.280"},{"price":"1231.29","quantity":"0.000"},{"price":"1562.66","quantity":"0.376"},{"price":"1562.67","quantity":"7.258"},{"price":"1643.18","quantity":"0.014"},{"price":"1666.80","quantity":"0.348"},{"price":"1701.56","quantity":"0.088"},{"price":"1704.17","quantity":"163.107"},{"price":"1718.36","quantity":"127.975"},{"price":"1730.01","quantity":"7.605"},{"price":"1730.23","quantity":"33.557"},{"price":"1732.20","quantity":"0.156"},{"price":"1732.43","quantity":"0.105"},{"price":"1732.77","quantity":"76.290"},{"price":"1732.78","quantity":"4.644"},{"price":"1732.81","quantity":"3.336"},{"price":"1732.90","quantity":"2.305"},{"price":"1733.03","quantity":"63.227"},{"price":"1734.01","quantity":"17.457"},{"price":"1734.02","quantity":"5.120"},{"price":"1734.04","quantity":"124.770"},{"price":"1734.06","quantity":"16.697"},{"price":"1734.18","quantity":"421.933"},{"price":"1734.62","quantity":"119.388"},{"price":"1734.75","quantity":"68.135"},{"price":"1734.76","quantity":"217.201"},{"price":"1734.77","quantity":"84.150"},{"price":"1734.78","quantity":"11.963"},{"price":"1734.83","quantity":"6.893"},{"price":"1734.89","quantity":"0.168"},{"price":"1734.96","quantity":"218.933"},{"price":"1734.97","quantity":"37.413"},{"price":"1735.13","quantity":"6.209"},{"price":"1735.29","quantity":"29.649"},{"price":"1735.48","quantity":"3.155"},{"price":"1735.51","quantity":"89.617"},{"price":"1735.60","quantity":"1.552"},{"price":"1735.61","quantity":"11.654"},{"price":"1735.69","quantity":"3.996"},{"price":"1735.74","quantity":"3.476"},{"price":"1735.78","quantity":"14.045"},{"price":"1735.80","quantity":"0.130"},{"price":"1735.83","quantity":"26.105"},{"price":"1735.84","quantity":"4.372"},{"price":"1735.85","quantity":"2.945"},{"price":"1735.87","quantity":"29.784"},{"price":"1735.91","quantity":"13.960"},{"price":"1735.95","quantity":"0.074"},{"price":"1735.99","quantity":"2.438"},{"price":"1736.07","quantity":"1.948"},{"price":"1736.08","quantity":"4.581"},{"price":"1736.09","quantity":"0.838"},{"price":"1736.11","quantity":"124.342"},{"price":"1736.12","quantity":"14.617"},{"price":"1736.14","quantity":"40.371"},{"price":"1736.16","quantity":"6.673"},{"price":"1736.18","quantity":"4.683"},{"price":"1736.20","quantity":"7.098"},{"price":"1736.28","quantity":"3.763"},{"price":"1736.29","quantity":"95.206"}],"asks":[{"price":"1736.30","quantity":"120.000"},{"price":"1736.35","quantity":"0.062"},{"price":"1736.39","quantity":"10.342"},{"price":"1736.42","quantity":"0.135"},{"price":"1736.46","quantity":"19.818"},{"price":"1736.47","quantity":"4.561"},{"price":"1736.48","quantity":"14.550"},{"price":"1736.49","quantity":"2.055"},{"price":"1736.50","quantity":"18.206"},{"price":"1736.51","quantity":"3.065"},{"price":"1736.53","quantity":"5.439"},{"price":"1736.58","quantity":"1.408"},{"price":"1736.60","quantity":"4.957"},{"price":"1736.62","quantity":"0.807"},{"price":"1736.63","quantity":"50.637"},{"price":"1736.64","quantity":"13.706"},{"price":"1736.69","quantity":"12.992"},{"price":"1736.80","quantity":"9.750"},{"price":"1736.94","quantity":"19.186"},{"price":"1737.11","quantity":"16.916"},{"price":"1737.29","quantity":"1.832"},{"price":"1737.30","quantity":"2.995"},{"price":"1737.33","quantity":"24.697"},{"price":"1737.54","quantity":"1.204"},{"price":"1737.63","quantity":"11.612"},{"price":"1738.04","quantity":"1.906"},{"price":"1738.12","quantity":"4.331"},{"price":"1738.80","quantity":"8.419"},{"price":"1738.88","quantity":"17.795"},{"price":"1739.14","quantity":"4.597"},{"price":"1739.38","quantity":"24.638"},{"price":"1739.85","quantity":"32.975"},{"price":"1739.98","quantity":"1.446"},{"price":"1740.13","quantity":"16.956"},{"price":"1740.58","quantity":"10.233"},{"price":"1747.12","quantity":"0.000"},{"price":"1763.21","quantity":"75.097"},{"price":"1764.07","quantity":"10.934"},{"price":"1768.42","quantity":"11.371"},{"price":"1788.00","quantity":"255.761"},{"price":"2633.54","quantity":"0.001"},{"price":"2633.63","quantity":"0.000"}],"raw":{"e":"depthUpdate","E":1783517076274,"T":1783517076273,"s":"ETHUSDT","ps":"ETHUSDT","U":10999771491660,"u":10999771501019,"pu":10999771491544,"b":[["200.00","7.594"],["1221.29","1.536"],["1226.29","6.385"],["1231.28","1.280"],["1231.29","0.000"],["1562.66","0.376"],["1562.67","7.258"],["1643.18","0.014"],["1666.80","0.348"],["1701.56","0.088"],["1704.17","163.107"],["1718.36","127.975"],["1730.01","7.605"],["1730.23","33.557"],["1732.20","0.156"],["1732.43","0.105"],["1732.77","76.290"],["1732.78","4.644"],["1732.81","3.336"],["1732.90","2.305"],["1733.03","63.227"],["1734.01","17.457"],["1734.02","5.120"],["1734.04","124.770"],["1734.06","16.697"],["1734.18","421.933"],["1734.62","119.388"],["1734.75","68.135"],["1734.76","217.201"],["1734.77","84.150"],["1734.78","11.963"],["1734.83","6.893"],["1734.89","0.168"],["1734.96","218.933"],["1734.97","37.413"],["1735.13","6.209"],["1735.29","29.649"],["1735.48","3.155"],["1735.51","89.617"],["1735.60","1.552"],["1735.61","11.654"],["1735.69","3.996"],["1735.74","3.476"],["1735.78","14.045"],["1735.80","0.130"],["1735.83","26.105"],["1735.84","4.372"],["1735.85","2.945"],["1735.87","29.784"],["1735.91","13.960"],["1735.95","0.074"],["1735.99","2.438"],["1736.07","1.948"],["1736.08","4.581"],["1736.09","0.838"],["1736.11","124.342"],["1736.12","14.617"],["1736.14","40.371"],["1736.16","6.673"],["1736.18","4.683"],["1736.20","7.098"],["1736.28","3.763"],["1736.29","95.206"]],"a":[["1736.30","120.000"],["1736.35","0.062"],["1736.39","10.342"],["1736.42","0.135"],["1736.46","19.818"],["1736.47","4.561"],["1736.48","14.550"],["1736.49","2.055"],["1736.50","18.206"],["1736.51","3.065"],["1736.53","5.439"],["1736.58","1.408"],["1736.60","4.957"],["1736.62","0.807"],["1736.63","50.637"],["1736.64","13.706"],["1736.69","12.992"],["1736.80","9.750"],["1736.94","19.186"],["1737.11","16.916"],["1737.29","1.832"],["1737.30","2.995"],["1737.33","24.697"],["1737.54","1.204"],["1737.63","11.612"],["1738.04","1.906"],["1738.12","4.331"],["1738.80","8.419"],["1738.88","17.795"],["1739.14","4.597"],["1739.38","24.638"],["1739.85","32.975"],["1739.98","1.446"],["1740.13","16.956"],["1740.58","10.233"],["1747.12","0.000"],["1763.21","75.097"],["1764.07","10.934"],["1768.42","11.371"],["1788.00","255.761"],["2633.54","0.001"],["2633.63","0.000"]],"st":1}}
{"schema_version":"1.3.0","event_id":"8d1ba8a8-98dc-4a2b-aea8-84ac2e928777","event_type":"raw.depth_update","source":"binance_market_data_recorder","venue":"binance_usdm","market_type":"perpetual_futures","symbol":"ETHUSDT","event_time_ms":1783517076376,"received_time_ms":1783517076371,"trace_id":"b9f69439-03d3-4fe3-9aa3-83961b813c35","first_update_id":10999771501070,"final_update_id":10999771507376,"previous_final_update_id":10999771501019,"bids":[{"price":"1221.29","quantity":"2.080"},{"price":"1226.29","quantity":"6.097"},{"price":"1231.28","quantity":"1.024"},{"price":"1562.66","quantity":"0.376"},{"price":"1562.67","quantity":"7.258"},{"price":"1666.80","quantity":"0.233"},{"price":"1705.75","quantity":"58.547"},{"price":"1708.50","quantity":"64.615"},{"price":"1709.38","quantity":"15.818"},{"price":"1733.96","quantity":"4.606"},{"price":"1734.01","quantity":"20.653"},{"price":"1734.02","quantity":"3.674"},{"price":"1734.06","quantity":"18.143"},{"price":"1734.13","quantity":"3.167"},{"price":"1734.76","quantity":"0.031"},{"price":"1734.78","quantity":"0.444"},{"price":"1734.91","quantity":"218.471"},{"price":"1734.96","quantity":"1.785"},{"price":"1735.04","quantity":"3.819"},{"price":"1735.13","quantity":"0.450"},{"price":"1735.31","quantity":"34.175"},{"price":"1736.29","quantity":"81.207"}],"asks":[{"price":"1736.30","quantity":"120.023"},{"price":"1736.35","quantity":"0.038"},{"price":"1736.38","quantity":"0.120"},{"price":"1736.49","quantity":"2.055"},{"price":"1737.63","quantity":"0.093"},{"price":"1737.84","quantity":"10.614"},{"price":"1738.12","quantity":"5.998"},{"price":"1760.62","quantity":"45.150"},{"price":"1770.07","quantity":"37.242"},{"price":"1770.42","quantity":"0.000"},{"price":"2633.52","quantity":"0.001"},{"price":"2633.53","quantity":"0.001"},{"price":"2633.61","quantity":"0.000"},{"price":"2633.62","quantity":"0.000"}],"raw":{"e":"depthUpdate","E":1783517076376,"T":1783517076373,"s":"ETHUSDT","ps":"ETHUSDT","U":10999771501070,"u":10999771507376,"pu":10999771501019,"b":[["1221.29","2.080"],["1226.29","6.097"],["1231.28","1.024"],["1562.66","0.376"],["1562.67","7.258"],["1666.80","0.233"],["1705.75","58.547"],["1708.50","64.615"],["1709.38","15.818"],["1733.96","4.606"],["1734.01","20.653"],["1734.02","3.674"],["1734.06","18.143"],["1734.13","3.167"],["1734.76","0.031"],["1734.78","0.444"],["1734.91","218.471"],["1734.96","1.785"],["1735.04","3.819"],["1735.13","0.450"],["1735.31","34.175"],["1736.29","81.207"]],"a":[["1736.30","120.023"],["1736.35","0.038"],["1736.38","0.120"],["1736.49","2.055"],["1737.63","0.093"],["1737.84","10.614"],["1738.12","5.998"],["1760.62","45.150"],["1770.07","37.242"],["1770.42","0.000"],["2633.52","0.001"],["2633.53","0.001"],["2633.61","0.000"],["2633.62","0.000"]],"st":1}}
{"schema_version":"1.3.0","event_id":"c3a08faf-f9b2-426b-8c85-a9a663bf7765","event_type":"raw.depth_update","source":"binance_market_data_recorder","venue":"binance_usdm","market_type":"perpetual_futures","symbol":"ETHUSDT","event_time_ms":1783517076478,"received_time_ms":1783517076475,"trace_id":"9d0e014b-d39a-4ed1-8cf3-a8ff9b47c5e1","first_update_id":10999771507783,"final_update_id":10999771513857,"previous_final_update_id":10999771507376,"bids":[{"price":"200.00","quantity":"7.594"},{"price":"1221.29","quantity":"2.624"},{"price":"1226.29","quantity":"5.841"},{"price":"1231.28","quantity":"0.736"},{"price":"1562.66","quantity":"0.376"},{"price":"1562.67","quantity":"7.514"},{"price":"1595.06","quantity":"0.045"},{"price":"1701.56","quantity":"0.117"},{"price":"1704.86","quantity":"85.066"},{"price":"1710.25","quantity":"211.853"},{"price":"1718.75","quantity":"642.930"},{"price":"1730.23","quantity":"23.828"},{"price":"1730.44","quantity":"4.322"},{"price":"1730.79","quantity":"43.560"},{"price":"1730.93","quantity":"0.028"},{"price":"1734.01","quantity":"439.378"},{"price":"1734.06","quantity":"19.893"},{"price":"1734.18","quantity":"0.012"},{"price":"1734.76","quantity":"0.013"},{"price":"1734.77","quantity":"84.168"},{"price":"1734.88","quantity":"21.898"},{"price":"1734.91","quantity":"1.364"},{"price":"1735.03","quantity":"217.238"},{"price":"1735.15","quantity":"221.369"},{"price":"1735.42","quantity":"31.003"},{"price":"1735.75","quantity":"75.839"},{"price":"1735.82","quantity":"1.058"},{"price":"1735.87","quantity":"0.953"},{"price":"1735.95","quantity":"28.904"},{"price":"1735.98","quantity":"67.284"},{"price":"1736.09","quantity":"0.743"},{"price":"1736.12","quantity":"14.712"},{"price":"1736.15","quantity":"23.837"},{"price":"1736.19","quantity":"22.243"},{"price":"1736.29","quantity":"141.081"}],"asks":[{"price":"1736.30","quantity":"120.000"},{"price":"1736.50","quantity":"0.092"},{"price":"1737.30","quantity":"2.995"},{"price":"1738.88","quantity":"10.290"},{"price":"1741.59","quantity":"14.311"},{"price":"1741.71","quantity":"0.031"},{"price":"1768.42","quantity":"17.018"},{"price":"2633.50","quantity":"0.001"},{"price":"2633.51","quantity":"0.001"},{"price":"2633.59","quantity":"0.000"},{"price":"2633.60","quantity":"0.000"}],"raw":{"e":"depthUpdate","E":1783517076478,"T":1783517076477,"s":"ETHUSDT","ps":"ETHUSDT","U":10999771507783,"u":10999771513857,"pu":10999771507376,"b":[["200.00","7.594"],["1221.29","2.624"],["1226.29","5.841"],["1231.28","0.736"],["1562.66","0.376"],["1562.67","7.514"],["1595.06","0.045"],["1701.56","0.117"],["1704.86","85.066"],["1710.25","211.853"],["1718.75","642.930"],["1730.23","23.828"],["1730.44","4.322"],["1730.79","43.560"],["1730.93","0.028"],["1734.01","439.378"],["1734.06","19.893"],["1734.18","0.012"],["1734.76","0.013"],["1734.77","84.168"],["1734.88","21.898"],["1734.91","1.364"],["1735.03","217.238"],["1735.15","221.369"],["1735.42","31.003"],["1735.75","75.839"],["1735.82","1.058"],["1735.87","0.953"],["1735.95","28.904"],["1735.98","67.284"],["1736.09","0.743"],["1736.12","14.712"],["1736.15","23.837"],["1736.19","22.243"],["1736.29","141.081"]],"a":[["1736.30","120.000"],["1736.50","0.092"],["1737.30","2.995"],["1738.88","10.290"],["1741.59","14.311"],["1741.71","0.031"],["1768.42","17.018"],["2633.50","0.001"],["2633.51","0.001"],["2633.59","0.000"],["2633.60","0.000"]],"st":1}}
{"schema_version":"1.3.0","event_id":"60ad537b-978c-4ed1-87b3-3e054e6fc71c","event_type":"raw.depth_update","source":"binance_market_data_recorder","venue":"binance_usdm","market_type":"perpetual_futures","symbol":"ETHUSDT","event_time_ms":1783517076580,"received_time_ms":1783517076575,"trace_id":"96d0b402-0a2c-4ec4-8505-6fb039538d1f","first_update_id":10999771513875,"final_update_id":10999771519745,"previous_final_update_id":10999771513857,"bids":[{"price":"201.00","quantity":"2.300"},{"price":"1221.29","quantity":"3.168"},{"price":"1226.29","quantity":"5.553"},{"price":"1231.28","quantity":"0.480"},{"price":"1562.66","quantity":"0.376"},{"price":"1562.67","quantity":"7.514"},{"price":"1666.80","quantity":"0.348"},{"price":"1701.56","quantity":"0.088"},{"price":"1702.68","quantity":"0.000"},{"price":"1710.24","quantity":"104.983"},{"price":"1711.11","quantity":"168.590"},{"price":"1714.36","quantity":"11.584"},{"price":"1717.19","quantity":"508.750"},{"price":"1730.00","quantity":"802.501"},{"price":"1732.52","quantity":"9.729"},{"price":"1734.01","quantity":"17.457"},{"price":"1734.02","quantity":"3.674"},{"price":"1734.04","quantity":"126.216"},{"price":"1734.18","quantity":"421.933"},{"price":"1735.03","quantity":"0.123"},{"price":"1735.29","quantity":"29.649"},{"price":"1735.34","quantity":"1.610"},{"price":"1735.66","quantity":"0.199"},{"price":"1735.91","quantity":"13.948"},{"price":"1735.97","quantity":"5.987"},{"price":"1736.29","quantity":"141.093"}],"asks":[{"price":"1736.48","quantity":"10.856"},{"price":"1736.73","quantity":"4.051"},{"price":"1736.89","quantity":"6.366"},{"price":"1737.02","quantity":"16.572"},{"price":"1737.33","quantity":"23.003"},{"price":"1737.83","quantity":"33.086"},{"price":"1737.84","quantity":"36.744"},{"price":"1738.91","quantity":"0.345"},{"price":"1740.58","quantity":"17.738"},{"price":"1744.99","quantity":"0.343"},{"price":"1747.12","quantity":"15.000"},{"price":"1764.06","quantity":"28.292"},{"price":"1768.60","quantity":"28.013"},{"price":"1769.29","quantity":"69.372"},{"price":"2633.49","quantity":"0.001"},{"price":"2633.58","quantity":"0.000"}],"raw":{"e":"depthUpdate","E":1783517076580,"T":1783517076577,"s":"ETHUSDT","ps":"ETHUSDT","U":10999771513875,"u":10999771519745,"pu":10999771513857,"b":[["201.00","2.300"],["1221.29","3.168"],["1226.29","5.553"],["1231.28","0.480"],["1562.66","0.376"],["1562.67","7.514"],["1666.80","0.348"],["1701.56","0.088"],["1702.68","0.000"],["1710.24","104.983"],["1711.11","168.590"],["1714.36","11.584"],["1717.19","508.750"],["1730.00","802.501"],["1732.52","9.729"],["1734.01","17.457"],["1734.02","3.674"],["1734.04","126.216"],["1734.18","421.933"],["1735.03","0.123"],["1735.29","29.649"],["1735.34","1.610"],["1735.66","0.199"],["1735.91","13.948"],["1735.97","5.987"],["1736.29","141.093"]],"a":[["1736.48","10.856"],["1736.73","4.051"],["1736.89","6.366"],["1737.02","16.572"],["1737.33","23.003"],["1737.83","33.086"],["1737.84","36.744"],["1738.91","0.345"],["1740.58","17.738"],["1744.99","0.343"],["1747.12","15.000"],["1764.06","28.292"],["1768.60","28.013"],["1769.29","69.372"],["2633.49","0.001"],["2633.58","0.000"]],"st":1}}
{"schema_version":"1.3.0","event_id":"4c79ca52-a502-47cb-b475-559121c4df99","event_type":"raw.depth_update","source":"binance_market_data_recorder","venue":"binance_usdm","market_type":"perpetual_futures","symbol":"ETHUSDT","event_time_ms":1783517076682,"received_time_ms":1783517076677,"trace_id":"344cf0f4-5a20-4594-b4a1-ae2025cbcf16","first_update_id":10999771520022,"final_update_id":10999771525126,"previous_final_update_id":10999771519745,"bids":[{"price":"1221.29","quantity":"3.712"},{"price":"1226.29","quantity":"5.297"},{"price":"1231.28","quantity":"0.192"},{"price":"1562.66","quantity":"0.376"},{"price":"1562.67","quantity":"7.514"},{"price":"1666.80","quantity":"0.233"},{"price":"1701.56","quantity":"0.117"},{"price":"1718.04","quantity":"69.177"},{"price":"1718.64","quantity":"0.083"},{"price":"1730.07","quantity":"135.808"},{"price":"1730.08","quantity":"26.300"},{"price":"1730.09","quantity":"4.331"},{"price":"1732.24","quantity":"19.742"},{"price":"1734.89","quantity":"217.237"},{"price":"1734.91","quantity":"1.364"},{"price":"1735.01","quantity":"19.298"},{"price":"1735.15","quantity":"4.274"},{"price":"1735.51","quantity":"89.603"},{"price":"1735.68","quantity":"5.342"},{"price":"1735.94","quantity":"19.345"},{"price":"1735.97","quantity":"5.975"},{"price":"1736.11","quantity":"124.302"},{"price":"1736.12","quantity":"24.712"},{"price":"1736.19","quantity":"22.255"},{"price":"1736.20","quantity":"7.112"},{"price":"1736.24","quantity":"2.881"},{"price":"1736.29","quantity":"105.725"}],"asks":[{"price":"1736.30","quantity":"120.012"},{"price":"1736.49","quantity":"2.055"},{"price":"1736.60","quantity":"5.126"},{"price":"1736.66","quantity":"6.756"},{"price":"1736.72","quantity":"11.122"},{"price":"1736.73","quantity":"2.357"},{"price":"1736.89","quantity":"4.672"},{"price":"1737.17","quantity":"3.360"},{"price":"1737.60","quantity":"7.245"},{"price":"1737.89","quantity":"8.973"},{"price":"1738.56","quantity":"1.996"},{"price":"1738.89","quantity":"56.491"},{"price":"1738.91","quantity":"3.541"},{"price":"1782.14","quantity":"28.601"},{"price":"2633.47","quantity":"0.001"},{"price":"2633.48","quantity":"0.001"},{"price":"2633.56","quantity":"0.000"},{"price":"2633.57","quantity":"0.000"}],"raw":{"e":"depthUpdate","E":1783517076682,"T":1783517076681,"s":"ETHUSDT","ps":"ETHUSDT","U":10999771520022,"u":10999771525126,"pu":10999771519745,"b":[["1221.29","3.712"],["1226.29","5.297"],["1231.28","0.192"],["1562.66","0.376"],["1562.67","7.514"],["1666.80","0.233"],["1701.56","0.117"],["1718.04","69.177"],["1718.64","0.083"],["1730.07","135.808"],["1730.08","26.300"],["1730.09","4.331"],["1732.24","19.742"],["1734.89","217.237"],["1734.91","1.364"],["1735.01","19.298"],["1735.15","4.274"],["1735.51","89.603"],["1735.68","5.342"],["1735.94","19.345"],["1735.97","5.975"],["1736.11","124.302"],["1736.12","24.712"],["1736.19","22.255"],["1736.20","7.112"],["1736.24","2.881"],["1736.29","105.725"]],"a":[["1736.30","120.012"],["1736.49","2.055"],["1736.60","5.126"],["1736.66","6.756"],["1736.72","11.122"],["1736.73","2.357"],["1736.89","4.672"],["1737.17","3.360"],["1737.60","7.245"],["1737.89","8.973"],["1738.56","1.996"],["1738.89","56.491"],["1738.91","3.541"],["1782.14","28.601"],["2633.47","0.001"],["2633.48","0.001"],["2633.56","0.000"],["2633.57","0.000"]],"st":1}}
{"schema_version":"1.3.0","event_id":"e02f18e9-a0ef-4c90-ba29-d041c4a36920","event_type":"raw.depth_update","source":"binance_market_data_recorder","venue":"binance_usdm","market_type":"perpetual_futures","symbol":"ETHUSDT","event_time_ms":1783517076786,"received_time_ms":1783517076781,"trace_id":"4487416f-a848-450a-aa7a-33b40df6b26a","first_update_id":10999771525417,"final_update_id":10999771531070,"previous_final_update_id":10999771525126,"bids":[{"price":"200.00","quantity":"7.594"},{"price":"1221.29","quantity":"4.352"},{"price":"1226.29","quantity":"4.849"},{"price":"1231.28","quantity":"0.000"},{"price":"1562.66","quantity":"0.376"},{"price":"1562.67","quantity":"7.642"},{"price":"1650.00","quantity":"1681.405"},{"price":"1666.80","quantity":"0.348"},{"price":"1693.56","quantity":"318.194"},{"price":"1699.06","quantity":"31.861"},{"price":"1701.56","quantity":"0.088"},{"price":"1715.15","quantity":"11.763"},{"price":"1718.92","quantity":"79.053"},{"price":"1727.60","quantity":"0.090"},{"price":"1730.79","quantity":"27.229"},{"price":"1734.06","quantity":"18.447"},{"price":"1735.45","quantity":"29.542"},{"price":"1735.80","quantity":"0.130"}],"asks":[{"price":"1736.70","quantity":"79.656"},{"price":"1737.30","quantity":"2.995"},{"price":"1739.66","quantity":"2.112"},{"price":"1739.93","quantity":"20.476"},{"price":"1741.59","quantity":"0.013"},{"price":"1744.99","quantity":"0.331"},{"price":"1747.12","quantity":"0.000"},{"price":"1762.93","quantity":"9.937"},{"price":"1768.87","quantity":"30.482"},{"price":"2633.46","quantity":"0.001"},{"price":"2633.55","quantity":"0.000"}],"raw":{"e":"depthUpdate","E":1783517076786,"T":1783517076785,"s":"ETHUSDT","ps":"ETHUSDT","U":10999771525417,"u":10999771531070,"pu":10999771525126,"b":[["200.00","7.594"],["1221.29","4.352"],["1226.29","4.849"],["1231.28","0.000"],["1562.66","0.376"],["1562.67","7.642"],["1650.00","1681.405"],["1666.80","0.348"],["1693.56","318.194"],["1699.06","31.861"],["1701.56","0.088"],["1715.15","11.763"],["1718.92","79.053"],["1727.60","0.090"],["1730.79","27.229"],["1734.06","18.447"],["1735.45","29.542"],["1735.80","0.130"]],"a":[["1736.70","79.656"],["1737.30","2.995"],["1739.66","2.112"],["1739.93","20.476"],["1741.59","0.013"],["1744.99","0.331"],["1747.12","0.000"],["1762.93","9.937"],["1768.87","30.482"],["2633.46","0.001"],["2633.55","0.000"]],"st":1}}
{"schema_version":"1.3.0","event_id":"3de8a627-9b26-4b53-931a-0b988e185753","event_type":"raw.depth_update","source":"binance_market_data_recorder","venue":"binance_usdm","market_type":"perpetual_futures","symbol":"ETHUSDT","event_time_ms":1783517076888,"received_time_ms":1783517076887,"trace_id":"7e93636a-30eb-4007-a8c5-c9a09940a548","first_update_id":10999771531237,"final_update_id":10999771535535,"previous_final_update_id":10999771531070,"bids":[{"price":"1221.29","quantity":"5.152"},{"price":"1226.29","quantity":"4.049"},{"price":"1562.66","quantity":"0.376"},{"price":"1562.67","quantity":"7.514"},{"price":"1638.83","quantity":"0.045"},{"price":"1666.80","quantity":"0.233"},{"price":"1701.56","quantity":"0.117"},{"price":"1705.75","quantity":"58.547"},{"price":"1729.95","quantity":"0.929"},{"price":"1729.96","quantity":"14.388"},{"price":"1730.82","quantity":"23.230"},{"price":"1733.83","quantity":"0.562"},{"price":"1734.01","quantity":"443.260"},{"price":"1734.04","quantity":"127.662"},{"price":"1734.18","quantity":"0.012"},{"price":"1735.01","quantity":"236.364"},{"price":"1735.29","quantity":"29.649"},{"price":"1736.29","quantity":"111.472"}],"asks":[{"price":"1736.37","quantity":"4.032"},{"price":"1736.49","quantity":"2.055"},{"price":"1736.91","quantity":"34.386"},{"price":"1737.17","quantity":"3.264"},{"price":"1737.89","quantity":"7.279"},{"price":"1738.04","quantity":"0.239"},{"price":"1739.35","quantity":"1.814"},{"price":"1739.66","quantity":"0.728"},{"price":"1741.59","quantity":"14.311"},{"price":"1742.44","quantity":"17.451"},{"price":"1742.50","quantity":"0.656"},{"price":"2633.45","quantity":"0.001"},{"price":"2633.54","quantity":"0.000"}],"raw":{"e":"depthUpdate","E":1783517076888,"T":1783517076887,"s":"ETHUSDT","ps":"ETHUSDT","U":10999771531237,"u":10999771535535,"pu":10999771531070,"b":[["1221.29","5.152"],["1226.29","4.049"],["1562.66","0.376"],["1562.67","7.514"],["1638.83","0.045"],["1666.80","0.233"],["1701.56","0.117"],["1705.75","58.547"],["1729.95","0.929"],["1729.96","14.388"],["1730.82","23.230"],["1733.83","0.562"],["1734.01","443.260"],["1734.04","127.662"],["1734.18","0.012"],["1735.01","236.364"],["1735.29","29.649"],["1736.29","111.472"]],"a":[["1736.37","4.032"],["1736.49","2.055"],["1736.91","34.386"],["1737.17","3.264"],["1737.89","7.279"],["1738.04","0.239"],["1739.35","1.814"],["1739.66","0.728"],["1741.59","14.311"],["1742.44","17.451"],["1742.50","0.656"],["2633.45","0.001"],["2633.54","0.000"]],"st":1}}
{"schema_version":"1.3.0","event_id":"d2dee393-cf22-44a6-a56c-e4dd683446c0","event_type":"raw.depth_update","source":"binance_market_data_recorder","venue":"binance_usdm","market_type":"perpetual_futures","symbol":"ETHUSDT","event_time_ms":1783517076990,"received_time_ms":1783517076985,"trace_id":"1d61de0e-22c3-4fc5-b44b-222e2d809923","first_update_id":10999771535558,"final_update_id":10999771542145,"previous_final_update_id":10999771535535,"bids":[{"price":"1221.29","quantity":"5.984"},{"price":"1226.28","quantity":"0.384"},{"price":"1226.29","quantity":"3.249"},{"price":"1562.66","quantity":"0.376"},{"price":"1562.67","quantity":"7.514"},{"price":"1590.71","quantity":"0.077"},{"price":"1701.56","quantity":"0.088"},{"price":"1730.82","quantity":"6.899"},{"price":"1734.02","quantity":"5.424"},{"price":"1734.03","quantity":"102.497"},{"price":"1734.06","quantity":"16.697"},{"price":"1735.01","quantity":"19.298"},{"price":"1735.02","quantity":"49.970"},{"price":"1735.74","quantity":"15.206"},{"price":"1735.92","quantity":"59.930"},{"price":"1735.95","quantity":"0.074"},{"price":"1736.17","quantity":"0.050"},{"price":"1736.29","quantity":"117.399"}],"asks":[{"price":"1736.78","quantity":"19.029"},{"price":"1736.91","quantity":"32.692"},{"price":"1737.30","quantity":"2.995"},{"price":"1737.89","quantity":"8.973"},{"price":"1738.17","quantity":"70.223"},{"price":"1738.89","quantity":"59.687"},{"price":"1738.91","quantity":"0.345"},{"price":"1741.59","quantity":"0.013"},{"price":"1767.60","quantity":"13.556"},{"price":"2633.43","quantity":"0.001"},{"price":"2633.44","quantity":"0.015"},{"price":"2633.52","quantity":"0.000"},{"price":"2633.53","quantity":"0.000"}],"raw":{"e":"depthUpdate","E":1783517076990,"T":1783517076989,"s":"ETHUSDT","ps":"ETHUSDT","U":10999771535558,"u":10999771542145,"pu":10999771535535,"b":[["1221.29","5.984"],["1226.28","0.384"],["1226.29","3.249"],["1562.66","0.376"],["1562.67","7.514"],["1590.71","0.077"],["1701.56","0.088"],["1730.82","6.899"],["1734.02","5.424"],["1734.03","102.497"],["1734.06","16.697"],["1735.01","19.298"],["1735.02","49.970"],["1735.74","15.206"],["1735.92","59.930"],["1735.95","0.074"],["1736.17","0.050"],["1736.29","117.399"]],"a":[["1736.78","19.029"],["1736.91","32.692"],["1737.30","2.995"],["1737.89","8.973"],["1738.17","70.223"],["1738.89","59.687"],["1738.91","0.345"],["1741.59","0.013"],["1767.60","13.556"],["2633.43","0.001"],["2633.44","0.015"],["2633.52","0.000"],["2633.53","0.000"]],"st":1}}
