{"schema_version":"1.3.0","event_id":"59f573e6-103b-445c-aa42-9bc397575500","event_type":"raw.depth_update","source":"binance_market_data_recorder","venue":"binance_usdm","market_type":"perpetual_futures","symbol":"ETHUSDT","event_time_ms":1783517067580,"received_time_ms":1783517067578,"trace_id":"d61d00a9-33ac-4806-bd82-688fe7ef946a","first_update_id":10999770638293,"final_update_id":10999770649894,"previous_final_update_id":10999770638173,"bids":[{"price":"201.00","quantity":"2.300"},{"price":"1211.12","quantity":"7.361"},{"price":"1216.12","quantity":"2.272"},{"price":"1216.13","quantity":"0.000"},{"price":"1231.12","quantity":"0.160"},{"price":"1562.50","quantity":"1.060"},{"price":"1562.51","quantity":"8.880"},{"price":"1666.60","quantity":"1.078"},{"price":"1698.07","quantity":"0.207"},{"price":"1734.06","quantity":"54.181"},{"price":"1734.12","quantity":"55.897"},{"price":"1734.49","quantity":"53.070"},{"price":"1734.57","quantity":"29.351"},{"price":"1734.60","quantity":"0.309"},{"price":"1734.62","quantity":"119.388"},{"price":"1734.63","quantity":"23.322"},{"price":"1734.64","quantity":"0.556"},{"price":"1734.75","quantity":"68.153"},{"price":"1734.84","quantity":"272.872"},{"price":"1734.86","quantity":"258.509"},{"price":"1735.01","quantity":"19.586"},{"price":"1735.35","quantity":"20.788"},{"price":"1735.61","quantity":"8.774"},{"price":"1735.65","quantity":"20.560"},{"price":"1735.67","quantity":"20.051"},{"price":"1735.71","quantity":"0.050"},{"price":"1735.73","quantity":"26.047"},{"price":"1735.76","quantity":"15.145"},{"price":"1735.79","quantity":"4.090"},{"price":"1735.82","quantity":"0.866"},{"price":"1735.86","quantity":"68.396"},{"price":"1735.87","quantity":"1.139"},{"price":"1735.90","quantity":"3.012"},{"price":"1735.91","quantity":"9.957"},{"price":"1735.92","quantity":"30.835"},{"price":"1735.93","quantity":"22.962"},{"price":"1735.94","quantity":"6.510"},{"price":"1735.95","quantity":"2.378"},{"price":"1735.96","quantity":"2.280"},{"price":"1735.97","quantity":"3.095"},{"price":"1736.00","quantity":"7.546"},{"price":"1736.01","quantity":"0.050"},{"price":"1736.03","quantity":"0.153"},{"price":"1736.04","quantity":"1.227"},{"price":"1736.06","quantity":"0.014"},{"price":"1736.07","quantity":"0.036"},{"price":"1736.08","quantity":"0.735"},{"price":"1736.09","quantity":"0.942"},{"price":"1736.12","quantity":"113.423"}],"asks":[{"price":"1736.13","quantity":"121.857"},{"price":"1736.18","quantity":"1.858"},{"price":"1736.20","quantity":"2.828"},{"price":"1736.21","quantity":"0.032"},{"price":"1736.22","quantity":"20.213"},{"price":"1736.23","quantity":"21.780"},{"price":"1736.25","quantity":"3.977"},{"price":"1736.27","quantity":"0.814"},{"price":"1736.32","quantity":"0.130"},{"price":"1736.36","quantity":"5.168"},{"price":"1736.37","quantity":"10.715"},{"price":"1736.44","quantity":"10.857"},{"price":"1736.49","quantity":"3.015"},{"price":"1736.50","quantity":"0.114"},{"price":"1736.56","quantity":"9.096"},{"price":"1736.63","quantity":"10.262"},{"price":"1736.75","quantity":"78.830"},{"price":"1736.79","quantity":"0.096"},{"price":"1736.89","quantity":"9.594"},{"price":"1737.00","quantity":"71.577"},{"price":"1737.04","quantity":"29.478"},{"price":"1737.05","quantity":"0.797"},{"price":"1737.13","quantity":"7.142"},{"price":"1737.35","quantity":"42.850"},{"price":"1737.39","quantity":"2.576"},{"price":"1737.52","quantity":"2.666"},{"price":"1737.54","quantity":"1.118"},{"price":"1737.55","quantity":"37.237"},{"price":"1737.57","quantity":"42.677"},{"price":"1737.61","quantity":"12.960"},{"price":"1737.80","quantity":"31.254"},{"price":"1737.87","quantity":"7.926"},{"price":"1737.89","quantity":"7.279"},{"price":"1737.92","quantity":"0.730"},{"price":"1738.13","quantity":"21.531"},{"price":"1738.27","quantity":"15.155"},{"price":"1738.35","quantity":"0.047"},{"price":"1738.88","quantity":"1.079"},{"price":"1738.91","quantity":"3.541"},{"price":"1738.94","quantity":"7.156"},{"price":"1738.96","quantity":"3.196"},{"price":"1739.42","quantity":"25.430"},{"price":"1740.16","quantity":"9.755"},{"price":"1740.58","quantity":"8.287"},{"price":"1747.12","quantity":"0.000"},{"price":"2634.83","quantity":"0.001"},{"price":"2634.84","quantity":"0.399"},{"price":"2634.92","quantity":"0.019"},{"price":"2634.93","quantity":"0.000"}],"raw":{"e":"depthUpdate","E":1783517067580,"T":1783517067577,"s":"ETHUSDT","ps":"ETHUSDT","U":10999770638293,"u":10999770649894,"pu":10999770638173,"b":[["201.00","2.300"],["1211.12","7.361"],["1216.12","2.272"],["1216.13","0.000"],["1231.12","0.160"],["1562.50","1.060"],["1562.51","8.880"],["1666.60","1.078"],["1698.07","0.207"],["1734.06","54.181"],["1734.12","55.897"],["1734.49","53.070"],["1734.57","29.351"],["1734.60","0.309"],["1734.62","119.388"],["1734.63","23.322"],["1734.64","0.556"],["1734.75","68.153"],["1734.84","272.872"],["1734.86","258.509"],["1735.01","19.586"],["1735.35","20.788"],["1735.61","8.774"],["1735.65","20.560"],["1735.67","20.051"],["1735.71","0.050"],["1735.73","26.047"],["1735.76","15.145"],["1735.79","4.090"],["1735.82","0.866"],["1735.86","68.396"],["1735.87","1.139"],["1735.90","3.012"],["1735.91","9.957"],["1735.92","30.835"],["1735.93","22.962"],["1735.94","6.510"],["1735.95","2.378"],["1735.96","2.280"],["1735.97","3.095"],["1736.00","7.546"],["1736.01","0.050"],["1736.03","0.153"],["1736.04","1.227"],["1736.06","0.014"],["1736.07","0.036"],["1736.08","0.735"],["1736.09","0.942"],["1736.12","113.423"]],"a":[["1736.13","121.857"],["1736.18","1.858"],["1736.20","2.828"],["1736.21","0.032"],["1736.22","20.213"],["1736.23","21.780"],["1736.25","3.977"],["1736.27","0.814"],["1736.32","0.130"],["1736.36","5.168"],["1736.37","10.715"],["1736.44","10.857"],["1736.49","3.015"],["1736.50","0.114"],["1736.56","9.096"],["1736.63","10.262"],["1736.75","78.830"],["1736.79","0.096"],["1736.89","9.594"],["1737.00","71.577"],["1737.04","29.478"],["1737.05","0.797"],["1737.13","7.142"],["1737.35","42.850"],["1737.39","2.576"],["1737.52","2.666"],["1737.54","1.118"],["1737.55","37.237"],["1737.57","42.677"],["1737.61","12.960"],["1737.80","31.254"],["1737.87","7.926"],["1737.89","7.279"],["1737.92","0.730"],["1738.13","21.531"],["1738.27","15.155"],["1738.35","0.047"],["1738.88","1.079"],["1738.91","3.541"],["1738.94","7.156"],["1738.96","3.196"],["1739.42","25.430"],["1740.16","9.755"],["1740.58","8.287"],["1747.12","0.000"],["2634.83","0.001"],["2634.84","0.399"],["2634.92","0.019"],["2634.93","0.000"]],"st":1}}
{"schema_version":"1.3.0","event_id":"0e59475d-808d-45db-9015-1d9d0d62a2c4","event_type":"raw.depth_update","source":"binance_market_data_recorder","venue":"binance_usdm","market_type":"perpetual_futures","symbol":"ETHUSDT","event_time_ms":1783517067682,"received_time_ms":1783517067676,"trace_id":"d8759f16-9be4-403f-a616-a72256d5e4d6","first_update_id":10999770650079,"final_update_id":10999770659499,"previous_final_update_id":10999770649894,"bids":[{"price":"1211.12","quantity":"7.489"},{"price":"1216.12","quantity":"1.792"},{"price":"1231.12","quantity":"0.512"},{"price":"1562.50","quantity":"1.060"},{"price":"1562.51","quantity":"9.008"},{"price":"1701.39","quantity":"32.216"},{"price":"1712.87","quantity":"0.193"},{"price":"1718.09","quantity":"0.000"},{"price":"1718.75","quantity":"151.963"},{"price":"1720.00","quantity":"1507.920"},{"price":"1720.83","quantity":"23.210"},{"price":"1734.18","quantity":"0.070"},{"price":"1734.54","quantity":"17.709"},{"price":"1735.12","quantity":"96.297"},{"price":"1735.35","quantity":"20.776"},{"price":"1735.66","quantity":"0.169"},{"price":"1735.70","quantity":"0.025"},{"price":"1735.74","quantity":"57.898"},{"price":"1735.81","quantity":"6.958"},{"price":"1735.89","quantity":"14.523"},{"price":"1735.92","quantity":"39.475"},{"price":"1735.93","quantity":"0.778"},{"price":"1735.94","quantity":"6.452"},{"price":"1736.00","quantity":"4.479"},{"price":"1736.01","quantity":"22.234"},{"price":"1736.05","quantity":"0.063"},{"price":"1736.06","quantity":"0.026"},{"price":"1736.07","quantity":"0.048"},{"price":"1736.10","quantity":"3.738"},{"price":"1736.11","quantity":"4.307"},{"price":"1736.12","quantity":"113.493"}],"asks":[{"price":"1736.16","quantity":"0.267"},{"price":"1736.18","quantity":"0.130"},{"price":"1736.19","quantity":"0.032"},{"price":"1736.22","quantity":"17.678"},{"price":"1736.27","quantity":"0.314"},{"price":"1736.29","quantity":"1.710"},{"price":"1736.36","quantity":"5.168"},{"price":"1736.39","quantity":"0.098"},{"price":"1736.43","quantity":"56.447"},{"price":"1736.50","quantity":"0.102"},{"price":"1738.66","quantity":"3.806"},{"price":"1781.57","quantity":"0.013"},{"price":"2634.81","quantity":"0.001"},{"price":"2634.82","quantity":"0.001"},{"price":"2634.90","quantity":"0.000"},{"price":"2634.91","quantity":"0.000"}],"raw":{"e":"depthUpdate","E":1783517067682,"T":1783517067681,"s":"ETHUSDT","ps":"ETHUSDT","U":10999770650079,"u":10999770659499,"pu":10999770649894,"b":[["1211.12","7.489"],["1216.12","1.792"],["1231.12","0.512"],["1562.50","1.060"],["1562.51","9.008"],["1701.39","32.216"],["1712.87","0.193"],["1718.09","0.000"],["1718.75","151.963"],["1720.00","1507.920"],["1720.83","23.210"],["1734.18","0.070"],["1734.54","17.709"],["1735.12","96.297"],["1735.35","20.776"],["1735.66","0.169"],["1735.70","0.025"],["1735.74","57.898"],["1735.81","6.958"],["1735.89","14.523"],["1735.92","39.475"],["1735.93","0.778"],["1735.94","6.452"],["1736.00","4.479"],["1736.01","22.234"],["1736.05","0.063"],["1736.06","0.026"],["1736.07","0.048"],["1736.10","3.738"],["1736.11","4.307"],["1736.12","113.493"]],"a":[["1736.16","0.267"],["1736.18","0.130"],["1736.19","0.032"],["1736.22","17.678"],["1736.27","0.314"],["1736.29","1.710"],["1736.36","5.168"],["1736.39","0.098"],["1736.43","56.447"],["1736.50","0.102"],["1738.66","3.806"],["1781.57","0.013"],["2634.81","0.001"],["2634.82","0.001"],["2634.90","0.000"],["2634.91","0.000"]],"st":1}}
{"schema_version":"1.3.0","event_id":"d05a67ac-3d7f-4506-abeb-8c80a43c009c","event_type":"raw.depth_update","source":"binance_market_data_recorder","venue":"binance_usdm","market_type":"perpetual_futures","symbol":"ETHUSDT","event_time_ms":1783517067784,"received_time_ms":1783517067780,"trace_id":"5754bfa1-c7b6-4078-9194-81dba43fff51","first_update_id":10999770659591,"final_update_id":10999770667926,"previous_final_update_id":10999770659499,"bids":[{"price":"200.00","quantity":"7.594"},{"price":"1211.12","quantity":"7.201"},{"price":"1216.12","quantity":"1.536"},{"price":"1231.12","quantity":"1.056"},{"price":"1562.50","quantity":"1.060"},{"price":"1562.51","quantity":"9.008"},{"price":"1666.60","quantity":"1.193"},{"price":"1701.39","quantity":"32.187"},{"price":"1704.85","quantity":"11.997"},{"price":"1718.75","quantity":"169.394"},{"price":"1733.72","quantity":"1.615"},{"price":"1734.84","quantity":"269.416"},{"price":"1734.86","quantity":"39.120"},{"price":"1734.87","quantity":"239.191"},{"price":"1735.17","quantity":"6.739"},{"price":"1735.25","quantity":"0.189"},{"price":"1735.70","quantity":"0.037"},{"price":"1735.79","quantity":"4.440"},{"price":"1735.90","quantity":"11.661"},{"price":"1735.93","quantity":"0.800"},{"price":"1735.94","quantity":"5.006"},{"price":"1736.12","quantity":"113.495"}],"asks":[{"price":"1736.32","quantity":"0.130"},{"price":"1736.50","quantity":"0.114"},{"price":"1736.82","quantity":"26.995"},{"price":"1736.91","quantity":"88.160"},{"price":"1737.13","quantity":"7.142"},{"price":"1737.43","quantity":"8.581"},{"price":"1737.88","quantity":"34.874"},{"price":"1738.70","quantity":"0.197"},{"price":"1738.71","quantity":"35.150"},{"price":"2634.80","quantity":"0.001"},{"price":"2634.89","quantity":"0.000"}],"raw":{"e":"depthUpdate","E":1783517067784,"T":1783517067783,"s":"ETHUSDT","ps":"ETHUSDT","U":10999770659591,"u":10999770667926,"pu":10999770659499,"b":[["200.00","7.594"],["1211.12","7.201"],["1216.12","1.536"],["1231.12","1.056"],["1562.50","1.060"],["1562.51","9.008"],["1666.60","1.193"],["1701.39","32.187"],["1704.85","11.997"],["1718.75","169.394"],["1733.72","1.615"],["1734.84","269.416"],["1734.86","39.120"],["1734.87","239.191"],["1735.17","6.739"],["1735.25","0.189"],["1735.70","0.037"],["1735.79","4.440"],["1735.90","11.661"],["1735.93","0.800"],["1735.94","5.006"],["1736.12","113.495"]],"a":[["1736.32","0.130"],["1736.50","0.114"],["1736.82","26.995"],["1736.91","88.160"],["1737.13","7.142"],["1737.43","8.581"],["1737.88","34.874"],["1738.70","0.197"],["1738.71","35.150"],["2634.80","0.001"],["2634.89","0.000"]],"st":1}}
{"schema_version":"1.3.0","event_id":"eb3e18c4-6b32-4a3e-8e94-9b136c3737dd","event_type":"raw.depth_update","source":"binance_market_data_recorder","venue":"binance_usdm","market_type":"perpetual_futures","symbol":"ETHUSDT","event_time_ms":1783517067886,"received_time_ms":1783517067881,"trace_id":"4bf6566b-542f-4c38-a2a4-a7289d4282af","first_update_id":10999770668098,"final_update_id":10999770676439,"previous_final_update_id":10999770667926,"bids":[{"price":"1211.12","quantity":"6.945"},{"price":"1216.12","quantity":"1.248"},{"price":"1231.12","quantity":"1.600"},{"price":"1562.50","quantity":"1.060"},{"price":"1562.51","quantity":"8.894"},{"price":"1666.60","quantity":"1.078"},{"price":"1684.04","quantity":"35.838"},{"price":"1712.92","quantity":"13.119"},{"price":"1722.23","quantity":"0.020"},{"price":"1733.65","quantity":"428.877"},{"price":"1733.70","quantity":"16.600"},{"price":"1733.72","quantity":"0.169"},{"price":"1733.76","quantity":"94.780"},{"price":"1733.85","quantity":"89.846"},{"price":"1733.86","quantity":"5.287"},{"price":"1734.98","quantity":"289.248"},{"price":"1735.02","quantity":"93.353"},{"price":"1735.03","quantity":"0.065"},{"price":"1735.18","quantity":"0.385"},{"price":"1735.21","quantity":"36.547"},{"price":"1735.22","quantity":"17.353"},{"price":"1735.58","quantity":"0.094"},{"price":"1735.63","quantity":"6.343"},{"price":"1735.77","quantity":"16.201"},{"price":"1736.12","quantity":"115.408"}],"asks":[{"price":"1736.15","quantity":"0.101"},{"price":"1736.18","quantity":"0.041"},{"price":"1736.91","quantity":"84.799"},{"price":"1737.01","quantity":"74.995"},{"price":"1737.37","quantity":"29.259"},{"price":"1737.43","quantity":"0.643"},{"price":"1737.88","quantity":"36.568"},{"price":"1738.00","quantity":"88.971"},{"price":"1738.04","quantity":"1.906"},{"price":"1738.08","quantity":"408.649"},{"price":"1738.13","quantity":"19.864"},{"price":"1738.17","quantity":"7.677"},{"price":"1738.25","quantity":"2.878"},{"price":"1743.10","quantity":"7.467"},{"price":"1747.12","quantity":"15.000"},{"price":"1762.00","quantity":"133.397"},{"price":"1780.00","quantity":"1285.325"},{"price":"1780.29","quantity":"81.353"},{"price":"2634.79","quantity":"0.001"},{"price":"2634.88","quantity":"0.000"}],"raw":{"e":"depthUpdate","E":1783517067886,"T":1783517067885,"s":"ETHUSDT","ps":"ETHUSDT","U":10999770668098,"u":10999770676439,"pu":10999770667926,"b":[["1211.12","6.945"],["1216.12","1.248"],["1231.12","1.600"],["1562.50","1.060"],["1562.51","8.894"],["1666.60","1.078"],["1684.04","35.838"],["1712.92","13.119"],["1722.23","0.020"],["1733.65","428.877"],["1733.70","16.600"],["1733.72","0.169"],["1733.76","94.780"],["1733.85","89.846"],["1733.86","5.287"],["1734.98","289.248"],["1735.02","93.353"],["1735.03","0.065"],["1735.18","0.385"],["1735.21","36.547"],["1735.22","17.353"],["1735.58","0.094"],["1735.63","6.343"],["1735.77","16.201"],["1736.12","115.408"]],"a":[["1736.15","0.101"],["1736.18","0.041"],["1736.91","84.799"],["1737.01","74.995"],["1737.37","29.259"],["1737.43","0.643"],["1737.88","36.568"],["1738.00","88.971"],["1738.04","1.906"],["1738.08","408.649"],["1738.13","19.864"],["1738.17","7.677"],["1738.25","2.878"],["1743.10","7.467"],["1747.12","15.000"],["1762.00","133.397"],["1780.00","1285.325"],["1780.29","81.353"],["2634.79","0.001"],["2634.88","0.000"]],"st":1}}
{"schema_version":"1.3.0","event_id":"2ae7fe9e-d3b7-4d97-b76d-2ce32ea0505c","event_type":"raw.depth_update","source":"binance_market_data_recorder","venue":"binance_usdm","market_type":"perpetual_futures","symbol":"ETHUSDT","event_time_ms":1783517067990,"received_time_ms":1783517067986,"trace_id":"626de289-e674-4eb7-8fcd-307068f1f45f","first_update_id":10999770676599,"final_update_id":10999770685130,"previous_final_update_id":10999770676439,"bids":[{"price":"200.00","quantity":"7.594"},{"price":"1211.12","quantity":"6.689"},{"price":"1216.12","quantity":"0.960"},{"price":"1231.12","quantity":"2.144"},{"price":"1562.50","quantity":"1.060"},{"price":"1562.51","quantity":"8.894"},{"price":"1666.60","quantity":"1.193"},{"price":"1701.39","quantity":"32.216"},{"price":"1730.66","quantity":"16.417"},{"price":"1730.81","quantity":"2.353"},{"price":"1733.65","quantity":"9.919"},{"price":"1733.66","quantity":"23.837"},{"price":"1733.71","quantity":"84.523"},{"price":"1733.76","quantity":"94.780"},{"price":"1733.88","quantity":"463.674"},{"price":"1734.18","quantity":"0.012"},{"price":"1734.57","quantity":"29.409"},{"price":"1734.98","quantity":"69.905"},{"price":"1735.02","quantity":"53.535"},{"price":"1735.12","quantity":"96.297"},{"price":"1736.12","quantity":"115.420"}],"asks":[{"price":"1736.13","quantity":"129.795"},{"price":"1736.32","quantity":"0.130"},{"price":"1736.90","quantity":"40.769"},{"price":"1737.52","quantity":"0.026"},{"price":"1741.42","quantity":"27.631"},{"price":"1741.64","quantity":"23.317"},{"price":"1769.11","quantity":"15.393"},{"price":"2634.77","quantity":"0.001"},{"price":"2634.78","quantity":"0.022"},{"price":"2634.86","quantity":"0.000"},{"price":"2634.87","quantity":"0.000"}],"raw":{"e":"depthUpdate","E":1783517067990,"T":1783517067989,"s":"ETHUSDT","ps":"ETHUSDT","U":10999770676599,"u":10999770685130,"pu":10999770676439,"b":[["200.00","7.594"],["1211.12","6.689"],["1216.12","0.960"],["1231.12","2.144"],["1562.50","1.060"],["1562.51","8.894"],["1666.60","1.193"],["1701.39","32.216"],["1730.66","16.417"],["1730.81","2.353"],["1733.65","9.919"],["1733.66","23.837"],["1733.71","84.523"],["1733.76","94.780"],["1733.88","463.674"],["1734.18","0.012"],["1734.57","29.409"],["1734.98","69.905"],["1735.02","53.535"],["1735.12","96.297"],["1736.12","115.420"]],"a":[["1736.13","129.795"],["1736.32","0.130"],["1736.90","40.769"],["1737.52","0.026"],["1741.42","27.631"],["1741.64","23.317"],["1769.11","15.393"],["2634.77","0.001"],["2634.78","0.022"],["2634.86","0.000"],["2634.87","0.000"]],"st":1}}
{"schema_version":"1.3.0","event_id":"a841c3d0-0a27-45a0-ba59-52d272a51766","event_type":"raw.depth_update","source":"binance_market_data_recorder","venue":"binance_usdm","market_type":"perpetual_futures","symbol":"ETHUSDT","event_time_ms":1783517068092,"received_time_ms":1783517068247,"trace_id":"846d6c94-497c-408f-9b57-4c7d33a0bf44","first_update_id":10999770685188,"final_update_id":10999770697543,"previous_final_update_id":10999770685130,"bids":[{"price":"200.00","quantity":"7.594"},{"price":"1211.11","quantity":"0.069"},{"price":"1211.12","quantity":"6.369"},{"price":"1216.12","quantity":"0.704"},{"price":"1231.11","quantity":"0.096"},{"price":"1231.12","quantity":"2.592"},{"price":"1236.11","quantity":"0.315"},{"price":"1562.04","quantity":"0.154"},{"price":"1562.49","quantity":"0.026"},{"price":"1562.50","quantity":"1.162"},{"price":"1562.51","quantity":"5.708"},{"price":"1666.60","quantity":"1.078"},{"price":"1695.52","quantity":"0.465"},{"price":"1701.39","quantity":"32.187"},{"price":"1701.40","quantity":"20.919"},{"price":"1704.97","quantity":"29.286"},{"price":"1730.55","quantity":"5.326"},{"price":"1732.10","quantity":"10.440"},{"price":"1732.26","quantity":"20.837"},{"price":"1733.50","quantity":"13.855"},{"price":"1733.65","quantity":"428.877"},{"price":"1733.66","quantity":"82.471"},{"price":"1733.71","quantity":"85.969"},{"price":"1733.72","quantity":"3.365"},{"price":"1733.76","quantity":"35.799"},{"price":"1733.85","quantity":"88.400"},{"price":"1733.86","quantity":"2.091"},{"price":"1733.88","quantity":"44.716"},{"price":"1733.89","quantity":"0.765"},{"price":"1733.94","quantity":"29.283"},{"price":"1734.15","quantity":"0.778"},{"price":"1734.32","quantity":"11.730"},{"price":"1734.44","quantity":"56.236"},{"price":"1734.56","quantity":"3.962"},{"price":"1734.57","quantity":"29.409"},{"price":"1734.68","quantity":"8.509"},{"price":"1734.73","quantity":"316.159"},{"price":"1734.74","quantity":"11.549"},{"price":"1734.78","quantity":"0.444"},{"price":"1734.83","quantity":"6.893"},{"price":"1734.86","quantity":"38.717"},{"price":"1734.87","quantity":"19.838"},{"price":"1734.88","quantity":"59.476"},{"price":"1734.91","quantity":"1.346"},{"price":"1734.92","quantity":"62.428"},{"price":"1734.93","quantity":"68.155"},{"price":"1734.95","quantity":"8.820"},{"price":"1735.00","quantity":"216.833"},{"price":"1735.02","quantity":"53.535"},{"price":"1735.08","quantity":"7.016"},{"price":"1735.12","quantity":"95.456"},{"price":"1735.16","quantity":"4.709"},{"price":"1735.18","quantity":"0.559"},{"price":"1735.20","quantity":"46.708"},{"price":"1735.21","quantity":"35.605"},{"price":"1735.22","quantity":"18.363"},{"price":"1735.23","quantity":"43.841"},{"price":"1735.25","quantity":"0.169"},{"price":"1735.26","quantity":"0.209"},{"price":"1735.27","quantity":"68.102"},{"price":"1735.28","quantity":"4.962"},{"price":"1735.30","quantity":"29.159"},{"price":"1735.34","quantity":"0.110"},{"price":"1735.35","quantity":"17.788"},{"price":"1735.37","quantity":"3.595"},{"price":"1735.43","quantity":"4.390"},{"price":"1735.47","quantity":"16.796"},{"price":"1735.52","quantity":"77.961"},{"price":"1735.53","quantity":"8.517"},{"price":"1735.54","quantity":"0.027"},{"price":"1735.56","quantity":"27.796"},{"price":"1735.61","quantity":"8.774"},{"price":"1735.63","quantity":"6.343"},{"price":"1735.64","quantity":"76.667"},{"price":"1735.65","quantity":"20.560"},{"price":"1735.67","quantity":"0.051"},{"price":"1735.68","quantity":"35.169"},{"price":"1735.69","quantity":"4.774"},{"price":"1735.70","quantity":"28.871"},{"price":"1735.71","quantity":"0.050"},{"price":"1735.73","quantity":"27.850"},{"price":"1735.74","quantity":"29.064"},{"price":"1735.76","quantity":"11.833"},{"price":"1735.77","quantity":"10.978"},{"price":"1735.79","quantity":"4.333"},{"price":"1735.82","quantity":"0.842"},{"price":"1735.86","quantity":"1.436"},{"price":"1735.87","quantity":"1.157"},{"price":"1735.88","quantity":"67.266"},{"price":"1735.89","quantity":"14.235"},{"price":"1735.90","quantity":"4.012"},{"price":"1735.91","quantity":"14.267"},{"price":"1735.92","quantity":"35.165"},{"price":"1735.93","quantity":"0.800"},{"price":"1735.94","quantity":"3.854"},{"price":"1735.95","quantity":"2.436"},{"price":"1735.96","quantity":"2.280"},{"price":"1735.98","quantity":"1.214"},{"price":"1735.99","quantity":"0.052"},{"price":"1736.00","quantity":"26.663"},{"price":"1736.01","quantity":"0.050"},{"price":"1736.03","quantity":"1.134"},{"price":"1736.04","quantity":"0.012"},{"price":"1736.05","quantity":"0.051"},{"price":"1736.06","quantity":"0.014"},{"price":"1736.07","quantity":"0.042"},{"price":"1736.08","quantity":"0.730"},{"price":"1736.09","quantity":"0.930"},{"price":"1736.10","quantity":"3.753"},{"price":"1736.11","quantity":"105.448"},{"price":"1736.12","quantity":"0.000"}],"asks":[{"price":"1736.12","quantity":"304.261"},{"price":"1736.13","quantity":"10.898"},{"price":"1736.14","quantity":"0.040"},{"price":"1736.15","quantity":"0.012"},{"price":"1736.16","quantity":"0.279"},{"price":"1736.17","quantity":"1.764"},{"price":"1736.20","quantity":"3.980"},{"price":"1736.21","quantity":"0.032"},{"price":"1736.22","quantity":"20.900"},{"price":"1736.24","quantity":"0.617"},{"price":"1736.26","quantity":"13.609"},{"price":"1736.27","quantity":"0.314"},{"price":"1736.28","quantity":"40.972"},{"price":"1736.31","quantity":"22.927"},{"price":"1736.33","quantity":"1.712"},{"price":"1736.34","quantity":"67.271"},{"price":"1736.36","quantity":"5.168"},{"price":"1736.38","quantity":"0.278"},{"price":"1736.39","quantity":"0.098"},{"price":"1736.40","quantity":"21.386"},{"price":"1736.41","quantity":"9.508"},{"price":"1736.42","quantity":"7.578"},{"price":"1736.43","quantity":"49.743"},{"price":"1736.46","quantity":"37.917"},{"price":"1736.47","quantity":"2.139"},{"price":"1736.48","quantity":"12.772"},{"price":"1736.49","quantity":"2.992"},{"price":"1736.50","quantity":"1.814"},{"price":"1736.56","quantity":"18.977"},{"price":"1736.84","quantity":"5.069"},{"price":"1736.95","quantity":"0.434"},{"price":"1736.99","quantity":"21.442"},{"price":"1737.01","quantity":"77.995"},{"price":"1737.02","quantity":"25.859"},{"price":"1737.05","quantity":"0.797"},{"price":"1737.13","quantity":"7.142"},{"price":"1737.16","quantity":"11.330"},{"price":"1737.17","quantity":"1.527"},{"price":"1737.18","quantity":"23.455"},{"price":"1737.21","quantity":"0.022"},{"price":"1737.22","quantity":"5.290"},{"price":"1737.25","quantity":"71.600"},{"price":"1737.34","quantity":"17.549"},{"price":"1737.36","quantity":"68.335"},{"price":"1737.38","quantity":"87.911"},{"price":"1737.42","quantity":"6.315"},{"price":"1737.51","quantity":"0.218"},{"price":"1737.52","quantity":"0.026"},{"price":"1737.55","quantity":"38.237"},{"price":"1737.61","quantity":"10.320"},{"price":"1737.86","quantity":"2.288"},{"price":"1737.94","quantity":"0.012"},{"price":"1738.00","quantity":"30.118"},{"price":"1738.04","quantity":"0.239"},{"price":"1738.08","quantity":"1.684"},{"price":"1738.15","quantity":"14.723"},{"price":"1738.36","quantity":"81.145"},{"price":"1738.38","quantity":"407.011"},{"price":"1738.39","quantity":"18.325"},{"price":"1738.56","quantity":"1.984"},{"price":"1738.64","quantity":"11.058"},{"price":"1738.78","quantity":"7.305"},{"price":"1738.88","quantity":"1.079"},{"price":"1738.89","quantity":"56.549"},{"price":"1738.91","quantity":"0.345"},{"price":"1738.94","quantity":"3.960"},{"price":"1738.96","quantity":"0.000"},{"price":"1739.20","quantity":"8.656"},{"price":"1739.27","quantity":"7.087"},{"price":"1739.36","quantity":"3.344"},{"price":"1739.42","quantity":"17.925"},{"price":"1739.60","quantity":"38.666"},{"price":"1739.61","quantity":"20.766"},{"price":"1740.16","quantity":"19.743"},{"price":"1740.47","quantity":"21.804"},{"price":"1740.48","quantity":"17.056"},{"price":"1740.58","quantity":"18.016"},{"price":"1741.33","quantity":"2.652"},{"price":"1741.34","quantity":"16.480"},{"price":"1742.20","quantity":"8.201"},{"price":"1742.21","quantity":"50.659"},{"price":"1743.07","quantity":"18.540"},{"price":"1743.08","quantity":"4.747"},{"price":"1747.12","quantity":"0.000"},{"price":"1835.74","quantity":"0.000"},{"price":"1835.77","quantity":"0.083"},{"price":"1835.78","quantity":"0.019"},{"price":"1836.12","quantity":"0.163"},{"price":"2634.75","quantity":"0.001"},{"price":"2634.76","quantity":"0.001"},{"price":"2634.84","quantity":"0.398"},{"price":"2634.85","quantity":"0.000"}],"raw":{"e":"depthUpdate","E":1783517068092,"T":1783517068091,"s":"ETHUSDT","ps":"ETHUSDT","U":10999770685188,"u":10999770697543,"pu":10999770685130,"b":[["200.00","7.594"],["1211.11","0.069"],["1211.12","6.369"],["1216.12","0.704"],["1231.11","0.096"],["1231.12","2.592"],["1236.11","0.315"],["1562.04","0.154"],["1562.49","0.026"],["1562.50","1.162"],["1562.51","5.708"],["1666.60","1.078"],["1695.52","0.465"],["1701.39","32.187"],["1701.40","20.919"],["1704.97","29.286"],["1730.55","5.326"],["1732.10","10.440"],["1732.26","20.837"],["1733.50","13.855"],["1733.65","428.877"],["1733.66","82.471"],["1733.71","85.969"],["1733.72","3.365"],["1733.76","35.799"],["1733.85","88.400"],["1733.86","2.091"],["1733.88","44.716"],["1733.89","0.765"],["1733.94","29.283"],["1734.15","0.778"],["1734.32","11.730"],["1734.44","56.236"],["1734.56","3.962"],["1734.57","29.409"],["1734.68","8.509"],["1734.73","316.159"],["1734.74","11.549"],["1734.78","0.444"],["1734.83","6.893"],["1734.86","38.717"],["1734.87","19.838"],["1734.88","59.476"],["1734.91","1.346"],["1734.92","62.428"],["1734.93","68.155"],["1734.95","8.820"],["1735.00","216.833"],["1735.02","53.535"],["1735.08","7.016"],["1735.12","95.456"],["1735.16","4.709"],["1735.18","0.559"],["1735.20","46.708"],["1735.21","35.605"],["1735.22","18.363"],["1735.23","43.841"],["1735.25","0.169"],["1735.26","0.209"],["1735.27","68.102"],["1735.28","4.962"],["1735.30","29.159"],["1735.34","0.110"],["1735.35","17.788"],["1735.37","3.595"],["1735.43","4.390"],["1735.47","16.796"],["1735.52","77.961"],["1735.53","8.517"],["1735.54","0.027"],["1735.56","27.796"],["1735.61","8.774"],["1735.63","6.343"],["1735.64","76.667"],["1735.65","20.560"],["1735.67","0.051"],["1735.68","35.169"],["1735.69","4.774"],["1735.70","28.871"],["1735.71","0.050"],["1735.73","27.850"],["1735.74","29.064"],["1735.76","11.833"],["1735.77","10.978"],["1735.79","4.333"],["1735.82","0.842"],["1735.86","1.436"],["1735.87","1.157"],["1735.88","67.266"],["1735.89","14.235"],["1735.90","4.012"],["1735.91","14.267"],["1735.92","35.165"],["1735.93","0.800"],["1735.94","3.854"],["1735.95","2.436"],["1735.96","2.280"],["1735.98","1.214"],["1735.99","0.052"],["1736.00","26.663"],["1736.01","0.050"],["1736.03","1.134"],["1736.04","0.012"],["1736.05","0.051"],["1736.06","0.014"],["1736.07","0.042"],["1736.08","0.730"],["1736.09","0.930"],["1736.10","3.753"],["1736.11","105.448"],["1736.12","0.000"]],"a":[["1736.12","304.261"],["1736.13","10.898"],["1736.14","0.040"],["1736.15","0.012"],["1736.16","0.279"],["1736.17","1.764"],["1736.20","3.980"],["1736.21","0.032"],["1736.22","20.900"],["1736.24","0.617"],["1736.26","13.609"],["1736.27","0.314"],["1736.28","40.972"],["1736.31","22.927"],["1736.33","1.712"],["1736.34","67.271"],["1736.36","5.168"],["1736.38","0.278"],["1736.39","0.098"],["1736.40","21.386"],["1736.41","9.508"],["1736.42","7.578"],["1736.43","49.743"],["1736.46","37.917"],["1736.47","2.139"],["1736.48","12.772"],["1736.49","2.992"],["1736.50","1.814"],["1736.56","18.977"],["1736.84","5.069"],["1736.95","0.434"],["1736.99","21.442"],["1737.01","77.995"],["1737.02","25.859"],["1737.05","0.797"],["1737.13","7.142"],["1737.16","11.330"],["1737.17","1.527"],["1737.18","23.455"],["1737.21","0.022"],["1737.22","5.290"],["1737.25","71.600"],["1737.34","17.549"],["1737.36","68.335"],["1737.38","87.911"],["1737.42","6.315"],["1737.51","0.218"],["1737.52","0.026"],["1737.55","38.237"],["1737.61","10.320"],["1737.86","2.288"],["1737.94","0.012"],["1738.00","30.118"],["1738.04","0.239"],["1738.08","1.684"],["1738.15","14.723"],["1738.36","81.145"],["1738.38","407.011"],["1738.39","18.325"],["1738.56","1.984"],["1738.64","11.058"],["1738.78","7.305"],["1738.88","1.079"],["1738.89","56.549"],["1738.91","0.345"],["1738.94","3.960"],["1738.96","0.000"],["1739.20","8.656"],["1739.27","7.087"],["1739.36","3.344"],["1739.42","17.925"],["1739.60","38.666"],["1739.61","20.766"],["1740.16","19.743"],["1740.47","21.804"],["1740.48","17.056"],["1740.58","18.016"],["1741.33","2.652"],["1741.34","16.480"],["1742.20","8.201"],["1742.21","50.659"],["1743.07","18.540"],["1743.08","4.747"],["1747.12","0.000"],["1835.74","0.000"],["1835.77","0.083"],["1835.78","0.019"],["1836.12","0.163"],["2634.75","0.001"],["2634.76","0.001"],["2634.84","0.398"],["2634.85","0.000"]],"st":1}}
{"schema_version":"1.3.0","event_id":"301e2921-4855-4829-a51f-b778931ac938","event_type":"raw.depth_update","source":"binance_market_data_recorder","venue":"binance_usdm","market_type":"perpetual_futures","symbol":"ETHUSDT","event_time_ms":1783517068194,"received_time_ms":1783517068261,"trace_id":"26f0d0d1-a370-4f39-aa56-b2ee59673937","first_update_id":10999770697550,"final_update_id":10999770707218,"previous_final_update_id":10999770697543,"bids":[{"price":"1211.11","quantity":"0.357"},{"price":"1211.12","quantity":"5.825"},{"price":"1216.12","quantity":"0.416"},{"price":"1231.11","quantity":"0.640"},{"price":"1562.49","quantity":"0.026"},{"price":"1562.50","quantity":"1.546"},{"price":"1701.39","quantity":"32.216"},{"price":"1732.77","quantity":"76.302"},{"price":"1733.65","quantity":"9.919"},{"price":"1733.71","quantity":"504.927"},{"price":"1734.66","quantity":"12.726"},{"price":"1734.72","quantity":"223.510"},{"price":"1734.73","quantity":"97.067"},{"price":"1734.74","quantity":"11.949"},{"price":"1735.00","quantity":"223.240"},{"price":"1735.11","quantity":"45.389"},{"price":"1735.12","quantity":"95.441"},{"price":"1735.15","quantity":"6.663"},{"price":"1735.16","quantity":"8.164"},{"price":"1735.17","quantity":"3.284"},{"price":"1735.18","quantity":"0.982"},{"price":"1735.31","quantity":"33.996"},{"price":"1735.34","quantity":"0.098"},{"price":"1735.35","quantity":"21.053"},{"price":"1735.44","quantity":"27.914"},{"price":"1735.55","quantity":"6.304"},{"price":"1735.73","quantity":"26.150"},{"price":"1735.79","quantity":"3.983"},{"price":"1735.88","quantity":"75.933"},{"price":"1735.89","quantity":"13.995"},{"price":"1735.90","quantity":"2.994"},{"price":"1735.91","quantity":"9.957"},{"price":"1735.97","quantity":"25.279"},{"price":"1736.00","quantity":"7.910"},{"price":"1736.04","quantity":"0.024"},{"price":"1736.05","quantity":"0.063"},{"price":"1736.06","quantity":"0.026"},{"price":"1736.07","quantity":"0.059"},{"price":"1736.10","quantity":"3.741"},{"price":"1736.11","quantity":"105.628"}],"asks":[{"price":"1736.12","quantity":"298.719"},{"price":"1736.13","quantity":"9.651"},{"price":"1736.15","quantity":"0.024"},{"price":"1736.18","quantity":"0.053"},{"price":"1736.25","quantity":"4.477"},{"price":"1736.29","quantity":"1.210"},{"price":"1736.30","quantity":"13.550"},{"price":"1736.31","quantity":"22.895"},{"price":"1736.32","quantity":"0.143"},{"price":"1736.33","quantity":"1.735"},{"price":"1736.34","quantity":"67.289"},{"price":"1736.36","quantity":"5.180"},{"price":"1736.40","quantity":"21.369"},{"price":"1736.42","quantity":"10.075"},{"price":"1736.50","quantity":"0.114"},{"price":"1736.68","quantity":"6.405"},{"price":"1736.81","quantity":"22.200"},{"price":"1736.89","quantity":"9.582"},{"price":"1737.16","quantity":"17.090"},{"price":"1737.35","quantity":"43.850"},{"price":"1737.51","quantity":"14.378"},{"price":"1737.55","quantity":"37.237"},{"price":"1737.86","quantity":"5.136"},{"price":"1737.94","quantity":"1.679"},{"price":"1737.95","quantity":"86.265"},{"price":"1738.19","quantity":"423.285"},{"price":"1738.38","quantity":"0.046"},{"price":"1738.89","quantity":"59.745"},{"price":"1739.42","quantity":"20.408"},{"price":"1740.62","quantity":"1.223"},{"price":"1744.82","quantity":"0.066"},{"price":"1774.55","quantity":"0.038"},{"price":"2634.74","quantity":"0.001"},{"price":"2634.83","quantity":"0.000"}],"raw":{"e":"depthUpdate","E":1783517068194,"T":1783517068193,"s":"ETHUSDT","ps":"ETHUSDT","U":10999770697550,"u":10999770707218,"pu":10999770697543,"b":[["1211.11","0.357"],["1211.12","5.825"],["1216.12","0.416"],["1231.11","0.640"],["1562.49","0.026"],["1562.50","1.546"],["1701.39","32.216"],["1732.77","76.302"],["1733.65","9.919"],["1733.71","504.927"],["1734.66","12.726"],["1734.72","223.510"],["1734.73","97.067"],["1734.74","11.949"],["1735.00","223.240"],["1735.11","45.389"],["1735.12","95.441"],["1735.15","6.663"],["1735.16","8.164"],["1735.17","3.284"],["1735.18","0.982"],["1735.31","33.996"],["1735.34","0.098"],["1735.35","21.053"],["1735.44","27.914"],["1735.55","6.304"],["1735.73","26.150"],["1735.79","3.983"],["1735.88","75.933"],["1735.89","13.995"],["1735.90","2.994"],["1735.91","9.957"],["1735.97","25.279"],["1736.00","7.910"],["1736.04","0.024"],["1736.05","0.063"],["1736.06","0.026"],["1736.07","0.059"],["1736.10","3.741"],["1736.11","105.628"]],"a":[["1736.12","298.719"],["1736.13","9.651"],["1736.15","0.024"],["1736.18","0.053"],["1736.25","4.477"],["1736.29","1.210"],["1736.30","13.550"],["1736.31","22.895"],["1736.32","0.143"],["1736.33","1.735"],["1736.34","67.289"],["1736.36","5.180"],["1736.40","21.369"],["1736.42","10.075"],["1736.50","0.114"],["1736.68","6.405"],["1736.81","22.200"],["1736.89","9.582"],["1737.16","17.090"],["1737.35","43.850"],["1737.51","14.378"],["1737.55","37.237"],["1737.86","5.136"],["1737.94","1.679"],["1737.95","86.265"],["1738.19","423.285"],["1738.38","0.046"],["1738.89","59.745"],["1739.42","20.408"],["1740.62","1.223"],["1744.82","0.066"],["1774.55","0.038"],["2634.74","0.001"],["2634.83","0.000"]],"st":1}}
{"schema_version":"1.3.0","event_id":"e2f8ca9e-d465-43f9-93da-21245ea4567b","event_type":"raw.depth_update","source":"binance_market_data_recorder","venue":"binance_usdm","market_type":"perpetual_futures","symbol":"ETHUSDT","event_time_ms":1783517068298,"received_time_ms":1783517068292,"trace_id":"ce0066c5-e036-449a-b751-1961f2ab4f8d","first_update_id":10999770707369,"final_update_id":10999770716754,"previous_final_update_id":10999770707218,"bids":[{"price":"200.00","quantity":"7.594"},{"price":"1211.11","quantity":"0.613"},{"price":"1211.12","quantity":"5.249"},{"price":"1216.12","quantity":"0.160"},{"price":"1231.11","quantity":"1.216"},{"price":"1562.49","quantity":"0.026"},{"price":"1562.50","quantity":"2.186"},{"price":"1666.60","quantity":"1.193"},{"price":"1684.88","quantity":"106.260"},{"price":"1701.39","quantity":"32.187"},{"price":"1704.65","quantity":"1.906"},{"price":"1710.34","quantity":"116.832"},{"price":"1727.42","quantity":"0.629"},{"price":"1733.66","quantity":"23.837"},{"price":"1733.71","quantity":"84.523"},{"price":"1733.72","quantity":"0.169"},{"price":"1733.74","quantity":"19.608"},{"price":"1733.76","quantity":"95.473"},{"price":"1733.82","quantity":"421.533"},{"price":"1734.72","quantity":"2.933"},{"price":"1734.84","quantity":"490.019"},{"price":"1734.89","quantity":"0.168"},{"price":"1735.00","quantity":"217.480"},{"price":"1735.13","quantity":"3.144"},{"price":"1735.23","quantity":"4.905"},{"price":"1735.30","quantity":"68.094"},{"price":"1735.35","quantity":"18.173"},{"price":"1735.82","quantity":"0.866"},{"price":"1735.89","quantity":"16.299"},{"price":"1735.90","quantity":"2.994"},{"price":"1735.95","quantity":"1.284"},{"price":"1736.11","quantity":"122.095"}],"asks":[{"price":"1736.17","quantity":"0.036"},{"price":"1736.19","quantity":"0.012"},{"price":"1736.25","quantity":"3.977"},{"price":"1736.27","quantity":"0.814"},{"price":"1736.40","quantity":"21.538"},{"price":"1736.42","quantity":"10.157"},{"price":"1736.55","quantity":"31.365"},{"price":"1736.64","quantity":"76.115"},{"price":"1736.81","quantity":"19.320"},{"price":"1737.16","quantity":"11.330"},{"price":"1737.51","quantity":"2.858"},{"price":"1738.17","quantity":"67.763"},{"price":"1738.36","quantity":"23.590"},{"price":"1740.63","quantity":"1.411"},{"price":"1744.82","quantity":"0.054"},{"price":"1747.75","quantity":"9.020"},{"price":"1747.76","quantity":"37.449"},{"price":"1747.77","quantity":"0.000"},{"price":"1781.63","quantity":"0.369"},{"price":"2634.72","quantity":"0.001"},{"price":"2634.73","quantity":"0.021"},{"price":"2634.81","quantity":"0.000"},{"price":"2634.82","quantity":"0.000"}],"raw":{"e":"depthUpdate","E":1783517068298,"T":1783517068297,"s":"ETHUSDT","ps":"ETHUSDT","U":10999770707369,"u":10999770716754,"pu":10999770707218,"b":[["200.00","7.594"],["1211.11","0.613"],["1211.12","5.249"],["1216.12","0.160"],["1231.11","1.216"],["1562.49","0.026"],["1562.50","2.186"],["1666.60","1.193"],["1684.88","106.260"],["1701.39","32.187"],["1704.65","1.906"],["1710.34","116.832"],["1727.42","0.629"],["1733.66","23.837"],["1733.71","84.523"],["1733.72","0.169"],["1733.74","19.608"],["1733.76","95.473"],["1733.82","421.533"],["1734.72","2.933"],["1734.84","490.019"],["1734.89","0.168"],["1735.00","217.480"],["1735.13","3.144"],["1735.23","4.905"],["1735.30","68.094"],["1735.35","18.173"],["1735.82","0.866"],["1735.89","16.299"],["1735.90","2.994"],["1735.95","1.284"],["1736.11","122.095"]],"a":[["1736.17","0.036"],["1736.19","0.012"],["1736.25","3.977"],["1736.27","0.814"],["1736.40","21.538"],["1736.42","10.157"],["1736.55","31.365"],["1736.64","76.115"],["1736.81","19.320"],["1737.16","11.330"],["1737.51","2.858"],["1738.17","67.763"],["1738.36","23.590"],["1740.63","1.411"],["1744.82","0.054"],["1747.75","9.020"],["1747.76","37.449"],["1747.77","0.000"],["1781.63","0.369"],["2634.72","0.001"],["2634.73","0.021"],["2634.81","0.000"],["2634.82","0.000"]],"st":1}}
{"schema_version":"1.3.0","event_id":"315566b2-9364-45d1-8979-ba25c5b755de","event_type":"raw.depth_update","source":"binance_market_data_recorder","venue":"binance_usdm","market_type":"perpetual_futures","symbol":"ETHUSDT","event_time_ms":1783517068400,"received_time_ms":1783517068395,"trace_id":"2d5a85c6-fe32-4613-b22c-8243eb3c5aa4","first_update_id":10999770716849,"final_update_id":10999770725639,"previous_final_update_id":10999770716754,"bids":[{"price":"200.00","quantity":"7.594"},{"price":"1211.11","quantity":"0.773"},{"price":"1211.12","quantity":"4.609"},{"price":"1216.12","quantity":"0.000"},{"price":"1231.11","quantity":"1.856"},{"price":"1562.49","quantity":"0.026"},{"price":"1562.50","quantity":"2.840"},{"price":"1666.60","quantity":"1.078"},{"price":"1698.08","quantity":"5.889"},{"price":"1703.81","quantity":"0.284"},{"price":"1719.04","quantity":"5.845"},{"price":"1719.95","quantity":"0.000"},{"price":"1720.51","quantity":"429.909"},{"price":"1727.42","quantity":"0.641"},{"price":"1732.09","quantity":"40.542"},{"price":"1732.17","quantity":"144.024"},{"price":"1732.43","quantity":"0.105"},{"price":"1732.50","quantity":"23.728"},{"price":"1733.50","quantity":"10.855"},{"price":"1733.59","quantity":"22.671"},{"price":"1733.66","quantity":"23.837"},{"price":"1733.70","quantity":"16.600"},{"price":"1733.74","quantity":"19.608"},{"price":"1733.76","quantity":"95.257"},{"price":"1733.82","quantity":"2.575"},{"price":"1733.83","quantity":"2.008"},{"price":"1733.88","quantity":"463.674"},{"price":"1734.32","quantity":"11.558"},{"price":"1734.66","quantity":"1.206"},{"price":"1734.74","quantity":"232.581"},{"price":"1734.80","quantity":"11.203"},{"price":"1734.81","quantity":"19.312"},{"price":"1734.84","quantity":"269.416"},{"price":"1735.07","quantity":"6.117"},{"price":"1735.21","quantity":"33.697"},{"price":"1735.22","quantity":"17.409"},{"price":"1735.24","quantity":"7.546"},{"price":"1735.82","quantity":"0.842"},{"price":"1735.90","quantity":"2.994"},{"price":"1735.97","quantity":"25.567"},{"price":"1736.11","quantity":"104.558"}],"asks":[{"price":"1736.12","quantity":"293.382"},{"price":"1736.27","quantity":"0.026"},{"price":"1736.29","quantity":"1.998"},{"price":"1736.31","quantity":"22.895"},{"price":"1736.91","quantity":"68.123"},{"price":"1737.01","quantity":"79.981"},{"price":"1737.02","quantity":"24.439"},{"price":"1737.03","quantity":"83.757"},{"price":"1737.12","quantity":"7.826"},{"price":"1737.13","quantity":"7.127"},{"price":"1737.34","quantity":"14.909"},{"price":"1737.68","quantity":"17.646"},{"price":"1739.98","quantity":"32.614"},{"price":"1739.99","quantity":"144.299"},{"price":"1740.24","quantity":"29.962"},{"price":"1740.26","quantity":"16.353"},{"price":"1745.04","quantity":"0.390"},{"price":"1745.15","quantity":"0.074"},{"price":"1747.12","quantity":"15.000"},{"price":"1748.17","quantity":"0.319"},{"price":"1748.28","quantity":"0.000"},{"price":"1770.15","quantity":"15.234"},{"price":"2634.70","quantity":"0.001"},{"price":"2634.71","quantity":"0.001"},{"price":"2634.79","quantity":"0.000"},{"price":"2634.80","quantity":"0.000"}],"raw":{"e":"depthUpdate","E":1783517068400,"T":1783517068397,"s":"ETHUSDT","ps":"ETHUSDT","U":10999770716849,"u":10999770725639,"pu":10999770716754,"b":[["200.00","7.594"],["1211.11","0.773"],["1211.12","4.609"],["1216.12","0.000"],["1231.11","1.856"],["1562.49","0.026"],["1562.50","2.840"],["1666.60","1.078"],["1698.08","5.889"],["1703.81","0.284"],["1719.04","5.845"],["1719.95","0.000"],["1720.51","429.909"],["1727.42","0.641"],["1732.09","40.542"],["1732.17","144.024"],["1732.43","0.105"],["1732.50","23.728"],["1733.50","10.855"],["1733.59","22.671"],["1733.66","23.837"],["1733.70","16.600"],["1733.74","19.608"],["1733.76","95.257"],["1733.82","2.575"],["1733.83","2.008"],["1733.88","463.674"],["1734.32","11.558"],["1734.66","1.206"],["1734.74","232.581"],["1734.80","11.203"],["1734.81","19.312"],["1734.84","269.416"],["1735.07","6.117"],["1735.21","33.697"],["1735.22","17.409"],["1735.24","7.546"],["1735.82","0.842"],["1735.90","2.994"],["1735.97","25.567"],["1736.11","104.558"]],"a":[["1736.12","293.382"],["1736.27","0.026"],["1736.29","1.998"],["1736.31","22.895"],["1736.91","68.123"],["1737.01","79.981"],["1737.02","24.439"],["1737.03","83.757"],["1737.12","7.826"],["1737.13","7.127"],["1737.34","14.909"],["1737.68","17.646"],["1739.98","32.614"],["1739.99","144.299"],["1740.24","29.962"],["1740.26","16.353"],["1745.04","0.390"],["1745.15","0.074"],["1747.12","15.000"],["1748.17","0.319"],["1748.28","0.000"],["1770.15","15.234"],["2634.70","0.001"],["2634.71","0.001"],["2634.79","0.000"],["2634.80","0.000"]],"st":1}}
{"schema_version":"1.3.0","event_id":"fe155708-a4ca-4119-b302-e65f22375242","event_type":"raw.depth_update","source":"binance_market_data_recorder","venue":"binance_usdm","market_type":"perpetual_futures","symbol":"ETHUSDT","event_time_ms":1783517068502,"received_time_ms":1783517068496,"trace_id":"87727928-4d59-4066-9968-c8d2997bcb04","first_update_id":10999770725989,"final_update_id":10999770732928,"previous_final_update_id":10999770725639,"bids":[{"price":"201.00","quantity":"2.400"},{"price":"1211.12","quantity":"3.777"},{"price":"1231.11","quantity":"2.688"},{"price":"1562.49","quantity":"0.026"},{"price":"1562.50","quantity":"3.480"},{"price":"1666.60","quantity":"1.193"},{"price":"1701.38","quantity":"43.670"},{"price":"1709.04","quantity":"49.318"},{"price":"1733.74","quantity":"16.412"},{"price":"1733.76","quantity":"35.799"},{"price":"1733.83","quantity":"0.562"},{"price":"1733.88","quantity":"44.716"},{"price":"1733.89","quantity":"0.765"},{"price":"1733.94","quantity":"29.283"},{"price":"1733.95","quantity":"5.388"},{"price":"1734.06","quantity":"473.139"},{"price":"1734.12","quantity":"111.427"},{"price":"1734.62","quantity":"340.024"},{"price":"1734.63","quantity":"53.475"},{"price":"1734.74","quantity":"11.949"},{"price":"1735.11","quantity":"45.389"},{"price":"1735.90","quantity":"2.994"},{"price":"1736.11","quantity":"100.765"}],"asks":[{"price":"1736.33","quantity":"1.735"},{"price":"1736.37","quantity":"7.833"},{"price":"1736.44","quantity":"9.416"},{"price":"1736.49","quantity":"2.851"},{"price":"1736.63","quantity":"8.821"},{"price":"1736.89","quantity":"8.141"},{"price":"1737.35","quantity":"17.720"},{"price":"1737.42","quantity":"3.675"},{"price":"1738.13","quantity":"78.702"},{"price":"1738.14","quantity":"423.260"},{"price":"1738.17","quantity":"7.677"},{"price":"1738.19","quantity":"16.320"},{"price":"1738.64","quantity":"7.862"},{"price":"1739.42","quantity":"30.137"},{"price":"1740.58","quantity":"8.287"},{"price":"1764.65","quantity":"0.034"},{"price":"1771.88","quantity":"36.427"},{"price":"1776.79","quantity":"28.045"},{"price":"1780.32","quantity":"81.351"},{"price":"2634.69","quantity":"0.001"},{"price":"2634.78","quantity":"0.021"}],"raw":{"e":"depthUpdate","E":1783517068502,"T":1783517068501,"s":"ETHUSDT","ps":"ETHUSDT","U":10999770725989,"u":10999770732928,"pu":10999770725639,"b":[["201.00","2.400"],["1211.12","3.777"],["1231.11","2.688"],["1562.49","0.026"],["1562.50","3.480"],["1666.60","1.193"],["1701.38","43.670"],["1709.04","49.318"],["1733.74","16.412"],["1733.76","35.799"],["1733.83","0.562"],["1733.88","44.716"],["1733.89","0.765"],["1733.94","29.283"],["1733.95","5.388"],["1734.06","473.139"],["1734.12","111.427"],["1734.62","340.024"],["1734.63","53.475"],["1734.74","11.949"],["1735.11","45.389"],["1735.90","2.994"],["1736.11","100.765"]],"a":[["1736.33","1.735"],["1736.37","7.833"],["1736.44","9.416"],["1736.49","2.851"],["1736.63","8.821"],["1736.89","8.141"],["1737.35","17.720"],["1737.42","3.675"],["1738.13","78.702"],["1738.14","423.260"],["1738.17","7.677"],["1738.19","16.320"],["1738.64","7.862"],["1739.42","30.137"],["1740.58","8.287"],["1764.65","0.034"],["1771.88","36.427"],["1776.79","28.045"],["1780.32","81.351"],["2634.69","0.001"],["2634.78","0.021"]],"st":1}}
{"schema_version":"1.3.0","event_id":"80427b28-a227-474e-ab23-48fdeac390fc","event_type":"raw.depth_update","source":"binance_market_data_recorder","venue":"binance_usdm","market_type":"perpetual_futures","symbol":"ETHUSDT","event_time_ms":1783517068604,"received_time_ms":1783517068598,"trace_id":"b8c57e67-dde3-403d-9155-21e893a30004","first_update_id":10999770732953,"final_update_id":10999770740981,"previous_final_update_id":10999770732928,"bids":[{"price":"200.00","quantity":"7.594"},{"price":"201.00","quantity":"2.300"},{"price":"1211.12","quantity":"2.977"},{"price":"1231.11","quantity":"3.488"},{"price":"1562.49","quantity":"0.026"},{"price":"1562.50","quantity":"3.992"},{"price":"1666.60","quantity":"1.078"},{"price":"1684.89","quantity":"53.141"},{"price":"1692.97","quantity":"0.140"},{"price":"1694.99","quantity":"0.032"},{"price":"1698.25","quantity":"0.784"},{"price":"1701.38","quantity":"43.641"},{"price":"1703.30","quantity":"25.227"},{"price":"1704.53","quantity":"88.023"},{"price":"1706.12","quantity":"29.285"},{"price":"1713.91","quantity":"18.756"},{"price":"1730.66","quantity":"0.000"},{"price":"1730.67","quantity":"16.462"},{"price":"1733.59","quantity":"22.671"},{"price":"1733.66","quantity":"23.837"},{"price":"1733.71","quantity":"504.899"},{"price":"1733.74","quantity":"17.858"},{"price":"1733.76","quantity":"95.207"},{"price":"1733.95","quantity":"7.138"},{"price":"1734.06","quantity":"54.181"},{"price":"1734.12","quantity":"55.897"},{"price":"1734.62","quantity":"119.388"},{"price":"1734.63","quantity":"23.322"},{"price":"1734.73","quantity":"317.705"},{"price":"1734.85","quantity":"222.145"},{"price":"1736.11","quantity":"102.177"}],"asks":[{"price":"1736.12","quantity":"293.394"},{"price":"1736.13","quantity":"9.663"},{"price":"1736.14","quantity":"0.028"},{"price":"1736.31","quantity":"22.895"},{"price":"1736.93","quantity":"16.386"},{"price":"1737.12","quantity":"7.826"},{"price":"1737.35","quantity":"1.044"},{"price":"1737.51","quantity":"2.858"},{"price":"1737.73","quantity":"4.742"},{"price":"1738.00","quantity":"89.072"},{"price":"1738.08","quantity":"409.324"},{"price":"1738.13","quantity":"19.864"},{"price":"1738.14","quantity":"16.295"},{"price":"1738.78","quantity":"4.109"},{"price":"1738.89","quantity":"59.745"},{"price":"1741.41","quantity":"24.723"},{"price":"1741.42","quantity":"13.266"},{"price":"1747.12","quantity":"0.000"},{"price":"2634.67","quantity":"0.001"},{"price":"2634.68","quantity":"0.001"},{"price":"2634.76","quantity":"0.000"},{"price":"2634.77","quantity":"0.000"}],"raw":{"e":"depthUpdate","E":1783517068604,"T":1783517068601,"s":"ETHUSDT","ps":"ETHUSDT","U":10999770732953,"u":10999770740981,"pu":10999770732928,"b":[["200.00","7.594"],["201.00","2.300"],["1211.12","2.977"],["1231.11","3.488"],["1562.49","0.026"],["1562.50","3.992"],["1666.60","1.078"],["1684.89","53.141"],["1692.97","0.140"],["1694.99","0.032"],["1698.25","0.784"],["1701.38","43.641"],["1703.30","25.227"],["1704.53","88.023"],["1706.12","29.285"],["1713.91","18.756"],["1730.66","0.000"],["1730.67","16.462"],["1733.59","22.671"],["1733.66","23.837"],["1733.71","504.899"],["1733.74","17.858"],["1733.76","95.207"],["1733.95","7.138"],["1734.06","54.181"],["1734.12","55.897"],["1734.62","119.388"],["1734.63","23.322"],["1734.73","317.705"],["1734.85","222.145"],["1736.11","102.177"]],"a":[["1736.12","293.394"],["1736.13","9.663"],["1736.14","0.028"],["1736.31","22.895"],["1736.93","16.386"],["1737.12","7.826"],["1737.35","1.044"],["1737.51","2.858"],["1737.73","4.742"],["1738.00","89.072"],["1738.08","409.324"],["1738.13","19.864"],["1738.14","16.295"],["1738.78","4.109"],["1738.89","59.745"],["1741.41","24.723"],["1741.42","13.266"],["1747.12","0.000"],["2634.67","0.001"],["2634.68","0.001"],["2634.76","0.000"],["2634.77","0.000"]],"st":1}}
{"schema_version":"1.3.0","event_id":"ce0b4dc5-28cb-4e14-af8f-abd4df0aebe5","event_type":"raw.depth_update","source":"binance_market_data_recorder","venue":"binance_usdm","market_type":"perpetual_futures","symbol":"ETHUSDT","event_time_ms":1783517068706,"received_time_ms":1783517068700,"trace_id":"97e3a45d-2a77-44cf-93d3-be1573457cbe","first_update_id":10999770741624,"final_update_id":10999770751353,"previous_final_update_id":10999770740981,"bids":[{"price":"200.00","quantity":"7.594"},{"price":"1211.12","quantity":"2.145"},{"price":"1231.11","quantity":"4.320"},{"price":"1562.49","quantity":"0.026"},{"price":"1562.50","quantity":"4.262"},{"price":"1701.38","quantity":"43.670"},{"price":"1703.10","quantity":"11.729"},{"price":"1714.21","quantity":"0.001"},{"price":"1717.88","quantity":"23.267"},{"price":"1718.55","quantity":"31.975"},{"price":"1724.98","quantity":"0.895"},{"price":"1725.00","quantity":"1296.212"},{"price":"1727.24","quantity":"3.387"},{"price":"1727.26","quantity":"0.517"},{"price":"1730.67","quantity":"0.000"},{"price":"1733.71","quantity":"84.523"},{"price":"1733.74","quantity":"16.412"},{"price":"1733.76","quantity":"35.799"},{"price":"1733.82","quantity":"2.575"},{"price":"1733.88","quantity":"465.092"},{"price":"1733.94","quantity":"93.267"},{"price":"1734.80","quantity":"9.123"},{"price":"1734.81","quantity":"18.272"},{"price":"1734.85","quantity":"1.504"},{"price":"1734.87","quantity":"21.930"},{"price":"1734.88","quantity":"60.522"},{"price":"1735.39","quantity":"0.565"},{"price":"1735.70","quantity":"28.859"},{"price":"1735.86","quantity":"5.986"},{"price":"1736.11","quantity":"102.192"}],"asks":[{"price":"1736.12","quantity":"293.407"},{"price":"1736.20","quantity":"3.992"},{"price":"1736.50","quantity":"0.102"},{"price":"1738.00","quantity":"30.118"},{"price":"1738.08","quantity":"1.684"},{"price":"1738.13","quantity":"78.803"},{"price":"1738.14","quantity":"423.935"},{"price":"1741.41","quantity":"10.358"},{"price":"1757.83","quantity":"33.502"},{"price":"2634.66","quantity":"0.001"},{"price":"2634.75","quantity":"0.000"}],"raw":{"e":"depthUpdate","E":1783517068706,"T":1783517068705,"s":"ETHUSDT","ps":"ETHUSDT","U":10999770741624,"u":10999770751353,"pu":10999770740981,"b":[["200.00","7.594"],["1211.12","2.145"],["1231.11","4.320"],["1562.49","0.026"],["1562.50","4.262"],["1701.38","43.670"],["1703.10","11.729"],["1714.21","0.001"],["1717.88","23.267"],["1718.55","31.975"],["1724.98","0.895"],["1725.00","1296.212"],["1727.24","3.387"],["1727.26","0.517"],["1730.67","0.000"],["1733.71","84.523"],["1733.74","16.412"],["1733.76","35.799"],["1733.82","2.575"],["1733.88","465.092"],["1733.94","93.267"],["1734.80","9.123"],["1734.81","18.272"],["1734.85","1.504"],["1734.87","21.930"],["1734.88","60.522"],["1735.39","0.565"],["1735.70","28.859"],["1735.86","5.986"],["1736.11","102.192"]],"a":[["1736.12","293.407"],["1736.20","3.992"],["1736.50","0.102"],["1738.00","30.118"],["1738.08","1.684"],["1738.13","78.803"],["1738.14","423.935"],["1741.41","10.358"],["1757.83","33.502"],["2634.66","0.001"],["2634.75","0.000"]],"st":1}}
{"schema_version":"1.3.0","event_id":"8b89374e-1b47-4fd8-90df-ed94e50480d4","event_type":"raw.depth_update","source":"binance_market_data_recorder","venue":"binance_usdm","market_type":"perpetual_futures","symbol":"ETHUSDT","event_time_ms":1783517068808,"received_time_ms":1783517068803,"trace_id":"5a3c48a0-8a07-4589-ae61-37db43e5bc96","first_update_id":10999770751441,"final_update_id":10999770758332,"previous_final_update_id":10999770751353,"bids":[{"price":"1211.12","quantity":"1.569"},{"price":"1226.11","quantity":"0.224"},{"price":"1231.11","quantity":"4.896"},{"price":"1231.12","quantity":"2.368"},{"price":"1562.49","quantity":"0.026"},{"price":"1562.50","quantity":"4.390"},{"price":"1666.60","quantity":"1.193"},{"price":"1680.19","quantity":"0.020"},{"price":"1701.38","quantity":"43.641"},{"price":"1712.88","quantity":"13.577"},{"price":"1730.67","quantity":"16.462"},{"price":"1733.89","quantity":"2.211"},{"price":"1734.42","quantity":"0.858"},{"price":"1735.11","quantity":"45.389"},{"price":"1735.70","quantity":"28.871"}],"asks":[{"price":"1736.25","quantity":"4.265"},{"price":"1736.29","quantity":"1.710"},{"price":"1736.42","quantity":"7.674"},{"price":"1736.50","quantity":"0.114"},{"price":"1736.88","quantity":"5.315"},{"price":"1736.91","quantity":"69.817"},{"price":"1737.34","quantity":"13.215"},{"price":"1737.86","quantity":"3.469"},{"price":"1737.88","quantity":"34.874"},{"price":"1737.94","quantity":"0.012"},{"price":"1738.00","quantity":"31.032"},{"price":"1738.03","quantity":"1.667"},{"price":"1739.29","quantity":"2.017"},{"price":"1739.30","quantity":"3.887"},{"price":"1741.41","quantity":"24.723"},{"price":"1770.42","quantity":"19.745"},{"price":"1797.77","quantity":"0.048"},{"price":"2634.64","quantity":"0.001"},{"price":"2634.65","quantity":"0.001"},{"price":"2634.73","quantity":"0.020"},{"price":"2634.74","quantity":"0.000"}],"raw":{"e":"depthUpdate","E":1783517068808,"T":1783517068806,"s":"ETHUSDT","ps":"ETHUSDT","U":10999770751441,"u":10999770758332,"pu":10999770751353,"b":[["1211.12","1.569"],["1226.11","0.224"],["1231.11","4.896"],["1231.12","2.368"],["1562.49","0.026"],["1562.50","4.390"],["1666.60","1.193"],["1680.19","0.020"],["1701.38","43.641"],["1712.88","13.577"],["1730.67","16.462"],["1733.89","2.211"],["1734.42","0.858"],["1735.11","45.389"],["1735.70","28.871"]],"a":[["1736.25","4.265"],["1736.29","1.710"],["1736.42","7.674"],["1736.50","0.114"],["1736.88","5.315"],["1736.91","69.817"],["1737.34","13.215"],["1737.86","3.469"],["1737.88","34.874"],["1737.94","0.012"],["1738.00","31.032"],["1738.03","1.667"],["1739.29","2.017"],["1739.30","3.887"],["1741.41","24.723"],["1770.42","19.745"],["1797.77","0.048"],["2634.64","0.001"],["2634.65","0.001"],["2634.73","0.020"],["2634.74","0.000"]],"st":1}}
{"schema_version":"1.3.0","event_id":"35214492-8f81-4c09-bde0-c1e59eb42f41","event_type":"raw.depth_update","source":"binance_market_data_recorder","venue":"binance_usdm","market_type":"perpetual_futures","symbol":"ETHUSDT","event_time_ms":1783517068910,"received_time_ms":1783517068905,"trace_id":"2f38b937-3e56-4ba2-9b73-eb716016a9fd","first_update_id":10999770758453,"final_update_id":10999770775364,"previous_final_update_id":10999770758332,"bids":[{"price":"200.00","quantity":"7.594"},{"price":"1211.12","quantity":"1.185"},{"price":"1226.11","quantity":"0.672"},{"price":"1231.11","quantity":"5.280"},{"price":"1231.12","quantity":"1.920"},{"price":"1562.49","quantity":"0.026"},{"price":"1562.50","quantity":"4.262"},{"price":"1666.60","quantity":"1.078"},{"price":"1701.38","quantity":"43.670"},{"price":"1707.85","quantity":"29.252"},{"price":"1730.67","quantity":"16.462"},{"price":"1732.09","quantity":"37.542"},{"price":"1733.50","quantity":"13.855"},{"price":"1733.88","quantity":"44.716"},{"price":"1733.89","quantity":"0.765"},{"price":"1733.95","quantity":"3.942"},{"price":"1734.18","quantity":"420.446"},{"price":"1734.23","quantity":"60.276"},{"price":"1734.24","quantity":"1.474"},{"price":"1734.30","quantity":"50.741"},{"price":"1734.31","quantity":"17.757"},{"price":"1734.53","quantity":"255.561"},{"price":"1734.57","quantity":"29.351"},{"price":"1734.61","quantity":"0.240"},{"price":"1734.71","quantity":"206.715"},{"price":"1734.73","quantity":"97.085"},{"price":"1734.74","quantity":"11.549"},{"price":"1735.14","quantity":"9.918"},{"price":"1735.17","quantity":"3.284"},{"price":"1735.23","quantity":"43.841"},{"price":"1735.24","quantity":"7.526"},{"price":"1735.30","quantity":"29.159"},{"price":"1735.33","quantity":"16.529"},{"price":"1735.34","quantity":"0.110"},{"price":"1735.37","quantity":"3.595"},{"price":"1735.46","quantity":"21.336"},{"price":"1735.53","quantity":"5.205"},{"price":"1735.56","quantity":"33.563"},{"price":"1735.58","quantity":"0.094"},{"price":"1735.61","quantity":"8.774"},{"price":"1735.63","quantity":"0.588"},{"price":"1735.64","quantity":"76.667"},{"price":"1735.65","quantity":"20.560"},{"price":"1735.66","quantity":"29.107"},{"price":"1735.68","quantity":"15.169"},{"price":"1735.70","quantity":"0.037"},{"price":"1735.71","quantity":"0.038"},{"price":"1735.73","quantity":"26.047"},{"price":"1735.76","quantity":"11.257"},{"price":"1735.81","quantity":"7.246"},{"price":"1735.83","quantity":"21.004"},{"price":"1735.84","quantity":"8.707"},{"price":"1735.86","quantity":"27.882"},{"price":"1735.87","quantity":"0.757"},{"price":"1735.88","quantity":"0.254"},{"price":"1735.89","quantity":"81.225"},{"price":"1735.90","quantity":"1.266"},{"price":"1735.91","quantity":"10.048"},{"price":"1735.92","quantity":"25.525"},{"price":"1735.93","quantity":"10.246"},{"price":"1735.95","quantity":"0.074"},{"price":"1735.96","quantity":"0.552"},{"price":"1735.97","quantity":"3.383"},{"price":"1735.98","quantity":"1.036"},{"price":"1736.00","quantity":"3.544"},{"price":"1736.03","quantity":"1.122"},{"price":"1736.04","quantity":"0.012"},{"price":"1736.05","quantity":"0.051"},{"price":"1736.07","quantity":"0.047"},{"price":"1736.11","quantity":"12.408"}],"asks":[{"price":"1736.12","quantity":"301.409"},{"price":"1736.15","quantity":"0.048"},{"price":"1736.16","quantity":"1.431"},{"price":"1736.18","quantity":"1.781"},{"price":"1736.20","quantity":"4.780"},{"price":"1736.24","quantity":"9.257"},{"price":"1736.25","quantity":"3.977"},{"price":"1736.29","quantity":"1.210"},{"price":"1736.31","quantity":"22.895"},{"price":"1736.33","quantity":"1.735"},{"price":"1736.36","quantity":"34.003"},{"price":"1736.37","quantity":"17.728"},{"price":"1736.42","quantity":"7.674"},{"price":"1736.43","quantity":"20.921"},{"price":"1736.65","quantity":"22.453"},{"price":"1736.90","quantity":"57.445"},{"price":"1736.98","quantity":"16.096"},{"price":"1737.01","quantity":"76.981"},{"price":"1737.12","quantity":"7.826"},{"price":"1737.19","quantity":"6.167"},{"price":"1737.35","quantity":"0.044"},{"price":"1737.37","quantity":"30.259"},{"price":"1737.54","quantity":"27.248"},{"price":"1737.57","quantity":"42.677"},{"price":"1737.80","quantity":"5.124"},{"price":"1737.89","quantity":"17.008"},{"price":"1737.94","quantity":"1.679"},{"price":"1738.00","quantity":"90.234"},{"price":"1738.03","quantity":"0.000"},{"price":"1738.08","quantity":"409.324"},{"price":"1738.12","quantity":"21.565"},{"price":"1738.13","quantity":"19.864"},{"price":"1738.14","quantity":"16.295"},{"price":"1738.80","quantity":"8.359"},{"price":"1738.88","quantity":"8.584"},{"price":"1739.42","quantity":"20.408"},{"price":"1740.16","quantity":"2.509"},{"price":"1740.58","quantity":"0.782"},{"price":"1741.41","quantity":"24.723"},{"price":"1747.12","quantity":"15.000"},{"price":"2634.63","quantity":"0.010"},{"price":"2634.72","quantity":"0.000"}],"raw":{"e":"depthUpdate","E":1783517068910,"T":1783517068909,"s":"ETHUSDT","ps":"ETHUSDT","U":10999770758453,"u":10999770775364,"pu":10999770758332,"b":[["200.00","7.594"],["1211.12","1.185"],["1226.11","0.672"],["1231.11","5.280"],["1231.12","1.920"],["1562.49","0.026"],["1562.50","4.262"],["1666.60","1.078"],["1701.38","43.670"],["1707.85","29.252"],["1730.67","16.462"],["1732.09","37.542"],["1733.50","13.855"],["1733.88","44.716"],["1733.89","0.765"],["1733.95","3.942"],["1734.18","420.446"],["1734.23","60.276"],["1734.24","1.474"],["1734.30","50.741"],["1734.31","17.757"],["1734.53","255.561"],["1734.57","29.351"],["1734.61","0.240"],["1734.71","206.715"],["1734.73","97.085"],["1734.74","11.549"],["1735.14","9.918"],["1735.17","3.284"],["1735.23","43.841"],["1735.24","7.526"],["1735.30","29.159"],["1735.33","16.529"],["1735.34","0.110"],["1735.37","3.595"],["1735.46","21.336"],["1735.53","5.205"],["1735.56","33.563"],["1735.58","0.094"],["1735.61","8.774"],["1735.63","0.588"],["1735.64","76.667"],["1735.65","20.560"],["1735.66","29.107"],["1735.68","15.169"],["1735.70","0.037"],["1735.71","0.038"],["1735.73","26.047"],["1735.76","11.257"],["1735.81","7.246"],["1735.83","21.004"],["1735.84","8.707"],["1735.86","27.882"],["1735.87","0.757"],["1735.88","0.254"],["1735.89","81.225"],["1735.90","1.266"],["1735.91","10.048"],["1735.92","25.525"],["1735.93","10.246"],["1735.95","0.074"],["1735.96","0.552"],["1735.97","3.383"],["1735.98","1.036"],["1736.00","3.544"],["1736.03","1.122"],["1736.04","0.012"],["1736.05","0.051"],["1736.07","0.047"],["1736.11","12.408"]],"a":[["1736.12","301.409"],["1736.15","0.048"],["1736.16","1.431"],["1736.18","1.781"],["1736.20","4.780"],["1736.24","9.257"],["1736.25","3.977"],["1736.29","1.210"],["1736.31","22.895"],["1736.33","1.735"],["1736.36","34.003"],["1736.37","17.728"],["1736.42","7.674"],["1736.43","20.921"],["1736.65","22.453"],["1736.90","57.445"],["1736.98","16.096"],["1737.01","76.981"],["1737.12","7.826"],["1737.19","6.167"],["1737.35","0.044"],["1737.37","30.259"],["1737.54","27.248"],["1737.57","42.677"],["1737.80","5.124"],["1737.89","17.008"],["1737.94","1.679"],["1738.00","90.234"],["1738.03","0.000"],["1738.08","409.324"],["1738.12","21.565"],["1738.13","19.864"],["1738.14","16.295"],["1738.80","8.359"],["1738.88","8.584"],["1739.42","20.408"],["1740.16","2.509"],["1740.58","0.782"],["1741.41","24.723"],["1747.12","15.000"],["2634.63","0.010"],["2634.72","0.000"]],"st":1}}
{"schema_version":"1.3.0","event_id":"f8f08ca2-c1b8-441f-9879-3ec2fbf9cebe","event_type":"raw.depth_update","source":"binance_market_data_recorder","venue":"binance_usdm","market_type":"perpetual_futures","symbol":"ETHUSDT","event_time_ms":1783517069012,"received_time_ms":1783517069007,"trace_id":"280fb0f3-19b3-44f6-bd35-8651f630fb75","first_update_id":10999770775501,"final_update_id":10999770790546,"previous_final_update_id":10999770775364,"bids":[{"price":"200.00","quantity":"7.594"},{"price":"1211.12","quantity":"0.897"},{"price":"1226.11","quantity":"1.184"},{"price":"1231.11","quantity":"5.568"},{"price":"1231.12","quantity":"1.408"},{"price":"1236.11","quantity":"0.295"},{"price":"1562.49","quantity":"0.026"},{"price":"1562.50","quantity":"4.276"},{"price":"1650.00","quantity":"1681.223"},{"price":"1666.60","quantity":"1.193"},{"price":"1701.38","quantity":"43.641"},{"price":"1733.65","quantity":"430.295"},{"price":"1733.66","quantity":"23.837"},{"price":"1733.67","quantity":"5.201"},{"price":"1733.94","quantity":"29.283"},{"price":"1734.18","quantity":"0.070"},{"price":"1734.21","quantity":"79.399"},{"price":"1734.23","quantity":"60.276"},{"price":"1734.24","quantity":"1.474"},{"price":"1734.30","quantity":"21.202"},{"price":"1734.31","quantity":"17.757"},{"price":"1734.33","quantity":"240.475"},{"price":"1734.37","quantity":"41.529"},{"price":"1734.41","quantity":"80.351"},{"price":"1734.53","quantity":"34.922"},{"price":"1734.57","quantity":"29.351"},{"price":"1734.63","quantity":"25.416"},{"price":"1734.64","quantity":"1.603"},{"price":"1734.87","quantity":"19.838"},{"price":"1734.88","quantity":"59.476"},{"price":"1735.11","quantity":"45.389"},{"price":"1735.29","quantity":"29.658"},{"price":"1735.30","quantity":"29.171"},{"price":"1735.31","quantity":"34.008"},{"price":"1735.32","quantity":"27.000"},{"price":"1735.84","quantity":"0.058"},{"price":"1735.88","quantity":"0.236"},{"price":"1735.89","quantity":"81.243"},{"price":"1735.93","quantity":"7.050"},{"price":"1736.11","quantity":"1.611"}],"asks":[{"price":"1736.12","quantity":"300.040"},{"price":"1736.21","quantity":"2.515"},{"price":"1736.33","quantity":"1.735"},{"price":"1736.88","quantity":"3.621"},{"price":"1736.91","quantity":"68.123"},{"price":"1737.16","quantity":"13.024"},{"price":"1737.35","quantity":"26.174"},{"price":"1737.42","quantity":"6.315"},{"price":"1737.51","quantity":"2.858"},{"price":"1737.68","quantity":"0.970"},{"price":"1737.88","quantity":"36.568"},{"price":"1738.00","quantity":"31.032"},{"price":"1738.08","quantity":"1.684"},{"price":"1738.13","quantity":"78.803"},{"price":"1738.14","quantity":"423.935"},{"price":"1738.88","quantity":"11.780"},{"price":"1739.59","quantity":"2.304"},{"price":"1739.60","quantity":"36.362"},{"price":"1740.46","quantity":"2.304"},{"price":"1740.47","quantity":"19.500"},{"price":"1741.32","quantity":"18.212"},{"price":"1741.33","quantity":"0.348"},{"price":"1742.19","quantity":"4.827"},{"price":"1742.20","quantity":"5.897"},{"price":"1743.06","quantity":"2.402"},{"price":"1743.07","quantity":"16.236"},{"price":"1763.28","quantity":"41.091"},{"price":"2634.61","quantity":"0.119"},{"price":"2634.62","quantity":"0.001"},{"price":"2634.70","quantity":"0.000"},{"price":"2634.71","quantity":"0.000"}],"raw":{"e":"depthUpdate","E":1783517069012,"T":1783517069010,"s":"ETHUSDT","ps":"ETHUSDT","U":10999770775501,"u":10999770790546,"pu":10999770775364,"b":[["200.00","7.594"],["1211.12","0.897"],["1226.11","1.184"],["1231.11","5.568"],["1231.12","1.408"],["1236.11","0.295"],["1562.49","0.026"],["1562.50","4.276"],["1650.00","1681.223"],["1666.60","1.193"],["1701.38","43.641"],["1733.65","430.295"],["1733.66","23.837"],["1733.67","5.201"],["1733.94","29.283"],["1734.18","0.070"],["1734.21","79.399"],["1734.23","60.276"],["1734.24","1.474"],["1734.30","21.202"],["1734.31","17.757"],["1734.33","240.475"],["1734.37","41.529"],["1734.41","80.351"],["1734.53","34.922"],["1734.57","29.351"],["1734.63","25.416"],["1734.64","1.603"],["1734.87","19.838"],["1734.88","59.476"],["1735.11","45.389"],["1735.29","29.658"],["1735.30","29.171"],["1735.31","34.008"],["1735.32","27.000"],["1735.84","0.058"],["1735.88","0.236"],["1735.89","81.243"],["1735.93","7.050"],["1736.11","1.611"]],"a":[["1736.12","300.040"],["1736.21","2.515"],["1736.33","1.735"],["1736.88","3.621"],["1736.91","68.123"],["1737.16","13.024"],["1737.35","26.174"],["1737.42","6.315"],["1737.51","2.858"],["1737.68","0.970"],["1737.88","36.568"],["1738.00","31.032"],["1738.08","1.684"],["1738.13","78.803"],["1738.14","423.935"],["1738.88","11.780"],["1739.59","2.304"],["1739.60","36.362"],["1740.46","2.304"],["1740.47","19.500"],["1741.32","18.212"],["1741.33","0.348"],["1742.19","4.827"],["1742.20","5.897"],["1743.06","2.402"],["1743.07","16.236"],["1763.28","41.091"],["2634.61","0.119"],["2634.62","0.001"],["2634.70","0.000"],["2634.71","0.000"]],"st":1}}
{"schema_version":"1.3.0","event_id":"174663d8-662c-4bc6-ab98-d9b7ba72e134","event_type":"raw.depth_update","source":"binance_market_data_recorder","venue":"binance_usdm","market_type":"perpetual_futures","symbol":"ETHUSDT","event_time_ms":1783517069114,"received_time_ms":1783517069110,"trace_id":"0380a3a7-b7e0-4ce0-a468-523d15562a53","first_update_id":10999770790801,"final_update_id":10999770805757,"previous_final_update_id":10999770790546,"bids":[{"price":"1211.12","quantity":"0.641"},{"price":"1226.11","quantity":"1.760"},{"price":"1231.11","quantity":"5.824"},{"price":"1231.12","quantity":"0.832"},{"price":"1562.49","quantity":"0.026"},{"price":"1562.50","quantity":"4.418"},{"price":"1666.60","quantity":"1.078"},{"price":"1696.13","quantity":"29.523"},{"price":"1705.90","quantity":"13.794"},{"price":"1711.51","quantity":"13.853"},{"price":"1712.76","quantity":"0.870"},{"price":"1732.13","quantity":"183.379"},{"price":"1732.14","quantity":"37.402"},{"price":"1732.17","quantity":"0.024"},{"price":"1733.65","quantity":"9.919"},{"price":"1733.66","quantity":"23.837"},{"price":"1733.67","quantity":"5.201"},{"price":"1733.83","quantity":"2.290"},{"price":"1733.86","quantity":"0.363"},{"price":"1733.88","quantity":"465.092"},{"price":"1733.89","quantity":"3.961"},{"price":"1733.94","quantity":"93.009"},{"price":"1734.21","quantity":"18.716"},{"price":"1734.22","quantity":"17.049"},{"price":"1734.24","quantity":"1.565"},{"price":"1734.31","quantity":"17.666"},{"price":"1734.33","quantity":"19.867"},{"price":"1734.37","quantity":"9.825"},{"price":"1734.38","quantity":"13.652"},{"price":"1734.45","quantity":"0.656"},{"price":"1734.46","quantity":"25.640"},{"price":"1734.49","quantity":"53.052"},{"price":"1734.63","quantity":"1.527"},{"price":"1734.64","quantity":"221.128"},{"price":"1734.65","quantity":"68.581"},{"price":"1734.71","quantity":"206.733"},{"price":"1734.73","quantity":"97.067"},{"price":"1734.86","quantity":"38.717"},{"price":"1735.06","quantity":"2.219"},{"price":"1735.07","quantity":"7.163"},{"price":"1735.23","quantity":"4.905"},{"price":"1735.28","quantity":"4.974"},{"price":"1735.31","quantity":"72.943"},{"price":"1735.56","quantity":"27.796"},{"price":"1735.60","quantity":"4.613"},{"price":"1735.63","quantity":"6.355"},{"price":"1735.65","quantity":"40.560"},{"price":"1735.66","quantity":"29.004"},{"price":"1735.71","quantity":"0.136"},{"price":"1735.76","quantity":"15.145"},{"price":"1735.83","quantity":"21.004"},{"price":"1735.86","quantity":"5.698"},{"price":"1735.90","quantity":"2.266"},{"price":"1735.91","quantity":"11.685"},{"price":"1735.92","quantity":"25.525"},{"price":"1735.93","quantity":"3.162"},{"price":"1735.95","quantity":"1.226"},{"price":"1735.96","quantity":"0.730"},{"price":"1735.99","quantity":"22.235"},{"price":"1736.06","quantity":"0.014"},{"price":"1736.07","quantity":"0.035"},{"price":"1736.11","quantity":"125.972"}],"asks":[{"price":"1736.12","quantity":"285.297"},{"price":"1736.15","quantity":"0.024"},{"price":"1736.16","quantity":"0.279"},{"price":"1736.20","quantity":"3.992"},{"price":"1736.21","quantity":"0.032"},{"price":"1736.22","quantity":"20.900"},{"price":"1736.25","quantity":"4.765"},{"price":"1736.31","quantity":"22.895"},{"price":"1736.33","quantity":"1.735"},{"price":"1736.35","quantity":"4.537"},{"price":"1736.36","quantity":"5.180"},{"price":"1736.39","quantity":"28.921"},{"price":"1736.47","quantity":"2.139"},{"price":"1736.67","quantity":"12.217"},{"price":"1736.73","quantity":"7.063"},{"price":"1736.77","quantity":"39.064"},{"price":"1736.96","quantity":"3.499"},{"price":"1737.12","quantity":"7.826"},{"price":"1737.34","quantity":"29.891"},{"price":"1738.00","quantity":"31.032"},{"price":"1738.08","quantity":"1.684"},{"price":"1738.12","quantity":"14.060"},{"price":"1738.13","quantity":"19.864"},{"price":"1738.14","quantity":"16.295"},{"price":"1738.17","quantity":"67.863"},{"price":"1738.25","quantity":"410.518"},{"price":"1738.37","quantity":"89.779"},{"price":"1738.39","quantity":"16.597"},{"price":"1738.89","quantity":"59.745"},{"price":"1739.42","quantity":"27.913"},{"price":"1739.97","quantity":"32.859"},{"price":"1739.98","quantity":"145.446"},{"price":"1739.99","quantity":"0.299"},{"price":"1763.30","quantity":"43.606"},{"price":"1764.34","quantity":"283.150"},{"price":"2634.59","quantity":"0.001"},{"price":"2634.60","quantity":"0.001"},{"price":"2634.68","quantity":"0.000"},{"price":"2634.69","quantity":"0.000"}],"raw":{"e":"depthUpdate","E":1783517069114,"T":1783517069113,"s":"ETHUSDT","ps":"ETHUSDT","U":10999770790801,"u":10999770805757,"pu":10999770790546,"b":[["1211.12","0.641"],["1226.11","1.760"],["1231.11","5.824"],["1231.12","0.832"],["1562.49","0.026"],["1562.50","4.418"],["1666.60","1.078"],["1696.13","29.523"],["1705.90","13.794"],["1711.51","13.853"],["1712.76","0.870"],["1732.13","183.379"],["1732.14","37.402"],["1732.17","0.024"],["1733.65","9.919"],["1733.66","23.837"],["1733.67","5.201"],["1733.83","2.290"],["1733.86","0.363"],["1733.88","465.092"],["1733.89","3.961"],["1733.94","93.009"],["1734.21","18.716"],["1734.22","17.049"],["1734.24","1.565"],["1734.31","17.666"],["1734.33","19.867"],["1734.37","9.825"],["1734.38","13.652"],["1734.45","0.656"],["1734.46","25.640"],["1734.49","53.052"],["1734.63","1.527"],["1734.64","221.128"],["1734.65","68.581"],["1734.71","206.733"],["1734.73","97.067"],["1734.86","38.717"],["1735.06","2.219"],["1735.07","7.163"],["1735.23","4.905"],["1735.28","4.974"],["1735.31","72.943"],["1735.56","27.796"],["1735.60","4.613"],["1735.63","6.355"],["1735.65","40.560"],["1735.66","29.004"],["1735.71","0.136"],["1735.76","15.145"],["1735.83","21.004"],["1735.86","5.698"],["1735.90","2.266"],["1735.91","11.685"],["1735.92","25.525"],["1735.93","3.162"],["1735.95","1.226"],["1735.96","0.730"],["1735.99","22.235"],["1736.06","0.014"],["1736.07","0.035"],["1736.11","125.972"]],"a":[["1736.12","285.297"],["1736.15","0.024"],["1736.16","0.279"],["1736.20","3.992"],["1736.21","0.032"],["1736.22","20.900"],["1736.25","4.765"],["1736.31","22.895"],["1736.33","1.735"],["1736.35","4.537"],["1736.36","5.180"],["1736.39","28.921"],["1736.47","2.139"],["1736.67","12.217"],["1736.73","7.063"],["1736.77","39.064"],["1736.96","3.499"],["1737.12","7.826"],["1737.34","29.891"],["1738.00","31.032"],["1738.08","1.684"],["1738.12","14.060"],["1738.13","19.864"],["1738.14","16.295"],["1738.17","67.863"],["1738.25","410.518"],["1738.37","89.779"],["1738.39","16.597"],["1738.89","59.745"],["1739.42","27.913"],["1739.97","32.859"],["1739.98","145.446"],["1739.99","0.299"],["1763.30","43.606"],["1764.34","283.150"],["2634.59","0.001"],["2634.60","0.001"],["2634.68","0.000"],["2634.69","0.000"]],"st":1}}
{"schema_version":"1.3.0","event_id":"e4073cc7-498d-412a-8f7c-2b36407ea4cc","event_type":"raw.depth_update","source":"binance_market_data_recorder","venue":"binance_usdm","market_type":"perpetual_futures","symbol":"ETHUSDT","event_time_ms":1783517069218,"received_time_ms":1783517069212,"trace_id":"55d0f705-a75b-4253-a700-f2c1eb34b19e","first_update_id":10999770806036,"final_update_id":10999770817136,"previous_final_update_id":10999770805757,"bids":[{"price":"200.00","quantity":"7.594"},{"price":"1211.12","quantity":"0.353"},{"price":"1226.11","quantity":"2.304"},{"price":"1231.11","quantity":"6.112"},{"price":"1231.12","quantity":"0.288"},{"price":"1562.49","quantity":"0.026"},{"price":"1562.50","quantity":"4.290"},{"price":"1690.42","quantity":"105.508"},{"price":"1701.38","quantity":"43.670"},{"price":"1706.13","quantity":"20.490"},{"price":"1733.59","quantity":"443.047"},{"price":"1733.66","quantity":"82.683"},{"price":"1733.74","quantity":"16.412"},{"price":"1733.88","quantity":"44.716"},{"price":"1733.94","quantity":"29.283"},{"price":"1733.99","quantity":"0.014"},{"price":"1734.44","quantity":"56.254"},{"price":"1734.45","quantity":"0.638"},{"price":"1734.46","quantity":"25.640"},{"price":"1734.62","quantity":"119.370"},{"price":"1734.64","quantity":"221.146"},{"price":"1734.66","quantity":"221.822"},{"price":"1734.80","quantity":"9.123"},{"price":"1735.15","quantity":"6.663"},{"price":"1735.28","quantity":"4.962"},{"price":"1735.29","quantity":"29.646"},{"price":"1735.30","quantity":"29.159"},{"price":"1735.31","quantity":"72.931"},{"price":"1735.32","quantity":"26.988"},{"price":"1735.33","quantity":"16.517"},{"price":"1735.34","quantity":"0.098"},{"price":"1735.63","quantity":"6.343"},{"price":"1735.67","quantity":"0.063"},{"price":"1735.71","quantity":"0.136"},{"price":"1735.90","quantity":"1.266"},{"price":"1735.96","quantity":"22.914"},{"price":"1735.99","quantity":"0.052"},{"price":"1736.00","quantity":"6.548"},{"price":"1736.04","quantity":"0.024"},{"price":"1736.05","quantity":"0.063"},{"price":"1736.06","quantity":"0.026"},{"price":"1736.07","quantity":"0.047"},{"price":"1736.11","quantity":"89.118"}],"asks":[{"price":"1736.12","quantity":"285.168"},{"price":"1736.16","quantity":"0.291"},{"price":"1736.24","quantity":"9.300"},{"price":"1736.25","quantity":"4.265"},{"price":"1736.27","quantity":"0.526"},{"price":"1736.61","quantity":"13.962"},{"price":"1736.65","quantity":"18.214"},{"price":"1736.96","quantity":"9.259"},{"price":"1736.97","quantity":"2.975"},{"price":"1737.31","quantity":"20.947"},{"price":"1738.13","quantity":"78.803"},{"price":"1738.14","quantity":"423.935"},{"price":"1738.17","quantity":"7.677"},{"price":"1738.25","quantity":"2.878"},{"price":"1738.34","quantity":"10.619"},{"price":"1747.12","quantity":"0.000"},{"price":"1764.46","quantity":"31.242"},{"price":"1769.55","quantity":"82.979"},{"price":"2634.58","quantity":"0.001"},{"price":"2634.67","quantity":"0.000"}],"raw":{"e":"depthUpdate","E":1783517069218,"T":1783517069217,"s":"ETHUSDT","ps":"ETHUSDT","U":10999770806036,"u":10999770817136,"pu":10999770805757,"b":[["200.00","7.594"],["1211.12","0.353"],["1226.11","2.304"],["1231.11","6.112"],["1231.12","0.288"],["1562.49","0.026"],["1562.50","4.290"],["1690.42","105.508"],["1701.38","43.670"],["1706.13","20.490"],["1733.59","443.047"],["1733.66","82.683"],["1733.74","16.412"],["1733.88","44.716"],["1733.94","29.283"],["1733.99","0.014"],["1734.44","56.254"],["1734.45","0.638"],["1734.46","25.640"],["1734.62","119.370"],["1734.64","221.146"],["1734.66","221.822"],["1734.80","9.123"],["1735.15","6.663"],["1735.28","4.962"],["1735.29","29.646"],["1735.30","29.159"],["1735.31","72.931"],["1735.32","26.988"],["1735.33","16.517"],["1735.34","0.098"],["1735.63","6.343"],["1735.67","0.063"],["1735.71","0.136"],["1735.90","1.266"],["1735.96","22.914"],["1735.99","0.052"],["1736.00","6.548"],["1736.04","0.024"],["1736.05","0.063"],["1736.06","0.026"],["1736.07","0.047"],["1736.11","89.118"]],"a":[["1736.12","285.168"],["1736.16","0.291"],["1736.24","9.300"],["1736.25","4.265"],["1736.27","0.526"],["1736.61","13.962"],["1736.65","18.214"],["1736.96","9.259"],["1736.97","2.975"],["1737.31","20.947"],["1738.13","78.803"],["1738.14","423.935"],["1738.17","7.677"],["1738.25","2.878"],["1738.34","10.619"],["1747.12","0.000"],["1764.46","31.242"],["1769.55","82.979"],["2634.58","0.001"],["2634.67","0.000"]],"st":1}}
{"schema_version":"1.3.0","event_id":"f94ea7f5-b146-4cb7-ac69-fe367d1eb9f5","event_type":"raw.depth_update","source":"binance_market_data_recorder","venue":"binance_usdm","market_type":"perpetual_futures","symbol":"ETHUSDT","event_time_ms":1783517069320,"received_time_ms":1783517069320,"trace_id":"f2ebb8d5-9fb8-4e86-94ea-6bde77c02a61","first_update_id":10999770817295,"final_update_id":10999770830523,"previous_final_update_id":10999770817136,"bids":[{"price":"200.00","quantity":"7.594"},{"price":"1211.11","quantity":"0.677"},{"price":"1211.12","quantity":"0.193"},{"price":"1226.11","quantity":"2.848"},{"price":"1231.11","quantity":"6.112"},{"price":"1231.12","quantity":"0.000"},{"price":"1562.49","quantity":"0.026"},{"price":"1562.50","quantity":"4.162"},{"price":"1666.60","quantity":"1.193"},{"price":"1701.38","quantity":"43.641"},{"price":"1703.00","quantity":"194.417"},{"price":"1706.60","quantity":"57.976"},{"price":"1708.81","quantity":"15.781"},{"price":"1708.97","quantity":"9.593"},{"price":"1710.24","quantity":"172.251"},{"price":"1718.74","quantity":"57.612"},{"price":"1727.42","quantity":"0.629"},{"price":"1727.89","quantity":"10.013"},{"price":"1727.91","quantity":"2.673"},{"price":"1727.94","quantity":"0.176"},{"price":"1733.59","quantity":"22.671"},{"price":"1733.60","quantity":"68.107"},{"price":"1733.66","quantity":"23.837"},{"price":"1733.68","quantity":"18.785"},{"price":"1733.82","quantity":"2.575"},{"price":"1733.89","quantity":"0.765"},{"price":"1734.12","quantity":"55.897"},{"price":"1734.18","quantity":"0.012"},{"price":"1734.44","quantity":"56.236"},{"price":"1734.47","quantity":"4.441"},{"price":"1734.49","quantity":"53.070"},{"price":"1734.57","quantity":"29.409"},{"price":"1734.62","quantity":"119.388"},{"price":"1734.64","quantity":"0.556"},{"price":"1734.65","quantity":"13.554"},{"price":"1734.66","quantity":"1.206"},{"price":"1734.72","quantity":"2.933"},{"price":"1734.98","quantity":"290.505"},{"price":"1735.11","quantity":"45.389"},{"price":"1735.13","quantity":"3.178"},{"price":"1735.32","quantity":"27.000"},{"price":"1735.33","quantity":"16.529"},{"price":"1735.34","quantity":"0.110"},{"price":"1735.56","quantity":"27.796"},{"price":"1735.59","quantity":"4.353"},{"price":"1735.62","quantity":"10.466"},{"price":"1735.63","quantity":"6.343"},{"price":"1735.65","quantity":"20.560"},{"price":"1735.66","quantity":"20.169"},{"price":"1735.67","quantity":"0.051"},{"price":"1735.71","quantity":"0.050"},{"price":"1735.73","quantity":"54.881"},{"price":"1735.75","quantity":"71.542"},{"price":"1735.76","quantity":"15.145"},{"price":"1735.77","quantity":"14.174"},{"price":"1735.78","quantity":"3.944"},{"price":"1735.82","quantity":"0.866"},{"price":"1735.87","quantity":"9.406"},{"price":"1735.88","quantity":"0.236"},{"price":"1735.89","quantity":"9.703"},{"price":"1735.90","quantity":"5.576"},{"price":"1735.92","quantity":"18.813"},{"price":"1735.93","quantity":"0.858"},{"price":"1735.94","quantity":"5.006"},{"price":"1735.95","quantity":"0.074"},{"price":"1735.96","quantity":"0.552"},{"price":"1735.97","quantity":"5.111"},{"price":"1735.98","quantity":"23.220"},{"price":"1735.99","quantity":"0.230"},{"price":"1736.00","quantity":"2.489"},{"price":"1736.03","quantity":"1.134"},{"price":"1736.05","quantity":"0.051"},{"price":"1736.06","quantity":"0.014"},{"price":"1736.07","quantity":"0.035"},{"price":"1736.10","quantity":"3.755"},{"price":"1736.11","quantity":"145.507"}],"asks":[{"price":"1736.12","quantity":"265.351"},{"price":"1736.14","quantity":"0.028"},{"price":"1736.18","quantity":"0.053"},{"price":"1736.21","quantity":"0.044"},{"price":"1736.24","quantity":"0.660"},{"price":"1736.25","quantity":"3.977"},{"price":"1736.27","quantity":"0.026"},{"price":"1736.28","quantity":"41.260"},{"price":"1736.31","quantity":"22.895"},{"price":"1736.33","quantity":"1.735"},{"price":"1736.39","quantity":"0.098"},{"price":"1736.42","quantity":"36.496"},{"price":"1736.52","quantity":"5.845"},{"price":"1736.55","quantity":"31.365"},{"price":"1736.60","quantity":"5.055"},{"price":"1736.61","quantity":"11.082"},{"price":"1736.88","quantity":"3.633"},{"price":"1736.90","quantity":"57.445"},{"price":"1736.96","quantity":"3.499"},{"price":"1737.16","quantity":"11.330"},{"price":"1737.31","quantity":"9.427"},{"price":"1737.51","quantity":"2.858"},{"price":"1737.83","quantity":"33.086"},{"price":"1737.88","quantity":"34.874"},{"price":"1740.55","quantity":"6.242"},{"price":"1742.19","quantity":"3.099"},{"price":"1744.33","quantity":"2.075"},{"price":"1744.34","quantity":"10.023"},{"price":"1744.38","quantity":"2.137"},{"price":"1744.39","quantity":"0.000"},{"price":"1744.81","quantity":"0.154"},{"price":"1762.00","quantity":"153.236"},{"price":"1763.23","quantity":"15.531"},{"price":"2634.56","quantity":"0.001"},{"price":"2634.57","quantity":"0.001"},{"price":"2634.65","quantity":"0.000"},{"price":"2634.66","quantity":"0.000"}],"raw":{"e":"depthUpdate","E":1783517069320,"T":1783517069319,"s":"ETHUSDT","ps":"ETHUSDT","U":10999770817295,"u":10999770830523,"pu":10999770817136,"b":[["200.00","7.594"],["1211.11","0.677"],["1211.12","0.193"],["1226.11","2.848"],["1231.11","6.112"],["1231.12","0.000"],["1562.49","0.026"],["1562.50","4.162"],["1666.60","1.193"],["1701.38","43.641"],["1703.00","194.417"],["1706.60","57.976"],["1708.81","15.781"],["1708.97","9.593"],["1710.24","172.251"],["1718.74","57.612"],["1727.42","0.629"],["1727.89","10.013"],["1727.91","2.673"],["1727.94","0.176"],["1733.59","22.671"],["1733.60","68.107"],["1733.66","23.837"],["1733.68","18.785"],["1733.82","2.575"],["1733.89","0.765"],["1734.12","55.897"],["1734.18","0.012"],["1734.44","56.236"],["1734.47","4.441"],["1734.49","53.070"],["1734.57","29.409"],["1734.62","119.388"],["1734.64","0.556"],["1734.65","13.554"],["1734.66","1.206"],["1734.72","2.933"],["1734.98","290.505"],["1735.11","45.389"],["1735.13","3.178"],["1735.32","27.000"],["1735.33","16.529"],["1735.34","0.110"],["1735.56","27.796"],["1735.59","4.353"],["1735.62","10.466"],["1735.63","6.343"],["1735.65","20.560"],["1735.66","20.169"],["1735.67","0.051"],["1735.71","0.050"],["1735.73","54.881"],["1735.75","71.542"],["1735.76","15.145"],["1735.77","14.174"],["1735.78","3.944"],["1735.82","0.866"],["1735.87","9.406"],["1735.88","0.236"],["1735.89","9.703"],["1735.90","5.576"],["1735.92","18.813"],["1735.93","0.858"],["1735.94","5.006"],["1735.95","0.074"],["1735.96","0.552"],["1735.97","5.111"],["1735.98","23.220"],["1735.99","0.230"],["1736.00","2.489"],["1736.03","1.134"],["1736.05","0.051"],["1736.06","0.014"],["1736.07","0.035"],["1736.10","3.755"],["1736.11","145.507"]],"a":[["1736.12","265.351"],["1736.14","0.028"],["1736.18","0.053"],["1736.21","0.044"],["1736.24","0.660"],["1736.25","3.977"],["1736.27","0.026"],["1736.28","41.260"],["1736.31","22.895"],["1736.33","1.735"],["1736.39","0.098"],["1736.42","36.496"],["1736.52","5.845"],["1736.55","31.365"],["1736.60","5.055"],["1736.61","11.082"],["1736.88","3.633"],["1736.90","57.445"],["1736.96","3.499"],["1737.16","11.330"],["1737.31","9.427"],["1737.51","2.858"],["1737.83","33.086"],["1737.88","34.874"],["1740.55","6.242"],["1742.19","3.099"],["1744.33","2.075"],["1744.34","10.023"],["1744.38","2.137"],["1744.39","0.000"],["1744.81","0.154"],["1762.00","153.236"],["1763.23","15.531"],["2634.56","0.001"],["2634.57","0.001"],["2634.65","0.000"],["2634.66","0.000"]],"st":1}}
{"schema_version":"1.3.0","event_id":"fa6015be-b082-4065-b9ae-16bc85404088","event_type":"raw.depth_update","source":"binance_market_data_recorder","venue":"binance_usdm","market_type":"perpetual_futures","symbol":"ETHUSDT","event_time_ms":1783517069422,"received_time_ms":1783517069419,"trace_id":"f48fb1ae-d5d6-4c25-9a5f-be8b0ac7a84d","first_update_id":10999770830681,"final_update_id":10999770844120,"previous_final_update_id":10999770830523,"bids":[{"price":"1211.11","quantity":"0.389"},{"price":"1226.11","quantity":"3.392"},{"price":"1231.11","quantity":"5.856"},{"price":"1562.49","quantity":"0.026"},{"price":"1562.50","quantity":"4.290"},{"price":"1666.60","quantity":"1.078"},{"price":"1693.95","quantity":"0.016"},{"price":"1701.38","quantity":"43.670"},{"price":"1727.42","quantity":"0.617"},{"price":"1730.01","quantity":"4.410"},{"price":"1731.00","quantity":"77.120"},{"price":"1731.25","quantity":"6.640"},{"price":"1732.39","quantity":"9.271"},{"price":"1732.47","quantity":"22.682"},{"price":"1732.70","quantity":"7.567"},{"price":"1732.72","quantity":"21.088"},{"price":"1733.64","quantity":"423.270"},{"price":"1733.68","quantity":"17.339"},{"price":"1734.06","quantity":"54.181"},{"price":"1734.21","quantity":"18.126"},{"price":"1734.61","quantity":"0.834"},{"price":"1734.98","quantity":"69.923"},{"price":"1735.00","quantity":"217.462"},{"price":"1735.06","quantity":"2.219"},{"price":"1735.09","quantity":"2.035"},{"price":"1735.17","quantity":"1.084"},{"price":"1735.20","quantity":"46.708"},{"price":"1735.23","quantity":"4.905"},{"price":"1735.24","quantity":"7.546"},{"price":"1735.29","quantity":"250.268"},{"price":"1735.30","quantity":"29.159"},{"price":"1735.31","quantity":"33.978"},{"price":"1735.37","quantity":"0.595"},{"price":"1735.38","quantity":"67.276"},{"price":"1735.39","quantity":"39.498"},{"price":"1735.46","quantity":"19.608"},{"price":"1735.47","quantity":"15.996"},{"price":"1735.51","quantity":"52.524"},{"price":"1735.53","quantity":"5.781"},{"price":"1735.59","quantity":"7.353"},{"price":"1735.67","quantity":"0.063"},{"price":"1735.70","quantity":"5.798"},{"price":"1735.71","quantity":"0.038"},{"price":"1735.74","quantity":"29.406"},{"price":"1735.75","quantity":"72.244"},{"price":"1735.76","quantity":"14.584"},{"price":"1735.77","quantity":"14.192"},{"price":"1735.78","quantity":"3.944"},{"price":"1735.79","quantity":"5.316"},{"price":"1735.80","quantity":"2.112"},{"price":"1735.81","quantity":"7.056"},{"price":"1735.84","quantity":"0.058"},{"price":"1735.86","quantity":"72.946"},{"price":"1735.87","quantity":"0.739"},{"price":"1735.90","quantity":"6.576"},{"price":"1735.91","quantity":"11.973"},{"price":"1735.92","quantity":"25.386"},{"price":"1735.93","quantity":"9.440"},{"price":"1735.97","quantity":"4.823"},{"price":"1735.98","quantity":"1.036"},{"price":"1735.99","quantity":"0.139"},{"price":"1736.00","quantity":"2.489"},{"price":"1736.02","quantity":"1.789"},{"price":"1736.05","quantity":"0.154"},{"price":"1736.06","quantity":"0.026"},{"price":"1736.07","quantity":"0.047"},{"price":"1736.09","quantity":"1.518"},{"price":"1736.11","quantity":"167.906"}],"asks":[{"price":"1736.12","quantity":"86.317"},{"price":"1736.13","quantity":"8.944"},{"price":"1736.19","quantity":"0.101"},{"price":"1736.20","quantity":"2.820"},{"price":"1736.21","quantity":"0.024"},{"price":"1736.22","quantity":"10.192"},{"price":"1736.28","quantity":"14.775"},{"price":"1736.29","quantity":"1.210"},{"price":"1736.30","quantity":"9.174"},{"price":"1736.32","quantity":"8.783"},{"price":"1736.33","quantity":"2.023"},{"price":"1736.34","quantity":"0.559"},{"price":"1736.40","quantity":"21.369"},{"price":"1736.42","quantity":"8.379"},{"price":"1736.46","quantity":"42.462"},{"price":"1736.47","quantity":"2.139"},{"price":"1736.49","quantity":"2.851"},{"price":"1736.50","quantity":"28.936"},{"price":"1736.57","quantity":"2.094"},{"price":"1736.64","quantity":"76.129"},{"price":"1736.75","quantity":"67.315"},{"price":"1736.77","quantity":"0.161"},{"price":"1736.80","quantity":"43.120"},{"price":"1736.83","quantity":"49.173"},{"price":"1736.87","quantity":"26.251"},{"price":"1736.90","quantity":"40.769"},{"price":"1736.92","quantity":"67.349"},{"price":"1736.98","quantity":"13.096"},{"price":"1737.00","quantity":"83.091"},{"price":"1737.12","quantity":"7.826"},{"price":"1737.23","quantity":"35.967"},{"price":"1737.42","quantity":"3.675"},{"price":"1737.60","quantity":"7.231"},{"price":"1737.68","quantity":"3.610"},{"price":"1737.89","quantity":"7.279"},{"price":"1737.94","quantity":"0.012"},{"price":"1738.03","quantity":"1.667"},{"price":"1738.07","quantity":"440.529"},{"price":"1738.12","quantity":"21.007"},{"price":"1738.13","quantity":"19.864"},{"price":"1738.14","quantity":"16.295"},{"price":"1738.80","quantity":"1.464"},{"price":"1738.88","quantity":"1.079"},{"price":"1738.94","quantity":"7.156"},{"price":"1738.96","quantity":"3.196"},{"price":"1738.98","quantity":"43.748"},{"price":"1739.42","quantity":"20.408"},{"price":"1740.58","quantity":"18.016"},{"price":"1742.47","quantity":"17.246"},{"price":"1744.81","quantity":"0.166"},{"price":"1747.12","quantity":"15.000"},{"price":"1763.03","quantity":"22.927"},{"price":"2634.54","quantity":"0.001"},{"price":"2634.55","quantity":"0.001"},{"price":"2634.63","quantity":"0.009"},{"price":"2634.64","quantity":"0.000"}],"raw":{"e":"depthUpdate","E":1783517069422,"T":1783517069421,"s":"ETHUSDT","ps":"ETHUSDT","U":10999770830681,"u":10999770844120,"pu":10999770830523,"b":[["1211.11","0.389"],["1226.11","3.392"],["1231.11","5.856"],["1562.49","0.026"],["1562.50","4.290"],["1666.60","1.078"],["1693.95","0.016"],["1701.38","43.670"],["1727.42","0.617"],["1730.01","4.410"],["1731.00","77.120"],["1731.25","6.640"],["1732.39","9.271"],["1732.47","22.682"],["1732.70","7.567"],["1732.72","21.088"],["1733.64","423.270"],["1733.68","17.339"],["1734.06","54.181"],["1734.21","18.126"],["1734.61","0.834"],["1734.98","69.923"],["1735.00","217.462"],["1735.06","2.219"],["1735.09","2.035"],["1735.17","1.084"],["1735.20","46.708"],["1735.23","4.905"],["1735.24","7.546"],["1735.29","250.268"],["1735.30","29.159"],["1735.31","33.978"],["1735.37","0.595"],["1735.38","67.276"],["1735.39","39.498"],["1735.46","19.608"],["1735.47","15.996"],["1735.51","52.524"],["1735.53","5.781"],["1735.59","7.353"],["1735.67","0.063"],["1735.70","5.798"],["1735.71","0.038"],["1735.74","29.406"],["1735.75","72.244"],["1735.76","14.584"],["1735.77","14.192"],["1735.78","3.944"],["1735.79","5.316"],["1735.80","2.112"],["1735.81","7.056"],["1735.84","0.058"],["1735.86","72.946"],["1735.87","0.739"],["1735.90","6.576"],["1735.91","11.973"],["1735.92","25.386"],["1735.93","9.440"],["1735.97","4.823"],["1735.98","1.036"],["1735.99","0.139"],["1736.00","2.489"],["1736.02","1.789"],["1736.05","0.154"],["1736.06","0.026"],["1736.07","0.047"],["1736.09","1.518"],["1736.11","167.906"]],"a":[["1736.12","86.317"],["1736.13","8.944"],["1736.19","0.101"],["1736.20","2.820"],["1736.21","0.024"],["1736.22","10.192"],["1736.28","14.775"],["1736.29","1.210"],["1736.30","9.174"],["1736.32","8.783"],["1736.33","2.023"],["1736.34","0.559"],["1736.40","21.369"],["1736.42","8.379"],["1736.46","42.462"],["1736.47","2.139"],["1736.49","2.851"],["1736.50","28.936"],["1736.57","2.094"],["1736.64","76.129"],["1736.75","67.315"],["1736.77","0.161"],["1736.80","43.120"],["1736.83","49.173"],["1736.87","26.251"],["1736.90","40.769"],["1736.92","67.349"],["1736.98","13.096"],["1737.00","83.091"],["1737.12","7.826"],["1737.23","35.967"],["1737.42","3.675"],["1737.60","7.231"],["1737.68","3.610"],["1737.89","7.279"],["1737.94","0.012"],["1738.03","1.667"],["1738.07","440.529"],["1738.12","21.007"],["1738.13","19.864"],["1738.14","16.295"],["1738.80","1.464"],["1738.88","1.079"],["1738.94","7.156"],["1738.96","3.196"],["1738.98","43.748"],["1739.42","20.408"],["1740.58","18.016"],["1742.47","17.246"],["1744.81","0.166"],["1747.12","15.000"],["1763.03","22.927"],["2634.54","0.001"],["2634.55","0.001"],["2634.63","0.009"],["2634.64","0.000"]],"st":1}}
{"schema_version":"1.3.0","event_id":"e43a0211-48a0-477c-ab7c-8f20e586d1eb","event_type":"raw.depth_update","source":"binance_market_data_recorder","venue":"binance_usdm","market_type":"perpetual_futures","symbol":"ETHUSDT","event_time_ms":1783517069524,"received_time_ms":1783517069519,"trace_id":"cdcdaf7f-b12b-43b2-ae24-9d5d0863e91e","first_update_id":10999770844229,"final_update_id":10999770857138,"previous_final_update_id":10999770844120,"bids":[{"price":"200.00","quantity":"7.594"},{"price":"201.00","quantity":"2.300"},{"price":"1211.11","quantity":"0.133"},{"price":"1226.11","quantity":"3.936"},{"price":"1231.11","quantity":"5.568"},{"price":"1562.49","quantity":"0.026"},{"price":"1562.50","quantity":"4.176"},{"price":"1666.60","quantity":"1.193"},{"price":"1699.08","quantity":"59.375"},{"price":"1701.38","quantity":"43.641"},{"price":"1702.05","quantity":"17.650"},{"price":"1704.85","quantity":"32.496"},{"price":"1714.32","quantity":"0.000"},{"price":"1714.41","quantity":"81.538"},{"price":"1733.17","quantity":"1.452"},{"price":"1733.59","quantity":"22.671"},{"price":"1733.64","quantity":"2.894"},{"price":"1733.70","quantity":"436.976"},{"price":"1734.06","quantity":"54.181"},{"price":"1734.88","quantity":"21.974"},{"price":"1734.98","quantity":"69.905"},{"price":"1735.00","quantity":"217.480"},{"price":"1735.06","quantity":"0.127"},{"price":"1735.07","quantity":"6.117"},{"price":"1735.11","quantity":"45.389"},{"price":"1735.12","quantity":"132.938"},{"price":"1735.19","quantity":"72.207"},{"price":"1735.20","quantity":"47.754"},{"price":"1735.29","quantity":"29.664"},{"price":"1735.32","quantity":"26.988"},{"price":"1735.33","quantity":"237.068"},{"price":"1735.34","quantity":"0.098"},{"price":"1735.46","quantity":"19.608"},{"price":"1735.50","quantity":"239.319"},{"price":"1735.73","quantity":"26.047"},{"price":"1735.77","quantity":"10.996"},{"price":"1735.78","quantity":"1.640"},{"price":"1735.80","quantity":"30.944"},{"price":"1735.81","quantity":"6.958"},{"price":"1735.84","quantity":"0.156"},{"price":"1735.87","quantity":"3.043"},{"price":"1735.99","quantity":"1.291"},{"price":"1736.02","quantity":"1.812"},{"price":"1736.05","quantity":"0.063"},{"price":"1736.08","quantity":"0.821"},{"price":"1736.11","quantity":"168.021"}],"asks":[{"price":"1736.12","quantity":"79.526"},{"price":"1736.15","quantity":"0.024"},{"price":"1736.16","quantity":"1.167"},{"price":"1736.20","quantity":"0.052"},{"price":"1736.23","quantity":"20.052"},{"price":"1736.24","quantity":"0.141"},{"price":"1736.28","quantity":"14.688"},{"price":"1736.31","quantity":"17.453"},{"price":"1736.34","quantity":"0.059"},{"price":"1736.37","quantity":"18.228"},{"price":"1736.39","quantity":"15.775"},{"price":"1736.40","quantity":"12.729"},{"price":"1736.46","quantity":"38.086"},{"price":"1736.47","quantity":"7.668"},{"price":"1736.50","quantity":"0.114"},{"price":"1736.52","quantity":"0.087"},{"price":"1736.54","quantity":"31.690"},{"price":"1736.59","quantity":"7.592"},{"price":"1736.63","quantity":"13.197"},{"price":"1736.90","quantity":"42.436"},{"price":"1764.05","quantity":"100.856"},{"price":"1769.65","quantity":"0.000"},{"price":"1770.07","quantity":"59.806"},{"price":"2634.53","quantity":"0.001"},{"price":"2634.62","quantity":"0.000"}],"raw":{"e":"depthUpdate","E":1783517069524,"T":1783517069523,"s":"ETHUSDT","ps":"ETHUSDT","U":10999770844229,"u":10999770857138,"pu":10999770844120,"b":[["200.00","7.594"],["201.00","2.300"],["1211.11","0.133"],["1226.11","3.936"],["1231.11","5.568"],["1562.49","0.026"],["1562.50","4.176"],["1666.60","1.193"],["1699.08","59.375"],["1701.38","43.641"],["1702.05","17.650"],["1704.85","32.496"],["1714.32","0.000"],["1714.41","81.538"],["1733.17","1.452"],["1733.59","22.671"],["1733.64","2.894"],["1733.70","436.976"],["1734.06","54.181"],["1734.88","21.974"],["1734.98","69.905"],["1735.00","217.480"],["1735.06","0.127"],["1735.07","6.117"],["1735.11","45.389"],["1735.12","132.938"],["1735.19","72.207"],["1735.20","47.754"],["1735.29","29.664"],["1735.32","26.988"],["1735.33","237.068"],["1735.34","0.098"],["1735.46","19.608"],["1735.50","239.319"],["1735.73","26.047"],["1735.77","10.996"],["1735.78","1.640"],["1735.80","30.944"],["1735.81","6.958"],["1735.84","0.156"],["1735.87","3.043"],["1735.99","1.291"],["1736.02","1.812"],["1736.05","0.063"],["1736.08","0.821"],["1736.11","168.021"]],"a":[["1736.12","79.526"],["1736.15","0.024"],["1736.16","1.167"],["1736.20","0.052"],["1736.23","20.052"],["1736.24","0.141"],["1736.28","14.688"],["1736.31","17.453"],["1736.34","0.059"],["1736.37","18.228"],["1736.39","15.775"],["1736.40","12.729"],["1736.46","38.086"],["1736.47","7.668"],["1736.50","0.114"],["1736.52","0.087"],["1736.54","31.690"],["1736.59","7.592"],["1736.63","13.197"],["1736.90","42.436"],["1764.05","100.856"],["1769.65","0.000"],["1770.07","59.806"],["2634.53","0.001"],["2634.62","0.000"]],"st":1}}
{"schema_version":"1.3.0","event_id":"c08e4d77-e9e5-438f-8edd-043b183c383f","event_type":"raw.depth_update","source":"binance_market_data_recorder","venue":"binance_usdm","market_type":"perpetual_futures","symbol":"ETHUSDT","event_time_ms":1783517069626,"received_time_ms":1783517069621,"trace_id":"640bdfce-621f-4f5e-84d0-0fba7ff45016","first_update_id":10999770857231,"final_update_id":10999770865301,"previous_final_update_id":10999770857138,"bids":[{"price":"200.00","quantity":"7.594"},{"price":"1211.11","quantity":"0.037"},{"price":"1226.11","quantity":"4.672"},{"price":"1231.11","quantity":"4.928"},{"price":"1562.04","quantity":"0.140"},{"price":"1562.49","quantity":"0.026"},{"price":"1562.50","quantity":"4.176"},{"price":"1666.60","quantity":"1.078"},{"price":"1692.70","quantity":"91.767"},{"price":"1701.39","quantity":"32.216"},{"price":"1707.92","quantity":"24.853"},{"price":"1710.39","quantity":"316.357"},{"price":"1732.19","quantity":"0.100"},{"price":"1733.70","quantity":"16.600"},{"price":"1734.06","quantity":"473.253"},{"price":"1734.15","quantity":"0.490"},{"price":"1735.18","quantity":"0.694"},{"price":"1735.33","quantity":"16.517"},{"price":"1735.53","quantity":"9.093"},{"price":"1735.61","quantity":"8.709"},{"price":"1735.76","quantity":"11.272"},{"price":"1735.99","quantity":"9.939"},{"price":"1736.00","quantity":"5.557"}],"asks":[{"price":"1736.12","quantity":"79.366"},{"price":"1736.20","quantity":"0.072"},{"price":"1736.46","quantity":"42.293"},{"price":"1736.52","quantity":"0.256"},{"price":"1736.63","quantity":"8.870"},{"price":"1736.90","quantity":"31.436"},{"price":"1737.03","quantity":"86.757"},{"price":"1737.12","quantity":"7.826"},{"price":"1737.23","quantity":"32.967"},{"price":"1737.42","quantity":"5.342"},{"price":"1737.51","quantity":"0.218"},{"price":"1738.89","quantity":"56.549"},{"price":"1740.14","quantity":"0.000"},{"price":"1742.16","quantity":"18.982"},{"price":"1742.23","quantity":"9.044"},{"price":"1742.28","quantity":"0.137"},{"price":"1757.09","quantity":"44.357"},{"price":"2634.51","quantity":"0.001"},{"price":"2634.52","quantity":"0.001"},{"price":"2634.60","quantity":"0.000"},{"price":"2634.61","quantity":"0.118"}],"raw":{"e":"depthUpdate","E":1783517069626,"T":1783517069625,"s":"ETHUSDT","ps":"ETHUSDT","U":10999770857231,"u":10999770865301,"pu":10999770857138,"b":[["200.00","7.594"],["1211.11","0.037"],["1226.11","4.672"],["1231.11","4.928"],["1562.04","0.140"],["1562.49","0.026"],["1562.50","4.176"],["1666.60","1.078"],["1692.70","91.767"],["1701.39","32.216"],["1707.92","24.853"],["1710.39","316.357"],["1732.19","0.100"],["1733.70","16.600"],["1734.06","473.253"],["1734.15","0.490"],["1735.18","0.694"],["1735.33","16.517"],["1735.53","9.093"],["1735.61","8.709"],["1735.76","11.272"],["1735.99","9.939"],["1736.00","5.557"]],"a":[["1736.12","79.366"],["1736.20","0.072"],["1736.46","42.293"],["1736.52","0.256"],["1736.63","8.870"],["1736.90","31.436"],["1737.03","86.757"],["1737.12","7.826"],["1737.23","32.967"],["1737.42","5.342"],["1737.51","0.218"],["1738.89","56.549"],["1740.14","0.000"],["1742.16","18.982"],["1742.23","9.044"],["1742.28","0.137"],["1757.09","44.357"],["2634.51","0.001"],["2634.52","0.001"],["2634.60","0.000"],["2634.61","0.118"]],"st":1}}
{"schema_version":"1.3.0","event_id":"10f08033-43f0-44b9-8d38-89babbbb0899","event_type":"raw.depth_update","source":"binance_market_data_recorder","venue":"binance_usdm","market_type":"perpetual_futures","symbol":"ETHUSDT","event_time_ms":1783517069730,"received_time_ms":1783517069724,"trace_id":"b989c978-04ee-4784-99cf-0bd534afed89","first_update_id":10999770865635,"final_update_id":10999770873125,"previous_final_update_id":10999770865301,"bids":[{"price":"1226.11","quantity":"5.504"},{"price":"1231.11","quantity":"4.096"},{"price":"1562.49","quantity":"0.026"},{"price":"1562.50","quantity":"4.176"},{"price":"1687.87","quantity":"0.189"},{"price":"1701.39","quantity":"32.187"},{"price":"1719.12","quantity":"3.115"},{"price":"1732.14","quantity":"42.402"},{"price":"1735.45","quantity":"220.714"},{"price":"1735.50","quantity":"18.754"},{"price":"1735.63","quantity":"0.576"},{"price":"1735.70","quantity":"5.786"},{"price":"1735.73","quantity":"31.813"},{"price":"1735.91","quantity":"11.685"},{"price":"1735.94","quantity":"9.556"},{"price":"1735.98","quantity":"1.324"},{"price":"1736.09","quantity":"1.532"}],"asks":[{"price":"1736.12","quantity":"62.931"},{"price":"1736.18","quantity":"0.065"},{"price":"1736.31","quantity":"17.453"},{"price":"1736.33","quantity":"1.735"},{"price":"1736.37","quantity":"18.516"},{"price":"1736.50","quantity":"0.102"},{"price":"1737.35","quantity":"0.044"},{"price":"1737.54","quantity":"1.118"},{"price":"1737.89","quantity":"33.409"},{"price":"1740.09","quantity":"37.626"},{"price":"1742.31","quantity":"11.636"},{"price":"1742.32","quantity":"0.013"},{"price":"1747.12","quantity":"0.000"},{"price":"1762.77","quantity":"25.808"},{"price":"1768.76","quantity":"155.305"},{"price":"1769.13","quantity":"11.336"},{"price":"2634.50","quantity":"0.001"},{"price":"2634.59","quantity":"0.000"}],"raw":{"e":"depthUpdate","E":1783517069730,"T":1783517069729,"s":"ETHUSDT","ps":"ETHUSDT","U":10999770865635,"u":10999770873125,"pu":10999770865301,"b":[["1226.11","5.504"],["1231.11","4.096"],["1562.49","0.026"],["1562.50","4.176"],["1687.87","0.189"],["1701.39","32.187"],["1719.12","3.115"],["1732.14","42.402"],["1735.45","220.714"],["1735.50","18.754"],["1735.63","0.576"],["1735.70","5.786"],["1735.73","31.813"],["1735.91","11.685"],["1735.94","9.556"],["1735.98","1.324"],["1736.09","1.532"]],"a":[["1736.12","62.931"],["1736.18","0.065"],["1736.31","17.453"],["1736.33","1.735"],["1736.37","18.516"],["1736.50","0.102"],["1737.35","0.044"],["1737.54","1.118"],["1737.89","33.409"],["1740.09","37.626"],["1742.31","11.636"],["1742.32","0.013"],["1747.12","0.000"],["1762.77","25.808"],["1768.76","155.305"],["1769.13","11.336"],["2634.50","0.001"],["2634.59","0.000"]],"st":1}}
{"schema_version":"1.3.0","event_id":"c3740863-1ec6-4cad-9dc3-79982e74655a","event_type":"raw.depth_update","source":"binance_market_data_recorder","venue":"binance_usdm","market_type":"perpetual_futures","symbol":"ETHUSDT","event_time_ms":1783517069834,"received_time_ms":1783517069828,"trace_id":"7e70c9e4-79f3-450a-b98a-e1f493d4cfc2","first_update_id":10999770873511,"final_update_id":10999770879690,"previous_final_update_id":10999770873125,"bids":[{"price":"200.00","quantity":"7.594"},{"price":"1226.11","quantity":"6.336"},{"price":"1231.11","quantity":"3.264"},{"price":"1562.49","quantity":"0.026"},{"price":"1562.50","quantity":"4.432"},{"price":"1666.60","quantity":"1.193"},{"price":"1706.13","quantity":"0.000"},{"price":"1710.08","quantity":"112.553"},{"price":"1714.74","quantity":"35.375"},{"price":"1715.12","quantity":"11.644"},{"price":"1729.25","quantity":"1.285"},{"price":"1729.85","quantity":"22.358"},{"price":"1730.67","quantity":"0.000"},{"price":"1734.06","quantity":"54.181"},{"price":"1734.12","quantity":"474.969"},{"price":"1735.11","quantity":"45.389"},{"price":"1735.31","quantity":"254.509"},{"price":"1735.45","quantity":"0.178"},{"price":"1735.55","quantity":"4.604"},{"price":"1735.67","quantity":"0.128"},{"price":"1735.70","quantity":"5.798"},{"price":"1735.71","quantity":"5.804"},{"price":"1735.73","quantity":"27.747"},{"price":"1736.03","quantity":"1.154"}],"asks":[{"price":"1736.12","quantity":"73.552"},{"price":"1736.13","quantity":"8.956"},{"price":"1736.19","quantity":"0.012"},{"price":"1736.23","quantity":"20.141"},{"price":"1736.36","quantity":"22.091"},{"price":"1736.46","quantity":"45.089"},{"price":"1736.50","quantity":"1.814"},{"price":"1736.68","quantity":"4.705"},{"price":"1736.90","quantity":"29.769"},{"price":"1736.91","quantity":"68.135"},{"price":"1736.97","quantity":"4.979"},{"price":"1737.00","quantity":"94.091"},{"price":"1737.02","quantity":"22.435"},{"price":"1737.60","quantity":"4.591"},{"price":"1738.80","quantity":"5.949"},{"price":"1738.94","quantity":"3.960"},{"price":"1741.41","quantity":"10.358"},{"price":"1748.86","quantity":"0.123"},{"price":"1755.22","quantity":"33.090"},{"price":"1768.24","quantity":"38.974"},{"price":"2634.48","quantity":"0.149"},{"price":"2634.49","quantity":"0.001"},{"price":"2634.57","quantity":"0.000"},{"price":"2634.58","quantity":"0.000"}],"raw":{"e":"depthUpdate","E":1783517069834,"T":1783517069833,"s":"ETHUSDT","ps":"ETHUSDT","U":10999770873511,"u":10999770879690,"pu":10999770873125,"b":[["200.00","7.594"],["1226.11","6.336"],["1231.11","3.264"],["1562.49","0.026"],["1562.50","4.432"],["1666.60","1.193"],["1706.13","0.000"],["1710.08","112.553"],["1714.74","35.375"],["1715.12","11.644"],["1729.25","1.285"],["1729.85","22.358"],["1730.67","0.000"],["1734.06","54.181"],["1734.12","474.969"],["1735.11","45.389"],["1735.31","254.509"],["1735.45","0.178"],["1735.55","4.604"],["1735.67","0.128"],["1735.70","5.798"],["1735.71","5.804"],["1735.73","27.747"],["1736.03","1.154"]],"a":[["1736.12","73.552"],["1736.13","8.956"],["1736.19","0.012"],["1736.23","20.141"],["1736.36","22.091"],["1736.46","45.089"],["1736.50","1.814"],["1736.68","4.705"],["1736.90","29.769"],["1736.91","68.135"],["1736.97","4.979"],["1737.00","94.091"],["1737.02","22.435"],["1737.60","4.591"],["1738.80","5.949"],["1738.94","3.960"],["1741.41","10.358"],["1748.86","0.123"],["1755.22","33.090"],["1768.24","38.974"],["2634.48","0.149"],["2634.49","0.001"],["2634.57","0.000"],["2634.58","0.000"]],"st":1}}
{"schema_version":"1.3.0","event_id":"48c61ef5-c7f9-49e3-b4f5-bd5d34958147","event_type":"raw.depth_update","source":"binance_market_data_recorder","venue":"binance_usdm","market_type":"perpetual_futures","symbol":"ETHUSDT","event_time_ms":1783517069938,"received_time_ms":1783517069932,"trace_id":"dc1956d0-7132-42ff-84a6-075cdcac8a17","first_update_id":10999770879947,"final_update_id":10999770885423,"previous_final_update_id":10999770879690,"bids":[{"price":"200.00","quantity":"7.594"},{"price":"1221.11","quantity":"0.064"},{"price":"1226.11","quantity":"7.040"},{"price":"1231.11","quantity":"2.496"},{"price":"1562.49","quantity":"0.026"},{"price":"1562.50","quantity":"4.304"},{"price":"1666.60","quantity":"1.078"},{"price":"1701.39","quantity":"32.216"},{"price":"1706.77","quantity":"25.781"},{"price":"1708.50","quantity":"83.080"},{"price":"1730.76","quantity":"17.121"},{"price":"1734.12","quantity":"55.897"},{"price":"1734.18","quantity":"419.084"},{"price":"1735.96","quantity":"0.840"},{"price":"1735.98","quantity":"1.036"}],"asks":[{"price":"1736.60","quantity":"5.151"},{"price":"1736.98","quantity":"13.000"},{"price":"1737.34","quantity":"13.215"},{"price":"1737.68","quantity":"3.610"},{"price":"1737.82","quantity":"42.838"},{"price":"1737.86","quantity":"20.145"},{"price":"1738.12","quantity":"4.331"},{"price":"1738.96","quantity":"0.000"},{"price":"1741.55","quantity":"14.286"},{"price":"1744.60","quantity":"88.497"},{"price":"1768.24","quantity":"50.268"},{"price":"2634.47","quantity":"0.001"},{"price":"2634.56","quantity":"0.000"}],"raw":{"e":"depthUpdate","E":1783517069938,"T":1783517069937,"s":"ETHUSDT","ps":"ETHUSDT","U":10999770879947,"u":10999770885423,"pu":10999770879690,"b":[["200.00","7.594"],["1221.11","0.064"],["1226.11","7.040"],["1231.11","2.496"],["1562.49","0.026"],["1562.50","4.304"],["1666.60","1.078"],["1701.39","32.216"],["1706.77","25.781"],["1708.50","83.080"],["1730.76","17.121"],["1734.12","55.897"],["1734.18","419.084"],["1735.96","0.840"],["1735.98","1.036"]],"a":[["1736.60","5.151"],["1736.98","13.000"],["1737.34","13.215"],["1737.68","3.610"],["1737.82","42.838"],["1737.86","20.145"],["1738.12","4.331"],["1738.96","0.000"],["1741.55","14.286"],["1744.60","88.497"],["1768.24","50.268"],["2634.47","0.001"],["2634.56","0.000"]],"st":1}}
{"schema_version":"1.3.0","event_id":"1d2a675f-bec3-4ddc-9d71-4d647b3feb23","event_type":"raw.depth_update","source":"binance_market_data_recorder","venue":"binance_usdm","market_type":"perpetual_futures","symbol":"ETHUSDT","event_time_ms":1783517070040,"received_time_ms":1783517070035,"trace_id":"5c3709c2-fb93-4cac-92fb-793015fc168a","first_update_id":10999770885484,"final_update_id":10999770892193,"previous_final_update_id":10999770885423,"bids":[{"price":"1221.11","quantity":"0.320"},{"price":"1226.11","quantity":"7.328"},{"price":"1231.11","quantity":"1.952"},{"price":"1562.49","quantity":"0.026"},{"price":"1562.50","quantity":"4.318"},{"price":"1666.60","quantity":"1.193"},{"price":"1701.39","quantity":"32.187"},{"price":"1704.86","quantity":"32.357"},{"price":"1708.44","quantity":"51.352"},{"price":"1710.34","quantity":"29.258"},{"price":"1716.55","quantity":"58.711"},{"price":"1733.91","quantity":"3.661"},{"price":"1734.99","quantity":"0.122"},{"price":"1735.17","quantity":"0.047"},{"price":"1735.19","quantity":"70.115"},{"price":"1735.20","quantity":"48.803"},{"price":"1735.21","quantity":"34.744"},{"price":"1735.31","quantity":"33.978"},{"price":"1735.41","quantity":"344.695"},{"price":"1735.76","quantity":"11.416"},{"price":"1736.11","quantity":"168.957"}],"asks":[{"price":"1736.12","quantity":"73.564"},{"price":"1736.13","quantity":"9.832"},{"price":"1736.16","quantity":"0.291"},{"price":"1736.19","quantity":"0.101"},{"price":"1736.23","quantity":"20.052"},{"price":"1736.31","quantity":"17.453"},{"price":"1736.47","quantity":"7.812"},{"price":"1736.65","quantity":"17.640"},{"price":"1736.70","quantity":"11.247"},{"price":"1737.12","quantity":"7.826"},{"price":"1737.77","quantity":"17.434"},{"price":"1738.03","quantity":"0.000"},{"price":"1738.97","quantity":"185.116"},{"price":"1747.12","quantity":"15.000"},{"price":"2634.46","quantity":"0.001"},{"price":"2634.55","quantity":"0.000"}],"raw":{"e":"depthUpdate","E":1783517070040,"T":1783517070037,"s":"ETHUSDT","ps":"ETHUSDT","U":10999770885484,"u":10999770892193,"pu":10999770885423,"b":[["1221.11","0.320"],["1226.11","7.328"],["1231.11","1.952"],["1562.49","0.026"],["1562.50","4.318"],["1666.60","1.193"],["1701.39","32.187"],["1704.86","32.357"],["1708.44","51.352"],["1710.34","29.258"],["1716.55","58.711"],["1733.91","3.661"],["1734.99","0.122"],["1735.17","0.047"],["1735.19","70.115"],["1735.20","48.803"],["1735.21","34.744"],["1735.31","33.978"],["1735.41","344.695"],["1735.76","11.416"],["1736.11","168.957"]],"a":[["1736.12","73.564"],["1736.13","9.832"],["1736.16","0.291"],["1736.19","0.101"],["1736.23","20.052"],["1736.31","17.453"],["1736.47","7.812"],["1736.65","17.640"],["1736.70","11.247"],["1737.12","7.826"],["1737.77","17.434"],["1738.03","0.000"],["1738.97","185.116"],["1747.12","15.000"],["2634.46","0.001"],["2634.55","0.000"]],"st":1}}
{"schema_version":"1.3.0","event_id":"37ea3425-7745-4624-b905-2b7b358e5531","event_type":"raw.depth_update","source":"binance_market_data_recorder","venue":"binance_usdm","market_type":"perpetual_futures","symbol":"ETHUSDT","event_time_ms":1783517070142,"received_time_ms":1783517070283,"trace_id":"1bbeaf40-54ac-4f36-bd44-39aecba4db17","first_update_id":10999770892579,"final_update_id":10999770904137,"previous_final_update_id":10999770892193,"bids":[{"price":"200.00","quantity":"7.594"},{"price":"1221.11","quantity":"0.832"},{"price":"1226.11","quantity":"7.136"},{"price":"1231.11","quantity":"1.632"},{"price":"1562.49","quantity":"0.026"},{"price":"1562.50","quantity":"4.446"},{"price":"1705.46","quantity":"0.630"},{"price":"1708.35","quantity":"29.229"},{"price":"1715.55","quantity":"1.510"},{"price":"1720.65","quantity":"40.932"},{"price":"1732.41","quantity":"7.697"},{"price":"1733.65","quantity":"9.919"},{"price":"1733.66","quantity":"92.522"},{"price":"1733.72","quantity":"3.365"},{"price":"1733.91","quantity":"0.465"},{"price":"1733.93","quantity":"5.192"},{"price":"1734.06","quantity":"473.253"},{"price":"1734.18","quantity":"0.012"},{"price":"1734.95","quantity":"8.702"},{"price":"1735.11","quantity":"45.389"},{"price":"1735.13","quantity":"3.243"},{"price":"1735.26","quantity":"10.582"},{"price":"1735.41","quantity":"124.169"},{"price":"1735.44","quantity":"248.413"},{"price":"1735.48","quantity":"3.753"},{"price":"1735.51","quantity":"50.796"},{"price":"1735.65","quantity":"20.560"},{"price":"1735.76","quantity":"11.272"},{"price":"1735.86","quantity":"68.396"},{"price":"1735.99","quantity":"1.291"},{"price":"1736.01","quantity":"8.698"},{"price":"1736.08","quantity":"2.549"},{"price":"1736.11","quantity":"168.957"}],"asks":[{"price":"1736.12","quantity":"63.189"},{"price":"1736.13","quantity":"9.913"},{"price":"1736.17","quantity":"0.024"},{"price":"1736.23","quantity":"0.052"},{"price":"1736.25","quantity":"22.810"},{"price":"1736.28","quantity":"14.688"},{"price":"1736.29","quantity":"1.210"},{"price":"1736.31","quantity":"17.366"},{"price":"1736.32","quantity":"0.143"},{"price":"1736.33","quantity":"2.887"},{"price":"1736.37","quantity":"17.261"},{"price":"1736.38","quantity":"10.173"},{"price":"1736.42","quantity":"8.297"},{"price":"1736.47","quantity":"7.668"},{"price":"1736.60","quantity":"5.137"},{"price":"1736.67","quantity":"3.518"},{"price":"1736.74","quantity":"24.750"},{"price":"1736.87","quantity":"26.347"},{"price":"1736.88","quantity":"12.332"},{"price":"1737.03","quantity":"83.757"},{"price":"1737.09","quantity":"38.747"},{"price":"1737.18","quantity":"22.765"},{"price":"1737.24","quantity":"3.141"},{"price":"1737.39","quantity":"3.266"},{"price":"1738.00","quantity":"30.932"},{"price":"1738.07","quantity":"32.889"},{"price":"1738.25","quantity":"411.712"},{"price":"1738.96","quantity":"3.196"},{"price":"1738.98","quantity":"40.552"},{"price":"1743.35","quantity":"18.586"},{"price":"1762.88","quantity":"1304.330"},{"price":"1763.89","quantity":"19.842"},{"price":"2634.44","quantity":"0.001"},{"price":"2634.45","quantity":"0.001"},{"price":"2634.53","quantity":"0.000"},{"price":"2634.54","quantity":"0.000"}],"raw":{"e":"depthUpdate","E":1783517070142,"T":1783517070141,"s":"ETHUSDT","ps":"ETHUSDT","U":10999770892579,"u":10999770904137,"pu":10999770892193,"b":[["200.00","7.594"],["1221.11","0.832"],["1226.11","7.136"],["1231.11","1.632"],["1562.49","0.026"],["1562.50","4.446"],["1705.46","0.630"],["1708.35","29.229"],["1715.55","1.510"],["1720.65","40.932"],["1732.41","7.697"],["1733.65","9.919"],["1733.66","92.522"],["1733.72","3.365"],["1733.91","0.465"],["1733.93","5.192"],["1734.06","473.253"],["1734.18","0.012"],["1734.95","8.702"],["1735.11","45.389"],["1735.13","3.243"],["1735.26","10.582"],["1735.41","124.169"],["1735.44","248.413"],["1735.48","3.753"],["1735.51","50.796"],["1735.65","20.560"],["1735.76","11.272"],["1735.86","68.396"],["1735.99","1.291"],["1736.01","8.698"],["1736.08","2.549"],["1736.11","168.957"]],"a":[["1736.12","63.189"],["1736.13","9.913"],["1736.17","0.024"],["1736.23","0.052"],["1736.25","22.810"],["1736.28","14.688"],["1736.29","1.210"],["1736.31","17.366"],["1736.32","0.143"],["1736.33","2.887"],["1736.37","17.261"],["1736.38","10.173"],["1736.42","8.297"],["1736.47","7.668"],["1736.60","5.137"],["1736.67","3.518"],["1736.74","24.750"],["1736.87","26.347"],["1736.88","12.332"],["1737.03","83.757"],["1737.09","38.747"],["1737.18","22.765"],["1737.24","3.141"],["1737.39","3.266"],["1738.00","30.932"],["1738.07","32.889"],["1738.25","411.712"],["1738.96","3.196"],["1738.98","40.552"],["1743.35","18.586"],["1762.88","1304.330"],["1763.89","19.842"],["2634.44","0.001"],["2634.45","0.001"],["2634.53","0.000"],["2634.54","0.000"]],"st":1}}
{"schema_version":"1.3.0","event_id":"2dbed377-70c4-4043-8efe-7167784b14fd","event_type":"raw.depth_update","source":"binance_market_data_recorder","venue":"binance_usdm","market_type":"perpetual_futures","symbol":"ETHUSDT","event_time_ms":1783517070244,"received_time_ms":1783517070312,"trace_id":"eed296a9-727f-4b5e-bfa9-6d0c0429b570","first_update_id":10999770904283,"final_update_id":10999770916232,"previous_final_update_id":10999770904137,"bids":[{"price":"200.00","quantity":"7.594"},{"price":"1221.11","quantity":"1.376"},{"price":"1226.11","quantity":"6.848"},{"price":"1231.11","quantity":"1.376"},{"price":"1562.04","quantity":"0.126"},{"price":"1562.49","quantity":"0.026"},{"price":"1562.50","quantity":"4.318"},{"price":"1666.60","quantity":"1.078"},{"price":"1685.32","quantity":"0.106"},{"price":"1696.18","quantity":"15.810"},{"price":"1701.39","quantity":"32.216"},{"price":"1704.86","quantity":"61.641"},{"price":"1708.35","quantity":"29.564"},{"price":"1732.52","quantity":"0.000"},{"price":"1732.53","quantity":"1.871"},{"price":"1733.13","quantity":"40.100"},{"price":"1733.14","quantity":"19.085"},{"price":"1733.66","quantity":"23.837"},{"price":"1733.72","quantity":"0.169"},{"price":"1733.92","quantity":"18.830"},{"price":"1733.93","quantity":"6.942"},{"price":"1734.65","quantity":"13.554"},{"price":"1735.00","quantity":"217.480"},{"price":"1735.09","quantity":"2.635"},{"price":"1735.14","quantity":"9.518"},{"price":"1735.15","quantity":"6.463"},{"price":"1735.26","quantity":"231.048"},{"price":"1735.35","quantity":"18.173"},{"price":"1735.42","quantity":"20.653"},{"price":"1735.44","quantity":"27.914"},{"price":"1735.48","quantity":"0.874"},{"price":"1736.01","quantity":"8.698"},{"price":"1736.09","quantity":"1.532"}],"asks":[{"price":"1736.12","quantity":"73.785"},{"price":"1736.13","quantity":"9.955"},{"price":"1736.17","quantity":"0.036"},{"price":"1736.20","quantity":"0.084"},{"price":"1736.24","quantity":"0.156"},{"price":"1736.25","quantity":"23.962"},{"price":"1736.31","quantity":"17.453"},{"price":"1736.34","quantity":"4.978"},{"price":"1736.81","quantity":"22.200"},{"price":"1737.01","quantity":"74.995"},{"price":"1737.02","quantity":"22.592"},{"price":"1737.03","quantity":"83.938"},{"price":"1737.08","quantity":"16.761"},{"price":"1737.12","quantity":"7.826"},{"price":"1737.16","quantity":"17.090"},{"price":"1737.26","quantity":"6.084"},{"price":"1737.42","quantity":"3.675"},{"price":"1737.51","quantity":"11.738"},{"price":"1738.12","quantity":"5.998"},{"price":"1738.14","quantity":"425.129"},{"price":"1738.17","quantity":"7.677"},{"price":"1738.20","quantity":"0.256"},{"price":"1738.25","quantity":"2.878"},{"price":"1743.22","quantity":"33.087"},{"price":"1747.12","quantity":"0.000"},{"price":"1758.26","quantity":"11.370"},{"price":"1763.20","quantity":"60.263"},{"price":"1763.89","quantity":"20.177"},{"price":"2634.43","quantity":"0.001"},{"price":"2634.52","quantity":"0.000"}],"raw":{"e":"depthUpdate","E":1783517070244,"T":1783517070241,"s":"ETHUSDT","ps":"ETHUSDT","U":10999770904283,"u":10999770916232,"pu":10999770904137,"b":[["200.00","7.594"],["1221.11","1.376"],["1226.11","6.848"],["1231.11","1.376"],["1562.04","0.126"],["1562.49","0.026"],["1562.50","4.318"],["1666.60","1.078"],["1685.32","0.106"],["1696.18","15.810"],["1701.39","32.216"],["1704.86","61.641"],["1708.35","29.564"],["1732.52","0.000"],["1732.53","1.871"],["1733.13","40.100"],["1733.14","19.085"],["1733.66","23.837"],["1733.72","0.169"],["1733.92","18.830"],["1733.93","6.942"],["1734.65","13.554"],["1735.00","217.480"],["1735.09","2.635"],["1735.14","9.518"],["1735.15","6.463"],["1735.26","231.048"],["1735.35","18.173"],["1735.42","20.653"],["1735.44","27.914"],["1735.48","0.874"],["1736.01","8.698"],["1736.09","1.532"]],"a":[["1736.12","73.785"],["1736.13","9.955"],["1736.17","0.036"],["1736.20","0.084"],["1736.24","0.156"],["1736.25","23.962"],["1736.31","17.453"],["1736.34","4.978"],["1736.81","22.200"],["1737.01","74.995"],["1737.02","22.592"],["1737.03","83.938"],["1737.08","16.761"],["1737.12","7.826"],["1737.16","17.090"],["1737.26","6.084"],["1737.42","3.675"],["1737.51","11.738"],["1738.12","5.998"],["1738.14","425.129"],["1738.17","7.677"],["1738.20","0.256"],["1738.25","2.878"],["1743.22","33.087"],["1747.12","0.000"],["1758.26","11.370"],["1763.20","60.263"],["1763.89","20.177"],["2634.43","0.001"],["2634.52","0.000"]],"st":1}}
{"schema_version":"1.3.0","event_id":"049bdebc-47a6-4904-aa2b-3394a23b7f50","event_type":"raw.depth_update","source":"binance_market_data_recorder","venue":"binance_usdm","market_type":"perpetual_futures","symbol":"ETHUSDT","event_time_ms":1783517070346,"received_time_ms":1783517070345,"trace_id":"9e297c1e-c1eb-4dcd-bdca-0df2daeba8d6","first_update_id":10999770916457,"final_update_id":10999770925181,"previous_final_update_id":10999770916232,"bids":[{"price":"1221.11","quantity":"1.920"},{"price":"1226.11","quantity":"6.592"},{"price":"1231.11","quantity":"1.088"},{"price":"1562.49","quantity":"0.026"},{"price":"1562.50","quantity":"4.332"},{"price":"1666.60","quantity":"1.193"},{"price":"1701.39","quantity":"32.187"},{"price":"1708.33","quantity":"135.823"},{"price":"1712.08","quantity":"107.785"},{"price":"1713.54","quantity":"168.322"},{"price":"1713.82","quantity":"34.592"},{"price":"1714.41","quantity":"90.273"},{"price":"1718.74","quantity":"57.600"},{"price":"1720.77","quantity":"142.207"},{"price":"1727.42","quantity":"0.629"},{"price":"1736.09","quantity":"3.014"}],"asks":[{"price":"1736.12","quantity":"62.509"},{"price":"1736.29","quantity":"1.210"},{"price":"1736.34","quantity":"4.978"},{"price":"1736.81","quantity":"19.320"},{"price":"1737.02","quantity":"21.868"},{"price":"1737.03","quantity":"83.757"},{"price":"1737.06","quantity":"22.110"},{"price":"1737.07","quantity":"0.661"},{"price":"1737.16","quantity":"11.330"},{"price":"1737.51","quantity":"0.218"},{"price":"1744.81","quantity":"0.154"},{"price":"1760.69","quantity":"0.000"},{"price":"1762.17","quantity":"51.578"},{"price":"1764.23","quantity":"0.000"},{"price":"2634.41","quantity":"0.001"},{"price":"2634.42","quantity":"0.001"},{"price":"2634.50","quantity":"0.000"},{"price":"2634.51","quantity":"0.000"}],"raw":{"e":"depthUpdate","E":1783517070346,"T":1783517070345,"s":"ETHUSDT","ps":"ETHUSDT","U":10999770916457,"u":10999770925181,"pu":10999770916232,"b":[["1221.11","1.920"],["1226.11","6.592"],["1231.11","1.088"],["1562.49","0.026"],["1562.50","4.332"],["1666.60","1.193"],["1701.39","32.187"],["1708.33","135.823"],["1712.08","107.785"],["1713.54","168.322"],["1713.82","34.592"],["1714.41","90.273"],["1718.74","57.600"],["1720.77","142.207"],["1727.42","0.629"],["1736.09","3.014"]],"a":[["1736.12","62.509"],["1736.29","1.210"],["1736.34","4.978"],["1736.81","19.320"],["1737.02","21.868"],["1737.03","83.757"],["1737.06","22.110"],["1737.07","0.661"],["1737.16","11.330"],["1737.51","0.218"],["1744.81","0.154"],["1760.69","0.000"],["1762.17","51.578"],["1764.23","0.000"],["2634.41","0.001"],["2634.42","0.001"],["2634.50","0.000"],["2634.51","0.000"]],"st":1}}
{"schema_version":"1.3.0","event_id":"5ce97604-8a6f-4f49-90e2-cfda03f627e5","event_type":"raw.depth_update","source":"binance_market_data_recorder","venue":"binance_usdm","market_type":"perpetual_futures","symbol":"ETHUSDT","event_time_ms":1783517070448,"received_time_ms":1783517070455,"trace_id":"7875015b-f10d-4f47-9de2-8442c1ea5bd6","first_update_id":10999770925336,"final_update_id":10999770939113,"previous_final_update_id":10999770925181,"bids":[{"price":"200.00","quantity":"7.594"},{"price":"1221.11","quantity":"2.464"},{"price":"1226.11","quantity":"6.304"},{"price":"1231.11","quantity":"0.832"},{"price":"1562.49","quantity":"0.026"},{"price":"1562.50","quantity":"4.332"},{"price":"1666.60","quantity":"1.078"},{"price":"1703.64","quantity":"116.805"},{"price":"1704.86","quantity":"90.925"},{"price":"1710.07","quantity":"66.409"},{"price":"1711.95","quantity":"12.998"},{"price":"1720.50","quantity":"19.075"},{"price":"1727.42","quantity":"0.641"},{"price":"1730.07","quantity":"135.828"},{"price":"1730.08","quantity":"26.320"},{"price":"1730.09","quantity":"4.351"},{"price":"1732.39","quantity":"9.271"},{"price":"1732.41","quantity":"0.192"},{"price":"1733.86","quantity":"0.363"},{"price":"1733.92","quantity":"17.384"},{"price":"1733.93","quantity":"3.746"},{"price":"1733.95","quantity":"5.388"},{"price":"1734.01","quantity":"20.653"},{"price":"1734.06","quantity":"473.253"},{"price":"1735.11","quantity":"45.389"},{"price":"1735.26","quantity":"10.582"},{"price":"1735.37","quantity":"0.613"},{"price":"1735.38","quantity":"67.258"},{"price":"1735.48","quantity":"0.874"},{"price":"1735.51","quantity":"50.796"},{"price":"1735.52","quantity":"80.840"},{"price":"1735.58","quantity":"0.094"},{"price":"1735.61","quantity":"8.709"},{"price":"1735.63","quantity":"0.576"},{"price":"1735.76","quantity":"11.272"},{"price":"1735.80","quantity":"39.344"},{"price":"1735.84","quantity":"0.058"},{"price":"1735.87","quantity":"3.043"},{"price":"1735.88","quantity":"0.334"},{"price":"1736.01","quantity":"0.050"},{"price":"1736.02","quantity":"1.812"},{"price":"1736.04","quantity":"0.044"},{"price":"1736.08","quantity":"0.730"},{"price":"1736.10","quantity":"4.304"},{"price":"1736.11","quantity":"175.590"}],"asks":[{"price":"1736.12","quantity":"12.525"},{"price":"1736.13","quantity":"9.037"},{"price":"1736.15","quantity":"0.012"},{"price":"1736.16","quantity":"0.279"},{"price":"1736.17","quantity":"0.024"},{"price":"1736.19","quantity":"0.888"},{"price":"1736.23","quantity":"0.064"},{"price":"1736.24","quantity":"5.060"},{"price":"1736.25","quantity":"8.585"},{"price":"1736.26","quantity":"13.698"},{"price":"1736.29","quantity":"2.363"},{"price":"1736.31","quantity":"17.366"},{"price":"1736.32","quantity":"0.143"},{"price":"1736.34","quantity":"0.059"},{"price":"1736.35","quantity":"31.165"},{"price":"1736.36","quantity":"17.483"},{"price":"1736.38","quantity":"11.840"},{"price":"1736.42","quantity":"11.753"},{"price":"1736.67","quantity":"0.062"},{"price":"1736.73","quantity":"8.730"},{"price":"1736.80","quantity":"4.218"},{"price":"1736.86","quantity":"39.223"},{"price":"1736.89","quantity":"8.153"},{"price":"1736.90","quantity":"29.781"},{"price":"1736.91","quantity":"68.147"},{"price":"1736.92","quantity":"67.361"},{"price":"1736.95","quantity":"0.446"},{"price":"1736.98","quantity":"5.219"},{"price":"1737.68","quantity":"3.610"},{"price":"1737.82","quantity":"16.708"},{"price":"1738.12","quantity":"4.331"},{"price":"1738.13","quantity":"45.994"},{"price":"1738.98","quantity":"43.748"},{"price":"1744.81","quantity":"0.142"},{"price":"1744.99","quantity":"0.615"},{"price":"1745.04","quantity":"0.106"},{"price":"1748.12","quantity":"6.140"},{"price":"1748.17","quantity":"0.036"},{"price":"1781.24","quantity":"297.349"},{"price":"2634.39","quantity":"0.001"},{"price":"2634.40","quantity":"0.001"},{"price":"2634.48","quantity":"0.148"},{"price":"2634.49","quantity":"0.000"}],"raw":{"e":"depthUpdate","E":1783517070448,"T":1783517070447,"s":"ETHUSDT","ps":"ETHUSDT","U":10999770925336,"u":10999770939113,"pu":10999770925181,"b":[["200.00","7.594"],["1221.11","2.464"],["1226.11","6.304"],["1231.11","0.832"],["1562.49","0.026"],["1562.50","4.332"],["1666.60","1.078"],["1703.64","116.805"],["1704.86","90.925"],["1710.07","66.409"],["1711.95","12.998"],["1720.50","19.075"],["1727.42","0.641"],["1730.07","135.828"],["1730.08","26.320"],["1730.09","4.351"],["1732.39","9.271"],["1732.41","0.192"],["1733.86","0.363"],["1733.92","17.384"],["1733.93","3.746"],["1733.95","5.388"],["1734.01","20.653"],["1734.06","473.253"],["1735.11","45.389"],["1735.26","10.582"],["1735.37","0.613"],["1735.38","67.258"],["1735.48","0.874"],["1735.51","50.796"],["1735.52","80.840"],["1735.58","0.094"],["1735.61","8.709"],["1735.63","0.576"],["1735.76","11.272"],["1735.80","39.344"],["1735.84","0.058"],["1735.87","3.043"],["1735.88","0.334"],["1736.01","0.050"],["1736.02","1.812"],["1736.04","0.044"],["1736.08","0.730"],["1736.10","4.304"],["1736.11","175.590"]],"a":[["1736.12","12.525"],["1736.13","9.037"],["1736.15","0.012"],["1736.16","0.279"],["1736.17","0.024"],["1736.19","0.888"],["1736.23","0.064"],["1736.24","5.060"],["1736.25","8.585"],["1736.26","13.698"],["1736.29","2.363"],["1736.31","17.366"],["1736.32","0.143"],["1736.34","0.059"],["1736.35","31.165"],["1736.36","17.483"],["1736.38","11.840"],["1736.42","11.753"],["1736.67","0.062"],["1736.73","8.730"],["1736.80","4.218"],["1736.86","39.223"],["1736.89","8.153"],["1736.90","29.781"],["1736.91","68.147"],["1736.92","67.361"],["1736.95","0.446"],["1736.98","5.219"],["1737.68","3.610"],["1737.82","16.708"],["1738.12","4.331"],["1738.13","45.994"],["1738.98","43.748"],["1744.81","0.142"],["1744.99","0.615"],["1745.04","0.106"],["1748.12","6.140"],["1748.17","0.036"],["1781.24","297.349"],["2634.39","0.001"],["2634.40","0.001"],["2634.48","0.148"],["2634.49","0.000"]],"st":1}}
{"schema_version":"1.3.0","event_id":"52eaa669-3256-4146-8e93-878f1011aa56","event_type":"raw.depth_update","source":"binance_market_data_recorder","venue":"binance_usdm","market_type":"perpetual_futures","symbol":"ETHUSDT","event_time_ms":1783517070550,"received_time_ms":1783517070546,"trace_id":"2ea17621-3dd4-4a0f-95c6-0c33dd136d9e","first_update_id":10999770939154,"final_update_id":10999770946956,"previous_final_update_id":10999770939113,"bids":[{"price":"200.00","quantity":"7.594"},{"price":"201.00","quantity":"2.300"},{"price":"1221.11","quantity":"3.008"},{"price":"1226.11","quantity":"6.048"},{"price":"1231.11","quantity":"0.544"},{"price":"1562.49","quantity":"0.026"},{"price":"1562.50","quantity":"4.332"},{"price":"1666.60","quantity":"1.193"},{"price":"1701.38","quantity":"43.670"},{"price":"1705.67","quantity":"58.818"},{"price":"1718.29","quantity":"7.604"},{"price":"1719.03","quantity":"203.356"},{"price":"1720.64","quantity":"35.699"},{"price":"1722.51","quantity":"13.932"},{"price":"1731.25","quantity":"14.145"},{"price":"1733.59","quantity":"441.743"},{"price":"1734.06","quantity":"54.181"},{"price":"1735.10","quantity":"233.264"},{"price":"1735.20","quantity":"279.988"},{"price":"1735.23","quantity":"4.905"},{"price":"1735.34","quantity":"0.116"},{"price":"1735.37","quantity":"0.595"},{"price":"1735.38","quantity":"67.258"},{"price":"1735.44","quantity":"27.914"},{"price":"1735.52","quantity":"77.961"},{"price":"1735.82","quantity":"0.964"},{"price":"1735.88","quantity":"0.236"},{"price":"1735.99","quantity":"8.787"},{"price":"1736.02","quantity":"0.084"},{"price":"1736.06","quantity":"0.117"},{"price":"1736.09","quantity":"0.944"},{"price":"1736.11","quantity":"168.922"}],"asks":[{"price":"1736.12","quantity":"87.663"},{"price":"1736.13","quantity":"9.079"},{"price":"1736.14","quantity":"0.904"},{"price":"1736.15","quantity":"0.024"},{"price":"1736.16","quantity":"0.291"},{"price":"1736.18","quantity":"0.178"},{"price":"1736.19","quantity":"0.000"},{"price":"1736.21","quantity":"0.113"},{"price":"1736.23","quantity":"20.064"},{"price":"1736.24","quantity":"2.388"},{"price":"1736.26","quantity":"13.609"},{"price":"1736.28","quantity":"5.261"},{"price":"1736.29","quantity":"1.210"},{"price":"1736.30","quantity":"20.951"},{"price":"1736.31","quantity":"17.471"},{"price":"1736.32","quantity":"18.078"},{"price":"1736.34","quantity":"1.041"},{"price":"1736.35","quantity":"4.537"},{"price":"1736.40","quantity":"21.369"},{"price":"1736.42","quantity":"8.297"},{"price":"1736.57","quantity":"2.108"},{"price":"1736.63","quantity":"12.326"},{"price":"1736.64","quantity":"76.115"},{"price":"1736.72","quantity":"10.939"},{"price":"1736.73","quantity":"15.358"},{"price":"1736.81","quantity":"20.987"},{"price":"1736.89","quantity":"8.141"},{"price":"1736.90","quantity":"31.436"},{"price":"1736.91","quantity":"68.135"},{"price":"1736.92","quantity":"67.349"},{"price":"1737.12","quantity":"7.826"},{"price":"1737.14","quantity":"72.888"},{"price":"1737.39","quantity":"2.576"},{"price":"1738.08","quantity":"410.518"},{"price":"1738.12","quantity":"5.998"},{"price":"1738.14","quantity":"16.295"},{"price":"1738.19","quantity":"16.320"},{"price":"1738.98","quantity":"40.552"},{"price":"1742.47","quantity":"7.517"},{"price":"1747.12","quantity":"15.000"},{"price":"1769.11","quantity":"37.969"},{"price":"1795.47","quantity":"50.157"},{"price":"2634.38","quantity":"0.001"},{"price":"2634.47","quantity":"0.000"}],"raw":{"e":"depthUpdate","E":1783517070550,"T":1783517070549,"s":"ETHUSDT","ps":"ETHUSDT","U":10999770939154,"u":10999770946956,"pu":10999770939113,"b":[["200.00","7.594"],["201.00","2.300"],["1221.11","3.008"],["1226.11","6.048"],["1231.11","0.544"],["1562.49","0.026"],["1562.50","4.332"],["1666.60","1.193"],["1701.38","43.670"],["1705.67","58.818"],["1718.29","7.604"],["1719.03","203.356"],["1720.64","35.699"],["1722.51","13.932"],["1731.25","14.145"],["1733.59","441.743"],["1734.06","54.181"],["1735.10","233.264"],["1735.20","279.988"],["1735.23","4.905"],["1735.34","0.116"],["1735.37","0.595"],["1735.38","67.258"],["1735.44","27.914"],["1735.52","77.961"],["1735.82","0.964"],["1735.88","0.236"],["1735.99","8.787"],["1736.02","0.084"],["1736.06","0.117"],["1736.09","0.944"],["1736.11","168.922"]],"a":[["1736.12","87.663"],["1736.13","9.079"],["1736.14","0.904"],["1736.15","0.024"],["1736.16","0.291"],["1736.18","0.178"],["1736.19","0.000"],["1736.21","0.113"],["1736.23","20.064"],["1736.24","2.388"],["1736.26","13.609"],["1736.28","5.261"],["1736.29","1.210"],["1736.30","20.951"],["1736.31","17.471"],["1736.32","18.078"],["1736.34","1.041"],["1736.35","4.537"],["1736.40","21.369"],["1736.42","8.297"],["1736.57","2.108"],["1736.63","12.326"],["1736.64","76.115"],["1736.72","10.939"],["1736.73","15.358"],["1736.81","20.987"],["1736.89","8.141"],["1736.90","31.436"],["1736.91","68.135"],["1736.92","67.349"],["1737.12","7.826"],["1737.14","72.888"],["1737.39","2.576"],["1738.08","410.518"],["1738.12","5.998"],["1738.14","16.295"],["1738.19","16.320"],["1738.98","40.552"],["1742.47","7.517"],["1747.12","15.000"],["1769.11","37.969"],["1795.47","50.157"],["2634.38","0.001"],["2634.47","0.000"]],"st":1}}
{"schema_version":"1.3.0","event_id":"33ae3a58-f240-47e2-8b86-b09ff1985143","event_type":"raw.depth_update","source":"binance_market_data_recorder","venue":"binance_usdm","market_type":"perpetual_futures","symbol":"ETHUSDT","event_time_ms":1783517070652,"received_time_ms":1783517070646,"trace_id":"df7daa5b-e457-4556-a090-2ab37c217d2e","first_update_id":10999770947079,"final_update_id":10999770954256,"previous_final_update_id":10999770946956,"bids":[{"price":"1221.11","quantity":"3.552"},{"price":"1226.11","quantity":"5.760"},{"price":"1231.11","quantity":"0.288"},{"price":"1562.49","quantity":"0.026"},{"price":"1562.50","quantity":"4.204"},{"price":"1701.38","quantity":"43.641"},{"price":"1703.43","quantity":"72.830"},{"price":"1706.60","quantity":"62.366"},{"price":"1709.74","quantity":"0.280"},{"price":"1710.07","quantity":"76.637"},{"price":"1711.80","quantity":"174.117"},{"price":"1717.01","quantity":"27.336"},{"price":"1718.54","quantity":"20.340"},{"price":"1718.75","quantity":"372.741"},{"price":"1728.20","quantity":"0.366"},{"price":"1733.41","quantity":"42.081"},{"price":"1733.42","quantity":"4.369"},{"price":"1733.59","quantity":"22.671"},{"price":"1733.65","quantity":"9.919"},{"price":"1735.10","quantity":"13.075"},{"price":"1735.11","quantity":"45.389"},{"price":"1735.79","quantity":"4.516"},{"price":"1735.84","quantity":"0.858"},{"price":"1735.87","quantity":"3.843"},{"price":"1735.88","quantity":"1.036"},{"price":"1736.05","quantity":"0.083"}],"asks":[{"price":"1736.12","quantity":"87.681"},{"price":"1736.17","quantity":"0.036"},{"price":"1736.18","quantity":"0.190"},{"price":"1736.19","quantity":"0.012"},{"price":"1736.32","quantity":"18.078"},{"price":"1736.34","quantity":"0.041"},{"price":"1736.75","quantity":"67.765"},{"price":"1738.08","quantity":"1.684"},{"price":"1738.12","quantity":"4.331"},{"price":"1738.14","quantity":"16.295"},{"price":"1738.96","quantity":"3.196"},{"price":"1781.26","quantity":"50.466"},{"price":"2634.36","quantity":"0.001"},{"price":"2634.37","quantity":"0.026"},{"price":"2634.45","quantity":"0.000"},{"price":"2634.46","quantity":"0.000"}],"raw":{"e":"depthUpdate","E":1783517070652,"T":1783517070651,"s":"ETHUSDT","ps":"ETHUSDT","U":10999770947079,"u":10999770954256,"pu":10999770946956,"b":[["1221.11","3.552"],["1226.11","5.760"],["1231.11","0.288"],["1562.49","0.026"],["1562.50","4.204"],["1701.38","43.641"],["1703.43","72.830"],["1706.60","62.366"],["1709.74","0.280"],["1710.07","76.637"],["1711.80","174.117"],["1717.01","27.336"],["1718.54","20.340"],["1718.75","372.741"],["1728.20","0.366"],["1733.41","42.081"],["1733.42","4.369"],["1733.59","22.671"],["1733.65","9.919"],["1735.10","13.075"],["1735.11","45.389"],["1735.79","4.516"],["1735.84","0.858"],["1735.87","3.843"],["1735.88","1.036"],["1736.05","0.083"]],"a":[["1736.12","87.681"],["1736.17","0.036"],["1736.18","0.190"],["1736.19","0.012"],["1736.32","18.078"],["1736.34","0.041"],["1736.75","67.765"],["1738.08","1.684"],["1738.12","4.331"],["1738.14","16.295"],["1738.96","3.196"],["1781.26","50.466"],["2634.36","0.001"],["2634.37","0.026"],["2634.45","0.000"],["2634.46","0.000"]],"st":1}}
{"schema_version":"1.3.0","event_id":"e5bb5b18-fa19-44a4-b022-5377c0ab947a","event_type":"raw.depth_update","source":"binance_market_data_recorder","venue":"binance_usdm","market_type":"perpetual_futures","symbol":"ETHUSDT","event_time_ms":1783517070754,"received_time_ms":1783517070748,"trace_id":"cdd913d7-d751-4a32-88b5-a94286cd4f9a","first_update_id":10999770954281,"final_update_id":10999770961753,"previous_final_update_id":10999770954256,"bids":[{"price":"200.00","quantity":"7.594"},{"price":"1221.11","quantity":"4.096"},{"price":"1226.11","quantity":"5.504"},{"price":"1231.11","quantity":"0.000"},{"price":"1562.49","quantity":"0.026"},{"price":"1562.50","quantity":"4.204"},{"price":"1666.60","quantity":"1.078"},{"price":"1701.38","quantity":"43.670"},{"price":"1717.01","quantity":"114.570"},{"price":"1720.48","quantity":"87.146"},{"price":"1733.59","quantity":"22.671"},{"price":"1733.70","quantity":"440.113"},{"price":"1733.88","quantity":"44.716"},{"price":"1733.89","quantity":"3.961"},{"price":"1733.95","quantity":"3.942"},{"price":"1734.01","quantity":"17.457"},{"price":"1735.05","quantity":"220.612"},{"price":"1735.09","quantity":"1.835"},{"price":"1735.13","quantity":"3.178"},{"price":"1735.20","quantity":"59.803"},{"price":"1735.36","quantity":"42.719"},{"price":"1735.39","quantity":"0.565"},{"price":"1735.70","quantity":"5.786"},{"price":"1735.74","quantity":"28.606"},{"price":"1736.01","quantity":"22.233"},{"price":"1736.02","quantity":"3.402"},{"price":"1736.11","quantity":"135.919"}],"asks":[{"price":"1736.24","quantity":"2.376"},{"price":"1736.37","quantity":"17.343"},{"price":"1736.50","quantity":"1.802"},{"price":"1736.57","quantity":"2.120"},{"price":"1736.60","quantity":"5.055"},{"price":"1736.75","quantity":"67.765"},{"price":"1736.77","quantity":"39.064"},{"price":"1736.86","quantity":"0.322"},{"price":"1737.08","quantity":"16.761"},{"price":"1737.89","quantity":"7.279"},{"price":"1738.08","quantity":"408.508"},{"price":"1738.20","quantity":"0.256"},{"price":"1738.97","quantity":"181.920"},{"price":"1739.10","quantity":"16.508"},{"price":"1745.64","quantity":"0.768"},{"price":"1757.32","quantity":"8.109"},{"price":"1759.04","quantity":"9.458"},{"price":"1775.97","quantity":"0.038"},{"price":"2634.35","quantity":"0.001"},{"price":"2634.44","quantity":"0.000"}],"raw":{"e":"depthUpdate","E":1783517070754,"T":1783517070753,"s":"ETHUSDT","ps":"ETHUSDT","U":10999770954281,"u":10999770961753,"pu":10999770954256,"b":[["200.00","7.594"],["1221.11","4.096"],["1226.11","5.504"],["1231.11","0.000"],["1562.49","0.026"],["1562.50","4.204"],["1666.60","1.078"],["1701.38","43.670"],["1717.01","114.570"],["1720.48","87.146"],["1733.59","22.671"],["1733.70","440.113"],["1733.88","44.716"],["1733.89","3.961"],["1733.95","3.942"],["1734.01","17.457"],["1735.05","220.612"],["1735.09","1.835"],["1735.13","3.178"],["1735.20","59.803"],["1735.36","42.719"],["1735.39","0.565"],["1735.70","5.786"],["1735.74","28.606"],["1736.01","22.233"],["1736.02","3.402"],["1736.11","135.919"]],"a":[["1736.24","2.376"],["1736.37","17.343"],["1736.50","1.802"],["1736.57","2.120"],["1736.60","5.055"],["1736.75","67.765"],["1736.77","39.064"],["1736.86","0.322"],["1737.08","16.761"],["1737.89","7.279"],["1738.08","408.508"],["1738.20","0.256"],["1738.97","181.920"],["1739.10","16.508"],["1745.64","0.768"],["1757.32","8.109"],["1759.04","9.458"],["1775.97","0.038"],["2634.35","0.001"],["2634.44","0.000"]],"st":1}}
{"schema_version":"1.3.0","event_id":"9187b8ec-8cff-4209-865c-4072eb0e29fc","event_type":"raw.depth_update","source":"binance_market_data_recorder","venue":"binance_usdm","market_type":"perpetual_futures","symbol":"ETHUSDT","event_time_ms":1783517070856,"received_time_ms":1783517070851,"trace_id":"21d37866-58d3-4fbd-b4f5-652a93bdb296","first_update_id":10999770961784,"final_update_id":10999770969359,"previous_final_update_id":10999770961753,"bids":[{"price":"200.00","quantity":"7.594"},{"price":"1221.11","quantity":"4.896"},{"price":"1226.11","quantity":"4.704"},{"price":"1562.04","quantity":"0.112"},{"price":"1562.49","quantity":"0.026"},{"price":"1562.50","quantity":"4.332"},{"price":"1666.60","quantity":"1.193"},{"price":"1682.77","quantity":"0.094"},{"price":"1701.38","quantity":"43.641"},{"price":"1709.48","quantity":"10.225"},{"price":"1710.94","quantity":"18.156"},{"price":"1712.08","quantity":"20.292"},{"price":"1719.03","quantity":"116.217"},{"price":"1720.77","quantity":"92.869"},{"price":"1732.08","quantity":"0.026"},{"price":"1733.50","quantity":"13.855"},{"price":"1733.59","quantity":"446.184"},{"price":"1733.70","quantity":"16.600"},{"price":"1733.72","quantity":"1.615"},{"price":"1733.76","quantity":"95.675"},{"price":"1733.88","quantity":"44.716"},{"price":"1734.78","quantity":"220.562"},{"price":"1734.90","quantity":"19.409"},{"price":"1734.93","quantity":"68.137"},{"price":"1734.94","quantity":"12.482"},{"price":"1735.02","quantity":"53.535"},{"price":"1735.05","quantity":"0.432"},{"price":"1735.24","quantity":"7.526"},{"price":"1735.34","quantity":"3.098"},{"price":"1735.38","quantity":"67.276"},{"price":"1735.51","quantity":"52.524"},{"price":"1735.59","quantity":"4.353"},{"price":"1735.69","quantity":"10.540"},{"price":"1735.70","quantity":"5.798"},{"price":"1735.71","quantity":"0.038"},{"price":"1735.76","quantity":"11.355"},{"price":"1735.77","quantity":"10.196"},{"price":"1735.82","quantity":"0.842"},{"price":"1735.86","quantity":"68.996"},{"price":"1735.90","quantity":"1.266"},{"price":"1735.93","quantity":"5.110"},{"price":"1735.94","quantity":"8.692"},{"price":"1735.96","quantity":"0.552"},{"price":"1735.97","quantity":"3.095"},{"price":"1735.99","quantity":"0.139"},{"price":"1736.02","quantity":"3.493"},{"price":"1736.04","quantity":"0.024"},{"price":"1736.05","quantity":"0.063"},{"price":"1736.06","quantity":"0.026"},{"price":"1736.11","quantity":"75.910"}],"asks":[{"price":"1736.12","quantity":"164.155"},{"price":"1736.14","quantity":"0.040"},{"price":"1736.17","quantity":"0.125"},{"price":"1736.18","quantity":"1.918"},{"price":"1736.19","quantity":"0.032"},{"price":"1736.20","quantity":"1.236"},{"price":"1736.21","quantity":"0.024"},{"price":"1736.25","quantity":"3.977"},{"price":"1736.29","quantity":"5.586"},{"price":"1736.31","quantity":"17.471"},{"price":"1736.33","quantity":"3.675"},{"price":"1736.35","quantity":"9.145"},{"price":"1736.37","quantity":"16.555"},{"price":"1736.38","quantity":"10.173"},{"price":"1736.47","quantity":"36.490"},{"price":"1736.50","quantity":"1.814"},{"price":"1736.54","quantity":"2.869"},{"price":"1736.81","quantity":"19.320"},{"price":"1737.01","quantity":"75.727"},{"price":"1737.02","quantity":"22.051"},{"price":"1737.04","quantity":"32.478"},{"price":"1737.06","quantity":"21.378"},{"price":"1737.07","quantity":"0.478"},{"price":"1737.12","quantity":"7.826"},{"price":"1737.24","quantity":"0.141"},{"price":"1737.60","quantity":"7.231"},{"price":"1737.68","quantity":"0.970"},{"price":"1737.80","quantity":"31.254"},{"price":"1737.82","quantity":"42.838"},{"price":"1738.00","quantity":"89.764"},{"price":"1738.03","quantity":"1.667"},{"price":"1738.08","quantity":"1.684"},{"price":"1738.13","quantity":"19.864"},{"price":"1738.14","quantity":"423.119"},{"price":"1739.42","quantity":"30.137"},{"price":"1740.16","quantity":"19.743"},{"price":"1740.58","quantity":"8.287"},{"price":"1741.75","quantity":"2.539"},{"price":"1742.47","quantity":"0.012"},{"price":"1747.12","quantity":"0.000"},{"price":"1773.23","quantity":"92.009"},{"price":"2634.33","quantity":"0.001"},{"price":"2634.34","quantity":"0.001"},{"price":"2634.42","quantity":"0.000"},{"price":"2634.43","quantity":"0.000"}],"raw":{"e":"depthUpdate","E":1783517070856,"T":1783517070854,"s":"ETHUSDT","ps":"ETHUSDT","U":10999770961784,"u":10999770969359,"pu":10999770961753,"b":[["200.00","7.594"],["1221.11","4.896"],["1226.11","4.704"],["1562.04","0.112"],["1562.49","0.026"],["1562.50","4.332"],["1666.60","1.193"],["1682.77","0.094"],["1701.38","43.641"],["1709.48","10.225"],["1710.94","18.156"],["1712.08","20.292"],["1719.03","116.217"],["1720.77","92.869"],["1732.08","0.026"],["1733.50","13.855"],["1733.59","446.184"],["1733.70","16.600"],["1733.72","1.615"],["1733.76","95.675"],["1733.88","44.716"],["1734.78","220.562"],["1734.90","19.409"],["1734.93","68.137"],["1734.94","12.482"],["1735.02","53.535"],["1735.05","0.432"],["1735.24","7.526"],["1735.34","3.098"],["1735.38","67.276"],["1735.51","52.524"],["1735.59","4.353"],["1735.69","10.540"],["1735.70","5.798"],["1735.71","0.038"],["1735.76","11.355"],["1735.77","10.196"],["1735.82","0.842"],["1735.86","68.996"],["1735.90","1.266"],["1735.93","5.110"],["1735.94","8.692"],["1735.96","0.552"],["1735.97","3.095"],["1735.99","0.139"],["1736.02","3.493"],["1736.04","0.024"],["1736.05","0.063"],["1736.06","0.026"],["1736.11","75.910"]],"a":[["1736.12","164.155"],["1736.14","0.040"],["1736.17","0.125"],["1736.18","1.918"],["1736.19","0.032"],["1736.20","1.236"],["1736.21","0.024"],["1736.25","3.977"],["1736.29","5.586"],["1736.31","17.471"],["1736.33","3.675"],["1736.35","9.145"],["1736.37","16.555"],["1736.38","10.173"],["1736.47","36.490"],["1736.50","1.814"],["1736.54","2.869"],["1736.81","19.320"],["1737.01","75.727"],["1737.02","22.051"],["1737.04","32.478"],["1737.06","21.378"],["1737.07","0.478"],["1737.12","7.826"],["1737.24","0.141"],["1737.60","7.231"],["1737.68","0.970"],["1737.80","31.254"],["1737.82","42.838"],["1738.00","89.764"],["1738.03","1.667"],["1738.08","1.684"],["1738.13","19.864"],["1738.14","423.119"],["1739.42","30.137"],["1740.16","19.743"],["1740.58","8.287"],["1741.75","2.539"],["1742.47","0.012"],["1747.12","0.000"],["1773.23","92.009"],["2634.33","0.001"],["2634.34","0.001"],["2634.42","0.000"],["2634.43","0.000"]],"st":1}}
{"schema_version":"1.3.0","event_id":"c05e5fe3-1396-40d3-ad2f-49fdc48d0414","event_type":"raw.depth_update","source":"binance_market_data_recorder","venue":"binance_usdm","market_type":"perpetual_futures","symbol":"ETHUSDT","event_time_ms":1783517070958,"received_time_ms":1783517070952,"trace_id":"15f953c9-1ed7-4249-bb04-d4c234abb148","first_update_id":10999770969515,"final_update_id":10999770975728,"previous_final_update_id":10999770969359,"bids":[{"price":"1221.11","quantity":"5.728"},{"price":"1226.11","quantity":"3.872"},{"price":"1562.49","quantity":"0.026"},{"price":"1562.50","quantity":"4.332"},{"price":"1666.60","quantity":"1.078"},{"price":"1699.65","quantity":"0.000"},{"price":"1701.38","quantity":"43.670"},{"price":"1710.07","quantity":"164.233"},{"price":"1729.01","quantity":"0.578"},{"price":"1733.59","quantity":"22.671"},{"price":"1733.70","quantity":"440.113"},{"price":"1733.72","quantity":"0.169"},{"price":"1733.76","quantity":"35.799"},{"price":"1733.77","quantity":"19.838"},{"price":"1734.88","quantity":"242.084"},{"price":"1735.09","quantity":"1.235"},{"price":"1735.11","quantity":"45.389"},{"price":"1735.29","quantity":"30.264"},{"price":"1735.60","quantity":"5.413"},{"price":"1735.67","quantity":"0.063"},{"price":"1735.75","quantity":"71.444"},{"price":"1735.76","quantity":"10.755"},{"price":"1735.77","quantity":"39.029"},{"price":"1735.80","quantity":"10.512"},{"price":"1735.87","quantity":"3.843"},{"price":"1735.96","quantity":"9.200"},{"price":"1735.97","quantity":"3.186"},{"price":"1736.02","quantity":"3.379"}],"asks":[{"price":"1736.12","quantity":"164.232"},{"price":"1736.17","quantity":"0.036"},{"price":"1736.18","quantity":"1.938"},{"price":"1736.20","quantity":"1.259"},{"price":"1736.21","quantity":"8.310"},{"price":"1736.25","quantity":"3.989"},{"price":"1736.46","quantity":"40.713"},{"price":"1736.48","quantity":"12.786"},{"price":"1736.57","quantity":"2.106"},{"price":"1736.63","quantity":"12.277"},{"price":"1736.69","quantity":"7.376"},{"price":"1736.73","quantity":"13.691"},{"price":"1736.98","quantity":"5.231"},{"price":"1737.08","quantity":"16.761"},{"price":"1737.46","quantity":"9.167"},{"price":"1737.68","quantity":"17.646"},{"price":"1737.77","quantity":"0.758"},{"price":"1737.86","quantity":"3.469"},{"price":"1738.00","quantity":"30.932"},{"price":"1738.08","quantity":"408.508"},{"price":"1738.12","quantity":"4.331"},{"price":"1738.14","quantity":"16.295"},{"price":"1738.94","quantity":"7.156"},{"price":"1738.96","quantity":"3.196"},{"price":"1758.70","quantity":"21.360"},{"price":"1763.20","quantity":"80.088"},{"price":"1805.95","quantity":"0.000"},{"price":"2634.32","quantity":"0.001"},{"price":"2634.41","quantity":"0.000"}],"raw":{"e":"depthUpdate","E":1783517070958,"T":1783517070957,"s":"ETHUSDT","ps":"ETHUSDT","U":10999770969515,"u":10999770975728,"pu":10999770969359,"b":[["1221.11","5.728"],["1226.11","3.872"],["1562.49","0.026"],["1562.50","4.332"],["1666.60","1.078"],["1699.65","0.000"],["1701.38","43.670"],["1710.07","164.233"],["1729.01","0.578"],["1733.59","22.671"],["1733.70","440.113"],["1733.72","0.169"],["1733.76","35.799"],["1733.77","19.838"],["1734.88","242.084"],["1735.09","1.235"],["1735.11","45.389"],["1735.29","30.264"],["1735.60","5.413"],["1735.67","0.063"],["1735.75","71.444"],["1735.76","10.755"],["1735.77","39.029"],["1735.80","10.512"],["1735.87","3.843"],["1735.96","9.200"],["1735.97","3.186"],["1736.02","3.379"]],"a":[["1736.12","164.232"],["1736.17","0.036"],["1736.18","1.938"],["1736.20","1.259"],["1736.21","8.310"],["1736.25","3.989"],["1736.46","40.713"],["1736.48","12.786"],["1736.57","2.106"],["1736.63","12.277"],["1736.69","7.376"],["1736.73","13.691"],["1736.98","5.231"],["1737.08","16.761"],["1737.46","9.167"],["1737.68","17.646"],["1737.77","0.758"],["1737.86","3.469"],["1738.00","30.932"],["1738.08","408.508"],["1738.12","4.331"],["1738.14","16.295"],["1738.94","7.156"],["1738.96","3.196"],["1758.70","21.360"],["1763.20","80.088"],["1805.95","0.000"],["2634.32","0.001"],["2634.41","0.000"]],"st":1}}
{"schema_version":"1.3.0","event_id":"b57416b8-9a89-4ead-a248-ef8565c58e25","event_type":"raw.depth_update","source":"binance_market_data_recorder","venue":"binance_usdm","market_type":"perpetual_futures","symbol":"ETHUSDT","event_time_ms":1783517071062,"received_time_ms":1783517071058,"trace_id":"51384533-9171-4faf-b303-6b4668109243","first_update_id":10999770975866,"final_update_id":10999770983545,"previous_final_update_id":10999770975728,"bids":[{"price":"200.00","quantity":"7.594"},{"price":"1221.11","quantity":"6.560"},{"price":"1226.11","quantity":"3.040"},{"price":"1562.49","quantity":"0.026"},{"price":"1562.50","quantity":"4.332"},{"price":"1666.60","quantity":"1.193"},{"price":"1678.49","quantity":"59.962"},{"price":"1701.38","quantity":"43.641"},{"price":"1706.00","quantity":"495.806"},{"price":"1717.01","quantity":"201.812"},{"price":"1733.70","quantity":"16.600"},{"price":"1733.77","quantity":"18.392"},{"price":"1733.85","quantity":"87.882"},{"price":"1733.89","quantity":"2.211"},{"price":"1733.91","quantity":"3.661"},{"price":"1733.95","quantity":"4.460"},{"price":"1734.06","quantity":"477.694"},{"price":"1734.78","quantity":"0.444"},{"price":"1734.88","quantity":"21.974"},{"price":"1734.93","quantity":"68.155"},{"price":"1734.94","quantity":"12.464"},{"price":"1734.98","quantity":"290.009"},{"price":"1735.08","quantity":"7.016"},{"price":"1735.19","quantity":"70.915"},{"price":"1735.26","quantity":"0.209"},{"price":"1735.72","quantity":"2.339"},{"price":"1735.74","quantity":"16.742"},{"price":"1735.76","quantity":"10.755"},{"price":"1735.93","quantity":"5.110"},{"price":"1735.96","quantity":"0.552"},{"price":"1735.97","quantity":"3.095"},{"price":"1736.02","quantity":"3.470"},{"price":"1736.11","quantity":"162.324"}],"asks":[{"price":"1736.12","quantity":"164.297"},{"price":"1736.17","quantity":"0.125"},{"price":"1736.29","quantity":"5.663"},{"price":"1736.31","quantity":"17.471"},{"price":"1736.32","quantity":"0.143"},{"price":"1736.38","quantity":"9.984"},{"price":"1736.39","quantity":"0.098"},{"price":"1736.47","quantity":"36.490"},{"price":"1736.53","quantity":"1.523"},{"price":"1736.59","quantity":"7.515"},{"price":"1736.64","quantity":"76.774"},{"price":"1736.67","quantity":"0.062"},{"price":"1736.73","quantity":"13.173"},{"price":"1736.84","quantity":"4.965"},{"price":"1736.90","quantity":"29.769"},{"price":"1736.94","quantity":"19.260"},{"price":"1737.08","quantity":"16.761"},{"price":"1737.12","quantity":"7.826"},{"price":"1737.46","quantity":"9.147"},{"price":"1737.57","quantity":"43.195"},{"price":"1737.73","quantity":"4.224"},{"price":"1738.64","quantity":"8.380"},{"price":"1738.88","quantity":"0.561"},{"price":"1747.12","quantity":"15.000"},{"price":"1762.53","quantity":"0.196"},{"price":"1765.96","quantity":"47.926"},{"price":"1768.24","quantity":"55.914"},{"price":"2634.30","quantity":"0.001"},{"price":"2634.31","quantity":"0.053"},{"price":"2634.39","quantity":"0.000"},{"price":"2634.40","quantity":"0.000"}],"raw":{"e":"depthUpdate","E":1783517071062,"T":1783517071061,"s":"ETHUSDT","ps":"ETHUSDT","U":10999770975866,"u":10999770983545,"pu":10999770975728,"b":[["200.00","7.594"],["1221.11","6.560"],["1226.11","3.040"],["1562.49","0.026"],["1562.50","4.332"],["1666.60","1.193"],["1678.49","59.962"],["1701.38","43.641"],["1706.00","495.806"],["1717.01","201.812"],["1733.70","16.600"],["1733.77","18.392"],["1733.85","87.882"],["1733.89","2.211"],["1733.91","3.661"],["1733.95","4.460"],["1734.06","477.694"],["1734.78","0.444"],["1734.88","21.974"],["1734.93","68.155"],["1734.94","12.464"],["1734.98","290.009"],["1735.08","7.016"],["1735.19","70.915"],["1735.26","0.209"],["1735.72","2.339"],["1735.74","16.742"],["1735.76","10.755"],["1735.93","5.110"],["1735.96","0.552"],["1735.97","3.095"],["1736.02","3.470"],["1736.11","162.324"]],"a":[["1736.12","164.297"],["1736.17","0.125"],["1736.29","5.663"],["1736.31","17.471"],["1736.32","0.143"],["1736.38","9.984"],["1736.39","0.098"],["1736.47","36.490"],["1736.53","1.523"],["1736.59","7.515"],["1736.64","76.774"],["1736.67","0.062"],["1736.73","13.173"],["1736.84","4.965"],["1736.90","29.769"],["1736.94","19.260"],["1737.08","16.761"],["1737.12","7.826"],["1737.46","9.147"],["1737.57","43.195"],["1737.73","4.224"],["1738.64","8.380"],["1738.88","0.561"],["1747.12","15.000"],["1762.53","0.196"],["1765.96","47.926"],["1768.24","55.914"],["2634.30","0.001"],["2634.31","0.053"],["2634.39","0.000"],["2634.40","0.000"]],"st":1}}
{"schema_version":"1.3.0","event_id":"46fb6831-defe-44f9-9b6d-8462bc91cfee","event_type":"raw.depth_update","source":"binance_market_data_recorder","venue":"binance_usdm","market_type":"perpetual_futures","symbol":"ETHUSDT","event_time_ms":1783517071164,"received_time_ms":1783517071159,"trace_id":"fed7e866-481b-4f24-ae09-ca141a9e4ce0","first_update_id":10999770983605,"final_update_id":10999770990095,"previous_final_update_id":10999770983545,"bids":[{"price":"200.00","quantity":"7.594"},{"price":"1216.11","quantity":"0.128"},{"price":"1221.11","quantity":"7.104"},{"price":"1226.11","quantity":"2.368"},{"price":"1562.49","quantity":"0.026"},{"price":"1562.50","quantity":"4.474"},{"price":"1699.85","quantity":"17.783"},{"price":"1718.75","quantity":"422.137"},{"price":"1723.74","quantity":"16.817"},{"price":"1734.06","quantity":"54.181"},{"price":"1734.18","quantity":"423.525"},{"price":"1734.48","quantity":"18.844"},{"price":"1734.92","quantity":"282.532"},{"price":"1734.93","quantity":"68.261"},{"price":"1734.98","quantity":"69.905"},{"price":"1735.11","quantity":"45.389"},{"price":"1735.15","quantity":"8.596"},{"price":"1735.16","quantity":"9.230"},{"price":"1735.17","quantity":"0.647"},{"price":"1735.20","quantity":"57.708"},{"price":"1735.21","quantity":"33.697"},{"price":"1735.87","quantity":"3.843"},{"price":"1735.91","quantity":"12.485"},{"price":"1735.96","quantity":"9.200"},{"price":"1736.11","quantity":"162.166"}],"asks":[{"price":"1736.12","quantity":"164.299"},{"price":"1736.14","quantity":"0.129"},{"price":"1736.17","quantity":"0.036"},{"price":"1736.28","quantity":"0.085"},{"price":"1736.48","quantity":"12.772"},{"price":"1736.52","quantity":"0.270"},{"price":"1770.00","quantity":"1351.359"},{"price":"1773.62","quantity":"0.000"},{"price":"2634.29","quantity":"0.026"},{"price":"2634.38","quantity":"0.000"}],"raw":{"e":"depthUpdate","E":1783517071164,"T":1783517071161,"s":"ETHUSDT","ps":"ETHUSDT","U":10999770983605,"u":10999770990095,"pu":10999770983545,"b":[["200.00","7.594"],["1216.11","0.128"],["1221.11","7.104"],["1226.11","2.368"],["1562.49","0.026"],["1562.50","4.474"],["1699.85","17.783"],["1718.75","422.137"],["1723.74","16.817"],["1734.06","54.181"],["1734.18","423.525"],["1734.48","18.844"],["1734.92","282.532"],["1734.93","68.261"],["1734.98","69.905"],["1735.11","45.389"],["1735.15","8.596"],["1735.16","9.230"],["1735.17","0.647"],["1735.20","57.708"],["1735.21","33.697"],["1735.87","3.843"],["1735.91","12.485"],["1735.96","9.200"],["1736.11","162.166"]],"a":[["1736.12","164.299"],["1736.14","0.129"],["1736.17","0.036"],["1736.28","0.085"],["1736.48","12.772"],["1736.52","0.270"],["1770.00","1351.359"],["1773.62","0.000"],["2634.29","0.026"],["2634.38","0.000"]],"st":1}}
{"schema_version":"1.3.0","event_id":"bab0f51a-f3fe-4c08-8dda-c1b754c434cf","event_type":"raw.depth_update","source":"binance_market_data_recorder","venue":"binance_usdm","market_type":"perpetual_futures","symbol":"ETHUSDT","event_time_ms":1783517071266,"received_time_ms":1783517071260,"trace_id":"a67d1546-8ab9-4b28-8580-ace34915b702","first_update_id":10999770990348,"final_update_id":10999770995067,"previous_final_update_id":10999770990095,"bids":[{"price":"1216.11","quantity":"0.416"},{"price":"1221.11","quantity":"7.360"},{"price":"1226.11","quantity":"1.824"},{"price":"1562.04","quantity":"0.098"},{"price":"1562.49","quantity":"0.026"},{"price":"1562.50","quantity":"4.346"},{"price":"1666.60","quantity":"1.078"},{"price":"1701.38","quantity":"43.670"},{"price":"1709.09","quantity":"21.632"},{"price":"1713.71","quantity":"0.082"},{"price":"1733.89","quantity":"0.765"},{"price":"1734.74","quantity":"23.069"},{"price":"1735.06","quantity":"220.230"},{"price":"1735.08","quantity":"12.776"},{"price":"1735.15","quantity":"6.463"},{"price":"1735.16","quantity":"8.164"},{"price":"1735.18","quantity":"2.827"},{"price":"1735.19","quantity":"71.981"},{"price":"1735.43","quantity":"7.270"},{"price":"1735.53","quantity":"10.821"},{"price":"1735.60","quantity":"5.478"},{"price":"1735.76","quantity":"9.027"},{"price":"1735.97","quantity":"5.975"},{"price":"1736.10","quantity":"3.755"},{"price":"1736.11","quantity":"162.692"}],"asks":[{"price":"1736.12","quantity":"162.949"},{"price":"1736.20","quantity":"0.107"},{"price":"1736.31","quantity":"17.471"},{"price":"1736.41","quantity":"9.677"},{"price":"1736.52","quantity":"0.101"},{"price":"1736.89","quantity":"11.021"},{"price":"1737.24","quantity":"5.901"},{"price":"1737.26","quantity":"4.390"},{"price":"1737.59","quantity":"15.351"},{"price":"1737.77","quantity":"17.434"},{"price":"1738.78","quantity":"1.109"},{"price":"1740.17","quantity":"49.948"},{"price":"1763.90","quantity":"24.281"},{"price":"1769.11","quantity":"52.078"},{"price":"2634.27","quantity":"0.001"},{"price":"2634.28","quantity":"0.040"},{"price":"2634.36","quantity":"0.000"},{"price":"2634.37","quantity":"0.025"}],"raw":{"e":"depthUpdate","E":1783517071266,"T":1783517071265,"s":"ETHUSDT","ps":"ETHUSDT","U":10999770990348,"u":10999770995067,"pu":10999770990095,"b":[["1216.11","0.416"],["1221.11","7.360"],["1226.11","1.824"],["1562.04","0.098"],["1562.49","0.026"],["1562.50","4.346"],["1666.60","1.078"],["1701.38","43.670"],["1709.09","21.632"],["1713.71","0.082"],["1733.89","0.765"],["1734.74","23.069"],["1735.06","220.230"],["1735.08","12.776"],["1735.15","6.463"],["1735.16","8.164"],["1735.18","2.827"],["1735.19","71.981"],["1735.43","7.270"],["1735.53","10.821"],["1735.60","5.478"],["1735.76","9.027"],["1735.97","5.975"],["1736.10","3.755"],["1736.11","162.692"]],"a":[["1736.12","162.949"],["1736.20","0.107"],["1736.31","17.471"],["1736.41","9.677"],["1736.52","0.101"],["1736.89","11.021"],["1737.24","5.901"],["1737.26","4.390"],["1737.59","15.351"],["1737.77","17.434"],["1738.78","1.109"],["1740.17","49.948"],["1763.90","24.281"],["1769.11","52.078"],["2634.27","0.001"],["2634.28","0.040"],["2634.36","0.000"],["2634.37","0.025"]],"st":1}}
{"schema_version":"1.3.0","event_id":"2f7278b8-85bc-484a-bc07-e34f873353b1","event_type":"raw.depth_update","source":"binance_market_data_recorder","venue":"binance_usdm","market_type":"perpetual_futures","symbol":"ETHUSDT","event_time_ms":1783517071368,"received_time_ms":1783517071363,"trace_id":"00edb982-e345-490b-9159-ae5b76f87bdd","first_update_id":10999770995142,"final_update_id":10999771001828,"previous_final_update_id":10999770995067,"bids":[{"price":"200.00","quantity":"7.744"},{"price":"1216.11","quantity":"0.960"},{"price":"1221.11","quantity":"7.072"},{"price":"1226.11","quantity":"1.568"},{"price":"1562.49","quantity":"0.026"},{"price":"1562.50","quantity":"4.346"},{"price":"1666.60","quantity":"1.193"},{"price":"1680.22","quantity":"0.373"},{"price":"1701.38","quantity":"43.641"},{"price":"1709.89","quantity":"1274.799"},{"price":"1711.33","quantity":"63.256"},{"price":"1722.74","quantity":"5.853"},{"price":"1725.58","quantity":"1.658"},{"price":"1727.42","quantity":"0.629"},{"price":"1729.84","quantity":"15.567"},{"price":"1733.64","quantity":"426.407"},{"price":"1733.77","quantity":"19.838"},{"price":"1733.91","quantity":"0.465"},{"price":"1734.01","quantity":"20.653"},{"price":"1734.18","quantity":"0.012"},{"price":"1734.23","quantity":"10.276"},{"price":"1734.58","quantity":"0.519"},{"price":"1735.02","quantity":"50.511"},{"price":"1736.03","quantity":"1.134"}],"asks":[{"price":"1736.17","quantity":"0.056"},{"price":"1736.21","quantity":"8.322"},{"price":"1736.99","quantity":"22.016"},{"price":"1737.04","quantity":"32.765"},{"price":"1737.12","quantity":"7.826"},{"price":"1737.26","quantity":"1.657"},{"price":"1737.60","quantity":"7.231"},{"price":"1737.69","quantity":"2.123"},{"price":"1738.47","quantity":"41.217"},{"price":"1738.94","quantity":"3.960"},{"price":"1747.12","quantity":"0.000"},{"price":"1763.03","quantity":"35.952"},{"price":"2634.25","quantity":"1.094"},{"price":"2634.26","quantity":"0.079"},{"price":"2634.34","quantity":"0.000"},{"price":"2634.35","quantity":"0.000"}],"raw":{"e":"depthUpdate","E":1783517071368,"T":1783517071367,"s":"ETHUSDT","ps":"ETHUSDT","U":10999770995142,"u":10999771001828,"pu":10999770995067,"b":[["200.00","7.744"],["1216.11","0.960"],["1221.11","7.072"],["1226.11","1.568"],["1562.49","0.026"],["1562.50","4.346"],["1666.60","1.193"],["1680.22","0.373"],["1701.38","43.641"],["1709.89","1274.799"],["1711.33","63.256"],["1722.74","5.853"],["1725.58","1.658"],["1727.42","0.629"],["1729.84","15.567"],["1733.64","426.407"],["1733.77","19.838"],["1733.91","0.465"],["1734.01","20.653"],["1734.18","0.012"],["1734.23","10.276"],["1734.58","0.519"],["1735.02","50.511"],["1736.03","1.134"]],"a":[["1736.17","0.056"],["1736.21","8.322"],["1736.99","22.016"],["1737.04","32.765"],["1737.12","7.826"],["1737.26","1.657"],["1737.60","7.231"],["1737.69","2.123"],["1738.47","41.217"],["1738.94","3.960"],["1747.12","0.000"],["1763.03","35.952"],["2634.25","1.094"],["2634.26","0.079"],["2634.34","0.000"],["2634.35","0.000"]],"st":1}}
{"schema_version":"1.3.0","event_id":"53be32a9-a319-455f-898c-30b58b67a985","event_type":"raw.depth_update","source":"binance_market_data_recorder","venue":"binance_usdm","market_type":"perpetual_futures","symbol":"ETHUSDT","event_time_ms":1783517071470,"received_time_ms":1783517071468,"trace_id":"6fe7bbaf-89fd-4062-8a74-0edfa90c1480","first_update_id":10999771001925,"final_update_id":10999771007668,"previous_final_update_id":10999771001828,"bids":[{"price":"200.00","quantity":"7.594"},{"price":"1216.11","quantity":"1.504"},{"price":"1221.11","quantity":"6.816"},{"price":"1226.11","quantity":"1.280"},{"price":"1562.49","quantity":"0.026"},{"price":"1562.50","quantity":"4.346"},{"price":"1666.60","quantity":"1.078"},{"price":"1701.39","quantity":"32.216"},{"price":"1717.74","quantity":"55.242"},{"price":"1725.58","quantity":"88.867"},{"price":"1725.66","quantity":"21.746"},{"price":"1727.42","quantity":"0.617"},{"price":"1730.68","quantity":"32.838"},{"price":"1730.76","quantity":"0.528"},{"price":"1733.64","quantity":"2.894"},{"price":"1733.73","quantity":"43.339"},{"price":"1733.77","quantity":"18.392"},{"price":"1733.86","quantity":"1.809"},{"price":"1734.06","quantity":"477.694"},{"price":"1734.12","quantity":"55.897"},{"price":"1734.21","quantity":"18.217"},{"price":"1734.24","quantity":"1.474"},{"price":"1734.30","quantity":"12.542"},{"price":"1735.06","quantity":"0.127"},{"price":"1735.11","quantity":"45.389"},{"price":"1735.24","quantity":"7.546"},{"price":"1735.55","quantity":"6.304"},{"price":"1735.73","quantity":"26.047"},{"price":"1735.76","quantity":"8.929"},{"price":"1735.80","quantity":"10.610"},{"price":"1735.96","quantity":"0.552"},{"price":"1735.97","quantity":"14.623"},{"price":"1736.01","quantity":"0.050"},{"price":"1736.02","quantity":"0.152"},{"price":"1736.09","quantity":"23.127"},{"price":"1736.10","quantity":"7.539"}],"asks":[{"price":"1736.12","quantity":"145.529"},{"price":"1736.14","quantity":"0.040"},{"price":"1736.18","quantity":"0.299"},{"price":"1736.27","quantity":"0.038"},{"price":"1736.29","quantity":"1.287"},{"price":"1736.31","quantity":"17.471"},{"price":"1736.46","quantity":"45.089"},{"price":"1736.47","quantity":"7.668"},{"price":"1736.50","quantity":"28.935"},{"price":"1736.52","quantity":"0.087"},{"price":"1736.56","quantity":"18.991"},{"price":"1736.68","quantity":"6.405"},{"price":"1736.77","quantity":"0.161"},{"price":"1736.80","quantity":"43.120"},{"price":"1736.89","quantity":"8.141"},{"price":"1737.24","quantity":"0.141"},{"price":"1737.59","quantity":"3.831"},{"price":"1737.83","quantity":"34.780"},{"price":"1738.03","quantity":"0.000"},{"price":"1738.08","quantity":"1.684"},{"price":"1738.12","quantity":"5.998"},{"price":"1738.38","quantity":"0.046"},{"price":"1738.43","quantity":"406.836"},{"price":"1738.46","quantity":"27.583"},{"price":"1738.96","quantity":"3.196"},{"price":"1738.97","quantity":"185.116"},{"price":"1741.41","quantity":"24.723"},{"price":"1741.55","quantity":"0.014"},{"price":"1744.81","quantity":"0.166"},{"price":"2634.24","quantity":"0.001"},{"price":"2634.33","quantity":"0.000"}],"raw":{"e":"depthUpdate","E":1783517071470,"T":1783517071469,"s":"ETHUSDT","ps":"ETHUSDT","U":10999771001925,"u":10999771007668,"pu":10999771001828,"b":[["200.00","7.594"],["1216.11","1.504"],["1221.11","6.816"],["1226.11","1.280"],["1562.49","0.026"],["1562.50","4.346"],["1666.60","1.078"],["1701.39","32.216"],["1717.74","55.242"],["1725.58","88.867"],["1725.66","21.746"],["1727.42","0.617"],["1730.68","32.838"],["1730.76","0.528"],["1733.64","2.894"],["1733.73","43.339"],["1733.77","18.392"],["1733.86","1.809"],["1734.06","477.694"],["1734.12","55.897"],["1734.21","18.217"],["1734.24","1.474"],["1734.30","12.542"],["1735.06","0.127"],["1735.11","45.389"],["1735.24","7.546"],["1735.55","6.304"],["1735.73","26.047"],["1735.76","8.929"],["1735.80","10.610"],["1735.96","0.552"],["1735.97","14.623"],["1736.01","0.050"],["1736.02","0.152"],["1736.09","23.127"],["1736.10","7.539"]],"a":[["1736.12","145.529"],["1736.14","0.040"],["1736.18","0.299"],["1736.27","0.038"],["1736.29","1.287"],["1736.31","17.471"],["1736.46","45.089"],["1736.47","7.668"],["1736.50","28.935"],["1736.52","0.087"],["1736.56","18.991"],["1736.68","6.405"],["1736.77","0.161"],["1736.80","43.120"],["1736.89","8.141"],["1737.24","0.141"],["1737.59","3.831"],["1737.83","34.780"],["1738.03","0.000"],["1738.08","1.684"],["1738.12","5.998"],["1738.38","0.046"],["1738.43","406.836"],["1738.46","27.583"],["1738.96","3.196"],["1738.97","185.116"],["1741.41","24.723"],["1741.55","0.014"],["1744.81","0.166"],["2634.24","0.001"],["2634.33","0.000"]],"st":1}}
{"schema_version":"1.3.0","event_id":"4bf75e5d-a0ae-4d89-8540-ed8c391b3936","event_type":"raw.depth_update","source":"binance_market_data_recorder","venue":"binance_usdm","market_type":"perpetual_futures","symbol":"ETHUSDT","event_time_ms":1783517071574,"received_time_ms":1783517071569,"trace_id":"2776be4c-a2a3-467b-9f2b-22b37cf36426","first_update_id":10999771007768,"final_update_id":10999771015005,"previous_final_update_id":10999771007668,"bids":[{"price":"201.00","quantity":"2.300"},{"price":"1216.11","quantity":"2.080"},{"price":"1221.11","quantity":"6.496"},{"price":"1226.11","quantity":"1.024"},{"price":"1562.49","quantity":"0.026"},{"price":"1562.50","quantity":"4.346"},{"price":"1666.60","quantity":"1.193"},{"price":"1701.39","quantity":"32.187"},{"price":"1706.63","quantity":"29.265"},{"price":"1709.02","quantity":"21.457"},{"price":"1710.07","quantity":"177.375"},{"price":"1732.27","quantity":"1.444"},{"price":"1732.29","quantity":"37.902"},{"price":"1733.86","quantity":"0.363"},{"price":"1733.89","quantity":"2.211"},{"price":"1734.06","quantity":"54.181"},{"price":"1734.11","quantity":"79.720"},{"price":"1734.18","quantity":"423.525"},{"price":"1734.48","quantity":"18.044"},{"price":"1734.89","quantity":"25.168"},{"price":"1735.17","quantity":"220.745"},{"price":"1735.32","quantity":"29.804"},{"price":"1735.72","quantity":"2.321"},{"price":"1735.75","quantity":"71.462"},{"price":"1735.76","quantity":"8.944"},{"price":"1735.82","quantity":"0.866"},{"price":"1735.87","quantity":"3.843"},{"price":"1736.02","quantity":"0.173"},{"price":"1736.11","quantity":"163.871"}],"asks":[{"price":"1736.12","quantity":"87.764"},{"price":"1736.33","quantity":"3.175"},{"price":"1736.35","quantity":"9.645"},{"price":"1737.12","quantity":"7.826"},{"price":"1737.15","quantity":"7.871"},{"price":"1737.33","quantity":"21.257"},{"price":"1737.36","quantity":"70.029"},{"price":"1737.59","quantity":"28.831"},{"price":"1737.68","quantity":"20.286"},{"price":"1738.03","quantity":"1.667"},{"price":"1738.08","quantity":"408.508"},{"price":"1738.12","quantity":"4.331"},{"price":"1738.37","quantity":"139.779"},{"price":"1738.43","quantity":"0.012"},{"price":"1739.81","quantity":"11.827"},{"price":"1739.87","quantity":"31.585"},{"price":"1739.92","quantity":"0.025"},{"price":"2634.22","quantity":"0.002"},{"price":"2634.23","quantity":"0.001"},{"price":"2634.31","quantity":"0.052"},{"price":"2634.32","quantity":"0.000"}],"raw":{"e":"depthUpdate","E":1783517071574,"T":1783517071573,"s":"ETHUSDT","ps":"ETHUSDT","U":10999771007768,"u":10999771015005,"pu":10999771007668,"b":[["201.00","2.300"],["1216.11","2.080"],["1221.11","6.496"],["1226.11","1.024"],["1562.49","0.026"],["1562.50","4.346"],["1666.60","1.193"],["1701.39","32.187"],["1706.63","29.265"],["1709.02","21.457"],["1710.07","177.375"],["1732.27","1.444"],["1732.29","37.902"],["1733.86","0.363"],["1733.89","2.211"],["1734.06","54.181"],["1734.11","79.720"],["1734.18","423.525"],["1734.48","18.044"],["1734.89","25.168"],["1735.17","220.745"],["1735.32","29.804"],["1735.72","2.321"],["1735.75","71.462"],["1735.76","8.944"],["1735.82","0.866"],["1735.87","3.843"],["1736.02","0.173"],["1736.11","163.871"]],"a":[["1736.12","87.764"],["1736.33","3.175"],["1736.35","9.645"],["1737.12","7.826"],["1737.15","7.871"],["1737.33","21.257"],["1737.36","70.029"],["1737.59","28.831"],["1737.68","20.286"],["1738.03","1.667"],["1738.08","408.508"],["1738.12","4.331"],["1738.37","139.779"],["1738.43","0.012"],["1739.81","11.827"],["1739.87","31.585"],["1739.92","0.025"],["2634.22","0.002"],["2634.23","0.001"],["2634.31","0.052"],["2634.32","0.000"]],"st":1}}
{"schema_version":"1.3.0","event_id":"ad75bff7-868e-4bd4-b936-554ca018a528","event_type":"raw.depth_update","source":"binance_market_data_recorder","venue":"binance_usdm","market_type":"perpetual_futures","symbol":"ETHUSDT","event_time_ms":1783517071676,"received_time_ms":1783517071672,"trace_id":"4aceb3a9-2710-4c7f-a8bb-4ac99d8eae54","first_update_id":10999771015159,"final_update_id":10999771027291,"previous_final_update_id":10999771015005,"bids":[{"price":"200.00","quantity":"7.594"},{"price":"1216.11","quantity":"2.592"},{"price":"1221.11","quantity":"6.272"},{"price":"1226.11","quantity":"0.736"},{"price":"1562.49","quantity":"0.026"},{"price":"1562.50","quantity":"4.218"},{"price":"1701.39","quantity":"32.216"},{"price":"1709.19","quantity":"15.858"},{"price":"1715.30","quantity":"21.495"},{"price":"1731.25","quantity":"14.145"},{"price":"1733.53","quantity":"0.892"},{"price":"1733.63","quantity":"51.010"},{"price":"1733.64","quantity":"2.894"},{"price":"1733.68","quantity":"17.339"},{"price":"1733.69","quantity":"1.006"},{"price":"1733.70","quantity":"16.600"},{"price":"1733.89","quantity":"3.961"},{"price":"1733.98","quantity":"0.245"},{"price":"1734.01","quantity":"17.457"},{"price":"1734.06","quantity":"54.181"},{"price":"1734.12","quantity":"484.932"},{"price":"1734.18","quantity":"0.012"},{"price":"1734.33","quantity":"19.867"},{"price":"1734.58","quantity":"1.519"},{"price":"1734.74","quantity":"11.549"},{"price":"1734.79","quantity":"7.220"},{"price":"1734.92","quantity":"62.446"},{"price":"1734.93","quantity":"68.243"},{"price":"1735.07","quantity":"226.064"},{"price":"1735.08","quantity":"7.016"},{"price":"1735.09","quantity":"1.635"},{"price":"1735.10","quantity":"13.275"},{"price":"1735.12","quantity":"132.938"},{"price":"1735.13","quantity":"3.243"},{"price":"1735.17","quantity":"0.647"},{"price":"1735.18","quantity":"2.827"},{"price":"1735.19","quantity":"71.963"},{"price":"1735.21","quantity":"33.715"},{"price":"1735.27","quantity":"68.102"},{"price":"1735.29","quantity":"29.664"},{"price":"1735.34","quantity":"0.098"},{"price":"1735.37","quantity":"0.509"},{"price":"1735.41","quantity":"124.169"},{"price":"1735.43","quantity":"0.479"},{"price":"1735.45","quantity":"2.971"},{"price":"1735.51","quantity":"52.524"},{"price":"1735.53","quantity":"10.821"},{"price":"1735.54","quantity":"3.027"},{"price":"1735.60","quantity":"5.478"},{"price":"1735.62","quantity":"10.466"},{"price":"1735.67","quantity":"0.149"},{"price":"1735.69","quantity":"4.774"},{"price":"1735.76","quantity":"12.941"},{"price":"1735.77","quantity":"15.962"},{"price":"1735.78","quantity":"1.640"},{"price":"1735.80","quantity":"10.512"},{"price":"1735.82","quantity":"29.698"},{"price":"1735.86","quantity":"68.996"},{"price":"1735.87","quantity":"3.843"},{"price":"1735.90","quantity":"2.266"},{"price":"1735.93","quantity":"5.510"},{"price":"1735.94","quantity":"17.332"},{"price":"1735.97","quantity":"5.975"},{"price":"1735.99","quantity":"0.139"},{"price":"1736.00","quantity":"5.557"},{"price":"1736.01","quantity":"22.233"},{"price":"1736.02","quantity":"0.082"},{"price":"1736.03","quantity":"2.862"},{"price":"1736.04","quantity":"0.044"},{"price":"1736.07","quantity":"0.138"},{"price":"1736.09","quantity":"0.944"},{"price":"1736.10","quantity":"7.687"},{"price":"1736.11","quantity":"165.487"}],"asks":[{"price":"1736.12","quantity":"83.408"},{"price":"1736.13","quantity":"9.079"},{"price":"1736.15","quantity":"0.024"},{"price":"1736.16","quantity":"0.291"},{"price":"1736.17","quantity":"0.024"},{"price":"1736.18","quantity":"0.190"},{"price":"1736.19","quantity":"0.012"},{"price":"1736.20","quantity":"0.064"},{"price":"1736.21","quantity":"0.125"},{"price":"1736.23","quantity":"0.064"},{"price":"1736.24","quantity":"0.097"},{"price":"1736.25","quantity":"23.989"},{"price":"1736.26","quantity":"13.209"},{"price":"1736.28","quantity":"0.085"},{"price":"1736.29","quantity":"1.287"},{"price":"1736.30","quantity":"9.261"},{"price":"1736.31","quantity":"17.384"},{"price":"1736.32","quantity":"18.248"},{"price":"1736.33","quantity":"2.887"},{"price":"1736.34","quantity":"0.041"},{"price":"1736.35","quantity":"9.145"},{"price":"1736.37","quantity":"12.746"},{"price":"1736.38","quantity":"0.089"},{"price":"1736.40","quantity":"13.517"},{"price":"1736.41","quantity":"9.508"},{"price":"1736.42","quantity":"27.757"},{"price":"1736.46","quantity":"45.089"},{"price":"1736.48","quantity":"8.341"},{"price":"1736.49","quantity":"3.220"},{"price":"1736.50","quantity":"0.114"},{"price":"1736.53","quantity":"1.611"},{"price":"1736.54","quantity":"31.690"},{"price":"1736.56","quantity":"18.977"},{"price":"1736.59","quantity":"7.515"},{"price":"1736.62","quantity":"4.786"},{"price":"1736.63","quantity":"8.821"},{"price":"1736.65","quantity":"18.840"},{"price":"1736.66","quantity":"2.002"},{"price":"1736.69","quantity":"7.390"},{"price":"1736.72","quantity":"9.786"},{"price":"1736.73","quantity":"11.605"},{"price":"1736.74","quantity":"29.060"},{"price":"1736.85","quantity":"1.760"},{"price":"1736.87","quantity":"26.347"},{"price":"1736.89","quantity":"9.847"},{"price":"1736.90","quantity":"29.781"},{"price":"1737.07","quantity":"0.556"},{"price":"1737.09","quantity":"28.385"},{"price":"1737.14","quantity":"73.980"},{"price":"1737.15","quantity":"8.561"},{"price":"1737.22","quantity":"5.290"},{"price":"1737.33","quantity":"19.563"},{"price":"1737.37","quantity":"30.259"},{"price":"1737.42","quantity":"5.342"},{"price":"1737.49","quantity":"35.965"},{"price":"1737.59","quantity":"28.831"},{"price":"1738.08","quantity":"1.684"},{"price":"1738.12","quantity":"5.998"},{"price":"1738.14","quantity":"16.295"},{"price":"1738.19","quantity":"423.353"},{"price":"1738.78","quantity":"4.109"},{"price":"1738.98","quantity":"43.748"},{"price":"1740.16","quantity":"12.238"},{"price":"1740.17","quantity":"46.948"},{"price":"1740.75","quantity":"0.062"},{"price":"1741.75","quantity":"10.044"},{"price":"1742.48","quantity":"22.888"},{"price":"1746.39","quantity":"2.506"},{"price":"1746.41","quantity":"0.014"},{"price":"1747.12","quantity":"15.000"},{"price":"1748.02","quantity":"50.052"},{"price":"1766.08","quantity":"147.032"},{"price":"2634.21","quantity":"0.001"},{"price":"2634.30","quantity":"0.000"}],"raw":{"e":"depthUpdate","E":1783517071676,"T":1783517071675,"s":"ETHUSDT","ps":"ETHUSDT","U":10999771015159,"u":10999771027291,"pu":10999771015005,"b":[["200.00","7.594"],["1216.11","2.592"],["1221.11","6.272"],["1226.11","0.736"],["1562.49","0.026"],["1562.50","4.218"],["1701.39","32.216"],["1709.19","15.858"],["1715.30","21.495"],["1731.25","14.145"],["1733.53","0.892"],["1733.63","51.010"],["1733.64","2.894"],["1733.68","17.339"],["1733.69","1.006"],["1733.70","16.600"],["1733.89","3.961"],["1733.98","0.245"],["1734.01","17.457"],["1734.06","54.181"],["1734.12","484.932"],["1734.18","0.012"],["1734.33","19.867"],["1734.58","1.519"],["1734.74","11.549"],["1734.79","7.220"],["1734.92","62.446"],["1734.93","68.243"],["1735.07","226.064"],["1735.08","7.016"],["1735.09","1.635"],["1735.10","13.275"],["1735.12","132.938"],["1735.13","3.243"],["1735.17","0.647"],["1735.18","2.827"],["1735.19","71.963"],["1735.21","33.715"],["1735.27","68.102"],["1735.29","29.664"],["1735.34","0.098"],["1735.37","0.509"],["1735.41","124.169"],["1735.43","0.479"],["1735.45","2.971"],["1735.51","52.524"],["1735.53","10.821"],["1735.54","3.027"],["1735.60","5.478"],["1735.62","10.466"],["1735.67","0.149"],["1735.69","4.774"],["1735.76","12.941"],["1735.77","15.962"],["1735.78","1.640"],["1735.80","10.512"],["1735.82","29.698"],["1735.86","68.996"],["1735.87","3.843"],["1735.90","2.266"],["1735.93","5.510"],["1735.94","17.332"],["1735.97","5.975"],["1735.99","0.139"],["1736.00","5.557"],["1736.01","22.233"],["1736.02","0.082"],["1736.03","2.862"],["1736.04","0.044"],["1736.07","0.138"],["1736.09","0.944"],["1736.10","7.687"],["1736.11","165.487"]],"a":[["1736.12","83.408"],["1736.13","9.079"],["1736.15","0.024"],["1736.16","0.291"],["1736.17","0.024"],["1736.18","0.190"],["1736.19","0.012"],["1736.20","0.064"],["1736.21","0.125"],["1736.23","0.064"],["1736.24","0.097"],["1736.25","23.989"],["1736.26","13.209"],["1736.28","0.085"],["1736.29","1.287"],["1736.30","9.261"],["1736.31","17.384"],["1736.32","18.248"],["1736.33","2.887"],["1736.34","0.041"],["1736.35","9.145"],["1736.37","12.746"],["1736.38","0.089"],["1736.40","13.517"],["1736.41","9.508"],["1736.42","27.757"],["1736.46","45.089"],["1736.48","8.341"],["1736.49","3.220"],["1736.50","0.114"],["1736.53","1.611"],["1736.54","31.690"],["1736.56","18.977"],["1736.59","7.515"],["1736.62","4.786"],["1736.63","8.821"],["1736.65","18.840"],["1736.66","2.002"],["1736.69","7.390"],["1736.72","9.786"],["1736.73","11.605"],["1736.74","29.060"],["1736.85","1.760"],["1736.87","26.347"],["1736.89","9.847"],["1736.90","29.781"],["1737.07","0.556"],["1737.09","28.385"],["1737.14","73.980"],["1737.15","8.561"],["1737.22","5.290"],["1737.33","19.563"],["1737.37","30.259"],["1737.42","5.342"],["1737.49","35.965"],["1737.59","28.831"],["1738.08","1.684"],["1738.12","5.998"],["1738.14","16.295"],["1738.19","423.353"],["1738.78","4.109"],["1738.98","43.748"],["1740.16","12.238"],["1740.17","46.948"],["1740.75","0.062"],["1741.75","10.044"],["1742.48","22.888"],["1746.39","2.506"],["1746.41","0.014"],["1747.12","15.000"],["1748.02","50.052"],["1766.08","147.032"],["2634.21","0.001"],["2634.30","0.000"]],"st":1}}
{"schema_version":"1.3.0","event_id":"53c30dac-655f-4952-b073-feebabd42ed4","event_type":"raw.depth_update","source":"binance_market_data_recorder","venue":"binance_usdm","market_type":"perpetual_futures","symbol":"ETHUSDT","event_time_ms":1783517071778,"received_time_ms":1783517071775,"trace_id":"91e1b988-d32f-4835-b906-1330649c59ad","first_update_id":10999771027366,"final_update_id":10999771034274,"previous_final_update_id":10999771027291,"bids":[{"price":"1216.11","quantity":"3.168"},{"price":"1221.11","quantity":"5.952"},{"price":"1226.11","quantity":"0.480"},{"price":"1562.49","quantity":"0.026"},{"price":"1562.50","quantity":"4.218"},{"price":"1666.60","quantity":"1.078"},{"price":"1698.41","quantity":"29.507"},{"price":"1701.39","quantity":"32.187"},{"price":"1709.03","quantity":"20.640"},{"price":"1715.28","quantity":"9.897"},{"price":"1733.65","quantity":"438.954"},{"price":"1733.86","quantity":"1.809"},{"price":"1734.11","quantity":"29.720"},{"price":"1734.12","quantity":"55.897"},{"price":"1734.18","quantity":"0.012"},{"price":"1734.58","quantity":"0.519"},{"price":"1734.78","quantity":"1.444"},{"price":"1734.89","quantity":"0.168"},{"price":"1735.10","quantity":"13.075"},{"price":"1735.11","quantity":"45.389"},{"price":"1735.19","quantity":"71.981"},{"price":"1735.21","quantity":"33.697"},{"price":"1735.29","quantity":"29.864"},{"price":"1735.32","quantity":"26.988"},{"price":"1735.45","quantity":"0.092"},{"price":"1735.74","quantity":"22.508"},{"price":"1735.77","quantity":"10.196"},{"price":"1735.94","quantity":"17.044"},{"price":"1735.99","quantity":"0.427"},{"price":"1736.01","quantity":"0.050"},{"price":"1736.02","quantity":"8.730"},{"price":"1736.11","quantity":"187.670"}],"asks":[{"price":"1736.12","quantity":"83.426"},{"price":"1736.20","quantity":"0.084"},{"price":"1736.29","quantity":"6.206"},{"price":"1736.30","quantity":"20.893"},{"price":"1736.35","quantity":"9.145"},{"price":"1736.89","quantity":"9.835"},{"price":"1736.90","quantity":"29.769"},{"price":"1737.15","quantity":"5.704"},{"price":"1737.59","quantity":"3.831"},{"price":"1737.60","quantity":"4.591"},{"price":"1738.14","quantity":"423.328"},{"price":"1738.19","quantity":"16.320"},{"price":"1738.37","quantity":"89.779"},{"price":"2634.20","quantity":"0.042"},{"price":"2634.29","quantity":"0.025"}],"raw":{"e":"depthUpdate","E":1783517071778,"T":1783517071777,"s":"ETHUSDT","ps":"ETHUSDT","U":10999771027366,"u":10999771034274,"pu":10999771027291,"b":[["1216.11","3.168"],["1221.11","5.952"],["1226.11","0.480"],["1562.49","0.026"],["1562.50","4.218"],["1666.60","1.078"],["1698.41","29.507"],["1701.39","32.187"],["1709.03","20.640"],["1715.28","9.897"],["1733.65","438.954"],["1733.86","1.809"],["1734.11","29.720"],["1734.12","55.897"],["1734.18","0.012"],["1734.58","0.519"],["1734.78","1.444"],["1734.89","0.168"],["1735.10","13.075"],["1735.11","45.389"],["1735.19","71.981"],["1735.21","33.697"],["1735.29","29.864"],["1735.32","26.988"],["1735.45","0.092"],["1735.74","22.508"],["1735.77","10.196"],["1735.94","17.044"],["1735.99","0.427"],["1736.01","0.050"],["1736.02","8.730"],["1736.11","187.670"]],"a":[["1736.12","83.426"],["1736.20","0.084"],["1736.29","6.206"],["1736.30","20.893"],["1736.35","9.145"],["1736.89","9.835"],["1736.90","29.769"],["1737.15","5.704"],["1737.59","3.831"],["1737.60","4.591"],["1738.14","423.328"],["1738.19","16.320"],["1738.37","89.779"],["2634.20","0.042"],["2634.29","0.025"]],"st":1}}
{"schema_version":"1.3.0","event_id":"a377c3af-91b5-402c-b45b-84d32b3cf401","event_type":"raw.depth_update","source":"binance_market_data_recorder","venue":"binance_usdm","market_type":"perpetual_futures","symbol":"ETHUSDT","event_time_ms":1783517071880,"received_time_ms":1783517071874,"trace_id":"c16131ba-1607-4dba-a24e-ee39d4bdb800","first_update_id":10999771034304,"final_update_id":10999771041276,"previous_final_update_id":10999771034274,"bids":[{"price":"1216.11","quantity":"3.680"},{"price":"1221.11","quantity":"5.728"},{"price":"1226.11","quantity":"0.192"},{"price":"1562.49","quantity":"0.026"},{"price":"1562.50","quantity":"4.360"},{"price":"1666.60","quantity":"1.193"},{"price":"1677.68","quantity":"52.260"},{"price":"1701.38","quantity":"43.670"},{"price":"1705.75","quantity":"58.547"},{"price":"1711.44","quantity":"8.810"},{"price":"1718.06","quantity":"0.055"},{"price":"1733.65","quantity":"9.919"},{"price":"1733.86","quantity":"0.363"},{"price":"1733.89","quantity":"0.765"},{"price":"1734.18","quantity":"429.047"},{"price":"1734.21","quantity":"80.049"},{"price":"1734.22","quantity":"17.140"},{"price":"1735.11","quantity":"76.231"},{"price":"1735.18","quantity":"0.694"},{"price":"1735.19","quantity":"73.049"},{"price":"1735.20","quantity":"58.775"},{"price":"1735.22","quantity":"17.297"},{"price":"1735.26","quantity":"0.209"},{"price":"1735.56","quantity":"30.675"},{"price":"1735.70","quantity":"5.798"},{"price":"1735.82","quantity":"30.678"},{"price":"1736.03","quantity":"2.882"},{"price":"1736.10","quantity":"6.221"},{"price":"1736.11","quantity":"187.565"}],"asks":[{"price":"1736.14","quantity":"0.028"},{"price":"1736.23","quantity":"0.076"},{"price":"1736.24","quantity":"1.825"},{"price":"1736.29","quantity":"1.287"},{"price":"1736.50","quantity":"0.202"},{"price":"1736.52","quantity":"0.087"},{"price":"1736.53","quantity":"1.523"},{"price":"1736.55","quantity":"31.365"},{"price":"1736.60","quantity":"5.340"},{"price":"1736.65","quantity":"17.640"},{"price":"1736.74","quantity":"30.260"},{"price":"1736.89","quantity":"8.141"},{"price":"1737.11","quantity":"22.971"},{"price":"1737.12","quantity":"7.826"},{"price":"1737.19","quantity":"5.880"},{"price":"1737.22","quantity":"1.835"},{"price":"1737.64","quantity":"21.435"},{"price":"1737.68","quantity":"3.610"},{"price":"1737.80","quantity":"5.124"},{"price":"1737.82","quantity":"42.838"},{"price":"1737.83","quantity":"34.780"},{"price":"1738.00","quantity":"90.044"},{"price":"1738.08","quantity":"408.717"},{"price":"1738.12","quantity":"4.331"},{"price":"1738.14","quantity":"16.295"},{"price":"1738.96","quantity":"0.000"},{"price":"1747.12","quantity":"0.000"},{"price":"1756.61","quantity":"54.836"},{"price":"1756.95","quantity":"9.663"},{"price":"1763.40","quantity":"28.128"},{"price":"1764.78","quantity":"16.991"},{"price":"2634.18","quantity":"0.001"},{"price":"2634.19","quantity":"0.001"},{"price":"2634.27","quantity":"0.000"},{"price":"2634.28","quantity":"0.039"}],"raw":{"e":"depthUpdate","E":1783517071880,"T":1783517071879,"s":"ETHUSDT","ps":"ETHUSDT","U":10999771034304,"u":10999771041276,"pu":10999771034274,"b":[["1216.11","3.680"],["1221.11","5.728"],["1226.11","0.192"],["1562.49","0.026"],["1562.50","4.360"],["1666.60","1.193"],["1677.68","52.260"],["1701.38","43.670"],["1705.75","58.547"],["1711.44","8.810"],["1718.06","0.055"],["1733.65","9.919"],["1733.86","0.363"],["1733.89","0.765"],["1734.18","429.047"],["1734.21","80.049"],["1734.22","17.140"],["1735.11","76.231"],["1735.18","0.694"],["1735.19","73.049"],["1735.20","58.775"],["1735.22","17.297"],["1735.26","0.209"],["1735.56","30.675"],["1735.70","5.798"],["1735.82","30.678"],["1736.03","2.882"],["1736.10","6.221"],["1736.11","187.565"]],"a":[["1736.14","0.028"],["1736.23","0.076"],["1736.24","1.825"],["1736.29","1.287"],["1736.50","0.202"],["1736.52","0.087"],["1736.53","1.523"],["1736.55","31.365"],["1736.60","5.340"],["1736.65","17.640"],["1736.74","30.260"],["1736.89","8.141"],["1737.11","22.971"],["1737.12","7.826"],["1737.19","5.880"],["1737.22","1.835"],["1737.64","21.435"],["1737.68","3.610"],["1737.80","5.124"],["1737.82","42.838"],["1737.83","34.780"],["1738.00","90.044"],["1738.08","408.717"],["1738.12","4.331"],["1738.14","16.295"],["1738.96","0.000"],["1747.12","0.000"],["1756.61","54.836"],["1756.95","9.663"],["1763.40","28.128"],["1764.78","16.991"],["2634.18","0.001"],["2634.19","0.001"],["2634.27","0.000"],["2634.28","0.039"]],"st":1}}
{"schema_version":"1.3.0","event_id":"c19e0870-d389-4268-9653-093f3a7d4d99","event_type":"raw.depth_update","source":"binance_market_data_recorder","venue":"binance_usdm","market_type":"perpetual_futures","symbol":"ETHUSDT","event_time_ms":1783517071982,"received_time_ms":1783517071979,"trace_id":"be871b07-7a8c-4c9f-a7da-236b7306e5bf","first_update_id":10999771041351,"final_update_id":10999771046361,"previous_final_update_id":10999771041276,"bids":[{"price":"200.00","quantity":"7.594"},{"price":"1216.11","quantity":"4.320"},{"price":"1221.11","quantity":"5.280"},{"price":"1226.11","quantity":"0.000"},{"price":"1562.49","quantity":"0.026"},{"price":"1562.50","quantity":"4.232"},{"price":"1660.94","quantity":"2.445"},{"price":"1666.60","quantity":"1.078"},{"price":"1696.18","quantity":"45.249"},{"price":"1701.38","quantity":"43.641"},{"price":"1710.24","quantity":"189.771"},{"price":"1715.34","quantity":"219.660"},{"price":"1733.91","quantity":"3.661"},{"price":"1735.11","quantity":"76.231"},{"price":"1735.43","quantity":"3.358"},{"price":"1735.51","quantity":"53.392"},{"price":"1735.56","quantity":"27.796"},{"price":"1735.60","quantity":"5.413"}],"asks":[{"price":"1736.17","quantity":"0.036"},{"price":"1736.31","quantity":"17.384"},{"price":"1736.63","quantity":"8.870"},{"price":"1736.74","quantity":"29.060"},{"price":"1736.85","quantity":"1.018"},{"price":"1736.86","quantity":"1.522"},{"price":"1737.22","quantity":"1.835"},{"price":"1738.97","quantity":"181.920"},{"price":"1740.64","quantity":"175.727"},{"price":"1740.75","quantity":"0.050"},{"price":"2634.17","quantity":"0.001"},{"price":"2634.26","quantity":"0.078"}],"raw":{"e":"depthUpdate","E":1783517071982,"T":1783517071981,"s":"ETHUSDT","ps":"ETHUSDT","U":10999771041351,"u":10999771046361,"pu":10999771041276,"b":[["200.00","7.594"],["1216.11","4.320"],["1221.11","5.280"],["1226.11","0.000"],["1562.49","0.026"],["1562.50","4.232"],["1660.94","2.445"],["1666.60","1.078"],["1696.18","45.249"],["1701.38","43.641"],["1710.24","189.771"],["1715.34","219.660"],["1733.91","3.661"],["1735.11","76.231"],["1735.43","3.358"],["1735.51","53.392"],["1735.56","27.796"],["1735.60","5.413"]],"a":[["1736.17","0.036"],["1736.31","17.384"],["1736.63","8.870"],["1736.74","29.060"],["1736.85","1.018"],["1736.86","1.522"],["1737.22","1.835"],["1738.97","181.920"],["1740.64","175.727"],["1740.75","0.050"],["2634.17","0.001"],["2634.26","0.078"]],"st":1}}
